Workbook

Sheet Report1
A3: PAPER MACHINE 16 DAILY REPORT 1
A6: Date | B6: Grade | C6: GSM | D6: Speed yankee (mpm) | E6: Speed reel (mpm) | F6: Creep ( % ) | G6: Real Eff PM ( % ) | H6: Real Eff PM vs Target (%) | I6: Real Eff FG vs Real Eff PM (%) | J6: Eff FG vs Target (%) | L6: Kapasitas Target (ton) | N6: Kapasitas Teori Real (ton) | P6: PM PROD Timbangan (TON) | R6: FINSHED GOODS (TON) | T6: GAS HOOD | Z6: STEAM (TON) | AF6: POWER (kWh) | AL6: Kapasitas Running (ton) | AN6: Eff FG vs Target Running(%)
T7: CONSUMPTION | V7: /TON PM. | X7: /TON FG. | Z7: CONSUMPTION | AB7: /TON PM. | AD7: /TON FG. | AF7: CONSUMPTION | AH7: /TON PM | AJ7: /TON FG
J8: TODAY | K8: TODATE | L8: TODAY | M8: TODATE | N8: TODAY | O8: TODATE | P8: TODAY | Q8: TODATE | R8: TODAY | S8: TODATE | T8: TODAY | U8: TODATE | V8: TODAY | W8: TODATE | X8: TODAY | Y8: TODATE | Z8: TODAY | AA8: TODATE | AB8: TODAY | AC8: TODATE | AD8: TODAY | AE8: TODATE | AF8: TODAY | AG8: TODATE | AH8: TODAY | AI8: TODATE | AJ8: TODAY | AK8: TODATE | AL8: TODAY | AM8: TODATE | AN8: TODAY | AO8: TODATE
A9: 45992 | B9: Facial/Toilet | C9: 15/12,5/14 | D9: =+'1'!F42 -> 1305.2083 | E9: =+'1'!G42 -> 991.95833 | F9: =1-(E9/D9) -> 0.24 | G9: =+P9/N9 -> 1.0075891 | H9: =+P9/L9 -> 1.0075891 | I9: =+R9/P9 -> 1.0125728 | J9: =+R9/L9 -> 1.0202573 | K9: =+S9/M9 -> 1.0202573 | L9: =+SUM(Efficiency1!K6:K8) -> 53.677633 | M9: =L9 -> 53.677633 | N9: =+SUM(Efficiency1!C6:C8) -> 53.677633 | O9: =N9 -> 53.677633 | P9: ='1'!I38 -> 54.085 | Q9: =P9 -> 54.085 | R9: ='1'!I40 -> 54.765 | S9: =R9 -> 54.765 | T9: 0 | U9: =T9 -> 0 | V9: =T9/P9 -> 0 | W9: =U9/Q9 -> 0 | X9: =IF(AND(R9>0,T9>0),(T9/(R9*1000))*1000,0) -> 0 | Y9: =IF(AND(S9>0,U9>0),U9/S9,0) -> 0 | Z9: 126.4 | AA9: =Z9 -> 126.4 | AB9: =Z9/(P9) -> 2.337062 | AC9: =AA9/(Q9) -> 2.337062 | AD9: =IF(AND(R9>0,Z9>0),Z9/(R9),0) -> 2.3080435 | AE9: =IF(AND(S9>0,AA9>0),AA9/(S9),0) -> 2.3080435 | AF9: ='1'!I46 -> 33191.36 | AG9: =AF9 -> 33191.36 | AH9: =IF(AND(L9>0,AF9>0),(AF9/(P9*1000)*1000),0) -> 613.68882 | AI9: =IF(AND(M9>0,AG9>0),(AG9/(Q9*1000)*1000),0) -> 613.68882 | AJ9: =IF(AND(R9>0,AF9>0),(AF9/(R9*1000)*1000),0) -> 606.06884 | AK9: =IF(AND(S9>0,AG9>0),(AG9/(S9*1000)*1000),0) -> 606.06884 | AL9: =+SUM(Efficiency2!K6:K8) -> 53.677633 | AM9: =AL9 -> 53.677633 | AN9: =+R9/AL9 -> 1.0202573 | AO9: =+S9/AM9 -> 1.0202573
A10: =A9+1 -> 45993 | B10: Toilet | C10: 14 | D10: =+'2'!F42 -> 1300 | E10: =+'2'!G42 -> 988 | F10: =1-(E10/D10) -> 0.24 | G10: =+P10/N10 -> 0.99169064 | H10: =+P10/L10 -> 0.99169064 | I10: =+R10/P10 -> 0.98844157 | J10: =+R10/L10 -> 0.98022825 | K10: =+S10/M10 -> 1.0001501 | L10: =+Efficiency1!K11 -> 54.177178 | M10: =M9+L10 -> 107.85481 | N10: =+Efficiency1!C11 -> 54.177178 | O10: =O9+N10 -> 107.85481 | P10: ='2'!I38 -> 53.727 | Q10: =Q9+P10 -> 107.812 | R10: ='2'!I40 -> 53.106 | S10: =S9+R10 -> 107.871 | U10: =T10+U9 -> 0 | V10: =T10/P10 -> 0 | W10: =U10/Q10 -> 0 | X10: =IF(AND(R10>0,T10>0),(T10/(R10*1000))*1000,0) -> 0 | Y10: =IF(AND(S10>0,U10>0),U10/S10,0) -> 0 | Z10: 128.5 | AA10: =Z10+AA9 -> 254.9 | AB10: =Z10/(P10) -> 2.3917211 | AC10: =AA10/(Q10) -> 2.3643008 | AD10: =IF(AND(R10>0,Z10>0),Z10/(R10),0) -> 2.4196889 | AE10: =IF(AND(S10>0,AA10>0),AA10/(S10),0) -> 2.3630077 | AF10: ='2'!I46 -> 32671.9 | AG10: =AF10+AG9 -> 65863.26 | AH10: =IF(AND(L10>0,AF10>0),(AF10/(P10*1000)*1000),0) -> 608.10952 | AI10: =IF(AND(M10>0,AG10>0),(AG10/(Q10*1000)*1000),0) -> 610.90843 | AJ10: =IF(AND(R10>0,AF10>0),(AF10/(R10*1000)*1000),0) -> 615.2205 | AK10: =IF(AND(S10>0,AG10>0),(AG10/(S10*1000)*1000),0) -> 610.5743 | AL10: =+Efficiency2!K11 -> 54.177178 | AM10: =AM9+AL10 -> 107.85481 | AN10: =+R10/AL10 -> 0.98022825 | AO10: =+S10/AM10 -> 1.0001501
A11: =A10+1 -> 45994 | B11: Toilet | C11: 14 | D11: =+'3'!F42 -> 1300 | E11: =+'3'!G42 -> 988 | F11: =1-(E11/D11) -> 0.24 | G11: =+P11/N11 -> 1.0149661 | H11: =+P11/L11 -> 1.0149661 | I11: =+R11/P11 -> 1.0383356 | J11: =+R11/L11 -> 1.0538755 | K11: =+S11/M11 -> 1.0181138 | L11: =+Efficiency1!K16 -> 54.177178 | M11: =M10+L11 -> 162.03199 | N11: =+Efficiency1!C16 -> 54.177178 | O11: =O10+N11 -> 162.03199 | P11: ='3'!I38 -> 54.988 | Q11: =Q10+P11 -> 162.8 | R11: ='3'!I40 -> 57.096 | S11: =S10+R11 -> 164.967 | U11: =T11+U10 -> 0 | V11: =T11/P11 -> 0 | W11: =U11/Q11 -> 0 | X11: =IF(AND(R11>0,T11>0),(T11/(R11*1000))*1000,0) -> 0 | Y11: =IF(AND(S11>0,U11>0),U11/S11,0) -> 0 | Z11: 128.6 | AA11: =Z11+AA10 -> 383.5 | AB11: =Z11/(P11) -> 2.3386921 | AC11: =AA11/(Q11) -> 2.3556511 | AD11: =IF(AND(R11>0,Z11>0),Z11/(R11),0) -> 2.2523469 | AE11: =IF(AND(S11>0,AA11>0),AA11/(S11),0) -> 2.3247074 | AF11: ='3'!I46 -> 34318.84 | AG11: =AF11+AG10 -> 100182.1 | AH11: =IF(AND(L11>0,AF11>0),(AF11/(P11*1000)*1000),0) -> 624.11508 | AI11: =IF(AND(M11>0,AG11>0),(AG11/(Q11*1000)*1000),0) -> 615.36916 | AJ11: =IF(AND(R11>0,AF11>0),(AF11/(R11*1000)*1000),0) -> 601.07258 | AK11: =IF(AND(S11>0,AG11>0),(AG11/(S11*1000)*1000),0) -> 607.2857 | AL11: =+Efficiency2!K16 -> 54.177178 | AM11: =AM10+AL11 -> 162.03199 | AN11: =+R11/AL11 -> 1.0538755 | AO11: =+S11/AM11 -> 1.0181138
A12: =A11+1 -> 45995 | B12: Toilet | C12: 14 | D12: =+'4'!F42 -> 1300 | E12: =+'4'!G42 -> 988 | F12: =1-(E12/D12) -> 0.24 | G12: =+P12/N12 -> 0.90248334 | H12: =+P12/L12 -> 0.90248334 | I12: =+R12/P12 -> 0.83961222 | J12: =+R12/L12 -> 0.75773604 | K12: =+S12/M12 -> 0.95286894 | L12: =+Efficiency1!K20 -> 54.177178 | M12: =M11+L12 -> 216.20917 | N12: =+Efficiency1!C20 -> 54.177178 | O12: =O11+N12 -> 216.20917 | P12: ='4'!I38 -> 48.894 | Q12: =Q11+P12 -> 211.694 | R12: ='4'!I40 -> 41.052 | S12: =S11+R12 -> 206.019 | U12: =T12+U11 -> 0 | V12: =T12/P12 -> 0 | W12: =U12/Q12 -> 0 | X12: =IF(AND(R12>0,T12>0),(T12/(R12*1000))*1000,0) -> 0 | Y12: =IF(AND(S12>0,U12>0),U12/S12,0) -> 0 | Z12: 120.8 | AA12: =Z12+AA11 -> 504.3 | AB12: =Z12/(P12) -> 2.4706508 | AC12: =AA12/(Q12) -> 2.3822121 | AD12: =IF(AND(R12>0,Z12>0),Z12/(R12),0) -> 2.9426094 | AE12: =IF(AND(S12>0,AA12>0),AA12/(S12),0) -> 2.4478325 | AF12: ='4'!I46 -> 29201.52 | AG12: =AF12+AG11 -> 129383.62 | AH12: =IF(AND(L12>0,AF12>0),(AF12/(P12*1000)*1000),0) -> 597.24138 | AI12: =IF(AND(M12>0,AG12>0),(AG12/(Q12*1000)*1000),0) -> 611.18227 | AJ12: =IF(AND(R12>0,AF12>0),(AF12/(R12*1000)*1000),0) -> 711.33002 | AK12: =IF(AND(S12>0,AG12>0),(AG12/(S12*1000)*1000),0) -> 628.0179 | AL12: =+Efficiency2!K20 -> 54.177178 | AM12: =AM11+AL12 -> 216.20917 | AN12: =+R12/AL12 -> 0.75773604 | AO12: =+S12/AM12 -> 0.95286894
A13: =A12+1 -> 45996 | B13: Toilet | C13: 14/18/12,5 | D13: =+'5'!F42 -> 1214.5833 | E13: =+'5'!G42 -> 923.08333 | F13: =1-(E13/D13) -> 0.24 | G13: =+P13/N13 -> 0.98564952 | H13: =+P13/L13 -> 0.98564952 | I13: =+R13/P13 -> 0.96639294 | J13: =+R13/L13 -> 0.95252474 | K13: =+S13/M13 -> 0.95279941 | L13: =+SUM(Efficiency1!K25:K27) -> 54.732437 | M13: =M12+L13 -> 270.9416 | N13: =+SUM(Efficiency1!C25:C27) -> 54.732437 | O13: =O12+N13 -> 270.9416 | P13: ='5'!I38 -> 53.947 | Q13: =Q12+P13 -> 265.641 | R13: ='5'!I40 -> 52.134 | S13: =S12+R13 -> 258.153 | U13: =T13+U12 -> 0 | V13: =T13/P13 -> 0 | W13: =U13/Q13 -> 0 | X13: =IF(AND(R13>0,T13>0),(T13/(R13*1000))*1000,0) -> 0 | Y13: =IF(AND(S13>0,U13>0),U13/S13,0) -> 0 | Z13: 130.3 | AA13: =Z13+AA12 -> 634.6 | AB13: =Z13/(P13) -> 2.4153336 | AC13: =AA13/(Q13) -> 2.3889385 | AD13: =IF(AND(R13>0,Z13>0),Z13/(R13),0) -> 2.4993287 | AE13: =IF(AND(S13>0,AA13>0),AA13/(S13),0) -> 2.4582321 | AF13: ='5'!I46 -> 36373.82 | AG13: =AF13+AG12 -> 165757.44 | AH13: =IF(AND(L13>0,AF13>0),(AF13/(P13*1000)*1000),0) -> 674.25102 | AI13: =IF(AND(M13>0,AG13>0),(AG13/(Q13*1000)*1000),0) -> 623.99042 | AJ13: =IF(AND(R13>0,AF13>0),(AF13/(R13*1000)*1000),0) -> 697.69862 | AK13: =IF(AND(S13>0,AG13>0),(AG13/(S13*1000)*1000),0) -> 642.08992 | AL13: =+SUM(Efficiency2!K25:K27) -> 54.732437 | AM13: =AM12+AL13 -> 270.9416 | AN13: =+R13/AL13 -> 0.95252474 | AO13: =+S13/AM13 -> 0.95279941
A14: =A13+1 -> 45997 | B14: Toilet/Facial | C14: 12,5/13/12 | D14: =+'6'!F42 -> 1358.9792 | E14: =+'6'!G42 -> 1032.8242 | F14: =1-(E14/D14) -> 0.24 | G14: =+P14/N14 -> 0.94638359 | H14: =+P14/L14 -> 0.93905161 | I14: =+R14/P14 -> 0.95942082 | J14: =+R14/L14 -> 0.90094567 | K14: =+S14/M14 -> 0.94443053 | L14: =+SUM(Efficiency1!K29:K31) -> 52.144099 | M14: =M13+L14 -> 323.0857 | N14: =+SUM(Efficiency1!C29:C31) -> 51.74012 | O14: =O13+N14 -> 322.68172 | P14: ='6'!I38 -> 48.966 | Q14: =Q13+P14 -> 314.607 | R14: ='6'!I40 -> 46.979 | S14: =S13+R14 -> 305.132 | U14: =T14+U13 -> 0 | V14: =T14/P14 -> 0 | W14: =U14/Q14 -> 0 | X14: =IF(AND(R14>0,T14>0),(T14/(R14*1000))*1000,0) -> 0 | Y14: =IF(AND(S14>0,U14>0),U14/S14,0) -> 0 | Z14: 128.8 | AA14: =Z14+AA13 -> 763.4 | AB14: =Z14/(P14) -> 2.6303966 | AC14: =AA14/(Q14) -> 2.4265194 | AD14: =IF(AND(R14>0,Z14>0),Z14/(R14),0) -> 2.7416505 | AE14: =IF(AND(S14>0,AA14>0),AA14/(S14),0) -> 2.501868 | AF14: ='6'!I46 -> 52185.497 | AG14: =AF14+AG13 -> 217942.94 | AH14: =IF(AND(L14>0,AF14>0),(AF14/(P14*1000)*1000),0) -> 1065.7496 | AI14: =IF(AND(M14>0,AG14>0),(AG14/(Q14*1000)*1000),0) -> 692.74662 | AJ14: =IF(AND(R14>0,AF14>0),(AF14/(R14*1000)*1000),0) -> 1110.8261 | AK14: =IF(AND(S14>0,AG14>0),(AG14/(S14*1000)*1000),0) -> 714.25789 | AL14: =+SUM(Efficiency2!K29:K31) -> 52.144099 | AM14: =AM13+AL14 -> 323.0857 | AN14: =+R14/AL14 -> 0.90094567 | AO14: =+S14/AM14 -> 0.94443053
A15: =A14+1 -> 45998 | B15: Facial | C15: 12 | D15: =+'7'!F42 -> 1400 | E15: =+'7'!G42 -> 1064 | F15: =1-(E15/D15) -> 0.24 | G15: =+P15/N15 -> 0.95224265 | H15: =+P15/L15 -> 0.95224265 | I15: =+R15/P15 -> 0.90736812 | J15: =+R15/L15 -> 0.86403462 | K15: =+S15/M15 -> 0.93338087 | L15: =+Efficiency1!K33 -> 51.480576 | M15: =M14+L15 -> 374.56628 | N15: =+Efficiency1!C33 -> 51.480576 | O15: =O14+N15 -> 374.1623 | P15: ='7'!I38 -> 49.022 | Q15: =Q14+P15 -> 363.629 | R15: ='7'!I40 -> 44.481 | S15: =S14+R15 -> 349.613 | U15: =T15+U14 -> 0 | V15: =T15/P15 -> 0 | W15: =U15/Q15 -> 0 | X15: =IF(AND(R15>0,T15>0),(T15/(R15*1000))*1000,0) -> 0 | Y15: =IF(AND(S15>0,U15>0),U15/S15,0) -> 0 | Z15: 124.5 | AA15: =Z15+AA14 -> 887.9 | AB15: =Z15/(P15) -> 2.5396761 | AC15: =AA15/(Q15) -> 2.4417744 | AD15: =IF(AND(R15>0,Z15>0),Z15/(R15),0) -> 2.7989479 | AE15: =IF(AND(S15>0,AA15>0),AA15/(S15),0) -> 2.5396653 | AF15: ='7'!I46 -> 53845.359 | AG15: =AF15+AG14 -> 271788.3 | AH15: =IF(AND(L15>0,AF15>0),(AF15/(P15*1000)*1000),0) -> 1098.3917 | AI15: =IF(AND(M15>0,AG15>0),(AG15/(Q15*1000)*1000),0) -> 747.43295 | AJ15: =IF(AND(R15>0,AF15>0),(AF15/(R15*1000)*1000),0) -> 1210.5249 | AK15: =IF(AND(S15>0,AG15>0),(AG15/(S15*1000)*1000),0) -> 777.39757 | AL15: =+Efficiency2!K33 -> 51.480576 | AM15: =AM14+AL15 -> 374.56628 | AN15: =+R15/AL15 -> 0.86403462 | AO15: =+S15/AM15 -> 0.93338087
A16: =A15+1 -> 45999 | B16: Facial | C16: 12 | D16: =+'8'!F42 -> 1400 | E16: =+'8'!G42 -> 1064 | F16: =1-(E16/D16) -> 0.24 | G16: =+P16/N16 -> 0.93070054 | H16: =+P16/L16 -> 0.93070054 | I16: =+R16/P16 -> 1.1306743 | J16: =+R16/L16 -> 1.0523192 | K16: =+S16/M16 -> 0.94775257 | L16: =+Efficiency1!K37 -> 51.480576 | M16: =M15+L16 -> 426.04685 | N16: =+Efficiency1!C37 -> 51.480576 | O16: =O15+N16 -> 425.64287 | P16: ='8'!I38 -> 47.913 | Q16: =Q15+P16 -> 411.542 | R16: ='8'!I40 -> 54.174 | S16: =S15+R16 -> 403.787 | U16: =T16+U15 -> 0 | V16: =T16/P16 -> 0 | W16: =U16/Q16 -> 0 | X16: =IF(AND(R16>0,T16>0),(T16/(R16*1000))*1000,0) -> 0 | Y16: =IF(AND(S16>0,U16>0),U16/S16,0) -> 0 | Z16: 123.7 | AA16: =Z16+AA15 -> 1011.6 | AB16: =Z16/(P16) -> 2.5817628 | AC16: =AA16/(Q16) -> 2.4580723 | AD16: =IF(AND(R16>0,Z16>0),Z16/(R16),0) -> 2.2833832 | AE16: =IF(AND(S16>0,AA16>0),AA16/(S16),0) -> 2.5052812 | AF16: ='8'!I46 -> 51471.653 | AG16: =AF16+AG15 -> 323259.95 | AH16: =IF(AND(L16>0,AF16>0),(AF16/(P16*1000)*1000),0) -> 1074.2732 | AI16: =IF(AND(M16>0,AG16>0),(AG16/(Q16*1000)*1000),0) -> 785.48471 | AJ16: =IF(AND(R16>0,AF16>0),(AF16/(R16*1000)*1000),0) -> 950.11727 | AK16: =IF(AND(S16>0,AG16>0),(AG16/(S16*1000)*1000),0) -> 800.57047 | AL16: =+Efficiency2!K37 -> 51.480576 | AM16: =AM15+AL16 -> 426.04685 | AN16: =+R16/AL16 -> 1.0523192 | AO16: =+S16/AM16 -> 0.94775257
A17: =A16+1 -> 46000 | B17: Facial | C17: 12 | D17: =+'9'!F42 -> 1400 | E17: =+'9'!G42 -> 1064 | F17: =1-(E17/D17) -> 0.24 | G17: =+P17/N17 -> 0.92157089 | H17: =+P17/L17 -> 0.92157089 | I17: =+R17/P17 -> 1.0377506 | J17: =+R17/L17 -> 0.95636071 | K17: =+S17/M17 -> 0.94868058 | L17: =+Efficiency1!K41 -> 51.480576 | M17: =M16+L17 -> 477.52743 | N17: =+Efficiency1!C41 -> 51.480576 | O17: =O16+N17 -> 477.12345 | P17: ='9'!I38 -> 47.443 | Q17: =Q16+P17 -> 458.985 | R17: ='9'!I40 -> 49.234 | S17: =S16+R17 -> 453.021 | U17: =T17+U16 -> 0 | V17: =T17/P17 -> 0 | W17: =U17/Q17 -> 0 | X17: =IF(AND(R17>0,T17>0),(T17/(R17*1000))*1000,0) -> 0 | Y17: =IF(AND(S17>0,U17>0),U17/S17,0) -> 0 | Z17: 121.2 | AA17: =Z17+AA16 -> 1132.8 | AB17: =Z17/(P17) -> 2.5546445 | AC17: =AA17/(Q17) -> 2.4680545 | AD17: =IF(AND(R17>0,Z17>0),Z17/(R17),0) -> 2.4617135 | AE17: =IF(AND(S17>0,AA17>0),AA17/(S17),0) -> 2.5005463 | AF17: ='9'!I46 -> 51496.608 | AG17: =AF17+AG16 -> 374756.56 | AH17: =IF(AND(L17>0,AF17>0),(AF17/(P17*1000)*1000),0) -> 1085.4417 | AI17: =IF(AND(M17>0,AG17>0),(AG17/(Q17*1000)*1000),0) -> 816.48977 | AJ17: =IF(AND(R17>0,AF17>0),(AF17/(R17*1000)*1000),0) -> 1045.9562 | AK17: =IF(AND(S17>0,AG17>0),(AG17/(S17*1000)*1000),0) -> 827.23882 | AL17: =+Efficiency2!K41 -> 51.480576 | AM17: =AM16+AL17 -> 477.52743 | AN17: =+R17/AL17 -> 0.95636071 | AO17: =+S17/AM17 -> 0.94868058
A18: =A17+1 -> 46001 | B18: Facial | C18: 12 | D18: =+'10'!F42 -> 1400 | E18: =+'10'!G42 -> 1064 | F18: =1-(E18/D18) -> 0.24 | G18: =+P18/N18 -> 0.97052139 | H18: =+P18/L18 -> 0.97052139 | I18: =+R18/P18 -> 0.99055301 | J18: =+R18/L18 -> 0.96135288 | K18: =+S18/M18 -> 0.94991379 | L18: =+Efficiency1!K45 -> 51.480576 | M18: =M17+L18 -> 529.00801 | N18: =+Efficiency1!C45 -> 51.480576 | O18: =O17+N18 -> 528.60403 | P18: ='10'!I38 -> 49.963 | Q18: =Q17+P18 -> 508.948 | R18: ='10'!I40 -> 49.491 | S18: =S17+R18 -> 502.512 | U18: =T18+U17 -> 0 | V18: =T18/P18 -> 0 | W18: =U18/Q18 -> 0 | X18: =IF(AND(R18>0,T18>0),(T18/(R18*1000))*1000,0) -> 0 | Y18: =IF(AND(S18>0,U18>0),U18/S18,0) -> 0 | Z18: 119 | AA18: =Z18+AA17 -> 1251.8 | AB18: =Z18/(P18) -> 2.3817625 | AC18: =AA18/(Q18) -> 2.4595833 | AD18: =IF(AND(R18>0,Z18>0),Z18/(R18),0) -> 2.4044776 | AE18: =IF(AND(S18>0,AA18>0),AA18/(S18),0) -> 2.4910848 | AF18: ='10'!I46 -> 54581.959 | AG18: =AF18+AG17 -> 429338.52 | AH18: =IF(AND(L18>0,AF18>0),(AF18/(P18*1000)*1000),0) -> 1092.4476 | AI18: =IF(AND(M18>0,AG18>0),(AG18/(Q18*1000)*1000),0) -> 843.58032 | AJ18: =IF(AND(R18>0,AF18>0),(AF18/(R18*1000)*1000),0) -> 1102.8664 | AK18: =IF(AND(S18>0,AG18>0),(AG18/(S18*1000)*1000),0) -> 854.3846 | AL18: =+Efficiency2!K45 -> 51.480576 | AM18: =AM17+AL18 -> 529.00801 | AN18: =+R18/AL18 -> 0.96135288 | AO18: =+S18/AM18 -> 0.94991379
A19: =A18+1 -> 46002 | B19: Facial | C19: 12 | D19: =+'11'!F42 -> 1400 | E19: =+'11'!G42 -> 1064 | F19: =1-(E19/D19) -> 0.24 | G19: =+P19/N19 -> 0.9101491 | H19: =+P19/L19 -> 0.9101491 | I19: =+R19/P19 -> 0.89896489 | J19: =+R19/L19 -> 0.81819209 | K19: =+S19/M19 -> 0.93823206 | L19: =+Efficiency1!K49 -> 51.480576 | M19: =M18+L19 -> 580.48858 | N19: =+Efficiency1!C49 -> 51.480576 | O19: =O18+N19 -> 580.0846 | P19: ='11'!I38 -> 46.855 | Q19: =Q18+P19 -> 555.803 | R19: ='11'!I40 -> 42.121 | S19: =S18+R19 -> 544.633 | U19: =T19+U18 -> 0 | V19: =T19/P19 -> 0 | W19: =U19/Q19 -> 0 | X19: =IF(AND(R19>0,T19>0),(T19/(R19*1000))*1000,0) -> 0 | Y19: =IF(AND(S19>0,U19>0),U19/S19,0) -> 0 | Z19: 120.2 | AA19: =Z19+AA18 -> 1372 | AB19: =Z19/(P19) -> 2.5653612 | AC19: =AA19/(Q19) -> 2.4685005 | AD19: =IF(AND(R19>0,Z19>0),Z19/(R19),0) -> 2.8536834 | AE19: =IF(AND(S19>0,AA19>0),AA19/(S19),0) -> 2.5191276 | AF19: ='11'!I46 -> 48587.584 | AG19: =AF19+AG18 -> 477926.1 | AH19: =IF(AND(L19>0,AF19>0),(AF19/(P19*1000)*1000),0) -> 1036.9776 | AI19: =IF(AND(M19>0,AG19>0),(AG19/(Q19*1000)*1000),0) -> 859.88399 | AJ19: =IF(AND(R19>0,AF19>0),(AF19/(R19*1000)*1000),0) -> 1153.524 | AK19: =IF(AND(S19>0,AG19>0),(AG19/(S19*1000)*1000),0) -> 877.51954 | AL19: =+Efficiency2!K49 -> 51.480576 | AM19: =AM18+AL19 -> 580.48858 | AN19: =+R19/AL19 -> 0.81819209 | AO19: =+S19/AM19 -> 0.93823206
A20: =A19+1 -> 46003 | B20: Facial | C20: 12 | D20: =+'12'!F42 -> 1400 | E20: =+'12'!G42 -> 1064 | F20: =1-(E20/D20) -> 0.24 | G20: =+P20/N20 -> 0.89894099 | H20: =+P20/L20 -> 0.89894099 | I20: =+R20/P20 -> 0.92478067 | J20: =+R20/L20 -> 0.83132325 | K20: =+S20/M20 -> 0.92952321 | L20: =+Efficiency1!K53 -> 51.480576 | M20: =M19+L20 -> 631.96916 | N20: =+Efficiency2!K53 -> 51.480576 | O20: =O19+N20 -> 631.56518 | P20: ='12'!I38 -> 46.278 | Q20: =Q19+P20 -> 602.081 | R20: ='12'!I40 -> 42.797 | S20: =S19+R20 -> 587.43 | U20: =T20+U19 -> 0 | V20: =T20/P20 -> 0 | W20: =U20/Q20 -> 0 | X20: =IF(AND(R20>0,T20>0),(T20/(R20*1000))*1000,0) -> 0 | Y20: =IF(AND(S20>0,U20>0),U20/S20,0) -> 0 | Z20: 119.8 | AA20: =Z20+AA19 -> 1491.8 | AB20: =Z20/(P20) -> 2.5887031 | AC20: =AA20/(Q20) -> 2.4777397 | AD20: =IF(AND(R20>0,Z20>0),Z20/(R20),0) -> 2.7992616 | AE20: =IF(AND(S20>0,AA20>0),AA20/(S20),0) -> 2.5395366 | AF20: ='12'!I46 -> 53430.178 | AG20: =AF20+AG19 -> 531356.28 | AH20: =IF(AND(L20>0,AF20>0),(AF20/(P20*1000)*1000),0) -> 1154.5481 | AI20: =IF(AND(M20>0,AG20>0),(AG20/(Q20*1000)*1000),0) -> 882.53288 | AJ20: =IF(AND(R20>0,AF20>0),(AF20/(R20*1000)*1000),0) -> 1248.4561 | AK20: =IF(AND(S20>0,AG20>0),(AG20/(S20*1000)*1000),0) -> 904.54399 | AL20: =+Efficiency2!K53 -> 51.480576 | AM20: =AM19+AL20 -> 631.96916 | AN20: =+R20/AL20 -> 0.83132325 | AO20: =+S20/AM20 -> 0.92952321
A21: =A20+1 -> 46004 | B21: Facial | C21: 12 | D21: =+'13'!F42 -> 1400 | E21: =+'13'!G42 -> 1064 | F21: =1-(E21/D21) -> 0.24 | G21: =+P21/N21 -> 0.95226207 | H21: =+P21/L21 -> 0.95226207 | I21: =+R21/P21 -> 0.99383963 | J21: =+R21/L21 -> 0.94639578 | K21: =+S21/M21 -> 0.93079413 | L21: =+Efficiency1!K57 -> 51.480576 | M21: =M20+L21 -> 683.44973 | N21: =+Efficiency1!C57 -> 51.480576 | O21: =O20+N21 -> 683.04575 | P21: ='13'!I38 -> 49.023 | Q21: =Q20+P21 -> 651.104 | R21: ='13'!I40 -> 48.721 | S21: =S20+R21 -> 636.151 | U21: =T21+U20 -> 0 | V21: =T21/P21 -> 0 | W21: =U21/Q21 -> 0 | X21: =IF(AND(R21>0,T21>0),(T21/(R21*1000))*1000,0) -> 0 | Y21: =IF(AND(S21>0,U21>0),U21/S21,0) -> 0 | Z21: 116.4 | AA21: =Z21+AA20 -> 1608.2 | AB21: =Z21/(P21) -> 2.3743957 | AC21: =AA21/(Q21) -> 2.4699587 | AD21: =IF(AND(R21>0,Z21>0),Z21/(R21),0) -> 2.3891135 | AE21: =IF(AND(S21>0,AA21>0),AA21/(S21),0) -> 2.5280161 | AF21: ='13'!I46 -> 53717.128 | AG21: =AF21+AG20 -> 585073.41 | AH21: =IF(AND(L21>0,AF21>0),(AF21/(P21*1000)*1000),0) -> 1095.7536 | AI21: =IF(AND(M21>0,AG21>0),(AG21/(Q21*1000)*1000),0) -> 898.58672 | AJ21: =IF(AND(R21>0,AF21>0),(AF21/(R21*1000)*1000),0) -> 1102.5457 | AK21: =IF(AND(S21>0,AG21>0),(AG21/(S21*1000)*1000),0) -> 919.70838 | AL21: =+Efficiency2!K57 -> 51.480576 | AM21: =AM20+AL21 -> 683.44973 | AN21: =+R21/AL21 -> 0.94639578 | AO21: =+S21/AM21 -> 0.93079413
A22: =A21+1 -> 46005 | B22: Facial | C22: 12/13/11,5 | D22: =+'14'!F42 -> 1387.5816 | E22: =+'14'!G42 -> 1054.562 | F22: =1-(E22/D22) -> 0.24 | G22: =+P22/N22 -> 0.92014455 | H22: =+P22/L22 -> 0.92014455 | I22: =+R22/P22 -> 0.97182102 | J22: =+R22/L22 -> 0.89421582 | K22: =+S22/M22 -> 0.92819769 | L22: =+SUM(Efficiency1!K61:K63) -> 52.220056 | M22: =M21+L22 -> 735.66979 | N22: =+SUM(Efficiency1!C61:C63) -> 52.220056 | O22: =O21+N22 -> 735.26581 | P22: ='14'!I38 -> 48.05 | Q22: =Q21+P22 -> 699.154 | R22: ='14'!I40 -> 46.696 | S22: =S21+R22 -> 682.847 | U22: =T22+U21 -> 0 | V22: =T22/P22 -> 0 | W22: =U22/Q22 -> 0 | X22: =IF(AND(R22>0,T22>0),(T22/(R22*1000))*1000,0) -> 0 | Y22: =IF(AND(S22>0,U22>0),U22/S22,0) -> 0 | Z22: 116.4 | AA22: =Z22+AA21 -> 1724.6 | AB22: =Z22/(P22) -> 2.4224766 | AC22: =AA22/(Q22) -> 2.4666955 | AD22: =IF(AND(R22>0,Z22>0),Z22/(R22),0) -> 2.4927189 | AE22: =IF(AND(S22>0,AA22>0),AA22/(S22),0) -> 2.5256024 | AF22: ='14'!I46 -> 47159.3 | AG22: =AF22+AG21 -> 632232.71 | AH22: =IF(AND(L22>0,AF22>0),(AF22/(P22*1000)*1000),0) -> 981.46306 | AI22: =IF(AND(M22>0,AG22>0),(AG22/(Q22*1000)*1000),0) -> 904.28247 | AJ22: =IF(AND(R22>0,AF22>0),(AF22/(R22*1000)*1000),0) -> 1009.9216 | AK22: =IF(AND(S22>0,AG22>0),(AG22/(S22*1000)*1000),0) -> 925.87755 | AL22: =+SUM(Efficiency2!K61:K63) -> 52.220056 | AM22: =AM21+AL22 -> 735.66979 | AN22: =+R22/AL22 -> 0.89421582 | AO22: =+S22/AM22 -> 0.92819769
A23: =A22+1 -> 46006 | B23: Facial | C23: 11,5 | D23: =+'15'!F42 -> 1400 | E23: =+'15'!G42 -> 1064 | F23: =1-(E23/D23) -> 0.24 | G23: =+P23/N23 -> 0.89688983 | H23: =+P23/L23 -> 0.89688983 | I23: =+R23/P23 -> 0.87939139 | J23: =+R23/L23 -> 0.7887172 | K23: =+S23/M23 -> 0.91947136 | L23: =+Efficiency1!K66 -> 49.097446 | M23: =M22+L23 -> 784.76724 | N23: =+Efficiency1!C66 -> 49.097446 | O23: =O22+N23 -> 784.36326 | P23: ='15'!I38 -> 44.035 | Q23: =Q22+P23 -> 743.189 | R23: ='15'!I40 -> 38.724 | S23: =S22+R23 -> 721.571 | U23: =T23+U22 -> 0 | V23: =T23/P23 -> 0 | W23: =U23/Q23 -> 0 | X23: =IF(AND(R23>0,T23>0),(T23/(R23*1000))*1000,0) -> 0 | Y23: =IF(AND(S23>0,U23>0),U23/S23,0) -> 0 | Z23: 115.4 | AA23: =Z23+AA22 -> 1840 | AB23: =Z23/(P23) -> 2.6206427 | AC23: =AA23/(Q23) -> 2.4758171 | AD23: =IF(AND(R23>0,Z23>0),Z23/(R23),0) -> 2.980064 | AE23: =IF(AND(S23>0,AA23>0),AA23/(S23),0) -> 2.5499916 | AF23: ='15'!I46 -> 46980.992 | AG23: =AF23+AG22 -> 679213.7 | AH23: =IF(AND(L23>0,AF23>0),(AF23/(P23*1000)*1000),0) -> 1066.9012 | AI23: =IF(AND(M23>0,AG23>0),(AG23/(Q23*1000)*1000),0) -> 913.91786 | AJ23: =IF(AND(R23>0,AF23>0),(AF23/(R23*1000)*1000),0) -> 1213.2267 | AK23: =IF(AND(S23>0,AG23>0),(AG23/(S23*1000)*1000),0) -> 941.2985 | AL23: =+Efficiency2!K66 -> 49.097446 | AM23: =AM22+AL23 -> 784.76724 | AN23: =+R23/AL23 -> 0.7887172 | AO23: =+S23/AM23 -> 0.91947136
A24: =A23+1 -> 46007 | B24: Facial/Toilet | C24: 11,5/12 | D24: =+'16'!F42 -> 1400 | E24: =+'16'!G42 -> 1064 | F24: =1-(E24/D24) -> 0.24 | G24: =+P24/N24 -> 0.9566245 | H24: =+P24/L24 -> 0.9566245 | I24: =+R24/P24 -> 0.96012212 | J24: =+R24/L24 -> 0.91847634 | K24: =+S24/M24 -> 0.91941178 | L24: =+SUM(Efficiency1!K70:K71) -> 49.989312 | M24: =M23+L24 -> 834.75655 | N24: =+SUM(Efficiency1!C70:C71) -> 49.989312 | O24: =O23+N24 -> 834.35257 | P24: ='16'!I38 -> 47.821 | Q24: =Q23+P24 -> 791.01 | R24: ='16'!I40 -> 45.914 | S24: =S23+R24 -> 767.485 | U24: =T24+U23 -> 0 | V24: =T24/P24 -> 0 | W24: =U24/Q24 -> 0 | X24: =IF(AND(R24>0,T24>0),(T24/(R24*1000))*1000,0) -> 0 | Y24: =IF(AND(S24>0,U24>0),U24/S24,0) -> 0 | Z24: 116.7 | AA24: =Z24+AA23 -> 1956.7 | AB24: =Z24/(P24) -> 2.4403505 | AC24: =AA24/(Q24) -> 2.4736729 | AD24: =IF(AND(R24>0,Z24>0),Z24/(R24),0) -> 2.5417084 | AE24: =IF(AND(S24>0,AA24>0),AA24/(S24),0) -> 2.5494961 | AF24: ='16'!I46 -> 46468.575 | AG24: =AF24+AG23 -> 725682.27 | AH24: =IF(AND(L24>0,AF24>0),(AF24/(P24*1000)*1000),0) -> 971.719 | AI24: =IF(AND(M24>0,AG24>0),(AG24/(Q24*1000)*1000),0) -> 917.41226 | AJ24: =IF(AND(R24>0,AF24>0),(AF24/(R24*1000)*1000),0) -> 1012.0785 | AK24: =IF(AND(S24>0,AG24>0),(AG24/(S24*1000)*1000),0) -> 945.53284 | AL24: =+SUM(Efficiency2!K70:K71) -> 49.989312 | AM24: =AM23+AL24 -> 834.75655 | AN24: =+R24/AL24 -> 0.91847634 | AO24: =+S24/AM24 -> 0.91941178
A25: =A24+1 -> 46008 | B25: Toilet | C25: 12/17/18 | D25: =+'17'!F42 -> 1303.6667 | E25: =+'17'!G42 -> 1029.6667 | F25: =1-(E25/D25) -> 0.21017643 | G25: =+P25/N25 -> 0.98631032 | H25: =+P25/L25 -> 0.98631032 | I25: =+R25/P25 -> 1.0223232 | J25: =+R25/L25 -> 1.0083279 | K25: =+S25/M25 -> 0.924729 | L25: =+SUM(Efficiency1!K74:K76) -> 53.093837 | M25: =M24+L25 -> 887.85038 | N25: =+SUM(Efficiency1!C74:C76) -> 53.093837 | O25: =O24+N25 -> 887.44641 | P25: ='17'!I38 -> 52.367 | Q25: =Q24+P25 -> 843.377 | R25: ='17'!I40 -> 53.536 | S25: =S24+R25 -> 821.021 | U25: =T25+U24 -> 0 | V25: =T25/P25 -> 0 | W25: =U25/Q25 -> 0 | X25: =IF(AND(R25>0,T25>0),(T25/(R25*1000))*1000,0) -> 0 | Y25: =IF(AND(S25>0,U25>0),U25/S25,0) -> 0 | Z25: 121.1 | AA25: =Z25+AA24 -> 2077.8 | AB25: =Z25/(P25) -> 2.3125251 | AC25: =AA25/(Q25) -> 2.4636669 | AD25: =IF(AND(R25>0,Z25>0),Z25/(R25),0) -> 2.2620293 | AE25: =IF(AND(S25>0,AA25>0),AA25/(S25),0) -> 2.5307513 | AF25: ='17'!I46 -> 43860.739 | AG25: =AF25+AG24 -> 769543.01 | AH25: =IF(AND(L25>0,AF25>0),(AF25/(P25*1000)*1000),0) -> 837.56448 | AI25: =IF(AND(M25>0,AG25>0),(AG25/(Q25*1000)*1000),0) -> 912.45435 | AJ25: =IF(AND(R25>0,AF25>0),(AF25/(R25*1000)*1000),0) -> 819.27561 | AK25: =IF(AND(S25>0,AG25>0),(AG25/(S25*1000)*1000),0) -> 937.30003 | AL25: =+SUM(Efficiency2!K74:K76) -> 53.093837 | AM25: =AM24+AL25 -> 887.85038 | AN25: =+R25/AL25 -> 1.0083279 | AO25: =+S25/AM25 -> 0.924729
A26: =A25+1 -> 46009 | B26: Toilet | C26: 18 | D26: =+'18'!F42 -> 1100 | E26: =+'18'!G42 -> 847 | F26: =1-(E26/D26) -> 0.23 | G26: =+P26/N26 -> 0.92606984 | H26: =+P26/L26 -> 0.92606984 | I26: =+R26/P26 -> 0.91230352 | J26: =+R26/L26 -> 0.84485678 | K26: =+S26/M26 -> 0.91962617 | L26: =+Efficiency1!K78 -> 60.593702 | M26: =M25+L26 -> 948.44409 | N26: =+Efficiency1!C78 -> 60.593702 | O26: =O25+N26 -> 948.04011 | P26: ='18'!I38 -> 56.114 | Q26: =Q25+P26 -> 899.491 | R26: ='18'!I40 -> 51.193 | S26: =S25+R26 -> 872.214 | U26: =T26+U25 -> 0 | V26: =T26/P26 -> 0 | W26: =U26/Q26 -> 0 | X26: =IF(AND(R26>0,T26>0),(T26/(R26*1000))*1000,0) -> 0 | Y26: =IF(AND(S26>0,U26>0),U26/S26,0) -> 0 | Z26: 120.4 | AA26: =Z26+AA25 -> 2198.2 | AB26: =Z26/(P26) -> 2.1456321 | AC26: =AA26/(Q26) -> 2.4438266 | AD26: =IF(AND(R26>0,Z26>0),Z26/(R26),0) -> 2.351884 | AE26: =IF(AND(S26>0,AA26>0),AA26/(S26),0) -> 2.5202531 | AF26: ='18'!I46 -> 40830.024 | AG26: =AF26+AG25 -> 810373.04 | AH26: =IF(AND(L26>0,AF26>0),(AF26/(P26*1000)*1000),0) -> 727.62634 | AI26: =IF(AND(M26>0,AG26>0),(AG26/(Q26*1000)*1000),0) -> 900.92401 | AJ26: =IF(AND(R26>0,AF26>0),(AF26/(R26*1000)*1000),0) -> 797.57045 | AK26: =IF(AND(S26>0,AG26>0),(AG26/(S26*1000)*1000),0) -> 929.09886 | AL26: =+Efficiency2!K78 -> 60.593702 | AM26: =AM25+AL26 -> 948.44409 | AN26: =+R26/AL26 -> 0.84485678 | AO26: =+S26/AM26 -> 0.91962617
A27: =A26+1 -> 46010 | B27: Toilet | C27: 18/16 | D27: =+'19'!F42 -> 1113.125 | E27: =+'19'!G42 -> 838.51042 | F27: =1-(E27/D27) -> 0.24670597 | G27: =+P27/N27 -> 1.015056 | H27: =+P27/L27 -> 1.015056 | I27: =+R27/P27 -> 0.93932373 | J27: =+R27/L27 -> 0.95346615 | K27: =+S27/M27 -> 0.9215978 | L27: =+SUM(Efficiency1!K82:K83) -> 58.678538 | M27: =M26+L27 -> 1007.1226 | N27: =+SUM(Efficiency1!C82:C83) -> 58.678538 | O27: =O26+N27 -> 1006.7186 | P27: ='19'!I38 -> 59.562 | Q27: =Q26+P27 -> 959.053 | R27: ='19'!I40 -> 55.948 | S27: =S26+R27 -> 928.162 | U27: =T27+U26 -> 0 | V27: =T27/P27 -> 0 | W27: =U27/Q27 -> 0 | X27: =IF(AND(R27>0,T27>0),(T27/(R27*1000))*1000,0) -> 0 | Y27: =IF(AND(S27>0,U27>0),U27/S27,0) -> 0 | Z27: 121.5 | AA27: =Z27+AA26 -> 2319.7 | AB27: =Z27/(P27) -> 2.0398912 | AC27: =AA27/(Q27) -> 2.4187402 | AD27: =IF(AND(R27>0,Z27>0),Z27/(R27),0) -> 2.1716594 | AE27: =IF(AND(S27>0,AA27>0),AA27/(S27),0) -> 2.4992404 | AF27: ='19'!I46 -> 44507.821 | AG27: =AF27+AG26 -> 854880.86 | AH27: =IF(AND(L27>0,AF27>0),(AF27/(P27*1000)*1000),0) -> 747.25196 | AI27: =IF(AND(M27>0,AG27>0),(AG27/(Q27*1000)*1000),0) -> 891.3802 | AJ27: =IF(AND(R27>0,AF27>0),(AF27/(R27*1000)*1000),0) -> 795.52122 | AK27: =IF(AND(S27>0,AG27>0),(AG27/(S27*1000)*1000),0) -> 921.04703 | AL27: =+SUM(Efficiency2!K82:K83) -> 58.678538 | AM27: =AM26+AL27 -> 1007.1226 | AN27: =+R27/AL27 -> 0.95346615 | AO27: =+S27/AM27 -> 0.9215978
A28: =A27+1 -> 46011 | B28: Toilet | C28: 16/15 | D28: =+'20'!F42 -> 1191.5278 | E28: =+'20'!G42 -> 893.64583 | F28: =1-(E28/D28) -> 0.25 | G28: =+P28/N28 -> 0.98133738 | H28: =+P28/L28 -> 0.98133738 | I28: =+R28/P28 -> 1.117707 | J28: =+R28/L28 -> 1.0968476 | K28: =+S28/M28 -> 0.93083102 | L28: =+SUM(Efficiency1!K86:K87) -> 56.012337 | M28: =M27+L28 -> 1063.135 | N28: =+SUM(Efficiency1!C86:C87) -> 56.012337 | O28: =O27+N28 -> 1062.731 | P28: ='20'!I38 -> 54.967 | Q28: =Q27+P28 -> 1014.02 | R28: ='20'!I40 -> 61.437 | S28: =S27+R28 -> 989.599 | U28: =T28+U27 -> 0 | V28: =T28/P28 -> 0 | W28: =U28/Q28 -> 0 | X28: =IF(AND(R28>0,T28>0),(T28/(R28*1000))*1000,0) -> 0 | Y28: =IF(AND(S28>0,U28>0),U28/S28,0) -> 0 | Z28: 119.3 | AA28: =Z28+AA27 -> 2439 | AB28: =Z28/(P28) -> 2.1703931 | AC28: =AA28/(Q28) -> 2.405278 | AD28: =IF(AND(R28>0,Z28>0),Z28/(R28),0) -> 1.9418266 | AE28: =IF(AND(S28>0,AA28>0),AA28/(S28),0) -> 2.4646347 | AF28: ='20'!I46 -> 44667.521 | AG28: =AF28+AG27 -> 899548.38 | AH28: =IF(AND(L28>0,AF28>0),(AF28/(P28*1000)*1000),0) -> 812.62432 | AI28: =IF(AND(M28>0,AG28>0),(AG28/(Q28*1000)*1000),0) -> 887.11108 | AJ28: =IF(AND(R28>0,AF28>0),(AF28/(R28*1000)*1000),0) -> 727.04593 | AK28: =IF(AND(S28>0,AG28>0),(AG28/(S28*1000)*1000),0) -> 909.00292 | AL28: =+SUM(Efficiency2!K86:K87) -> 56.012337 | AM28: =AM27+AL28 -> 1063.135 | AN28: =+R28/AL28 -> 1.0968476 | AO28: =+S28/AM28 -> 0.93083102
A29: =A28+1 -> 46012 | B29: Toilet | C29: 15 | D29: =+'21'!F42 -> 1270 | E29: =+'21'!G42 -> 952.5 | F29: =1-(E29/D29) -> 0.25 | G29: =+P29/N29 -> 0.94045461 | H29: =+P29/L29 -> 0.94045461 | I29: =+R29/P29 -> 0.9298354 | J29: =+R29/L29 -> 0.87446799 | K29: =+S29/M29 -> 0.92797319 | L29: =+Efficiency1!K90 -> 56.78424 | M29: =M28+L29 -> 1119.9192 | N29: =+Efficiency1!C90 -> 56.78424 | O29: =O28+N29 -> 1119.5152 | P29: ='21'!I38 -> 53.403 | Q29: =Q28+P29 -> 1067.423 | R29: ='21'!I40 -> 49.656 | S29: =S28+R29 -> 1039.255 | U29: =T29+U28 -> 0 | V29: =T29/P29 -> 0 | W29: =U29/Q29 -> 0 | X29: =IF(AND(R29>0,T29>0),(T29/(R29*1000))*1000,0) -> 0 | Y29: =IF(AND(S29>0,U29>0),U29/S29,0) -> 0 | Z29: 125.5 | AA29: =Z29+AA28 -> 2564.5 | AB29: =Z29/(P29) -> 2.3500552 | AC29: =AA29/(Q29) -> 2.4025152 | AD29: =IF(AND(R29>0,Z29>0),Z29/(R29),0) -> 2.5273884 | AE29: =IF(AND(S29>0,AA29>0),AA29/(S29),0) -> 2.4676331 | AF29: ='21'!I46 -> 45190.689 | AG29: =AF29+AG28 -> 944739.07 | AH29: =IF(AND(L29>0,AF29>0),(AF29/(P29*1000)*1000),0) -> 846.22005 | AI29: =IF(AND(M29>0,AG29>0),(AG29/(Q29*1000)*1000),0) -> 885.06531 | AJ29: =IF(AND(R29>0,AF29>0),(AF29/(R29*1000)*1000),0) -> 910.0751 | AK29: =IF(AND(S29>0,AG29>0),(AG29/(S29*1000)*1000),0) -> 909.05415 | AL29: =+Efficiency2!K90 -> 56.78424 | AM29: =AM28+AL29 -> 1119.9192 | AN29: =+R29/AL29 -> 0.87446799 | AO29: =+S29/AM29 -> 0.92797319
A30: =A29+1 -> 46013 | B30: Toilet | C30: 15/13,5 | D30: =+'22'!F42 -> 1281.9444 | E30: =+'22'!G42 -> 961.45833 | F30: =1-(E30/D30) -> 0.25 | G30: =+P30/N30 -> 0.96802836 | H30: =+P30/L30 -> 0.96802836 | I30: =+R30/P30 -> 1.016302 | J30: =+R30/L30 -> 0.98380913 | K30: =+S30/M30 -> 0.93065308 | L30: =+SUM(Efficiency1!K94:K95) -> 56.461155 | M30: =M29+L30 -> 1176.3804 | N30: =+SUM(Efficiency1!C94:C95) -> 56.461155 | O30: =O29+N30 -> 1175.9764 | P30: ='22'!I38 -> 54.656 | Q30: =Q29+P30 -> 1122.079 | R30: ='22'!I40 -> 55.547 | S30: =S29+R30 -> 1094.802 | U30: =T30+U29 -> 0 | V30: =T30/P30 -> 0 | W30: =U30/Q30 -> 0 | X30: =IF(AND(R30>0,T30>0),(T30/(R30*1000))*1000,0) -> 0 | Y30: =IF(AND(S30>0,U30>0),U30/S30,0) -> 0 | Z30: 124.1 | AA30: =Z30+AA29 -> 2688.6 | AB30: =Z30/(P30) -> 2.270565 | AC30: =AA30/(Q30) -> 2.396088 | AD30: =IF(AND(R30>0,Z30>0),Z30/(R30),0) -> 2.2341441 | AE30: =IF(AND(S30>0,AA30>0),AA30/(S30),0) -> 2.4557865 | AF30: ='22'!I46 -> 45153.744 | AG30: =AF30+AG29 -> 989892.81 | AH30: =IF(AND(L30>0,AF30>0),(AF30/(P30*1000)*1000),0) -> 826.14432 | AI30: =IF(AND(M30>0,AG30>0),(AG30/(Q30*1000)*1000),0) -> 882.19529 | AJ30: =IF(AND(R30>0,AF30>0),(AF30/(R30*1000)*1000),0) -> 812.89258 | AK30: =IF(AND(S30>0,AG30>0),(AG30/(S30*1000)*1000),0) -> 904.17519 | AL30: =+SUM(Efficiency2!K94:K95) -> 56.461155 | AM30: =AM29+AL30 -> 1176.3804 | AN30: =+R30/AL30 -> 0.98380913 | AO30: =+S30/AM30 -> 0.93065308
A31: =A30+1 -> 46014 | B31: Toilet | C31: 13,5/14,5 | D31: =+'23'!F42 -> 1297.5 | E31: =+'23'!G42 -> 973.125 | F31: =1-(E31/D31) -> 0.25 | G31: =+P31/N31 -> 0.9691408 | H31: =+P31/L31 -> 0.9691408 | I31: =+R31/P31 -> 0.9492759 | J31: =+R31/L31 -> 0.91998201 | K31: =+S31/M31 -> 0.93017523 | L31: =+SUM(Efficiency1!K98:K99) -> 55.147817 | M31: =M30+L31 -> 1231.5282 | N31: =+SUM(Efficiency1!C98:C99) -> 55.147817 | O31: =O30+N31 -> 1231.1242 | P31: ='23'!I38 -> 53.446 | Q31: =Q30+P31 -> 1175.525 | R31: ='23'!I40 -> 50.735 | S31: =S30+R31 -> 1145.537 | U31: =T31+U30 -> 0 | V31: =T31/P31 -> 0 | W31: =U31/Q31 -> 0 | X31: =IF(AND(R31>0,T31>0),(T31/(R31*1000))*1000,0) -> 0 | Y31: =IF(AND(S31>0,U31>0),U31/S31,0) -> 0 | Z31: 120.1 | AA31: =Z31+AA30 -> 2808.7 | AB31: =Z31/(P31) -> 2.2471279 | AC31: =AA31/(Q31) -> 2.3893154 | AD31: =IF(AND(R31>0,Z31>0),Z31/(R31),0) -> 2.3672021 | AE31: =IF(AND(S31>0,AA31>0),AA31/(S31),0) -> 2.4518632 | AF31: ='23'!I46 -> 47900.264 | AG31: =AF31+AG30 -> 1037793.1 | AH31: =IF(AND(L31>0,AF31>0),(AF31/(P31*1000)*1000),0) -> 896.23665 | AI31: =IF(AND(M31>0,AG31>0),(AG31/(Q31*1000)*1000),0) -> 882.83369 | AJ31: =IF(AND(R31>0,AF31>0),(AF31/(R31*1000)*1000),0) -> 944.12662 | AK31: =IF(AND(S31>0,AG31>0),(AG31/(S31*1000)*1000),0) -> 905.94461 | AL31: =+SUM(Efficiency2!K98:K99) -> 55.147817 | AM31: =AM30+AL31 -> 1231.5282 | AN31: =+R31/AL31 -> 0.91998201 | AO31: =+S31/AM31 -> 0.93017523
A32: =A31+1 -> 46015 | B32: Toilet/Facial | C32: 14,5/116/13/12 | D32: =+'24'!F42 -> 1311.1111 | E32: =+'24'!G42 -> 992.33333 | F32: =1-(E32/D32) -> 0.24313559 | G32: =+P32/N32 -> 0.96571176 | H32: =+P32/L32 -> 0.96216501 | I32: =+R32/P32 -> 1.0331959 | J32: =+R32/L32 -> 0.99410497 | K32: =+S32/M32 -> 0.93278636 | L32: =+SUM(Efficiency1!K102:K105) -> 52.442148 | M32: =M31+L32 -> 1283.9703 | N32: =+SUM(Efficiency1!C102:C105) -> 52.249545 | O32: =O31+N32 -> 1283.3737 | P32: ='24'!I38 -> 50.458 | Q32: =Q31+P32 -> 1225.983 | R32: ='24'!I40 -> 52.133 | S32: =S31+R32 -> 1197.67 | U32: =T32+U31 -> 0 | V32: =T32/P32 -> 0 | W32: =U32/Q32 -> 0 | X32: =IF(AND(R32>0,T32>0),(T32/(R32*1000))*1000,0) -> 0 | Y32: =IF(AND(S32>0,U32>0),U32/S32,0) -> 0 | Z32: 120.5 | AA32: =Z32+AA31 -> 2929.2 | AB32: =Z32/(P32) -> 2.3881248 | AC32: =AA32/(Q32) -> 2.3892664 | AD32: =IF(AND(R32>0,Z32>0),Z32/(R32),0) -> 2.3113959 | AE32: =IF(AND(S32>0,AA32>0),AA32/(S32),0) -> 2.4457488 | AF32: =+'24'!I46 -> 48553.369 | AG32: =AF32+AG31 -> 1086346.4 | AH32: =IF(AND(L32>0,AF32>0),(AF32/(P32*1000)*1000),0) -> 962.25314 | AI32: =IF(AND(M32>0,AG32>0),(AG32/(Q32*1000)*1000),0) -> 886.10237 | AJ32: =IF(AND(R32>0,AF32>0),(AF32/(R32*1000)*1000),0) -> 931.33656 | AK32: =IF(AND(S32>0,AG32>0),(AG32/(S32*1000)*1000),0) -> 907.04989 | AL32: =+SUM(Efficiency2!K102:K105) -> 52.442148 | AM32: =AM31+AL32 -> 1283.9703 | AN32: =+R32/AL32 -> 0.99410497 | AO32: =+S32/AM32 -> 0.93278636
A33: =A32+1 -> 46016 | B33: Facial | C33: 12/12,5 | D33: =+'25'!F42 -> 1400 | E33: =+'25'!G42 -> 1064 | F33: =1-(E33/D33) -> 0.24 | G33: =+P33/N33 -> 0.97320103 | H33: =+P33/L33 -> 0.97320103 | I33: =+R33/P33 -> 0.92763393 | J33: =+R33/L33 -> 0.90277429 | K33: =+S33/M33 -> 0.93162193 | L33: =+SUM(Efficiency1!K107:K108) -> 51.826908 | M33: =M32+L33 -> 1335.7972 | N33: =+SUM(Efficiency1!C107:C108) -> 51.826908 | O33: =O32+N33 -> 1335.2006 | P33: ='25'!I38 -> 50.438 | Q33: =Q32+P33 -> 1276.421 | R33: ='25'!I40 -> 46.788 | S33: =S32+R33 -> 1244.458 | U33: =T33+U32 -> 0 | V33: =T33/P33 -> 0 | W33: =U33/Q33 -> 0 | X33: =IF(AND(R33>0,T33>0),(T33/(R33*1000))*1000,0) -> 0 | Y33: =IF(AND(S33>0,U33>0),U33/S33,0) -> 0 | Z33: 123.8 | AA33: =Z33+AA32 -> 3053 | AB33: =Z33/(P33) -> 2.4544986 | AC33: =AA33/(Q33) -> 2.3918441 | AD33: =IF(AND(R33>0,Z33>0),Z33/(R33),0) -> 2.6459776 | AE33: =IF(AND(S33>0,AA33>0),AA33/(S33),0) -> 2.4532768 | AF33: =+'25'!I46 -> 51416.83 | AG33: =AF33+AG32 -> 1137763.3 | AH33: =IF(AND(L33>0,AF33>0),(AF33/(P33*1000)*1000),0) -> 1019.4066 | AI33: =IF(AND(M33>0,AG33>0),(AG33/(Q33*1000)*1000),0) -> 891.36991 | AJ33: =IF(AND(R33>0,AF33>0),(AF33/(R33*1000)*1000),0) -> 1098.932 | AK33: =IF(AND(S33>0,AG33>0),(AG33/(S33*1000)*1000),0) -> 914.2641 | AL33: =+SUM(Efficiency2!K107:K108) -> 51.826908 | AM33: =AM32+AL33 -> 1335.7972 | AN33: =+R33/AL33 -> 0.90277429 | AO33: =+S33/AM33 -> 0.93162193
A34: =A33+1 -> 46017 | B34: Facial | C34: 12,5 | D34: =+'26'!F42 -> 1400 | E34: =+'26'!G42 -> 1064 | F34: =1-(E34/D34) -> 0.24 | G34: =+P34/N34 -> 0.90591061 | H34: =+P34/L34 -> 0.90591061 | I34: =+R34/P34 -> 0.97573075 | J34: =+R34/L34 -> 0.88392484 | K34: =+S34/M34 -> 0.92978104 | L34: =+Efficiency1!K111 -> 53.6256 | M34: =M33+L34 -> 1389.4228 | N34: =+Efficiency1!C111 -> 53.6256 | O34: =O33+N34 -> 1388.8262 | P34: ='26'!I38 -> 48.58 | Q34: =Q33+P34 -> 1325.001 | R34: ='26'!I40 -> 47.401 | S34: =S33+R34 -> 1291.859 | U34: =T34+U33 -> 0 | V34: =T34/P34 -> 0 | W34: =U34/Q34 -> 0 | X34: =IF(AND(R34>0,T34>0),(T34/(R34*1000))*1000,0) -> 0 | Y34: =IF(AND(S34>0,U34>0),U34/S34,0) -> 0 | Z34: 118.7 | AA34: =Z34+AA33 -> 3171.7 | AB34: =Z34/(P34) -> 2.4433923 | AC34: =AA34/(Q34) -> 2.393734 | AD34: =IF(AND(R34>0,Z34>0),Z34/(R34),0) -> 2.5041666 | AE34: =IF(AND(S34>0,AA34>0),AA34/(S34),0) -> 2.4551441 | AF34: ='26'!I46 -> 49826.74 | AG34: =AF34+AG33 -> 1187590 | AH34: =IF(AND(L34>0,AF34>0),(AF34/(P34*1000)*1000),0) -> 1025.6636 | AI34: =IF(AND(M34>0,AG34>0),(AG34/(Q34*1000)*1000),0) -> 896.29367 | AJ34: =IF(AND(R34>0,AF34>0),(AF34/(R34*1000)*1000),0) -> 1051.1749 | AK34: =IF(AND(S34>0,AG34>0),(AG34/(S34*1000)*1000),0) -> 919.28764 | AL34: =+Efficiency2!K111 -> 53.6256 | AM34: =AM33+AL34 -> 1389.4228 | AN34: =+R34/AL34 -> 0.88392484 | AO34: =+S34/AM34 -> 0.92978104
A35: =A34+1 -> 46018 | B35: Facial | C35: 12,5/12 | D35: =+'27'!F42 -> 1400 | E35: =+'27'!G42 -> 1064 | F35: =1-(E35/D35) -> 0.24 | G35: =+P35/N35 -> 0.91146949 | H35: =+P35/L35 -> 0.91146949 | I35: =+R35/P35 -> 1.0428911 | J35: =+R35/L35 -> 0.95056341 | K35: =+S35/M35 -> 0.93053969 | L35: =+SUM(Efficiency1!K115:K116) -> 52.642464 | M35: =M34+L35 -> 1442.0653 | N35: =+SUM(Efficiency1!C115:C116) -> 52.642464 | O35: =O34+N35 -> 1441.4687 | P35: ='27'!I38 -> 47.982 | Q35: =Q34+P35 -> 1372.983 | R35: ='27'!I40 -> 50.04 | S35: =S34+R35 -> 1341.899 | U35: =T35+U34 -> 0 | V35: =T35/P35 -> 0 | W35: =U35/Q35 -> 0 | X35: =IF(AND(R35>0,T35>0),(T35/(R35*1000))*1000,0) -> 0 | Y35: =IF(AND(S35>0,U35>0),U35/S35,0) -> 0 | Z35: 117.3 | AA35: =Z35+AA34 -> 3289 | AB35: =Z35/(P35) -> 2.4446668 | AC35: =AA35/(Q35) -> 2.395514 | AD35: =IF(AND(R35>0,Z35>0),Z35/(R35),0) -> 2.3441247 | AE35: =IF(AND(S35>0,AA35>0),AA35/(S35),0) -> 2.4510041 | AF35: ='27'!I46 -> 49423.229 | AG35: =AF35+AG34 -> 1237013.2 | AH35: =IF(AND(L35>0,AF35>0),(AF35/(P35*1000)*1000),0) -> 1030.0369 | AI35: =IF(AND(M35>0,AG35>0),(AG35/(Q35*1000)*1000),0) -> 900.96763 | AJ35: =IF(AND(R35>0,AF35>0),(AF35/(R35*1000)*1000),0) -> 987.67445 | AK35: =IF(AND(S35>0,AG35>0),(AG35/(S35*1000)*1000),0) -> 921.83782 | AL35: =+SUM(Efficiency2!K115:K116) -> 52.642464 | AM35: =AM34+AL35 -> 1442.0653 | AN35: =+R35/AL35 -> 0.95056341 | AO35: =+S35/AM35 -> 0.93053969
A36: =A35+1 -> 46019 | B36: Facial | C36: 12 | D36: =+'28'!F42 -> 1400 | E36: =+'28'!G42 -> 1064 | F36: =1-(E36/D36) -> 0.24 | G36: =+P36/N36 -> 0.95527645 | H36: =+P36/L36 -> 0.95527645 | I36: =+R36/P36 -> 0.97711562 | J36: =+R36/L36 -> 0.93341554 | K36: =+S36/M36 -> 0.93063742 | L36: =+Efficiency1!K119 -> 50.729818 | M36: =M35+L36 -> 1492.7951 | N36: =+Efficiency1!C119 -> 50.729818 | O36: =O35+N36 -> 1492.1985 | P36: ='28'!I38 -> 48.461 | Q36: =Q35+P36 -> 1421.444 | R36: ='28'!I40 -> 47.352 | S36: =S35+R36 -> 1389.251 | U36: =T36+U35 -> 0 | V36: =T36/P36 -> 0 | W36: =U36/Q36 -> 0 | X36: =IF(AND(R36>0,T36>0),(T36/(R36*1000))*1000,0) -> 0 | Y36: =IF(AND(S36>0,U36>0),U36/S36,0) -> 0 | Z36: 118.2 | AA36: =Z36+AA35 -> 3407.2 | AB36: =Z36/(P36) -> 2.4390747 | AC36: =AA36/(Q36) -> 2.3969991 | AD36: =IF(AND(R36>0,Z36>0),Z36/(R36),0) -> 2.4961987 | AE36: =IF(AND(S36>0,AA36>0),AA36/(S36),0) -> 2.4525446 | AF36: ='28'!I46 -> 53616.462 | AG36: =AF36+AG35 -> 1290629.7 | AH36: =IF(AND(L36>0,AF36>0),(AF36/(P36*1000)*1000),0) -> 1106.3837 | AI36: =IF(AND(M36>0,AG36>0),(AG36/(Q36*1000)*1000),0) -> 907.97084 | AJ36: =IF(AND(R36>0,AF36>0),(AF36/(R36*1000)*1000),0) -> 1132.2956 | AK36: =IF(AND(S36>0,AG36>0),(AG36/(S36*1000)*1000),0) -> 929.01118 | AL36: =+Efficiency2!K119 -> 50.729818 | AM36: =AM35+AL36 -> 1492.7951 | AN36: =+R36/AL36 -> 0.93341554 | AO36: =+S36/AM36 -> 0.93063742
A37: =A36+1 -> 46020 | B37: Facial | C37: 12 | D37: =+'29'!F42 -> 1400 | E37: =+'29'!G42 -> 1064 | F37: =1-(E37/D37) -> 0.24 | G37: =+P37/N37 -> 0.96596474 | H37: =+P37/L37 -> 0.96596474 | I37: =+R37/P37 -> 0.95683925 | J37: =+R37/L37 -> 0.92427298 | K37: =+S37/M37 -> 0.93043553 | L37: =+Efficiency1!K123 -> 48.906547 | M37: =M36+L37 -> 1541.7017 | N37: =+Efficiency1!C123 -> 48.906547 | O37: =O36+N37 -> 1541.1051 | P37: ='29'!I38 -> 47.242 | Q37: =Q36+P37 -> 1468.686 | R37: ='29'!I40 -> 45.203 | S37: =S36+R37 -> 1434.454 | U37: =T37+U36 -> 0 | V37: =T37/P37 -> 0 | W37: =U37/Q37 -> 0 | X37: =IF(AND(R37>0,T37>0),(T37/(R37*1000))*1000,0) -> 0 | Y37: =IF(AND(S37>0,U37>0),U37/S37,0) -> 0 | Z37: 116 | AA37: =Z37+AA36 -> 3523.2 | AB37: =Z37/(P37) -> 2.4554422 | AC37: =AA37/(Q37) -> 2.398879 | AD37: =IF(AND(R37>0,Z37>0),Z37/(R37),0) -> 2.5662014 | AE37: =IF(AND(S37>0,AA37>0),AA37/(S37),0) -> 2.4561262 | AF37: ='29'!I46 -> 45280.98 | AG37: =AF37+AG36 -> 1335910.7 | AH37: =IF(AND(L37>0,AF37>0),(AF37/(P37*1000)*1000),0) -> 958.48989 | AI37: =IF(AND(M37>0,AG37>0),(AG37/(Q37*1000)*1000),0) -> 909.59585 | AJ37: =IF(AND(R37>0,AF37>0),(AF37/(R37*1000)*1000),0) -> 1001.7251 | AK37: =IF(AND(S37>0,AG37>0),(AG37/(S37*1000)*1000),0) -> 931.30256 | AL37: =+Efficiency2!K123 -> 48.906547 | AM37: =AM36+AL37 -> 1541.7017 | AN37: =+R37/AL37 -> 0.92427298 | AO37: =+S37/AM37 -> 0.93043553
A38: =A37+1 -> 46021 | B38: Facial/Toilet | C38: 12/15 | D38: =+'30'!F42 -> 1327.9236 | E38: =+'30'!G42 -> 995.94271 | F38: =1-(E38/D38) -> 0.25 | G38: =+P38/N38 -> 0.94362244 | H38: =+P38/L38 -> 0.94362244 | I38: =+R38/P38 -> 0.97564321 | J38: =+R38/L38 -> 0.92063883 | K38: =+S38/M38 -> 0.93012187 | L38: =+SUM(Efficiency1!K128:K129) -> 50.992852 | M38: =M37+L38 -> 1592.6945 | N38: =+SUM(Efficiency1!C128:C129) -> 50.992852 | O38: =O37+N38 -> 1592.0979 | P38: ='30'!I38 -> 48.118 | Q38: =Q37+P38 -> 1516.804 | R38: ='30'!I40 -> 46.946 | S38: =S37+R38 -> 1481.4 | U38: =T38+U37 -> 0 | V38: =T38/P38 -> 0 | W38: =U38/Q38 -> 0 | X38: =IF(AND(R38>0,T38>0),(T38/(R38*1000))*1000,0) -> 0 | Y38: =IF(AND(S38>0,U38>0),U38/S38,0) -> 0 | Z38: 122.7 | AA38: =Z38+AA37 -> 3645.9 | AB38: =Z38/(P38) -> 2.5499813 | AC38: =AA38/(Q38) -> 2.4036725 | AD38: =IF(AND(R38>0,Z38>0),Z38/(R38),0) -> 2.6136412 | AE38: =IF(AND(S38>0,AA38>0),AA38/(S38),0) -> 2.4611179 | AF38: ='30'!I46 -> 44525.152 | AG38: =AF38+AG37 -> 1380435.8 | AH38: =IF(AND(L38>0,AF38>0),(AF38/(P38*1000)*1000),0) -> 925.33257 | AI38: =IF(AND(M38>0,AG38>0),(AG38/(Q38*1000)*1000),0) -> 910.09507 | AJ38: =IF(AND(R38>0,AF38>0),(AF38/(R38*1000)*1000),0) -> 948.43336 | AK38: =IF(AND(S38>0,AG38>0),(AG38/(S38*1000)*1000),0) -> 931.84544 | AL38: =+SUM(Efficiency2!K128:K129) -> 50.992852 | AM38: =AM37+AL38 -> 1592.6945 | AN38: =+R38/AL38 -> 0.92063883 | AO38: =+S38/AM38 -> 0.93012187
A39: =A38+1 -> 46022 | B39: Toilet | C39: 15 | D39: =+'31'!F42 -> 1249.8958 | E39: =+'31'!G42 -> 937.42188 | F39: =1-(E39/D39) -> 0.25 | G39: =+P39/N39 -> 1.018464 | H39: =+P39/L39 -> 1.018464 | I39: =+R39/P39 -> 0.95480671 | J39: =+R39/L39 -> 0.97243622 | K39: =+S39/M39 -> 0.93153026 | L39: =+Efficiency1!K132 -> 54.836502 | M39: =M38+L39 -> 1647.531 | N39: =+Efficiency1!C132 -> 54.836502 | O39: =O38+N39 -> 1646.9344 | P39: ='31'!I38 -> 55.849 | Q39: =Q38+P39 -> 1572.653 | R39: ='31'!I40 -> 53.325 | S39: =S38+R39 -> 1534.725 | U39: =T39+U38 -> 0 | V39: =T39/P39 -> 0 | W39: =U39/Q39 -> 0 | X39: =IF(AND(R39>0,T39>0),(T39/(R39*1000))*1000,0) -> 0 | Y39: =IF(AND(S39>0,U39>0),U39/S39,0) -> 0 | Z39: 130.6 | AA39: =Z39+AA38 -> 3776.5 | AB39: =Z39/(P39) -> 2.3384483 | AC39: =AA39/(Q39) -> 2.4013562 | AD39: =IF(AND(R39>0,Z39>0),Z39/(R39),0) -> 2.4491327 | AE39: =IF(AND(S39>0,AA39>0),AA39/(S39),0) -> 2.4607014 | AF39: ='31'!I46 -> 41738.34 | AG39: =AF39+AG38 -> 1422174.2 | AH39: =IF(AND(L39>0,AF39>0),(AF39/(P39*1000)*1000),0) -> 747.34265 | AI39: =IF(AND(M39>0,AG39>0),(AG39/(Q39*1000)*1000),0) -> 904.3153 | AJ39: =IF(AND(R39>0,AF39>0),(AF39/(R39*1000)*1000),0) -> 782.71617 | AK39: =IF(AND(S39>0,AG39>0),(AG39/(S39*1000)*1000),0) -> 926.66385 | AL39: =+Efficiency2!K132 -> 54.836502 | AM39: =AM38+AL39 -> 1647.531 | AN39: =+R39/AL39 -> 0.97243622 | AO39: =+S39/AM39 -> 0.93153026
G41: =+P41/N41 -> 0.95489715 | H41: =+P41/L41 -> 0.95455138 | I41: =+R41/P41 -> 0.97588279 | J41: =+R41/L41 -> 0.93153026 | L41: =SUM(L9:L39) -> 1647.531 | N41: =SUM(N9:N39) -> 1646.9344 | P41: =SUM(P9:P39) -> 1572.653 | R41: =SUM(R9:R39) -> 1534.725 | T41: =SUM(T9:T39) -> 0 | V41: =T41/P41 -> 0 | X41: =IF(AND(R41>0,T41>0),(T41/(R41*1000))*1000,0) -> 0 | Z41: =SUM(Z9:Z40) -> 3776.5 | AB41: =Z41/P41 -> 2.4013562 | AD41: =Z41/R41 -> 2.4607014 | AF41: =SUM(AF9:AF39) -> 1422174.2 | AH41: =AF41/P41 -> 904.3153 | AJ41: =AF41/R41 -> 926.66385 | AL41: =SUM(AL9:AL39) -> 1647.531 | AN41: =+R41/AL41 -> 0.93153026

Sheet GRAFIK

Sheet Listrik
A2: MACHINE POWER CONSUMPTION (PER PANEL)
A4: Date | B4: PM (TON) | C4: FINSHED GOODS (TON) | AN4: Total PM16
D5: Vacuum A | H5: Vacuum B | L5: MCC Aux TM | P5: Multi Screen | T5: MCC | X5: Drive Panel | AB5: Aux Panel | AF5: Stock Prep | AJ5: Pulper
D6: KWH | E6: Consumption | F6: /TON PM | G6: /TON FG | H6: KWH | I6: Consumption | J6: /TON PM | K6: /TON FG | L6: KWH | M6: Consumption | N6: /TON PM | O6: /TON FG | P6: KWH | Q6: Consumption | R6: /TON PM | S6: /TON FG | T6: KWH | U6: Consumption | V6: /TON PM | W6: /TON FG | X6: KWH | Y6: Consumption | Z6: /TON PM | AA6: /TON FG | AB6: KWH | AC6: Consumption | AD6: /TON PM | AE6: /TON FG | AF6: KWH | AG6: Consumption | AH6: /TON PM | AI6: /TON FG | AJ6: KWH | AK6: Consumption | AL6: /TON PM | AM6: /TON FG | AN6: Consumption | AO6: /TON PM | AP6: /TON FG
A8: =+Report1!A9 -> 45992 | B8: =+Report1!P9 -> 54.085 | C8: =+Report1!R9 -> 54.765 | D8: =+D7+E8 -> 0 | F8: =E8/B8 -> 0 | G8: =E8/C8 -> 0 | H8: =+H7+I8 -> 0 | I8: 0 | J8: =I8/B8 -> 0 | K8: =I8/C8 -> 0 | L8: =+L7+M8 -> 0 | N8: =M8/B8 -> 0 | O8: =M8/C8 -> 0 | P8: =+P7+Q8 -> 0 | R8: =Q8/B8 -> 0 | S8: =Q8/C8 -> 0 | T8: =+T7+U8 -> 7383.33 | U8: =+[1]DailyDes!AT7 -> 7383.33 | V8: =U8/B8 -> 136.51345 | W8: =U8/C8 -> 134.81841 | X8: =+X7+Y8 -> 14430 | Y8: =+[1]DailyDes!AU7 -> 14430 | Z8: =Y8/B8 -> 266.80226 | AA8: =Y8/C8 -> 263.48945 | AB8: =+AB7+AC8 -> 9749.33 | AC8: =+[1]DailyDes!AV7 -> 9749.33 | AD8: =AC8/B8 -> 180.25941 | AE8: =AC8/C8 -> 178.02118 | AF8: =+AF7+AG8 -> 0 | AG8: =+[1]DailyDes!AW7 -> 0 | AH8: =AG8/B8 -> 0 | AI8: =AG8/C8 -> 0 | AJ8: =+AJ7+AK8 -> 1628.7 | AK8: =+[1]DailyDes!AX7 -> 1628.7 | AL8: =AK8/B8 -> 30.11371 | AM8: =AK8/C8 -> 29.739797 | AN8: =+E8+I8+M8+Q8+U8+Y8+AC8+AG8+AK8 -> 33191.36 | AO8: =AN8/B8 -> 613.68882 | AP8: =AN8/C8 -> 606.06884 | AT8: Off Reel | AU8: Off Rewinder
A9: =A8+1 -> 45993 | B9: =+Report1!P10 -> 53.727 | C9: =+Report1!R10 -> 53.106 | D9: =+D8+E9 -> 0 | F9: =E9/B9 -> 0 | G9: =E9/C9 -> 0 | H9: =+H8+I9 -> 0 | J9: =I9/B9 -> 0 | K9: =I9/C9 -> 0 | L9: =+L8+M9 -> 0 | N9: =M9/B9 -> 0 | O9: =M9/C9 -> 0 | P9: =+P8+Q9 -> 0 | R9: =Q9/B9 -> 0 | S9: =Q9/C9 -> 0 | T9: =+T8+U9 -> 14291.28 | U9: =+[1]DailyDes!AT8 -> 6907.95 | V9: =U9/B9 -> 128.57502 | W9: =U9/C9 -> 130.07852 | X9: =+X8+Y9 -> 29110 | Y9: =+[1]DailyDes!AU8 -> 14680 | Z9: =Y9/B9 -> 273.2332 | AA9: =Y9/C9 -> 276.42828 | AB9: =+AB8+AC9 -> 18959.28 | AC9: =+[1]DailyDes!AV8 -> 9209.95 | AD9: =AC9/B9 -> 171.42126 | AE9: =AC9/C9 -> 173.42579 | AF9: =+AF8+AG9 -> 0 | AG9: =+[1]DailyDes!AW8 -> 0 | AH9: =AG9/B9 -> 0 | AI9: =AG9/C9 -> 0 | AJ9: =+AJ8+AK9 -> 3502.7 | AK9: =+[1]DailyDes!AX8 -> 1874 | AL9: =AK9/B9 -> 34.880042 | AM9: =AK9/C9 -> 35.287915 | AN9: =+E9+I9+M9+Q9+U9+Y9+AC9+AG9+AK9 -> 32671.9 | AO9: =AN9/B9 -> 608.10952 | AP9: =AN9/C9 -> 615.2205 | AT9: Kwh/ ton | AU9: Kwh/ ton
A10: =A9+1 -> 45994 | B10: =+Report1!P11 -> 54.988 | C10: =+Report1!R11 -> 57.096 | D10: =+D9+E10 -> 0 | F10: =E10/B10 -> 0 | G10: =E10/C10 -> 0 | H10: =+H9+I10 -> 0 | J10: =I10/B10 -> 0 | K10: =I10/C10 -> 0 | L10: =+L9+M10 -> 0 | N10: =M10/B10 -> 0 | O10: =M10/C10 -> 0 | P10: =+P9+Q10 -> 0 | R10: =Q10/B10 -> 0 | S10: =Q10/C10 -> 0 | T10: =+T9+U10 -> 21615.7 | U10: =+[1]DailyDes!AT9 -> 7324.42 | V10: =U10/B10 -> 133.20033 | W10: =U10/C10 -> 128.28254 | X10: =+X9+Y10 -> 42110 | Y10: =+[1]DailyDes!AU9 -> 13000 | Z10: =Y10/B10 -> 236.41522 | AA10: =Y10/C10 -> 227.6867 | AB10: =+AB9+AC10 -> 31033.7 | AC10: =+[1]DailyDes!AV9 -> 12074.42 | AD10: =AC10/B10 -> 219.58282 | AE10: =AC10/C10 -> 211.47576 | AF10: =+AF9+AG10 -> 0 | AG10: =+[1]DailyDes!AW9 -> 0 | AH10: =AG10/B10 -> 0 | AI10: =AG10/C10 -> 0 | AJ10: =+AJ9+AK10 -> 5422.7 | AK10: =+[1]DailyDes!AX9 -> 1920 | AL10: =AK10/B10 -> 34.916709 | AM10: =AK10/C10 -> 33.627575 | AN10: =+E10+I10+M10+Q10+U10+Y10+AC10+AG10+AK10 -> 34318.84 | AO10: =AN10/B10 -> 624.11508 | AP10: =AN10/C10 -> 601.07258 | AT10: Kwh/ ton | AU10: Kwh/ ton
A11: =A10+1 -> 45995 | B11: =+Report1!P12 -> 48.894 | C11: =+Report1!R12 -> 41.052 | D11: =+D10+E11 -> 0 | F11: =E11/B11 -> 0 | G11: =E11/C11 -> 0 | H11: =+H10+I11 -> 0 | J11: =I11/B11 -> 0 | K11: =I11/C11 -> 0 | L11: =+L10+M11 -> 0 | N11: =M11/B11 -> 0 | O11: =M11/C11 -> 0 | P11: =+P10+Q11 -> 0 | R11: =Q11/B11 -> 0 | S11: =Q11/C11 -> 0 | T11: =+T10+U11 -> 27901.46 | U11: =+[1]DailyDes!AT10 -> 6285.76 | V11: =U11/B11 -> 128.55892 | W11: =U11/C11 -> 153.11702 | X11: =+X10+Y11 -> 55110 | Y11: =+[1]DailyDes!AU10 -> 13000 | Z11: =Y11/B11 -> 265.88129 | AA11: =Y11/C11 -> 316.67154 | AB11: =+AB10+AC11 -> 38869.46 | AC11: =+[1]DailyDes!AV10 -> 7835.76 | AD11: =AC11/B11 -> 160.26015 | AE11: =AC11/C11 -> 190.87401 | AF11: =+AF10+AG11 -> 0 | AG11: =+[1]DailyDes!AW10 -> 0 | AH11: =AG11/B11 -> 0 | AI11: =AG11/C11 -> 0 | AJ11: =+AJ10+AK11 -> 7502.7 | AK11: =+[1]DailyDes!AX10 -> 2080 | AL11: =AK11/B11 -> 42.541007 | AM11: =AK11/C11 -> 50.667446 | AN11: =+E11+I11+M11+Q11+U11+Y11+AC11+AG11+AK11 -> 29201.52 | AO11: =AN11/B11 -> 597.24138 | AP11: =AN11/C11 -> 711.33002 | AS11: Vacuum B | AT11: =+J39 -> 0 | AU11: =+K39 -> 0
A12: =A11+1 -> 45996 | B12: =+Report1!P13 -> 53.947 | C12: =+Report1!R13 -> 52.134 | D12: =+D11+E12 -> 0 | F12: =E12/B12 -> 0 | G12: =E12/C12 -> 0 | H12: =+H11+I12 -> 0 | J12: =I12/B12 -> 0 | K12: =I12/C12 -> 0 | L12: =+L11+M12 -> 0 | N12: =M12/B12 -> 0 | O12: =M12/C12 -> 0 | P12: =+P11+Q12 -> 0 | R12: =Q12/B12 -> 0 | S12: =Q12/C12 -> 0 | T12: =+T11+U12 -> 35283.37 | U12: =+[1]DailyDes!AT11 -> 7381.91 | V12: =U12/B12 -> 136.83634 | W12: =U12/C12 -> 141.59493 | X12: =+X11+Y12 -> 72110 | Y12: =+[1]DailyDes!AU11 -> 17000 | Z12: =Y12/B12 -> 315.1241 | AA12: =Y12/C12 -> 326.08279 | AB12: =+AB11+AC12 -> 49051.37 | AC12: =+[1]DailyDes!AV11 -> 10181.91 | AD12: =AC12/B12 -> 188.73913 | AE12: =AC12/C12 -> 195.30268 | AF12: =+AF11+AG12 -> 0 | AG12: =+[1]DailyDes!AW11 -> 0 | AH12: =AG12/B12 -> 0 | AI12: =AG12/C12 -> 0 | AJ12: =+AJ11+AK12 -> 9312.7 | AK12: =+[1]DailyDes!AX11 -> 1810 | AL12: =AK12/B12 -> 33.551449 | AM12: =AK12/C12 -> 34.718226 | AN12: =+E12+I12+M12+Q12+U12+Y12+AC12+AG12+AK12 -> 36373.82 | AO12: =AN12/B12 -> 674.25102 | AP12: =AN12/C12 -> 697.69862 | AS12: MCC Aux TM | AT12: =+N39 -> 0 | AU12: =+O39 -> 0
A13: =A12+1 -> 45997 | B13: =+Report1!P14 -> 48.966 | C13: =+Report1!R14 -> 46.979 | D13: =+D12+E13 -> 0 | F13: =E13/B13 -> 0 | G13: =E13/C13 -> 0 | H13: =+H12+I13 -> 0 | J13: =I13/B13 -> 0 | K13: =I13/C13 -> 0 | L13: =+L12+M13 -> 0 | N13: =M13/B13 -> 0 | O13: =M13/C13 -> 0 | P13: =+P12+Q13 -> 0 | R13: =Q13/B13 -> 0 | S13: =Q13/C13 -> 0 | T13: =+T12+U13 -> 42800.36 | U13: =+[1]DailyDes!AT12 -> 7516.99 | V13: =U13/B13 -> 153.51448 | W13: =U13/C13 -> 160.00745 | X13: =+X12+Y13 -> 90110 | Y13: =+[1]DailyDes!AU12 -> 18000 | Z13: =Y13/B13 -> 367.60201 | AA13: =Y13/C13 -> 383.14992 | AB13: =+AB12+AC13 -> 59518.36 | AC13: =+[1]DailyDes!AV12 -> 10466.99 | AD13: =AC13/B13 -> 213.76036 | AE13: =AC13/C13 -> 222.80146 | AF13: =+AF12+AG13 -> 14401.517 | AG13: =+[1]DailyDes!AW12 -> 14401.517 | AH13: =AG13/B13 -> 294.11259 | AI13: =AG13/C13 -> 306.55223 | AJ13: =+AJ12+AK13 -> 11112.7 | AK13: =+[1]DailyDes!AX12 -> 1800 | AL13: =AK13/B13 -> 36.760201 | AM13: =AK13/C13 -> 38.314992 | AN13: =+E13+I13+M13+Q13+U13+Y13+AC13+AG13+AK13 -> 52185.497 | AO13: =AN13/B13 -> 1065.7496 | AP13: =AN13/C13 -> 1110.8261 | AS13: Multi Screen | AT13: =+R39 -> 0 | AU13: =+S39 -> 0
A14: =A13+1 -> 45998 | B14: =+Report1!P15 -> 49.022 | C14: =+Report1!R15 -> 44.481 | D14: =+D13+E14 -> 0 | F14: =E14/B14 -> 0 | G14: =E14/C14 -> 0 | H14: =+H13+I14 -> 0 | J14: =I14/B14 -> 0 | K14: =I14/C14 -> 0 | L14: =+L13+M14 -> 0 | N14: =M14/B14 -> 0 | O14: =M14/C14 -> 0 | P14: =+P13+Q14 -> 0 | R14: =Q14/B14 -> 0 | S14: =Q14/C14 -> 0 | T14: =+T13+U14 -> 50612.15 | U14: =+[1]DailyDes!AT13 -> 7811.79 | V14: =U14/B14 -> 159.35274 | W14: =U14/C14 -> 175.62083 | X14: =+X13+Y14 -> 109110 | Y14: =+[1]DailyDes!AU13 -> 19000 | Z14: =Y14/B14 -> 387.58109 | AA14: =Y14/C14 -> 427.14867 | AB14: =+AB13+AC14 -> 70030.15 | AC14: =+[1]DailyDes!AV13 -> 10511.79 | AD14: =AC14/B14 -> 214.43005 | AE14: =AC14/C14 -> 236.3209 | AF14: =+AF13+AG14 -> 29033.296 | AG14: =+[1]DailyDes!AW13 -> 14631.779 | AH14: =AG14/B14 -> 298.47372 | AI14: =AG14/C14 -> 328.94446 | AJ14: =+AJ13+AK14 -> 13002.7 | AK14: =+[1]DailyDes!AX13 -> 1890 | AL14: =AK14/B14 -> 38.554119 | AM14: =AK14/C14 -> 42.490052 | AN14: =+E14+I14+M14+Q14+U14+Y14+AC14+AG14+AK14 -> 53845.359 | AO14: =AN14/B14 -> 1098.3917 | AP14: =AN14/C14 -> 1210.5249 | AS14: WL II 1250 A (yankee + popereel) | AT14: =+V39 -> 0 | AU14: =+W39 -> 0
A15: =A14+1 -> 45999 | B15: =+Report1!P16 -> 47.913 | C15: =+Report1!R16 -> 54.174 | D15: =+D14+E15 -> 0 | F15: =E15/B15 -> 0 | G15: =E15/C15 -> 0 | H15: =+H14+I15 -> 0 | J15: =I15/B15 -> 0 | K15: =I15/C15 -> 0 | L15: =+L14+M15 -> 0 | N15: =M15/B15 -> 0 | O15: =M15/C15 -> 0 | P15: =+P14+Q15 -> 0 | R15: =Q15/B15 -> 0 | S15: =Q15/C15 -> 0 | T15: =+T14+U15 -> 58077.34 | U15: =+[1]DailyDes!AT14 -> 7465.19 | V15: =U15/B15 -> 155.80719 | W15: =U15/C15 -> 137.80024 | X15: =+X14+Y15 -> 127110 | Y15: =+[1]DailyDes!AU14 -> 18000 | Z15: =Y15/B15 -> 375.68092 | AA15: =Y15/C15 -> 332.26271 | AB15: =+AB14+AC15 -> 80145.34 | AC15: =+[1]DailyDes!AV14 -> 10115.19 | AD15: =AC15/B15 -> 211.11577 | AE15: =AC15/C15 -> 186.71669 | AF15: =+AF14+AG15 -> 42994.569 | AG15: =+[1]DailyDes!AW14 -> 13961.273 | AH15: =AG15/B15 -> 291.38799 | AI15: =AG15/C15 -> 257.71169 | AJ15: =+AJ14+AK15 -> 14932.7 | AK15: =+[1]DailyDes!AX14 -> 1930 | AL15: =AK15/B15 -> 40.281343 | AM15: =AK15/C15 -> 35.625946 | AN15: =+E15+I15+M15+Q15+U15+Y15+AC15+AG15+AK15 -> 51471.653 | AO15: =AN15/B15 -> 1074.2732 | AP15: =AN15/C15 -> 950.11727 | AS15: WL II 3200 A (Hood, Fan Pump, Felt & Wire) | AT15: =+Z39 -> 0 | AU15: =+AA39 -> 0
A16: =A15+1 -> 46000 | B16: =+Report1!P17 -> 47.443 | C16: =+Report1!R17 -> 49.234 | D16: =+D15+E16 -> 0 | F16: =E16/B16 -> 0 | G16: =E16/C16 -> 0 | H16: =+H15+I16 -> 0 | J16: =I16/B16 -> 0 | K16: =I16/C16 -> 0 | L16: =+L15+M16 -> 0 | N16: =M16/B16 -> 0 | O16: =M16/C16 -> 0 | P16: =+P15+Q16 -> 0 | R16: =Q16/B16 -> 0 | S16: =Q16/C16 -> 0 | T16: =+T15+U16 -> 64076.5 | U16: =+[1]DailyDes!AT15 -> 5999.16 | V16: =U16/B16 -> 126.44985 | W16: =U16/C16 -> 121.84994 | X16: =+X15+Y16 -> 146110 | Y16: =+[1]DailyDes!AU15 -> 19000 | Z16: =Y16/B16 -> 400.48058 | AA16: =Y16/C16 -> 385.91217 | AB16: =+AB15+AC16 -> 90844.5 | AC16: =+[1]DailyDes!AV15 -> 10699.16 | AD16: =AC16/B16 -> 225.51609 | AE16: =AC16/C16 -> 217.31243 | AF16: =+AF15+AG16 -> 56792.857 | AG16: =+[1]DailyDes!AW15 -> 13798.288 | AH16: =AG16/B16 -> 290.83929 | AI16: =AG16/C16 -> 280.25934 | AJ16: =+AJ15+AK16 -> 16932.7 | AK16: =+[1]DailyDes!AX15 -> 2000 | AL16: =AK16/B16 -> 42.15585 | AM16: =AK16/C16 -> 40.622334 | AN16: =+E16+I16+M16+Q16+U16+Y16+AC16+AG16+AK16 -> 51496.608 | AO16: =AN16/B16 -> 1085.4417 | AP16: =AN16/C16 -> 1045.9562 | AT16: =SUM(AT10:AT15) -> 0 | AU16: =SUM(AU10:AU15) -> 0
A17: =A16+1 -> 46001 | B17: =+Report1!P18 -> 49.963 | C17: =+Report1!R18 -> 49.491 | D17: =+D16+E17 -> 0 | F17: =E17/B17 -> 0 | G17: =E17/C17 -> 0 | H17: =+H16+I17 -> 0 | J17: =I17/B17 -> 0 | K17: =I17/C17 -> 0 | L17: =+L16+M17 -> 0 | N17: =M17/B17 -> 0 | O17: =M17/C17 -> 0 | P17: =+P16+Q17 -> 0 | R17: =Q17/B17 -> 0 | S17: =Q17/C17 -> 0 | T17: =+T16+U17 -> 72552.8 | U17: =+[1]DailyDes!AT16 -> 8476.3 | V17: =U17/B17 -> 169.65154 | W17: =U17/C17 -> 171.26952 | X17: =+X16+Y17 -> 165110 | Y17: =+[1]DailyDes!AU16 -> 19000 | Z17: =Y17/B17 -> 380.28141 | AA17: =Y17/C17 -> 383.90819 | AB17: =+AB16+AC17 -> 101420.8 | AC17: =+[1]DailyDes!AV16 -> 10576.3 | AD17: =AC17/B17 -> 211.68265 | AE17: =AC17/C17 -> 213.70148 | AF17: =+AF16+AG17 -> 70812.216 | AG17: =+[1]DailyDes!AW16 -> 14019.359 | AH17: =AG17/B17 -> 280.59482 | AI17: =AG17/C17 -> 283.27088 | AJ17: =+AJ16+AK17 -> 19442.7 | AK17: =+[1]DailyDes!AX16 -> 2510 | AL17: =AK17/B17 -> 50.237176 | AM17: =AK17/C17 -> 50.716292 | AN17: =+E17+I17+M17+Q17+U17+Y17+AC17+AG17+AK17 -> 54581.959 | AO17: =AN17/B17 -> 1092.4476 | AP17: =AN17/C17 -> 1102.8664 | AR17: Stockprep | AS17: Stock Prep & UTM 1 (3200 A) | AT17: =+AD39 -> 0 | AU17: =+AE39 -> 0
A18: =A17+1 -> 46002 | B18: =+Report1!P19 -> 46.855 | C18: =+Report1!R19 -> 42.121 | D18: =+D17+E18 -> 0 | F18: =E18/B18 -> 0 | G18: =E18/C18 -> 0 | H18: =+H17+I18 -> 0 | J18: =I18/B18 -> 0 | K18: =I18/C18 -> 0 | L18: =+L17+M18 -> 0 | N18: =M18/B18 -> 0 | O18: =M18/C18 -> 0 | P18: =+P17+Q18 -> 0 | R18: =Q18/B18 -> 0 | S18: =Q18/C18 -> 0 | T18: =+T17+U18 -> 79655.42 | U18: =+[1]DailyDes!AT17 -> 7102.62 | V18: =U18/B18 -> 151.58724 | W18: =U18/C18 -> 168.6242 | X18: =+X17+Y18 -> 183110 | Y18: =+[1]DailyDes!AU17 -> 18000 | Z18: =Y18/B18 -> 384.16391 | AA18: =Y18/C18 -> 427.34028 | AB18: =+AB17+AC18 -> 110723.42 | AC18: =+[1]DailyDes!AV17 -> 9302.62 | AD18: =AC18/B18 -> 198.5406 | AE18: =AC18/C18 -> 220.85468 | AF18: =+AF17+AG18 -> 82604.56 | AG18: =+[1]DailyDes!AW17 -> 11792.344 | AH18: =AG18/B18 -> 251.67738 | AI18: =AG18/C18 -> 279.96352 | AJ18: =+AJ17+AK18 -> 21832.7 | AK18: =+[1]DailyDes!AX17 -> 2390 | AL18: =AK18/B18 -> 51.00843 | AM18: =AK18/C18 -> 56.741293 | AN18: =+E18+I18+M18+Q18+U18+Y18+AC18+AG18+AK18 -> 48587.584 | AO18: =AN18/B18 -> 1036.9776 | AP18: =AN18/C18 -> 1153.524 | AS18: Stock Prep & UTM 2 (3200 A) | AT18: =+AH39 -> 0 | AU18: =+AI39 -> 0
A19: =A18+1 -> 46003 | B19: =+Report1!P20 -> 46.278 | C19: =+Report1!R20 -> 42.797 | D19: =+D18+E19 -> 0 | F19: =E19/B19 -> 0 | G19: =E19/C19 -> 0 | H19: =+H18+I19 -> 0 | J19: =I19/B19 -> 0 | K19: =I19/C19 -> 0 | L19: =+L18+M19 -> 0 | N19: =M19/B19 -> 0 | O19: =M19/C19 -> 0 | P19: =+P18+Q19 -> 0 | R19: =Q19/B19 -> 0 | S19: =Q19/C19 -> 0 | T19: =+T18+U19 -> 87344.66 | U19: =+[1]DailyDes!AT18 -> 7689.24 | V19: =U19/B19 -> 166.15325 | W19: =U19/C19 -> 179.66773 | X19: =+X18+Y19 -> 202110 | Y19: =+[1]DailyDes!AU18 -> 19000 | Z19: =Y19/B19 -> 410.56225 | AA19: =Y19/C19 -> 443.95635 | AB19: =+AB18+AC19 -> 121712.66 | AC19: =+[1]DailyDes!AV18 -> 10989.24 | AD19: =AC19/B19 -> 237.46143 | AE19: =AC19/C19 -> 256.77594 | AF19: =+AF18+AG19 -> 95936.258 | AG19: =+[1]DailyDes!AW18 -> 13331.698 | AH19: =AG19/B19 -> 288.07852 | AI19: =AG19/C19 -> 311.5101 | AJ19: =+AJ18+AK19 -> 24252.7 | AK19: =+[1]DailyDes!AX18 -> 2420 | AL19: =AK19/B19 -> 52.292666 | AM19: =AK19/C19 -> 56.54602 | AN19: =+E19+I19+M19+Q19+U19+Y19+AC19+AG19+AK19 -> 53430.178 | AO19: =AN19/B19 -> 1154.5481 | AP19: =AN19/C19 -> 1248.4561 | AT19: =SUM(AT17:AT18) -> 0 | AU19: =SUM(AU17:AU18) -> 0
