Workbook

Sheet eff all value

Sheet eff all value (2)

Sheet eff all value (3)

Sheet eff all value (4)

Sheet Report1
A3: PAPER MACHINE 16 DAILY REPORT 1
A6: Date | B6: Grade | C6: GSM | D6: Speed yankee (mpm) | E6: Speed reel (mpm) | F6: Creep ( % ) | G6: Real Eff PM ( % ) | H6: Real Eff PM vs Target (%) | I6: Real Eff FG vs Real Eff PM (%) | J6: Eff FG vs Target (%) | L6: Kapasitas Target (ton) | N6: Kapasitas Teori Real (ton) | P6: PM PROD Timbangan (TON) | R6: FINSHED GOODS (TON) | T6: STEAM (TON) | Z6: POWER (kWh) | AF6: POWER WPL (kWh) | AL6: Kapasitas Running (ton) | AN6: Eff FG vs Target Running(%)
T7: CONSUMPTION | V7: /TON PM. | X7: /TON FG. | Z7: CONSUMPTION | AB7: /TON PM | AD7: /TON FG | AF7: CONSUMPTION | AH7: /TON PM | AJ7: /TON FG
J8: TODAY | K8: TODATE | L8: TODAY | M8: TODATE | N8: TODAY | O8: TODATE | P8: TODAY | Q8: TODATE | R8: TODAY | S8: TODATE | T8: TODAY | U8: TODATE | V8: TODAY | W8: TODATE | X8: TODAY | Y8: TODATE | Z8: TODAY | AA8: TODATE | AB8: TODAY | AC8: TODATE | AD8: TODAY | AE8: TODATE | AF8: TODAY | AG8: TODATE | AH8: TODAY | AI8: TODATE | AJ8: TODAY | AK8: TODATE | AL8: TODAY | AM8: TODATE | AN8: TODAY | AO8: TODATE
A9: 46113 | B9: Napkin | C9: 12 | D9: =+'1'!F42 -> 1393.7121 | E9: =+'1'!G42 -> 1142.8439 | F9: =1-(E9/D9) -> 0.18 | G9: =+P9/N9 -> 0.69173976 | H9: =+P9/L9 -> 0.68863292 | I9: =+R9/P9 -> 0.9656732 | J9: =+R9/L9 -> 0.66499436 | K9: =+S9/M9 -> 0.66499436 | L9: =+Efficiency1!K6 -> 55.544832 | M9: =L9 -> 55.544832 | N9: =+Efficiency1!C6 -> 55.295361 | O9: =N9 -> 55.295361 | P9: ='1'!I38 -> 38.25 | Q9: =P9 -> 38.25 | R9: ='1'!I40 -> 36.937 | S9: =R9 -> 36.937 | T9: 121.9 | U9: =T9 -> 121.9 | V9: =T9/(P9) -> 3.1869281 | W9: =U9/(Q9) -> 3.1869281 | X9: =IF(AND(R9>0,T9>0),T9/(R9),0) -> 3.3002139 | Y9: =IF(AND(S9>0,U9>0),U9/(S9),0) -> 3.3002139 | Z9: ='1'!I46 -> 49061.086 | AA9: =Z9 -> 49061.086 | AB9: =IF(AND(L9>0,Z9>0),(Z9/(P9*1000)*1000),0) -> 1282.6428 | AC9: =IF(AND(M9>0,AA9>0),(AA9/(Q9*1000)*1000),0) -> 1282.6428 | AD9: =IF(AND(R9>0,Z9>0),(Z9/(R9*1000)*1000),0) -> 1328.2369 | AE9: =IF(AND(S9>0,AA9>0),(AA9/(S9*1000)*1000),0) -> 1328.2369 | AF9: =+Listrik!AQ8 -> 0 | AG9: =AF9 -> 0 | AH9: =IF(AND(L9>0,AF9>0),(AF9/(P9*1000)*1000),0) -> 0 | AI9: =IF(AND(M9>0,AG9>0),(AG9/(Q9*1000)*1000),0) -> 0 | AJ9: =IF(AND(R9>0,AF9>0),(AF9/(R9*1000)*1000),0) -> 0 | AK9: =IF(AND(S9>0,AG9>0),(AG9/(S9*1000)*1000),0) -> 0 | AL9: =+Efficiency2!K6 -> 55.544832 | AM9: =AL9 -> 55.544832 | AN9: =+R9/AL9 -> 0.66499436 | AO9: =+S9/AM9 -> 0.66499436
A10: =A9+1 -> 46114 | B10: Napkin | C10: 12 | D10: =+'2'!F42 -> 1400 | E10: =+'2'!G42 -> 1148 | F10: =1-(E10/D10) -> 0.18 | G10: =+P10/N10 -> 0.94487638 | H10: =+P10/L10 -> 0.94487638 | I10: =+R10/P10 -> 1.0229027 | J10: =+R10/L10 -> 0.96651656 | K10: =+S10/M10 -> 0.81575546 | L10: =+Efficiency1!K11 -> 55.544832 | M10: =M9+L10 -> 111.08966 | N10: =+Efficiency1!C11 -> 55.544832 | O10: =O9+N10 -> 110.84019 | P10: ='2'!I38 -> 52.483 | Q10: =Q9+P10 -> 90.733 | R10: ='2'!I40 -> 53.685 | S10: =S9+R10 -> 90.622 | T10: 126.1 | U10: =T10+U9 -> 248 | V10: =T10/(P10) -> 2.4026828 | W10: =U10/(Q10) -> 2.7332944 | X10: =IF(AND(R10>0,T10>0),T10/(R10),0) -> 2.348887 | Y10: =IF(AND(S10>0,U10>0),U10/(S10),0) -> 2.7366423 | Z10: ='2'!I46 -> 56751.539 | AA10: =Z10+AA9 -> 105812.63 | AB10: =IF(AND(L10>0,Z10>0),(Z10/(P10*1000)*1000),0) -> 1081.3318 | AC10: =IF(AND(M10>0,AA10>0),(AA10/(Q10*1000)*1000),0) -> 1166.1978 | AD10: =IF(AND(R10>0,Z10>0),(Z10/(R10*1000)*1000),0) -> 1057.121 | AE10: =IF(AND(S10>0,AA10>0),(AA10/(S10*1000)*1000),0) -> 1167.6262 | AF10: =+Listrik!AQ9 -> 0 | AG10: =AF10+AG9 -> 0 | AH10: =IF(AND(L10>0,AF10>0),(AF10/(P10*1000)*1000),0) -> 0 | AI10: =IF(AND(M10>0,AG10>0),(AG10/(Q10*1000)*1000),0) -> 0 | AJ10: =IF(AND(R10>0,AF10>0),(AF10/(R10*1000)*1000),0) -> 0 | AK10: =IF(AND(S10>0,AG10>0),(AG10/(S10*1000)*1000),0) -> 0 | AL10: =+Efficiency2!K11 -> 55.544832 | AM10: =AM9+AL10 -> 111.08966 | AN10: =+R10/AL10 -> 0.96651656 | AO10: =+S10/AM10 -> 0.81575546
A11: =A10+1 -> 46115 | B11: Napkin | C11: 12/11 | D11: =+'3'!F42 -> 1400 | E11: =+'3'!G42 -> 1148 | F11: =1-(E11/D11) -> 0.18 | G11: =+P11/N11 -> 0.98510456 | H11: =+P11/L11 -> 0.98510456 | I11: =+R11/P11 -> 1.1140426 | J11: =+R11/L11 -> 1.0974484 | K11: =+S11/M11 -> 0.90459365 | L11: =+SUM(Efficiency1!K16:K17) -> 51.173248 | M11: =M10+L11 -> 162.26291 | N11: =+SUM(Efficiency1!C16:C17) -> 51.173248 | O11: =O10+N11 -> 162.01344 | P11: ='3'!I38 -> 50.411 | Q11: =Q10+P11 -> 141.144 | R11: ='3'!I40 -> 56.16 | S11: =S10+R11 -> 146.782 | T11: 126.8 | U11: =T11+U10 -> 374.8 | V11: =T11/(P11) -> 2.515324 | W11: =U11/(Q11) -> 2.6554441 | X11: =IF(AND(R11>0,T11>0),T11/(R11),0) -> 2.2578348 | Y11: =IF(AND(S11>0,U11>0),U11/(S11),0) -> 2.5534466 | Z11: ='3'!I46 -> 54153.334 | AA11: =Z11+AA10 -> 159965.96 | AB11: =IF(AND(L11>0,Z11>0),(Z11/(P11*1000)*1000),0) -> 1074.2365 | AC11: =IF(AND(M11>0,AA11>0),(AA11/(Q11*1000)*1000),0) -> 1133.3529 | AD11: =IF(AND(R11>0,Z11>0),(Z11/(R11*1000)*1000),0) -> 964.26876 | AE11: =IF(AND(S11>0,AA11>0),(AA11/(S11*1000)*1000),0) -> 1089.82 | AF11: =+Listrik!AQ10 -> 0 | AG11: =AF11+AG10 -> 0 | AH11: =IF(AND(L11>0,AF11>0),(AF11/(P11*1000)*1000),0) -> 0 | AI11: =IF(AND(M11>0,AG11>0),(AG11/(Q11*1000)*1000),0) -> 0 | AJ11: =IF(AND(R11>0,AF11>0),(AF11/(R11*1000)*1000),0) -> 0 | AK11: =IF(AND(S11>0,AG11>0),(AG11/(S11*1000)*1000),0) -> 0 | AL11: =+SUM(Efficiency2!K16:K17) -> 51.173248 | AM11: =AM10+AL11 -> 162.26291 | AN11: =+R11/AL11 -> 1.0974484 | AO11: =+S11/AM11 -> 0.90459365
A12: =A11+1 -> 46116 | B12: Napkin | C12: 11/16,5/17 | D12: =+'4'!F42 -> 1160.3333 | E12: =+'4'!G42 -> 968.78333 | F12: =1-(E12/D12) -> 0.16508187 | G12: =+P12/N12 -> 0.94752367 | H12: =+P12/L12 -> 0.94752367 | I12: =+R12/P12 -> 0.90292706 | J12: =+R12/L12 -> 0.85554476 | K12: =+S12/M12 -> 0.89247977 | L12: =+SUM(Efficiency1!K20:K23) -> 53.218723 | M12: =M11+L12 -> 215.48164 | N12: =+SUM(Efficiency1!C20:C23) -> 53.218723 | O12: =O11+N12 -> 215.23216 | P12: ='4'!I38 -> 50.426 | Q12: =Q11+P12 -> 191.57 | R12: ='4'!I40 -> 45.531 | S12: =S11+R12 -> 192.313 | T12: 123 | U12: =T12+U11 -> 497.8 | V12: =T12/(P12) -> 2.4392179 | W12: =U12/(Q12) -> 2.598528 | X12: =IF(AND(R12>0,T12>0),T12/(R12),0) -> 2.7014562 | Y12: =IF(AND(S12>0,U12>0),U12/(S12),0) -> 2.5884886 | Z12: ='4'!I46 -> 45869.034 | AA12: =Z12+AA11 -> 205834.99 | AB12: =IF(AND(L12>0,Z12>0),(Z12/(P12*1000)*1000),0) -> 909.63062 | AC12: =IF(AND(M12>0,AA12>0),(AA12/(Q12*1000)*1000),0) -> 1074.4636 | AD12: =IF(AND(R12>0,Z12>0),(Z12/(R12*1000)*1000),0) -> 1007.4243 | AE12: =IF(AND(S12>0,AA12>0),(AA12/(S12*1000)*1000),0) -> 1070.3124 | AF12: =+Listrik!AQ11 -> 0 | AG12: =AF12+AG11 -> 0 | AH12: =IF(AND(L12>0,AF12>0),(AF12/(P12*1000)*1000),0) -> 0 | AI12: =IF(AND(M12>0,AG12>0),(AG12/(Q12*1000)*1000),0) -> 0 | AJ12: =IF(AND(R12>0,AF12>0),(AF12/(R12*1000)*1000),0) -> 0 | AK12: =IF(AND(S12>0,AG12>0),(AG12/(S12*1000)*1000),0) -> 0 | AL12: =+SUM(Efficiency2!K20:K23) -> 53.218723 | AM12: =AM11+AL12 -> 215.48164 | AN12: =+R12/AL12 -> 0.85554476 | AO12: =+S12/AM12 -> 0.89247977
A13: =A12+1 -> 46117 | B13: Napkin | C13: 17 | D13: =+'5'!F42 -> 980 | E13: =+'5'!G42 -> 833 | F13: =1-(E13/D13) -> 0.15 | G13: =+P13/N13 -> 0.87618562 | H13: =+P13/L13 -> 0.87618562 | I13: =+R13/P13 -> 0.77002964 | J13: =+R13/L13 -> 0.6746889 | K13: =+S13/M13 -> 0.84815678 | L13: =+Efficiency1!K25 -> 55.057968 | M13: =M12+L13 -> 270.5396 | N13: =+Efficiency1!C25 -> 55.057968 | O13: =O12+N13 -> 270.29013 | P13: ='5'!I38 -> 48.241 | Q13: =Q12+P13 -> 239.811 | R13: ='5'!I40 -> 37.147 | S13: =S12+R13 -> 229.46 | T13: 117.8 | U13: =T13+U12 -> 615.6 | V13: =T13/(P13) -> 2.4419063 | W13: =U13/(Q13) -> 2.5670215 | X13: =IF(AND(R13>0,T13>0),T13/(R13),0) -> 3.1711848 | Y13: =IF(AND(S13>0,U13>0),U13/(S13),0) -> 2.6828205 | Z13: ='5'!I46 -> 44000.883 | AA13: =Z13+AA12 -> 249835.88 | AB13: =IF(AND(L13>0,Z13>0),(Z13/(P13*1000)*1000),0) -> 912.10553 | AC13: =IF(AND(M13>0,AA13>0),(AA13/(Q13*1000)*1000),0) -> 1041.8032 | AD13: =IF(AND(R13>0,Z13>0),(Z13/(R13*1000)*1000),0) -> 1184.507 | AE13: =IF(AND(S13>0,AA13>0),(AA13/(S13*1000)*1000),0) -> 1088.7992 | AF13: =+Listrik!AQ12 -> 0 | AG13: =AF13+AG12 -> 0 | AH13: =IF(AND(L13>0,AF13>0),(AF13/(P13*1000)*1000),0) -> 0 | AI13: =IF(AND(M13>0,AG13>0),(AG13/(Q13*1000)*1000),0) -> 0 | AJ13: =IF(AND(R13>0,AF13>0),(AF13/(R13*1000)*1000),0) -> 0 | AK13: =IF(AND(S13>0,AG13>0),(AG13/(S13*1000)*1000),0) -> 0 | AL13: =+Efficiency2!K25 -> 55.057968 | AM13: =AM12+AL13 -> 270.5396 | AN13: =+R13/AL13 -> 0.6746889 | AO13: =+S13/AM13 -> 0.84815678
A14: =A13+1 -> 46118 | B14: Napkin/Towel | C14: 17/17,5/17 | D14: =+'6'!F42 -> 980 | E14: =+'6'!G42 -> 814.7509 | F14: =1-(E14/D14) -> 0.16862153 | G14: =+P14/N14 -> 0.96634942 | H14: =+P14/L14 -> 0.96634942 | I14: =+R14/P14 -> 0.78915038 | J14: =+R14/L14 -> 0.76259501 | K14: =+S14/M14 -> 0.83349853 | L14: =+SUM(Efficiency1!K30:K32) -> 55.93008 | M14: =M13+L14 -> 326.46968 | N14: =+SUM(Efficiency1!C30:C32) -> 55.93008 | O14: =O13+N14 -> 326.22021 | P14: ='6'!I38 -> 54.048 | Q14: =Q13+P14 -> 293.859 | R14: ='6'!I40 -> 42.652 | S14: =S13+R14 -> 272.112 | T14: 119.1 | U14: =T14+U13 -> 734.7 | V14: =T14/(P14) -> 2.2035968 | W14: =U14/(Q14) -> 2.5001787 | X14: =IF(AND(R14>0,T14>0),T14/(R14),0) -> 2.7923661 | Y14: =IF(AND(S14>0,U14>0),U14/(S14),0) -> 2.6999912 | Z14: ='6'!I46 -> 43195.426 | AA14: =Z14+AA13 -> 293031.3 | AB14: =IF(AND(L14>0,Z14>0),(Z14/(P14*1000)*1000),0) -> 799.20489 | AC14: =IF(AND(M14>0,AA14>0),(AA14/(Q14*1000)*1000),0) -> 997.18335 | AD14: =IF(AND(R14>0,Z14>0),(Z14/(R14*1000)*1000),0) -> 1012.7409 | AE14: =IF(AND(S14>0,AA14>0),(AA14/(S14*1000)*1000),0) -> 1076.8775 | AF14: =+Listrik!AQ13 -> 0 | AG14: =AF14+AG13 -> 0 | AH14: =IF(AND(L14>0,AF14>0),(AF14/(P14*1000)*1000),0) -> 0 | AI14: =IF(AND(M14>0,AG14>0),(AG14/(Q14*1000)*1000),0) -> 0 | AJ14: =IF(AND(R14>0,AF14>0),(AF14/(R14*1000)*1000),0) -> 0 | AK14: =IF(AND(S14>0,AG14>0),(AG14/(S14*1000)*1000),0) -> 0 | AL14: =+SUM(Efficiency2!K30:K32) -> 55.93008 | AM14: =AM13+AL14 -> 326.46968 | AN14: =+R14/AL14 -> 0.76259501 | AO14: =+S14/AM14 -> 0.83349853
A15: =A14+1 -> 46119 | B15: Towel | C15: 17 | D15: =+'7'!F42 -> 980 | E15: =+'7'!G42 -> 784 | F15: =1-(E15/D15) -> 0.2 | G15: =+P15/N15 -> 0.97626476 | H15: =+P15/L15 -> 0.97626476 | I15: =+R15/P15 -> 1.1492099 | J15: =+R15/L15 -> 1.1219331 | K15: =+S15/M15 -> 0.87426578 | L15: =+Efficiency1!K34 -> 53.738496 | M15: =M14+L15 -> 380.20818 | N15: =+Efficiency1!C34 -> 53.738496 | O15: =O14+N15 -> 379.95871 | P15: ='7'!I38 -> 52.463 | Q15: =Q14+P15 -> 346.322 | R15: ='7'!I40 -> 60.291 | S15: =S14+R15 -> 332.403 | T15: 120.3 | U15: =T15+U14 -> 855 | V15: =T15/(P15) -> 2.2930446 | W15: =U15/(Q15) -> 2.4688007 | X15: =IF(AND(R15>0,T15>0),T15/(R15),0) -> 1.9953227 | Y15: =IF(AND(S15>0,U15>0),U15/(S15),0) -> 2.572179 | Z15: ='7'!I46 -> 49844.235 | AA15: =Z15+AA14 -> 342875.54 | AB15: =IF(AND(L15>0,Z15>0),(Z15/(P15*1000)*1000),0) -> 950.08359 | AC15: =IF(AND(M15>0,AA15>0),(AA15/(Q15*1000)*1000),0) -> 990.04838 | AD15: =IF(AND(R15>0,Z15>0),(Z15/(R15*1000)*1000),0) -> 826.72763 | AE15: =IF(AND(S15>0,AA15>0),(AA15/(S15*1000)*1000),0) -> 1031.5055 | AF15: =+Listrik!AQ14 -> 0 | AG15: =AF15+AG14 -> 0 | AH15: =IF(AND(L15>0,AF15>0),(AF15/(P15*1000)*1000),0) -> 0 | AI15: =IF(AND(M15>0,AG15>0),(AG15/(Q15*1000)*1000),0) -> 0 | AJ15: =IF(AND(R15>0,AF15>0),(AF15/(R15*1000)*1000),0) -> 0 | AK15: =IF(AND(S15>0,AG15>0),(AG15/(S15*1000)*1000),0) -> 0 | AL15: =+Efficiency2!K34 -> 53.738496 | AM15: =AM14+AL15 -> 380.20818 | AN15: =+R15/AL15 -> 1.1219331 | AO15: =+S15/AM15 -> 0.87426578
A16: =A15+1 -> 46120 | B16: Towel | C16: 17 | D16: =+'8'!F42 -> 980 | E16: =+'8'!G42 -> 774.2 | F16: =1-(E16/D16) -> 0.21 | G16: =+P16/N16 -> 0.91313273 | H16: =+P16/L16 -> 0.90171857 | I16: =+R16/P16 -> 0.95466083 | J16: =+R16/L16 -> 0.86083541 | K16: =+S16/M16 -> 0.87260261 | L16: =+Efficiency1!K38 -> 53.738496 | M16: =M15+L16 -> 433.94667 | N16: =+Efficiency1!C38 -> 53.066765 | O16: =O15+N16 -> 433.02547 | P16: ='8'!I38 -> 48.457 | Q16: =Q15+P16 -> 394.779 | R16: ='8'!I40 -> 46.26 | S16: =S15+R16 -> 378.663 | T16: 112 | U16: =T16+U15 -> 967 | V16: =T16/(P16) -> 2.3113276 | W16: =U16/(Q16) -> 2.4494717 | X16: =IF(AND(R16>0,T16>0),T16/(R16),0) -> 2.4210981 | Y16: =IF(AND(S16>0,U16>0),U16/(S16),0) -> 2.5537219 | Z16: ='8'!I46 -> 45712.115 | AA16: =Z16+AA15 -> 388587.65 | AB16: =IF(AND(L16>0,Z16>0),(Z16/(P16*1000)*1000),0) -> 943.3542 | AC16: =IF(AND(M16>0,AA16>0),(AA16/(Q16*1000)*1000),0) -> 984.31692 | AD16: =IF(AND(R16>0,Z16>0),(Z16/(R16*1000)*1000),0) -> 988.15639 | AE16: =IF(AND(S16>0,AA16>0),(AA16/(S16*1000)*1000),0) -> 1026.2097 | AF16: =+Listrik!AQ15 -> 0 | AG16: =AF16+AG15 -> 0 | AH16: =IF(AND(L16>0,AF16>0),(AF16/(P16*1000)*1000),0) -> 0 | AI16: =IF(AND(M16>0,AG16>0),(AG16/(Q16*1000)*1000),0) -> 0 | AJ16: =IF(AND(R16>0,AF16>0),(AF16/(R16*1000)*1000),0) -> 0 | AK16: =IF(AND(S16>0,AG16>0),(AG16/(S16*1000)*1000),0) -> 0 | AL16: =+Efficiency2!K38 -> 53.738496 | AM16: =AM15+AL16 -> 433.94667 | AN16: =+R16/AL16 -> 0.86083541 | AO16: =+S16/AM16 -> 0.87260261
A17: =A16+1 -> 46121 | B17: Towel | C17: 17 | D17: =+'9'!F42 -> 980 | E17: =+'9'!G42 -> 774.2 | F17: =1-(E17/D17) -> 0.21 | G17: =+P17/N17 -> 1.0270458 | H17: =+P17/L17 -> 1.0142078 | I17: =+R17/P17 -> 0.90099446 | J17: =+R17/L17 -> 0.91379558 | K17: =+S17/M17 -> 0.8771417 | L17: =+Efficiency1!K43 -> 53.738496 | M17: =M16+L17 -> 487.68517 | N17: =+Efficiency1!C43 -> 53.066765 | O17: =O16+N17 -> 486.09224 | P17: ='9'!I38 -> 54.502 | Q17: =Q16+P17 -> 449.281 | R17: ='9'!I40 -> 49.106 | S17: =S16+R17 -> 427.769 | T17: 127.6 | U17: =T17+U16 -> 1094.6 | V17: =T17/(P17) -> 2.3411985 | W17: =U17/(Q17) -> 2.4363372 | X17: =IF(AND(R17>0,T17>0),T17/(R17),0) -> 2.5984605 | Y17: =IF(AND(S17>0,U17>0),U17/(S17),0) -> 2.5588577 | Z17: ='9'!I46 -> 48950.709 | AA17: =Z17+AA16 -> 437538.36 | AB17: =IF(AND(L17>0,Z17>0),(Z17/(P17*1000)*1000),0) -> 898.14519 | AC17: =IF(AND(M17>0,AA17>0),(AA17/(Q17*1000)*1000),0) -> 973.86348 | AD17: =IF(AND(R17>0,Z17>0),(Z17/(R17*1000)*1000),0) -> 996.83764 | AE17: =IF(AND(S17>0,AA17>0),(AA17/(S17*1000)*1000),0) -> 1022.8379 | AF17: =+Listrik!AQ16 -> 0 | AG17: =AF17+AG16 -> 0 | AH17: =IF(AND(L17>0,AF17>0),(AF17/(P17*1000)*1000),0) -> 0 | AI17: =IF(AND(M17>0,AG17>0),(AG17/(Q17*1000)*1000),0) -> 0 | AJ17: =IF(AND(R17>0,AF17>0),(AF17/(R17*1000)*1000),0) -> 0 | AK17: =IF(AND(S17>0,AG17>0),(AG17/(S17*1000)*1000),0) -> 0 | AL17: =+Efficiency2!K43 -> 53.738496 | AM17: =AM16+AL17 -> 487.68517 | AN17: =+R17/AL17 -> 0.91379558 | AO17: =+S17/AM17 -> 0.8771417
A18: =A17+1 -> 46122 | B18: Towel | C18: 17 | D18: =+'10'!F42 -> 980 | E18: =+'10'!G42 -> 774.2 | F18: =1-(E18/D18) -> 0.21 | G18: =+P18/N18 -> 1.0068637 | H18: =+P18/L18 -> 0.99427792 | I18: =+R18/P18 -> 1.0644944 | J18: =+R18/L18 -> 1.0584033 | K18: =+S18/M18 -> 0.89513265 | L18: =+Efficiency1!K48 -> 53.738496 | M18: =M17+L18 -> 541.42367 | N18: =+Efficiency1!C48 -> 53.066765 | O18: =O17+N18 -> 539.159 | P18: ='10'!I38 -> 53.431 | Q18: =Q17+P18 -> 502.712 | R18: ='10'!I40 -> 56.877 | S18: =S17+R18 -> 484.646 | T18: 127.2 | U18: =T18+U17 -> 1221.8 | V18: =T18/(P18) -> 2.3806405 | W18: =U18/(Q18) -> 2.4304174 | X18: =IF(AND(R18>0,T18>0),T18/(R18),0) -> 2.2364049 | Y18: =IF(AND(S18>0,U18>0),U18/(S18),0) -> 2.5210153 | Z18: ='10'!I46 -> 48563.043 | AA18: =Z18+AA17 -> 486101.4 | AB18: =IF(AND(L18>0,Z18>0),(Z18/(P18*1000)*1000),0) -> 908.89265 | AC18: =IF(AND(M18>0,AA18>0),(AA18/(Q18*1000)*1000),0) -> 966.95803 | AD18: =IF(AND(R18>0,Z18>0),(Z18/(R18*1000)*1000),0) -> 853.82568 | AE18: =IF(AND(S18>0,AA18>0),(AA18/(S18*1000)*1000),0) -> 1003.003 | AF18: =+Listrik!AQ17 -> 0 | AG18: =AF18+AG17 -> 0 | AH18: =IF(AND(L18>0,AF18>0),(AF18/(P18*1000)*1000),0) -> 0 | AI18: =IF(AND(M18>0,AG18>0),(AG18/(Q18*1000)*1000),0) -> 0 | AJ18: =IF(AND(R18>0,AF18>0),(AF18/(R18*1000)*1000),0) -> 0 | AK18: =IF(AND(S18>0,AG18>0),(AG18/(S18*1000)*1000),0) -> 0 | AL18: =+Efficiency2!K48 -> 53.738496 | AM18: =AM17+AL18 -> 541.42367 | AN18: =+R18/AL18 -> 1.0584033 | AO18: =+S18/AM18 -> 0.89513265
A19: =A18+1 -> 46123 | B19: Towel/Napkin | C19: 17/15,5 | D19: =+'11'!F42 -> 1010.8681 | E19: =+'11'!G42 -> 816.05903 | F19: =1-(E19/D19) -> 0.19271459 | G19: =+P19/N19 -> 0.95324701 | H19: =+P19/L19 -> 0.95324701 | I19: =+R19/P19 -> 0.85254175 | J19: =+R19/L19 -> 0.81268287 | K19: =+S19/M19 -> 0.88767526 | L19: =+SUM(Efficiency1!K52:K53) -> 53.84019 | M19: =M18+L19 -> 595.26386 | N19: =+SUM(Efficiency1!C52:C53) -> 53.84019 | O19: =O18+N19 -> 592.99919 | P19: ='11'!I38 -> 51.323 | Q19: =Q18+P19 -> 554.035 | R19: ='11'!I40 -> 43.755 | S19: =S18+R19 -> 528.401 | T19: 128.2 | U19: =T19+U18 -> 1350 | V19: =T19/(P19) -> 2.4979054 | W19: =U19/(Q19) -> 2.4366692 | X19: =IF(AND(R19>0,T19>0),T19/(R19),0) -> 2.9299509 | Y19: =IF(AND(S19>0,U19>0),U19/(S19),0) -> 2.5548778 | Z19: ='11'!I46 -> 46365.074 | AA19: =Z19+AA18 -> 532466.48 | AB19: =IF(AND(L19>0,Z19>0),(Z19/(P19*1000)*1000),0) -> 903.39758 | AC19: =IF(AND(M19>0,AA19>0),(AA19/(Q19*1000)*1000),0) -> 961.07011 | AD19: =IF(AND(R19>0,Z19>0),(Z19/(R19*1000)*1000),0) -> 1059.652 | AE19: =IF(AND(S19>0,AA19>0),(AA19/(S19*1000)*1000),0) -> 1007.6939 | AF19: =+Listrik!AQ18 -> 0 | AG19: =AF19+AG18 -> 0 | AH19: =IF(AND(L19>0,AF19>0),(AF19/(P19*1000)*1000),0) -> 0 | AI19: =IF(AND(M19>0,AG19>0),(AG19/(Q19*1000)*1000),0) -> 0 | AJ19: =IF(AND(R19>0,AF19>0),(AF19/(R19*1000)*1000),0) -> 0 | AK19: =IF(AND(S19>0,AG19>0),(AG19/(S19*1000)*1000),0) -> 0 | AL19: =+SUM(Efficiency2!K52:K53) -> 53.84019 | AM19: =AM18+AL19 -> 595.26386 | AN19: =+R19/AL19 -> 0.81268287 | AO19: =+S19/AM19 -> 0.88767526
A20: =A19+1 -> 46124 | B20: Napkin | C20: 15,5/11 | D20: =+'12'!F42 -> 1177.0526 | E20: =+'12'!G42 -> 936.79368 | F20: =1-(E20/D20) -> 0.20411912 | G20: =+P20/N20 -> 0.97544492 | H20: =+P20/L20 -> 0.97544492 | I20: =+R20/P20 -> 1.0219334 | J20: =+R20/L20 -> 0.99683971 | K20: =+S20/M20 -> 0.89604845 | L20: =+SUM(Efficiency1!K56:K57) -> 49.45128 | M20: =M19+L20 -> 644.71514 | N20: =+SUM(Efficiency1!C56:C57) -> 49.45128 | O20: =O19+N20 -> 642.45047 | P20: ='12'!I38 -> 48.237 | Q20: =Q19+P20 -> 602.272 | R20: ='12'!I40 -> 49.295 | S20: =S19+R20 -> 577.696 | T20: 129.6 | U20: =T20+U19 -> 1479.6 | V20: =T20/(P20) -> 2.6867342 | W20: =U20/(Q20) -> 2.4566973 | X20: =IF(AND(R20>0,T20>0),T20/(R20),0) -> 2.6290699 | Y20: =IF(AND(S20>0,U20>0),U20/(S20),0) -> 2.5612087 | Z20: ='12'!I46 -> 51463.622 | AA20: =Z20+AA19 -> 583930.1 | AB20: =IF(AND(L20>0,Z20>0),(Z20/(P20*1000)*1000),0) -> 1066.891 | AC20: =IF(AND(M20>0,AA20>0),(AA20/(Q20*1000)*1000),0) -> 969.54549 | AD20: =IF(AND(R20>0,Z20>0),(Z20/(R20*1000)*1000),0) -> 1043.9927 | AE20: =IF(AND(S20>0,AA20>0),(AA20/(S20*1000)*1000),0) -> 1010.7913 | AF20: =+Listrik!AQ19 -> 0 | AG20: =AF20+AG19 -> 0 | AH20: =IF(AND(L20>0,AF20>0),(AF20/(P20*1000)*1000),0) -> 0 | AI20: =IF(AND(M20>0,AG20>0),(AG20/(Q20*1000)*1000),0) -> 0 | AJ20: =IF(AND(R20>0,AF20>0),(AF20/(R20*1000)*1000),0) -> 0 | AK20: =IF(AND(S20>0,AG20>0),(AG20/(S20*1000)*1000),0) -> 0 | AL20: =+SUM(Efficiency2!K56:K57) -> 49.45128 | AM20: =AM19+AL20 -> 644.71514 | AN20: =+R20/AL20 -> 0.99683971 | AO20: =+S20/AM20 -> 0.89604845
A21: =A20+1 -> 46125 | B21: Napkin | C21: 11 | D21: =+'13'!F42 -> 1221 | E21: =+'13'!G42 -> 976.8 | F21: =1-(E21/D21) -> 0.2 | G21: =+P21/N21 -> 0.62705674 | H21: =+P21/L21 -> 0.55885859 | I21: =+R21/P21 -> 0.66874034 | J21: =+R21/L21 -> 0.37373128 | K21: =+S21/M21 -> 0.85942821 | L21: =+Efficiency1!K62 -> 48.609792 | M21: =M20+L21 -> 693.32493 | N21: =+Efficiency1!C62 -> 43.323034 | O21: =O20+N21 -> 685.77351 | P21: ='13'!I38 -> 27.166 | Q21: =Q20+P21 -> 629.438 | R21: ='13'!I40 -> 18.167 | S21: =S20+R21 -> 595.863 | T21: 82.8 | U21: =T21+U20 -> 1562.4 | V21: =T21/(P21) -> 3.0479276 | W21: =U21/(Q21) -> 2.4822143 | X21: =IF(AND(R21>0,T21>0),T21/(R21),0) -> 4.5577145 | Y21: =IF(AND(S21>0,U21>0),U21/(S21),0) -> 2.6220792 | Z21: ='13'!I46 -> 36531.48 | AA21: =Z21+AA20 -> 620461.58 | AB21: =IF(AND(L21>0,Z21>0),(Z21/(P21*1000)*1000),0) -> 1344.7501 | AC21: =IF(AND(M21>0,AA21>0),(AA21/(Q21*1000)*1000),0) -> 985.73899 | AD21: =IF(AND(R21>0,Z21>0),(Z21/(R21*1000)*1000),0) -> 2010.8703 | AE21: =IF(AND(S21>0,AA21>0),(AA21/(S21*1000)*1000),0) -> 1041.2823 | AF21: =+Listrik!AQ20 -> 0 | AG21: =AF21+AG20 -> 0 | AH21: =IF(AND(L21>0,AF21>0),(AF21/(P21*1000)*1000),0) -> 0 | AI21: =IF(AND(M21>0,AG21>0),(AG21/(Q21*1000)*1000),0) -> 0 | AJ21: =IF(AND(R21>0,AF21>0),(AF21/(R21*1000)*1000),0) -> 0 | AK21: =IF(AND(S21>0,AG21>0),(AG21/(S21*1000)*1000),0) -> 0 | AL21: =+Efficiency2!K62 -> 34.972045 | AM21: =AM20+AL21 -> 679.68718 | AN21: =+R21/AL21 -> 0.51947206 | AO21: =+S21/AM21 -> 0.87667241
A22: =A21+1 -> 46126 | B22: Napkin/Toilet | C22: 11/14/16/18 | D22: =+'14'!F42 -> 1075.3125 | E22: =+'14'!G42 -> 807.19271 | F22: =1-(E22/D22) -> 0.24934128 | G22: =+P22/N22 -> 0.96735614 | H22: =+P22/L22 -> 0.9621501 | I22: =+R22/P22 -> 1.047739 | J22: =+R22/L22 -> 1.0080822 | K22: =+S22/M22 -> 0.87009993 | L22: =+SUM(Efficiency1!K67:K70) -> 53.622611 | M22: =M21+L22 -> 746.94754 | N22: =+SUM(Efficiency1!C67:C70) -> 53.334029 | O22: =O21+N22 -> 739.10753 | P22: ='14'!I38 -> 51.593 | Q22: =Q21+P22 -> 681.031 | R22: ='14'!I40 -> 54.056 | S22: =S21+R22 -> 649.919 | T22: 123.4 | U22: =T22+U21 -> 1685.8 | V22: =T22/(P22) -> 2.3917973 | W22: =U22/(Q22) -> 2.4753646 | X22: =IF(AND(R22>0,T22>0),T22/(R22),0) -> 2.2828178 | Y22: =IF(AND(S22>0,U22>0),U22/(S22),0) -> 2.5938617 | Z22: ='14'!I46 -> 39509.715 | AA22: =Z22+AA21 -> 659971.29 | AB22: =IF(AND(L22>0,Z22>0),(Z22/(P22*1000)*1000),0) -> 765.79603 | AC22: =IF(AND(M22>0,AA22>0),(AA22/(Q22*1000)*1000),0) -> 969.07673 | AD22: =IF(AND(R22>0,Z22>0),(Z22/(R22*1000)*1000),0) -> 730.90341 | AE22: =IF(AND(S22>0,AA22>0),(AA22/(S22*1000)*1000),0) -> 1015.467 | AF22: =+Listrik!AQ21 -> 0 | AG22: =AF22+AG21 -> 0 | AH22: =IF(AND(L22>0,AF22>0),(AF22/(P22*1000)*1000),0) -> 0 | AI22: =IF(AND(M22>0,AG22>0),(AG22/(Q22*1000)*1000),0) -> 0 | AJ22: =IF(AND(R22>0,AF22>0),(AF22/(R22*1000)*1000),0) -> 0 | AK22: =IF(AND(S22>0,AG22>0),(AG22/(S22*1000)*1000),0) -> 0 | AL22: =+SUM(Efficiency2!K67:K70) -> 53.622611 | AM22: =AM21+AL22 -> 733.30979 | AN22: =+R22/AL22 -> 1.0080822 | AO22: =+S22/AM22 -> 0.88628163
A23: =A22+1 -> 46127 | B23: Toilet | C23: 18/16 | D23: =+'15'!F42 -> 1139.75 | E23: =+'15'!G42 -> 854.8125 | F23: =1-(E23/D23) -> 0.25 | G23: =+P23/N23 -> 0.99540412 | H23: =+P23/L23 -> 0.99540412 | I23: =+R23/P23 -> 0.91397132 | J23: =+R23/L23 -> 0.90977082 | K23: =+S23/M23 -> 0.87285249 | L23: =+SUM(Efficiency1!K72:K73) -> 55.690949 | M23: =M22+L23 -> 802.63849 | N23: =+SUM(Efficiency1!C72:C73) -> 55.690949 | O23: =O22+N23 -> 794.79848 | P23: ='15'!I38 -> 55.435 | Q23: =Q22+P23 -> 736.466 | R23: ='15'!I40 -> 50.666 | S23: =S22+R23 -> 700.585 | T23: 125.8 | U23: =T23+U22 -> 1811.6 | V23: =T23/(P23) -> 2.2693244 | W23: =U23/(Q23) -> 2.4598556 | X23: =IF(AND(R23>0,T23>0),T23/(R23),0) -> 2.4829274 | Y23: =IF(AND(S23>0,U23>0),U23/(S23),0) -> 2.585839 | Z23: ='15'!I46 -> 40176.573 | AA23: =Z23+AA22 -> 700147.87 | AB23: =IF(AND(L23>0,Z23>0),(Z23/(P23*1000)*1000),0) -> 724.75103 | AC23: =IF(AND(M23>0,AA23>0),(AA23/(Q23*1000)*1000),0) -> 950.68594 | AD23: =IF(AND(R23>0,Z23>0),(Z23/(R23*1000)*1000),0) -> 792.96912 | AE23: =IF(AND(S23>0,AA23>0),(AA23/(S23*1000)*1000),0) -> 999.37605 | AF23: =+Listrik!AQ22 -> 0 | AG23: =AF23+AG22 -> 0 | AH23: =IF(AND(L23>0,AF23>0),(AF23/(P23*1000)*1000),0) -> 0 | AI23: =IF(AND(M23>0,AG23>0),(AG23/(Q23*1000)*1000),0) -> 0 | AJ23: =IF(AND(R23>0,AF23>0),(AF23/(R23*1000)*1000),0) -> 0 | AK23: =IF(AND(S23>0,AG23>0),(AG23/(S23*1000)*1000),0) -> 0 | AL23: =+SUM(Efficiency2!K72:K73) -> 55.690949 | AM23: =AM22+AL23 -> 789.00074 | AN23: =+R23/AL23 -> 0.90977082 | AO23: =+S23/AM23 -> 0.8879396
A24: =A23+1 -> 46128 | B24: Toilet/Facial | C24: 16/15/13 | D24: =+'16'!F42 -> 1283.3681 | E24: =+'16'!G42 -> 962.52604 | F24: =1-(E24/D24) -> 0.25 | G24: =+P24/N24 -> 0.93853484 | H24: =+P24/L24 -> 0.93522708 | I24: =+R24/P24 -> 0.81753694 | J24: =+R24/L24 -> 0.76458269 | K24: =+S24/M24 -> 0.86619277 | L24: =+SUM(Efficiency1!K76:K78) -> 52.606475 | M24: =M23+L24 -> 855.24496 | N24: =+SUM(Efficiency1!C76:C78) -> 52.42107 | O24: =O23+N24 -> 847.21955 | P24: ='16'!I38 -> 49.199 | Q24: =Q23+P24 -> 785.665 | R24: ='16'!I40 -> 40.222 | S24: =S23+R24 -> 740.807 | T24: 123.7 | U24: =T24+U23 -> 1935.3 | V24: =T24/(P24) -> 2.5142787 | W24: =U24/(Q24) -> 2.4632636 | X24: =IF(AND(R24>0,T24>0),T24/(R24),0) -> 3.0754314 | Y24: =IF(AND(S24>0,U24>0),U24/(S24),0) -> 2.6124213 | Z24: ='16'!I46 -> 46468.109 | AA24: =Z24+AA23 -> 746615.98 | AB24: =IF(AND(L24>0,Z24>0),(Z24/(P24*1000)*1000),0) -> 944.49296 | AC24: =IF(AND(M24>0,AA24>0),(AA24/(Q24*1000)*1000),0) -> 950.29813 | AD24: =IF(AND(R24>0,Z24>0),(Z24/(R24*1000)*1000),0) -> 1155.2909 | AE24: =IF(AND(S24>0,AA24>0),(AA24/(S24*1000)*1000),0) -> 1007.8414 | AF24: =+Listrik!AQ23 -> 0 | AG24: =AF24+AG23 -> 0 | AH24: =IF(AND(L24>0,AF24>0),(AF24/(P24*1000)*1000),0) -> 0 | AI24: =IF(AND(M24>0,AG24>0),(AG24/(Q24*1000)*1000),0) -> 0 | AJ24: =IF(AND(R24>0,AF24>0),(AF24/(R24*1000)*1000),0) -> 0 | AK24: =IF(AND(S24>0,AG24>0),(AG24/(S24*1000)*1000),0) -> 0 | AL24: =+SUM(Efficiency2!K76:K78) -> 52.606475 | AM24: =AM23+AL24 -> 841.60722 | AN24: =+R24/AL24 -> 0.76458269 | AO24: =+S24/AM24 -> 0.88022891
A25: =A24+1 -> 46129 | B25: Facial | C25: 13 | D25: =+'17'!F42 -> 1350 | E25: =+'17'!G42 -> 1012.5 | F25: =1-(E25/D25) -> 0.25 | G25: =+P25/N25 -> 0.93113966 | H25: =+P25/L25 -> 0.93113966 | I25: =+R25/P25 -> 0.87329729 | J25: =+R25/L25 -> 0.81316174 | K25: =+S25/M25 -> 0.86319475 | L25: =+Efficiency1!K80 -> 51.246877 | M25: =M24+L25 -> 906.49184 | N25: =+Efficiency1!C80 -> 51.246877 | O25: =O24+N25 -> 898.46643 | P25: ='17'!I38 -> 47.718 | Q25: =Q24+P25 -> 833.383 | R25: ='17'!I40 -> 41.672 | S25: =S24+R25 -> 782.479 | T25: 125.7 | U25: =T25+U24 -> 2061 | V25: =T25/(P25) -> 2.6342261 | W25: =U25/(Q25) -> 2.4730526 | X25: =IF(AND(R25>0,T25>0),T25/(R25),0) -> 3.0164139 | Y25: =IF(AND(S25>0,U25>0),U25/(S25),0) -> 2.6339365 | Z25: ='17'!I46 -> 48839.193 | AA25: =Z25+AA24 -> 795455.17 | AB25: =IF(AND(L25>0,Z25>0),(Z25/(P25*1000)*1000),0) -> 1023.4962 | AC25: =IF(AND(M25>0,AA25>0),(AA25/(Q25*1000)*1000),0) -> 954.48932 | AD25: =IF(AND(R25>0,Z25>0),(Z25/(R25*1000)*1000),0) -> 1171.9906 | AE25: =IF(AND(S25>0,AA25>0),(AA25/(S25*1000)*1000),0) -> 1016.5834 | AF25: =+Listrik!AQ24 -> 0 | AG25: =AF25+AG24 -> 0 | AH25: =IF(AND(L25>0,AF25>0),(AF25/(P25*1000)*1000),0) -> 0 | AI25: =IF(AND(M25>0,AG25>0),(AG25/(Q25*1000)*1000),0) -> 0 | AJ25: =IF(AND(R25>0,AF25>0),(AF25/(R25*1000)*1000),0) -> 0 | AK25: =IF(AND(S25>0,AG25>0),(AG25/(S25*1000)*1000),0) -> 0 | AL25: =+SUM(Efficiency2!K80) -> 51.246877 | AM25: =AM24+AL25 -> 892.85409 | AN25: =+R25/AL25 -> 0.81316174 | AO25: =+S25/AM25 -> 0.87637947
A26: =A25+1 -> 46130 | B26: Facial | C26: 13 | D26: =+'18'!F42 -> 1350 | E26: =+'18'!G42 -> 1012.5 | F26: =1-(E26/D26) -> 0.25 | G26: =+P26/N26 -> 0.97049727 | H26: =+P26/L26 -> 0.97049727 | I26: =+R26/P26 -> 1.0365918 | J26: =+R26/L26 -> 1.0060095 | K26: =+S26/M26 -> 0.8708131 | L26: =+Efficiency1!K84 -> 51.08103 | M26: =M25+L26 -> 957.57287 | N26: =+Efficiency1!C84 -> 51.08103 | O26: =O25+N26 -> 949.54746 | P26: ='18'!I38 -> 49.574 | Q26: =Q25+P26 -> 882.957 | R26: ='18'!I40 -> 51.388 | S26: =S25+R26 -> 833.867 | T26: 122.2 | U26: =T26+U25 -> 2183.2 | V26: =T26/(P26) -> 2.4650018 | W26: =U26/(Q26) -> 2.4726006 | X26: =IF(AND(R26>0,T26>0),T26/(R26),0) -> 2.3779871 | Y26: =IF(AND(S26>0,U26>0),U26/(S26),0) -> 2.6181633 | Z26: ='18'!I46 -> 44126.787 | AA26: =Z26+AA25 -> 839581.96 | AB26: =IF(AND(L26>0,Z26>0),(Z26/(P26*1000)*1000),0) -> 890.11956 | AC26: =IF(AND(M26>0,AA26>0),(AA26/(Q26*1000)*1000),0) -> 950.87525 | AD26: =IF(AND(R26>0,Z26>0),(Z26/(R26*1000)*1000),0) -> 858.69827 | AE26: =IF(AND(S26>0,AA26>0),(AA26/(S26*1000)*1000),0) -> 1006.8536 | AF26: =+Listrik!AQ25 -> 0 | AG26: =AF26+AG25 -> 0 | AH26: =IF(AND(L26>0,AF26>0),(AF26/(P26*1000)*1000),0) -> 0 | AI26: =IF(AND(M26>0,AG26>0),(AG26/(Q26*1000)*1000),0) -> 0 | AJ26: =IF(AND(R26>0,AF26>0),(AF26/(R26*1000)*1000),0) -> 0 | AK26: =IF(AND(S26>0,AG26>0),(AG26/(S26*1000)*1000),0) -> 0 | AL26: =+Efficiency2!K84 -> 51.08103 | AM26: =AM25+AL26 -> 943.93512 | AN26: =+R26/AL26 -> 1.0060095 | AO26: =+S26/AM26 -> 0.8833944
A27: =A26+1 -> 46131 | B27: Facial | C27: 13 | D27: =+'19'!F42 -> 1350 | E27: =+'19'!G42 -> 1012.5 | F27: =1-(E27/D27) -> 0.25 | G27: =+P27/N27 -> 0.96160001 | H27: =+P27/L27 -> 0.96160001 | I27: =+R27/P27 -> 1.0973636 | J27: =+R27/L27 -> 1.0552249 | K27: =+S27/M27 -> 0.88027551 | L27: =+Efficiency1!K88 -> 51.791805 | M27: =M26+L27 -> 1009.3647 | N27: =+Efficiency1!C88 -> 51.791805 | O27: =O26+N27 -> 1001.3393 | P27: ='19'!I38 -> 49.803 | Q27: =Q26+P27 -> 932.76 | R27: ='19'!I40 -> 54.652 | S27: =S26+R27 -> 888.519 | T27: 122.2 | U27: =T27+U26 -> 2305.4 | V27: =T27/(P27) -> 2.4536674 | W27: =U27/(Q27) -> 2.4715897 | X27: =IF(AND(R27>0,T27>0),T27/(R27),0) -> 2.2359657 | Y27: =IF(AND(S27>0,U27>0),U27/(S27),0) -> 2.5946547 | Z27: ='19'!I46 -> 45466.082 | AA27: =Z27+AA26 -> 885048.04 | AB27: =IF(AND(L27>0,Z27>0),(Z27/(P27*1000)*1000),0) -> 912.91853 | AC27: =IF(AND(M27>0,AA27>0),(AA27/(Q27*1000)*1000),0) -> 948.84862 | AD27: =IF(AND(R27>0,Z27>0),(Z27/(R27*1000)*1000),0) -> 831.91981 | AE27: =IF(AND(S27>0,AA27>0),(AA27/(S27*1000)*1000),0) -> 996.09354 | AF27: =+Listrik!AQ26 -> 0 | AG27: =AF27+AG26 -> 0 | AH27: =IF(AND(L27>0,AF27>0),(AF27/(P27*1000)*1000),0) -> 0 | AI27: =IF(AND(M27>0,AG27>0),(AG27/(Q27*1000)*1000),0) -> 0 | AJ27: =IF(AND(R27>0,AF27>0),(AF27/(R27*1000)*1000),0) -> 0 | AK27: =IF(AND(S27>0,AG27>0),(AG27/(S27*1000)*1000),0) -> 0 | AL27: =+Efficiency2!K88 -> 51.791805 | AM27: =AM26+AL27 -> 995.72693 | AN27: =+R27/AL27 -> 1.0552249 | AO27: =+S27/AM27 -> 0.892332
A28: =A27+1 -> 46132 | B28: Facial | C28: 13 | D28: =+'20'!F42 -> 1350 | E28: =+'20'!G42 -> 1012.5 | F28: =1-(E28/D28) -> 0.25 | G28: =+P28/N28 -> 0.97178933 | H28: =+P28/L28 -> 0.97178933 | I28: =+R28/P28 -> 0.90592264 | J28: =+R28/L28 -> 0.88036596 | K28: =+S28/M28 -> 0.88027986 | L28: =+Efficiency1!K92 -> 51.08103 | M28: =M27+L28 -> 1060.4457 | N28: =+Efficiency1!C92 -> 51.08103 | O28: =O27+N28 -> 1052.4203 | P28: ='20'!I38 -> 49.64 | Q28: =Q27+P28 -> 982.4 | R28: ='20'!I40 -> 44.97 | S28: =S27+R28 -> 933.489 | T28: 121.2 | U28: =T28+U27 -> 2426.6 | V28: =T28/(P28) -> 2.4415794 | W28: =U28/(Q28) -> 2.4700733 | X28: =IF(AND(R28>0,T28>0),T28/(R28),0) -> 2.6951301 | Y28: =IF(AND(S28>0,U28>0),U28/(S28),0) -> 2.599495 | Z28: ='20'!I46 -> 45745.382 | AA28: =Z28+AA27 -> 930793.42 | AB28: =IF(AND(L28>0,Z28>0),(Z28/(P28*1000)*1000),0) -> 921.54275 | AC28: =IF(AND(M28>0,AA28>0),(AA28/(Q28*1000)*1000),0) -> 947.46887 | AD28: =IF(AND(R28>0,Z28>0),(Z28/(R28*1000)*1000),0) -> 1017.2422 | AE28: =IF(AND(S28>0,AA28>0),(AA28/(S28*1000)*1000),0) -> 997.11236 | AF28: =+Listrik!AQ27 -> 0 | AG28: =AF28+AG27 -> 0 | AH28: =IF(AND(L28>0,AF28>0),(AF28/(P28*1000)*1000),0) -> 0 | AI28: =IF(AND(M28>0,AG28>0),(AG28/(Q28*1000)*1000),0) -> 0 | AJ28: =IF(AND(R28>0,AF28>0),(AF28/(R28*1000)*1000),0) -> 0 | AK28: =IF(AND(S28>0,AG28>0),(AG28/(S28*1000)*1000),0) -> 0 | AL28: =+Efficiency2!K92 -> 51.08103 | AM28: =AM27+AL28 -> 1046.808 | AN28: =+R28/AL28 -> 0.88036596 | AO28: =+S28/AM28 -> 0.89174809
A29: =A28+1 -> 46133 | B29: Facial | C29: 13 | D29: =+'21'!F42 -> 1350 | E29: =+'21'!G42 -> 1012.5 | F29: =1-(E29/D29) -> 0.25 | G29: =+P29/N29 -> 1.0123328 | H29: =+P29/L29 -> 1.0123328 | I29: =+R29/P29 -> 1.0016438 | J29: =+R29/L29 -> 1.0139968 | K29: =+S29/M29 -> 0.88642492 | L29: =+Efficiency1!K96 -> 51.08103 | M29: =M28+L29 -> 1111.5267 | N29: =+Efficiency1!C96 -> 51.08103 | O29: =O28+N29 -> 1103.5013 | P29: ='21'!I38 -> 51.711 | Q29: =Q28+P29 -> 1034.111 | R29: ='21'!I40 -> 51.796 | S29: =S28+R29 -> 985.285 | T29: 119 | U29: =T29+U28 -> 2545.6 | V29: =T29/(P29) -> 2.3012512 | W29: =U29/(Q29) -> 2.4616313 | X29: =IF(AND(R29>0,T29>0),T29/(R29),0) -> 2.2974747 | Y29: =IF(AND(S29>0,U29>0),U29/(S29),0) -> 2.5836179 | Z29: ='21'!I46 -> 48826.457 | AA29: =Z29+AA28 -> 979619.88 | AB29: =IF(AND(L29>0,Z29>0),(Z29/(P29*1000)*1000),0) -> 944.21799 | AC29: =IF(AND(M29>0,AA29>0),(AA29/(Q29*1000)*1000),0) -> 947.30631 | AD29: =IF(AND(R29>0,Z29>0),(Z29/(R29*1000)*1000),0) -> 942.66848 | AE29: =IF(AND(S29>0,AA29>0),(AA29/(S29*1000)*1000),0) -> 994.25027 | AF29: =+Listrik!AQ28 -> 0 | AG29: =AF29+AG28 -> 0 | AH29: =IF(AND(L29>0,AF29>0),(AF29/(P29*1000)*1000),0) -> 0 | AI29: =IF(AND(M29>0,AG29>0),(AG29/(Q29*1000)*1000),0) -> 0 | AJ29: =IF(AND(R29>0,AF29>0),(AF29/(R29*1000)*1000),0) -> 0 | AK29: =IF(AND(S29>0,AG29>0),(AG29/(S29*1000)*1000),0) -> 0 | AL29: =+Efficiency2!K96 -> 51.08103 | AM29: =AM28+AL29 -> 1097.889 | AN29: =+R29/AL29 -> 1.0139968 | AO29: =+S29/AM29 -> 0.89743591
A30: =A29+1 -> 46134 | B30: Facial | C30: 13 | D30: =+'22'!F42 -> 1350 | E30: =+'22'!G42 -> 1012.5 | F30: =1-(E30/D30) -> 0.25 | G30: =+P30/N30 -> 0.97531314 | H30: =+P30/L30 -> 0.97531314 | I30: =+R30/P30 -> 0.97996788 | J30: =+R30/L30 -> 0.95577556 | K30: =+S30/M30 -> 0.88947195 | L30: =+Efficiency1!K100 -> 51.08103 | M30: =M29+L30 -> 1162.6078 | N30: =+Efficiency1!C100 -> 51.08103 | O30: =O29+N30 -> 1154.5824 | P30: ='22'!I38 -> 49.82 | Q30: =Q29+P30 -> 1083.931 | R30: ='22'!I40 -> 48.822 | S30: =S29+R30 -> 1034.107 | T30: 119.4 | U30: =T30+U29 -> 2665 | V30: =T30/(P30) -> 2.3966279 | W30: =U30/(Q30) -> 2.4586436 | X30: =IF(AND(R30>0,T30>0),T30/(R30),0) -> 2.4456188 | Y30: =IF(AND(S30>0,U30>0),U30/(S30),0) -> 2.5771028 | Z30: ='22'!I46 -> 44440.815 | AA30: =Z30+AA29 -> 1024060.7 | AB30: =IF(AND(L30>0,Z30>0),(Z30/(P30*1000)*1000),0) -> 892.02759 | AC30: =IF(AND(M30>0,AA30>0),(AA30/(Q30*1000)*1000),0) -> 944.76557 | AD30: =IF(AND(R30>0,Z30>0),(Z30/(R30*1000)*1000),0) -> 910.26207 | AE30: =IF(AND(S30>0,AA30>0),(AA30/(S30*1000)*1000),0) -> 990.28504 | AF30: =+Listrik!AQ29 -> 0 | AG30: =AF30+AG29 -> 0 | AH30: =IF(AND(L30>0,AF30>0),(AF30/(P30*1000)*1000),0) -> 0 | AI30: =IF(AND(M30>0,AG30>0),(AG30/(Q30*1000)*1000),0) -> 0 | AJ30: =IF(AND(R30>0,AF30>0),(AF30/(R30*1000)*1000),0) -> 0 | AK30: =IF(AND(S30>0,AG30>0),(AG30/(S30*1000)*1000),0) -> 0 | AL30: =+Efficiency2!K100 -> 51.08103 | AM30: =AM29+AL30 -> 1148.97 | AN30: =+R30/AL30 -> 0.95577556 | AO30: =+S30/AM30 -> 0.90002958
A31: =A30+1 -> 46135 | B31: Facial | C31: 13 | D31: =+'23'!F42 -> 1350 | E31: =+'23'!G42 -> 1012.5 | F31: =1-(E31/D31) -> 0.25 | G31: =+P31/N31 -> 1.010982 | H31: =+P31/L31 -> 1.010982 | I31: =+R31/P31 -> 0.92941792 | J31: =+R31/L31 -> 0.93962475 | K31: =+S31/M31 -> 0.89158275 | L31: =+Efficiency1!K105 -> 51.08103 | M31: =M30+L31 -> 1213.6888 | N31: =+Efficiency1!C105 -> 51.08103 | O31: =O30+N31 -> 1205.6634 | P31: ='23'!I38 -> 51.642 | Q31: =Q30+P31 -> 1135.573 | R31: ='23'!I40 -> 47.997 | S31: =S30+R31 -> 1082.104 | T31: 119.3 | U31: =T31+U30 -> 2784.3 | V31: =T31/(P31) -> 2.3101352 | W31: =U31/(Q31) -> 2.4518899 | X31: =IF(AND(R31>0,T31>0),T31/(R31),0) -> 2.485572 | Y31: =IF(AND(S31>0,U31>0),U31/(S31),0) -> 2.5730429 | Z31: ='23'!I46 -> 44584.471 | AA31: =Z31+AA30 -> 1068645.2 | AB31: =IF(AND(L31>0,Z31>0),(Z31/(P31*1000)*1000),0) -> 863.33743 | AC31: =IF(AND(M31>0,AA31>0),(AA31/(Q31*1000)*1000),0) -> 941.0625 | AD31: =IF(AND(R31>0,Z31>0),(Z31/(R31*1000)*1000),0) -> 928.90121 | AE31: =IF(AND(S31>0,AA31>0),(AA31/(S31*1000)*1000),0) -> 987.56234 | AF31: =+Listrik!AQ30 -> 0 | AG31: =AF31+AG30 -> 0 | AH31: =IF(AND(L31>0,AF31>0),(AF31/(P31*1000)*1000),0) -> 0 | AI31: =IF(AND(M31>0,AG31>0),(AG31/(Q31*1000)*1000),0) -> 0 | AJ31: =IF(AND(R31>0,AF31>0),(AF31/(R31*1000)*1000),0) -> 0 | AK31: =IF(AND(S31>0,AG31>0),(AG31/(S31*1000)*1000),0) -> 0 | AL31: =+Efficiency2!K105 -> 51.08103 | AM31: =AM30+AL31 -> 1200.051 | AN31: =+R31/AL31 -> 0.93962475 | AO31: =+S31/AM31 -> 0.90171497
A32: =A31+1 -> 46136 | B32: Facial | C32: 13 | D32: =+'24'!F42 -> 1350 | E32: =+'24'!G42 -> 1012.5 | F32: =1-(E32/D32) -> 0.25 | G32: =+P32/N32 -> 0.96431102 | H32: =+P32/L32 -> 0.96431102 | I32: =+R32/P32 -> 1.0916196 | J32: =+R32/L32 -> 1.0526608 | K32: =+S32/M32 -> 0.89808831 | L32: =+Efficiency1!K109 -> 51.08103 | M32: =M31+L32 -> 1264.7698 | N32: =+Efficiency1!C109 -> 51.08103 | O32: =O31+N32 -> 1256.7444 | P32: ='24'!I38 -> 49.258 | Q32: =Q31+P32 -> 1184.831 | R32: ='24'!I40 -> 53.771 | S32: =S31+R32 -> 1135.875 | T32: 120 | U32: =T32+U31 -> 2904.3 | V32: =T32/(P32) -> 2.4361525 | W32: =U32/(Q32) -> 2.4512357 | X32: =IF(AND(R32>0,T32>0),T32/(R32),0) -> 2.2316862 | Y32: =IF(AND(S32>0,U32>0),U32/(S32),0) -> 2.5568835 | Z32: =+'24'!I46 -> 46550.358 | AA32: =Z32+AA31 -> 1115195.5 | AB32: =IF(AND(L32>0,Z32>0),(Z32/(P32*1000)*1000),0) -> 945.03143 | AC32: =IF(AND(M32>0,AA32>0),(AA32/(Q32*1000)*1000),0) -> 941.2275 | AD32: =IF(AND(R32>0,Z32>0),(Z32/(R32*1000)*1000),0) -> 865.71494 | AE32: =IF(AND(S32>0,AA32>0),(AA32/(S32*1000)*1000),0) -> 981.79423 | AF32: =+Listrik!AQ31 -> 0 | AG32: =AF32+AG31 -> 0 | AH32: =IF(AND(L32>0,AF32>0),(AF32/(P32*1000)*1000),0) -> 0 | AI32: =IF(AND(M32>0,AG32>0),(AG32/(Q32*1000)*1000),0) -> 0 | AJ32: =IF(AND(R32>0,AF32>0),(AF32/(R32*1000)*1000),0) -> 0 | AK32: =IF(AND(S32>0,AG32>0),(AG32/(S32*1000)*1000),0) -> 0 | AL32: =+Efficiency2!K109 -> 51.08103 | AM32: =AM31+AL32 -> 1251.1321 | AN32: =+R32/AL32 -> 1.0526608 | AO32: =+S32/AM32 -> 0.90787777
A33: =A32+1 -> 46137 | B33: Facial | C33: 13 | D33: =+'25'!F42 -> 1350 | E33: =+'25'!G42 -> 1012.5 | F33: =1-(E33/D33) -> 0.25 | G33: =+P33/N33 -> 0.95882953 | H33: =+P33/L33 -> 0.95882953 | I33: =+R33/P33 -> 0.89777043 | J33: =+R33/L33 -> 0.8608088 | K33: =+S33/M33 -> 0.89664113 | L33: =+Efficiency1!K113 -> 51.08103 | M33: =M32+L33 -> 1315.8509 | N33: =+Efficiency1!C113 -> 51.08103 | O33: =O32+N33 -> 1307.8254 | P33: ='25'!I38 -> 48.978 | Q33: =Q32+P33 -> 1233.809 | R33: ='25'!I40 -> 43.971 | S33: =S32+R33 -> 1179.846 | T33: 120.6 | U33: =T33+U32 -> 3024.9 | V33: =T33/(P33) -> 2.46233 | W33: =U33/(Q33) -> 2.4516761 | X33: =IF(AND(R33>0,T33>0),T33/(R33),0) -> 2.7427168 | Y33: =IF(AND(S33>0,U33>0),U33/(S33),0) -> 2.5638092 | Z33: =+'25'!I46 -> 47143.817 | AA33: =Z33+AA32 -> 1162339.3 | AB33: =IF(AND(L33>0,Z33>0),(Z33/(P33*1000)*1000),0) -> 962.55088 | AC33: =IF(AND(M33>0,AA33>0),(AA33/(Q33*1000)*1000),0) -> 942.07397 | AD33: =IF(AND(R33>0,Z33>0),(Z33/(R33*1000)*1000),0) -> 1072.157 | AE33: =IF(AND(S33>0,AA33>0),(AA33/(S33*1000)*1000),0) -> 985.16191 | AF33: =+Listrik!AQ32 -> 0 | AG33: =AF33+AG32 -> 0 | AH33: =IF(AND(L33>0,AF33>0),(AF33/(P33*1000)*1000),0) -> 0 | AI33: =IF(AND(M33>0,AG33>0),(AG33/(Q33*1000)*1000),0) -> 0 | AJ33: =IF(AND(R33>0,AF33>0),(AF33/(R33*1000)*1000),0) -> 0 | AK33: =IF(AND(S33>0,AG33>0),(AG33/(S33*1000)*1000),0) -> 0 | AL33: =+Efficiency2!K113 -> 51.08103 | AM33: =AM32+AL33 -> 1302.2131 | AN33: =+R33/AL33 -> 0.8608088 | AO33: =+S33/AM33 -> 0.90603143
A34: =A33+1 -> 46138 | B34: Facial | C34: 13 | D34: =+'26'!F42 -> 1350 | E34: =+'26'!G42 -> 1012.5 | F34: =1-(E34/D34) -> 0.25 | G34: =+P34/N34 -> 1.0116476 | H34: =+P34/L34 -> 1.0116476 | I34: =+R34/P34 -> 0.87355832 | J34: =+R34/L34 -> 0.88373316 | K34: =+S34/M34 -> 0.89615877 | L34: =+Efficiency1!K117 -> 51.08103 | M34: =M33+L34 -> 1366.9319 | N34: =+Efficiency1!C117 -> 51.08103 | O34: =O33+N34 -> 1358.9065 | P34: ='26'!I38 -> 51.676 | Q34: =Q33+P34 -> 1285.485 | R34: ='26'!I40 -> 45.142 | S34: =S33+R34 -> 1224.988 | T34: 121.2 | U34: =T34+U33 -> 3146.1 | V34: =T34/(P34) -> 2.3453828 | W34: =U34/(Q34) -> 2.4474031 | X34: =IF(AND(R34>0,T34>0),T34/(R34),0) -> 2.6848611 | Y34: =IF(AND(S34>0,U34>0),U34/(S34),0) -> 2.5682701 | Z34: ='26'!I46 -> 48978.838 | AA34: =Z34+AA33 -> 1211318.2 | AB34: =IF(AND(L34>0,Z34>0),(Z34/(P34*1000)*1000),0) -> 947.8063 | AC34: =IF(AND(M34>0,AA34>0),(AA34/(Q34*1000)*1000),0) -> 942.3044 | AD34: =IF(AND(R34>0,Z34>0),(Z34/(R34*1000)*1000),0) -> 1084.9949 | AE34: =IF(AND(S34>0,AA34>0),(AA34/(S34*1000)*1000),0) -> 988.84085 | AF34: =+Listrik!AQ33 -> 0 | AG34: =AF34+AG33 -> 0 | AH34: =IF(AND(L34>0,AF34>0),(AF34/(P34*1000)*1000),0) -> 0 | AI34: =IF(AND(M34>0,AG34>0),(AG34/(Q34*1000)*1000),0) -> 0 | AJ34: =IF(AND(R34>0,AF34>0),(AF34/(R34*1000)*1000),0) -> 0 | AK34: =IF(AND(S34>0,AG34>0),(AG34/(S34*1000)*1000),0) -> 0 | AL34: =+Efficiency2!K117 -> 51.08103 | AM34: =AM33+AL34 -> 1353.2941 | AN34: =+R34/AL34 -> 0.88373316 | AO34: =+S34/AM34 -> 0.90518976
A35: =A34+1 -> 46139 | B35: Facial | C35: 13/12 | D35: =+'27'!F42 -> 1350 | E35: =+'27'!G42 -> 1012.5 | F35: =1-(E35/D35) -> 0.25 | G35: =+P35/N35 -> 0.85035249 | H35: =+P35/L35 -> 0.84474641 | I35: =+R35/P35 -> 1.1663071 | J35: =+R35/L35 -> 0.98523373 | K35: =+S35/M35 -> 0.8993644 | L35: =+SUM(Efficiency1!K121:K122) -> 51.029516 | M35: =M34+L35 -> 1417.9614 | N35: =+SUM(Efficiency1!C121:C122) -> 50.693096 | O35: =O34+N35 -> 1409.5996 | P35: ='27'!I38 -> 43.107 | Q35: =Q34+P35 -> 1328.592 | R35: ='27'!I40 -> 50.276 | S35: =S34+R35 -> 1275.264 | T35: 106.8 | U35: =T35+U34 -> 3252.9 | V35: =T35/(P35) -> 2.4775558 | W35: =U35/(Q35) -> 2.4483814 | X35: =IF(AND(R35>0,T35>0),T35/(R35),0) -> 2.124274 | Y35: =IF(AND(S35>0,U35>0),U35/(S35),0) -> 2.550766 | Z35: ='27'!I46 -> 42056.831 | AA35: =Z35+AA34 -> 1253375 | AB35: =IF(AND(L35>0,Z35>0),(Z35/(P35*1000)*1000),0) -> 975.63808 | AC35: =IF(AND(M35>0,AA35>0),(AA35/(Q35*1000)*1000),0) -> 943.38594 | AD35: =IF(AND(R35>0,Z35>0),(Z35/(R35*1000)*1000),0) -> 836.51903 | AE35: =IF(AND(S35>0,AA35>0),(AA35/(S35*1000)*1000),0) -> 982.83572 | AF35: =+Listrik!AQ34 -> 0 | AG35: =AF35+AG34 -> 0 | AH35: =IF(AND(L35>0,AF35>0),(AF35/(P35*1000)*1000),0) -> 0 | AI35: =IF(AND(M35>0,AG35>0),(AG35/(Q35*1000)*1000),0) -> 0 | AJ35: =IF(AND(R35>0,AF35>0),(AF35/(R35*1000)*1000),0) -> 0 | AK35: =IF(AND(S35>0,AG35>0),(AG35/(S35*1000)*1000),0) -> 0 | AL35: =+SUM(Efficiency2!K121:K122) -> 51.029516 | AM35: =AM34+AL35 -> 1404.3237 | AN35: =+R35/AL35 -> 0.98523373 | AO35: =+S35/AM35 -> 0.90809835
A36: =A35+1 -> 46140 | B36: Facial/Toilet | C36: 14/13/15 | D36: =+'28'!F42 -> 1275.8279 | E36: =+'28'!G42 -> 956.87093 | F36: =1-(E36/D36) -> 0.25 | G36: =+P36/N36 -> 0.47696246 | H36: =+P36/L36 -> 0.44968034 | I36: =+R36/P36 -> 0.94910241 | J36: =+R36/L36 -> 0.42679269 | K36: =+S36/M36 -> 0.88198631 | L36: =+SUM(Efficiency1!K126:K128) -> 54.13401 | M36: =M35+L36 -> 1472.0954 | N36: =+SUM(Efficiency1!C126:C128) -> 51.03756 | O36: =O35+N36 -> 1460.6371 | P36: ='28'!I38 -> 24.343 | Q36: =Q35+P36 -> 1352.935 | R36: ='28'!I40 -> 23.104 | S36: =S35+R36 -> 1298.368 | T36: 82.3 | U36: =T36+U35 -> 3335.2 | V36: =T36/(P36) -> 3.3808487 | W36: =U36/(Q36) -> 2.4651591 | X36: =IF(AND(R36>0,T36>0),T36/(R36),0) -> 3.5621537 | Y36: =IF(AND(S36>0,U36>0),U36/(S36),0) -> 2.5687632 | Z36: ='28'!I46 -> 25534.648 | AA36: =Z36+AA35 -> 1278909.7 | AB36: =IF(AND(L36>0,Z36>0),(Z36/(P36*1000)*1000),0) -> 1048.9524 | AC36: =IF(AND(M36>0,AA36>0),(AA36/(Q36*1000)*1000),0) -> 945.28536 | AD36: =IF(AND(R36>0,Z36>0),(Z36/(R36*1000)*1000),0) -> 1105.2047 | AE36: =IF(AND(S36>0,AA36>0),(AA36/(S36*1000)*1000),0) -> 985.01323 | AF36: =+Listrik!AQ35 -> 0 | AG36: =AF36+AG35 -> 0 | AH36: =IF(AND(L36>0,AF36>0),(AF36/(P36*1000)*1000),0) -> 0 | AI36: =IF(AND(M36>0,AG36>0),(AG36/(Q36*1000)*1000),0) -> 0 | AJ36: =IF(AND(R36>0,AF36>0),(AF36/(R36*1000)*1000),0) -> 0 | AK36: =IF(AND(S36>0,AG36>0),(AG36/(S36*1000)*1000),0) -> 0 | AL36: =+SUM(Efficiency2!K126:K128) -> 49.177832 | AM36: =AM35+AL36 -> 1453.5015 | AN36: =+R36/AL36 -> 0.46980518 | AO36: =+S36/AM36 -> 0.89326912
A37: =A36+1 -> 46141 | B37: Toilet | C37: 15/16 | D37: =+'29'!F42 -> 1195.8197 | E37: =+'29'!G42 -> 896.86475 | F37: =1-(E37/D37) -> 0.25 | G37: =+P37/N37 -> 0.85225194 | H37: =+P37/L37 -> 0.85225194 | I37: =+R37/P37 -> 0.88257188 | J37: =+R37/L37 -> 0.7521736 | K37: =+S37/M37 -> 0.87740053 | L37: =+SUM(Efficiency1!K132:K133) -> 53.907768 | M37: =M36+L37 -> 1526.0032 | N37: =+SUM(Efficiency1!C132:C133) -> 53.907768 | O37: =O36+N37 -> 1514.5449 | P37: ='29'!I38 -> 45.943 | Q37: =Q36+P37 -> 1398.878 | R37: ='29'!I40 -> 40.548 | S37: =S36+R37 -> 1338.916 | T37: 111 | U37: =T37+U36 -> 3446.2 | V37: =T37/(P37) -> 2.4160373 | W37: =U37/(Q37) -> 2.4635458 | X37: =IF(AND(R37>0,T37>0),T37/(R37),0) -> 2.7374963 | Y37: =IF(AND(S37>0,U37>0),U37/(S37),0) -> 2.5738732 | Z37: ='29'!I46 -> 39450.608 | AA37: =Z37+AA36 -> 1318360.3 | AB37: =IF(AND(L37>0,Z37>0),(Z37/(P37*1000)*1000),0) -> 858.68594 | AC37: =IF(AND(M37>0,AA37>0),(AA37/(Q37*1000)*1000),0) -> 942.4412 | AD37: =IF(AND(R37>0,Z37>0),(Z37/(R37*1000)*1000),0) -> 972.93598 | AE37: =IF(AND(S37>0,AA37>0),(AA37/(S37*1000)*1000),0) -> 984.64748 | AF37: =+Listrik!AQ36 -> 0 | AG37: =AF37+AG36 -> 0 | AH37: =IF(AND(L37>0,AF37>0),(AF37/(P37*1000)*1000),0) -> 0 | AI37: =IF(AND(M37>0,AG37>0),(AG37/(Q37*1000)*1000),0) -> 0 | AJ37: =IF(AND(R37>0,AF37>0),(AF37/(R37*1000)*1000),0) -> 0 | AK37: =IF(AND(S37>0,AG37>0),(AG37/(S37*1000)*1000),0) -> 0 | AL37: =+SUM(Efficiency2!K132:K133) -> 45.710568 | AM37: =AM36+AL37 -> 1499.2121 | AN37: =+R37/AL37 -> 0.88705964 | AO37: =+S37/AM37 -> 0.8930798
A38: =A37+1 -> 46142 | B38: Facial/Toilet | C38: 12/14/18/19 | D38: =+'30'!F42 -> 1193.2519 | E38: =+'30'!G42 -> 894.93893 | F38: =1-(E38/D38) -> 0.25 | G38: =+P38/N38 -> 0.9079211 | H38: =+P38/L38 -> 0.83450878 | I38: =+R38/P38 -> 0.88411409 | J38: =+R38/L38 -> 0.73780097 | K38: =+S38/M38 -> 0.87269494 | L38: =+SUM(Efficiency1!K137:K140) -> 53.232514 | M38: =M37+L38 -> 1579.2357 | N38: =+SUM(Efficiency1!C137:C140) -> 48.92826 | O38: =O37+N38 -> 1563.4732 | P38: ='30'!I38 -> 44.423 | Q38: =Q37+P38 -> 1443.301 | R38: ='30'!I40 -> 39.275 | S38: =S37+R38 -> 1378.191 | T38: 105 | U38: =T38+U37 -> 3551.2 | V38: =T38/(P38) -> 2.3636405 | W38: =U38/(Q38) -> 2.4604708 | X38: =IF(AND(R38>0,T38>0),T38/(R38),0) -> 2.6734564 | Y38: =IF(AND(S38>0,U38>0),U38/(S38),0) -> 2.5767111 | Z38: ='30'!I46 -> 42080.284 | AA38: =Z38+AA37 -> 1360440.5 | AB38: =IF(AND(L38>0,Z38>0),(Z38/(P38*1000)*1000),0) -> 947.26344 | AC38: =IF(AND(M38>0,AA38>0),(AA38/(Q38*1000)*1000),0) -> 942.58962 | AD38: =IF(AND(R38>0,Z38>0),(Z38/(R38*1000)*1000),0) -> 1071.4267 | AE38: =IF(AND(S38>0,AA38>0),(AA38/(S38*1000)*1000),0) -> 987.12047 | AF38: =+Listrik!AQ37 -> 0 | AG38: =AF38+AG37 -> 0 | AH38: =IF(AND(L38>0,AF38>0),(AF38/(P38*1000)*1000),0) -> 0 | AI38: =IF(AND(M38>0,AG38>0),(AG38/(Q38*1000)*1000),0) -> 0 | AJ38: =IF(AND(R38>0,AF38>0),(AF38/(R38*1000)*1000),0) -> 0 | AK38: =IF(AND(S38>0,AG38>0),(AG38/(S38*1000)*1000),0) -> 0 | AL38: =+SUM(Efficiency2!K137:K140) -> 48.809914 | AM38: =AM37+AL38 -> 1548.022 | AN38: =+R38/AL38 -> 0.80465211 | AO38: =+S38/AM38 -> 0.89029163
G41: =+P41/N41 -> 0.92313769 | H41: =+P41/L41 -> 0.91392375 | I41: =+R41/P41 -> 0.95488813 | J41: =+R41/L41 -> 0.87269494 | L41: =SUM(L9:L39) -> 1579.2357 | N41: =SUM(N9:N39) -> 1563.4732 | P41: =SUM(P9:P39) -> 1443.301 | R41: =SUM(R9:R39) -> 1378.191 | T41: =SUM(T9:T40) -> 3551.2 | V41: =T41/P41 -> 2.4604708 | X41: =T41/R41 -> 2.5767111 | Z41: =SUM(Z9:Z39) -> 1360440.5 | AB41: =Z41/P41 -> 942.58962 | AD41: =Z41/R41 -> 987.12047 | AF41: =SUM(AF9:AF39) -> 0 | AH41: =AF41/P41 -> 0 | AJ41: =AF41/R41 -> 0 | AL41: =SUM(AL9:AL39) -> 1548.022 | AN41: =+R41/AL41 -> 0.89029163

Sheet GRAFIK

Sheet Listrik
A2: MACHINE POWER CONSUMPTION (PER PANEL)
A4: Date | B4: PM (TON) | C4: FINSHED GOODS (TON) | AN4: Total PM16 | AQ4: LISTRIK WPL
D5: Vacuum A | H5: Vacuum B | L5: MCC Aux TM | P5: Multi Screen | T5: MCC | X5: Drive Panel | AB5: Aux Panel | AF5: Stock Prep | AJ5: Pulper
D6: KWH | E6: Consumption | F6: /TON PM | G6: /TON FG | H6: KWH | I6: Consumption | J6: /TON PM | K6: /TON FG | L6: KWH | M6: Consumption | N6: /TON PM | O6: /TON FG | P6: KWH | Q6: Consumption | R6: /TON PM | S6: /TON FG | T6: KWH | U6: Consumption | V6: /TON PM | W6: /TON FG | X6: KWH | Y6: Consumption | Z6: /TON PM | AA6: /TON FG | AB6: KWH | AC6: Consumption | AD6: /TON PM | AE6: /TON FG | AF6: KWH | AG6: Consumption | AH6: /TON PM | AI6: /TON FG | AJ6: KWH | AK6: Consumption | AL6: /TON PM | AM6: /TON FG | AN6: Consumption | AO6: /TON PM | AP6: /TON FG | AQ6: Consumption | AR6: /TON PM | AS6: /TON FG
A8: =+Report1!A9 -> 46113 | B8: =+Report1!P9 -> 38.25 | C8: =+Report1!R9 -> 36.937 | D8: =+D7+E8 -> 0 | F8: =E8/B8 -> 0 | G8: =E8/C8 -> 0 | H8: =+H7+I8 -> 0 | I8: 0 | J8: =I8/B8 -> 0 | K8: =I8/C8 -> 0 | L8: =+L7+M8 -> 0 | N8: =M8/B8 -> 0 | O8: =M8/C8 -> 0 | P8: =+P7+Q8 -> 0 | R8: =Q8/B8 -> 0 | S8: =Q8/C8 -> 0 | T8: =+T7+U8 -> 6273.01 | U8: =+[1]DailyApr!$AT7 -> 6273.01 | V8: =U8/B8 -> 164.00026 | W8: =U8/C8 -> 169.82998 | X8: =+X7+Y8 -> 19110 | Y8: =+[1]DailyApr!$AU7 -> 19110 | Z8: =Y8/B8 -> 499.60784 | AA8: =Y8/C8 -> 517.36741 | AB8: =+AB7+AC8 -> 9924.01 | AC8: =+[1]DailyApr!$AV7 -> 9924.01 | AD8: =AC8/B8 -> 259.45124 | AE8: =AC8/C8 -> 268.67396 | AF8: =+AF7+AG8 -> 12011.666 | AG8: =+[1]DailyApr!$AW7 -> 12011.666 | AH8: =AG8/B8 -> 314.03049 | AI8: =AG8/C8 -> 325.19334 | AJ8: =+AJ7+AK8 -> 1742.4 | AK8: =+[1]DailyApr!$AX7 -> 1742.4 | AL8: =AK8/B8 -> 45.552941 | AM8: =AK8/C8 -> 47.172212 | AN8: =+E8+I8+M8+Q8+U8+Y8+AC8+AG8+AK8 -> 49061.086 | AO8: =AN8/B8 -> 1282.6428 | AP8: =AN8/C8 -> 1328.2369 | AQ8: =+[1]DailyApr!BS7 -> 0 | AR8: =AQ8/B8 -> 0 | AS8: =AQ8/C8 -> 0 | AW8: Off Reel | AX8: Off Rewinder
A9: =A8+1 -> 46114 | B9: =+Report1!P10 -> 52.483 | C9: =+Report1!R10 -> 53.685 | D9: =+D8+E9 -> 0 | F9: =E9/B9 -> 0 | G9: =E9/C9 -> 0 | H9: =+H8+I9 -> 0 | J9: =I9/B9 -> 0 | K9: =I9/C9 -> 0 | L9: =+L8+M9 -> 0 | N9: =M9/B9 -> 0 | O9: =M9/C9 -> 0 | P9: =+P8+Q9 -> 0 | R9: =Q9/B9 -> 0 | S9: =Q9/C9 -> 0 | T9: =+T8+U9 -> 13028.22 | U9: =+[1]DailyApr!$AT8 -> 6755.21 | V9: =U9/B9 -> 128.71234 | W9: =U9/C9 -> 125.83049 | X9: =+X8+Y9 -> 37850 | Y9: =+[1]DailyApr!$AU8 -> 18740 | Z9: =Y9/B9 -> 357.068 | AA9: =Y9/C9 -> 349.0733 | AB9: =+AB8+AC9 -> 20740.22 | AC9: =+[1]DailyApr!$AV8 -> 10816.21 | AD9: =AC9/B9 -> 206.08978 | AE9: =AC9/C9 -> 201.47546 | AF9: =+AF8+AG9 -> 30606.985 | AG9: =+[1]DailyApr!$AW8 -> 18595.319 | AH9: =AG9/B9 -> 354.31128 | AI9: =AG9/C9 -> 346.3783 | AJ9: =+AJ8+AK9 -> 3587.2 | AK9: =+[1]DailyApr!$AX8 -> 1844.8 | AL9: =AK9/B9 -> 35.15043 | AM9: =AK9/C9 -> 34.363416 | AN9: =+E9+I9+M9+Q9+U9+Y9+AC9+AG9+AK9 -> 56751.539 | AO9: =AN9/B9 -> 1081.3318 | AP9: =AN9/C9 -> 1057.121 | AQ9: =+[1]DailyApr!BS8 -> 0 | AR9: =AQ9/B9 -> 0 | AS9: =AQ9/C9 -> 0 | AW9: Kwh/ ton | AX9: Kwh/ ton
A10: =A9+1 -> 46115 | B10: =+Report1!P11 -> 50.411 | C10: =+Report1!R11 -> 56.16 | D10: =+D9+E10 -> 0 | F10: =E10/B10 -> 0 | G10: =E10/C10 -> 0 | H10: =+H9+I10 -> 0 | J10: =I10/B10 -> 0 | K10: =I10/C10 -> 0 | L10: =+L9+M10 -> 0 | N10: =M10/B10 -> 0 | O10: =M10/C10 -> 0 | P10: =+P9+Q10 -> 0 | R10: =Q10/B10 -> 0 | S10: =Q10/C10 -> 0 | T10: =+T9+U10 -> 19629.33 | U10: =+[1]DailyApr!$AT9 -> 6601.11 | V10: =U10/B10 -> 130.94583 | W10: =U10/C10 -> 117.54113 | X10: =+X9+Y10 -> 57850 | Y10: =+[1]DailyApr!$AU9 -> 20000 | Z10: =Y10/B10 -> 396.73881 | AA10: =Y10/C10 -> 356.12536 | AB10: =+AB9+AC10 -> 30641.33 | AC10: =+[1]DailyApr!$AV9 -> 9901.11 | AD10: =AC10/B10 -> 196.40773 | AE10: =AC10/C10 -> 176.30182 | AF10: =+AF9+AG10 -> 46288.099 | AG10: =+[1]DailyApr!$AW9 -> 15681.114 | AH10: =AG10/B10 -> 311.06532 | AI10: =AG10/C10 -> 279.22211 | AJ10: =+AJ9+AK10 -> 5557.2 | AK10: =+[1]DailyApr!$AX9 -> 1970 | AL10: =AK10/B10 -> 39.078772 | AM10: =AK10/C10 -> 35.078348 | AN10: =+E10+I10+M10+Q10+U10+Y10+AC10+AG10+AK10 -> 54153.334 | AO10: =AN10/B10 -> 1074.2365 | AP10: =AN10/C10 -> 964.26876 | AQ10: =+[1]DailyApr!BS9 -> 0 | AR10: =AQ10/B10 -> 0 | AS10: =AQ10/C10 -> 0 | AW10: Kwh/ ton | AX10: Kwh/ ton
A11: =A10+1 -> 46116 | B11: =+Report1!P12 -> 50.426 | C11: =+Report1!R12 -> 45.531 | D11: =+D10+E11 -> 0 | F11: =E11/B11 -> 0 | G11: =E11/C11 -> 0 | H11: =+H10+I11 -> 0 | J11: =I11/B11 -> 0 | K11: =I11/C11 -> 0 | L11: =+L10+M11 -> 0 | N11: =M11/B11 -> 0 | O11: =M11/C11 -> 0 | P11: =+P10+Q11 -> 0 | R11: =Q11/B11 -> 0 | S11: =Q11/C11 -> 0 | T11: =+T10+U11 -> 25293.02 | U11: =+[1]DailyApr!$AT10 -> 5663.69 | V11: =U11/B11 -> 112.31686 | W11: =U11/C11 -> 124.39195 | X11: =+X10+Y11 -> 71850 | Y11: =+[1]DailyApr!$AU10 -> 14000 | Z11: =Y11/B11 -> 277.63455 | AA11: =Y11/C11 -> 307.48281 | AB11: =+AB10+AC11 -> 40455.02 | AC11: =+[1]DailyApr!$AV10 -> 9813.69 | AD11: =AC11/B11 -> 194.61567 | AE11: =AC11/C11 -> 215.53864 | AF11: =+AF10+AG11 -> 60709.753 | AG11: =+[1]DailyApr!$AW10 -> 14421.654 | AH11: =AG11/B11 -> 285.99638 | AI11: =AG11/C11 -> 316.74362 | AJ11: =+AJ10+AK11 -> 7527.2 | AK11: =+[1]DailyApr!$AX10 -> 1970 | AL11: =AK11/B11 -> 39.067148 | AM11: =AK11/C11 -> 43.267225 | AN11: =+E11+I11+M11+Q11+U11+Y11+AC11+AG11+AK11 -> 45869.034 | AO11: =AN11/B11 -> 909.63062 | AP11: =AN11/C11 -> 1007.4243 | AQ11: =+[1]DailyApr!BS10 -> 0 | AR11: =AQ11/B11 -> 0 | AS11: =AQ11/C11 -> 0 | AV11: Vacuum B | AW11: =+J39 -> 0 | AX11: =+K39 -> 0
A12: =A11+1 -> 46117 | B12: =+Report1!P13 -> 48.241 | C12: =+Report1!R13 -> 37.147 | D12: =+D11+E12 -> 0 | F12: =E12/B12 -> 0 | G12: =E12/C12 -> 0 | H12: =+H11+I12 -> 0 | J12: =I12/B12 -> 0 | K12: =I12/C12 -> 0 | L12: =+L11+M12 -> 0 | N12: =M12/B12 -> 0 | O12: =M12/C12 -> 0 | P12: =+P11+Q12 -> 0 | R12: =Q12/B12 -> 0 | S12: =Q12/C12 -> 0 | T12: =+T11+U12 -> 32700.46 | U12: =+[1]DailyApr!$AT11 -> 7407.44 | V12: =U12/B12 -> 153.55071 | W12: =U12/C12 -> 199.40884 | X12: =+X11+Y12 -> 79850 | Y12: =+[1]DailyApr!$AU11 -> 8000 | Z12: =Y12/B12 -> 165.83404 | AA12: =Y12/C12 -> 215.36059 | AB12: =+AB11+AC12 -> 50912.46 | AC12: =+[1]DailyApr!$AV11 -> 10457.44 | AD12: =AC12/B12 -> 216.77494 | AE12: =AC12/C12 -> 281.51506 | AF12: =+AF11+AG12 -> 76975.756 | AG12: =+[1]DailyApr!$AW11 -> 16266.003 | AH12: =AG12/B12 -> 337.18212 | AI12: =AG12/C12 -> 437.882 | AJ12: =+AJ11+AK12 -> 9397.2 | AK12: =+[1]DailyApr!$AX11 -> 1870 | AL12: =AK12/B12 -> 38.763707 | AM12: =AK12/C12 -> 50.340539 | AN12: =+E12+I12+M12+Q12+U12+Y12+AC12+AG12+AK12 -> 44000.883 | AO12: =AN12/B12 -> 912.10553 | AP12: =AN12/C12 -> 1184.507 | AQ12: =+[1]DailyApr!BS11 -> 0 | AR12: =AQ12/B12 -> 0 | AS12: =AQ12/C12 -> 0 | AV12: MCC Aux TM | AW12: =+N39 -> 0 | AX12: =+O39 -> 0
A13: =A12+1 -> 46118 | B13: =+Report1!P14 -> 54.048 | C13: =+Report1!R14 -> 42.652 | D13: =+D12+E13 -> 0 | F13: =E13/B13 -> 0 | G13: =E13/C13 -> 0 | H13: =+H12+I13 -> 0 | J13: =I13/B13 -> 0 | K13: =I13/C13 -> 0 | L13: =+L12+M13 -> 0 | N13: =M13/B13 -> 0 | O13: =M13/C13 -> 0 | P13: =+P12+Q13 -> 0 | R13: =Q13/B13 -> 0 | S13: =Q13/C13 -> 0 | T13: =+T12+U13 -> 38620.91 | U13: =+[1]DailyApr!$AT12 -> 5920.45 | V13: =U13/B13 -> 109.54059 | W13: =U13/C13 -> 138.80826 | X13: =+X12+Y13 -> 88850 | Y13: =+[1]DailyApr!$AU12 -> 9000 | Z13: =Y13/B13 -> 166.51865 | AA13: =Y13/C13 -> 211.01003 | AB13: =+AB12+AC13 -> 61332.91 | AC13: =+[1]DailyApr!$AV12 -> 10420.45 | AD13: =AC13/B13 -> 192.79992 | AE13: =AC13/C13 -> 244.31328 | AF13: =+AF12+AG13 -> 93100.281 | AG13: =+[1]DailyApr!$AW12 -> 16124.526 | AH13: =AG13/B13 -> 298.33714 | AI13: =AG13/C13 -> 378.04852 | AJ13: =+AJ12+AK13 -> 11127.2 | AK13: =+[1]DailyApr!$AX12 -> 1730 | AL13: =AK13/B13 -> 32.008585 | AM13: =AK13/C13 -> 40.560818 | AN13: =+E13+I13+M13+Q13+U13+Y13+AC13+AG13+AK13 -> 43195.426 | AO13: =AN13/B13 -> 799.20489 | AP13: =AN13/C13 -> 1012.7409 | AQ13: =+[1]DailyApr!BS12 -> 0 | AR13: =AQ13/B13 -> 0 | AS13: =AQ13/C13 -> 0 | AV13: Multi Screen | AW13: =+R39 -> 0 | AX13: =+S39 -> 0
A14: =A13+1 -> 46119 | B14: =+Report1!P15 -> 52.463 | C14: =+Report1!R15 -> 60.291 | D14: =+D13+E14 -> 0 | F14: =E14/B14 -> 0 | G14: =E14/C14 -> 0 | H14: =+H13+I14 -> 0 | J14: =I14/B14 -> 0 | K14: =I14/C14 -> 0 | L14: =+L13+M14 -> 0 | N14: =M14/B14 -> 0 | O14: =M14/C14 -> 0 | P14: =+P13+Q14 -> 0 | R14: =Q14/B14 -> 0 | S14: =Q14/C14 -> 0 | T14: =+T13+U14 -> 45562.06 | U14: =+[1]DailyApr!$AT13 -> 6941.15 | V14: =U14/B14 -> 132.30562 | W14: =U14/C14 -> 115.12747 | X14: =+X13+Y14 -> 98850 | Y14: =+[1]DailyApr!$AU13 -> 10000 | Z14: =Y14/B14 -> 190.61053 | AA14: =Y14/C14 -> 165.86223 | AB14: =+AB13+AC14 -> 71424.06 | AC14: =+[1]DailyApr!$AV13 -> 10091.15 | AD14: =AC14/B14 -> 192.34794 | AE14: =AC14/C14 -> 167.37407 | AF14: =+AF13+AG14 -> 114022.22 | AG14: =+[1]DailyApr!$AW13 -> 20921.935 | AH14: =AG14/B14 -> 398.79411 | AI14: =AG14/C14 -> 347.0159 | AJ14: =+AJ13+AK14 -> 13017.2 | AK14: =+[1]DailyApr!$AX13 -> 1890 | AL14: =AK14/B14 -> 36.025389 | AM14: =AK14/C14 -> 31.347962 | AN14: =+E14+I14+M14+Q14+U14+Y14+AC14+AG14+AK14 -> 49844.235 | AO14: =AN14/B14 -> 950.08359 | AP14: =AN14/C14 -> 826.72763 | AQ14: =+[1]DailyApr!BS13 -> 0 | AR14: =AQ14/B14 -> 0 | AS14: =AQ14/C14 -> 0 | AV14: WL II 1250 A (yankee + popereel) | AW14: =+V39 -> 0 | AX14: =+W39 -> 0
A15: =A14+1 -> 46120 | B15: =+Report1!P16 -> 48.457 | C15: =+Report1!R16 -> 46.26 | D15: =+D14+E15 -> 0 | F15: =E15/B15 -> 0 | G15: =E15/C15 -> 0 | H15: =+H14+I15 -> 0 | J15: =I15/B15 -> 0 | K15: =I15/C15 -> 0 | L15: =+L14+M15 -> 0 | N15: =M15/B15 -> 0 | O15: =M15/C15 -> 0 | P15: =+P14+Q15 -> 0 | R15: =Q15/B15 -> 0 | S15: =Q15/C15 -> 0 | T15: =+T14+U15 -> 51448.52 | U15: =+[1]DailyApr!$AT14 -> 5886.46 | V15: =U15/B15 -> 121.47801 | W15: =U15/C15 -> 127.2473 | X15: =+X14+Y15 -> 106850 | Y15: =+[1]DailyApr!$AU14 -> 8000 | Z15: =Y15/B15 -> 165.09483 | AA15: =Y15/C15 -> 172.93558 | AB15: =+AB14+AC15 -> 81910.52 | AC15: =+[1]DailyApr!$AV14 -> 10486.46 | AD15: =AC15/B15 -> 216.40754 | AE15: =AC15/C15 -> 226.68526 | AF15: =+AF14+AG15 -> 133881.41 | AG15: =+[1]DailyApr!$AW14 -> 19859.195 | AH15: =AG15/B15 -> 409.83128 | AI15: =AG15/C15 -> 429.29517 | AJ15: =+AJ14+AK15 -> 14497.2 | AK15: =+[1]DailyApr!$AX14 -> 1480 | AL15: =AK15/B15 -> 30.542543 | AM15: =AK15/C15 -> 31.993083 | AN15: =+E15+I15+M15+Q15+U15+Y15+AC15+AG15+AK15 -> 45712.115 | AO15: =AN15/B15 -> 943.3542 | AP15: =AN15/C15 -> 988.15639 | AQ15: =+[1]DailyApr!BS14 -> 0 | AR15: =AQ15/B15 -> 0 | AS15: =AQ15/C15 -> 0 | AV15: WL II 3200 A (Hood, Fan Pump, Felt & Wire) | AW15: =+Z39 -> 0 | AX15: =+AA39 -> 0
A16: =A15+1 -> 46121 | B16: =+Report1!P17 -> 54.502 | C16: =+Report1!R17 -> 49.106 | D16: =+D15+E16 -> 0 | F16: =E16/B16 -> 0 | G16: =E16/C16 -> 0 | H16: =+H15+I16 -> 0 | J16: =I16/B16 -> 0 | K16: =I16/C16 -> 0 | L16: =+L15+M16 -> 0 | N16: =M16/B16 -> 0 | O16: =M16/C16 -> 0 | P16: =+P15+Q16 -> 0 | R16: =Q16/B16 -> 0 | S16: =Q16/C16 -> 0 | T16: =+T15+U16 -> 58175.91 | U16: =+[1]DailyApr!$AT15 -> 6727.39 | V16: =U16/B16 -> 123.43382 | W16: =U16/C16 -> 136.99731 | X16: =+X15+Y16 -> 116850 | Y16: =+[1]DailyApr!$AU15 -> 10000 | Z16: =Y16/B16 -> 183.47951 | AA16: =Y16/C16 -> 203.6411 | AB16: =+AB15+AC16 -> 91787.91 | AC16: =+[1]DailyApr!$AV15 -> 9877.39 | AD16: =AC16/B16 -> 181.22986 | AE16: =AC16/C16 -> 201.14426 | AF16: =+AF15+AG16 -> 154327.34 | AG16: =+[1]DailyApr!$AW15 -> 20445.929 | AH16: =AG16/B16 -> 375.14089 | AI16: =AG16/C16 -> 416.36315 | AJ16: =+AJ15+AK16 -> 16397.2 | AK16: =+[1]DailyApr!$AX15 -> 1900 | AL16: =AK16/B16 -> 34.861106 | AM16: =AK16/C16 -> 38.69181 | AN16: =+E16+I16+M16+Q16+U16+Y16+AC16+AG16+AK16 -> 48950.709 | AO16: =AN16/B16 -> 898.14519 | AP16: =AN16/C16 -> 996.83764 | AQ16: =+[1]DailyApr!BS15 -> 0 | AR16: =AQ16/B16 -> 0 | AS16: =AQ16/C16 -> 0 | AW16: =SUM(AW10:AW15) -> 0 | AX16: =SUM(AX10:AX15) -> 0
A17: =A16+1 -> 46122 | B17: =+Report1!P18 -> 53.431 | C17: =+Report1!R18 -> 56.877 | D17: =+D16+E17 -> 0 | F17: =E17/B17 -> 0 | G17: =E17/C17 -> 0 | H17: =+H16+I17 -> 0 | J17: =I17/B17 -> 0 | K17: =I17/C17 -> 0 | L17: =+L16+M17 -> 0 | N17: =M17/B17 -> 0 | O17: =M17/C17 -> 0 | P17: =+P16+Q17 -> 0 | R17: =Q17/B17 -> 0 | S17: =Q17/C17 -> 0 | T17: =+T16+U17 -> 64026.48 | U17: =+[1]DailyApr!$AT16 -> 5850.57 | V17: =U17/B17 -> 109.49767 | W17: =U17/C17 -> 102.86355 | X17: =+X16+Y17 -> 125850 | Y17: =+[1]DailyApr!$AU16 -> 9000 | Z17: =Y17/B17 -> 168.44154 | AA17: =Y17/C17 -> 158.23619 | AB17: =+AB16+AC17 -> 102288.48 | AC17: =+[1]DailyApr!$AV16 -> 10500.57 | AD17: =AC17/B17 -> 196.5258 | AE17: =AC17/C17 -> 184.61891 | AF17: =+AF16+AG17 -> 175339.24 | AG17: =+[1]DailyApr!$AW16 -> 21011.903 | AH17: =AG17/B17 -> 393.25304 | AI17: =AG17/C17 -> 369.42706 | AJ17: =+AJ16+AK17 -> 18597.2 | AK17: =+[1]DailyApr!$AX16 -> 2200 | AL17: =AK17/B17 -> 41.174599 | AM17: =AK17/C17 -> 38.679959 | AN17: =+E17+I17+M17+Q17+U17+Y17+AC17+AG17+AK17 -> 48563.043 | AO17: =AN17/B17 -> 908.89265 | AP17: =AN17/C17 -> 853.82568 | AQ17: =+[1]DailyApr!BS16 -> 0 | AR17: =AQ17/B17 -> 0 | AS17: =AQ17/C17 -> 0 | AU17: Stockprep | AV17: Stock Prep & UTM 1 (3200 A) | AW17: =+AD39 -> 0 | AX17: =+AE39 -> 0
