Workbook

Sheet Report1
A3: PAPER MACHINE 16 DAILY REPORT 1
A6: Date | B6: Grade | C6: GSM | D6: Speed yankee (mpm) | E6: Speed reel (mpm) | F6: Creep ( % ) | G6: Real Eff PM ( % ) | H6: Real Eff PM vs Target (%) | I6: Real Eff FG vs Real Eff PM (%) | J6: Eff FG vs Target (%) | L6: Kapasitas Target (ton) | N6: Kapasitas Teori Real (ton) | P6: PM PROD Timbangan (TON) | R6: FINSHED GOODS (TON) | T6: GAS HOOD | Z6: STEAM (TON) | AF6: POWER (kWh) | AL6: Kapasitas Running (ton) | AN6: Eff FG vs Target Running(%)
T7: CONSUMPTION | V7: /TON PM. | X7: /TON FG. | Z7: CONSUMPTION | AB7: /TON PM. | AD7: /TON FG. | AF7: CONSUMPTION | AH7: /TON PM | AJ7: /TON FG
J8: TODAY | K8: TODATE | L8: TODAY | M8: TODATE | N8: TODAY | O8: TODATE | P8: TODAY | Q8: TODATE | R8: TODAY | S8: TODATE | T8: TODAY | U8: TODATE | V8: TODAY | W8: TODATE | X8: TODAY | Y8: TODATE | Z8: TODAY | AA8: TODATE | AB8: TODAY | AC8: TODATE | AD8: TODAY | AE8: TODATE | AF8: TODAY | AG8: TODATE | AH8: TODAY | AI8: TODATE | AJ8: TODAY | AK8: TODATE | AL8: TODAY | AM8: TODATE | AN8: TODAY | AO8: TODATE
A9: 45931 | B9: Toilet | C9: 12,5/15 | D9: =+'1'!F42 -> 1193.9777 | E9: =+'1'!G42 -> 907.42302 | F9: =1-(E9/D9) -> 0.24 | G9: =+P9/N9 -> 0.62770305 | H9: =+P9/L9 -> 0.57573809 | I9: =+R9/P9 -> 0.65324244 | J9: =+R9/L9 -> 0.37609655 | K9: =+S9/M9 -> 0.37609655 | L9: =+SUM(Efficiency1!K6:K7) -> 49.68405 | M9: =L9 -> 49.68405 | N9: =+SUM(Efficiency1!C6:C7) -> 45.570911 | O9: =N9 -> 45.570911 | P9: ='1'!I38 -> 28.605 | Q9: =P9 -> 28.605 | R9: ='1'!I40 -> 18.686 | S9: =R9 -> 18.686 | T9: 0 | U9: =T9 -> 0 | V9: =T9/P9 -> 0 | W9: =U9/Q9 -> 0 | X9: =IF(AND(R9>0,T9>0),(T9/(R9*1000))*1000,0) -> 0 | Y9: =IF(AND(S9>0,U9>0),U9/S9,0) -> 0 | Z9: 79.6 | AA9: =Z9 -> 79.6 | AB9: =Z9/(P9) -> 2.7827303 | AC9: =AA9/(Q9) -> 2.7827303 | AD9: =IF(AND(R9>0,Z9>0),Z9/(R9),0) -> 4.2598737 | AE9: =IF(AND(S9>0,AA9>0),AA9/(S9),0) -> 4.2598737 | AF9: ='1'!I46 -> 37404.6 | AG9: =AF9 -> 37404.6 | AH9: =IF(AND(L9>0,AF9>0),(AF9/(P9*1000)*1000),0) -> 1307.6245 | AI9: =IF(AND(M9>0,AG9>0),(AG9/(Q9*1000)*1000),0) -> 1307.6245 | AJ9: =IF(AND(R9>0,AF9>0),(AF9/(R9*1000)*1000),0) -> 2001.7446 | AK9: =IF(AND(S9>0,AG9>0),(AG9/(S9*1000)*1000),0) -> 2001.7446 | AL9: =+SUM(Efficiency2!K6:K7) -> 38.699181 | AM9: =AL9 -> 38.699181 | AN9: =+R9/AL9 -> 0.4828526 | AO9: =+S9/AM9 -> 0.4828526
A10: =A9+1 -> 45932 | B10: Toilet | C10: 15/14,5 | D10: =+'2'!F42 -> 1099.0278 | E10: =+'2'!G42 -> 836.35 | F10: =1-(E10/D10) -> 0.23900923 | G10: =+P10/N10 -> 1.0131651 | H10: =+P10/L10 -> 0.95131093 | I10: =+R10/P10 -> 1.0001393 | J10: =+R10/L10 -> 0.95144341 | K10: =+S10/M10 -> 0.67262167 | L10: =+SUM(Efficiency1!K11:K12) -> 52.838666 | M10: =M9+L10 -> 102.52272 | N10: =+SUM(Efficiency1!C11:C12) -> 49.61284 | O10: =O9+N10 -> 95.183751 | P10: ='2'!I38 -> 50.266 | Q10: =Q9+P10 -> 78.871 | R10: ='2'!I40 -> 50.273 | S10: =S9+R10 -> 68.959 | U10: =T10+U9 -> 0 | V10: =T10/P10 -> 0 | W10: =U10/Q10 -> 0 | X10: =IF(AND(R10>0,T10>0),(T10/(R10*1000))*1000,0) -> 0 | Y10: =IF(AND(S10>0,U10>0),U10/S10,0) -> 0 | Z10: 117.4 | AA10: =Z10+AA9 -> 197 | AB10: =Z10/(P10) -> 2.3355747 | AC10: =AA10/(Q10) -> 2.4977495 | AD10: =IF(AND(R10>0,Z10>0),Z10/(R10),0) -> 2.3352495 | AE10: =IF(AND(S10>0,AA10>0),AA10/(S10),0) -> 2.85677 | AF10: ='2'!I46 -> 44118.36 | AG10: =AF10+AG9 -> 81522.96 | AH10: =IF(AND(L10>0,AF10>0),(AF10/(P10*1000)*1000),0) -> 877.69785 | AI10: =IF(AND(M10>0,AG10>0),(AG10/(Q10*1000)*1000),0) -> 1033.624 | AJ10: =IF(AND(R10>0,AF10>0),(AF10/(R10*1000)*1000),0) -> 877.57564 | AK10: =IF(AND(S10>0,AG10>0),(AG10/(S10*1000)*1000),0) -> 1182.1946 | AL10: =+SUM(Efficiency2!K11:K12) -> 52.838666 | AM10: =AM9+AL10 -> 91.537847 | AN10: =+R10/AL10 -> 0.95144341 | AO10: =+S10/AM10 -> 0.75333867
A11: =A10+1 -> 45933 | B11: Toilet | C11: 14,5/12,5 | D11: =+'3'!F42 -> 1215.2778 | E11: =+'3'!G42 -> 956.72917 | F11: =1-(E11/D11) -> 0.21274857 | G11: =+P11/N11 -> 0.93574089 | H11: =+P11/L11 -> 0.91973787 | I11: =+R11/P11 -> 0.86932224 | J11: =+R11/L11 -> 0.79954858 | K11: =+S11/M11 -> 0.71604177 | L11: =+SUM(Efficiency1!K15:K16) -> 53.30758 | M11: =M10+L11 -> 155.8303 | N11: =+SUM(Efficiency1!C15:C16) -> 52.395915 | O11: =O10+N11 -> 147.57967 | P11: ='3'!I38 -> 49.029 | Q11: =Q10+P11 -> 127.9 | R11: ='3'!I40 -> 42.622 | S11: =S10+R11 -> 111.581 | U11: =T11+U10 -> 0 | V11: =T11/P11 -> 0 | W11: =U11/Q11 -> 0 | X11: =IF(AND(R11>0,T11>0),(T11/(R11*1000))*1000,0) -> 0 | Y11: =IF(AND(S11>0,U11>0),U11/S11,0) -> 0 | Z11: 125 | AA11: =Z11+AA10 -> 322 | AB11: =Z11/(P11) -> 2.5495115 | AC11: =AA11/(Q11) -> 2.5175919 | AD11: =IF(AND(R11>0,Z11>0),Z11/(R11),0) -> 2.9327577 | AE11: =IF(AND(S11>0,AA11>0),AA11/(S11),0) -> 2.885796 | AF11: ='3'!I46 -> 45154.44 | AG11: =AF11+AG10 -> 126677.4 | AH11: =IF(AND(L11>0,AF11>0),(AF11/(P11*1000)*1000),0) -> 920.97412 | AI11: =IF(AND(M11>0,AG11>0),(AG11/(Q11*1000)*1000),0) -> 990.44097 | AJ11: =IF(AND(R11>0,AF11>0),(AF11/(R11*1000)*1000),0) -> 1059.4163 | AK11: =IF(AND(S11>0,AG11>0),(AG11/(S11*1000)*1000),0) -> 1135.2954 | AL11: =+SUM(Efficiency2!K15:K16) -> 53.30758 | AM11: =AM10+AL11 -> 144.84543 | AN11: =+R11/AL11 -> 0.79954858 | AO11: =+S11/AM11 -> 0.77034534
A12: =A11+1 -> 45934 | B12: Toilet/Facial | C12: 12,5/12/13,5/12 | D12: =+'4'!F42 -> 1370 | E12: =+'4'!G42 -> 1072.6149 | F12: =1-(E12/D12) -> 0.21706944 | G12: =+P12/N12 -> 0.92544684 | H12: =+P12/L12 -> 0.92544684 | I12: =+R12/P12 -> 0.95637707 | J12: =+R12/L12 -> 0.88507614 | K12: =+S12/M12 -> 0.75890216 | L12: =+SUM(Efficiency1!K20:K23) -> 52.934429 | M12: =M11+L12 -> 208.76472 | N12: =+SUM(Efficiency1!C20:C23) -> 52.934429 | O12: =O11+N12 -> 200.51409 | P12: ='4'!I38 -> 48.988 | Q12: =Q11+P12 -> 176.888 | R12: ='4'!I40 -> 46.851 | S12: =S11+R12 -> 158.432 | U12: =T12+U11 -> 0 | V12: =T12/P12 -> 0 | W12: =U12/Q12 -> 0 | X12: =IF(AND(R12>0,T12>0),(T12/(R12*1000))*1000,0) -> 0 | Y12: =IF(AND(S12>0,U12>0),U12/S12,0) -> 0 | Z12: 126.6 | AA12: =Z12+AA11 -> 448.6 | AB12: =Z12/(P12) -> 2.5843064 | AC12: =AA12/(Q12) -> 2.536068 | AD12: =IF(AND(R12>0,Z12>0),Z12/(R12),0) -> 2.7021835 | AE12: =IF(AND(S12>0,AA12>0),AA12/(S12),0) -> 2.8314987 | AF12: ='4'!I46 -> 50042.88 | AG12: =AF12+AG11 -> 176720.28 | AH12: =IF(AND(L12>0,AF12>0),(AF12/(P12*1000)*1000),0) -> 1021.5334 | AI12: =IF(AND(M12>0,AG12>0),(AG12/(Q12*1000)*1000),0) -> 999.05183 | AJ12: =IF(AND(R12>0,AF12>0),(AF12/(R12*1000)*1000),0) -> 1068.1283 | AK12: =IF(AND(S12>0,AG12>0),(AG12/(S12*1000)*1000),0) -> 1115.433 | AL12: =+SUM(Efficiency2!K20:K23) -> 52.934429 | AM12: =AM11+AL12 -> 197.77986 | AN12: =+R12/AL12 -> 0.88507614 | AO12: =+S12/AM12 -> 0.80105226
A13: =A12+1 -> 45935 | B13: Facial | C13: 12/12,5 | D13: =+'5'!F42 -> 1370 | E13: =+'5'!G42 -> 1041.2 | F13: =1-(E13/D13) -> 0.24 | G13: =+P13/N13 -> 0.92682145 | H13: =+P13/L13 -> 0.92682145 | I13: =+R13/P13 -> 0.93725593 | J13: =+R13/L13 -> 0.86866891 | K13: =+S13/M13 -> 0.77983074 | L13: =+SUM(Efficiency1!K25:K26) -> 49.180994 | M13: =M12+L13 -> 257.94572 | N13: =+SUM(Efficiency1!C25:C26) -> 49.180994 | O13: =O12+N13 -> 249.69509 | P13: ='5'!I38 -> 45.582 | Q13: =Q12+P13 -> 222.47 | R13: ='5'!I40 -> 42.722 | S13: =S12+R13 -> 201.154 | U13: =T13+U12 -> 0 | V13: =T13/P13 -> 0 | W13: =U13/Q13 -> 0 | X13: =IF(AND(R13>0,T13>0),(T13/(R13*1000))*1000,0) -> 0 | Y13: =IF(AND(S13>0,U13>0),U13/S13,0) -> 0 | Z13: 123.3 | AA13: =Z13+AA12 -> 571.9 | AB13: =Z13/(P13) -> 2.7050151 | AC13: =AA13/(Q13) -> 2.5706837 | AD13: =IF(AND(R13>0,Z13>0),Z13/(R13),0) -> 2.8861008 | AE13: =IF(AND(S13>0,AA13>0),AA13/(S13),0) -> 2.8430953 | AF13: ='5'!I46 -> 48740.96 | AG13: =AF13+AG12 -> 225461.24 | AH13: =IF(AND(L13>0,AF13>0),(AF13/(P13*1000)*1000),0) -> 1069.3028 | AI13: =IF(AND(M13>0,AG13>0),(AG13/(Q13*1000)*1000),0) -> 1013.4456 | AJ13: =IF(AND(R13>0,AF13>0),(AF13/(R13*1000)*1000),0) -> 1140.8867 | AK13: =IF(AND(S13>0,AG13>0),(AG13/(S13*1000)*1000),0) -> 1120.839 | AL13: =+SUM(Efficiency2!K25:K26) -> 49.180994 | AM13: =AM12+AL13 -> 246.96085 | AN13: =+R13/AL13 -> 0.86866891 | AO13: =+S13/AM13 -> 0.81451777
A14: =A13+1 -> 45936 | B14: Facial | C14: 12,5 | D14: =+'6'!F42 -> 1370 | E14: =+'6'!G42 -> 1041.2 | F14: =1-(E14/D14) -> 0.24 | G14: =+P14/N14 -> 0.89169065 | H14: =+P14/L14 -> 0.89169065 | I14: =+R14/P14 -> 0.97910754 | J14: =+R14/L14 -> 0.87306104 | K14: =+S14/M14 -> 0.79531404 | L14: =+Efficiency1!K29 -> 51.369833 | M14: =M13+L14 -> 309.31555 | N14: =+Efficiency1!C29 -> 51.369833 | O14: =O13+N14 -> 301.06492 | P14: ='6'!I38 -> 45.806 | Q14: =Q13+P14 -> 268.276 | R14: ='6'!I40 -> 44.849 | S14: =S13+R14 -> 246.003 | U14: =T14+U13 -> 0 | V14: =T14/P14 -> 0 | W14: =U14/Q14 -> 0 | X14: =IF(AND(R14>0,T14>0),(T14/(R14*1000))*1000,0) -> 0 | Y14: =IF(AND(S14>0,U14>0),U14/S14,0) -> 0 | Z14: 124.6 | AA14: =Z14+AA13 -> 696.5 | AB14: =Z14/(P14) -> 2.7201677 | AC14: =AA14/(Q14) -> 2.5962069 | AD14: =IF(AND(R14>0,Z14>0),Z14/(R14),0) -> 2.7782113 | AE14: =IF(AND(S14>0,AA14>0),AA14/(S14),0) -> 2.8312663 | AF14: ='6'!I46 -> 50699.48 | AG14: =AF14+AG13 -> 276160.72 | AH14: =IF(AND(L14>0,AF14>0),(AF14/(P14*1000)*1000),0) -> 1106.8305 | AI14: =IF(AND(M14>0,AG14>0),(AG14/(Q14*1000)*1000),0) -> 1029.3903 | AJ14: =IF(AND(R14>0,AF14>0),(AF14/(R14*1000)*1000),0) -> 1130.4484 | AK14: =IF(AND(S14>0,AG14>0),(AG14/(S14*1000)*1000),0) -> 1122.5909 | AL14: =+Efficiency2!K29 -> 51.369833 | AM14: =AM13+AL14 -> 298.33068 | AN14: =+R14/AL14 -> 0.87306104 | AO14: =+S14/AM14 -> 0.82459839
A15: =A14+1 -> 45937 | B15: Facial/Toilet | C15: 12,5/12/13/12,5 | D15: =+'7'!F42 -> 1370 | E15: =+'7'!G42 -> 1046.9083 | F15: =1-(E15/D15) -> 0.23583333 | G15: =+P15/N15 -> 0.92818405 | H15: =+P15/L15 -> 0.92818405 | I15: =+R15/P15 -> 0.94330944 | J15: =+R15/L15 -> 0.87556478 | K15: =+S15/M15 -> 0.80655069 | L15: =+SUM(Efficiency1!K33:K36) -> 50.361779 | M15: =M14+L15 -> 359.67733 | N15: =+SUM(Efficiency1!C33:C36) -> 50.361779 | O15: =O14+N15 -> 351.4267 | P15: ='7'!I38 -> 46.745 | Q15: =Q14+P15 -> 315.021 | R15: ='7'!I40 -> 44.095 | S15: =S14+R15 -> 290.098 | U15: =T15+U14 -> 0 | V15: =T15/P15 -> 0 | W15: =U15/Q15 -> 0 | X15: =IF(AND(R15>0,T15>0),(T15/(R15*1000))*1000,0) -> 0 | Y15: =IF(AND(S15>0,U15>0),U15/S15,0) -> 0 | Z15: 123.4 | AA15: =Z15+AA14 -> 819.9 | AB15: =Z15/(P15) -> 2.6398545 | AC15: =AA15/(Q15) -> 2.6026836 | AD15: =IF(AND(R15>0,Z15>0),Z15/(R15),0) -> 2.7985032 | AE15: =IF(AND(S15>0,AA15>0),AA15/(S15),0) -> 2.8262863 | AF15: ='7'!I46 -> 55121.6 | AG15: =AF15+AG14 -> 331282.32 | AH15: =IF(AND(L15>0,AF15>0),(AF15/(P15*1000)*1000),0) -> 1179.1978 | AI15: =IF(AND(M15>0,AG15>0),(AG15/(Q15*1000)*1000),0) -> 1051.6198 | AJ15: =IF(AND(R15>0,AF15>0),(AF15/(R15*1000)*1000),0) -> 1250.0646 | AK15: =IF(AND(S15>0,AG15>0),(AG15/(S15*1000)*1000),0) -> 1141.9669 | AL15: =+SUM(Efficiency2!K33:K36) -> 50.361779 | AM15: =AM14+AL15 -> 348.69246 | AN15: =+R15/AL15 -> 0.87556478 | AO15: =+S15/AM15 -> 0.83195948
A16: =A15+1 -> 45938 | B16: Toilet | C16: 12,5 | D16: =+'8'!F42 -> 1370 | E16: =+'8'!G42 -> 1109.7 | F16: =1-(E16/D16) -> 0.19 | G16: =+P16/N16 -> 0.91532935 | H16: =+P16/L16 -> 0.91532935 | I16: =+R16/P16 -> 0.95212978 | J16: =+R16/L16 -> 0.87151233 | K16: =+S16/M16 -> 0.81515145 | L16: =+Efficiency1!K38 -> 54.887347 | M16: =M15+L16 -> 414.56468 | N16: =+Efficiency1!C38 -> 54.887347 | O16: =O15+N16 -> 406.31405 | P16: ='8'!I38 -> 50.24 | Q16: =Q15+P16 -> 365.261 | R16: ='8'!I40 -> 47.835 | S16: =S15+R16 -> 337.933 | U16: =T16+U15 -> 0 | V16: =T16/P16 -> 0 | W16: =U16/Q16 -> 0 | X16: =IF(AND(R16>0,T16>0),(T16/(R16*1000))*1000,0) -> 0 | Y16: =IF(AND(S16>0,U16>0),U16/S16,0) -> 0 | Z16: 123.5 | AA16: =Z16+AA15 -> 943.4 | AB16: =Z16/(P16) -> 2.4582006 | AC16: =AA16/(Q16) -> 2.5828106 | AD16: =IF(AND(R16>0,Z16>0),Z16/(R16),0) -> 2.5817916 | AE16: =IF(AND(S16>0,AA16>0),AA16/(S16),0) -> 2.7916776 | AF16: ='8'!I46 -> 48453.52 | AG16: =AF16+AG15 -> 379735.84 | AH16: =IF(AND(L16>0,AF16>0),(AF16/(P16*1000)*1000),0) -> 964.44108 | AI16: =IF(AND(M16>0,AG16>0),(AG16/(Q16*1000)*1000),0) -> 1039.6288 | AJ16: =IF(AND(R16>0,AF16>0),(AF16/(R16*1000)*1000),0) -> 1012.9303 | AK16: =IF(AND(S16>0,AG16>0),(AG16/(S16*1000)*1000),0) -> 1123.7016 | AL16: =+Efficiency2!K38 -> 54.887347 | AM16: =AM15+AL16 -> 403.57981 | AN16: =+R16/AL16 -> 0.87151233 | AO16: =+S16/AM16 -> 0.83733872
A17: =A16+1 -> 45939 | B17: Toilet | C17: 12,5 | D17: =+'9'!F42 -> 1383.3333 | E17: =+'9'!G42 -> 1120.5 | F17: =1-(E17/D17) -> 0.19 | G17: =+P17/N17 -> 0.94565151 | H17: =+P17/L17 -> 0.94565151 | I17: =+R17/P17 -> 1.057457 | J17: =+R17/L17 -> 0.99998578 | K17: =+S17/M17 -> 0.83747379 | L17: =+Efficiency1!K42 -> 56.94381 | M17: =M16+L17 -> 471.50849 | N17: =+Efficiency1!C42 -> 56.94381 | O17: =O16+N17 -> 463.25786 | P17: ='9'!I38 -> 53.849 | Q17: =Q16+P17 -> 419.11 | R17: ='9'!I40 -> 56.943 | S17: =S16+R17 -> 394.876 | U17: =T17+U16 -> 0 | V17: =T17/P17 -> 0 | W17: =U17/Q17 -> 0 | X17: =IF(AND(R17>0,T17>0),(T17/(R17*1000))*1000,0) -> 0 | Y17: =IF(AND(S17>0,U17>0),U17/S17,0) -> 0 | Z17: 124.7 | AA17: =Z17+AA16 -> 1068.1 | AB17: =Z17/(P17) -> 2.3157347 | AC17: =AA17/(Q17) -> 2.5484956 | AD17: =IF(AND(R17>0,Z17>0),Z17/(R17),0) -> 2.1899092 | AE17: =IF(AND(S17>0,AA17>0),AA17/(S17),0) -> 2.7048998 | AF17: ='9'!I46 -> 59159.72 | AG17: =AF17+AG16 -> 438895.56 | AH17: =IF(AND(L17>0,AF17>0),(AF17/(P17*1000)*1000),0) -> 1098.6224 | AI17: =IF(AND(M17>0,AG17>0),(AG17/(Q17*1000)*1000),0) -> 1047.2085 | AJ17: =IF(AND(R17>0,AF17>0),(AF17/(R17*1000)*1000),0) -> 1038.9288 | AK17: =IF(AND(S17>0,AG17>0),(AG17/(S17*1000)*1000),0) -> 1111.4769 | AL17: =+Efficiency2!K42 -> 56.94381 | AM17: =AM16+AL17 -> 460.52362 | AN17: =+R17/AL17 -> 0.99998578 | AO17: =+S17/AM17 -> 0.85745005
A18: =A17+1 -> 45940 | B18: Toilet | C18: 12,5 | D18: =+'10'!F42 -> 1397.5694 | E18: =+'10'!G42 -> 1118.0556 | F18: =1-(E18/D18) -> 0.2 | G18: =+P18/N18 -> 0.89478395 | H18: =+P18/L18 -> 0.89478395 | I18: =+R18/P18 -> 0.80414045 | J18: =+R18/L18 -> 0.71953197 | K18: =+S18/M18 -> 0.82500006 | L18: =+Efficiency1!K46 -> 55.765417 | M18: =M17+L18 -> 527.2739 | N18: =+Efficiency1!C46 -> 55.765417 | O18: =O17+N18 -> 519.02327 | P18: ='10'!I38 -> 49.898 | Q18: =Q17+P18 -> 469.008 | R18: ='10'!I40 -> 40.125 | S18: =S17+R18 -> 435.001 | U18: =T18+U17 -> 0 | V18: =T18/P18 -> 0 | W18: =U18/Q18 -> 0 | X18: =IF(AND(R18>0,T18>0),(T18/(R18*1000))*1000,0) -> 0 | Y18: =IF(AND(S18>0,U18>0),U18/S18,0) -> 0 | Z18: 124.8 | AA18: =Z18+AA17 -> 1192.9 | AB18: =Z18/(P18) -> 2.5011022 | AC18: =AA18/(Q18) -> 2.5434534 | AD18: =IF(AND(R18>0,Z18>0),Z18/(R18),0) -> 3.1102804 | AE18: =IF(AND(S18>0,AA18>0),AA18/(S18),0) -> 2.7422925 | AF18: ='10'!I46 -> 51974.438 | AG18: =AF18+AG17 -> 490870 | AH18: =IF(AND(L18>0,AF18>0),(AF18/(P18*1000)*1000),0) -> 1041.6136 | AI18: =IF(AND(M18>0,AG18>0),(AG18/(Q18*1000)*1000),0) -> 1046.6133 | AJ18: =IF(AND(R18>0,AF18>0),(AF18/(R18*1000)*1000),0) -> 1295.3131 | AK18: =IF(AND(S18>0,AG18>0),(AG18/(S18*1000)*1000),0) -> 1128.4342 | AL18: =+Efficiency2!K46 -> 55.765417 | AM18: =AM17+AL18 -> 516.28904 | AN18: =+R18/AL18 -> 0.71953197 | AO18: =+S18/AM18 -> 0.84255324
A19: =A18+1 -> 45941 | B19: Toilet | C19: 12,5/14 | D19: =+'11'!F42 -> 1379.8611 | E19: =+'11'!G42 -> 1082.2361 | F19: =1-(E19/D19) -> 0.215692 | G19: =+P19/N19 -> 0.93907939 | H19: =+P19/L19 -> 0.92962045 | I19: =+R19/P19 -> 1.0485532 | J19: =+R19/L19 -> 0.97475649 | K19: =+S19/M19 -> 0.83913283 | L19: =+SUM(Efficiency1!K50:K51) -> 54.945005 | M19: =M18+L19 -> 582.21891 | N19: =+SUM(Efficiency1!C50:C51) -> 54.391567 | O19: =O18+N19 -> 573.41484 | P19: ='11'!I38 -> 51.078 | Q19: =Q18+P19 -> 520.086 | R19: ='11'!I40 -> 53.558 | S19: =S18+R19 -> 488.559 | U19: =T19+U18 -> 0 | V19: =T19/P19 -> 0 | W19: =U19/Q19 -> 0 | X19: =IF(AND(R19>0,T19>0),(T19/(R19*1000))*1000,0) -> 0 | Y19: =IF(AND(S19>0,U19>0),U19/S19,0) -> 0 | Z19: 121 | AA19: =Z19+AA18 -> 1313.9 | AB19: =Z19/(P19) -> 2.368926 | AC19: =AA19/(Q19) -> 2.526313 | AD19: =IF(AND(R19>0,Z19>0),Z19/(R19),0) -> 2.259233 | AE19: =IF(AND(S19>0,AA19>0),AA19/(S19),0) -> 2.6893374 | AF19: ='11'!I46 -> 48763.17 | AG19: =AF19+AG18 -> 539633.17 | AH19: =IF(AND(L19>0,AF19>0),(AF19/(P19*1000)*1000),0) -> 954.68049 | AI19: =IF(AND(M19>0,AG19>0),(AG19/(Q19*1000)*1000),0) -> 1037.5845 | AJ19: =IF(AND(R19>0,AF19>0),(AF19/(R19*1000)*1000),0) -> 910.47407 | AK19: =IF(AND(S19>0,AG19>0),(AG19/(S19*1000)*1000),0) -> 1104.5404 | AL19: =+SUM(Efficiency2!K50:K51) -> 54.945005 | AM19: =AM18+AL19 -> 571.23404 | AN19: =+R19/AL19 -> 0.97475649 | AO19: =+S19/AM19 -> 0.85526941
A20: =A19+1 -> 45942 | B20: Toilet | C20: 14/15/12,5 | D20: =+'12'!F42 -> 1329.1667 | E20: =+'12'!G42 -> 1010.1667 | F20: =1-(E20/D20) -> 0.24 | G20: =+P20/N20 -> 0.91225022 | H20: =+P20/L20 -> 0.90890791 | I20: =+R20/P20 -> 1.0106905 | J20: =+R20/L20 -> 0.9186246 | K20: =+S20/M20 -> 0.84603596 | L20: =+SUM(Efficiency1!K54:K56) -> 55.368646 | M20: =M19+L20 -> 637.58755 | N20: =+SUM(Efficiency1!C54:C56) -> 55.165786 | O20: =O19+N20 -> 628.58063 | P20: ='12'!I38 -> 50.325 | Q20: =Q19+P20 -> 570.411 | R20: ='12'!I40 -> 50.863 | S20: =S19+R20 -> 539.422 | U20: =T20+U19 -> 0 | V20: =T20/P20 -> 0 | W20: =U20/Q20 -> 0 | X20: =IF(AND(R20>0,T20>0),(T20/(R20*1000))*1000,0) -> 0 | Y20: =IF(AND(S20>0,U20>0),U20/S20,0) -> 0 | Z20: 122.5 | AA20: =Z20+AA19 -> 1436.4 | AB20: =Z20/(P20) -> 2.4341778 | AC20: =AA20/(Q20) -> 2.5181843 | AD20: =IF(AND(R20>0,Z20>0),Z20/(R20),0) -> 2.4084305 | AE20: =IF(AND(S20>0,AA20>0),AA20/(S20),0) -> 2.6628502 | AF20: ='12'!I46 -> 49974.62 | AG20: =AF20+AG19 -> 589607.79 | AH20: =IF(AND(L20>0,AF20>0),(AF20/(P20*1000)*1000),0) -> 993.03766 | AI20: =IF(AND(M20>0,AG20>0),(AG20/(Q20*1000)*1000),0) -> 1033.6543 | AJ20: =IF(AND(R20>0,AF20>0),(AF20/(R20*1000)*1000),0) -> 982.53387 | AK20: =IF(AND(S20>0,AG20>0),(AG20/(S20*1000)*1000),0) -> 1093.0362 | AL20: =+SUM(Efficiency2!K54:K56) -> 55.368646 | AM20: =AM19+AL20 -> 626.60269 | AN20: =+R20/AL20 -> 0.9186246 | AO20: =+S20/AM20 -> 0.86086768
A21: =A20+1 -> 45943 | B21: Toilet | C21: 12,5/14 | D21: =+'13'!F42 -> 1387.5 | E21: =+'13'!G42 -> 1054.5 | F21: =1-(E21/D21) -> 0.24 | G21: =+P21/N21 -> 0.97897867 | H21: =+P21/L21 -> 0.95726523 | I21: =+R21/P21 -> 0.92241447 | J21: =+R21/L21 -> 0.8829953 | K21: =+S21/M21 -> 0.84889087 | L21: =+SUM(Efficiency1!K59:K61) -> 53.372878 | M21: =M20+L21 -> 690.96043 | N21: =+SUM(Efficiency1!C59:C61) -> 52.189084 | O21: =O20+N21 -> 680.76971 | P21: ='13'!I38 -> 51.092 | Q21: =Q20+P21 -> 621.503 | R21: ='13'!I40 -> 47.128 | S21: =S20+R21 -> 586.55 | U21: =T21+U20 -> 0 | V21: =T21/P21 -> 0 | W21: =U21/Q21 -> 0 | X21: =IF(AND(R21>0,T21>0),(T21/(R21*1000))*1000,0) -> 0 | Y21: =IF(AND(S21>0,U21>0),U21/S21,0) -> 0 | Z21: 122.3 | AA21: =Z21+AA20 -> 1558.7 | AB21: =Z21/(P21) -> 2.3937211 | AC21: =AA21/(Q21) -> 2.5079525 | AD21: =IF(AND(R21>0,Z21>0),Z21/(R21),0) -> 2.5950603 | AE21: =IF(AND(S21>0,AA21>0),AA21/(S21),0) -> 2.6574035 | AF21: ='13'!I46 -> 44644.41 | AG21: =AF21+AG20 -> 634252.2 | AH21: =IF(AND(L21>0,AF21>0),(AF21/(P21*1000)*1000),0) -> 873.80431 | AI21: =IF(AND(M21>0,AG21>0),(AG21/(Q21*1000)*1000),0) -> 1020.5135 | AJ21: =IF(AND(R21>0,AF21>0),(AF21/(R21*1000)*1000),0) -> 947.30118 | AK21: =IF(AND(S21>0,AG21>0),(AG21/(S21*1000)*1000),0) -> 1081.3267 | AL21: =+SUM(Efficiency2!K59:K61) -> 53.372878 | AM21: =AM20+AL21 -> 679.97556 | AN21: =+R21/AL21 -> 0.8829953 | AO21: =+S21/AM21 -> 0.86260453
A22: =A21+1 -> 45944 | B22: Toilet | C22: 14/15 | D22: =+'14'!F42 -> 1235.0694 | E22: =+'14'!G42 -> 946.24306 | F22: =1-(E22/D22) -> 0.23385437 | G22: =+P22/N22 -> 1.0224665 | H22: =+P22/L22 -> 1.0224665 | I22: =+R22/P22 -> 0.76796394 | J22: =+R22/L22 -> 0.78521739 | K22: =+S22/M22 -> 0.84429089 | L22: =+SUM(Efficiency1!K63:K64) -> 53.804208 | M22: =M21+L22 -> 744.76464 | N22: =+SUM(Efficiency1!C63:C64) -> 53.804208 | O22: =O21+N22 -> 734.57392 | P22: ='14'!I38 -> 55.013 | Q22: =Q21+P22 -> 676.516 | R22: ='14'!I40 -> 42.248 | S22: =S21+R22 -> 628.798 | U22: =T22+U21 -> 0 | V22: =T22/P22 -> 0 | W22: =U22/Q22 -> 0 | X22: =IF(AND(R22>0,T22>0),(T22/(R22*1000))*1000,0) -> 0 | Y22: =IF(AND(S22>0,U22>0),U22/S22,0) -> 0 | Z22: 129.3 | AA22: =Z22+AA21 -> 1688 | AB22: =Z22/(P22) -> 2.3503536 | AC22: =AA22/(Q22) -> 2.4951368 | AD22: =IF(AND(R22>0,Z22>0),Z22/(R22),0) -> 3.0604999 | AE22: =IF(AND(S22>0,AA22>0),AA22/(S22),0) -> 2.6844869 | AF22: ='14'!I46 -> 43708.6 | AG22: =AF22+AG21 -> 677960.8 | AH22: =IF(AND(L22>0,AF22>0),(AF22/(P22*1000)*1000),0) -> 794.51402 | AI22: =IF(AND(M22>0,AG22>0),(AG22/(Q22*1000)*1000),0) -> 1002.1356 | AJ22: =IF(AND(R22>0,AF22>0),(AF22/(R22*1000)*1000),0) -> 1034.5721 | AK22: =IF(AND(S22>0,AG22>0),(AG22/(S22*1000)*1000),0) -> 1078.1854 | AL22: =+SUM(Efficiency2!K63:K64) -> 53.804208 | AM22: =AM21+AL22 -> 733.77977 | AN22: =+R22/AL22 -> 0.78521739 | AO22: =+S22/AM22 -> 0.85693014
A23: =A22+1 -> 45945 | B23: Toilet | C23: 15/14/17 | D23: =+'15'!F42 -> 1236.4931 | E23: =+'15'!G42 -> 959.12049 | F23: =1-(E23/D23) -> 0.22432198 | G23: =+P23/N23 -> 0.94628336 | H23: =+P23/L23 -> 0.94628336 | I23: =+R23/P23 -> 0.92257824 | J23: =+R23/L23 -> 0.87302044 | K23: =+S23/M23 -> 0.84623167 | L23: =+SUM(Efficiency1!K67:K69) -> 53.956354 | M23: =M22+L23 -> 798.72099 | N23: =+SUM(Efficiency1!C67:C69) -> 53.956354 | O23: =O22+N23 -> 788.53027 | P23: ='15'!I38 -> 51.058 | Q23: =Q22+P23 -> 727.574 | R23: ='15'!I40 -> 47.105 | S23: =S22+R23 -> 675.903 | U23: =T23+U22 -> 0 | V23: =T23/P23 -> 0 | W23: =U23/Q23 -> 0 | X23: =IF(AND(R23>0,T23>0),(T23/(R23*1000))*1000,0) -> 0 | Y23: =IF(AND(S23>0,U23>0),U23/S23,0) -> 0 | Z23: 130.8 | AA23: =Z23+AA22 -> 1818.8 | AB23: =Z23/(P23) -> 2.5617925 | AC23: =AA23/(Q23) -> 2.4998145 | AD23: =IF(AND(R23>0,Z23>0),Z23/(R23),0) -> 2.7767753 | AE23: =IF(AND(S23>0,AA23>0),AA23/(S23),0) -> 2.6909187 | AF23: ='15'!I46 -> 44240.8 | AG23: =AF23+AG22 -> 722201.6 | AH23: =IF(AND(L23>0,AF23>0),(AF23/(P23*1000)*1000),0) -> 866.48126 | AI23: =IF(AND(M23>0,AG23>0),(AG23/(Q23*1000)*1000),0) -> 992.61601 | AJ23: =IF(AND(R23>0,AF23>0),(AF23/(R23*1000)*1000),0) -> 939.19541 | AK23: =IF(AND(S23>0,AG23>0),(AG23/(S23*1000)*1000),0) -> 1068.4989 | AL23: =+SUM(Efficiency2!K67:K69) -> 53.956354 | AM23: =AM22+AL23 -> 787.73613 | AN23: =+R23/AL23 -> 0.87302044 | AO23: =+S23/AM23 -> 0.85803225
A24: =A23+1 -> 45946 | B24: Toilet/Facial | C24: 17/13 | D24: =+'16'!F42 -> 1261.2639 | E24: =+'16'!G42 -> 964.13542 | F24: =1-(E24/D24) -> 0.23557994 | G24: =+P24/N24 -> 0.90327784 | H24: =+P24/L24 -> 0.90327784 | I24: =+R24/P24 -> 1.0541995 | J24: =+R24/L24 -> 0.95223505 | K24: =+S24/M24 -> 0.85300468 | L24: =+SUM(Efficiency1!K71:K72) -> 54.517002 | M24: =M23+L24 -> 853.238 | N24: =+SUM(Efficiency1!C71:C72) -> 54.517002 | O24: =O23+N24 -> 843.04728 | P24: ='16'!I38 -> 49.244 | Q24: =Q23+P24 -> 776.818 | R24: ='16'!I40 -> 51.913 | S24: =S23+R24 -> 727.816 | U24: =T24+U23 -> 0 | V24: =T24/P24 -> 0 | W24: =U24/Q24 -> 0 | X24: =IF(AND(R24>0,T24>0),(T24/(R24*1000))*1000,0) -> 0 | Y24: =IF(AND(S24>0,U24>0),U24/S24,0) -> 0 | Z24: 130 | AA24: =Z24+AA23 -> 1948.8 | AB24: =Z24/(P24) -> 2.6399155 | AC24: =AA24/(Q24) -> 2.5086957 | AD24: =IF(AND(R24>0,Z24>0),Z24/(R24),0) -> 2.5041897 | AE24: =IF(AND(S24>0,AA24>0),AA24/(S24),0) -> 2.6775998 | AF24: ='16'!I46 -> 49460.6 | AG24: =AF24+AG23 -> 771662.2 | AH24: =IF(AND(L24>0,AF24>0),(AF24/(P24*1000)*1000),0) -> 1004.3985 | AI24: =IF(AND(M24>0,AG24>0),(AG24/(Q24*1000)*1000),0) -> 993.36292 | AJ24: =IF(AND(R24>0,AF24>0),(AF24/(R24*1000)*1000),0) -> 952.75942 | AK24: =IF(AND(S24>0,AG24>0),(AG24/(S24*1000)*1000),0) -> 1060.2435 | AL24: =+SUM(Efficiency2!K71:K72) -> 54.517002 | AM24: =AM23+AL24 -> 842.25313 | AN24: =+R24/AL24 -> 0.95223505 | AO24: =+S24/AM24 -> 0.86412977
A25: =A24+1 -> 45947 | B25: Facial | C25: 13/12 | D25: =+'17'!F42 -> 1364.5833 | E25: =+'17'!G42 -> 1027.3333 | F25: =1-(E25/D25) -> 0.24714504 | G25: =+P25/N25 -> 0.94938532 | H25: =+P25/L25 -> 0.94938532 | I25: =+R25/P25 -> 0.94167655 | J25: =+R25/L25 -> 0.89401389 | K25: =+S25/M25 -> 0.85537787 | L25: =+SUM(Efficiency1!K77:K78) -> 52.4097 | M25: =M24+L25 -> 905.6477 | N25: =+SUM(Efficiency1!C77:C78) -> 52.4097 | O25: =O24+N25 -> 895.45698 | P25: ='17'!I38 -> 49.757 | Q25: =Q24+P25 -> 826.575 | R25: ='17'!I40 -> 46.855 | S25: =S24+R25 -> 774.671 | U25: =T25+U24 -> 0 | V25: =T25/P25 -> 0 | W25: =U25/Q25 -> 0 | X25: =IF(AND(R25>0,T25>0),(T25/(R25*1000))*1000,0) -> 0 | Y25: =IF(AND(S25>0,U25>0),U25/S25,0) -> 0 | Z25: 130 | AA25: =Z25+AA24 -> 2078.8 | AB25: =Z25/(P25) -> 2.6126977 | AC25: =AA25/(Q25) -> 2.5149563 | AD25: =IF(AND(R25>0,Z25>0),Z25/(R25),0) -> 2.7745171 | AE25: =IF(AND(S25>0,AA25>0),AA25/(S25),0) -> 2.6834618 | AF25: ='17'!I46 -> 50788.14 | AG25: =AF25+AG24 -> 822450.34 | AH25: =IF(AND(L25>0,AF25>0),(AF25/(P25*1000)*1000),0) -> 1020.7235 | AI25: =IF(AND(M25>0,AG25>0),(AG25/(Q25*1000)*1000),0) -> 995.00994 | AJ25: =IF(AND(R25>0,AF25>0),(AF25/(R25*1000)*1000),0) -> 1083.9428 | AK25: =IF(AND(S25>0,AG25>0),(AG25/(S25*1000)*1000),0) -> 1061.6769 | AL25: =+SUM(Efficiency2!K77:K78) -> 52.4097 | AM25: =AM24+AL25 -> 894.66283 | AN25: =+R25/AL25 -> 0.89401389 | AO25: =+S25/AM25 -> 0.86588039
A26: =A25+1 -> 45948 | B26: Facial | C26: 12 | D26: =+'18'!F42 -> 1400 | E26: =+'18'!G42 -> 1050 | F26: =1-(E26/D26) -> 0.25 | G26: =+P26/N26 -> 0.89630181 | H26: =+P26/L26 -> 0.89630181 | I26: =+R26/P26 -> 0.98071813 | J26: =+R26/L26 -> 0.87901943 | K26: =+S26/M26 -> 0.85663363 | L26: =+Efficiency1!K81 -> 50.8032 | M26: =M25+L26 -> 956.4509 | N26: =+Efficiency1!C81 -> 50.8032 | O26: =O25+N26 -> 946.26018 | P26: ='18'!I38 -> 45.535 | Q26: =Q25+P26 -> 872.11 | R26: ='18'!I40 -> 44.657 | S26: =S25+R26 -> 819.328 | U26: =T26+U25 -> 0 | V26: =T26/P26 -> 0 | W26: =U26/Q26 -> 0 | X26: =IF(AND(R26>0,T26>0),(T26/(R26*1000))*1000,0) -> 0 | Y26: =IF(AND(S26>0,U26>0),U26/S26,0) -> 0 | Z26: 126.7 | AA26: =Z26+AA25 -> 2205.5 | AB26: =Z26/(P26) -> 2.782475 | AC26: =AA26/(Q26) -> 2.5289241 | AD26: =IF(AND(R26>0,Z26>0),Z26/(R26),0) -> 2.8371812 | AE26: =IF(AND(S26>0,AA26>0),AA26/(S26),0) -> 2.6918401 | AF26: ='18'!I46 -> 52391.97 | AG26: =AF26+AG25 -> 874842.31 | AH26: =IF(AND(L26>0,AF26>0),(AF26/(P26*1000)*1000),0) -> 1150.5868 | AI26: =IF(AND(M26>0,AG26>0),(AG26/(Q26*1000)*1000),0) -> 1003.133 | AJ26: =IF(AND(R26>0,AF26>0),(AF26/(R26*1000)*1000),0) -> 1173.2085 | AK26: =IF(AND(S26>0,AG26>0),(AG26/(S26*1000)*1000),0) -> 1067.7559 | AL26: =+Efficiency2!K81 -> 50.8032 | AM26: =AM25+AL26 -> 945.46603 | AN26: =+R26/AL26 -> 0.87901943 | AO26: =+S26/AM26 -> 0.8665864
A27: =A26+1 -> 45949 | B27: Facial | C27: 12 | D27: =+'19'!F42 -> 1397.6389 | E27: =+'19'!G42 -> 1048.2292 | F27: =1-(E27/D27) -> 0.25 | G27: =+P27/N27 -> 0.96311886 | H27: =+P27/L27 -> 0.96149455 | I27: =+R27/P27 -> 0.95776609 | J27: =+R27/L27 -> 0.92088687 | K27: =+S27/M27 -> 0.85987439 | L27: =+Efficiency1!K85 -> 50.8032 | M27: =M26+L27 -> 1007.2541 | N27: =+Efficiency1!C85 -> 50.71752 | O27: =O26+N27 -> 996.9777 | P27: ='19'!I38 -> 48.847 | Q27: =Q26+P27 -> 920.957 | R27: ='19'!I40 -> 46.784 | S27: =S26+R27 -> 866.112 | U27: =T27+U26 -> 0 | V27: =T27/P27 -> 0 | W27: =U27/Q27 -> 0 | X27: =IF(AND(R27>0,T27>0),(T27/(R27*1000))*1000,0) -> 0 | Y27: =IF(AND(S27>0,U27>0),U27/S27,0) -> 0 | Z27: 128.5 | AA27: =Z27+AA26 -> 2334 | AB27: =Z27/(P27) -> 2.6306631 | AC27: =AA27/(Q27) -> 2.5343203 | AD27: =IF(AND(R27>0,Z27>0),Z27/(R27),0) -> 2.7466655 | AE27: =IF(AND(S27>0,AA27>0),AA27/(S27),0) -> 2.6948016 | AF27: ='19'!I46 -> 54304.87 | AG27: =AF27+AG26 -> 929147.18 | AH27: =IF(AND(L27>0,AF27>0),(AF27/(P27*1000)*1000),0) -> 1111.734 | AI27: =IF(AND(M27>0,AG27>0),(AG27/(Q27*1000)*1000),0) -> 1008.8931 | AJ27: =IF(AND(R27>0,AF27>0),(AF27/(R27*1000)*1000),0) -> 1160.7573 | AK27: =IF(AND(S27>0,AG27>0),(AG27/(S27*1000)*1000),0) -> 1072.7795 | AL27: =+Efficiency2!K85 -> 50.8032 | AM27: =AM26+AL27 -> 996.26923 | AN27: =+R27/AL27 -> 0.92088687 | AO27: =+S27/AM27 -> 0.86935537
A28: =A27+1 -> 45950 | B28: Facial | C28: 12 | D28: =+'20'!F42 -> 1400 | E28: =+'20'!G42 -> 1050 | F28: =1-(E28/D28) -> 0.25 | G28: =+P28/N28 -> 1.0185118 | H28: =+P28/L28 -> 1.0185118 | I28: =+R28/P28 -> 0.98807106 | J28: =+R28/L28 -> 1.0063621 | K28: =+S28/M28 -> 0.86677509 | L28: =+Efficiency1!K89 -> 49.7952 | M28: =M27+L28 -> 1057.0493 | N28: =+Efficiency1!C89 -> 49.7952 | O28: =O27+N28 -> 1046.7729 | P28: ='20'!I38 -> 50.717 | Q28: =Q27+P28 -> 971.674 | R28: ='20'!I40 -> 50.112 | S28: =S27+R28 -> 916.224 | U28: =T28+U27 -> 0 | V28: =T28/P28 -> 0 | W28: =U28/Q28 -> 0 | X28: =IF(AND(R28>0,T28>0),(T28/(R28*1000))*1000,0) -> 0 | Y28: =IF(AND(S28>0,U28>0),U28/S28,0) -> 0 | Z28: 129.1 | AA28: =Z28+AA27 -> 2463.1 | AB28: =Z28/(P28) -> 2.5454976 | AC28: =AA28/(Q28) -> 2.5349037 | AD28: =IF(AND(R28>0,Z28>0),Z28/(R28),0) -> 2.5762292 | AE28: =IF(AND(S28>0,AA28>0),AA28/(S28),0) -> 2.6883164 | AF28: ='20'!I46 -> 51377.83 | AG28: =AF28+AG27 -> 980525.01 | AH28: =IF(AND(L28>0,AF28>0),(AF28/(P28*1000)*1000),0) -> 1013.0298 | AI28: =IF(AND(M28>0,AG28>0),(AG28/(Q28*1000)*1000),0) -> 1009.109 | AJ28: =IF(AND(R28>0,AF28>0),(AF28/(R28*1000)*1000),0) -> 1025.26 | AK28: =IF(AND(S28>0,AG28>0),(AG28/(S28*1000)*1000),0) -> 1070.1804 | AL28: =+Efficiency2!K89 -> 49.7952 | AM28: =AM27+AL28 -> 1046.0644 | AN28: =+R28/AL28 -> 1.0063621 | AO28: =+S28/AM28 -> 0.87587722
A29: =A28+1 -> 45951 | B29: Facial/Toilet | C29: 12/12,5 | D29: =+'21'!F42 -> 1361.25 | E29: =+'21'!G42 -> 1042.9694 | F29: =1-(E29/D29) -> 0.23381492 | G29: =+P29/N29 -> 0.9005983 | H29: =+P29/L29 -> 0.9005983 | I29: =+R29/P29 -> 0.90292028 | J29: =+R29/L29 -> 0.81316847 | K29: =+S29/M29 -> 0.86425919 | L29: =+SUM(Efficiency1!K93:K94) -> 52.053174 | M29: =M28+L29 -> 1109.1025 | N29: =+SUM(Efficiency2!K93:K94) -> 52.053174 | O29: =O28+N29 -> 1098.8261 | P29: ='21'!I38 -> 46.879 | Q29: =Q28+P29 -> 1018.553 | R29: ='21'!I40 -> 42.328 | S29: =S28+R29 -> 958.552 | U29: =T29+U28 -> 0 | V29: =T29/P29 -> 0 | W29: =U29/Q29 -> 0 | X29: =IF(AND(R29>0,T29>0),(T29/(R29*1000))*1000,0) -> 0 | Y29: =IF(AND(S29>0,U29>0),U29/S29,0) -> 0 | Z29: 131.8 | AA29: =Z29+AA28 -> 2594.9 | AB29: =Z29/(P29) -> 2.8114934 | AC29: =AA29/(Q29) -> 2.5476338 | AD29: =IF(AND(R29>0,Z29>0),Z29/(R29),0) -> 3.1137781 | AE29: =IF(AND(S29>0,AA29>0),AA29/(S29),0) -> 2.707104 | AF29: ='21'!I46 -> 48122.29 | AG29: =AF29+AG28 -> 1028647.3 | AH29: =IF(AND(L29>0,AF29>0),(AF29/(P29*1000)*1000),0) -> 1026.5213 | AI29: =IF(AND(M29>0,AG29>0),(AG29/(Q29*1000)*1000),0) -> 1009.9104 | AJ29: =IF(AND(R29>0,AF29>0),(AF29/(R29*1000)*1000),0) -> 1136.8902 | AK29: =IF(AND(S29>0,AG29>0),(AG29/(S29*1000)*1000),0) -> 1073.1262 | AL29: =+SUM(Efficiency2!K93:K94) -> 52.053174 | AM29: =AM28+AL29 -> 1098.1176 | AN29: =+R29/AL29 -> 0.81316847 | AO29: =+S29/AM29 -> 0.87290469
A30: =A29+1 -> 45952 | B30: Toilet | C30: 12,5/14,5/18 | D30: =+'22'!F42 -> 1257.5 | E30: =+'22'!G42 -> 963.45833 | F30: =1-(E30/D30) -> 0.23383035 | G30: =+P30/N30 -> 0.97865227 | H30: =+P30/L30 -> 0.97168991 | I30: =+R30/P30 -> 0.97862957 | J30: =+R30/L30 -> 0.95092448 | K30: =+S30/M30 -> 0.86842517 | L30: =+SUM(Efficiency1!K97:K99) -> 56.006551 | M30: =M29+L30 -> 1165.109 | N30: =+SUM(Efficiency1!C97:C99) -> 55.608107 | O30: =O29+N30 -> 1154.4342 | P30: ='22'!I38 -> 54.421 | Q30: =Q29+P30 -> 1072.974 | R30: ='22'!I40 -> 53.258 | S30: =S29+R30 -> 1011.81 | U30: =T30+U29 -> 0 | V30: =T30/P30 -> 0 | W30: =U30/Q30 -> 0 | X30: =IF(AND(R30>0,T30>0),(T30/(R30*1000))*1000,0) -> 0 | Y30: =IF(AND(S30>0,U30>0),U30/S30,0) -> 0 | Z30: 134.2 | AA30: =Z30+AA29 -> 2729.1 | AB30: =Z30/(P30) -> 2.4659598 | AC30: =AA30/(Q30) -> 2.5434913 | AD30: =IF(AND(R30>0,Z30>0),Z30/(R30),0) -> 2.5198092 | AE30: =IF(AND(S30>0,AA30>0),AA30/(S30),0) -> 2.6972455 | AF30: ='22'!I46 -> 44206.22 | AG30: =AF30+AG29 -> 1072853.5 | AH30: =IF(AND(L30>0,AF30>0),(AF30/(P30*1000)*1000),0) -> 812.30077 | AI30: =IF(AND(M30>0,AG30>0),(AG30/(Q30*1000)*1000),0) -> 999.88771 | AJ30: =IF(AND(R30>0,AF30>0),(AF30/(R30*1000)*1000),0) -> 830.03906 | AK30: =IF(AND(S30>0,AG30>0),(AG30/(S30*1000)*1000),0) -> 1060.331 | AL30: =+SUM(Efficiency2!K97:K99) -> 56.006551 | AM30: =AM29+AL30 -> 1154.1242 | AN30: =+R30/AL30 -> 0.95092448 | AO30: =+S30/AM30 -> 0.87669078
A31: =A30+1 -> 45953 | B31: Toilet | C31: 18/14,5/12,5 | D31: =+'23'!F42 -> 1166.4236 | E31: =+'23'!G42 -> 886.48194 | F31: =1-(E31/D31) -> 0.24 | G31: =+P31/N31 -> 0.97533627 | H31: =+P31/L31 -> 0.96567135 | I31: =+R31/P31 -> 0.69476082 | J31: =+R31/L31 -> 0.67091062 | K31: =+S31/M31 -> 0.8593099 | L31: =+SUM(Efficiency1!K101:K103) -> 56.371146 | M31: =M30+L31 -> 1221.4802 | N31: =+SUM(Efficiency1!C101:C103) -> 55.812546 | O31: =O30+N31 -> 1210.2467 | P31: ='23'!I38 -> 54.436 | Q31: =Q30+P31 -> 1127.41 | R31: ='23'!I40 -> 37.82 | S31: =S30+R31 -> 1049.63 | U31: =T31+U30 -> 0 | V31: =T31/P31 -> 0 | W31: =U31/Q31 -> 0 | X31: =IF(AND(R31>0,T31>0),(T31/(R31*1000))*1000,0) -> 0 | Y31: =IF(AND(S31>0,U31>0),U31/S31,0) -> 0 | Z31: 128.9 | AA31: =Z31+AA30 -> 2858 | AB31: =Z31/(P31) -> 2.3679183 | AC31: =AA31/(Q31) -> 2.5350139 | AD31: =IF(AND(R31>0,Z31>0),Z31/(R31),0) -> 3.4082496 | AE31: =IF(AND(S31>0,AA31>0),AA31/(S31),0) -> 2.7228642 | AF31: ='23'!I46 -> 42635.91 | AG31: =AF31+AG30 -> 1115489.4 | AH31: =IF(AND(L31>0,AF31>0),(AF31/(P31*1000)*1000),0) -> 783.23003 | AI31: =IF(AND(M31>0,AG31>0),(AG31/(Q31*1000)*1000),0) -> 989.42659 | AJ31: =IF(AND(R31>0,AF31>0),(AF31/(R31*1000)*1000),0) -> 1127.3377 | AK31: =IF(AND(S31>0,AG31>0),(AG31/(S31*1000)*1000),0) -> 1062.7454 | AL31: =+SUM(Efficiency2!K101:K103) -> 49.585209 | AM31: =AM30+AL31 -> 1203.7094 | AN31: =+R31/AL31 -> 0.76272745 | AO31: =+S31/AM31 -> 0.87199621
A32: =A31+1 -> 45954 | B32: Toilet | C32: 12,5/18/14,5/15 | D32: =+'24'!F42 -> 1287.7083 | E32: =+'24'!G42 -> 988.41528 | F32: =1-(E32/D32) -> 0.23242302 | G32: =+P32/N32 -> 0.93501853 | H32: =+P32/L32 -> 0.90167523 | I32: =+R32/P32 -> 0.86105411 | J32: =+R32/L32 -> 0.77639117 | K32: =+S32/M32 -> 0.85572904 | L32: =+SUM(Efficiency1!K106:K109) -> 55.130715 | M32: =M31+L32 -> 1276.6109 | N32: =+SUM(Efficiency1!C106:C109) -> 53.164722 | O32: =O31+N32 -> 1263.4114 | P32: ='24'!I38 -> 49.71 | Q32: =Q31+P32 -> 1177.12 | R32: ='24'!I40 -> 42.803 | S32: =S31+R32 -> 1092.433 | U32: =T32+U31 -> 0 | V32: =T32/P32 -> 0 | W32: =U32/Q32 -> 0 | X32: =IF(AND(R32>0,T32>0),(T32/(R32*1000))*1000,0) -> 0 | Y32: =IF(AND(S32>0,U32>0),U32/S32,0) -> 0 | Z32: 132 | AA32: =Z32+AA31 -> 2990 | AB32: =Z32/(P32) -> 2.6554013 | AC32: =AA32/(Q32) -> 2.5400979 | AD32: =IF(AND(R32>0,Z32>0),Z32/(R32),0) -> 3.083896 | AE32: =IF(AND(S32>0,AA32>0),AA32/(S32),0) -> 2.73701 | AF32: =+'24'!I46 -> 47208.19 | AG32: =AF32+AG31 -> 1162697.6 | AH32: =IF(AND(L32>0,AF32>0),(AF32/(P32*1000)*1000),0) -> 949.6719 | AI32: =IF(AND(M32>0,AG32>0),(AG32/(Q32*1000)*1000),0) -> 987.74774 | AJ32: =IF(AND(R32>0,AF32>0),(AF32/(R32*1000)*1000),0) -> 1102.9178 | AK32: =IF(AND(S32>0,AG32>0),(AG32/(S32*1000)*1000),0) -> 1064.3194 | AL32: =+SUM(Efficiency2!K106:K109) -> 55.130715 | AM32: =AM31+AL32 -> 1258.8401 | AN32: =+R32/AL32 -> 0.77639117 | AO32: =+S32/AM32 -> 0.8678092
A33: =A32+1 -> 45955 | B33: Toilet | C33: 12,5 | D33: =+'25'!F42 -> 1393.3333 | E33: =+'25'!G42 -> 1058.9333 | F33: =1-(E33/D33) -> 0.24 | G33: =+P33/N33 -> 0.94415519 | H33: =+P33/L33 -> 0.93965922 | I33: =+R33/P33 -> 0.94662686 | J33: =+R33/L33 -> 0.88950665 | K33: =+S33/M33 -> 0.85705205 | L33: =+Efficiency1!K111 -> 52.041207 | M33: =M32+L33 -> 1328.6521 | N33: =+Efficiency1!C111 -> 51.793392 | O33: =O32+N33 -> 1315.2048 | P33: ='25'!I38 -> 48.901 | Q33: =Q32+P33 -> 1226.021 | R33: ='25'!I40 -> 46.291 | S33: =S32+R33 -> 1138.724 | U33: =T33+U32 -> 0 | V33: =T33/P33 -> 0 | W33: =U33/Q33 -> 0 | X33: =IF(AND(R33>0,T33>0),(T33/(R33*1000))*1000,0) -> 0 | Y33: =IF(AND(S33>0,U33>0),U33/S33,0) -> 0 | Z33: 134.9 | AA33: =Z33+AA32 -> 3124.9 | AB33: =Z33/(P33) -> 2.7586348 | AC33: =AA33/(Q33) -> 2.5488144 | AD33: =IF(AND(R33>0,Z33>0),Z33/(R33),0) -> 2.9141734 | AE33: =IF(AND(S33>0,AA33>0),AA33/(S33),0) -> 2.7442119 | AF33: =+'25'!I46 -> 49875.96 | AG33: =AF33+AG32 -> 1212573.6 | AH33: =IF(AND(L33>0,AF33>0),(AF33/(P33*1000)*1000),0) -> 1019.9374 | AI33: =IF(AND(M33>0,AG33>0),(AG33/(Q33*1000)*1000),0) -> 989.03165 | AJ33: =IF(AND(R33>0,AF33>0),(AF33/(R33*1000)*1000),0) -> 1077.444 | AK33: =IF(AND(S33>0,AG33>0),(AG33/(S33*1000)*1000),0) -> 1064.8529 | AL33: =+Efficiency2!K111 -> 52.041207 | AM33: =AM32+AL33 -> 1310.8813 | AN33: =+R33/AL33 -> 0.88950665 | AO33: =+S33/AM33 -> 0.86867058
A34: =A33+1 -> 45956 | B34: Toilet | C34: 12,5 | D34: =+'26'!F42 -> 1394.0208 | E34: =+'26'!G42 -> 1059.4558 | F34: =1-(E34/D34) -> 0.24 | G34: =+P34/N34 -> 0.91710889 | H34: =+P34/L34 -> 0.91319207 | I34: =+R34/P34 -> 0.88928393 | J34: =+R34/L34 -> 0.81208704 | K34: =+S34/M34 -> 0.85533759 | L34: =+Efficiency1!K115 -> 52.668 | M34: =M33+L34 -> 1381.3201 | N34: =+Efficiency1!C115 -> 52.443064 | O34: =O33+N34 -> 1367.6479 | P34: ='26'!I38 -> 48.096 | Q34: =Q33+P34 -> 1274.117 | R34: ='26'!I40 -> 42.771 | S34: =S33+R34 -> 1181.495 | U34: =T34+U33 -> 0 | V34: =T34/P34 -> 0 | W34: =U34/Q34 -> 0 | X34: =IF(AND(R34>0,T34>0),(T34/(R34*1000))*1000,0) -> 0 | Y34: =IF(AND(S34>0,U34>0),U34/S34,0) -> 0 | Z34: 135.8 | AA34: =Z34+AA33 -> 3260.7 | AB34: =Z34/(P34) -> 2.8235196 | AC34: =AA34/(Q34) -> 2.5591841 | AD34: =IF(AND(R34>0,Z34>0),Z34/(R34),0) -> 3.1750485 | AE34: =IF(AND(S34>0,AA34>0),AA34/(S34),0) -> 2.7598085 | AF34: ='26'!I46 -> 47430.33 | AG34: =AF34+AG33 -> 1260003.9 | AH34: =IF(AND(L34>0,AF34>0),(AF34/(P34*1000)*1000),0) -> 986.15956 | AI34: =IF(AND(M34>0,AG34>0),(AG34/(Q34*1000)*1000),0) -> 988.92324 | AJ34: =IF(AND(R34>0,AF34>0),(AF34/(R34*1000)*1000),0) -> 1108.9367 | AK34: =IF(AND(S34>0,AG34>0),(AG34/(S34*1000)*1000),0) -> 1066.4488 | AL34: =+Efficiency2!K115 -> 52.668 | AM34: =AM33+AL34 -> 1363.5493 | AN34: =+R34/AL34 -> 0.81208704 | AO34: =+S34/AM34 -> 0.866485
A35: =A34+1 -> 45957 | B35: Toilet/Facial | C35: 12,5/12 | D35: =+'27'!F42 -> 1398.2014 | E35: =+'27'!G42 -> 1062.6331 | F35: =1-(E35/D35) -> 0.24 | G35: =+P35/N35 -> 0.9137336 | H35: =+P35/L35 -> 0.91254251 | I35: =+R35/P35 -> 0.8055016 | J35: =+R35/L35 -> 0.73505446 | K35: =+S35/M35 -> 0.85098126 | L35: =+SUM(Efficiency1!K119:K120) -> 51.907719 | M35: =M34+L35 -> 1433.2278 | N35: =+SUM(Efficiency1!C119:C120) -> 51.840055 | O35: =O34+N35 -> 1419.488 | P35: ='27'!I38 -> 47.368 | Q35: =Q34+P35 -> 1321.485 | R35: ='27'!I40 -> 38.155 | S35: =S34+R35 -> 1219.65 | U35: =T35+U34 -> 0 | V35: =T35/P35 -> 0 | W35: =U35/Q35 -> 0 | X35: =IF(AND(R35>0,T35>0),(T35/(R35*1000))*1000,0) -> 0 | Y35: =IF(AND(S35>0,U35>0),U35/S35,0) -> 0 | Z35: 133.1 | AA35: =Z35+AA34 -> 3393.8 | AB35: =Z35/(P35) -> 2.8099139 | AC35: =AA35/(Q35) -> 2.5681714 | AD35: =IF(AND(R35>0,Z35>0),Z35/(R35),0) -> 3.4884026 | AE35: =IF(AND(S35>0,AA35>0),AA35/(S35),0) -> 2.7826016 | AF35: ='27'!I46 -> 49997.73 | AG35: =AF35+AG34 -> 1310001.6 | AH35: =IF(AND(L35>0,AF35>0),(AF35/(P35*1000)*1000),0) -> 1055.517 | AI35: =IF(AND(M35>0,AG35>0),(AG35/(Q35*1000)*1000),0) -> 991.31026 | AJ35: =IF(AND(R35>0,AF35>0),(AF35/(R35*1000)*1000),0) -> 1310.3847 | AK35: =IF(AND(S35>0,AG35>0),(AG35/(S35*1000)*1000),0) -> 1074.08 | AL35: =+SUM(Efficiency2!K119:K120) -> 51.907719 | AM35: =AM34+AL35 -> 1415.457 | AN35: =+R35/AL35 -> 0.73505446 | AO35: =+S35/AM35 -> 0.86166517
A36: =A35+1 -> 45958 | B36: Facial | C36: 12/13 | D36: =+'28'!F42 -> 1385.625 | E36: =+'28'!G42 -> 1053.075 | F36: =1-(E36/D36) -> 0.24 | G36: =+P36/N36 -> 0.8896474 | H36: =+P36/L36 -> 0.88521159 | I36: =+R36/P36 -> 0.89565121 | J36: =+R36/L36 -> 0.79284083 | K36: =+S36/M36 -> 0.8489818 | L36: =+SUM(Efficiency1!K123:K124) -> 51.044293 | M36: =M35+L36 -> 1484.2721 | N36: =+SUM(Efficiency1!C123:C124) -> 50.789785 | O36: =O35+N36 -> 1470.2777 | P36: ='28'!I38 -> 45.185 | Q36: =Q35+P36 -> 1366.67 | R36: ='28'!I40 -> 40.47 | S36: =S35+R36 -> 1260.12 | U36: =T36+U35 -> 0 | V36: =T36/P36 -> 0 | W36: =U36/Q36 -> 0 | X36: =IF(AND(R36>0,T36>0),(T36/(R36*1000))*1000,0) -> 0 | Y36: =IF(AND(S36>0,U36>0),U36/S36,0) -> 0 | Z36: 133.6 | AA36: =Z36+AA35 -> 3527.4 | AB36: =Z36/(P36) -> 2.9567334 | AC36: =AA36/(Q36) -> 2.5810181 | AD36: =IF(AND(R36>0,Z36>0),Z36/(R36),0) -> 3.3012108 | AE36: =IF(AND(S36>0,AA36>0),AA36/(S36),0) -> 2.7992572 | AF36: ='28'!I46 -> 45213.17 | AG36: =AF36+AG35 -> 1355214.8 | AH36: =IF(AND(L36>0,AF36>0),(AF36/(P36*1000)*1000),0) -> 1000.6234 | AI36: =IF(AND(M36>0,AG36>0),(AG36/(Q36*1000)*1000),0) -> 991.61817 | AJ36: =IF(AND(R36>0,AF36>0),(AF36/(R36*1000)*1000),0) -> 1117.2021 | AK36: =IF(AND(S36>0,AG36>0),(AG36/(S36*1000)*1000),0) -> 1075.4649 | AL36: =+SUM(Efficiency2!K123:K124) -> 51.044293 | AM36: =AM35+AL36 -> 1466.5013 | AN36: =+R36/AL36 -> 0.79284083 | AO36: =+S36/AM36 -> 0.85926961
A37: =A36+1 -> 45959 | B37: Facial | C37: 13/12 | D37: =+'29'!F42 -> 1370 | E37: =+'29'!G42 -> 1041.2 | F37: =1-(E37/D37) -> 0.24 | G37: =+P37/N37 -> 0.91447309 | H37: =+P37/L37 -> 0.90515036 | I37: =+R37/P37 -> 0.91337815 | J37: =+R37/L37 -> 0.82674456 | K37: =+S37/M37 -> 0.8482277 | L37: =+SUM(Efficiency1!K127:K128) -> 52.100736 | M37: =M36+L37 -> 1536.3728 | N37: =+SUM(Efficiency1!C127:C128) -> 51.569587 | O37: =O36+N37 -> 1521.8473 | P37: ='29'!I38 -> 47.159 | Q37: =Q36+P37 -> 1413.829 | R37: ='29'!I40 -> 43.074 | S37: =S36+R37 -> 1303.194 | U37: =T37+U36 -> 0 | V37: =T37/P37 -> 0 | W37: =U37/Q37 -> 0 | X37: =IF(AND(R37>0,T37>0),(T37/(R37*1000))*1000,0) -> 0 | Y37: =IF(AND(S37>0,U37>0),U37/S37,0) -> 0 | Z37: 136.2 | AA37: =Z37+AA36 -> 3663.6 | AB37: =Z37/(P37) -> 2.888102 | AC37: =AA37/(Q37) -> 2.591261 | AD37: =IF(AND(R37>0,Z37>0),Z37/(R37),0) -> 3.1620003 | AE37: =IF(AND(S37>0,AA37>0),AA37/(S37),0) -> 2.8112468 | AF37: ='29'!I46 -> 49073.74 | AG37: =AF37+AG36 -> 1404288.5 | AH37: =IF(AND(L37>0,AF37>0),(AF37/(P37*1000)*1000),0) -> 1040.6018 | AI37: =IF(AND(M37>0,AG37>0),(AG37/(Q37*1000)*1000),0) -> 993.25205 | AJ37: =IF(AND(R37>0,AF37>0),(AF37/(R37*1000)*1000),0) -> 1139.2891 | AK37: =IF(AND(S37>0,AG37>0),(AG37/(S37*1000)*1000),0) -> 1077.5744 | AL37: =+SUM(Efficiency2!K127:K128) -> 52.100736 | AM37: =AM36+AL37 -> 1518.602 | AN37: =+R37/AL37 -> 0.82674456 | AO37: =+S37/AM37 -> 0.85815373
A38: =A37+1 -> 45960 | B38: Facial/Toilet | C38: 12/12,5 | D38: =+'30'!F42 -> 1388.3333 | E38: =+'30'!G42 -> 1059.1 | F38: =1-(E38/D38) -> 0.23714286 | G38: =+P38/N38 -> 0.93759555 | H38: =+P38/L38 -> 0.93250723 | I38: =+R38/P38 -> 0.80176048 | J38: =+R38/L38 -> 0.74764745 | K38: =+S38/M38 -> 0.8449262 | L38: =+SUM(Efficiency1!K131:K132) -> 52.142223 | M38: =M37+L38 -> 1588.5151 | N38: =+SUM(Efficiency1!C131:C132) -> 51.859248 | O38: =O37+N38 -> 1573.7066 | P38: ='30'!I38 -> 48.623 | Q38: =Q37+P38 -> 1462.452 | R38: ='30'!I40 -> 38.984 | S38: =S37+R38 -> 1342.178 | U38: =T38+U37 -> 0 | V38: =T38/P38 -> 0 | W38: =U38/Q38 -> 0 | X38: =IF(AND(R38>0,T38>0),(T38/(R38*1000))*1000,0) -> 0 | Y38: =IF(AND(S38>0,U38>0),U38/S38,0) -> 0 | Z38: 138.3 | AA38: =Z38+AA37 -> 3801.9 | AB38: =Z38/(P38) -> 2.8443329 | AC38: =AA38/(Q38) -> 2.5996751 | AD38: =IF(AND(R38>0,Z38>0),Z38/(R38),0) -> 3.5476093 | AE38: =IF(AND(S38>0,AA38>0),AA38/(S38),0) -> 2.8326347 | AF38: ='30'!I46 -> 55118.02 | AG38: =AF38+AG37 -> 1459406.6 | AH38: =IF(AND(L38>0,AF38>0),(AF38/(P38*1000)*1000),0) -> 1133.5792 | AI38: =IF(AND(M38>0,AG38>0),(AG38/(Q38*1000)*1000),0) -> 997.91758 | AJ38: =IF(AND(R38>0,AF38>0),(AF38/(R38*1000)*1000),0) -> 1413.8626 | AK38: =IF(AND(S38>0,AG38>0),(AG38/(S38*1000)*1000),0) -> 1087.342 | AL38: =+SUM(Efficiency2!K131:K132) -> 52.142223 | AM38: =AM37+AL38 -> 1570.7443 | AN38: =+R38/AL38 -> 0.74764745 | AO38: =+S38/AM38 -> 0.85448538
A39: =A38+1 -> 45961 | B39: Toilet | C39: 12,5/13 | D39: =+'31'!F42 -> 1357.9167 | E39: =+'31'!G42 -> 1045.5958 | F39: =1-(E39/D39) -> 0.23 | G39: =+P39/N39 -> 0.9495878 | H39: =+P39/L39 -> 0.93601602 | I39: =+R39/P39 -> 0.89861238 | J39: =+R39/L39 -> 0.84111559 | K39: =+S39/M39 -> 0.84480151 | L39: =+SUM(Efficiency1!K135:K136) -> 53.740533 | M39: =M38+L39 -> 1642.2556 | N39: =+SUM(Efficiency1!C135:C136) -> 52.972458 | O39: =O38+N39 -> 1626.679 | P39: ='31'!I38 -> 50.302 | Q39: =Q38+P39 -> 1512.754 | R39: ='31'!I40 -> 45.202 | S39: =S38+R39 -> 1387.38 | U39: =T39+U38 -> 0 | V39: =T39/P39 -> 0 | W39: =U39/Q39 -> 0 | X39: =IF(AND(R39>0,T39>0),(T39/(R39*1000))*1000,0) -> 0 | Y39: =IF(AND(S39>0,U39>0),U39/S39,0) -> 0 | Z39: 140.3 | AA39: =Z39+AA38 -> 3942.2 | AB39: =Z39/(P39) -> 2.7891535 | AC39: =AA39/(Q39) -> 2.6059756 | AD39: =IF(AND(R39>0,Z39>0),Z39/(R39),0) -> 3.103845 | AE39: =IF(AND(S39>0,AA39>0),AA39/(S39),0) -> 2.841471 | AF39: ='31'!I46 -> 59209.96 | AG39: =AF39+AG38 -> 1518616.5 | AH39: =IF(AND(L39>0,AF39>0),(AF39/(P39*1000)*1000),0) -> 1177.0896 | AI39: =IF(AND(M39>0,AG39>0),(AG39/(Q39*1000)*1000),0) -> 1003.8754 | AJ39: =IF(AND(R39>0,AF39>0),(AF39/(R39*1000)*1000),0) -> 1309.8969 | AK39: =IF(AND(S39>0,AG39>0),(AG39/(S39*1000)*1000),0) -> 1094.5931 | AL39: =+SUM(Efficiency2!K135:K136) -> 53.740533 | AM39: =AM38+AL39 -> 1624.4848 | AN39: =+R39/AL39 -> 0.84111559 | AO39: =+S39/AM39 -> 0.85404309
G41: =+P41/N41 -> 0.92996465 | H41: =+P41/L41 -> 0.92114407 | I41: =+R41/P41 -> 0.91712202 | J41: =+R41/L41 -> 0.84480151 | L41: =SUM(L9:L39) -> 1642.2556 | N41: =SUM(N9:N39) -> 1626.679 | P41: =SUM(P9:P39) -> 1512.754 | R41: =SUM(R9:R39) -> 1387.38 | T41: =SUM(T9:T39) -> 0 | V41: =T41/P41 -> 0 | X41: =IF(AND(R41>0,T41>0),(T41/(R41*1000))*1000,0) -> 0 | Z41: =SUM(Z9:Z40) -> 3942.2 | AB41: =Z41/P41 -> 2.6059756 | AD41: =Z41/R41 -> 2.841471 | AF41: =SUM(AF9:AF39) -> 1518616.5 | AH41: =AF41/P41 -> 1003.8754 | AJ41: =AF41/R41 -> 1094.5931 | AL41: =SUM(AL9:AL39) -> 1624.4848 | AN41: =+R41/AL41 -> 0.85404309

Sheet GRAFIK

Sheet Listrik
A2: MACHINE POWER CONSUMPTION (PER PANEL)
A4: Date | B4: PM (TON) | C4: FINSHED GOODS (TON) | AN4: Total PM16
D5: Vacuum A | H5: Vacuum B | L5: MCC Aux TM | P5: Multi Screen | T5: MCC | X5: Drive Panel | AB5: Aux Panel | AF5: Stock Prep | AJ5: Pulper
D6: KWH | E6: Consumption | F6: /TON PM | G6: /TON FG | H6: KWH | I6: Consumption | J6: /TON PM | K6: /TON FG | L6: KWH | M6: Consumption | N6: /TON PM | O6: /TON FG | P6: KWH | Q6: Consumption | R6: /TON PM | S6: /TON FG | T6: KWH | U6: Consumption | V6: /TON PM | W6: /TON FG | X6: KWH | Y6: Consumption | Z6: /TON PM | AA6: /TON FG | AB6: KWH | AC6: Consumption | AD6: /TON PM | AE6: /TON FG | AF6: KWH | AG6: Consumption | AH6: /TON PM | AI6: /TON FG | AJ6: KWH | AK6: Consumption | AL6: /TON PM | AM6: /TON FG | AN6: Consumption | AO6: /TON PM | AP6: /TON FG
A8: =+Report1!A9 -> 45931 | B8: =+Report1!P9 -> 28.605 | C8: =+Report1!R9 -> 18.686 | D8: =+D7+E8 -> 0 | F8: =E8/B8 -> 0 | G8: =E8/C8 -> 0 | H8: =+H7+I8 -> 0 | I8: 0 | J8: =I8/B8 -> 0 | K8: =I8/C8 -> 0 | L8: =+L7+M8 -> 0 | N8: =M8/B8 -> 0 | O8: =M8/C8 -> 0 | P8: =+P7+Q8 -> 0 | R8: =Q8/B8 -> 0 | S8: =Q8/C8 -> 0 | T8: =+T7+U8 -> 6818.65 | U8: =+[1]DailyOct!AT7 -> 6818.65 | V8: =U8/B8 -> 238.37266 | W8: =U8/C8 -> 364.90688 | X8: =+X7+Y8 -> 8000 | Y8: =+[1]DailyOct!AU7 -> 8000 | Z8: =Y8/B8 -> 279.67139 | AA8: =Y8/C8 -> 428.12801 | AB8: =+AB7+AC8 -> 8568.65 | AC8: =+[1]DailyOct!AV7 -> 8568.65 | AD8: =AC8/B8 -> 299.55078 | AE8: =AC8/C8 -> 458.55988 | AF8: =+AF7+AG8 -> 12937.3 | AG8: =+[1]DailyOct!AW7 -> 12937.3 | AH8: =AG8/B8 -> 452.27408 | AI8: =AG8/C8 -> 692.35256 | AJ8: =+AJ7+AK8 -> 1080 | AK8: =+[1]DailyOct!AX7 -> 1080 | AL8: =AK8/B8 -> 37.755637 | AM8: =AK8/C8 -> 57.797281 | AN8: =+E8+I8+M8+Q8+U8+Y8+AC8+AG8+AK8 -> 37404.6 | AO8: =AN8/B8 -> 1307.6245 | AP8: =AN8/C8 -> 2001.7446 | AT8: Off Reel | AU8: Off Rewinder
A9: =A8+1 -> 45932 | B9: =+Report1!P10 -> 50.266 | C9: =+Report1!R10 -> 50.273 | D9: =+D8+E9 -> 0 | F9: =E9/B9 -> 0 | G9: =E9/C9 -> 0 | H9: =+H8+I9 -> 0 | J9: =I9/B9 -> 0 | K9: =I9/C9 -> 0 | L9: =+L8+M9 -> 0 | N9: =M9/B9 -> 0 | O9: =M9/C9 -> 0 | P9: =+P8+Q9 -> 0 | R9: =Q9/B9 -> 0 | S9: =Q9/C9 -> 0 | T9: =+T8+U9 -> 13895.74 | U9: =+[1]DailyOct!AT8 -> 7077.09 | V9: =U9/B9 -> 140.79278 | W9: =U9/C9 -> 140.77318 | X9: =+X8+Y9 -> 18000 | Y9: =+[1]DailyOct!AU8 -> 10000 | Z9: =Y9/B9 -> 198.94163 | AA9: =Y9/C9 -> 198.91393 | AB9: =+AB8+AC9 -> 20945.74 | AC9: =+[1]DailyOct!AV8 -> 12377.09 | AD9: =AC9/B9 -> 246.23185 | AE9: =AC9/C9 -> 246.19756 | AF9: =+AF8+AG9 -> 25891.48 | AG9: =+[1]DailyOct!AW8 -> 12954.18 | AH9: =AG9/B9 -> 257.71257 | AI9: =AG9/C9 -> 257.67669 | AJ9: =+AJ8+AK9 -> 2790 | AK9: =+[1]DailyOct!AX8 -> 1710 | AL9: =AK9/B9 -> 34.019019 | AM9: =AK9/C9 -> 34.014282 | AN9: =+E9+I9+M9+Q9+U9+Y9+AC9+AG9+AK9 -> 44118.36 | AO9: =AN9/B9 -> 877.69785 | AP9: =AN9/C9 -> 877.57564 | AT9: Kwh/ ton | AU9: Kwh/ ton
A10: =A9+1 -> 45933 | B10: =+Report1!P11 -> 49.029 | C10: =+Report1!R11 -> 42.622 | D10: =+D9+E10 -> 0 | F10: =E10/B10 -> 0 | G10: =E10/C10 -> 0 | H10: =+H9+I10 -> 0 | J10: =I10/B10 -> 0 | K10: =I10/C10 -> 0 | L10: =+L9+M10 -> 0 | N10: =M10/B10 -> 0 | O10: =M10/C10 -> 0 | P10: =+P9+Q10 -> 0 | R10: =Q10/B10 -> 0 | S10: =Q10/C10 -> 0 | T10: =+T9+U10 -> 20731.85 | U10: =+[1]DailyOct!AT9 -> 6836.11 | V10: =U10/B10 -> 139.42993 | W10: =U10/C10 -> 160.38924 | X10: =+X9+Y10 -> 32000 | Y10: =+[1]DailyOct!AU9 -> 14000 | Z10: =Y10/B10 -> 285.54529 | AA10: =Y10/C10 -> 328.46887 | AB10: =+AB9+AC10 -> 30631.85 | AC10: =+[1]DailyOct!AV9 -> 9686.11 | AD10: =AC10/B10 -> 197.55879 | AE10: =AC10/C10 -> 227.25611 | AF10: =+AF9+AG10 -> 39263.7 | AG10: =+[1]DailyOct!AW9 -> 13372.22 | AH10: =AG10/B10 -> 272.74103 | AI10: =AG10/C10 -> 313.73985 | AJ10: =+AJ9+AK10 -> 4050 | AK10: =+[1]DailyOct!AX9 -> 1260 | AL10: =AK10/B10 -> 25.699076 | AM10: =AK10/C10 -> 29.562198 | AN10: =+E10+I10+M10+Q10+U10+Y10+AC10+AG10+AK10 -> 45154.44 | AO10: =AN10/B10 -> 920.97412 | AP10: =AN10/C10 -> 1059.4163 | AT10: Kwh/ ton | AU10: Kwh/ ton
A11: =A10+1 -> 45934 | B11: =+Report1!P12 -> 48.988 | C11: =+Report1!R12 -> 46.851 | D11: =+D10+E11 -> 0 | F11: =E11/B11 -> 0 | G11: =E11/C11 -> 0 | H11: =+H10+I11 -> 0 | J11: =I11/B11 -> 0 | K11: =I11/C11 -> 0 | L11: =+L10+M11 -> 0 | N11: =M11/B11 -> 0 | O11: =M11/C11 -> 0 | P11: =+P10+Q11 -> 0 | R11: =Q11/B11 -> 0 | S11: =Q11/C11 -> 0 | T11: =+T10+U11 -> 26995.07 | U11: =+[1]DailyOct!AT10 -> 6263.22 | V11: =U11/B11 -> 127.85213 | W11: =U11/C11 -> 133.68381 | X11: =+X10+Y11 -> 50000 | Y11: =+[1]DailyOct!AU10 -> 18000 | Z11: =Y11/B11 -> 367.43692 | AA11: =Y11/C11 -> 384.19671 | AB11: =+AB10+AC11 -> 41445.07 | AC11: =+[1]DailyOct!AV10 -> 10813.22 | AD11: =AC11/B11 -> 220.73202 | AE11: =AC11/C11 -> 230.8002 | AF11: =+AF10+AG11 -> 52490.14 | AG11: =+[1]DailyOct!AW10 -> 13226.44 | AH11: =AG11/B11 -> 269.99347 | AI11: =AG11/C11 -> 282.3086 | AJ11: =+AJ10+AK11 -> 5790 | AK11: =+[1]DailyOct!AX10 -> 1740 | AL11: =AK11/B11 -> 35.518903 | AM11: =AK11/C11 -> 37.139015 | AN11: =+E11+I11+M11+Q11+U11+Y11+AC11+AG11+AK11 -> 50042.88 | AO11: =AN11/B11 -> 1021.5334 | AP11: =AN11/C11 -> 1068.1283 | AS11: Vacuum B | AT11: =+J39 -> 0 | AU11: =+K39 -> 0
A12: =A11+1 -> 45935 | B12: =+Report1!P13 -> 45.582 | C12: =+Report1!R13 -> 42.722 | D12: =+D11+E12 -> 0 | F12: =E12/B12 -> 0 | G12: =E12/C12 -> 0 | H12: =+H11+I12 -> 0 | J12: =I12/B12 -> 0 | K12: =I12/C12 -> 0 | L12: =+L11+M12 -> 0 | N12: =M12/B12 -> 0 | O12: =M12/C12 -> 0 | P12: =+P11+Q12 -> 0 | R12: =Q12/B12 -> 0 | S12: =Q12/C12 -> 0 | T12: =+T11+U12 -> 34055.31 | U12: =+[1]DailyOct!AT11 -> 7060.24 | V12: =U12/B12 -> 154.89097 | W12: =U12/C12 -> 165.26005 | X12: =+X11+Y12 -> 66000 | Y12: =+[1]DailyOct!AU11 -> 16000 | Z12: =Y12/B12 -> 351.01575 | AA12: =Y12/C12 -> 374.5143 | AB12: =+AB11+AC12 -> 51905.31 | AC12: =+[1]DailyOct!AV11 -> 10460.24 | AD12: =AC12/B12 -> 229.48181 | AE12: =AC12/C12 -> 244.84434 | AF12: =+AF11+AG12 -> 66210.62 | AG12: =+[1]DailyOct!AW11 -> 13720.48 | AH12: =AG12/B12 -> 301.00654 | AI12: =AG12/C12 -> 321.15725 | AJ12: =+AJ11+AK12 -> 7290 | AK12: =+[1]DailyOct!AX11 -> 1500 | AL12: =AK12/B12 -> 32.907727 | AM12: =AK12/C12 -> 35.110716 | AN12: =+E12+I12+M12+Q12+U12+Y12+AC12+AG12+AK12 -> 48740.96 | AO12: =AN12/B12 -> 1069.3028 | AP12: =AN12/C12 -> 1140.8867 | AS12: MCC Aux TM | AT12: =+N39 -> 0 | AU12: =+O39 -> 0
A13: =A12+1 -> 45936 | B13: =+Report1!P14 -> 45.806 | C13: =+Report1!R14 -> 44.849 | D13: =+D12+E13 -> 0 | F13: =E13/B13 -> 0 | G13: =E13/C13 -> 0 | H13: =+H12+I13 -> 0 | J13: =I13/B13 -> 0 | K13: =I13/C13 -> 0 | L13: =+L12+M13 -> 0 | N13: =M13/B13 -> 0 | O13: =M13/C13 -> 0 | P13: =+P12+Q13 -> 0 | R13: =Q13/B13 -> 0 | S13: =Q13/C13 -> 0 | T13: =+T12+U13 -> 41667.68 | U13: =+[1]DailyOct!AT12 -> 7612.37 | V13: =U13/B13 -> 166.18718 | W13: =U13/C13 -> 169.73333 | X13: =+X12+Y13 -> 83000 | Y13: =+[1]DailyOct!AU12 -> 17000 | Z13: =Y13/B13 -> 371.13042 | AA13: =Y13/C13 -> 379.0497 | AB13: =+AB12+AC13 -> 62487.68 | AC13: =+[1]DailyOct!AV12 -> 10582.37 | AD13: =AC13/B13 -> 231.02585 | AE13: =AC13/C13 -> 235.95554 | AF13: =+AF12+AG13 -> 79975.36 | AG13: =+[1]DailyOct!AW12 -> 13764.74 | AH13: =AG13/B13 -> 300.50081 | AI13: =AG13/C13 -> 306.91297 | AJ13: =+AJ12+AK13 -> 9030 | AK13: =+[1]DailyOct!AX12 -> 1740 | AL13: =AK13/B13 -> 37.98629 | AM13: =AK13/C13 -> 38.796852 | AN13: =+E13+I13+M13+Q13+U13+Y13+AC13+AG13+AK13 -> 50699.48 | AO13: =AN13/B13 -> 1106.8305 | AP13: =AN13/C13 -> 1130.4484 | AS13: Multi Screen | AT13: =+R39 -> 0 | AU13: =+S39 -> 0
A14: =A13+1 -> 45937 | B14: =+Report1!P15 -> 46.745 | C14: =+Report1!R15 -> 44.095 | D14: =+D13+E14 -> 0 | F14: =E14/B14 -> 0 | G14: =E14/C14 -> 0 | H14: =+H13+I14 -> 0 | J14: =I14/B14 -> 0 | K14: =I14/C14 -> 0 | L14: =+L13+M14 -> 0 | N14: =M14/B14 -> 0 | O14: =M14/C14 -> 0 | P14: =+P13+Q14 -> 0 | R14: =Q14/B14 -> 0 | S14: =Q14/C14 -> 0 | T14: =+T13+U14 -> 49399.33 | U14: =+[1]DailyOct!AT13 -> 7731.65 | V14: =U14/B14 -> 165.40058 | W14: =U14/C14 -> 175.34074 | X14: =+X13+Y14 -> 101000 | Y14: =+[1]DailyOct!AU13 -> 18000 | Z14: =Y14/B14 -> 385.06792 | AA14: =Y14/C14 -> 408.20955 | AB14: =+AB13+AC14 -> 74174.33 | AC14: =+[1]DailyOct!AV13 -> 11686.65 | AD14: =AC14/B14 -> 250.00856 | AE14: =AC14/C14 -> 265.03345 | AF14: =+AF13+AG14 -> 95748.66 | AG14: =+[1]DailyOct!AW13 -> 15773.3 | AH14: =AG14/B14 -> 337.43288 | AI14: =AG14/C14 -> 357.71176 | AJ14: =+AJ13+AK14 -> 10960 | AK14: =+[1]DailyOct!AX13 -> 1930 | AL14: =AK14/B14 -> 41.287838 | AM14: =AK14/C14 -> 43.769135 | AN14: =+E14+I14+M14+Q14+U14+Y14+AC14+AG14+AK14 -> 55121.6 | AO14: =AN14/B14 -> 1179.1978 | AP14: =AN14/C14 -> 1250.0646 | AS14: WL II 1250 A (yankee + popereel) | AT14: =+V39 -> 0 | AU14: =+W39 -> 0
A15: =A14+1 -> 45938 | B15: =+Report1!P16 -> 50.24 | C15: =+Report1!R16 -> 47.835 | D15: =+D14+E15 -> 0 | F15: =E15/B15 -> 0 | G15: =E15/C15 -> 0 | H15: =+H14+I15 -> 0 | J15: =I15/B15 -> 0 | K15: =I15/C15 -> 0 | L15: =+L14+M15 -> 0 | N15: =M15/B15 -> 0 | O15: =M15/C15 -> 0 | P15: =+P14+Q15 -> 0 | R15: =Q15/B15 -> 0 | S15: =Q15/C15 -> 0 | T15: =+T14+U15 -> 56076.46 | U15: =+[1]DailyOct!AT14 -> 6677.13 | V15: =U15/B15 -> 132.90466 | W15: =U15/C15 -> 139.5867 | X15: =+X14+Y15 -> 117000 | Y15: =+[1]DailyOct!AU14 -> 16000 | Z15: =Y15/B15 -> 318.47134 | AA15: =Y15/C15 -> 334.48312 | AB15: =+AB14+AC15 -> 84446.46 | AC15: =+[1]DailyOct!AV14 -> 10272.13 | AD15: =AC15/B15 -> 204.46119 | AE15: =AC15/C15 -> 214.74088 | AF15: =+AF14+AG15 -> 109692.92 | AG15: =+[1]DailyOct!AW14 -> 13944.26 | AH15: =AG15/B15 -> 277.55295 | AI15: =AG15/C15 -> 291.50747 | AJ15: =+AJ14+AK15 -> 12520 | AK15: =+[1]DailyOct!AX14 -> 1560 | AL15: =AK15/B15 -> 31.050955 | AM15: =AK15/C15 -> 32.612104 | AN15: =+E15+I15+M15+Q15+U15+Y15+AC15+AG15+AK15 -> 48453.52 | AO15: =AN15/B15 -> 964.44108 | AP15: =AN15/C15 -> 1012.9303 | AS15: WL II 3200 A (Hood, Fan Pump, Felt & Wire) | AT15: =+Z39 -> 0 | AU15: =+AA39 -> 0
A16: =A15+1 -> 45939 | B16: =+Report1!P17 -> 53.849 | C16: =+Report1!R17 -> 56.943 | D16: =+D15+E16 -> 0 | F16: =E16/B16 -> 0 | G16: =E16/C16 -> 0 | H16: =+H15+I16 -> 0 | J16: =I16/B16 -> 0 | K16: =I16/C16 -> 0 | L16: =+L15+M16 -> 0 | N16: =M16/B16 -> 0 | O16: =M16/C16 -> 0 | P16: =+P15+Q16 -> 0 | R16: =Q16/B16 -> 0 | S16: =Q16/C16 -> 0 | T16: =+T15+U16 -> 62696.39 | U16: =+[1]DailyOct!AT15 -> 6619.93 | V16: =U16/B16 -> 122.93506 | W16: =U16/C16 -> 116.25538 | X16: =+X15+Y16 -> 135000 | Y16: =+[1]DailyOct!AU15 -> 18000 | Z16: =Y16/B16 -> 334.26805 | AA16: =Y16/C16 -> 316.10558 | AB16: =+AB15+AC16 -> 95176.39 | AC16: =+[1]DailyOct!AV15 -> 10729.93 | AD16: =AC16/B16 -> 199.2596 | AE16: =AC16/C16 -> 188.43282 | AF16: =+AF15+AG16 -> 131752.78 | AG16: =+[1]DailyOct!AW15 -> 22059.86 | AH16: =AG16/B16 -> 409.66146 | AI16: =AG16/C16 -> 387.40249 | AJ16: =+AJ15+AK16 -> 14270 | AK16: =+[1]DailyOct!AX15 -> 1750 | AL16: =AK16/B16 -> 32.498282 | AM16: =AK16/C16 -> 30.732487 | AN16: =+E16+I16+M16+Q16+U16+Y16+AC16+AG16+AK16 -> 59159.72 | AO16: =AN16/B16 -> 1098.6224 | AP16: =AN16/C16 -> 1038.9288 | AT16: =SUM(AT10:AT15) -> 0 | AU16: =SUM(AU10:AU15) -> 0
A17: =A16+1 -> 45940 | B17: =+Report1!P18 -> 49.898 | C17: =+Report1!R18 -> 40.125 | D17: =+D16+E17 -> 0 | F17: =E17/B17 -> 0 | G17: =E17/C17 -> 0 | H17: =+H16+I17 -> 0 | J17: =I17/B17 -> 0 | K17: =I17/C17 -> 0 | L17: =+L16+M17 -> 0 | N17: =M17/B17 -> 0 | O17: =M17/C17 -> 0 | P17: =+P16+Q17 -> 0 | R17: =Q17/B17 -> 0 | S17: =Q17/C17 -> 0 | T17: =+T16+U17 -> 69665.06 | U17: =+[1]DailyOct!AT16 -> 6968.67 | V17: =U17/B17 -> 139.6583 | W17: =U17/C17 -> 173.67402 | X17: =+X16+Y17 -> 152700 | Y17: =+[1]DailyOct!AU16 -> 17700 | Z17: =Y17/B17 -> 354.72364 | AA17: =Y17/C17 -> 441.1215 | AB17: =+AB16+AC17 -> 105183.06 | AC17: =+[1]DailyOct!AV16 -> 10006.67 | AD17: =AC17/B17 -> 200.54251 | AE17: =AC17/C17 -> 249.38741 | AF17: =+AF16+AG17 -> 147091.88 | AG17: =+[1]DailyOct!AW16 -> 15339.098 | AH17: =AG17/B17 -> 307.40907 | AI17: =AG17/C17 -> 382.28281 | AJ17: =+AJ16+AK17 -> 16230 | AK17: =+[1]DailyOct!AX16 -> 1960 | AL17: =AK17/B17 -> 39.280131 | AM17: =AK17/C17 -> 48.847352 | AN17: =+E17+I17+M17+Q17+U17+Y17+AC17+AG17+AK17 -> 51974.438 | AO17: =AN17/B17 -> 1041.6136 | AP17: =AN17/C17 -> 1295.3131 | AR17: Stockprep | AS17: Stock Prep & UTM 1 (3200 A) | AT17: =+AD39 -> 0 | AU17: =+AE39 -> 0
A18: =A17+1 -> 45941 | B18: =+Report1!P19 -> 51.078 | C18: =+Report1!R19 -> 53.558 | D18: =+D17+E18 -> 0 | F18: =E18/B18 -> 0 | G18: =E18/C18 -> 0 | H18: =+H17+I18 -> 0 | J18: =I18/B18 -> 0 | K18: =I18/C18 -> 0 | L18: =+L17+M18 -> 0 | N18: =M18/B18 -> 0 | O18: =M18/C18 -> 0 | P18: =+P17+Q18 -> 0 | R18: =Q18/B18 -> 0 | S18: =Q18/C18 -> 0 | T18: =+T17+U18 -> 76736.45 | U18: =+[1]DailyOct!AT17 -> 7071.39 | V18: =U18/B18 -> 138.44297 | W18: =U18/C18 -> 132.03238 | X18: =+X17+Y18 -> 169870 | Y18: =+[1]DailyOct!AU17 -> 17170 | Z18: =Y18/B18 -> 336.15255 | AA18: =Y18/C18 -> 320.58703 | AB18: =+AB17+AC18 -> 115328.45 | AC18: =+[1]DailyOct!AV17 -> 10145.39 | AD18: =AC18/B18 -> 198.62544 | AE18: =AC18/C18 -> 189.4281 | AF18: =+AF17+AG18 -> 159268.27 | AG18: =+[1]DailyOct!AW17 -> 12176.39 | AH18: =AG18/B18 -> 238.38815 | AI18: =AG18/C18 -> 227.3496 | AJ18: =+AJ17+AK18 -> 18430 | AK18: =+[1]DailyOct!AX17 -> 2200 | AL18: =AK18/B18 -> 43.071381 | AM18: =AK18/C18 -> 41.076963 | AN18: =+E18+I18+M18+Q18+U18+Y18+AC18+AG18+AK18 -> 48763.17 | AO18: =AN18/B18 -> 954.68049 | AP18: =AN18/C18 -> 910.47407 | AS18: Stock Prep & UTM 2 (3200 A) | AT18: =+AH39 -> 0 | AU18: =+AI39 -> 0
A19: =A18+1 -> 45942 | B19: =+Report1!P20 -> 50.325 | C19: =+Report1!R20 -> 50.863 | D19: =+D18+E19 -> 0 | F19: =E19/B19 -> 0 | G19: =E19/C19 -> 0 | H19: =+H18+I19 -> 0 | J19: =I19/B19 -> 0 | K19: =I19/C19 -> 0 | L19: =+L18+M19 -> 0 | N19: =M19/B19 -> 0 | O19: =M19/C19 -> 0 | P19: =+P18+Q19 -> 0 | R19: =Q19/B19 -> 0 | S19: =Q19/C19 -> 0 | T19: =+T18+U19 -> 85651.99 | U19: =+[1]DailyOct!AT18 -> 8915.54 | V19: =U19/B19 -> 177.15926 | W19: =U19/C19 -> 175.28537 | X19: =+X18+Y19 -> 185000 | Y19: =+[1]DailyOct!AU18 -> 15130 | Z19: =Y19/B19 -> 300.6458 | AA19: =Y19/C19 -> 297.46574 | AB19: =+AB18+AC19 -> 126571.99 | AC19: =+[1]DailyOct!AV18 -> 11243.54 | AD19: =AC19/B19 -> 223.41858 | AE19: =AC19/C19 -> 221.05538 | AF19: =+AF18+AG19 -> 171503.81 | AG19: =+[1]DailyOct!AW18 -> 12235.54 | AH19: =AG19/B19 -> 243.13045 | AI19: =AG19/C19 -> 240.55876 | AJ19: =+AJ18+AK19 -> 20880 | AK19: =+[1]DailyOct!AX18 -> 2450 | AL19: =AK19/B19 -> 48.683557 | AM19: =AK19/C19 -> 48.16861 | AN19: =+E19+I19+M19+Q19+U19+Y19+AC19+AG19+AK19 -> 49974.62 | AO19: =AN19/B19 -> 993.03766 | AP19: =AN19/C19 -> 982.53387 | AT19: =SUM(AT17:AT18) -> 0 | AU19: =SUM(AU17:AU18) -> 0
