Workbook

Sheet Report1
A3: PAPER MACHINE 14 DAILY REPORT 1
A6: Date | B6: Grade | C6: GSM | D6: Speed yankee (mpm) | E6: Speed reel (mpm) | F6: Creep ( % ) | G6: Real Eff PM ( % ) | H6: Real Eff PM vs Target (%) | I6: Real Eff FG vs Real Eff PM (%) | J6: Eff FG vs Target (%) | L6: Kapasitas Target (ton) | N6: Kapasitas Teori Real (ton) | P6: PM PROD Timbangan (TON) | R6: FINSHED GOODS (TON) | T6: GAS HOOD | Z6: STEAM (TON) | AF6: POWER (kWh) | BA6: Kapasitas Running (ton) | BC6: Eff FG vs Target Running(%)
T7: CONSUMPTION | V7: /TON PM. | X7: /TON FG. | Z7: CONSUMPTION | AB7: /TON PM. | AD7: /TON FG. | AF7: CONSUMPTION | AH7: /TON PM | AJ7: /TON FG | AL7: Gas based on report DCS | AO7: total | AP7: Flowmeter | AQ7: Selisih | AR7: % pengali | AU7: Adjust | AX7: PEMAKAIAN GAS
J8: TODAY | K8: TODATE | L8: TODAY | M8: TODATE | N8: TODAY | O8: TODATE | P8: TODAY | Q8: TODATE | R8: TODAY | S8: TODATE | T8: TODAY | U8: TODATE | V8: TODAY | W8: TODATE | X8: TODAY | Y8: TODATE | Z8: TODAY | AA8: TODATE | AB8: TODAY | AC8: TODATE | AD8: TODAY | AE8: TODATE | AF8: TODAY | AG8: TODATE | AH8: TODAY | AI8: TODATE | AJ8: TODAY | AK8: TODATE | AL8: 14 | AM8: 15 | AN8: 17 | AP8: PGN | AU8: 14 | AV8: 15 | AW8: 17 | AX8: 14 | AY8: 15 | AZ8: 17 | BA8: TODAY | BB8: TODATE | BC8: TODAY | BD8: TODATE
A9: 45901 | B9: Facial | C9: 12 | D9: =+'1'!F42 -> 1230 | E9: =+'1'!G42 -> 947.1 | F9: =1-(E9/D9) -> 0.23 | G9: =+P9/N9 -> 0.93239234 | H9: =+P9/L9 -> 0.93239234 | I9: =+R9/P9 -> 1.0356002 | J9: =+R9/L9 -> 0.96558565 | K9: =+S9/M9 -> 0.96558565 | L9: =+Efficiency1!K6 -> 42.960456 | M9: =L9 -> 42.960456 | N9: =+Efficiency1!C6 -> 42.960456 | O9: =N9 -> 42.960456 | P9: ='1'!I38 -> 40.056 | Q9: =P9 -> 40.056 | R9: ='1'!I40 -> 41.482 | S9: =R9 -> 41.482 | T9: =+AX9 -> 3426.7026 | U9: =T9 -> 3426.7026 | V9: =T9/P9 -> 85.547797 | W9: =U9/Q9 -> 85.547797 | X9: =IF(AND(R9>0,T9>0),(T9/(R9*1000))*1000,0) -> 82.606975 | Y9: =IF(AND(S9>0,U9>0),U9/S9,0) -> 82.606975 | Z9: 59 | AA9: =Z9 -> 59 | AB9: =Z9/(P9) -> 1.4729379 | AC9: =AA9/(Q9) -> 1.4729379 | AD9: =IF(AND(R9>0,Z9>0),Z9/(R9),0) -> 1.4223036 | AE9: =IF(AND(S9>0,AA9>0),AA9/(S9),0) -> 1.4223036 | AF9: ='1'!I46 -> 35377 | AG9: =AF9 -> 35377 | AH9: =IF(AND(L9>0,AF9>0),(AF9/(P9*1000)*1000),0) -> 883.18854 | AI9: =IF(AND(M9>0,AG9>0),(AG9/(Q9*1000)*1000),0) -> 883.18854 | AJ9: =IF(AND(R9>0,AF9>0),(AF9/(R9*1000)*1000),0) -> 852.82773 | AK9: =IF(AND(S9>0,AG9>0),(AG9/(S9*1000)*1000),0) -> 852.82773 | AL9: 3803 | AM9: 5530.7 | AN9: 3920.8 | AO9: =SUM(AL9:AN9) -> 13254.5 | AP9: =+[1]Sept!N4 -> 11943 | AQ9: =+AP9-AO9 -> -1311.5 | AR9: =+AL9/AO9 -> 0.28692142 | AS9: =+AM9/AO9 -> 0.41726961 | AT9: =1-AR9-AS9 -> 0.29580897 | AU9: =+AR9*AQ9 -> -376.29745 | AV9: =+AS9*AQ9 -> -547.24909 | AW9: =+AT9*AQ9 -> -387.95346 | AX9: =+AL9+AU9 -> 3426.7026 | AY9: =+AM9+AV9 -> 4983.4509 | AZ9: =+AN9+AW9 -> 3532.8465 | BA9: =+Efficiency2!K6 -> 42.960456 | BB9: =BA9 -> 42.960456 | BC9: =+R9/BA9 -> 0.96558565 | BD9: =+S9/BB9 -> 0.96558565
A10: =A9+1 -> 45902 | B10: Facial | C10: 12/13 | D10: =+'2'!F42 -> 1246.9618 | E10: =+'2'!G42 -> 960.16059 | F10: =1-(E10/D10) -> 0.23 | G10: =+P10/N10 -> 0.91427512 | H10: =+P10/L10 -> 0.89729594 | I10: =+R10/P10 -> 0.82181922 | J10: =+R10/L10 -> 0.73741505 | K10: =+S10/M10 -> 0.85158809 | L10: =+SUM(Efficiency1!K10:K11) -> 42.894432 | M10: =M9+L10 -> 85.854888 | N10: =+SUM(Efficiency1!C10:C11) -> 42.097832 | O10: =O9+N10 -> 85.058288 | P10: ='2'!I38 -> 38.489 | Q10: =Q9+P10 -> 78.545 | R10: ='2'!I40 -> 31.631 | S10: =S9+R10 -> 73.113 | T10: =+AX10 -> 3753.1046 | U10: =T10+U9 -> 7179.8072 | V10: =T10/P10 -> 97.511098 | W10: =U10/Q10 -> 91.410111 | X10: =IF(AND(R10>0,T10>0),(T10/(R10*1000))*1000,0) -> 118.65273 | Y10: =IF(AND(S10>0,U10>0),U10/S10,0) -> 98.201513 | Z10: 58.8 | AA10: =Z10+AA9 -> 117.8 | AB10: =Z10/(P10) -> 1.5277092 | AC10: =AA10/(Q10) -> 1.4997772 | AD10: =IF(AND(R10>0,Z10>0),Z10/(R10),0) -> 1.8589359 | AE10: =IF(AND(S10>0,AA10>0),AA10/(S10),0) -> 1.6112046 | AF10: ='2'!I46 -> 35412.3 | AG10: =AF10+AG9 -> 70789.3 | AH10: =IF(AND(L10>0,AF10>0),(AF10/(P10*1000)*1000),0) -> 920.06288 | AI10: =IF(AND(M10>0,AG10>0),(AG10/(Q10*1000)*1000),0) -> 901.25788 | AJ10: =IF(AND(R10>0,AF10>0),(AF10/(R10*1000)*1000),0) -> 1119.5441 | AK10: =IF(AND(S10>0,AG10>0),(AG10/(S10*1000)*1000),0) -> 968.21769 | AL10: 3950.8 | AM10: 5561 | AN10: 3965.6 | AO10: =SUM(AL10:AN10) -> 13477.4 | AP10: =+[1]Sept!N5 -> 12803 | AQ10: =+AP10-AO10 -> -674.4 | AR10: =+AL10/AO10 -> 0.29314259 | AS10: =+AM10/AO10 -> 0.41261668 | AT10: =1-AR10-AS10 -> 0.29424073 | AU10: =+AR10*AQ10 -> -197.69537 | AV10: =+AS10*AQ10 -> -278.26869 | AW10: =+AT10*AQ10 -> -198.43595 | AX10: =+AL10+AU10 -> 3753.1046 | AY10: =+AM10+AV10 -> 5282.7313 | AZ10: =+AN10+AW10 -> 3767.1641 | BA10: =+SUM(Efficiency2!K10:K11) -> 42.894432 | BB10: =BB9+BA10 -> 85.854888 | BC10: =+R10/BA10 -> 0.73741505 | BD10: =+S10/BB10 -> 0.85158809
A11: =A10+1 -> 45903 | B11: Facial | C11: 13/12 | D11: =+'3'!F42 -> 1215.125 | E11: =+'3'!G42 -> 935.64625 | F11: =1-(E11/D11) -> 0.23 | G11: =+P11/N11 -> 0.9154686 | H11: =+P11/L11 -> 0.90299749 | I11: =+R11/P11 -> 0.83188322 | J11: =+R11/L11 -> 0.75118846 | K11: =+S11/M11 -> 0.8184718 | L11: =+SUM(Efficiency1!K14:K15) -> 42.257039 | M11: =M10+L11 -> 128.11193 | N11: =+SUM(Efficiency1!C14:C15) -> 41.681386 | O11: =O10+N11 -> 126.73967 | P11: ='3'!I38 -> 38.158 | Q11: =Q10+P11 -> 116.703 | R11: ='3'!I40 -> 31.743 | S11: =S10+R11 -> 104.856 | T11: =+AX11 -> 3801.1346 | U11: =T11+U10 -> 10980.942 | V11: =T11/P11 -> 99.615666 | W11: =U11/Q11 -> 94.093055 | X11: =IF(AND(R11>0,T11>0),(T11/(R11*1000))*1000,0) -> 119.74718 | Y11: =IF(AND(S11>0,U11>0),U11/S11,0) -> 104.72402 | Z11: 55.3 | AA11: =Z11+AA10 -> 173.1 | AB11: =Z11/(P11) -> 1.4492374 | AC11: =AA11/(Q11) -> 1.4832524 | AD11: =IF(AND(R11>0,Z11>0),Z11/(R11),0) -> 1.7421164 | AE11: =IF(AND(S11>0,AA11>0),AA11/(S11),0) -> 1.6508354 | AF11: ='3'!I46 -> 33620.1 | AG11: =AF11+AG10 -> 104409.4 | AH11: =IF(AND(L11>0,AF11>0),(AF11/(P11*1000)*1000),0) -> 881.07605 | AI11: =IF(AND(M11>0,AG11>0),(AG11/(Q11*1000)*1000),0) -> 894.65909 | AJ11: =IF(AND(R11>0,AF11>0),(AF11/(R11*1000)*1000),0) -> 1059.1343 | AK11: =IF(AND(S11>0,AG11>0),(AG11/(S11*1000)*1000),0) -> 995.74083 | AL11: 3893 | AM11: 5447.5 | AN11: 3860 | AO11: =SUM(AL11:AN11) -> 13200.5 | AP11: =+[1]Sept!N6 -> 12889 | AQ11: =+AP11-AO11 -> -311.5 | AR11: =+AL11/AO11 -> 0.29491307 | AS11: =+AM11/AO11 -> 0.41267376 | AT11: =1-AR11-AS11 -> 0.29241317 | AU11: =+AR11*AQ11 -> -91.865422 | AV11: =+AS11*AQ11 -> -128.54788 | AW11: =+AT11*AQ11 -> -91.086701 | AX11: =+AL11+AU11 -> 3801.1346 | AY11: =+AM11+AV11 -> 5318.9521 | AZ11: =+AN11+AW11 -> 3768.9133 | BA11: =+SUM(Efficiency2!K14:K15) -> 42.257039 | BB11: =BB10+BA11 -> 128.11193 | BC11: =+R11/BA11 -> 0.75118846 | BD11: =+S11/BB11 -> 0.8184718
A12: =A11+1 -> 45904 | B12: Facial | C12: 12/14 | D12: =+'4'!F42 -> 1223.9514 | E12: =+'4'!G42 -> 924.53451 | F12: =1-(E12/D12) -> 0.24463135 | G12: =+P12/N12 -> 0.95909034 | H12: =+P12/L12 -> 0.95464608 | I12: =+R12/P12 -> 0.97801299 | J12: =+R12/L12 -> 0.93365626 | K12: =+S12/M12 -> 0.84769114 | L12: =+SUM(Efficiency1!K18:K19) -> 43.544934 | M12: =M11+L12 -> 171.65686 | N12: =+SUM(Efficiency1!C18:C19) -> 43.343154 | O12: =O11+N12 -> 170.08283 | P12: ='4'!I38 -> 41.57 | Q12: =Q11+P12 -> 158.273 | R12: ='4'!I40 -> 40.656 | S12: =S11+R12 -> 145.512 | T12: =+AX12 -> 3768.501 | U12: =T12+U11 -> 14749.443 | V12: =T12/P12 -> 90.654343 | W12: =U12/Q12 -> 93.189886 | X12: =IF(AND(R12>0,T12>0),(T12/(R12*1000))*1000,0) -> 92.692371 | Y12: =IF(AND(S12>0,U12>0),U12/S12,0) -> 101.36238 | Z12: 59.7 | AA12: =Z12+AA11 -> 232.8 | AB12: =Z12/(P12) -> 1.4361318 | AC12: =AA12/(Q12) -> 1.4708763 | AD12: =IF(AND(R12>0,Z12>0),Z12/(R12),0) -> 1.4684179 | AE12: =IF(AND(S12>0,AA12>0),AA12/(S12),0) -> 1.5998681 | AF12: ='4'!I46 -> 37489.92 | AG12: =AF12+AG11 -> 141899.32 | AH12: =IF(AND(L12>0,AF12>0),(AF12/(P12*1000)*1000),0) -> 901.85037 | AI12: =IF(AND(M12>0,AG12>0),(AG12/(Q12*1000)*1000),0) -> 896.54786 | AJ12: =IF(AND(R12>0,AF12>0),(AF12/(R12*1000)*1000),0) -> 922.12515 | AK12: =IF(AND(S12>0,AG12>0),(AG12/(S12*1000)*1000),0) -> 975.17263 | AL12: 3950.3 | AM12: 5547.2 | AN12: 3946.2 | AO12: =SUM(AL12:AN12) -> 13443.7 | AP12: =+[1]Sept!N7 -> 12825 | AQ12: =+AP12-AO12 -> -618.7 | AR12: =+AL12/AO12 -> 0.29384024 | AS12: =+AM12/AO12 -> 0.4126245 | AT12: =1-AR12-AS12 -> 0.29353526 | AU12: =+AR12*AQ12 -> -181.79895 | AV12: =+AS12*AQ12 -> -255.29078 | AW12: =+AT12*AQ12 -> -181.61027 | AX12: =+AL12+AU12 -> 3768.501 | AY12: =+AM12+AV12 -> 5291.9092 | AZ12: =+AN12+AW12 -> 3764.5897 | BA12: =+SUM(Efficiency2!K18:K19) -> 43.544934 | BB12: =BB11+BA12 -> 171.65686 | BC12: =+R12/BA12 -> 0.93365626 | BD12: =+S12/BB12 -> 0.84769114
A13: =A12+1 -> 45905 | B13: Facial | C13: 14 | D13: =+'5'!F42 -> 1230 | E13: =+'5'!G42 -> 922.5 | F13: =1-(E13/D13) -> 0.25 | G13: =+P13/N13 -> 0.95901711 | H13: =+P13/L13 -> 0.95901711 | I13: =+R13/P13 -> 0.97231632 | J13: =+R13/L13 -> 0.93246799 | K13: =+S13/M13 -> 0.86518585 | L13: =+Efficiency1!K22 -> 44.63424 | M13: =M12+L13 -> 216.2911 | N13: =+Efficiency1!C22 -> 44.63424 | O13: =O12+N13 -> 214.71707 | P13: ='5'!I38 -> 42.805 | Q13: =Q12+P13 -> 201.078 | R13: ='5'!I40 -> 41.62 | S13: =S12+R13 -> 187.132 | T13: =+AX13 -> 3742.2736 | U13: =T13+U12 -> 18491.716 | V13: =T13/P13 -> 87.426085 | W13: =U13/Q13 -> 91.962902 | X13: =IF(AND(R13>0,T13>0),(T13/(R13*1000))*1000,0) -> 89.91527 | Y13: =IF(AND(S13>0,U13>0),U13/S13,0) -> 98.816431 | Z13: 60.9 | AA13: =Z13+AA12 -> 293.7 | AB13: =Z13/(P13) -> 1.422731 | AC13: =AA13/(Q13) -> 1.4606272 | AD13: =IF(AND(R13>0,Z13>0),Z13/(R13),0) -> 1.4632388 | AE13: =IF(AND(S13>0,AA13>0),AA13/(S13),0) -> 1.5694804 | AF13: ='5'!I46 -> 34099.46 | AG13: =AF13+AG12 -> 175998.78 | AH13: =IF(AND(L13>0,AF13>0),(AF13/(P13*1000)*1000),0) -> 796.62329 | AI13: =IF(AND(M13>0,AG13>0),(AG13/(Q13*1000)*1000),0) -> 875.27616 | AJ13: =IF(AND(R13>0,AF13>0),(AF13/(R13*1000)*1000),0) -> 819.30466 | AK13: =IF(AND(S13>0,AG13>0),(AG13/(S13*1000)*1000),0) -> 940.50606 | AL13: 3929.6 | AM13: 5566.6 | AN13: 3432.1 | AO13: =SUM(AL13:AN13) -> 12928.3 | AP13: =+[1]Sept!N8 -> 12312 | AQ13: =+AP13-AO13 -> -616.3 | AR13: =+AL13/AO13 -> 0.30395334 | AS13: =+AM13/AO13 -> 0.43057479 | AT13: =1-AR13-AS13 -> 0.26547187 | AU13: =+AR13*AQ13 -> -187.32645 | AV13: =+AS13*AQ13 -> -265.36324 | AW13: =+AT13*AQ13 -> -163.61031 | AX13: =+AL13+AU13 -> 3742.2736 | AY13: =+AM13+AV13 -> 5301.2368 | AZ13: =+AN13+AW13 -> 3268.4897 | BA13: =+Efficiency2!K22 -> 44.63424 | BB13: =BB12+BA13 -> 216.2911 | BC13: =+R13/BA13 -> 0.93246799 | BD13: =+S13/BB13 -> 0.86518585
A14: =A13+1 -> 45906 | B14: Facial | C14: 14 | D14: =+'6'!F42 -> 1191.2432 | E14: =+'6'!G42 -> 893.43243 | F14: =1-(E14/D14) -> 0.25 | G14: =+P14/N14 -> 0.61253423 | H14: =+P14/L14 -> 0.61253423 | I14: =+R14/P14 -> 0.82765179 | J14: =+R14/L14 -> 0.50696506 | K14: =+S14/M14 -> 0.80390812 | L14: =+Efficiency1!K26 -> 44.63424 | M14: =M13+L14 -> 260.92534 | N14: =+Efficiency1!C26 -> 44.63424 | O14: =O13+N14 -> 259.35131 | P14: ='6'!I38 -> 27.34 | Q14: =Q13+P14 -> 228.418 | R14: ='6'!I40 -> 22.628 | S14: =S13+R14 -> 209.76 | T14: =+AX14 -> 2573.5487 | U14: =T14+U13 -> 21065.265 | V14: =T14/P14 -> 94.131263 | W14: =U14/Q14 -> 92.222439 | X14: =IF(AND(R14>0,T14>0),(T14/(R14*1000))*1000,0) -> 113.73293 | Y14: =IF(AND(S14>0,U14>0),U14/S14,0) -> 100.42556 | Z14: 45.5 | AA14: =Z14+AA13 -> 339.2 | AB14: =Z14/(P14) -> 1.6642282 | AC14: =AA14/(Q14) -> 1.4849968 | AD14: =IF(AND(R14>0,Z14>0),Z14/(R14),0) -> 2.0107831 | AE14: =IF(AND(S14>0,AA14>0),AA14/(S14),0) -> 1.6170862 | AF14: ='6'!I46 -> 23766.2 | AG14: =AF14+AG13 -> 199764.98 | AH14: =IF(AND(L14>0,AF14>0),(AF14/(P14*1000)*1000),0) -> 869.2831 | AI14: =IF(AND(M14>0,AG14>0),(AG14/(Q14*1000)*1000),0) -> 874.55884 | AJ14: =IF(AND(R14>0,AF14>0),(AF14/(R14*1000)*1000),0) -> 1050.3005 | AK14: =IF(AND(S14>0,AG14>0),(AG14/(S14*1000)*1000),0) -> 952.35021 | AL14: 2705.4 | AM14: 4755.4 | AN14: 3364.8 | AO14: =SUM(AL14:AN14) -> 10825.6 | AP14: =+[1]Sept!N9 -> 10298 | AQ14: =+AP14-AO14 -> -527.6 | AR14: =+AL14/AO14 -> 0.24990763 | AS14: =+AM14/AO14 -> 0.43927357 | AT14: =1-AR14-AS14 -> 0.3108188 | AU14: =+AR14*AQ14 -> -131.85126 | AV14: =+AS14*AQ14 -> -231.76074 | AW14: =+AT14*AQ14 -> -163.988 | AX14: =+AL14+AU14 -> 2573.5487 | AY14: =+AM14+AV14 -> 4523.6393 | AZ14: =+AN14+AW14 -> 3200.812 | BA14: =+Efficiency2!K26 -> 44.63424 | BB14: =BB13+BA14 -> 260.92534 | BC14: =+R14/BA14 -> 0.50696506 | BD14: =+S14/BB14 -> 0.80390812
A15: =A14+1 -> 45907 | B15: Facial/Toilet | C15: 14/12/12 | D15: =+'7'!F42 -> 1222.6415 | E15: =+'7'!G42 -> 936.79245 | F15: =1-(E15/D15) -> 0.2337963 | G15: =+P15/N15 -> 0.8451218 | H15: =+P15/L15 -> 0.8399417 | I15: =+R15/P15 -> 0.98752742 | J15: =+R15/L15 -> 0.82946545 | K15: =+S15/M15 -> 0.80742101 | L15: =+SUM(Efficiency1!K31:K33) -> 41.579791 | M15: =M14+L15 -> 302.50513 | N15: =+SUM(Efficiency1!C31:C33) -> 41.324931 | O15: =O14+N15 -> 300.67624 | P15: ='7'!I38 -> 34.9246 | Q15: =Q14+P15 -> 263.3426 | R15: ='7'!I40 -> 34.489 | S15: =S14+R15 -> 244.249 | T15: =+AX15 -> 3180.2115 | U15: =T15+U14 -> 24245.477 | V15: =T15/P15 -> 91.059352 | W15: =U15/Q15 -> 92.06819 | X15: =IF(AND(R15>0,T15>0),(T15/(R15*1000))*1000,0) -> 92.209442 | Y15: =IF(AND(S15>0,U15>0),U15/S15,0) -> 99.265408 | Z15: 55.1 | AA15: =Z15+AA14 -> 394.3 | AB15: =Z15/(P15) -> 1.5776845 | AC15: =AA15/(Q15) -> 1.4972891 | AD15: =IF(AND(R15>0,Z15>0),Z15/(R15),0) -> 1.5976108 | AE15: =IF(AND(S15>0,AA15>0),AA15/(S15),0) -> 1.6143362 | AF15: ='7'!I46 -> 35925.58 | AG15: =AF15+AG14 -> 235690.56 | AH15: =IF(AND(L15>0,AF15>0),(AF15/(P15*1000)*1000),0) -> 1028.6612 | AI15: =IF(AND(M15>0,AG15>0),(AG15/(Q15*1000)*1000),0) -> 894.99595 | AJ15: =IF(AND(R15>0,AF15>0),(AF15/(R15*1000)*1000),0) -> 1041.6533 | AK15: =IF(AND(S15>0,AG15>0),(AG15/(S15*1000)*1000),0) -> 964.96018 | AL15: 3489 | AM15: 5166.9 | AN15: 4154.9 | AO15: =SUM(AL15:AN15) -> 12810.8 | AP15: =+[1]Sept!N10 -> 11677 | AQ15: =+AP15-AO15 -> -1133.8 | AR15: =+AL15/AO15 -> 0.27234833 | AS15: =+AM15/AO15 -> 0.40332376 | AT15: =1-AR15-AS15 -> 0.32432791 | AU15: =+AR15*AQ15 -> -308.78854 | AV15: =+AS15*AQ15 -> -457.28848 | AW15: =+AT15*AQ15 -> -367.72299 | AX15: =+AL15+AU15 -> 3180.2115 | AY15: =+AM15+AV15 -> 4709.6115 | AZ15: =+AN15+AW15 -> 3787.177 | BA15: =+SUM(Efficiency2!K31:K33) -> 41.579791 | BB15: =BB14+BA15 -> 302.50513 | BC15: =+R15/BA15 -> 0.82946545 | BD15: =+S15/BB15 -> 0.80742101
A16: =A15+1 -> 45908 | B16: STOP | C16: 12 | D16: =+'8'!F42 -> 0 | E16: =+'8'!G42 -> 0 | F16: =1-(E16/D16) -> #DIV/0! | G16: =+P16/N16 -> 0 | H16: =+P16/L16 -> 0 | I16: =+R16/P16 -> #DIV/0! | J16: =+R16/L16 -> 0 | K16: =+S16/M16 -> 0.71088685 | L16: =+Efficiency1!K36 -> 41.078379 | M16: =M15+L16 -> 343.58351 | N16: =+Efficiency1!C36 -> 40.718576 | O16: =O15+N16 -> 341.39481 | P16: ='8'!I38 -> 0 | Q16: =Q15+P16 -> 263.3426 | R16: ='8'!I40 -> 0 | S16: =S15+R16 -> 244.249 | T16: =+AX16 -> 288.79704 | U16: =T16+U15 -> 24534.274 | V16: =T16/P16 -> #DIV/0! | W16: =U16/Q16 -> 93.164849 | X16: =IF(AND(R16>0,T16>0),(T16/(R16*1000))*1000,0) -> 0 | Y16: =IF(AND(S16>0,U16>0),U16/S16,0) -> 100.4478 | Z16: 15.8 | AA16: =Z16+AA15 -> 410.1 | AB16: =Z16/(P16) -> #DIV/0! | AC16: =AA16/(Q16) -> 1.557287 | AD16: =IF(AND(R16>0,Z16>0),Z16/(R16),0) -> 0 | AE16: =IF(AND(S16>0,AA16>0),AA16/(S16),0) -> 1.6790243 | AF16: ='8'!I46 -> 6737.7 | AG16: =AF16+AG15 -> 242428.26 | AH16: =IF(AND(L16>0,AF16>0),(AF16/(P16*1000)*1000),0) -> #DIV/0! | AI16: =IF(AND(M16>0,AG16>0),(AG16/(Q16*1000)*1000),0) -> 920.58125 | AJ16: =IF(AND(R16>0,AF16>0),(AF16/(R16*1000)*1000),0) -> 0 | AK16: =IF(AND(S16>0,AG16>0),(AG16/(S16*1000)*1000),0) -> 992.54556 | AL16: 301.1 | AM16: 5838.5 | AN16: 4083.1 | AO16: =SUM(AL16:AN16) -> 10222.7 | AP16: =+[1]Sept!N11 -> 9805 | AQ16: =+AP16-AO16 -> -417.7 | AR16: =+AL16/AO16 -> 0.029454058 | AS16: =+AM16/AO16 -> 0.57113091 | AT16: =1-AR16-AS16 -> 0.39941503 | AU16: =+AR16*AQ16 -> -12.30296 | AV16: =+AS16*AQ16 -> -238.56138 | AW16: =+AT16*AQ16 -> -166.83566 | AX16: =+AL16+AU16 -> 288.79704 | AY16: =+AM16+AV16 -> 5599.9386 | AZ16: =+AN16+AW16 -> 3916.2643 | BA16: =+Efficiency2!K36 -> 41.078379 | BB16: =BB15+BA16 -> 343.58351 | BC16: =+R16/BA16 -> 0 | BD16: =+S16/BB16 -> 0.71088685
A17: =A16+1 -> 45909 | B17: Facial | C17: 12/13 | D17: =+'9'!F42 -> 1123.75 | E17: =+'9'!G42 -> 865.2875 | F17: =1-(E17/D17) -> 0.23 | G17: =+P17/N17 -> 0.97413663 | H17: =+P17/L17 -> 0.88305266 | I17: =+R17/P17 -> 0.85867051 | J17: =+R17/L17 -> 0.75825128 | K17: =+S17/M17 -> 0.71642963 | L17: =+SUM(Efficiency1!K41:K42) -> 45.536356 | M17: =M16+L17 -> 389.11987 | N17: =+SUM(Efficiency1!C41:C42) -> 41.278604 | O17: =O16+N17 -> 382.67342 | P17: ='9'!I38 -> 40.211 | Q17: =Q16+P17 -> 303.5536 | R17: ='9'!I40 -> 34.528 | S17: =S16+R17 -> 278.777 | T17: =+AX17 -> 3682.139 | U17: =T17+U16 -> 28216.413 | V17: =T17/P17 -> 91.570441 | W17: =U17/Q17 -> 92.953642 | X17: =IF(AND(R17>0,T17>0),(T17/(R17*1000))*1000,0) -> 106.64212 | Y17: =IF(AND(S17>0,U17>0),U17/S17,0) -> 101.21499 | Z17: 64.5 | AA17: =Z17+AA16 -> 474.6 | AB17: =Z17/(P17) -> 1.6040387 | AC17: =AA17/(Q17) -> 1.5634801 | AD17: =IF(AND(R17>0,Z17>0),Z17/(R17),0) -> 1.8680491 | AE17: =IF(AND(S17>0,AA17>0),AA17/(S17),0) -> 1.702436 | AF17: ='9'!I46 -> 35659.62 | AG17: =AF17+AG16 -> 278087.88 | AH17: =IF(AND(L17>0,AF17>0),(AF17/(P17*1000)*1000),0) -> 886.81256 | AI17: =IF(AND(M17>0,AG17>0),(AG17/(Q17*1000)*1000),0) -> 916.108 | AJ17: =IF(AND(R17>0,AF17>0),(AF17/(R17*1000)*1000),0) -> 1032.774 | AK17: =IF(AND(S17>0,AG17>0),(AG17/(S17*1000)*1000),0) -> 997.52806 | AL17: 4075.3 | AM17: 4405.6 | AN17: 3623.9 | AO17: =SUM(AL17:AN17) -> 12104.8 | AP17: =+[1]Sept!N12 -> 10937 | AQ17: =+AP17-AO17 -> -1167.8 | AR17: =+AL17/AO17 -> 0.3366681 | AS17: =+AM17/AO17 -> 0.36395479 | AT17: =1-AR17-AS17 -> 0.29937711 | AU17: =+AR17*AQ17 -> -393.16101 | AV17: =+AS17*AQ17 -> -425.02641 | AW17: =+AT17*AQ17 -> -349.61259 | AX17: =+AL17+AU17 -> 3682.139 | AY17: =+AM17+AV17 -> 3980.5736 | AZ17: =+AN17+AW17 -> 3274.2874 | BA17: =+SUM(Efficiency2!K41:K42) -> 45.536356 | BB17: =BB16+BA17 -> 389.11987 | BC17: =+R17/BA17 -> 0.75825128 | BD17: =+S17/BB17 -> 0.71642963
A18: =A17+1 -> 45910 | B18: Facial | C18: 12/12,5 | D18: =+'10'!F42 -> 1230 | E18: =+'10'!G42 -> 947.1 | F18: =1-(E18/D18) -> 0.23 | G18: =+P18/N18 -> 0.90498989 | H18: =+P18/L18 -> 0.8998398 | I18: =+R18/P18 -> 0.94562851 | J18: =+R18/L18 -> 0.85091418 | K18: =+S18/M18 -> 0.73006475 | L18: =+SUM(Efficiency1!K45:K46) -> 43.90337 | M18: =M17+L18 -> 433.02324 | N18: =+SUM(Efficiency1!C45:C46) -> 43.653526 | O18: =O17+N18 -> 426.32694 | P18: ='10'!I38 -> 39.506 | Q18: =Q17+P18 -> 343.0596 | R18: ='10'!I40 -> 37.358 | S18: =S17+R18 -> 316.135 | T18: =+AX18 -> 4248.9101 | U18: =T18+U17 -> 32465.323 | V18: =T18/P18 -> 107.55101 | W18: =U18/Q18 -> 94.634643 | X18: =IF(AND(R18>0,T18>0),(T18/(R18*1000))*1000,0) -> 113.73495 | Y18: =IF(AND(S18>0,U18>0),U18/S18,0) -> 102.69449 | Z18: 58.4 | AA18: =Z18+AA17 -> 533 | AB18: =Z18/(P18) -> 1.4782565 | AC18: =AA18/(Q18) -> 1.5536659 | AD18: =IF(AND(R18>0,Z18>0),Z18/(R18),0) -> 1.5632529 | AE18: =IF(AND(S18>0,AA18>0),AA18/(S18),0) -> 1.6859886 | AF18: ='10'!I46 -> 34183.14 | AG18: =AF18+AG17 -> 312271.02 | AH18: =IF(AND(L18>0,AF18>0),(AF18/(P18*1000)*1000),0) -> 865.26452 | AI18: =IF(AND(M18>0,AG18>0),(AG18/(Q18*1000)*1000),0) -> 910.25297 | AJ18: =IF(AND(R18>0,AF18>0),(AF18/(R18*1000)*1000),0) -> 915.01526 | AK18: =IF(AND(S18>0,AG18>0),(AG18/(S18*1000)*1000),0) -> 987.77744 | AL18: 4141.4 | AM18: 1817.1 | AN18: 3290.4 | AO18: =SUM(AL18:AN18) -> 9248.9 | AP18: =+[1]Sept!N13 -> 9489 | AQ18: =+AP18-AO18 -> 240.1 | AR18: =+AL18/AO18 -> 0.44777217 | AS18: =+AM18/AO18 -> 0.19646661 | AT18: =1-AR18-AS18 -> 0.35576123 | AU18: =+AR18*AQ18 -> 107.5101 | AV18: =+AS18*AQ18 -> 47.171632 | AW18: =+AT18*AQ18 -> 85.41827 | AX18: =+AL18+AU18 -> 4248.9101 | AY18: =+AM18+AV18 -> 1864.2716 | AZ18: =+AN18+AW18 -> 3375.8183 | BA18: =+SUM(Efficiency2!K45:K46) -> 43.90337 | BB18: =BB17+BA18 -> 433.02324 | BC18: =+R18/BA18 -> 0.85091418 | BD18: =+S18/BB18 -> 0.73006475
A19: =A18+1 -> 45911 | B19: Facial | C19: 12,5/12 | D19: =+'11'!F42 -> 1195.0373 | E19: =+'11'!G42 -> 920.17873 | F19: =1-(E19/D19) -> 0.23 | G19: =+P19/N19 -> 0.93065184 | H19: =+P19/L19 -> 0.89446932 | I19: =+R19/P19 -> 0.97806918 | J19: =+R19/L19 -> 0.87485288 | K19: =+S19/M19 -> 0.74355839 | L19: =+SUM(Efficiency1!K50:K51) -> 44.503483 | M19: =M18+L19 -> 477.52672 | N19: =+SUM(Efficiency1!C50:C51) -> 42.773246 | O19: =O18+N19 -> 469.10019 | P19: ='11'!I38 -> 39.807 | Q19: =Q18+P19 -> 382.8666 | R19: ='11'!I40 -> 38.934 | S19: =S18+R19 -> 355.069 | T19: =+AX19 -> 3443.871 | U19: =T19+U18 -> 35909.194 | V19: =T19/P19 -> 86.514205 | W19: =U19/Q19 -> 93.790353 | X19: =IF(AND(R19>0,T19>0),(T19/(R19*1000))*1000,0) -> 88.454075 | Y19: =IF(AND(S19>0,U19>0),U19/S19,0) -> 101.133 | Z19: 60.2 | AA19: =Z19+AA18 -> 593.2 | AB19: =Z19/(P19) -> 1.5122968 | AC19: =AA19/(Q19) -> 1.5493647 | AD19: =IF(AND(R19>0,Z19>0),Z19/(R19),0) -> 1.5462064 | AE19: =IF(AND(S19>0,AA19>0),AA19/(S19),0) -> 1.6706612 | AF19: ='11'!I46 -> 37218.96 | AG19: =AF19+AG18 -> 349489.98 | AH19: =IF(AND(L19>0,AF19>0),(AF19/(P19*1000)*1000),0) -> 934.9853 | AI19: =IF(AND(M19>0,AG19>0),(AG19/(Q19*1000)*1000),0) -> 912.82441 | AJ19: =IF(AND(R19>0,AF19>0),(AF19/(R19*1000)*1000),0) -> 955.95007 | AK19: =IF(AND(S19>0,AG19>0),(AG19/(S19*1000)*1000),0) -> 984.2875 | AL19: 3778.1 | AM19: 4791.6 | AN19: 3294.9 | AO19: =SUM(AL19:AN19) -> 11864.6 | AP19: =+[1]Sept!N14 -> 10815 | AQ19: =+AP19-AO19 -> -1049.6 | AR19: =+AL19/AO19 -> 0.31843467 | AS19: =+AM19/AO19 -> 0.40385685 | AT19: =1-AR19-AS19 -> 0.27770848 | AU19: =+AR19*AQ19 -> -334.22903 | AV19: =+AS19*AQ19 -> -423.88815 | AW19: =+AT19*AQ19 -> -291.48282 | AX19: =+AL19+AU19 -> 3443.871 | AY19: =+AM19+AV19 -> 4367.7118 | AZ19: =+AN19+AW19 -> 3003.4172 | BA19: =+SUM(Efficiency2!K50:K51) -> 44.503483 | BB19: =BB18+BA19 -> 477.52672 | BC19: =+R19/BA19 -> 0.87485288 | BD19: =+S19/BB19 -> 0.74355839
A20: =A19+1 -> 45912 | B20: Facial | C20: 12/13,5/13 | D20: =+'12'!F42 -> 1228.2292 | E20: =+'12'!G42 -> 945.73646 | F20: =1-(E20/D20) -> 0.23 | G20: =+P20/N20 -> 0.98942646 | H20: =+P20/L20 -> 0.98114154 | I20: =+R20/P20 -> 0.90031749 | J20: =+R20/L20 -> 0.88333889 | K20: =+S20/M20 -> 0.75566095 | L20: =+SUM(Efficiency1!K55:K57) -> 45.264621 | M20: =M19+L20 -> 522.79134 | N20: =+SUM(Efficiency1!C55:C57) -> 44.8856 | O20: =O19+N20 -> 513.98579 | P20: ='12'!I38 -> 44.411 | Q20: =Q19+P20 -> 427.2776 | R20: ='12'!I40 -> 39.984 | S20: =S19+R20 -> 395.053 | T20: =+AX20 -> 4051.9974 | U20: =T20+U19 -> 39961.191 | V20: =T20/P20 -> 91.238598 | W20: =U20/Q20 -> 93.525125 | X20: =IF(AND(R20>0,T20>0),(T20/(R20*1000))*1000,0) -> 101.34047 | Y20: =IF(AND(S20>0,U20>0),U20/S20,0) -> 101.154 | Z20: 60.8 | AA20: =Z20+AA19 -> 654 | AB20: =Z20/(P20) -> 1.3690302 | AC20: =AA20/(Q20) -> 1.5306208 | AD20: =IF(AND(R20>0,Z20>0),Z20/(R20),0) -> 1.5206082 | AE20: =IF(AND(S20>0,AA20>0),AA20/(S20),0) -> 1.6554741 | AF20: ='12'!I46 -> 39870.6 | AG20: =AF20+AG19 -> 389360.58 | AH20: =IF(AND(L20>0,AF20>0),(AF20/(P20*1000)*1000),0) -> 897.76407 | AI20: =IF(AND(M20>0,AG20>0),(AG20/(Q20*1000)*1000),0) -> 911.25905 | AJ20: =IF(AND(R20>0,AF20>0),(AF20/(R20*1000)*1000),0) -> 997.16387 | AK20: =IF(AND(S20>0,AG20>0),(AG20/(S20*1000)*1000),0) -> 985.59074 | AL20: 4145.1 | AM20: 6415.6 | AN20: 3610.6 | AO20: =SUM(AL20:AN20) -> 14171.3 | AP20: =+[1]Sept!N15 -> 13853 | AQ20: =+AP20-AO20 -> -318.3 | AR20: =+AL20/AO20 -> 0.29249963 | AS20: =+AM20/AO20 -> 0.45271782 | AT20: =1-AR20-AS20 -> 0.25478255 | AU20: =+AR20*AQ20 -> -93.102632 | AV20: =+AS20*AQ20 -> -144.10008 | AW20: =+AT20*AQ20 -> -81.097287 | AX20: =+AL20+AU20 -> 4051.9974 | AY20: =+AM20+AV20 -> 6271.4999 | AZ20: =+AN20+AW20 -> 3529.5027 | BA20: =+SUM(Efficiency2!K55:K57) -> 45.264621 | BB20: =BB19+BA20 -> 522.79134 | BC20: =+R20/BA20 -> 0.88333889 | BD20: =+S20/BB20 -> 0.75566095
A21: =A20+1 -> 45913 | B21: Facial | C21: 13/12 | D21: =+'13'!F42 -> 1230 | E21: =+'13'!G42 -> 947.1 | F21: =1-(E21/D21) -> 0.23 | G21: =+P21/N21 -> 0.31265985 | H21: =+P21/L21 -> 0.31181437 | I21: =+R21/P21 -> 1.3655299 | J21: =+R21/L21 -> 0.42579185 | K21: =+S21/M21 -> 0.73019933 | L21: =+SUM(Efficiency1!K59:K60) -> 43.727939 | M21: =M20+L21 -> 566.51928 | N21: =+SUM(Efficiency1!C59:C60) -> 43.609693 | O21: =O20+N21 -> 557.59548 | P21: ='13'!I38 -> 13.635 | Q21: =Q20+P21 -> 440.9126 | R21: ='13'!I40 -> 18.619 | S21: =S20+R21 -> 413.672 | T21: =+AX21 -> 1108.2831 | U21: =T21+U20 -> 41069.474 | V21: =T21/P21 -> 81.282224 | W21: =U21/Q21 -> 93.14652 | X21: =IF(AND(R21>0,T21>0),(T21/(R21*1000))*1000,0) -> 59.52431 | Y21: =IF(AND(S21>0,U21>0),U21/S21,0) -> 99.280285 | Z21: 19.2 | AA21: =Z21+AA20 -> 673.2 | AB21: =Z21/(P21) -> 1.4081408 | AC21: =AA21/(Q21) -> 1.5268332 | AD21: =IF(AND(R21>0,Z21>0),Z21/(R21),0) -> 1.0312047 | AE21: =IF(AND(S21>0,AA21>0),AA21/(S21),0) -> 1.6273763 | AF21: ='13'!I46 -> 21110.86 | AG21: =AF21+AG20 -> 410471.44 | AH21: =IF(AND(L21>0,AF21>0),(AF21/(P21*1000)*1000),0) -> 1548.2846 | AI21: =IF(AND(M21>0,AG21>0),(AG21/(Q21*1000)*1000),0) -> 930.95874 | AJ21: =IF(AND(R21>0,AF21>0),(AF21/(R21*1000)*1000),0) -> 1133.8343 | AK21: =IF(AND(S21>0,AG21>0),(AG21/(S21*1000)*1000),0) -> 992.26305 | AL21: 1134.4 | AM21: 6869.1 | AN21: 3784.9 | AO21: =SUM(AL21:AN21) -> 11788.4 | AP21: =+[1]Sept!N16 -> 11517 | AQ21: =+AP21-AO21 -> -271.4 | AR21: =+AL21/AO21 -> 0.096230192 | AS21: =+AM21/AO21 -> 0.58269994 | AT21: =1-AR21-AS21 -> 0.32106987 | AU21: =+AR21*AQ21 -> -26.116874 | AV21: =+AS21*AQ21 -> -158.14476 | AW21: =+AT21*AQ21 -> -87.138361 | AX21: =+AL21+AU21 -> 1108.2831 | AY21: =+AM21+AV21 -> 6710.9552 | AZ21: =+AN21+AW21 -> 3697.7616 | BA21: =+SUM(Efficiency2!K59:K60) -> 14.023852 | BB21: =BB20+BA21 -> 536.81519 | BC21: =+R21/BA21 -> 1.3276666 | BD21: =+S21/BB21 -> 0.77060412
A22: =A21+1 -> 45914 | B22: STOP | C22: 12 | D22: =+'14'!F42 -> 0 | E22: =+'14'!G42 -> 0 | F22: =1-(E22/D22) -> #DIV/0! | G22: =+P22/N22 -> 0 | H22: =+P22/L22 -> 0 | I22: =+R22/P22 -> #DIV/0! | J22: =+R22/L22 -> 0 | K22: =+S22/M22 -> 0.67845643 | L22: =+Efficiency1!K64 -> 43.205944 | M22: =M21+L22 -> 609.72522 | N22: =+Efficiency1!C64 -> 43.205944 | O22: =O21+N22 -> 600.80143 | P22: ='14'!I38 -> 0 | Q22: =Q21+P22 -> 440.9126 | R22: ='14'!I40 -> 0 | S22: =S21+R22 -> 413.672 | T22: =+AX22 -> 0 | U22: =T22+U21 -> 41069.474 | V22: =T22/P22 -> #DIV/0! | W22: =U22/Q22 -> 93.14652 | X22: =IF(AND(R22>0,T22>0),(T22/(R22*1000))*1000,0) -> 0 | Y22: =IF(AND(S22>0,U22>0),U22/S22,0) -> 99.280285 | Z22: 2 | AA22: =Z22+AA21 -> 675.2 | AB22: =Z22/(P22) -> #DIV/0! | AC22: =AA22/(Q22) -> 1.5313693 | AD22: =IF(AND(R22>0,Z22>0),Z22/(R22),0) -> 0 | AE22: =IF(AND(S22>0,AA22>0),AA22/(S22),0) -> 1.632211 | AF22: ='14'!I46 -> 6791.74 | AG22: =AF22+AG21 -> 417263.18 | AH22: =IF(AND(L22>0,AF22>0),(AF22/(P22*1000)*1000),0) -> #DIV/0! | AI22: =IF(AND(M22>0,AG22>0),(AG22/(Q22*1000)*1000),0) -> 946.36257 | AJ22: =IF(AND(R22>0,AF22>0),(AF22/(R22*1000)*1000),0) -> 0 | AK22: =IF(AND(S22>0,AG22>0),(AG22/(S22*1000)*1000),0) -> 1008.6812 | AL22: 0 | AM22: 5705.8 | AN22: 4068.3 | AO22: =SUM(AL22:AN22) -> 9774.1 | AP22: =+[1]Sept!N17 -> 8962 | AQ22: =+AP22-AO22 -> -812.1 | AR22: =+AL22/AO22 -> 0 | AS22: =+AM22/AO22 -> 0.5837673 | AT22: =1-AR22-AS22 -> 0.4162327 | AU22: =+AR22*AQ22 -> 0 | AV22: =+AS22*AQ22 -> -474.07743 | AW22: =+AT22*AQ22 -> -338.02257 | AX22: =+AL22+AU22 -> 0 | AY22: =+AM22+AV22 -> 5231.7226 | AZ22: =+AN22+AW22 -> 3730.2774 | BA22: =+Efficiency2!K64 -> 0 | BB22: =BB21+BA22 -> 536.81519 | BC22: =+R22/BA22 -> #DIV/0! | BD22: =+S22/BB22 -> 0.77060412
A23: =A22+1 -> 45915 | B23: STOP | C23: 12 | D23: =+'15'!F42 -> 0 | E23: =+'15'!G42 -> 0 | F23: =1-(E23/D23) -> #DIV/0! | G23: =+P23/N23 -> 0 | H23: =+P23/L23 -> 0 | I23: =+R23/P23 -> #DIV/0! | J23: =+R23/L23 -> 0 | K23: =+S23/M23 -> 0.63356142 | L23: =+Efficiency1!K69 -> 43.205944 | M23: =M22+L23 -> 652.93117 | N23: =+Efficiency1!C69 -> 43.205944 | O23: =O22+N23 -> 644.00737 | P23: ='15'!I38 -> 0 | Q23: =Q22+P23 -> 440.9126 | R23: ='15'!I40 -> 0 | S23: =S22+R23 -> 413.672 | T23: =+AX23 -> 0 | U23: =T23+U22 -> 41069.474 | V23: =T23/P23 -> #DIV/0! | W23: =U23/Q23 -> 93.14652 | X23: =IF(AND(R23>0,T23>0),(T23/(R23*1000))*1000,0) -> 0 | Y23: =IF(AND(S23>0,U23>0),U23/S23,0) -> 99.280285 | Z23: 2.6 | AA23: =Z23+AA22 -> 677.8 | AB23: =Z23/(P23) -> #DIV/0! | AC23: =AA23/(Q23) -> 1.5372661 | AD23: =IF(AND(R23>0,Z23>0),Z23/(R23),0) -> 0 | AE23: =IF(AND(S23>0,AA23>0),AA23/(S23),0) -> 1.6384962 | AF23: ='15'!I46 -> 6015.06 | AG23: =AF23+AG22 -> 423278.24 | AH23: =IF(AND(L23>0,AF23>0),(AF23/(P23*1000)*1000),0) -> #DIV/0! | AI23: =IF(AND(M23>0,AG23>0),(AG23/(Q23*1000)*1000),0) -> 960.00486 | AJ23: =IF(AND(R23>0,AF23>0),(AF23/(R23*1000)*1000),0) -> 0 | AK23: =IF(AND(S23>0,AG23>0),(AG23/(S23*1000)*1000),0) -> 1023.2219 | AL23: 0 | AM23: 6410.1 | AN23: 3956.6 | AO23: =SUM(AL23:AN23) -> 10366.7 | AP23: =+[1]Sept!N18 -> 9595 | AQ23: =+AP23-AO23 -> -771.7 | AR23: =+AL23/AO23 -> 0 | AS23: =+AM23/AO23 -> 0.61833563 | AT23: =1-AR23-AS23 -> 0.38166437 | AU23: =+AR23*AQ23 -> 0 | AV23: =+AS23*AQ23 -> -477.16961 | AW23: =+AT23*AQ23 -> -294.53039 | AX23: =+AL23+AU23 -> 0 | AY23: =+AM23+AV23 -> 5932.9304 | AZ23: =+AN23+AW23 -> 3662.0696 | BA23: =+Efficiency2!K69 -> 0 | BB23: =BB22+BA23 -> 536.81519 | BC23: =+R23/BA23 -> #DIV/0! | BD23: =+S23/BB23 -> 0.77060412
A24: =A23+1 -> 45916 | B24: STOP | C24: 12 | D24: =+'16'!F42 -> 0 | E24: =+'16'!G42 -> 0 | F24: =1-(E24/D24) -> #DIV/0! | G24: =+P24/N24 -> 0 | H24: =+P24/L24 -> 0 | I24: =+R24/P24 -> #DIV/0! | J24: =+R24/L24 -> 0 | K24: =+S24/M24 -> 0.59423926 | L24: =+Efficiency1!K74 -> 43.205944 | M24: =M23+L24 -> 696.13711 | N24: =+Efficiency1!C74 -> 43.205944 | O24: =O23+N24 -> 687.21332 | P24: ='16'!I38 -> 0 | Q24: =Q23+P24 -> 440.9126 | R24: ='16'!I40 -> 0 | S24: =S23+R24 -> 413.672 | T24: =+AX24 -> 0 | U24: =T24+U23 -> 41069.474 | V24: =T24/P24 -> #DIV/0! | W24: =U24/Q24 -> 93.14652 | X24: =IF(AND(R24>0,T24>0),(T24/(R24*1000))*1000,0) -> 0 | Y24: =IF(AND(S24>0,U24>0),U24/S24,0) -> 99.280285 | Z24: 15.3 | AA24: =Z24+AA23 -> 693.1 | AB24: =Z24/(P24) -> #DIV/0! | AC24: =AA24/(Q24) -> 1.5719669 | AD24: =IF(AND(R24>0,Z24>0),Z24/(R24),0) -> 0 | AE24: =IF(AND(S24>0,AA24>0),AA24/(S24),0) -> 1.675482 | AF24: ='16'!I46 -> 8464.42 | AG24: =AF24+AG23 -> 431742.66 | AH24: =IF(AND(L24>0,AF24>0),(AF24/(P24*1000)*1000),0) -> #DIV/0! | AI24: =IF(AND(M24>0,AG24>0),(AG24/(Q24*1000)*1000),0) -> 979.20236 | AJ24: =IF(AND(R24>0,AF24>0),(AF24/(R24*1000)*1000),0) -> 0 | AK24: =IF(AND(S24>0,AG24>0),(AG24/(S24*1000)*1000),0) -> 1043.6835 | AL24: 0 | AM24: 6261.7 | AN24: 3554 | AO24: =SUM(AL24:AN24) -> 9815.7 | AP24: =+[1]Sept!N19 -> 9071 | AQ24: =+AP24-AO24 -> -744.7 | AR24: =+AL24/AO24 -> 0 | AS24: =+AM24/AO24 -> 0.63792699 | AT24: =1-AR24-AS24 -> 0.36207301 | AU24: =+AR24*AQ24 -> 0 | AV24: =+AS24*AQ24 -> -475.06423 | AW24: =+AT24*AQ24 -> -269.63577 | AX24: =+AL24+AU24 -> 0 | AY24: =+AM24+AV24 -> 5786.6358 | AZ24: =+AN24+AW24 -> 3284.3642 | BA24: =+Efficiency2!K74 -> 0 | BB24: =BB23+BA24 -> 536.81519 | BC24: =+R24/BA24 -> #DIV/0! | BD24: =+S24/BB24 -> 0.77060412
A25: =A24+1 -> 45917 | B25: STOP | C25: 12 | D25: =+'17'!F42 -> 0 | E25: =+'17'!G42 -> 0 | F25: =1-(E25/D25) -> #DIV/0! | G25: =+P25/N25 -> 0 | H25: =+P25/L25 -> 0 | I25: =+R25/P25 -> #DIV/0! | J25: =+R25/L25 -> 0 | K25: =+S25/M25 -> 0.55951293 | L25: =+Efficiency1!K79 -> 43.205944 | M25: =M24+L25 -> 739.34306 | N25: =+Efficiency1!M79 -> 947.1 | O25: =O24+N25 -> 1634.3133 | P25: ='17'!I38 -> 0 | Q25: =Q24+P25 -> 440.9126 | R25: ='17'!I40 -> 0 | S25: =S24+R25 -> 413.672 | T25: =+AX25 -> 0 | U25: =T25+U24 -> 41069.474 | V25: =T25/P25 -> #DIV/0! | W25: =U25/Q25 -> 93.14652 | X25: =IF(AND(R25>0,T25>0),(T25/(R25*1000))*1000,0) -> 0 | Y25: =IF(AND(S25>0,U25>0),U25/S25,0) -> 99.280285 | Z25: 5.5 | AA25: =Z25+AA24 -> 698.6 | AB25: =Z25/(P25) -> #DIV/0! | AC25: =AA25/(Q25) -> 1.584441 | AD25: =IF(AND(R25>0,Z25>0),Z25/(R25),0) -> 0 | AE25: =IF(AND(S25>0,AA25>0),AA25/(S25),0) -> 1.6887776 | AF25: ='17'!I46 -> 7350.72 | AG25: =AF25+AG24 -> 439093.38 | AH25: =IF(AND(L25>0,AF25>0),(AF25/(P25*1000)*1000),0) -> #DIV/0! | AI25: =IF(AND(M25>0,AG25>0),(AG25/(Q25*1000)*1000),0) -> 995.87397 | AJ25: =IF(AND(R25>0,AF25>0),(AF25/(R25*1000)*1000),0) -> 0 | AK25: =IF(AND(S25>0,AG25>0),(AG25/(S25*1000)*1000),0) -> 1061.453 | AL25: 0 | AM25: 6367 | AN25: 3841.6 | AO25: =SUM(AL25:AN25) -> 10208.6 | AP25: =+[1]Sept!N20 -> 10291 | AQ25: =+AP25-AO25 -> 82.4 | AR25: =+AL25/AO25 -> 0 | AS25: =+AM25/AO25 -> 0.62368983 | AT25: =1-AR25-AS25 -> 0.37631017 | AU25: =+AR25*AQ25 -> 0 | AV25: =+AS25*AQ25 -> 51.392042 | AW25: =+AT25*AQ25 -> 31.007958 | AX25: =+AL25+AU25 -> 0 | AY25: =+AM25+AV25 -> 6418.392 | AZ25: =+AN25+AW25 -> 3872.608 | BA25: =+Efficiency2!K79 -> 0 | BB25: =BB24+BA25 -> 536.81519 | BC25: =+R25/BA25 -> #DIV/0! | BD25: =+S25/BB25 -> 0.77060412
A26: =A25+1 -> 45918 | B26: STOP | C26: 12 | D26: =+'18'!F42 -> 0 | E26: =+'18'!G42 -> 0 | F26: =1-(E26/D26) -> #DIV/0! | G26: =+P26/N26 -> 0 | H26: =+P26/L26 -> 0 | I26: =+R26/P26 -> #DIV/0! | J26: =+R26/L26 -> 0 | K26: =+S26/M26 -> 0.52862121 | L26: =+Efficiency1!K84 -> 43.205944 | M26: =M25+L26 -> 782.549 | N26: =+Efficiency1!C84 -> 43.205944 | O26: =O25+N26 -> 1677.5193 | P26: ='18'!I38 -> 0 | Q26: =Q25+P26 -> 440.9126 | R26: ='18'!I40 -> 0 | S26: =S25+R26 -> 413.672 | T26: =+AX26 -> 0 | U26: =T26+U25 -> 41069.474 | V26: =T26/P26 -> #DIV/0! | W26: =U26/Q26 -> 93.14652 | X26: =IF(AND(R26>0,T26>0),(T26/(R26*1000))*1000,0) -> 0 | Y26: =IF(AND(S26>0,U26>0),U26/S26,0) -> 99.280285 | Z26: 2.7 | AA26: =Z26+AA25 -> 701.3 | AB26: =Z26/(P26) -> #DIV/0! | AC26: =AA26/(Q26) -> 1.5905647 | AD26: =IF(AND(R26>0,Z26>0),Z26/(R26),0) -> 0 | AE26: =IF(AND(S26>0,AA26>0),AA26/(S26),0) -> 1.6953045 | AF26: ='18'!I46 -> 5151.86 | AG26: =AF26+AG25 -> 444245.24 | AH26: =IF(AND(L26>0,AF26>0),(AF26/(P26*1000)*1000),0) -> #DIV/0! | AI26: =IF(AND(M26>0,AG26>0),(AG26/(Q26*1000)*1000),0) -> 1007.5585 | AJ26: =IF(AND(R26>0,AF26>0),(AF26/(R26*1000)*1000),0) -> 0 | AK26: =IF(AND(S26>0,AG26>0),(AG26/(S26*1000)*1000),0) -> 1073.907 | AL26: 0 | AM26: 6018 | AN26: 3472.3 | AO26: =SUM(AL26:AN26) -> 9490.3 | AP26: =+[1]Sept!N21 -> 9231 | AQ26: =+AP26-AO26 -> -259.3 | AR26: =+AL26/AO26 -> 0 | AS26: =+AM26/AO26 -> 0.63412116 | AT26: =1-AR26-AS26 -> 0.36587884 | AU26: =+AR26*AQ26 -> 0 | AV26: =+AS26*AQ26 -> -164.42762 | AW26: =+AT26*AQ26 -> -94.872384 | AX26: =+AL26+AU26 -> 0 | AY26: =+AM26+AV26 -> 5853.5724 | AZ26: =+AN26+AW26 -> 3377.4276 | BA26: =+Efficiency2!K84 -> 0 | BB26: =BB25+BA26 -> 536.81519 | BC26: =+R26/BA26 -> #DIV/0! | BD26: =+S26/BB26 -> 0.77060412
A27: =A26+1 -> 45919 | B27: STOP | C27: 12 | D27: =+'19'!F42 -> 0 | E27: =+'19'!G42 -> 0 | F27: =1-(E27/D27) -> #DIV/0! | G27: =+P27/N27 -> 0 | H27: =+P27/L27 -> 0 | I27: =+R27/P27 -> #DIV/0! | J27: =+R27/L27 -> 0 | K27: =+S27/M27 -> 0.50096218 | L27: =+Efficiency1!K89 -> 43.205944 | M27: =M26+L27 -> 825.75495 | N27: =+Efficiency1!C89 -> 43.205944 | O27: =O26+N27 -> 1720.7252 | P27: ='19'!I38 -> 0 | Q27: =Q26+P27 -> 440.9126 | R27: ='19'!I40 -> 0 | S27: =S26+R27 -> 413.672 | T27: =+AX27 -> 0 | U27: =T27+U26 -> 41069.474 | V27: =T27/P27 -> #DIV/0! | W27: =U27/Q27 -> 93.14652 | X27: =IF(AND(R27>0,T27>0),(T27/(R27*1000))*1000,0) -> 0 | Y27: =IF(AND(S27>0,U27>0),U27/S27,0) -> 99.280285 | Z27: 3.9 | AA27: =Z27+AA26 -> 705.2 | AB27: =Z27/(P27) -> #DIV/0! | AC27: =AA27/(Q27) -> 1.59941 | AD27: =IF(AND(R27>0,Z27>0),Z27/(R27),0) -> 0 | AE27: =IF(AND(S27>0,AA27>0),AA27/(S27),0) -> 1.7047323 | AF27: ='19'!I46 -> 7147.1 | AG27: =AF27+AG26 -> 451392.34 | AH27: =IF(AND(L27>0,AF27>0),(AF27/(P27*1000)*1000),0) -> #DIV/0! | AI27: =IF(AND(M27>0,AG27>0),(AG27/(Q27*1000)*1000),0) -> 1023.7683 | AJ27: =IF(AND(R27>0,AF27>0),(AF27/(R27*1000)*1000),0) -> 0 | AK27: =IF(AND(S27>0,AG27>0),(AG27/(S27*1000)*1000),0) -> 1091.1842 | AL27: 0 | AM27: 6275.7 | AN27: 3535.4 | AO27: =SUM(AL27:AN27) -> 9811.1 | AP27: =+[1]Sept!N22 -> 9557 | AQ27: =+AP27-AO27 -> -254.1 | AR27: =+AL27/AO27 -> 0 | AS27: =+AM27/AO27 -> 0.63965305 | AT27: =1-AR27-AS27 -> 0.36034695 | AU27: =+AR27*AQ27 -> 0 | AV27: =+AS27*AQ27 -> -162.53584 | AW27: =+AT27*AQ27 -> -91.564161 | AX27: =+AL27+AU27 -> 0 | AY27: =+AM27+AV27 -> 6113.1642 | AZ27: =+AN27+AW27 -> 3443.8358 | BA27: =+Efficiency2!K89 -> 0 | BB27: =BB26+BA27 -> 536.81519 | BC27: =+R27/BA27 -> #DIV/0! | BD27: =+S27/BB27 -> 0.77060412
A28: =A27+1 -> 45920 | B28: STOP | C28: 12 | D28: =+'20'!F42 -> 0 | E28: =+'20'!G42 -> 0 | F28: =1-(E28/D28) -> #DIV/0! | G28: =+P28/N28 -> 0 | H28: =+P28/L28 -> 0 | I28: =+R28/P28 -> #DIV/0! | J28: =+R28/L28 -> 0 | K28: =+S28/M28 -> 0.47605365 | L28: =+Efficiency1!K94 -> 43.205944 | M28: =M27+L28 -> 868.96089 | N28: =+Efficiency1!C94 -> 43.205944 | O28: =O27+N28 -> 1763.9311 | P28: ='20'!I38 -> 0 | Q28: =Q27+P28 -> 440.9126 | R28: ='20'!I40 -> 0 | S28: =S27+R28 -> 413.672 | T28: =+AX28 -> 0 | U28: =T28+U27 -> 41069.474 | V28: =T28/P28 -> #DIV/0! | W28: =U28/Q28 -> 93.14652 | X28: =IF(AND(R28>0,T28>0),(T28/(R28*1000))*1000,0) -> 0 | Y28: =IF(AND(S28>0,U28>0),U28/S28,0) -> 99.280285 | Z28: 1.6 | AA28: =Z28+AA27 -> 706.8 | AB28: =Z28/(P28) -> #DIV/0! | AC28: =AA28/(Q28) -> 1.6030388 | AD28: =IF(AND(R28>0,Z28>0),Z28/(R28),0) -> 0 | AE28: =IF(AND(S28>0,AA28>0),AA28/(S28),0) -> 1.7086001 | AF28: ='20'!I46 -> 6389.08 | AG28: =AF28+AG27 -> 457781.42 | AH28: =IF(AND(L28>0,AF28>0),(AF28/(P28*1000)*1000),0) -> #DIV/0! | AI28: =IF(AND(M28>0,AG28>0),(AG28/(Q28*1000)*1000),0) -> 1038.2589 | AJ28: =IF(AND(R28>0,AF28>0),(AF28/(R28*1000)*1000),0) -> 0 | AK28: =IF(AND(S28>0,AG28>0),(AG28/(S28*1000)*1000),0) -> 1106.629 | AL28: 0 | AM28: 6260.9 | AN28: 3285.9 | AO28: =SUM(AL28:AN28) -> 9546.8 | AP28: =+[1]Sept!N23 -> 9331 | AQ28: =+AP28-AO28 -> -215.8 | AR28: =+AL28/AO28 -> 0 | AS28: =+AM28/AO28 -> 0.65581137 | AT28: =1-AR28-AS28 -> 0.34418863 | AU28: =+AR28*AQ28 -> 0 | AV28: =+AS28*AQ28 -> -141.52409 | AW28: =+AT28*AQ28 -> -74.275906 | AX28: =+AL28+AU28 -> 0 | AY28: =+AM28+AV28 -> 6119.3759 | AZ28: =+AN28+AW28 -> 3211.6241 | BA28: =+Efficiency2!K94 -> 0 | BB28: =BB27+BA28 -> 536.81519 | BC28: =+R28/BA28 -> #DIV/0! | BD28: =+S28/BB28 -> 0.77060412
A29: =A28+1 -> 45921 | B29: STOP | C29: 12 | D29: =+'21'!F42 -> 0 | E29: =+'21'!G42 -> 0 | F29: =1-(E29/D29) -> #DIV/0! | G29: =+P29/N29 -> 0 | H29: =+P29/L29 -> 0 | I29: =+R29/P29 -> #DIV/0! | J29: =+R29/L29 -> 0 | K29: =+S29/M29 -> 0.45350476 | L29: =+Efficiency1!K99 -> 43.205944 | M29: =M28+L29 -> 912.16683 | N29: =+Efficiency1!C99 -> 43.205944 | O29: =O28+N29 -> 1807.1371 | P29: ='21'!I38 -> 0 | Q29: =Q28+P29 -> 440.9126 | R29: ='21'!I40 -> 0 | S29: =S28+R29 -> 413.672 | T29: =+AX29 -> 0 | U29: =T29+U28 -> 41069.474 | V29: =T29/P29 -> #DIV/0! | W29: =U29/Q29 -> 93.14652 | X29: =IF(AND(R29>0,T29>0),(T29/(R29*1000))*1000,0) -> 0 | Y29: =IF(AND(S29>0,U29>0),U29/S29,0) -> 99.280285 | Z29: 7.3 | AA29: =Z29+AA28 -> 714.1 | AB29: =Z29/(P29) -> #DIV/0! | AC29: =AA29/(Q29) -> 1.6195954 | AD29: =IF(AND(R29>0,Z29>0),Z29/(R29),0) -> 0 | AE29: =IF(AND(S29>0,AA29>0),AA29/(S29),0) -> 1.7262469 | AF29: ='21'!I46 -> 9165.48 | AG29: =AF29+AG28 -> 466946.9 | AH29: =IF(AND(L29>0,AF29>0),(AF29/(P29*1000)*1000),0) -> #DIV/0! | AI29: =IF(AND(M29>0,AG29>0),(AG29/(Q29*1000)*1000),0) -> 1059.0464 | AJ29: =IF(AND(R29>0,AF29>0),(AF29/(R29*1000)*1000),0) -> 0 | AK29: =IF(AND(S29>0,AG29>0),(AG29/(S29*1000)*1000),0) -> 1128.7854 | AL29: 0 | AM29: 6251.9 | AN29: 3791.6 | AO29: =SUM(AL29:AN29) -> 10043.5 | AP29: =+[1]Sept!N24 -> 9789 | AQ29: =+AP29-AO29 -> -254.5 | AR29: =+AL29/AO29 -> 0 | AS29: =+AM29/AO29 -> 0.6224822 | AT29: =1-AR29-AS29 -> 0.3775178 | AU29: =+AR29*AQ29 -> 0 | AV29: =+AS29*AQ29 -> -158.42172 | AW29: =+AT29*AQ29 -> -96.078279 | AX29: =+AL29+AU29 -> 0 | AY29: =+AM29+AV29 -> 6093.4783 | AZ29: =+AN29+AW29 -> 3695.5217 | BA29: =+Efficiency2!K99 -> 0 | BB29: =BB28+BA29 -> 536.81519 | BC29: =+R29/BA29 -> #DIV/0! | BD29: =+S29/BB29 -> 0.77060412
A30: =A29+1 -> 45922 | B30: STOP | C30: 12 | D30: =+'22'!F42 -> 0 | E30: =+'22'!G42 -> 0 | F30: =1-(E30/D30) -> #DIV/0! | G30: =+P30/N30 -> 0 | H30: =+P30/L30 -> 0 | I30: =+R30/P30 -> #DIV/0! | J30: =+R30/L30 -> 0 | K30: =+S30/M30 -> 0.43299538 | L30: =+Efficiency1!K104 -> 43.205944 | M30: =M29+L30 -> 955.37278 | N30: =+Efficiency1!C104 -> 43.205944 | O30: =O29+N30 -> 1850.343 | P30: ='22'!I38 -> 0 | Q30: =Q29+P30 -> 440.9126 | R30: ='22'!I40 -> 0 | S30: =S29+R30 -> 413.672 | T30: =+AX30 -> 0 | U30: =T30+U29 -> 41069.474 | V30: =T30/P30 -> #DIV/0! | W30: =U30/Q30 -> 93.14652 | X30: =IF(AND(R30>0,T30>0),(T30/(R30*1000))*1000,0) -> 0 | Y30: =IF(AND(S30>0,U30>0),U30/S30,0) -> 99.280285 | Z30: 18.2 | AA30: =Z30+AA29 -> 732.3 | AB30: =Z30/(P30) -> #DIV/0! | AC30: =AA30/(Q30) -> 1.6608734 | AD30: =IF(AND(R30>0,Z30>0),Z30/(R30),0) -> 0 | AE30: =IF(AND(S30>0,AA30>0),AA30/(S30),0) -> 1.7702431 | AF30: ='22'!I46 -> 5417.62 | AG30: =AF30+AG29 -> 472364.52 | AH30: =IF(AND(L30>0,AF30>0),(AF30/(P30*1000)*1000),0) -> #DIV/0! | AI30: =IF(AND(M30>0,AG30>0),(AG30/(Q30*1000)*1000),0) -> 1071.3337 | AJ30: =IF(AND(R30>0,AF30>0),(AF30/(R30*1000)*1000),0) -> 0 | AK30: =IF(AND(S30>0,AG30>0),(AG30/(S30*1000)*1000),0) -> 1141.8818 | AL30: 0 | AM30: 6289.2 | AN30: 3690 | AO30: =SUM(AL30:AN30) -> 9979.2 | AP30: =+[1]Sept!N25 -> 9757 | AQ30: =+AP30-AO30 -> -222.2 | AR30: =+AL30/AO30 -> 0 | AS30: =+AM30/AO30 -> 0.63023088 | AT30: =1-AR30-AS30 -> 0.36976912 | AU30: =+AR30*AQ30 -> 0 | AV30: =+AS30*AQ30 -> -140.0373 | AW30: =+AT30*AQ30 -> -82.162698 | AX30: =+AL30+AU30 -> 0 | AY30: =+AM30+AV30 -> 6149.1627 | AZ30: =+AN30+AW30 -> 3607.8373 | BA30: =+Efficiency2!K104 -> 0 | BB30: =BB29+BA30 -> 536.81519 | BC30: =+R30/BA30 -> #DIV/0! | BD30: =+S30/BB30 -> 0.77060412
A31: =A30+1 -> 45923 | B31: STOP | C31: 12 | D31: =+'23'!F42 -> 0 | E31: =+'23'!G42 -> 0 | F31: =1-(E31/D31) -> #DIV/0! | G31: =+P31/N31 -> 0 | H31: =+P31/L31 -> 0 | I31: =+R31/P31 -> #DIV/0! | J31: =+R31/L31 -> 0 | K31: =+S31/M31 -> 0.41426078 | L31: =+Efficiency1!K109 -> 43.205944 | M31: =M30+L31 -> 998.57872 | N31: =+Efficiency1!C109 -> 43.205944 | O31: =O30+N31 -> 1893.549 | P31: ='23'!I38 -> 0 | Q31: =Q30+P31 -> 440.9126 | R31: ='23'!I40 -> 0 | S31: =S30+R31 -> 413.672 | T31: =+AX31 -> 0 | U31: =T31+U30 -> 41069.474 | V31: =T31/P31 -> #DIV/0! | W31: =U31/Q31 -> 93.14652 | X31: =IF(AND(R31>0,T31>0),(T31/(R31*1000))*1000,0) -> 0 | Y31: =IF(AND(S31>0,U31>0),U31/S31,0) -> 99.280285 | Z31: 21.1 | AA31: =Z31+AA30 -> 753.4 | AB31: =Z31/(P31) -> #DIV/0! | AC31: =AA31/(Q31) -> 1.7087287 | AD31: =IF(AND(R31>0,Z31>0),Z31/(R31),0) -> 0 | AE31: =IF(AND(S31>0,AA31>0),AA31/(S31),0) -> 1.8212497 | AF31: ='23'!I46 -> 7439.9 | AG31: =AF31+AG30 -> 479804.42 | AH31: =IF(AND(L31>0,AF31>0),(AF31/(P31*1000)*1000),0) -> #DIV/0! | AI31: =IF(AND(M31>0,AG31>0),(AG31/(Q31*1000)*1000),0) -> 1088.2075 | AJ31: =IF(AND(R31>0,AF31>0),(AF31/(R31*1000)*1000),0) -> 0 | AK31: =IF(AND(S31>0,AG31>0),(AG31/(S31*1000)*1000),0) -> 1159.8668 | AL31: 0 | AM31: 6222.9 | AN31: 3621.7 | AO31: =SUM(AL31:AN31) -> 9844.6 | AP31: =+[1]Sept!N26 -> 9236 | AQ31: =+AP31-AO31 -> -608.6 | AR31: =+AL31/AO31 -> 0 | AS31: =+AM31/AO31 -> 0.63211304 | AT31: =1-AR31-AS31 -> 0.36788696 | AU31: =+AR31*AQ31 -> 0 | AV31: =+AS31*AQ31 -> -384.70399 | AW31: =+AT31*AQ31 -> -223.89601 | AX31: =+AL31+AU31 -> 0 | AY31: =+AM31+AV31 -> 5838.196 | AZ31: =+AN31+AW31 -> 3397.804 | BA31: =+Efficiency2!K109 -> 0 | BB31: =BB30+BA31 -> 536.81519 | BC31: =+R31/BA31 -> #DIV/0! | BD31: =+S31/BB31 -> 0.77060412
A32: =A31+1 -> 45924 | B32: STOP | C32: 12 | D32: =+'24'!F42 -> 0 | E32: =+'24'!G42 -> 0 | F32: =1-(E32/D32) -> #DIV/0! | G32: =+P32/N32 -> 0 | H32: =+P32/L32 -> 0 | I32: =+R32/P32 -> #DIV/0! | J32: =+R32/L32 -> 0 | K32: =+S32/M32 -> 0.39708014 | L32: =+Efficiency1!K114 -> 43.205944 | M32: =M31+L32 -> 1041.7847 | N32: =+Efficiency1!C114 -> 43.205944 | O32: =O31+N32 -> 1936.7549 | P32: ='24'!I38 -> 0 | Q32: =Q31+P32 -> 440.9126 | R32: ='24'!I40 -> 0 | S32: =S31+R32 -> 413.672 | T32: =+AX32 -> 0 | U32: =T32+U31 -> 41069.474 | V32: =T32/P32 -> #DIV/0! | W32: =U32/Q32 -> 93.14652 | X32: =IF(AND(R32>0,T32>0),(T32/(R32*1000))*1000,0) -> 0 | Y32: =IF(AND(S32>0,U32>0),U32/S32,0) -> 99.280285 | Z32: 3.7 | AA32: =Z32+AA31 -> 757.1 | AB32: =Z32/(P32) -> #DIV/0! | AC32: =AA32/(Q32) -> 1.7171204 | AD32: =IF(AND(R32>0,Z32>0),Z32/(R32),0) -> 0 | AE32: =IF(AND(S32>0,AA32>0),AA32/(S32),0) -> 1.830194 | AF32: =+'24'!I46 -> 7098.9 | AG32: =AF32+AG31 -> 486903.32 | AH32: =IF(AND(L32>0,AF32>0),(AF32/(P32*1000)*1000),0) -> #DIV/0! | AI32: =IF(AND(M32>0,AG32>0),(AG32/(Q32*1000)*1000),0) -> 1104.308 | AJ32: =IF(AND(R32>0,AF32>0),(AF32/(R32*1000)*1000),0) -> 0 | AK32: =IF(AND(S32>0,AG32>0),(AG32/(S32*1000)*1000),0) -> 1177.0275 | AL32: 0 | AM32: 5878.3 | AN32: 4024 | AO32: =SUM(AL32:AN32) -> 9902.3 | AP32: =+[1]Sept!N27 -> 9716 | AQ32: =+AP32-AO32 -> -186.3 | AR32: =+AL32/AO32 -> 0 | AS32: =+AM32/AO32 -> 0.59362976 | AT32: =1-AR32-AS32 -> 0.40637024 | AU32: =+AR32*AQ32 -> 0 | AV32: =+AS32*AQ32 -> -110.59322 | AW32: =+AT32*AQ32 -> -75.706775 | AX32: =+AL32+AU32 -> 0 | AY32: =+AM32+AV32 -> 5767.7068 | AZ32: =+AN32+AW32 -> 3948.2932 | BA32: =+Efficiency2!K114 -> 0 | BB32: =BB31+BA32 -> 536.81519 | BC32: =+R32/BA32 -> #DIV/0! | BD32: =+S32/BB32 -> 0.77060412
A33: =A32+1 -> 45925 | B33: STOP | C33: 12 | D33: =+'25'!F42 -> 0 | E33: =+'25'!G42 -> 0 | F33: =1-(E33/D33) -> #DIV/0! | G33: =+P33/N33 -> 0 | H33: =+P33/L33 -> 0 | I33: =+R33/P33 -> #DIV/0! | J33: =+R33/L33 -> 0 | K33: =+S33/M33 -> 0.38126782 | L33: =+Efficiency1!K119 -> 43.205944 | M33: =M32+L33 -> 1084.9906 | N33: =+Efficiency1!C119 -> 43.205944 | O33: =O32+N33 -> 1979.9609 | P33: ='25'!I38 -> 0 | Q33: =Q32+P33 -> 440.9126 | R33: ='25'!I40 -> 0 | S33: =S32+R33 -> 413.672 | T33: =+AX33 -> 0 | U33: =T33+U32 -> 41069.474 | V33: =T33/P33 -> #DIV/0! | W33: =U33/Q33 -> 93.14652 | X33: =IF(AND(R33>0,T33>0),(T33/(R33*1000))*1000,0) -> 0 | Y33: =IF(AND(S33>0,U33>0),U33/S33,0) -> 99.280285 | Z33: 4.6 | AA33: =Z33+AA32 -> 761.7 | AB33: =Z33/(P33) -> #DIV/0! | AC33: =AA33/(Q33) -> 1.7275533 | AD33: =IF(AND(R33>0,Z33>0),Z33/(R33),0) -> 0 | AE33: =IF(AND(S33>0,AA33>0),AA33/(S33),0) -> 1.8413139 | AF33: =+'25'!I46 -> 7965.82 | AG33: =AF33+AG32 -> 494869.14 | AH33: =IF(AND(L33>0,AF33>0),(AF33/(P33*1000)*1000),0) -> #DIV/0! | AI33: =IF(AND(M33>0,AG33>0),(AG33/(Q33*1000)*1000),0) -> 1122.3747 | AJ33: =IF(AND(R33>0,AF33>0),(AF33/(R33*1000)*1000),0) -> 0 | AK33: =IF(AND(S33>0,AG33>0),(AG33/(S33*1000)*1000),0) -> 1196.2839 | AL33: 0 | AM33: 6118.5 | AN33: 3643.9 | AO33: =SUM(AL33:AN33) -> 9762.4 | AP33: =+[1]Sept!N28 -> 9519 | AQ33: =+AP33-AO33 -> -243.4 | AR33: =+AL33/AO33 -> 0 | AS33: =+AM33/AO33 -> 0.62674138 | AT33: =1-AR33-AS33 -> 0.37325862 | AU33: =+AR33*AQ33 -> 0 | AV33: =+AS33*AQ33 -> -152.54885 | AW33: =+AT33*AQ33 -> -90.851149 | AX33: =+AL33+AU33 -> 0 | AY33: =+AM33+AV33 -> 5965.9511 | AZ33: =+AN33+AW33 -> 3553.0489 | BA33: =+Efficiency2!K119 -> 0 | BB33: =BB32+BA33 -> 536.81519 | BC33: =+R33/BA33 -> #DIV/0! | BD33: =+S33/BB33 -> 0.77060412
A34: =A33+1 -> 45926 | B34: STOP | C34: 12 | D34: =+'26'!F42 -> 0 | E34: =+'26'!G42 -> 0 | F34: =1-(E34/D34) -> #DIV/0! | G34: =+P34/N34 -> 0 | H34: =+P34/L34 -> 0 | I34: =+R34/P34 -> #DIV/0! | J34: =+R34/L34 -> 0 | K34: =+S34/M34 -> 0.3666666 | L34: =+Efficiency1!K124 -> 43.205944 | M34: =M33+L34 -> 1128.1966 | N34: =+Efficiency1!C124 -> 43.205944 | O34: =O33+N34 -> 2023.1668 | P34: ='26'!I38 -> 0 | Q34: =Q33+P34 -> 440.9126 | R34: ='26'!I40 -> 0 | S34: =S33+R34 -> 413.672 | T34: =+AX34 -> 0 | U34: =T34+U33 -> 41069.474 | V34: =T34/P34 -> #DIV/0! | W34: =U34/Q34 -> 93.14652 | X34: =IF(AND(R34>0,T34>0),(T34/(R34*1000))*1000,0) -> 0 | Y34: =IF(AND(S34>0,U34>0),U34/S34,0) -> 99.280285 | Z34: 4 | AA34: =Z34+AA33 -> 765.7 | AB34: =Z34/(P34) -> #DIV/0! | AC34: =AA34/(Q34) -> 1.7366254 | AD34: =IF(AND(R34>0,Z34>0),Z34/(R34),0) -> 0 | AE34: =IF(AND(S34>0,AA34>0),AA34/(S34),0) -> 1.8509834 | AF34: ='26'!I46 -> 5555.82 | AG34: =AF34+AG33 -> 500424.96 | AH34: =IF(AND(L34>0,AF34>0),(AF34/(P34*1000)*1000),0) -> #DIV/0! | AI34: =IF(AND(M34>0,AG34>0),(AG34/(Q34*1000)*1000),0) -> 1134.9754 | AJ34: =IF(AND(R34>0,AF34>0),(AF34/(R34*1000)*1000),0) -> 0 | AK34: =IF(AND(S34>0,AG34>0),(AG34/(S34*1000)*1000),0) -> 1209.7144 | AL34: 0 | AM34: 5867.5 | AN34: 4044.2 | AO34: =SUM(AL34:AN34) -> 9911.7 | AP34: =+[1]Sept!N29 -> 9800 | AQ34: =+AP34-AO34 -> -111.7 | AR34: =+AL34/AO34 -> 0 | AS34: =+AM34/AO34 -> 0.59197716 | AT34: =1-AR34-AS34 -> 0.40802284 | AU34: =+AR34*AQ34 -> 0 | AV34: =+AS34*AQ34 -> -66.123849 | AW34: =+AT34*AQ34 -> -45.576151 | AX34: =+AL34+AU34 -> 0 | AY34: =+AM34+AV34 -> 5801.3762 | AZ34: =+AN34+AW34 -> 3998.6238 | BA34: =+Efficiency2!K124 -> 0 | BB34: =BB33+BA34 -> 536.81519 | BC34: =+R34/BA34 -> #DIV/0! | BD34: =+S34/BB34 -> 0.77060412
A35: =A34+1 -> 45927 | B35: STOP | C35: 12 | D35: =+'27'!F42 -> 0 | E35: =+'27'!G42 -> 0 | F35: =1-(E35/D35) -> #DIV/0! | G35: =+P35/N35 -> 0 | H35: =+P35/L35 -> 0 | I35: =+R35/P35 -> #DIV/0! | J35: =+R35/L35 -> 0 | K35: =+S35/M35 -> 0.35314249 | L35: =+Efficiency1!K129 -> 43.205944 | M35: =M34+L35 -> 1171.4025 | N35: =+Efficiency1!C129 -> 43.205944 | O35: =O34+N35 -> 2066.3728 | P35: ='27'!I38 -> 0 | Q35: =Q34+P35 -> 440.9126 | R35: ='27'!I40 -> 0 | S35: =S34+R35 -> 413.672 | T35: =+AX35 -> 0 | U35: =T35+U34 -> 41069.474 | V35: =T35/P35 -> #DIV/0! | W35: =U35/Q35 -> 93.14652 | X35: =IF(AND(R35>0,T35>0),(T35/(R35*1000))*1000,0) -> 0 | Y35: =IF(AND(S35>0,U35>0),U35/S35,0) -> 99.280285 | Z35: 3.6 | AA35: =Z35+AA34 -> 769.3 | AB35: =Z35/(P35) -> #DIV/0! | AC35: =AA35/(Q35) -> 1.7447902 | AD35: =IF(AND(R35>0,Z35>0),Z35/(R35),0) -> 0 | AE35: =IF(AND(S35>0,AA35>0),AA35/(S35),0) -> 1.8596859 | AF35: ='27'!I46 -> 6030.3 | AG35: =AF35+AG34 -> 506455.26 | AH35: =IF(AND(L35>0,AF35>0),(AF35/(P35*1000)*1000),0) -> #DIV/0! | AI35: =IF(AND(M35>0,AG35>0),(AG35/(Q35*1000)*1000),0) -> 1148.6523 | AJ35: =IF(AND(R35>0,AF35>0),(AF35/(R35*1000)*1000),0) -> 0 | AK35: =IF(AND(S35>0,AG35>0),(AG35/(S35*1000)*1000),0) -> 1224.2919 | AL35: 0 | AM35: 5910.5 | AN35: 3593 | AO35: =SUM(AL35:AN35) -> 9503.5 | AP35: =+[1]Sept!N30 -> 9530 | AQ35: =+AP35-AO35 -> 26.5 | AR35: =+AL35/AO35 -> 0 | AS35: =+AM35/AO35 -> 0.62192876 | AT35: =1-AR35-AS35 -> 0.37807124 | AU35: =+AR35*AQ35 -> 0 | AV35: =+AS35*AQ35 -> 16.481112 | AW35: =+AT35*AQ35 -> 10.018888 | AX35: =+AL35+AU35 -> 0 | AY35: =+AM35+AV35 -> 5926.9811 | AZ35: =+AN35+AW35 -> 3603.0189 | BA35: =+Efficiency2!K129 -> 0 | BB35: =BB34+BA35 -> 536.81519 | BC35: =+R35/BA35 -> #DIV/0! | BD35: =+S35/BB35 -> 0.77060412
A36: =A35+1 -> 45928 | B36: STOP | C36: 12 | D36: =+'28'!F42 -> 0 | E36: =+'28'!G42 -> 0 | F36: =1-(E36/D36) -> #DIV/0! | G36: =+P36/N36 -> 0 | H36: =+P36/L36 -> 0 | I36: =+R36/P36 -> #DIV/0! | J36: =+R36/L36 -> 0 | K36: =+S36/M36 -> 0.34058054 | L36: =+Efficiency1!K134 -> 43.205944 | M36: =M35+L36 -> 1214.6084 | N36: =+Efficiency1!C134 -> 43.205944 | O36: =O35+N36 -> 2109.5787 | P36: ='28'!I38 -> 0 | Q36: =Q35+P36 -> 440.9126 | R36: ='28'!I40 -> 0 | S36: =S35+R36 -> 413.672 | T36: =+AX36 -> 0 | U36: =T36+U35 -> 41069.474 | V36: =T36/P36 -> #DIV/0! | W36: =U36/Q36 -> 93.14652 | X36: =IF(AND(R36>0,T36>0),(T36/(R36*1000))*1000,0) -> 0 | Y36: =IF(AND(S36>0,U36>0),U36/S36,0) -> 99.280285 | Z36: 4.4 | AA36: =Z36+AA35 -> 773.7 | AB36: =Z36/(P36) -> #DIV/0! | AC36: =AA36/(Q36) -> 1.7547695 | AD36: =IF(AND(R36>0,Z36>0),Z36/(R36),0) -> 0 | AE36: =IF(AND(S36>0,AA36>0),AA36/(S36),0) -> 1.8703224 | AF36: ='28'!I46 -> 9007.4 | AG36: =AF36+AG35 -> 515462.66 | AH36: =IF(AND(L36>0,AF36>0),(AF36/(P36*1000)*1000),0) -> #DIV/0! | AI36: =IF(AND(M36>0,AG36>0),(AG36/(Q36*1000)*1000),0) -> 1169.0813 | AJ36: =IF(AND(R36>0,AF36>0),(AF36/(R36*1000)*1000),0) -> 0 | AK36: =IF(AND(S36>0,AG36>0),(AG36/(S36*1000)*1000),0) -> 1246.0661 | AL36: 0 | AM36: 6117.6 | AN36: 3584.6 | AO36: =SUM(AL36:AN36) -> 9702.2 | AP36: =+[1]Sept!N31 -> 9290 | AQ36: =+AP36-AO36 -> -412.2 | AR36: =+AL36/AO36 -> 0 | AS36: =+AM36/AO36 -> 0.6305374 | AT36: =1-AR36-AS36 -> 0.3694626 | AU36: =+AR36*AQ36 -> 0 | AV36: =+AS36*AQ36 -> -259.90752 | AW36: =+AT36*AQ36 -> -152.29248 | AX36: =+AL36+AU36 -> 0 | AY36: =+AM36+AV36 -> 5857.6925 | AZ36: =+AN36+AW36 -> 3432.3075 | BA36: =+Efficiency2!K134 -> 0 | BB36: =BB35+BA36 -> 536.81519 | BC36: =+R36/BA36 -> #DIV/0! | BD36: =+S36/BB36 -> 0.77060412
A37: =A36+1 -> 45929 | B37: STOP | C37: 12 | D37: =+'29'!F42 -> 0 | E37: =+'29'!G42 -> 0 | F37: =1-(E37/D37) -> #DIV/0! | G37: =+P37/N37 -> 0 | H37: =+P37/L37 -> 0 | I37: =+R37/P37 -> #DIV/0! | J37: =+R37/L37 -> 0 | K37: =+S37/M37 -> 0.32888159 | L37: =+Efficiency1!K139 -> 43.205944 | M37: =M36+L37 -> 1257.8144 | N37: =+Efficiency1!C139 -> 43.205944 | O37: =O36+N37 -> 2152.7846 | P37: ='29'!I38 -> 0 | Q37: =Q36+P37 -> 440.9126 | R37: ='29'!I40 -> 0 | S37: =S36+R37 -> 413.672 | T37: =+AX37 -> 0 | U37: =T37+U36 -> 41069.474 | V37: =T37/P37 -> #DIV/0! | W37: =U37/Q37 -> 93.14652 | X37: =IF(AND(R37>0,T37>0),(T37/(R37*1000))*1000,0) -> 0 | Y37: =IF(AND(S37>0,U37>0),U37/S37,0) -> 99.280285 | Z37: 5.1 | AA37: =Z37+AA36 -> 778.8 | AB37: =Z37/(P37) -> #DIV/0! | AC37: =AA37/(Q37) -> 1.7663365 | AD37: =IF(AND(R37>0,Z37>0),Z37/(R37),0) -> 0 | AE37: =IF(AND(S37>0,AA37>0),AA37/(S37),0) -> 1.882651 | AF37: ='29'!I46 -> 4763.04 | AG37: =AF37+AG36 -> 520225.7 | AH37: =IF(AND(L37>0,AF37>0),(AF37/(P37*1000)*1000),0) -> #DIV/0! | AI37: =IF(AND(M37>0,AG37>0),(AG37/(Q37*1000)*1000),0) -> 1179.8839 | AJ37: =IF(AND(R37>0,AF37>0),(AF37/(R37*1000)*1000),0) -> 0 | AK37: =IF(AND(S37>0,AG37>0),(AG37/(S37*1000)*1000),0) -> 1257.5802 | AL37: 0 | AM37: 5779.9 | AN37: 3840.3 | AO37: =SUM(AL37:AN37) -> 9620.2 | AP37: =+[1]Sept!N32 -> 9399 | AQ37: =+AP37-AO37 -> -221.2 | AR37: =+AL37/AO37 -> 0 | AS37: =+AM37/AO37 -> 0.60080871 | AT37: =1-AR37-AS37 -> 0.39919129 | AU37: =+AR37*AQ37 -> 0 | AV37: =+AS37*AQ37 -> -132.89889 | AW37: =+AT37*AQ37 -> -88.301112 | AX37: =+AL37+AU37 -> 0 | AY37: =+AM37+AV37 -> 5647.0011 | AZ37: =+AN37+AW37 -> 3751.9989 | BA37: =+Efficiency2!K139 -> 0 | BB37: =BB36+BA37 -> 536.81519 | BC37: =+R37/BA37 -> #DIV/0! | BD37: =+S37/BB37 -> 0.77060412
A38: =A37+1 -> 45930 | B38: STOP | C38: 12 | D38: =+'30'!F42 -> 0 | E38: =+'30'!G42 -> 0 | F38: =1-(E38/D38) -> #DIV/0! | G38: =+P38/N38 -> 0 | H38: =+P38/L38 -> 0 | I38: =+R38/P38 -> #DIV/0! | J38: =+R38/L38 -> 0 | K38: =+S38/M38 -> 0.31795967 | L38: =+Efficiency1!K144 -> 43.205944 | M38: =M37+L38 -> 1301.0203 | N38: =+Efficiency1!C144 -> 43.205944 | O38: =O37+N38 -> 2195.9906 | P38: ='30'!I38 -> 0 | Q38: =Q37+P38 -> 440.9126 | R38: ='30'!I40 -> 0 | S38: =S37+R38 -> 413.672 | T38: =+AX38 -> 0 | U38: =T38+U37 -> 41069.474 | V38: =T38/P38 -> #DIV/0! | W38: =U38/Q38 -> 93.14652 | X38: =IF(AND(R38>0,T38>0),(T38/(R38*1000))*1000,0) -> 0 | Y38: =IF(AND(S38>0,U38>0),U38/S38,0) -> 99.280285 | Z38: 5 | AA38: =Z38+AA37 -> 783.8 | AB38: =Z38/(P38) -> #DIV/0! | AC38: =AA38/(Q38) -> 1.7776766 | AD38: =IF(AND(R38>0,Z38>0),Z38/(R38),0) -> 0 | AE38: =IF(AND(S38>0,AA38>0),AA38/(S38),0) -> 1.8947379 | AF38: ='30'!I46 -> 6338.66 | AG38: =AF38+AG37 -> 526564.36 | AH38: =IF(AND(L38>0,AF38>0),(AF38/(P38*1000)*1000),0) -> #DIV/0! | AI38: =IF(AND(M38>0,AG38>0),(AG38/(Q38*1000)*1000),0) -> 1194.2602 | AJ38: =IF(AND(R38>0,AF38>0),(AF38/(R38*1000)*1000),0) -> 0 | AK38: =IF(AND(S38>0,AG38>0),(AG38/(S38*1000)*1000),0) -> 1272.9031 | AL38: 0 | AM38: 5693.7 | AN38: 3441.7 | AO38: =SUM(AL38:AN38) -> 9135.4 | AP38: =+[1]Sept!N33 -> 8671 | AQ38: =+AP38-AO38 -> -464.4 | AR38: =+AL38/AO38 -> 0 | AS38: =+AM38/AO38 -> 0.62325678 | AT38: =1-AR38-AS38 -> 0.37674322 | AU38: =+AR38*AQ38 -> 0 | AV38: =+AS38*AQ38 -> -289.44045 | AW38: =+AT38*AQ38 -> -174.95955 | AX38: =+AL38+AU38 -> 0 | AY38: =+AM38+AV38 -> 5404.2596 | AZ38: =+AN38+AW38 -> 3266.7404 | BB38: =BB37+BA38 -> 536.81519 | BC38: =+R38/BA38 -> #DIV/0! | BD38: =+S38/BB38 -> 0.77060412
G41: =+P41/N41 -> 0.20078073 | H41: =+P41/L41 -> 0.33889755 | I41: =+R41/P41 -> 0.93821769 | J41: =+R41/L41 -> 0.31795967 | L41: =SUM(L9:L39) -> 1301.0203 | N41: =SUM(N9:N39) -> 2195.9906 | P41: =SUM(P9:P39) -> 440.9126 | R41: =SUM(R9:R39) -> 413.672 | T41: =SUM(T9:T39) -> 41069.474 | V41: =T41/P41 -> 93.14652 | X41: =IF(AND(R41>0,T41>0),(T41/(R41*1000))*1000,0) -> 99.280285 | Z41: =SUM(Z9:Z40) -> 783.8 | AB41: =Z41/P41 -> 1.7776766 | AD41: =Z41/R41 -> 1.8947379 | AF41: =SUM(AF9:AF39) -> 526564.36 | AH41: =AF41/P41 -> 1194.2602 | AJ41: =AF41/R41 -> 1272.9031 | AP41: =SUM(AP9:AP40) -> 311908 | AX41: =SUM(AX9:AX39) -> 41069.474 | AY41: =SUM(AY9:AY39) -> 164114.08 | AZ41: =SUM(AZ9:AZ39) -> 106724.45 | BA41: =SUM(BA9:BA39) -> 536.81519 | BC41: =+R41/BA41 -> 0.77060412
AY43: =SUM(AX41:AZ41) -> 311908

Sheet GRAFIK

Sheet Listrik
A2: MACHINE POWER CONSUMPTION (PER PANEL)
A4: Date | B4: PM (TON) | C4: FINSHED GOODS (TON) | P4: Total PM14
D5: Trafo (2500 A) | H5: Trafo (2500 B) | L5: Trafo (2500 A)
D6: KWH | E6: Consumption | F6: /TON PM | G6: /TON FG | H6: KWH | I6: Consumption | J6: /TON PM | K6: /TON FG | L6: KWH | M6: Consumption | N6: /TON PM | O6: /TON FG | P6: Consumption | Q6: /TON PM | R6: /TON FG
A7: =A8-1 -> 45900 | B7: 0 | C7: 0
A8: =+Report1!A9 -> 45901 | B8: =+Report1!P9 -> 40.056 | C8: =+Report1!R9 -> 41.482 | D8: =+D7+E8 -> 4400 | E8: =+[3]DailySep!AH7 -> 4400 | F8: =E8/B8 -> 109.84622 | G8: =E8/C8 -> 106.0701 | H8: =+H7+I8 -> 7908.5 | I8: =+[3]DailySep!AI7 -> 7908.5 | J8: =I8/B8 -> 197.43609 | K8: =I8/C8 -> 190.64896 | L8: =+L7+M8 -> 23068.5 | M8: =+[3]DailySep!AJ7 -> 23068.5 | N8: =M8/B8 -> 575.90623 | O8: =M8/C8 -> 556.10867 | P8: =+E8+I8+M8 -> 35377 | Q8: =P8/B8 -> 883.18854 | R8: =P8/C8 -> 852.82773 | V8: Off Reel | W8: Off Rewinder
A9: =+Report1!A10 -> 45902 | B9: =+Report1!P10 -> 38.489 | C9: =+Report1!R10 -> 31.631 | D9: =+D8+E9 -> 8600 | E9: =+[3]DailySep!AH8 -> 4200 | F9: =E9/B9 -> 109.12209 | G9: =E9/C9 -> 132.78113 | H9: =+H8+I9 -> 15934.65 | I9: =+[3]DailySep!AI8 -> 8026.15 | J9: =I9/B9 -> 208.53101 | K9: =I9/C9 -> 253.74316 | L9: =+L8+M9 -> 46254.65 | M9: =+[3]DailySep!AJ8 -> 23186.15 | N9: =M9/B9 -> 602.40978 | O9: =M9/C9 -> 733.01982 | P9: =+E9+I9+M9 -> 35412.3 | Q9: =P9/B9 -> 920.06288 | R9: =P9/C9 -> 1119.5441 | V9: Off Reel | W9: Off Rewinder
A10: =+Report1!A11 -> 45903 | B10: =+Report1!P11 -> 38.158 | C10: =+Report1!R11 -> 31.743 | D10: =+D9+E10 -> 13000 | E10: =+[3]DailySep!AH9 -> 4400 | F10: =E10/B10 -> 115.31003 | G10: =E10/C10 -> 138.61324 | H10: =+H9+I10 -> 22464.7 | I10: =+[3]DailySep!AI9 -> 6530.05 | J10: =I10/B10 -> 171.13187 | K10: =I10/C10 -> 205.71622 | L10: =+L9+M10 -> 68944.7 | M10: =+[3]DailySep!AJ9 -> 22690.05 | N10: =M10/B10 -> 594.63415 | O10: =M10/C10 -> 714.80484 | P10: =+E10+I10+M10 -> 33620.1 | Q10: =P10/B10 -> 881.07605 | R10: =P10/C10 -> 1059.1343 | V10: Off Reel | W10: Off Rewinder
A11: =+Report1!A12 -> 45904 | B11: =+Report1!P12 -> 41.57 | C11: =+Report1!R12 -> 40.656 | D11: =+D10+E11 -> 17300 | E11: =+[3]DailySep!AH10 -> 4300 | F11: =E11/B11 -> 103.43998 | G11: =E11/C11 -> 105.76545 | H11: =+H10+I11 -> 31979.66 | I11: =+[3]DailySep!AI10 -> 9514.96 | J11: =I11/B11 -> 228.89006 | K11: =I11/C11 -> 234.03581 | L11: =+L10+M11 -> 92619.66 | M11: =+[3]DailySep!AJ10 -> 23674.96 | N11: =M11/B11 -> 569.52033 | O11: =M11/C11 -> 582.32389 | P11: =+E11+I11+M11 -> 37489.92 | Q11: =P11/B11 -> 901.85037 | R11: =P11/C11 -> 922.12515 | V11: Off Reel | W11: Off Rewinder
A12: =+Report1!A13 -> 45905 | B12: =+Report1!P13 -> 42.805 | C12: =+Report1!R13 -> 41.62 | D12: =+D11+E12 -> 21700 | E12: =+[3]DailySep!AH11 -> 4400 | F12: =E12/B12 -> 102.79173 | G12: =E12/C12 -> 105.7184 | H12: =+H11+I12 -> 39749.39 | I12: =+[3]DailySep!AI11 -> 7769.73 | J12: =I12/B12 -> 181.51454 | K12: =I12/C12 -> 186.6826 | L12: =+L11+M12 -> 114549.39 | M12: =+[3]DailySep!AJ11 -> 21929.73 | N12: =M12/B12 -> 512.31702 | O12: =M12/C12 -> 526.90365 | P12: =+E12+I12+M12 -> 34099.46 | Q12: =P12/B12 -> 796.62329 | R12: =P12/C12 -> 819.30466 | V12: Off Reel | W12: Off Rewinder
