Workbook

Sheet Report1
A3: PAPER MACHINE 14 DAILY REPORT 1
A6: Date | B6: Grade | C6: GSM | D6: Speed yankee (mpm) | E6: Speed reel (mpm) | F6: Creep ( % ) | G6: Real Eff PM ( % ) | H6: Real Eff PM vs Target (%) | I6: Real Eff FG vs Real Eff PM (%) | J6: Eff FG vs Target (%) | L6: Kapasitas Target (ton) | N6: Kapasitas Teori Real (ton) | P6: PM PROD Timbangan (TON) | R6: FINSHED GOODS (TON) | T6: GAS HOOD | Z6: STEAM (TON) | AF6: POWER (kWh) | BA6: Kapasitas Running (ton) | BC6: Eff FG vs Target Running(%)
T7: CONSUMPTION | V7: /TON PM. | X7: /TON FG. | Z7: CONSUMPTION | AB7: /TON PM. | AD7: /TON FG. | AF7: CONSUMPTION | AH7: /TON PM | AJ7: /TON FG | AL7: Gas based on report DCS | AO7: total | AP7: Flowmeter | AQ7: Selisih | AR7: % pengali | AU7: Adjust | AX7: PEMAKAIAN GAS
J8: TODAY | K8: TODATE | L8: TODAY | M8: TODATE | N8: TODAY | O8: TODATE | P8: TODAY | Q8: TODATE | R8: TODAY | S8: TODATE | T8: TODAY | U8: TODATE | V8: TODAY | W8: TODATE | X8: TODAY | Y8: TODATE | Z8: TODAY | AA8: TODATE | AB8: TODAY | AC8: TODATE | AD8: TODAY | AE8: TODATE | AF8: TODAY | AG8: TODATE | AH8: TODAY | AI8: TODATE | AJ8: TODAY | AK8: TODATE | AL8: 14 | AM8: 15 | AN8: 17 | AP8: PGN | AU8: 14 | AV8: 15 | AW8: 17 | AX8: 14 | AY8: 15 | AZ8: 17 | BA8: TODAY | BB8: TODATE | BC8: TODAY | BD8: TODATE
A9: 45962 | B9: STOP | C9: 12 | D9: =+'1'!F42 -> 0 | E9: =+'1'!G42 -> 0 | F9: =1-(E9/D9) -> #DIV/0! | G9: =+P9/N9 -> 0 | H9: =+P9/L9 -> 0 | I9: =+R9/P9 -> #DIV/0! | J9: =+R9/L9 -> 0 | K9: =+S9/M9 -> 0 | L9: =+Efficiency1!K6 -> 43.297309 | M9: =L9 -> 43.297309 | N9: =+Efficiency1!C6 -> 43.297309 | O9: =N9 -> 43.297309 | P9: ='1'!I38 -> 0 | Q9: =P9 -> 0 | R9: ='1'!I40 -> 0 | S9: =R9 -> 0 | T9: =+AX9 -> 0 | U9: =T9 -> 0 | V9: =T9/P9 -> #DIV/0! | W9: =U9/Q9 -> #DIV/0! | X9: =IF(AND(R9>0,T9>0),(T9/(R9*1000))*1000,0) -> 0 | Y9: =IF(AND(S9>0,U9>0),U9/S9,0) -> 0 | Z9: 25.3 | AA9: =Z9 -> 25.3 | AB9: =Z9/(P9) -> #DIV/0! | AC9: =AA9/(Q9) -> #DIV/0! | AD9: =IF(AND(R9>0,Z9>0),Z9/(R9),0) -> 0 | AE9: =IF(AND(S9>0,AA9>0),AA9/(S9),0) -> 0 | AF9: ='1'!I46 -> 1921.3 | AG9: =AF9 -> 1921.3 | AH9: =IF(AND(L9>0,AF9>0),(AF9/(P9*1000)*1000),0) -> #DIV/0! | AI9: =IF(AND(M9>0,AG9>0),(AG9/(Q9*1000)*1000),0) -> #DIV/0! | AJ9: =IF(AND(R9>0,AF9>0),(AF9/(R9*1000)*1000),0) -> 0 | AK9: =IF(AND(S9>0,AG9>0),(AG9/(S9*1000)*1000),0) -> 0 | AL9: 0 | AM9: 5237.3 | AN9: 3557.2 | AO9: =SUM(AL9:AN9) -> 8794.5 | AP9: =+[1]Nov!N4 -> 8117 | AQ9: =+AP9-AO9 -> -677.5 | AR9: =+AL9/AO9 -> 0 | AS9: =+AM9/AO9 -> 0.59551993 | AT9: =1-AR9-AS9 -> 0.40448007 | AU9: =+AR9*AQ9 -> 0 | AV9: =+AS9*AQ9 -> -403.46475 | AW9: =+AT9*AQ9 -> -274.03525 | AX9: =+AL9+AU9 -> 0 | AY9: =+AM9+AV9 -> 4833.8352 | AZ9: =+AN9+AW9 -> 3283.1648 | BA9: =+Efficiency2!K6 -> 0 | BB9: =BA9 -> 0 | BC9: =+R9/BA9 -> #DIV/0! | BD9: =+S9/BB9 -> #DIV/0!
A10: =A9+1 -> 45963 | B10: STOP | C10: 12 | D10: =+'2'!F42 -> 0 | E10: =+'2'!G42 -> 0 | F10: =1-(E10/D10) -> #DIV/0! | G10: =+P10/N10 -> 0 | H10: =+P10/L10 -> 0 | I10: =+R10/P10 -> #DIV/0! | J10: =+R10/L10 -> 0 | K10: =+S10/M10 -> 0 | L10: =+Efficiency1!K12 -> 43.297309 | M10: =M9+L10 -> 86.594619 | N10: =+Efficiency1!C12 -> 43.297309 | O10: =O9+N10 -> 86.594619 | P10: ='2'!I38 -> 0 | Q10: =Q9+P10 -> 0 | R10: ='2'!I40 -> 0 | S10: =S9+R10 -> 0 | T10: =+AX10 -> 0 | U10: =T10+U9 -> 0 | V10: =T10/P10 -> #DIV/0! | W10: =U10/Q10 -> #DIV/0! | X10: =IF(AND(R10>0,T10>0),(T10/(R10*1000))*1000,0) -> 0 | Y10: =IF(AND(S10>0,U10>0),U10/S10,0) -> 0 | Z10: 23.5 | AA10: =Z10+AA9 -> 48.8 | AB10: =Z10/(P10) -> #DIV/0! | AC10: =AA10/(Q10) -> #DIV/0! | AD10: =IF(AND(R10>0,Z10>0),Z10/(R10),0) -> 0 | AE10: =IF(AND(S10>0,AA10>0),AA10/(S10),0) -> 0 | AF10: ='2'!I46 -> 7319.78 | AG10: =AF10+AG9 -> 9241.08 | AH10: =IF(AND(L10>0,AF10>0),(AF10/(P10*1000)*1000),0) -> #DIV/0! | AI10: =IF(AND(M10>0,AG10>0),(AG10/(Q10*1000)*1000),0) -> #DIV/0! | AJ10: =IF(AND(R10>0,AF10>0),(AF10/(R10*1000)*1000),0) -> 0 | AK10: =IF(AND(S10>0,AG10>0),(AG10/(S10*1000)*1000),0) -> 0 | AL10: 0 | AM10: 5640.2 | AN10: 2864 | AO10: =SUM(AL10:AN10) -> 8504.2 | AP10: =+[1]Nov!N5 -> 8682 | AQ10: =+AP10-AO10 -> 177.8 | AR10: =+AL10/AO10 -> 0 | AS10: =+AM10/AO10 -> 0.66322523 | AT10: =1-AR10-AS10 -> 0.33677477 | AU10: =+AR10*AQ10 -> 0 | AV10: =+AS10*AQ10 -> 117.92145 | AW10: =+AT10*AQ10 -> 59.878554 | AX10: =+AL10+AU10 -> 0 | AY10: =+AM10+AV10 -> 5758.1214 | AZ10: =+AN10+AW10 -> 2923.8786 | BA10: =+Efficiency2!K12 -> 0 | BB10: =BB9+BA10 -> 0 | BC10: =+R10/BA10 -> #DIV/0! | BD10: =+S10/BB10 -> #DIV/0!
A11: =A10+1 -> 45964 | B11: STOP | C11: 12 | D11: =+'3'!F42 -> 0 | E11: =+'3'!G42 -> 0 | F11: =1-(E11/D11) -> #DIV/0! | G11: =+P11/N11 -> 0 | H11: =+P11/L11 -> 0 | I11: =+R11/P11 -> #DIV/0! | J11: =+R11/L11 -> 0 | K11: =+S11/M11 -> 0 | L11: =+Efficiency1!K18 -> 43.297309 | M11: =M10+L11 -> 129.89193 | N11: =+Efficiency1!C18 -> 43.297309 | O11: =O10+N11 -> 129.89193 | P11: ='3'!I38 -> 0 | Q11: =Q10+P11 -> 0 | R11: ='3'!I40 -> 0 | S11: =S10+R11 -> 0 | T11: =+AX11 -> 0 | U11: =T11+U10 -> 0 | V11: =T11/P11 -> #DIV/0! | W11: =U11/Q11 -> #DIV/0! | X11: =IF(AND(R11>0,T11>0),(T11/(R11*1000))*1000,0) -> 0 | Y11: =IF(AND(S11>0,U11>0),U11/S11,0) -> 0 | Z11: 23.4 | AA11: =Z11+AA10 -> 72.2 | AB11: =Z11/(P11) -> #DIV/0! | AC11: =AA11/(Q11) -> #DIV/0! | AD11: =IF(AND(R11>0,Z11>0),Z11/(R11),0) -> 0 | AE11: =IF(AND(S11>0,AA11>0),AA11/(S11),0) -> 0 | AF11: ='3'!I46 -> 3507.08 | AG11: =AF11+AG10 -> 12748.16 | AH11: =IF(AND(L11>0,AF11>0),(AF11/(P11*1000)*1000),0) -> #DIV/0! | AI11: =IF(AND(M11>0,AG11>0),(AG11/(Q11*1000)*1000),0) -> #DIV/0! | AJ11: =IF(AND(R11>0,AF11>0),(AF11/(R11*1000)*1000),0) -> 0 | AK11: =IF(AND(S11>0,AG11>0),(AG11/(S11*1000)*1000),0) -> 0 | AL11: 0 | AM11: 5900.8 | AN11: 3564.8 | AO11: =SUM(AL11:AN11) -> 9465.6 | AP11: =+[1]Nov!N6 -> 9107 | AQ11: =+AP11-AO11 -> -358.6 | AR11: =+AL11/AO11 -> 0 | AS11: =+AM11/AO11 -> 0.62339419 | AT11: =1-AR11-AS11 -> 0.37660581 | AU11: =+AR11*AQ11 -> 0 | AV11: =+AS11*AQ11 -> -223.54915 | AW11: =+AT11*AQ11 -> -135.05085 | AX11: =+AL11+AU11 -> 0 | AY11: =+AM11+AV11 -> 5677.2508 | AZ11: =+AN11+AW11 -> 3429.7492 | BA11: =+Efficiency2!K18 -> 0 | BB11: =BB10+BA11 -> 0 | BC11: =+R11/BA11 -> #DIV/0! | BD11: =+S11/BB11 -> #DIV/0!
A12: =A11+1 -> 45965 | B12: STOP | C12: 12 | D12: =+'4'!F42 -> 0 | E12: =+'4'!G42 -> 0 | F12: =1-(E12/D12) -> #DIV/0! | G12: =+P12/N12 -> 0 | H12: =+P12/L12 -> 0 | I12: =+R12/P12 -> #DIV/0! | J12: =+R12/L12 -> 0 | K12: =+S12/M12 -> 0 | L12: =+Efficiency1!K24 -> 43.297309 | M12: =M11+L12 -> 173.18924 | N12: =+Efficiency1!C24 -> 43.297309 | O12: =O11+N12 -> 173.18924 | P12: ='4'!I38 -> 0 | Q12: =Q11+P12 -> 0 | R12: ='4'!I40 -> 0 | S12: =S11+R12 -> 0 | T12: =+AX12 -> 0 | U12: =T12+U11 -> 0 | V12: =T12/P12 -> #DIV/0! | W12: =U12/Q12 -> #DIV/0! | X12: =IF(AND(R12>0,T12>0),(T12/(R12*1000))*1000,0) -> 0 | Y12: =IF(AND(S12>0,U12>0),U12/S12,0) -> 0 | Z12: 7.1 | AA12: =Z12+AA11 -> 79.3 | AB12: =Z12/(P12) -> #DIV/0! | AC12: =AA12/(Q12) -> #DIV/0! | AD12: =IF(AND(R12>0,Z12>0),Z12/(R12),0) -> 0 | AE12: =IF(AND(S12>0,AA12>0),AA12/(S12),0) -> 0 | AF12: ='4'!I46 -> 3341.74 | AG12: =AF12+AG11 -> 16089.9 | AH12: =IF(AND(L12>0,AF12>0),(AF12/(P12*1000)*1000),0) -> #DIV/0! | AI12: =IF(AND(M12>0,AG12>0),(AG12/(Q12*1000)*1000),0) -> #DIV/0! | AJ12: =IF(AND(R12>0,AF12>0),(AF12/(R12*1000)*1000),0) -> 0 | AK12: =IF(AND(S12>0,AG12>0),(AG12/(S12*1000)*1000),0) -> 0 | AL12: 0 | AM12: 6022 | AN12: 4234.2 | AO12: =SUM(AL12:AN12) -> 10256.2 | AP12: =+[1]Nov!N7 -> 9873 | AQ12: =+AP12-AO12 -> -383.2 | AR12: =+AL12/AO12 -> 0 | AS12: =+AM12/AO12 -> 0.58715704 | AT12: =1-AR12-AS12 -> 0.41284296 | AU12: =+AR12*AQ12 -> 0 | AV12: =+AS12*AQ12 -> -224.99858 | AW12: =+AT12*AQ12 -> -158.20142 | AX12: =+AL12+AU12 -> 0 | AY12: =+AM12+AV12 -> 5797.0014 | AZ12: =+AN12+AW12 -> 4075.9986 | BA12: =+Efficiency2!K24 -> 0 | BB12: =BB11+BA12 -> 0 | BC12: =+R12/BA12 -> #DIV/0! | BD12: =+S12/BB12 -> #DIV/0!
A13: =A12+1 -> 45966 | B13: STOP | C13: 12 | D13: =+'5'!F42 -> 0 | E13: =+'5'!G42 -> 0 | F13: =1-(E13/D13) -> #DIV/0! | G13: =+P13/N13 -> 0 | H13: =+P13/L13 -> 0 | I13: =+R13/P13 -> #DIV/0! | J13: =+R13/L13 -> 0 | K13: =+S13/M13 -> 0 | L13: =+Efficiency1!K30 -> 43.297309 | M13: =M12+L13 -> 216.48655 | N13: =+Efficiency1!C30 -> 43.297309 | O13: =O12+N13 -> 216.48655 | P13: ='5'!I38 -> 0 | Q13: =Q12+P13 -> 0 | R13: ='5'!I40 -> 0 | S13: =S12+R13 -> 0 | T13: =+AX13 -> 0 | U13: =T13+U12 -> 0 | V13: =T13/P13 -> #DIV/0! | W13: =U13/Q13 -> #DIV/0! | X13: =IF(AND(R13>0,T13>0),(T13/(R13*1000))*1000,0) -> 0 | Y13: =IF(AND(S13>0,U13>0),U13/S13,0) -> 0 | Z13: 3.3 | AA13: =Z13+AA12 -> 82.6 | AB13: =Z13/(P13) -> #DIV/0! | AC13: =AA13/(Q13) -> #DIV/0! | AD13: =IF(AND(R13>0,Z13>0),Z13/(R13),0) -> 0 | AE13: =IF(AND(S13>0,AA13>0),AA13/(S13),0) -> 0 | AF13: ='5'!I46 -> 4724.56 | AG13: =AF13+AG12 -> 20814.46 | AH13: =IF(AND(L13>0,AF13>0),(AF13/(P13*1000)*1000),0) -> #DIV/0! | AI13: =IF(AND(M13>0,AG13>0),(AG13/(Q13*1000)*1000),0) -> #DIV/0! | AJ13: =IF(AND(R13>0,AF13>0),(AF13/(R13*1000)*1000),0) -> 0 | AK13: =IF(AND(S13>0,AG13>0),(AG13/(S13*1000)*1000),0) -> 0 | AL13: 0 | AM13: 3378.3 | AN13: 3703.2 | AO13: =SUM(AL13:AN13) -> 7081.5 | AP13: =+[1]Nov!N8 -> 6884 | AQ13: =+AP13-AO13 -> -197.5 | AR13: =+AL13/AO13 -> 0 | AS13: =+AM13/AO13 -> 0.47705994 | AT13: =1-AR13-AS13 -> 0.52294006 | AU13: =+AR13*AQ13 -> 0 | AV13: =+AS13*AQ13 -> -94.219339 | AW13: =+AT13*AQ13 -> -103.28066 | AX13: =+AL13+AU13 -> 0 | AY13: =+AM13+AV13 -> 3284.0807 | AZ13: =+AN13+AW13 -> 3599.9193 | BA13: =+Efficiency2!K30 -> 0 | BB13: =BB12+BA13 -> 0 | BC13: =+R13/BA13 -> #DIV/0! | BD13: =+S13/BB13 -> #DIV/0!
A14: =A13+1 -> 45967 | B14: STOP | C14: 12 | D14: =+'6'!F42 -> 0 | E14: =+'6'!G42 -> 0 | F14: =1-(E14/D14) -> #DIV/0! | G14: =+P14/N14 -> 0 | H14: =+P14/L14 -> 0 | I14: =+R14/P14 -> #DIV/0! | J14: =+R14/L14 -> 0 | K14: =+S14/M14 -> 0 | L14: =+Efficiency1!K36 -> 43.297309 | M14: =M13+L14 -> 259.78386 | N14: =+Efficiency1!C36 -> 43.297309 | O14: =O13+N14 -> 259.78386 | P14: ='6'!I38 -> 0 | Q14: =Q13+P14 -> 0 | R14: ='6'!I40 -> 0 | S14: =S13+R14 -> 0 | T14: =+AX14 -> 0 | U14: =T14+U13 -> 0 | V14: =T14/P14 -> #DIV/0! | W14: =U14/Q14 -> #DIV/0! | X14: =IF(AND(R14>0,T14>0),(T14/(R14*1000))*1000,0) -> 0 | Y14: =IF(AND(S14>0,U14>0),U14/S14,0) -> 0 | Z14: 4.3 | AA14: =Z14+AA13 -> 86.9 | AB14: =Z14/(P14) -> #DIV/0! | AC14: =AA14/(Q14) -> #DIV/0! | AD14: =IF(AND(R14>0,Z14>0),Z14/(R14),0) -> 0 | AE14: =IF(AND(S14>0,AA14>0),AA14/(S14),0) -> 0 | AF14: ='6'!I46 -> 7849.78 | AG14: =AF14+AG13 -> 28664.24 | AH14: =IF(AND(L14>0,AF14>0),(AF14/(P14*1000)*1000),0) -> #DIV/0! | AI14: =IF(AND(M14>0,AG14>0),(AG14/(Q14*1000)*1000),0) -> #DIV/0! | AJ14: =IF(AND(R14>0,AF14>0),(AF14/(R14*1000)*1000),0) -> 0 | AK14: =IF(AND(S14>0,AG14>0),(AG14/(S14*1000)*1000),0) -> 0 | AL14: 0 | AM14: 5688 | AN14: 4121.8 | AO14: =SUM(AL14:AN14) -> 9809.8 | AP14: =+[1]Nov!N9 -> 9530 | AQ14: =+AP14-AO14 -> -279.8 | AR14: =+AL14/AO14 -> 0 | AS14: =+AM14/AO14 -> 0.57982833 | AT14: =1-AR14-AS14 -> 0.42017167 | AU14: =+AR14*AQ14 -> 0 | AV14: =+AS14*AQ14 -> -162.23597 | AW14: =+AT14*AQ14 -> -117.56403 | AX14: =+AL14+AU14 -> 0 | AY14: =+AM14+AV14 -> 5525.764 | AZ14: =+AN14+AW14 -> 4004.236 | BA14: =+Efficiency2!K36 -> 0 | BB14: =BB13+BA14 -> 0 | BC14: =+R14/BA14 -> #DIV/0! | BD14: =+S14/BB14 -> #DIV/0!
A15: =A14+1 -> 45968 | B15: STOP | C15: 12 | D15: =+'7'!F42 -> 0 | E15: =+'7'!G42 -> 0 | F15: =1-(E15/D15) -> #DIV/0! | G15: =+P15/N15 -> 0 | H15: =+P15/L15 -> 0 | I15: =+R15/P15 -> #DIV/0! | J15: =+R15/L15 -> 0 | K15: =+S15/M15 -> 0 | L15: =+Efficiency1!K42 -> 43.297309 | M15: =M14+L15 -> 303.08117 | N15: =+Efficiency1!C42 -> 43.297309 | O15: =O14+N15 -> 303.08117 | P15: ='7'!I38 -> 0 | Q15: =Q14+P15 -> 0 | R15: ='7'!I40 -> 0 | S15: =S14+R15 -> 0 | T15: =+AX15 -> 0 | U15: =T15+U14 -> 0 | V15: =T15/P15 -> #DIV/0! | W15: =U15/Q15 -> #DIV/0! | X15: =IF(AND(R15>0,T15>0),(T15/(R15*1000))*1000,0) -> 0 | Y15: =IF(AND(S15>0,U15>0),U15/S15,0) -> 0 | Z15: 27.7 | AA15: =Z15+AA14 -> 114.6 | AB15: =Z15/(P15) -> #DIV/0! | AC15: =AA15/(Q15) -> #DIV/0! | AD15: =IF(AND(R15>0,Z15>0),Z15/(R15),0) -> 0 | AE15: =IF(AND(S15>0,AA15>0),AA15/(S15),0) -> 0 | AF15: ='7'!I46 -> 3326.1 | AG15: =AF15+AG14 -> 31990.34 | AH15: =IF(AND(L15>0,AF15>0),(AF15/(P15*1000)*1000),0) -> #DIV/0! | AI15: =IF(AND(M15>0,AG15>0),(AG15/(Q15*1000)*1000),0) -> #DIV/0! | AJ15: =IF(AND(R15>0,AF15>0),(AF15/(R15*1000)*1000),0) -> 0 | AK15: =IF(AND(S15>0,AG15>0),(AG15/(S15*1000)*1000),0) -> 0 | AL15: 0 | AM15: 5887.1 | AN15: 4518.8 | AO15: =SUM(AL15:AN15) -> 10405.9 | AP15: =+[1]Nov!N10 -> 9953 | AQ15: =+AP15-AO15 -> -452.9 | AR15: =+AL15/AO15 -> 0 | AS15: =+AM15/AO15 -> 0.56574636 | AT15: =1-AR15-AS15 -> 0.43425364 | AU15: =+AR15*AQ15 -> 0 | AV15: =+AS15*AQ15 -> -256.22652 | AW15: =+AT15*AQ15 -> -196.67348 | AX15: =+AL15+AU15 -> 0 | AY15: =+AM15+AV15 -> 5630.8735 | AZ15: =+AN15+AW15 -> 4322.1265 | BA15: =+Efficiency2!K42 -> 0 | BB15: =BB14+BA15 -> 0 | BC15: =+R15/BA15 -> #DIV/0! | BD15: =+S15/BB15 -> #DIV/0!
A16: =A15+1 -> 45969 | B16: STOP | C16: 12 | D16: =+'8'!F42 -> 0 | E16: =+'8'!G42 -> 0 | F16: =1-(E16/D16) -> #DIV/0! | G16: =+P16/N16 -> 0 | H16: =+P16/L16 -> 0 | I16: =+R16/P16 -> #DIV/0! | J16: =+R16/L16 -> 0 | K16: =+S16/M16 -> 0 | L16: =+Efficiency1!K48 -> 43.297309 | M16: =M15+L16 -> 346.37848 | N16: =+Efficiency1!C48 -> 43.297309 | O16: =O15+N16 -> 346.37848 | P16: ='8'!I38 -> 0 | Q16: =Q15+P16 -> 0 | R16: ='8'!I40 -> 0 | S16: =S15+R16 -> 0 | T16: =+AX16 -> 0 | U16: =T16+U15 -> 0 | V16: =T16/P16 -> #DIV/0! | W16: =U16/Q16 -> #DIV/0! | X16: =IF(AND(R16>0,T16>0),(T16/(R16*1000))*1000,0) -> 0 | Y16: =IF(AND(S16>0,U16>0),U16/S16,0) -> 0 | Z16: 29.6 | AA16: =Z16+AA15 -> 144.2 | AB16: =Z16/(P16) -> #DIV/0! | AC16: =AA16/(Q16) -> #DIV/0! | AD16: =IF(AND(R16>0,Z16>0),Z16/(R16),0) -> 0 | AE16: =IF(AND(S16>0,AA16>0),AA16/(S16),0) -> 0 | AF16: ='8'!I46 -> 7428.5 | AG16: =AF16+AG15 -> 39418.84 | AH16: =IF(AND(L16>0,AF16>0),(AF16/(P16*1000)*1000),0) -> #DIV/0! | AI16: =IF(AND(M16>0,AG16>0),(AG16/(Q16*1000)*1000),0) -> #DIV/0! | AJ16: =IF(AND(R16>0,AF16>0),(AF16/(R16*1000)*1000),0) -> 0 | AK16: =IF(AND(S16>0,AG16>0),(AG16/(S16*1000)*1000),0) -> 0 | AL16: 0 | AM16: 5774 | AN16: 4286.6 | AO16: =SUM(AL16:AN16) -> 10060.6 | AP16: =+[1]Nov!N11 -> 9996 | AQ16: =+AP16-AO16 -> -64.6 | AR16: =+AL16/AO16 -> 0 | AS16: =+AM16/AO16 -> 0.57392203 | AT16: =1-AR16-AS16 -> 0.42607797 | AU16: =+AR16*AQ16 -> 0 | AV16: =+AS16*AQ16 -> -37.075363 | AW16: =+AT16*AQ16 -> -27.524637 | AX16: =+AL16+AU16 -> 0 | AY16: =+AM16+AV16 -> 5736.9246 | AZ16: =+AN16+AW16 -> 4259.0754 | BA16: =+Efficiency2!K48 -> 0 | BB16: =BB15+BA16 -> 0 | BC16: =+R16/BA16 -> #DIV/0! | BD16: =+S16/BB16 -> #DIV/0!
A17: =A16+1 -> 45970 | B17: STOP | C17: 12 | D17: =+'9'!F42 -> 0 | E17: =+'9'!G42 -> 0 | F17: =1-(E17/D17) -> #DIV/0! | G17: =+P17/N17 -> 0 | H17: =+P17/L17 -> 0 | I17: =+R17/P17 -> #DIV/0! | J17: =+R17/L17 -> 0 | K17: =+S17/M17 -> 0 | L17: =+Efficiency1!K54 -> 43.297309 | M17: =M16+L17 -> 389.67578 | N17: =+Efficiency1!C54 -> 43.297309 | O17: =O16+N17 -> 389.67578 | P17: ='9'!I38 -> 0 | Q17: =Q16+P17 -> 0 | R17: ='9'!I40 -> 0 | S17: =S16+R17 -> 0 | T17: =+AX17 -> 0 | U17: =T17+U16 -> 0 | V17: =T17/P17 -> #DIV/0! | W17: =U17/Q17 -> #DIV/0! | X17: =IF(AND(R17>0,T17>0),(T17/(R17*1000))*1000,0) -> 0 | Y17: =IF(AND(S17>0,U17>0),U17/S17,0) -> 0 | Z17: 34.8 | AA17: =Z17+AA16 -> 179 | AB17: =Z17/(P17) -> #DIV/0! | AC17: =AA17/(Q17) -> #DIV/0! | AD17: =IF(AND(R17>0,Z17>0),Z17/(R17),0) -> 0 | AE17: =IF(AND(S17>0,AA17>0),AA17/(S17),0) -> 0 | AF17: ='9'!I46 -> 5877.94 | AG17: =AF17+AG16 -> 45296.78 | AH17: =IF(AND(L17>0,AF17>0),(AF17/(P17*1000)*1000),0) -> #DIV/0! | AI17: =IF(AND(M17>0,AG17>0),(AG17/(Q17*1000)*1000),0) -> #DIV/0! | AJ17: =IF(AND(R17>0,AF17>0),(AF17/(R17*1000)*1000),0) -> 0 | AK17: =IF(AND(S17>0,AG17>0),(AG17/(S17*1000)*1000),0) -> 0 | AL17: 0 | AM17: 5551.8 | AN17: 4018.7 | AO17: =SUM(AL17:AN17) -> 9570.5 | AP17: =+[1]Nov!N12 -> 8927 | AQ17: =+AP17-AO17 -> -643.5 | AR17: =+AL17/AO17 -> 0 | AS17: =+AM17/AO17 -> 0.58009508 | AT17: =1-AR17-AS17 -> 0.41990492 | AU17: =+AR17*AQ17 -> 0 | AV17: =+AS17*AQ17 -> -373.29119 | AW17: =+AT17*AQ17 -> -270.20881 | AX17: =+AL17+AU17 -> 0 | AY17: =+AM17+AV17 -> 5178.5088 | AZ17: =+AN17+AW17 -> 3748.4912 | BA17: =+Efficiency2!K54 -> 0 | BB17: =BB16+BA17 -> 0 | BC17: =+R17/BA17 -> #DIV/0! | BD17: =+S17/BB17 -> #DIV/0!
A18: =A17+1 -> 45971 | B18: STOP | C18: 12 | D18: =+'10'!F42 -> 0 | E18: =+'10'!G42 -> 0 | F18: =1-(E18/D18) -> #DIV/0! | G18: =+P18/N18 -> 0 | H18: =+P18/L18 -> 0 | I18: =+R18/P18 -> #DIV/0! | J18: =+R18/L18 -> 0 | K18: =+S18/M18 -> 0 | L18: =+Efficiency1!K60 -> 43.297309 | M18: =M17+L18 -> 432.97309 | N18: =+Efficiency1!C60 -> 43.297309 | O18: =O17+N18 -> 432.97309 | P18: ='10'!I38 -> 0 | Q18: =Q17+P18 -> 0 | R18: ='10'!I40 -> 0 | S18: =S17+R18 -> 0 | T18: =+AX18 -> 0 | U18: =T18+U17 -> 0 | V18: =T18/P18 -> #DIV/0! | W18: =U18/Q18 -> #DIV/0! | X18: =IF(AND(R18>0,T18>0),(T18/(R18*1000))*1000,0) -> 0 | Y18: =IF(AND(S18>0,U18>0),U18/S18,0) -> 0 | Z18: 33.8 | AA18: =Z18+AA17 -> 212.8 | AB18: =Z18/(P18) -> #DIV/0! | AC18: =AA18/(Q18) -> #DIV/0! | AD18: =IF(AND(R18>0,Z18>0),Z18/(R18),0) -> 0 | AE18: =IF(AND(S18>0,AA18>0),AA18/(S18),0) -> 0 | AF18: ='10'!I46 -> 4702.24 | AG18: =AF18+AG17 -> 49999.02 | AH18: =IF(AND(L18>0,AF18>0),(AF18/(P18*1000)*1000),0) -> #DIV/0! | AI18: =IF(AND(M18>0,AG18>0),(AG18/(Q18*1000)*1000),0) -> #DIV/0! | AJ18: =IF(AND(R18>0,AF18>0),(AF18/(R18*1000)*1000),0) -> 0 | AK18: =IF(AND(S18>0,AG18>0),(AG18/(S18*1000)*1000),0) -> 0 | AL18: 0 | AM18: 6339.4 | AN18: 3970.5 | AO18: =SUM(AL18:AN18) -> 10309.9 | AP18: =+[1]Nov!N13 -> 9851 | AQ18: =+AP18-AO18 -> -458.9 | AR18: =+AL18/AO18 -> 0 | AS18: =+AM18/AO18 -> 0.61488472 | AT18: =1-AR18-AS18 -> 0.38511528 | AU18: =+AR18*AQ18 -> 0 | AV18: =+AS18*AQ18 -> -282.1706 | AW18: =+AT18*AQ18 -> -176.7294 | AX18: =+AL18+AU18 -> 0 | AY18: =+AM18+AV18 -> 6057.2294 | AZ18: =+AN18+AW18 -> 3793.7706 | BA18: =+Efficiency2!K60 -> 0 | BB18: =BB17+BA18 -> 0 | BC18: =+R18/BA18 -> #DIV/0! | BD18: =+S18/BB18 -> #DIV/0!
A19: =A18+1 -> 45972 | B19: STOP | C19: 12 | D19: =+'11'!F42 -> 0 | E19: =+'11'!G42 -> 0 | F19: =1-(E19/D19) -> #DIV/0! | G19: =+P19/N19 -> 0 | H19: =+P19/L19 -> 0 | I19: =+R19/P19 -> #DIV/0! | J19: =+R19/L19 -> 0 | K19: =+S19/M19 -> 0 | L19: =+Efficiency1!K66 -> 43.297309 | M19: =M18+L19 -> 476.2704 | N19: =+Efficiency1!C66 -> 43.297309 | O19: =O18+N19 -> 476.2704 | P19: ='11'!I38 -> 0 | Q19: =Q18+P19 -> 0 | R19: ='11'!I40 -> 0 | S19: =S18+R19 -> 0 | T19: =+AX19 -> 0 | U19: =T19+U18 -> 0 | V19: =T19/P19 -> #DIV/0! | W19: =U19/Q19 -> #DIV/0! | X19: =IF(AND(R19>0,T19>0),(T19/(R19*1000))*1000,0) -> 0 | Y19: =IF(AND(S19>0,U19>0),U19/S19,0) -> 0 | Z19: 34 | AA19: =Z19+AA18 -> 246.8 | AB19: =Z19/(P19) -> #DIV/0! | AC19: =AA19/(Q19) -> #DIV/0! | AD19: =IF(AND(R19>0,Z19>0),Z19/(R19),0) -> 0 | AE19: =IF(AND(S19>0,AA19>0),AA19/(S19),0) -> 0 | AF19: ='11'!I46 -> 5965.74 | AG19: =AF19+AG18 -> 55964.76 | AH19: =IF(AND(L19>0,AF19>0),(AF19/(P19*1000)*1000),0) -> #DIV/0! | AI19: =IF(AND(M19>0,AG19>0),(AG19/(Q19*1000)*1000),0) -> #DIV/0! | AJ19: =IF(AND(R19>0,AF19>0),(AF19/(R19*1000)*1000),0) -> 0 | AK19: =IF(AND(S19>0,AG19>0),(AG19/(S19*1000)*1000),0) -> 0 | AL19: 0 | AM19: 5767 | AN19: 3937.9 | AO19: =SUM(AL19:AN19) -> 9704.9 | AP19: =+[1]Nov!N14 -> 9290 | AQ19: =+AP19-AO19 -> -414.9 | AR19: =+AL19/AO19 -> 0 | AS19: =+AM19/AO19 -> 0.5942359 | AT19: =1-AR19-AS19 -> 0.4057641 | AU19: =+AR19*AQ19 -> 0 | AV19: =+AS19*AQ19 -> -246.54848 | AW19: =+AT19*AQ19 -> -168.35152 | AX19: =+AL19+AU19 -> 0 | AY19: =+AM19+AV19 -> 5520.4515 | AZ19: =+AN19+AW19 -> 3769.5485 | BA19: =+Efficiency2!K66 -> 0 | BB19: =BB18+BA19 -> 0 | BC19: =+R19/BA19 -> #DIV/0! | BD19: =+S19/BB19 -> #DIV/0!
A20: =A19+1 -> 45973 | B20: STOP | C20: 12 | D20: =+'12'!F42 -> 0 | E20: =+'12'!G42 -> 0 | F20: =1-(E20/D20) -> #DIV/0! | G20: =+P20/N20 -> 0 | H20: =+P20/L20 -> 0 | I20: =+R20/P20 -> #DIV/0! | J20: =+R20/L20 -> 0 | K20: =+S20/M20 -> 0 | L20: =+Efficiency1!K72 -> 43.297309 | M20: =M19+L20 -> 519.56771 | N20: =+Efficiency1!C72 -> 43.297309 | O20: =O19+N20 -> 519.56771 | P20: ='12'!I38 -> 0 | Q20: =Q19+P20 -> 0 | R20: ='12'!I40 -> 0 | S20: =S19+R20 -> 0 | T20: =+AX20 -> 0 | U20: =T20+U19 -> 0 | V20: =T20/P20 -> #DIV/0! | W20: =U20/Q20 -> #DIV/0! | X20: =IF(AND(R20>0,T20>0),(T20/(R20*1000))*1000,0) -> 0 | Y20: =IF(AND(S20>0,U20>0),U20/S20,0) -> 0 | Z20: 24.5 | AA20: =Z20+AA19 -> 271.3 | AB20: =Z20/(P20) -> #DIV/0! | AC20: =AA20/(Q20) -> #DIV/0! | AD20: =IF(AND(R20>0,Z20>0),Z20/(R20),0) -> 0 | AE20: =IF(AND(S20>0,AA20>0),AA20/(S20),0) -> 0 | AF20: ='12'!I46 -> 5973.86 | AG20: =AF20+AG19 -> 61938.62 | AH20: =IF(AND(L20>0,AF20>0),(AF20/(P20*1000)*1000),0) -> #DIV/0! | AI20: =IF(AND(M20>0,AG20>0),(AG20/(Q20*1000)*1000),0) -> #DIV/0! | AJ20: =IF(AND(R20>0,AF20>0),(AF20/(R20*1000)*1000),0) -> 0 | AK20: =IF(AND(S20>0,AG20>0),(AG20/(S20*1000)*1000),0) -> 0 | AL20: 0 | AM20: 5487.3 | AN20: 4208.2 | AO20: =SUM(AL20:AN20) -> 9695.5 | AP20: =+[1]Nov!N15 -> 9193 | AQ20: =+AP20-AO20 -> -502.5 | AR20: =+AL20/AO20 -> 0 | AS20: =+AM20/AO20 -> 0.56596359 | AT20: =1-AR20-AS20 -> 0.43403641 | AU20: =+AR20*AQ20 -> 0 | AV20: =+AS20*AQ20 -> -284.3967 | AW20: =+AT20*AQ20 -> -218.1033 | AX20: =+AL20+AU20 -> 0 | AY20: =+AM20+AV20 -> 5202.9033 | AZ20: =+AN20+AW20 -> 3990.0967 | BA20: =+Efficiency2!K72 -> 0 | BB20: =BB19+BA20 -> 0 | BC20: =+R20/BA20 -> #DIV/0! | BD20: =+S20/BB20 -> #DIV/0!
A21: =A20+1 -> 45974 | B21: STOP | C21: 12 | D21: =+'13'!F42 -> 0 | E21: =+'13'!G42 -> 0 | F21: =1-(E21/D21) -> #DIV/0! | G21: =+P21/N21 -> 0 | H21: =+P21/L21 -> 0 | I21: =+R21/P21 -> #DIV/0! | J21: =+R21/L21 -> 0 | K21: =+S21/M21 -> 0 | L21: =+Efficiency1!K78 -> 43.297309 | M21: =M20+L21 -> 562.86502 | N21: =+Efficiency1!C78 -> 43.297309 | O21: =O20+N21 -> 562.86502 | P21: ='13'!I38 -> 0 | Q21: =Q20+P21 -> 0 | R21: ='13'!I40 -> 0 | S21: =S20+R21 -> 0 | T21: =+AX21 -> 0 | U21: =T21+U20 -> 0 | V21: =T21/P21 -> #DIV/0! | W21: =U21/Q21 -> #DIV/0! | X21: =IF(AND(R21>0,T21>0),(T21/(R21*1000))*1000,0) -> 0 | Y21: =IF(AND(S21>0,U21>0),U21/S21,0) -> 0 | Z21: 13.5 | AA21: =Z21+AA20 -> 284.8 | AB21: =Z21/(P21) -> #DIV/0! | AC21: =AA21/(Q21) -> #DIV/0! | AD21: =IF(AND(R21>0,Z21>0),Z21/(R21),0) -> 0 | AE21: =IF(AND(S21>0,AA21>0),AA21/(S21),0) -> 0 | AF21: ='13'!I46 -> 5379.3 | AG21: =AF21+AG20 -> 67317.92 | AH21: =IF(AND(L21>0,AF21>0),(AF21/(P21*1000)*1000),0) -> #DIV/0! | AI21: =IF(AND(M21>0,AG21>0),(AG21/(Q21*1000)*1000),0) -> #DIV/0! | AJ21: =IF(AND(R21>0,AF21>0),(AF21/(R21*1000)*1000),0) -> 0 | AK21: =IF(AND(S21>0,AG21>0),(AG21/(S21*1000)*1000),0) -> 0 | AL21: 0 | AM21: 4305.1 | AN21: 3078 | AO21: =SUM(AL21:AN21) -> 7383.1 | AP21: =+[1]Nov!N16 -> 7163 | AQ21: =+AP21-AO21 -> -220.1 | AR21: =+AL21/AO21 -> 0 | AS21: =+AM21/AO21 -> 0.58310195 | AT21: =1-AR21-AS21 -> 0.41689805 | AU21: =+AR21*AQ21 -> 0 | AV21: =+AS21*AQ21 -> -128.34074 | AW21: =+AT21*AQ21 -> -91.759261 | AX21: =+AL21+AU21 -> 0 | AY21: =+AM21+AV21 -> 4176.7593 | AZ21: =+AN21+AW21 -> 2986.2407 | BA21: =+Efficiency2!K78 -> 0 | BB21: =BB20+BA21 -> 0 | BC21: =+R21/BA21 -> #DIV/0! | BD21: =+S21/BB21 -> #DIV/0!
A22: =A21+1 -> 45975 | B22: STOP | C22: 12 | D22: =+'14'!F42 -> 0 | E22: =+'14'!G42 -> 0 | F22: =1-(E22/D22) -> #DIV/0! | G22: =+P22/N22 -> 0 | H22: =+P22/L22 -> 0 | I22: =+R22/P22 -> #DIV/0! | J22: =+R22/L22 -> 0 | K22: =+S22/M22 -> 0 | L22: =+Efficiency1!K84 -> 43.297309 | M22: =M21+L22 -> 606.16233 | N22: =+Efficiency1!C84 -> 43.297309 | O22: =O21+N22 -> 606.16233 | P22: ='14'!I38 -> 0 | Q22: =Q21+P22 -> 0 | R22: ='14'!I40 -> 0 | S22: =S21+R22 -> 0 | T22: =+AX22 -> 0 | U22: =T22+U21 -> 0 | V22: =T22/P22 -> #DIV/0! | W22: =U22/Q22 -> #DIV/0! | X22: =IF(AND(R22>0,T22>0),(T22/(R22*1000))*1000,0) -> 0 | Y22: =IF(AND(S22>0,U22>0),U22/S22,0) -> 0 | Z22: 21.4 | AA22: =Z22+AA21 -> 306.2 | AB22: =Z22/(P22) -> #DIV/0! | AC22: =AA22/(Q22) -> #DIV/0! | AD22: =IF(AND(R22>0,Z22>0),Z22/(R22),0) -> 0 | AE22: =IF(AND(S22>0,AA22>0),AA22/(S22),0) -> 0 | AF22: ='14'!I46 -> 5869.38 | AG22: =AF22+AG21 -> 73187.3 | AH22: =IF(AND(L22>0,AF22>0),(AF22/(P22*1000)*1000),0) -> #DIV/0! | AI22: =IF(AND(M22>0,AG22>0),(AG22/(Q22*1000)*1000),0) -> #DIV/0! | AJ22: =IF(AND(R22>0,AF22>0),(AF22/(R22*1000)*1000),0) -> 0 | AK22: =IF(AND(S22>0,AG22>0),(AG22/(S22*1000)*1000),0) -> 0 | AL22: 0 | AM22: 4911.4 | AN22: 3827.9 | AO22: =SUM(AL22:AN22) -> 8739.3 | AP22: =+[1]Nov!N17 -> 8270 | AQ22: =+AP22-AO22 -> -469.3 | AR22: =+AL22/AO22 -> 0 | AS22: =+AM22/AO22 -> 0.56199009 | AT22: =1-AR22-AS22 -> 0.43800991 | AU22: =+AR22*AQ22 -> 0 | AV22: =+AS22*AQ22 -> -263.74195 | AW22: =+AT22*AQ22 -> -205.55805 | AX22: =+AL22+AU22 -> 0 | AY22: =+AM22+AV22 -> 4647.6581 | AZ22: =+AN22+AW22 -> 3622.3419 | BA22: =+Efficiency2!K84 -> 0 | BB22: =BB21+BA22 -> 0 | BC22: =+R22/BA22 -> #DIV/0! | BD22: =+S22/BB22 -> #DIV/0!
A23: =A22+1 -> 45976 | B23: STOP | C23: 12 | D23: =+'15'!F42 -> 0 | E23: =+'15'!G42 -> 0 | F23: =1-(E23/D23) -> #DIV/0! | G23: =+P23/N23 -> 0 | H23: =+P23/L23 -> 0 | I23: =+R23/P23 -> #DIV/0! | J23: =+R23/L23 -> 0 | K23: =+S23/M23 -> 0 | L23: =+Efficiency1!K90 -> 43.297309 | M23: =M22+L23 -> 649.45964 | N23: =+Efficiency1!C90 -> 43.297309 | O23: =O22+N23 -> 649.45964 | P23: ='15'!I38 -> 0 | Q23: =Q22+P23 -> 0 | R23: ='15'!I40 -> 0 | S23: =S22+R23 -> 0 | T23: =+AX23 -> 222.4412 | U23: =T23+U22 -> 222.4412 | V23: =T23/P23 -> #DIV/0! | W23: =U23/Q23 -> #DIV/0! | X23: =IF(AND(R23>0,T23>0),(T23/(R23*1000))*1000,0) -> 0 | Y23: =IF(AND(S23>0,U23>0),U23/S23,0) -> 0 | Z23: 19 | AA23: =Z23+AA22 -> 325.2 | AB23: =Z23/(P23) -> #DIV/0! | AC23: =AA23/(Q23) -> #DIV/0! | AD23: =IF(AND(R23>0,Z23>0),Z23/(R23),0) -> 0 | AE23: =IF(AND(S23>0,AA23>0),AA23/(S23),0) -> 0 | AF23: ='15'!I46 -> 8729.52 | AG23: =AF23+AG22 -> 81916.82 | AH23: =IF(AND(L23>0,AF23>0),(AF23/(P23*1000)*1000),0) -> #DIV/0! | AI23: =IF(AND(M23>0,AG23>0),(AG23/(Q23*1000)*1000),0) -> #DIV/0! | AJ23: =IF(AND(R23>0,AF23>0),(AF23/(R23*1000)*1000),0) -> 0 | AK23: =IF(AND(S23>0,AG23>0),(AG23/(S23*1000)*1000),0) -> 0 | AL23: 215.1 | AM23: 5032.1 | AN23: 3824.2 | AO23: =SUM(AL23:AN23) -> 9071.4 | AP23: =+[1]Nov!N18 -> 9381 | AQ23: =+AP23-AO23 -> 309.6 | AR23: =+AL23/AO23 -> 0.023711886 | AS23: =+AM23/AO23 -> 0.55472143 | AT23: =1-AR23-AS23 -> 0.42156668 | AU23: =+AR23*AQ23 -> 7.3411998 | AV23: =+AS23*AQ23 -> 171.74176 | AW23: =+AT23*AQ23 -> 130.51704 | AX23: =+AL23+AU23 -> 222.4412 | AY23: =+AM23+AV23 -> 5203.8418 | AZ23: =+AN23+AW23 -> 3954.717 | BA23: =+Efficiency2!K90 -> 0 | BB23: =BB22+BA23 -> 0 | BC23: =+R23/BA23 -> #DIV/0! | BD23: =+S23/BB23 -> #DIV/0!
A24: =A23+1 -> 45977 | B24: Facial | C24: 12 | D24: =+'16'!F42 -> 855.68445 | E24: =+'16'!G42 -> 658.87703 | F24: =1-(E24/D24) -> 0.23 | G24: =+P24/N24 -> 0.83037041 | H24: =+P24/L24 -> 0.57767078 | I24: =+R24/P24 -> 0.90425918 | J24: =+R24/L24 -> 0.5223641 | K24: =+S24/M24 -> 0.032409516 | L24: =+Efficiency1!K96 -> 42.960456 | M24: =M23+L24 -> 692.4201 | N24: =+Efficiency1!C96 -> 29.886662 | O24: =O23+N24 -> 679.3463 | P24: ='16'!I38 -> 24.817 | Q24: =Q23+P24 -> 24.817 | R24: ='16'!I40 -> 22.441 | S24: =S23+R24 -> 22.441 | T24: =+AX24 -> 2914.2417 | U24: =T24+U23 -> 3136.6829 | V24: =T24/P24 -> 117.42925 | W24: =U24/Q24 -> 126.39251 | X24: =IF(AND(R24>0,T24>0),(T24/(R24*1000))*1000,0) -> 129.86238 | Y24: =IF(AND(S24>0,U24>0),U24/S24,0) -> 139.77465 | Z24: 54.8 | AA24: =Z24+AA23 -> 380 | AB24: =Z24/(P24) -> 2.2081638 | AC24: =AA24/(Q24) -> 15.312084 | AD24: =IF(AND(R24>0,Z24>0),Z24/(R24),0) -> 2.4419589 | AE24: =IF(AND(S24>0,AA24>0),AA24/(S24),0) -> 16.933292 | AF24: ='16'!I46 -> 29484.82 | AG24: =AF24+AG23 -> 111401.64 | AH24: =IF(AND(L24>0,AF24>0),(AF24/(P24*1000)*1000),0) -> 1188.0896 | AI24: =IF(AND(M24>0,AG24>0),(AG24/(Q24*1000)*1000),0) -> 4488.9245 | AJ24: =IF(AND(R24>0,AF24>0),(AF24/(R24*1000)*1000),0) -> 1313.8817 | AK24: =IF(AND(S24>0,AG24>0),(AG24/(S24*1000)*1000),0) -> 4964.2012 | AL24: 3312.8 | AM24: 5037.4 | AN24: 3264.1 | AO24: =SUM(AL24:AN24) -> 11614.3 | AP24: =+[1]Nov!N19 -> 10217 | AQ24: =+AP24-AO24 -> -1397.3 | AR24: =+AL24/AO24 -> 0.28523458 | AS24: =+AM24/AO24 -> 0.43372394 | AT24: =1-AR24-AS24 -> 0.28104147 | AU24: =+AR24*AQ24 -> -398.55828 | AV24: =+AS24*AQ24 -> -606.04247 | AW24: =+AT24*AQ24 -> -392.69925 | AX24: =+AL24+AU24 -> 2914.2417 | AY24: =+AM24+AV24 -> 4431.3575 | AZ24: =+AN24+AW24 -> 2871.4007 | BA24: =+Efficiency2!K96 -> 38.485408 | BB24: =BB23+BA24 -> 38.485408 | BC24: =+R24/BA24 -> 0.58310411 | BD24: =+S24/BB24 -> 0.58310411
A25: =A24+1 -> 45978 | B25: Facial | C25: 12 | D25: =+'17'!F42 -> 1057.6944 | E25: =+'17'!G42 -> 814.42472 | F25: =1-(E25/D25) -> 0.23 | G25: =+P25/N25 -> 0.92024576 | H25: =+P25/L25 -> 0.79133238 | I25: =+R25/P25 -> 0.75147076 | J25: =+R25/L25 -> 0.59466315 | K25: =+S25/M25 -> 0.065256009 | L25: =+Efficiency1!K102 -> 42.960456 | M25: =M24+L25 -> 735.38055 | N25: =+Efficiency1!C102 -> 36.942305 | O25: =O24+N25 -> 716.28861 | P25: ='17'!I38 -> 33.996 | Q25: =Q24+P25 -> 58.813 | R25: ='17'!I40 -> 25.547 | S25: =S24+R25 -> 47.988 | T25: =+AX25 -> 4002.7217 | U25: =T25+U24 -> 7139.4046 | V25: =T25/P25 -> 117.74096 | W25: =U25/Q25 -> 121.39161 | X25: =IF(AND(R25>0,T25>0),(T25/(R25*1000))*1000,0) -> 156.68069 | Y25: =IF(AND(S25>0,U25>0),U25/S25,0) -> 148.77479 | Z25: 61.1 | AA25: =Z25+AA24 -> 441.1 | AB25: =Z25/(P25) -> 1.7972703 | AC25: =AA25/(Q25) -> 7.5000425 | AD25: =IF(AND(R25>0,Z25>0),Z25/(R25),0) -> 2.3916703 | AE25: =IF(AND(S25>0,AA25>0),AA25/(S25),0) -> 9.1918813 | AF25: ='17'!I46 -> 36139.06 | AG25: =AF25+AG24 -> 147540.7 | AH25: =IF(AND(L25>0,AF25>0),(AF25/(P25*1000)*1000),0) -> 1063.0386 | AI25: =IF(AND(M25>0,AG25>0),(AG25/(Q25*1000)*1000),0) -> 2508.6409 | AJ25: =IF(AND(R25>0,AF25>0),(AF25/(R25*1000)*1000),0) -> 1414.6107 | AK25: =IF(AND(S25>0,AG25>0),(AG25/(S25*1000)*1000),0) -> 3074.5332 | AL25: 4212.4 | AM25: 5190.8 | AN25: 4061 | AO25: =SUM(AL25:AN25) -> 13464.2 | AP25: =+[1]Nov!N20 -> 12794 | AQ25: =+AP25-AO25 -> -670.2 | AR25: =+AL25/AO25 -> 0.31285929 | AS25: =+AM25/AO25 -> 0.38552606 | AT25: =1-AR25-AS25 -> 0.30161465 | AU25: =+AR25*AQ25 -> -209.67829 | AV25: =+AS25*AQ25 -> -258.37957 | AW25: =+AT25*AQ25 -> -202.14214 | AX25: =+AL25+AU25 -> 4002.7217 | AY25: =+AM25+AV25 -> 4932.4204 | AZ25: =+AN25+AW25 -> 3858.8579 | BA25: =+Efficiency2!K102 -> 42.960456 | BB25: =BB24+BA25 -> 81.445864 | BC25: =+R25/BA25 -> 0.59466315 | BD25: =+S25/BB25 -> 0.58920119
A26: =A25+1 -> 45979 | B26: Facial | C26: 12/10,3 | D26: =+'18'!F42 -> 1192.0365 | E26: =+'18'!G42 -> 913.66372 | F26: =1-(E26/D26) -> 0.23352706 | G26: =+P26/N26 -> 0.86476645 | H26: =+P26/L26 -> 0.8381348 | I26: =+R26/P26 -> 0.96357876 | J26: =+R26/L26 -> 0.80760889 | K26: =+S26/M26 -> 0.10586366 | L26: =+SUM(Efficiency1!K107:K108) -> 42.554014 | M26: =M25+L26 -> 777.93457 | N26: =+SUM(Efficiency1!C107:C108) -> 41.243506 | O26: =O25+N26 -> 757.53211 | P26: ='18'!I38 -> 35.666 | Q26: =Q25+P26 -> 94.479 | R26: ='18'!I40 -> 34.367 | S26: =S25+R26 -> 82.355 | T26: =+AX26 -> 4457.981 | U26: =T26+U25 -> 11597.386 | V26: =T26/P26 -> 124.99246 | W26: =U26/Q26 -> 122.75094 | X26: =IF(AND(R26>0,T26>0),(T26/(R26*1000))*1000,0) -> 129.71691 | Y26: =IF(AND(S26>0,U26>0),U26/S26,0) -> 140.82188 | Z26: 55.8 | AA26: =Z26+AA25 -> 496.9 | AB26: =Z26/(P26) -> 1.5645152 | AC26: =AA26/(Q26) -> 5.2593698 | AD26: =IF(AND(R26>0,Z26>0),Z26/(R26),0) -> 1.6236506 | AE26: =IF(AND(S26>0,AA26>0),AA26/(S26),0) -> 6.0336349 | AF26: ='18'!I46 -> 37593.88 | AG26: =AF26+AG25 -> 185134.58 | AH26: =IF(AND(L26>0,AF26>0),(AF26/(P26*1000)*1000),0) -> 1054.0537 | AI26: =IF(AND(M26>0,AG26>0),(AG26/(Q26*1000)*1000),0) -> 1959.5315 | AJ26: =IF(AND(R26>0,AF26>0),(AF26/(R26*1000)*1000),0) -> 1093.8947 | AK26: =IF(AND(S26>0,AG26>0),(AG26/(S26*1000)*1000),0) -> 2248.0066 | AL26: 4669.4 | AM26: 4810.6 | AN26: 4105.1 | AO26: =SUM(AL26:AN26) -> 13585.1 | AP26: =+[1]Nov!N21 -> 12970 | AQ26: =+AP26-AO26 -> -615.1 | AR26: =+AL26/AO26 -> 0.34371481 | AS26: =+AM26/AO26 -> 0.35410855 | AT26: =1-AR26-AS26 -> 0.30217665 | AU26: =+AR26*AQ26 -> -211.41898 | AV26: =+AS26*AQ26 -> -217.81217 | AW26: =+AT26*AQ26 -> -185.86886 | AX26: =+AL26+AU26 -> 4457.981 | AY26: =+AM26+AV26 -> 4592.7878 | AZ26: =+AN26+AW26 -> 3919.2311 | BA26: =+SUM(Efficiency2!K107:K108) -> 40.48035 | BB26: =BB25+BA26 -> 121.92621 | BC26: =+R26/BA26 -> 0.84897981 | BD26: =+S26/BB26 -> 0.67544949
A27: =A26+1 -> 45980 | B27: Facial | C27: 12 | D27: =+'19'!F42 -> 1230 | E27: =+'19'!G42 -> 942.30191 | F27: =1-(E27/D27) -> 0.23390089 | G27: =+P27/N27 -> 0.48044951 | H27: =+P27/L27 -> 0.48044951 | I27: =+R27/P27 -> 1.2598187 | J27: =+R27/L27 -> 0.60527929 | K27: =+S27/M27 -> 0.1314601 | L27: =+Efficiency1!K112 -> 42.025227 | M27: =M26+L27 -> 819.9598 | N27: =+Efficiency1!C112 -> 42.025227 | O27: =O26+N27 -> 799.55734 | P27: ='19'!I38 -> 20.191 | Q27: =Q26+P27 -> 114.67 | R27: ='19'!I40 -> 25.437 | S27: =S26+R27 -> 107.792 | T27: =+AX27 -> 2548.0121 | U27: =T27+U26 -> 14145.398 | V27: =T27/P27 -> 126.19544 | W27: =U27/Q27 -> 123.35744 | X27: =IF(AND(R27>0,T27>0),(T27/(R27*1000))*1000,0) -> 100.16952 | Y27: =IF(AND(S27>0,U27>0),U27/S27,0) -> 131.22864 | Z27: 29.1 | AA27: =Z27+AA26 -> 526 | AB27: =Z27/(P27) -> 1.4412362 | AC27: =AA27/(Q27) -> 4.587076 | AD27: =IF(AND(R27>0,Z27>0),Z27/(R27),0) -> 1.1440028 | AE27: =IF(AND(S27>0,AA27>0),AA27/(S27),0) -> 4.8797684 | AF27: ='19'!I46 -> 28376 | AG27: =AF27+AG26 -> 213510.58 | AH27: =IF(AND(L27>0,AF27>0),(AF27/(P27*1000)*1000),0) -> 1405.3786 | AI27: =IF(AND(M27>0,AG27>0),(AG27/(Q27*1000)*1000),0) -> 1861.9567 | AJ27: =IF(AND(R27>0,AF27>0),(AF27/(R27*1000)*1000),0) -> 1115.5404 | AK27: =IF(AND(S27>0,AG27>0),(AG27/(S27*1000)*1000),0) -> 1980.7646 | AL27: 2647.5 | AM27: 5128.8 | AN27: 3259.4 | AO27: =SUM(AL27:AN27) -> 11035.7 | AP27: =+[1]Nov!N22 -> 10621 | AQ27: =+AP27-AO27 -> -414.7 | AR27: =+AL27/AO27 -> 0.23990322 | AS27: =+AM27/AO27 -> 0.46474623 | AT27: =1-AR27-AS27 -> 0.29535054 | AU27: =+AR27*AQ27 -> -99.487867 | AV27: =+AS27*AQ27 -> -192.73026 | AW27: =+AT27*AQ27 -> -122.48187 | AX27: =+AL27+AU27 -> 2548.0121 | AY27: =+AM27+AV27 -> 4936.0697 | AZ27: =+AN27+AW27 -> 3136.9181 | BA27: =+Efficiency2!K112 -> 22.967954 | BB27: =BB26+BA27 -> 144.89417 | BC27: =+R27/BA27 -> 1.1074996 | BD27: =+S27/BB27 -> 0.74393608
A28: =A27+1 -> 45981 | B28: Facial | C28: 13/14 | D28: =+'20'!F42 -> 1126.6667 | E28: =+'20'!G42 -> 863.96541 | F28: =1-(E28/D28) -> 0.23316679 | G28: =+P28/N28 -> 0.4709505 | H28: =+P28/L28 -> 0.43396016 | I28: =+R28/P28 -> 0.59095915 | J28: =+R28/L28 -> 0.25645273 | K28: =+S28/M28 -> 0.1381041 | L28: =+SUM(Efficiency1!K117:K118) -> 46.031875 | M28: =M27+L28 -> 865.99167 | N28: =+SUM(Efficiency1!C117:C118) -> 42.416347 | O28: =O27+N28 -> 841.97369 | P28: ='20'!I38 -> 19.976 | Q28: =Q27+P28 -> 134.646 | R28: ='20'!I40 -> 11.805 | S28: =S27+R28 -> 119.597 | T28: =+AX28 -> 2577.3202 | U28: =T28+U27 -> 16722.718 | V28: =T28/P28 -> 129.02083 | W28: =U28/Q28 -> 124.19766 | X28: =IF(AND(R28>0,T28>0),(T28/(R28*1000))*1000,0) -> 218.32445 | Y28: =IF(AND(S28>0,U28>0),U28/S28,0) -> 139.82556 | Z28: 33.4 | AA28: =Z28+AA27 -> 559.4 | AB28: =Z28/(P28) -> 1.6720064 | AC28: =AA28/(Q28) -> 4.154598 | AD28: =IF(AND(R28>0,Z28>0),Z28/(R28),0) -> 2.8293096 | AE28: =IF(AND(S28>0,AA28>0),AA28/(S28),0) -> 4.6773749 | AF28: ='20'!I46 -> 19849.06 | AG28: =AF28+AG27 -> 233359.64 | AH28: =IF(AND(L28>0,AF28>0),(AF28/(P28*1000)*1000),0) -> 993.64537 | AI28: =IF(AND(M28>0,AG28>0),(AG28/(Q28*1000)*1000),0) -> 1733.1346 | AJ28: =IF(AND(R28>0,AF28>0),(AF28/(R28*1000)*1000),0) -> 1681.4113 | AK28: =IF(AND(S28>0,AG28>0),(AG28/(S28*1000)*1000),0) -> 1951.2165 | AL28: 2704.6 | AM28: 5209 | AN28: 4022.1 | AO28: =SUM(AL28:AN28) -> 11935.7 | AP28: =+[1]Nov!N23 -> 11374 | AQ28: =+AP28-AO28 -> -561.7 | AR28: =+AL28/AO28 -> 0.22659752 | AS28: =+AM28/AO28 -> 0.43642183 | AT28: =1-AR28-AS28 -> 0.33698065 | AU28: =+AR28*AQ28 -> -127.27983 | AV28: =+AS28*AQ28 -> -245.13814 | AW28: =+AT28*AQ28 -> -189.28203 | AX28: =+AL28+AU28 -> 2577.3202 | AY28: =+AM28+AV28 -> 4963.8619 | AZ28: =+AN28+AW28 -> 3832.818 | BA28: =+SUM(Efficiency2!K117:K118) -> 23.119021 | BB28: =BB27+BA28 -> 168.01319 | BC28: =+R28/BA28 -> 0.51061851 | BD28: =+S28/BB28 -> 0.71183102
A29: =A28+1 -> 45982 | B29: Facial | C29: 13/14/11 | D29: =+'21'!F42 -> 1166.7361 | E29: =+'21'!G42 -> 894.38681 | F29: =1-(E29/D29) -> 0.23342837 | G29: =+P29/N29 -> 0.96094511 | H29: =+P29/L29 -> 0.90815758 | I29: =+R29/P29 -> 1.0161142 | J29: =+R29/L29 -> 0.92279177 | K29: =+S29/M29 -> 0.17520869 | L29: =+SUM(Efficiency1!K122:K124) -> 42.981528 | M29: =M28+L29 -> 908.9732 | N29: =+SUM(Efficiency1!C122:C124) -> 40.620426 | O29: =O28+N29 -> 882.59412 | P29: ='21'!I38 -> 39.034 | Q29: =Q28+P29 -> 173.68 | R29: ='21'!I40 -> 39.663 | S29: =S28+R29 -> 159.26 | T29: =+AX29 -> 4544.7561 | U29: =T29+U28 -> 21267.474 | V29: =T29/P29 -> 116.43071 | W29: =U29/Q29 -> 122.45206 | X29: =IF(AND(R29>0,T29>0),(T29/(R29*1000))*1000,0) -> 114.58428 | Y29: =IF(AND(S29>0,U29>0),U29/S29,0) -> 133.53933 | Z29: 55.5 | AA29: =Z29+AA28 -> 614.9 | AB29: =Z29/(P29) -> 1.4218374 | AC29: =AA29/(Q29) -> 3.5404192 | AD29: =IF(AND(R29>0,Z29>0),Z29/(R29),0) -> 1.399289 | AE29: =IF(AND(S29>0,AA29>0),AA29/(S29),0) -> 3.860982 | AF29: ='21'!I46 -> 40426.02 | AG29: =AF29+AG28 -> 273785.66 | AH29: =IF(AND(L29>0,AF29>0),(AF29/(P29*1000)*1000),0) -> 1035.6617 | AI29: =IF(AND(M29>0,AG29>0),(AG29/(Q29*1000)*1000),0) -> 1576.3799 | AJ29: =IF(AND(R29>0,AF29>0),(AF29/(R29*1000)*1000),0) -> 1019.2376 | AK29: =IF(AND(S29>0,AG29>0),(AG29/(S29*1000)*1000),0) -> 1719.1113 | AL29: 4812 | AM29: 5025.7 | AN29: 4205.2 | AO29: =SUM(AL29:AN29) -> 14042.9 | AP29: =+[1]Nov!N24 -> 13263 | AQ29: =+AP29-AO29 -> -779.9 | AR29: =+AL29/AO29 -> 0.34266426 | AS29: =+AM29/AO29 -> 0.35788192 | AT29: =1-AR29-AS29 -> 0.29945382 | AU29: =+AR29*AQ29 -> -267.24386 | AV29: =+AS29*AQ29 -> -279.11211 | AW29: =+AT29*AQ29 -> -233.54403 | AX29: =+AL29+AU29 -> 4544.7561 | AY29: =+AM29+AV29 -> 4746.5879 | AZ29: =+AN29+AW29 -> 3971.656 | BA29: =+SUM(Efficiency2!K122:K124) -> 42.981528 | BB29: =BB28+BA29 -> 210.99472 | BC29: =+R29/BA29 -> 0.92279177 | BD29: =+S29/BB29 -> 0.75480563
A30: =A29+1 -> 45983 | B30: Facial | C30: 11/13 | D30: =+'22'!F42 -> 1181.4493 | E30: =+'22'!G42 -> 905.82029 | F30: =1-(E30/D30) -> 0.23329735 | G30: =+P30/N30 -> 0.92295291 | H30: =+P30/L30 -> 0.8859037 | I30: =+R30/P30 -> 0.93820854 | J30: =+R30/L30 -> 0.83116241 | K30: =+S30/M30 -> 0.20373151 | L30: =+SUM(Efficiency1!K127:K128) -> 41.321647 | M30: =M29+L30 -> 950.29485 | N30: =+SUM(Efficiency1!C127:C128) -> 39.662912 | O30: =O29+N30 -> 922.25703 | P30: ='22'!I38 -> 36.607 | Q30: =Q29+P30 -> 210.287 | R30: ='22'!I40 -> 34.345 | S30: =S29+R30 -> 193.605 | T30: =+AX30 -> 4441.2699 | U30: =T30+U29 -> 25708.744 | V30: =T30/P30 -> 121.32297 | W30: =U30/Q30 -> 122.25551 | X30: =IF(AND(R30>0,T30>0),(T30/(R30*1000))*1000,0) -> 129.31343 | Y30: =IF(AND(S30>0,U30>0),U30/S30,0) -> 132.78967 | Z30: 52.9 | AA30: =Z30+AA29 -> 667.8 | AB30: =Z30/(P30) -> 1.4450788 | AC30: =AA30/(Q30) -> 3.1756599 | AD30: =IF(AND(R30>0,Z30>0),Z30/(R30),0) -> 1.5402533 | AE30: =IF(AND(S30>0,AA30>0),AA30/(S30),0) -> 3.4492911 | AF30: ='22'!I46 -> 38351.7 | AG30: =AF30+AG29 -> 312137.36 | AH30: =IF(AND(L30>0,AF30>0),(AF30/(P30*1000)*1000),0) -> 1047.6603 | AI30: =IF(AND(M30>0,AG30>0),(AG30/(Q30*1000)*1000),0) -> 1484.3398 | AJ30: =IF(AND(R30>0,AF30>0),(AF30/(R30*1000)*1000),0) -> 1116.6604 | AK30: =IF(AND(S30>0,AG30>0),(AG30/(S30*1000)*1000),0) -> 1612.2381 | AL30: 4464.8 | AM30: 5314.3 | AN30: 4167.4 | AO30: =SUM(AL30:AN30) -> 13946.5 | AP30: =+[1]Nov!N25 -> 13873 | AQ30: =+AP30-AO30 -> -73.5 | AR30: =+AL30/AO30 -> 0.32013767 | AS30: =+AM30/AO30 -> 0.38104901 | AT30: =1-AR30-AS30 -> 0.29881332 | AU30: =+AR30*AQ30 -> -23.530119 | AV30: =+AS30*AQ30 -> -28.007102 | AW30: =+AT30*AQ30 -> -21.962779 | AX30: =+AL30+AU30 -> 4441.2699 | AY30: =+AM30+AV30 -> 5286.2929 | AZ30: =+AN30+AW30 -> 4145.4372 | BA30: =+SUM(Efficiency2!K127:K128) -> 41.321647 | BB30: =BB29+BA30 -> 252.31636 | BC30: =+R30/BA30 -> 0.83116241 | BD30: =+S30/BB30 -> 0.76731052
A31: =A30+1 -> 45984 | B31: Facial/Toilet | C31: 13/14/14 | D31: =+'23'!F42 -> 1129.0278 | E31: =+'23'!G42 -> 869.35139 | F31: =1-(E31/D31) -> 0.23 | G31: =+P31/N31 -> 0.92331201 | H31: =+P31/L31 -> 0.8457258 | I31: =+R31/P31 -> 0.96684074 | J31: =+R31/L31 -> 0.81768216 | K31: =+S31/M31 -> 0.23205715 | L31: =+SUM(Efficiency1!K132:K134) -> 45.96407 | M31: =M30+L31 -> 996.25892 | N31: =+SUM(Efficiency1!C132:C134) -> 42.101694 | O31: =O30+N31 -> 964.35872 | P31: ='23'!I38 -> 38.873 | Q31: =Q30+P31 -> 249.16 | R31: ='23'!I40 -> 37.584 | S31: =S30+R31 -> 231.189 | T31: =+AX31 -> 4443.1239 | U31: =T31+U30 -> 30151.868 | V31: =T31/P31 -> 114.29846 | W31: =U31/Q31 -> 121.01408 | X31: =IF(AND(R31>0,T31>0),(T31/(R31*1000))*1000,0) -> 118.2185 | Y31: =IF(AND(S31>0,U31>0),U31/S31,0) -> 130.42086 | Z31: 55.5 | AA31: =Z31+AA30 -> 723.3 | AB31: =Z31/(P31) -> 1.4277262 | AC31: =AA31/(Q31) -> 2.9029539 | AD31: =IF(AND(R31>0,Z31>0),Z31/(R31),0) -> 1.4766922 | AE31: =IF(AND(S31>0,AA31>0),AA31/(S31),0) -> 3.1286091 | AF31: ='23'!I46 -> 38161.6 | AG31: =AF31+AG30 -> 350298.96 | AH31: =IF(AND(L31>0,AF31>0),(AF31/(P31*1000)*1000),0) -> 981.69938 | AI31: =IF(AND(M31>0,AG31>0),(AG31/(Q31*1000)*1000),0) -> 1405.9197 | AJ31: =IF(AND(R31>0,AF31>0),(AF31/(R31*1000)*1000),0) -> 1015.3682 | AK31: =IF(AND(S31>0,AG31>0),(AG31/(S31*1000)*1000),0) -> 1515.206 | AL31: 4956.6 | AM31: 5365.5 | AN31: 3552.2 | AO31: =SUM(AL31:AN31) -> 13874.3 | AP31: =+[1]Nov!N26 -> 12437 | AQ31: =+AP31-AO31 -> -1437.3 | AR31: =+AL31/AO31 -> 0.35725046 | AS31: =+AM31/AO31 -> 0.38672221 | AT31: =1-AR31-AS31 -> 0.25602733 | AU31: =+AR31*AQ31 -> -513.47608 | AV31: =+AS31*AQ31 -> -555.83584 | AW31: =+AT31*AQ31 -> -367.98808 | AX31: =+AL31+AU31 -> 4443.1239 | AY31: =+AM31+AV31 -> 4809.6642 | AZ31: =+AN31+AW31 -> 3184.2119 | BA31: =+SUM(Efficiency2!K132:K134) -> 45.96407 | BB31: =BB30+BA31 -> 298.28043 | BC31: =+R31/BA31 -> 0.81768216 | BD31: =+S31/BB31 -> 0.77507263
A32: =A31+1 -> 45985 | B32: Toilet | C32: 14 | D32: =+'24'!F42 -> 1062.583 | E32: =+'24'!G42 -> 818.18893 | F32: =1-(E32/D32) -> 0.23 | G32: =+P32/N32 -> 0.88900211 | H32: =+P32/L32 -> 0.76799883 | I32: =+R32/P32 -> 0.93857135 | J32: =+R32/L32 -> 0.7208217 | K32: =+S32/M32 -> 0.25500098 | L32: =+Efficiency1!K136 -> 49.070388 | M32: =M31+L32 -> 1045.3293 | N32: =+Efficiency1!C136 -> 42.39135 | O32: =O31+N32 -> 1006.7501 | P32: ='24'!I38 -> 37.686 | Q32: =Q31+P32 -> 286.846 | R32: ='24'!I40 -> 35.371 | S32: =S31+R32 -> 266.56 | T32: =+AX32 -> 4859.2857 | U32: =T32+U31 -> 35011.154 | V32: =T32/P32 -> 128.9414 | W32: =U32/Q32 -> 122.05558 | X32: =IF(AND(R32>0,T32>0),(T32/(R32*1000))*1000,0) -> 137.3805 | Y32: =IF(AND(S32>0,U32>0),U32/S32,0) -> 131.34436 | Z32: 53.5 | AA32: =Z32+AA31 -> 776.8 | AB32: =Z32/(P32) -> 1.4196253 | AC32: =AA32/(Q32) -> 2.7080733 | AD32: =IF(AND(R32>0,Z32>0),Z32/(R32),0) -> 1.5125385 | AE32: =IF(AND(S32>0,AA32>0),AA32/(S32),0) -> 2.9141657 | AF32: =+'24'!I46 -> 36251.68 | AG32: =AF32+AG31 -> 386550.64 | AH32: =IF(AND(L32>0,AF32>0),(AF32/(P32*1000)*1000),0) -> 961.94024 | AI32: =IF(AND(M32>0,AG32>0),(AG32/(Q32*1000)*1000),0) -> 1347.5894 | AJ32: =IF(AND(R32>0,AF32>0),(AF32/(R32*1000)*1000),0) -> 1024.8984 | AK32: =IF(AND(S32>0,AG32>0),(AG32/(S32*1000)*1000),0) -> 1450.145 | AL32: 5092.2 | AM32: 5382.6 | AN32: 4092.5 | AO32: =SUM(AL32:AN32) -> 14567.3 | AP32: =+[1]Nov!N27 -> 13901 | AQ32: =+AP32-AO32 -> -666.3 | AR32: =+AL32/AO32 -> 0.34956375 | AS32: =+AM32/AO32 -> 0.36949881 | AT32: =1-AR32-AS32 -> 0.28093744 | AU32: =+AR32*AQ32 -> -232.91433 | AV32: =+AS32*AQ32 -> -246.19706 | AW32: =+AT32*AQ32 -> -187.18862 | AX32: =+AL32+AU32 -> 4859.2857 | AY32: =+AM32+AV32 -> 5136.4029 | AZ32: =+AN32+AW32 -> 3905.3114 | BA32: =+Efficiency2!K136 -> 49.070388 | BB32: =BB31+BA32 -> 347.35082 | BC32: =+R32/BA32 -> 0.7208217 | BD32: =+S32/BB32 -> 0.76740858
A33: =A32+1 -> 45986 | B33: Toilet | C33: 14/15 | D33: =+'25'!F42 -> 1049.9097 | E33: =+'25'!G42 -> 808.43049 | F33: =1-(E33/D33) -> 0.23 | G33: =+P33/N33 -> 0.92703585 | H33: =+P33/L33 -> 0.79943778 | I33: =+R33/P33 -> 0.94743454 | J33: =+R33/L33 -> 0.75741497 | K33: =+S33/M33 -> 0.27827741 | L33: =+SUM(Efficiency1!K141:K142) -> 50.781938 | M33: =M32+L33 -> 1096.1112 | N33: =+SUM(Efficiency1!C141:C142) -> 43.792265 | O33: =O32+N33 -> 1050.5423 | P33: ='25'!I38 -> 40.597 | Q33: =Q32+P33 -> 327.443 | R33: ='25'!I40 -> 38.463 | S33: =S32+R33 -> 305.023 | T33: =+AX33 -> 4979.4702 | U33: =T33+U32 -> 39990.624 | V33: =T33/P33 -> 122.65611 | W33: =U33/Q33 -> 122.13003 | X33: =IF(AND(R33>0,T33>0),(T33/(R33*1000))*1000,0) -> 129.46131 | Y33: =IF(AND(S33>0,U33>0),U33/S33,0) -> 131.10691 | Z33: 54.4 | AA33: =Z33+AA32 -> 831.2 | AB33: =Z33/(P33) -> 1.3400005 | AC33: =AA33/(Q33) -> 2.5384571 | AD33: =IF(AND(R33>0,Z33>0),Z33/(R33),0) -> 1.4143463 | AE33: =IF(AND(S33>0,AA33>0),AA33/(S33),0) -> 2.7250404 | AF33: =+'25'!I46 -> 35326.64 | AG33: =AF33+AG32 -> 421877.28 | AH33: =IF(AND(L33>0,AF33>0),(AF33/(P33*1000)*1000),0) -> 870.17858 | AI33: =IF(AND(M33>0,AG33>0),(AG33/(Q33*1000)*1000),0) -> 1288.3991 | AJ33: =IF(AND(R33>0,AF33>0),(AF33/(R33*1000)*1000),0) -> 918.45774 | AK33: =IF(AND(S33>0,AG33>0),(AG33/(S33*1000)*1000),0) -> 1383.0999 | AL33: 5279.5 | AM33: 5256.3 | AN33: 4111.6 | AO33: =SUM(AL33:AN33) -> 14647.4 | AP33: =+[1]Nov!N28 -> 13815 | AQ33: =+AP33-AO33 -> -832.4 | AR33: =+AL33/AO33 -> 0.3604394 | AS33: =+AM33/AO33 -> 0.3588555 | AT33: =1-AR33-AS33 -> 0.28070511 | AU33: =+AR33*AQ33 -> -300.02975 | AV33: =+AS33*AQ33 -> -298.71132 | AW33: =+AT33*AQ33 -> -233.65893 | AX33: =+AL33+AU33 -> 4979.4702 | AY33: =+AM33+AV33 -> 4957.5887 | AZ33: =+AN33+AW33 -> 3877.9411 | BA33: =+SUM(Efficiency2!K141:K142) -> 50.781938 | BB33: =BB32+BA33 -> 398.13276 | BC33: =+R33/BA33 -> 0.75741497 | BD33: =+S33/BB33 -> 0.76613389
A34: =A33+1 -> 45987 | B34: Toilet | C34: 15 | D34: =+'26'!F42 -> 1109.5139 | E34: =+'26'!G42 -> 854.32569 | F34: =1-(E34/D34) -> 0.23 | G34: =+P34/N34 -> 0.88372554 | H34: =+P34/L34 -> 0.81033534 | I34: =+R34/P34 -> 0.91224576 | J34: =+R34/L34 -> 0.73922498 | K34: =+S34/M34 -> 0.29940915 | L34: =+Efficiency1!K146 -> 52.664617 | M34: =M33+L34 -> 1148.7759 | N34: =+Efficiency1!C146 -> 48.291011 | O34: =O33+N34 -> 1098.8333 | P34: ='26'!I38 -> 42.676 | Q34: =Q33+P34 -> 370.119 | R34: ='26'!I40 -> 38.931 | S34: =S33+R34 -> 343.954 | T34: =+AX34 -> 5206.9112 | U34: =T34+U33 -> 45197.535 | V34: =T34/P34 -> 122.01029 | W34: =U34/Q34 -> 122.11622 | X34: =IF(AND(R34>0,T34>0),(T34/(R34*1000))*1000,0) -> 133.74717 | Y34: =IF(AND(S34>0,U34>0),U34/S34,0) -> 131.40575 | Z34: 54.8 | AA34: =Z34+AA33 -> 886 | AB34: =Z34/(P34) -> 1.2840941 | AC34: =AA34/(Q34) -> 2.3938247 | AD34: =IF(AND(R34>0,Z34>0),Z34/(R34),0) -> 1.4076186 | AE34: =IF(AND(S34>0,AA34>0),AA34/(S34),0) -> 2.5759259 | AF34: ='26'!I46 -> 37294.46 | AG34: =AF34+AG33 -> 459171.74 | AH34: =IF(AND(L34>0,AF34>0),(AF34/(P34*1000)*1000),0) -> 873.89774 | AI34: =IF(AND(M34>0,AG34>0),(AG34/(Q34*1000)*1000),0) -> 1240.6057 | AJ34: =IF(AND(R34>0,AF34>0),(AF34/(R34*1000)*1000),0) -> 957.96306 | AK34: =IF(AND(S34>0,AG34>0),(AG34/(S34*1000)*1000),0) -> 1334.9801 | AL34: 5530 | AM34: 5420.7 | AN34: 3918 | AO34: =SUM(AL34:AN34) -> 14868.7 | AP34: =+[1]Nov!N29 -> 14000 | AQ34: =+AP34-AO34 -> -868.7 | AR34: =+AL34/AO34 -> 0.37192223 | AS34: =+AM34/AO34 -> 0.36457121 | AT34: =1-AR34-AS34 -> 0.26350656 | AU34: =+AR34*AQ34 -> -323.08884 | AV34: =+AS34*AQ34 -> -316.70301 | AW34: =+AT34*AQ34 -> -228.90815 | AX34: =+AL34+AU34 -> 5206.9112 | AY34: =+AM34+AV34 -> 5103.997 | AZ34: =+AN34+AW34 -> 3689.0919 | BA34: =+Efficiency2!K146 -> 52.664617 | BB34: =BB33+BA34 -> 450.79738 | BC34: =+R34/BA34 -> 0.73922498 | BD34: =+S34/BB34 -> 0.76299024
A35: =A34+1 -> 45988 | B35: Toilet/Facial | C35: 15/12 | D35: =+'27'!F42 -> 1119.3681 | E35: =+'27'!G42 -> 861.9134 | F35: =1-(E35/D35) -> 0.23 | G35: =+P35/N35 -> 0.93717976 | H35: =+P35/L35 -> 0.85324075 | I35: =+R35/P35 -> 0.99149917 | J35: =+R35/L35 -> 0.8459875 | K35: =+S35/M35 -> 0.31968468 | L35: =+SUM(Efficiency1!K150:K151) -> 44.255973 | M35: =M34+L35 -> 1193.0318 | N35: =+SUM(Efficiency1!C150:C151) -> 40.292163 | O35: =O34+N35 -> 1139.1255 | P35: ='27'!I38 -> 37.761 | Q35: =Q34+P35 -> 407.88 | R35: ='27'!I40 -> 37.44 | S35: =S34+R35 -> 381.394 | T35: =+AX35 -> 4682.5869 | U35: =T35+U34 -> 49880.122 | V35: =T35/P35 -> 124.0059 | W35: =U35/Q35 -> 122.29117 | X35: =IF(AND(R35>0,T35>0),(T35/(R35*1000))*1000,0) -> 125.06909 | Y35: =IF(AND(S35>0,U35>0),U35/S35,0) -> 130.78371 | Z35: 54.1 | AA35: =Z35+AA34 -> 940.1 | AB35: =Z35/(P35) -> 1.4326951 | AC35: =AA35/(Q35) -> 2.3048446 | AD35: =IF(AND(R35>0,Z35>0),Z35/(R35),0) -> 1.4449786 | AE35: =IF(AND(S35>0,AA35>0),AA35/(S35),0) -> 2.4649051 | AF35: ='27'!I46 -> 39197.78 | AG35: =AF35+AG34 -> 498369.52 | AH35: =IF(AND(L35>0,AF35>0),(AF35/(P35*1000)*1000),0) -> 1038.0493 | AI35: =IF(AND(M35>0,AG35>0),(AG35/(Q35*1000)*1000),0) -> 1221.8533 | AJ35: =IF(AND(R35>0,AF35>0),(AF35/(R35*1000)*1000),0) -> 1046.9493 | AK35: =IF(AND(S35>0,AG35>0),(AG35/(S35*1000)*1000),0) -> 1306.7052 | AL35: 4918 | AM35: 4775.7 | AN35: 3906.3 | AO35: =SUM(AL35:AN35) -> 13600 | AP35: =+[1]Nov!N30 -> 12949 | AQ35: =+AP35-AO35 -> -651 | AR35: =+AL35/AO35 -> 0.36161765 | AS35: =+AM35/AO35 -> 0.35115441 | AT35: =1-AR35-AS35 -> 0.28722794 | AU35: =+AR35*AQ35 -> -235.41309 | AV35: =+AS35*AQ35 -> -228.60152 | AW35: =+AT35*AQ35 -> -186.98539 | AX35: =+AL35+AU35 -> 4682.5869 | AY35: =+AM35+AV35 -> 4547.0985 | AZ35: =+AN35+AW35 -> 3719.3146 | BA35: =+SUM(Efficiency2!K150:K151) -> 44.255973 | BB35: =BB34+BA35 -> 495.05335 | BC35: =+R35/BA35 -> 0.8459875 | BD35: =+S35/BB35 -> 0.7704099
A36: =A35+1 -> 45989 | B36: Facial | C36: 12/13 | D36: =+'28'!F42 -> 1227.5377 | E36: =+'28'!G42 -> 945.03625 | F36: =1-(E36/D36) -> 0.23013667 | G36: =+P36/N36 -> 0.93147428 | H36: =+P36/L36 -> 0.92960791 | I36: =+R36/P36 -> 0.95574075 | J36: =+R36/L36 -> 0.88846416 | K36: =+S36/M36 -> 0.33992288 | L36: =+SUM(Efficiency1!K154:K155) -> 44.016407 | M36: =M35+L36 -> 1237.0482 | N36: =+SUM(Efficiency1!C154:C155) -> 43.928213 | O36: =O35+N36 -> 1183.0537 | P36: ='28'!I38 -> 40.918 | Q36: =Q35+P36 -> 448.798 | R36: ='28'!I40 -> 39.107 | S36: =S35+R36 -> 420.501 | T36: =+AX36 -> 4964.5645 | U36: =T36+U35 -> 54844.686 | V36: =T36/P36 -> 121.3296 | W36: =U36/Q36 -> 122.2035 | X36: =IF(AND(R36>0,T36>0),(T36/(R36*1000))*1000,0) -> 126.94823 | Y36: =IF(AND(S36>0,U36>0),U36/S36,0) -> 130.42701 | Z36: 52.8 | AA36: =Z36+AA35 -> 992.9 | AB36: =Z36/(P36) -> 1.2903856 | AC36: =AA36/(Q36) -> 2.2123539 | AD36: =IF(AND(R36>0,Z36>0),Z36/(R36),0) -> 1.3501419 | AE36: =IF(AND(S36>0,AA36>0),AA36/(S36),0) -> 2.361231 | AF36: ='28'!I46 -> 40060.8 | AG36: =AF36+AG35 -> 538430.32 | AH36: =IF(AND(L36>0,AF36>0),(AF36/(P36*1000)*1000),0) -> 979.05078 | AI36: =IF(AND(M36>0,AG36>0),(AG36/(Q36*1000)*1000),0) -> 1199.7164 | AJ36: =IF(AND(R36>0,AF36>0),(AF36/(R36*1000)*1000),0) -> 1024.3895 | AK36: =IF(AND(S36>0,AG36>0),(AG36/(S36*1000)*1000),0) -> 1280.4496 | AL36: 5276 | AM36: 5229.6 | AN36: 3943.3 | AO36: =SUM(AL36:AN36) -> 14448.9 | AP36: =+[1]Nov!N31 -> 13596 | AQ36: =+AP36-AO36 -> -852.9 | AR36: =+AL36/AO36 -> 0.3651489 | AS36: =+AM36/AO36 -> 0.36193759 | AT36: =1-AR36-AS36 -> 0.27291351 | AU36: =+AR36*AQ36 -> -311.4355 | AV36: =+AS36*AQ36 -> -308.69657 | AW36: =+AT36*AQ36 -> -232.76793 | AX36: =+AL36+AU36 -> 4964.5645 | AY36: =+AM36+AV36 -> 4920.9034 | AZ36: =+AN36+AW36 -> 3710.5321 | BA36: =+SUM(Efficiency2!K154:K155) -> 44.016407 | BB36: =BB35+BA36 -> 539.06976 | BC36: =+R36/BA36 -> 0.88846416 | BD36: =+S36/BB36 -> 0.78004932
A37: =A36+1 -> 45990 | B37: Facial | C37: 12/14 | D37: =+'29'!F42 -> 1137.8472 | E37: =+'29'!G42 -> 866.94125 | F37: =1-(E37/D37) -> 0.23808642 | G37: =+P37/N37 -> 0.94029404 | H37: =+P37/L37 -> 0.86833602 | I37: =+R37/P37 -> 0.9308992 | J37: =+R37/L37 -> 0.80833331 | K37: =+S37/M37 -> 0.35736587 | L37: =+SUM(Efficiency1!K159:K160) -> 47.847836 | M37: =M36+L37 -> 1284.8961 | N37: =+SUM(Efficiency1!C159:C160) -> 44.186178 | O37: =O36+N37 -> 1227.2399 | P37: ='29'!I38 -> 41.548 | Q37: =Q36+P37 -> 490.346 | R37: ='29'!I40 -> 38.677 | S37: =S36+R37 -> 459.178 | T37: =+AX37 -> 4287.5898 | U37: =T37+U36 -> 59132.276 | V37: =T37/P37 -> 103.19606 | W37: =U37/Q37 -> 120.59296 | X37: =IF(AND(R37>0,T37>0),(T37/(R37*1000))*1000,0) -> 110.85632 | Y37: =IF(AND(S37>0,U37>0),U37/S37,0) -> 128.77855 | Z37: 50.3 | AA37: =Z37+AA36 -> 1043.2 | AB37: =Z37/(P37) -> 1.2106479 | AC37: =AA37/(Q37) -> 2.1274773 | AD37: =IF(AND(R37>0,Z37>0),Z37/(R37),0) -> 1.3005145 | AE37: =IF(AND(S37>0,AA37>0),AA37/(S37),0) -> 2.2718858 | AF37: ='29'!I46 -> 36711.22 | AG37: =AF37+AG36 -> 575141.54 | AH37: =IF(AND(L37>0,AF37>0),(AF37/(P37*1000)*1000),0) -> 883.58573 | AI37: =IF(AND(M37>0,AG37>0),(AG37/(Q37*1000)*1000),0) -> 1172.93 | AJ37: =IF(AND(R37>0,AF37>0),(AF37/(R37*1000)*1000),0) -> 949.17444 | AK37: =IF(AND(S37>0,AG37>0),(AG37/(S37*1000)*1000),0) -> 1252.5459 | AL37: 4802.6 | AM37: 5410.3 | AN37: 4019.3 | AO37: =SUM(AL37:AN37) -> 14232.2 | AP37: =+[1]Nov!N32 -> 12706 | AQ37: =+AP37-AO37 -> -1526.2 | AR37: =+AL37/AO37 -> 0.33744607 | AS37: =+AM37/AO37 -> 0.38014502 | AT37: =1-AR37-AS37 -> 0.2824089 | AU37: =+AR37*AQ37 -> -515.0102 | AV37: =+AS37*AQ37 -> -580.17733 | AW37: =+AT37*AQ37 -> -431.01247 | AX37: =+AL37+AU37 -> 4287.5898 | AY37: =+AM37+AV37 -> 4830.1227 | AZ37: =+AN37+AW37 -> 3588.2875 | BA37: =+SUM(Efficiency2!K159:K160) -> 47.847836 | BB37: =BB36+BA37 -> 586.91759 | BC37: =+R37/BA37 -> 0.80833331 | BD37: =+S37/BB37 -> 0.78235515
A38: =A37+1 -> 45991 | B38: Facial | C38: 14 | D38: =+'30'!F42 -> 1120 | E38: =+'30'!G42 -> 851.2 | F38: =1-(E38/D38) -> 0.24 | G38: =+P38/N38 -> 0.95594681 | H38: =+P38/L38 -> 0.87045563 | I38: =+R38/P38 -> 0.96243933 | J38: =+R38/L38 -> 0.83776074 | K38: =+S38/M38 -> 0.3750124 | L38: =+Efficiency1!K163 -> 48.998477 | M38: =M37+L38 -> 1333.8946 | N38: =+Efficiency1!C163 -> 44.616499 | O38: =O37+N38 -> 1271.8564 | P38: ='30'!I38 -> 42.651 | Q38: =Q37+P38 -> 532.997 | R38: ='30'!I40 -> 41.049 | S38: =S37+R38 -> 500.227 | T38: =+AX38 -> 4677.5084 | U38: =T38+U37 -> 63809.785 | V38: =T38/P38 -> 109.66937 | W38: =U38/Q38 -> 119.71884 | X38: =IF(AND(R38>0,T38>0),(T38/(R38*1000))*1000,0) -> 113.94939 | Y38: =IF(AND(S38>0,U38>0),U38/S38,0) -> 127.56166 | Z38: 52.1 | AA38: =Z38+AA37 -> 1095.3 | AB38: =Z38/(P38) -> 1.2215423 | AC38: =AA38/(Q38) -> 2.0549834 | AD38: =IF(AND(R38>0,Z38>0),Z38/(R38),0) -> 1.2692148 | AE38: =IF(AND(S38>0,AA38>0),AA38/(S38),0) -> 2.1896059 | AF38: ='30'!I46 -> 37716.6 | AG38: =AF38+AG37 -> 612858.14 | AH38: =IF(AND(L38>0,AF38>0),(AF38/(P38*1000)*1000),0) -> 884.30752 | AI38: =IF(AND(M38>0,AG38>0),(AG38/(Q38*1000)*1000),0) -> 1149.8341 | AJ38: =IF(AND(R38>0,AF38>0),(AF38/(R38*1000)*1000),0) -> 918.81897 | AK38: =IF(AND(S38>0,AG38>0),(AG38/(S38*1000)*1000),0) -> 1225.1601 | AL38: 4903.3 | AM38: 5226 | AN38: 3973.1 | AO38: =SUM(AL38:AN38) -> 14102.4 | AP38: =+[1]Nov!N33 -> 13453 | AQ38: =+AP38-AO38 -> -649.4 | AR38: =+AL38/AO38 -> 0.34769259 | AS38: =+AM38/AO38 -> 0.37057522 | AT38: =1-AR38-AS38 -> 0.28173219 | AU38: =+AR38*AQ38 -> -225.79157 | AV38: =+AS38*AQ38 -> -240.65155 | AW38: =+AT38*AQ38 -> -182.95688 | AX38: =+AL38+AU38 -> 4677.5084 | AY38: =+AM38+AV38 -> 4985.3485 | AZ38: =+AN38+AW38 -> 3790.1431 | BA38: =+Efficiency2!K163 -> 48.998477 | BB38: =BB37+BA38 -> 635.91607 | BC38: =+R38/BA38 -> 0.83776074 | BD38: =+S38/BB38 -> 0.78662425
A39: =A38+1 -> 45992 | D39: =+'31'!F42 -> 0 | E39: =+'31'!G42 -> 0 | F39: =1-(E39/D39) -> #DIV/0! | G39: =+P39/N39 -> #DIV/0! | H39: =+P39/L39 -> #DIV/0! | I39: =+R39/P39 -> #DIV/0! | J39: =+R39/L39 -> #DIV/0! | K39: =+S39/M39 -> 0.3750124 | M39: =M38+L39 -> 1333.8946 | O39: =O38+N39 -> 1271.8564 | P39: ='31'!I38 -> 0 | Q39: =Q38+P39 -> 532.997 | R39: ='31'!I40 -> 0 | S39: =S38+R39 -> 500.227 | U39: =T39+U38 -> 63809.785 | V39: =T39/P39 -> #DIV/0! | W39: =U39/Q39 -> 119.71884 | X39: =IF(AND(R39>0,T39>0),(T39/(R39*1000))*1000,0) -> 0 | Y39: =IF(AND(S39>0,U39>0),U39/S39,0) -> 127.56166 | AA39: =Z39+AA38 -> 1095.3 | AB39: =Z39/(P39) -> #DIV/0! | AC39: =AA39/(Q39) -> 2.0549834 | AD39: =IF(AND(R39>0,Z39>0),Z39/(R39),0) -> 0 | AE39: =IF(AND(S39>0,AA39>0),AA39/(S39),0) -> 2.1896059 | AF39: ='31'!I46 -> 0 | AG39: =AF39+AG38 -> 612858.14 | AH39: =IF(AND(L39>0,AF39>0),(AF39/(P39*1000)*1000),0) -> 0 | AI39: =IF(AND(M39>0,AG39>0),(AG39/(Q39*1000)*1000),0) -> 1149.8341 | AJ39: =IF(AND(R39>0,AF39>0),(AF39/(R39*1000)*1000),0) -> 0 | AK39: =IF(AND(S39>0,AG39>0),(AG39/(S39*1000)*1000),0) -> 1225.1601 | AO39: =SUM(AL39:AN39) -> 0 | AQ39: =+AP39-AO39 -> 0 | AR39: =+AL39/AO39 -> #DIV/0! | AS39: =+AM39/AO39 -> #DIV/0! | AT39: =1-AR39-AS39 -> #DIV/0! | AU39: =+AR39*AQ39 -> #DIV/0! | AV39: =+AS39*AQ39 -> #DIV/0! | AW39: =+AT39*AQ39 -> #DIV/0! | AX39: =+AL39+AU39 -> #DIV/0! | AY39: =+AM39+AV39 -> #DIV/0! | AZ39: =+AN39+AW39 -> #DIV/0! | BB39: =BB38+BA39 -> 635.91607 | BC39: =+R39/BA39 -> #DIV/0! | BD39: =+S39/BB39 -> 0.78662425
G41: =+P41/N41 -> 0.41907011 | H41: =+P41/L41 -> 0.39957956 | I41: =+R41/P41 -> 0.93851748 | J41: =+R41/L41 -> 0.3750124 | L41: =SUM(L9:L39) -> 1333.8946 | N41: =SUM(N9:N39) -> 1271.8564 | P41: =SUM(P9:P39) -> 532.997 | R41: =SUM(R9:R39) -> 500.227 | T41: =SUM(T9:T39) -> 63809.785 | V41: =T41/P41 -> 119.71884 | X41: =IF(AND(R41>0,T41>0),(T41/(R41*1000))*1000,0) -> 127.56166 | Z41: =SUM(Z9:Z40) -> 1095.3 | AB41: =Z41/P41 -> 2.0549834 | AD41: =Z41/R41 -> 2.1896059 | AF41: =SUM(AF9:AF39) -> 612858.14 | AH41: =AF41/P41 -> 1149.8341 | AJ41: =AF41/R41 -> 1225.1601 | AP41: =SUM(AP9:AP40) -> 326186 | AX41: =SUM(AX9:AX39) -> #DIV/0! | AY41: =SUM(AY9:AY39) -> #DIV/0! | AZ41: =SUM(AZ9:AZ39) -> #DIV/0! | BA41: =SUM(BA9:BA39) -> 635.91607 | BC41: =+R41/BA41 -> 0.78662425
AY43: =SUM(AX41:AZ41) -> #DIV/0!

Sheet GRAFIK

Sheet Listrik
A2: MACHINE POWER CONSUMPTION (PER PANEL)
A4: Date | B4: PM (TON) | C4: FINSHED GOODS (TON) | P4: Total PM14
D5: Trafo (2500 A) | H5: Trafo (2500 B) | L5: Trafo (2500 A)
D6: KWH | E6: Consumption | F6: /TON PM | G6: /TON FG | H6: KWH | I6: Consumption | J6: /TON PM | K6: /TON FG | L6: KWH | M6: Consumption | N6: /TON PM | O6: /TON FG | P6: Consumption | Q6: /TON PM | R6: /TON FG
A7: =A8-1 -> 45961 | B7: 0 | C7: 0
A8: =+Report1!A9 -> 45962 | B8: =+Report1!P9 -> 0 | C8: =+Report1!R9 -> 0 | D8: =+D7+E8 -> 300 | E8: =+[3]DailyNov!AH7 -> 300 | F8: =E8/B8 -> #DIV/0! | G8: =E8/C8 -> #DIV/0! | H8: =+H7+I8 -> 30.65 | I8: =+[3]DailyNov!AI7 -> 30.65 | J8: =I8/B8 -> #DIV/0! | K8: =I8/C8 -> #DIV/0! | L8: =+L7+M8 -> 1590.65 | M8: =+[3]DailyNov!AJ7 -> 1590.65 | N8: =M8/B8 -> #DIV/0! | O8: =M8/C8 -> #DIV/0! | P8: =+E8+I8+M8 -> 1921.3 | Q8: =P8/B8 -> #DIV/0! | R8: =P8/C8 -> #DIV/0! | V8: Off Reel | W8: Off Rewinder
A9: 45506 | B9: =+Report1!P10 -> 0 | C9: =+Report1!R10 -> 0 | D9: =+D8+E9 -> 500 | E9: =+[3]DailyNov!AH8 -> 200 | F9: =E9/B9 -> #DIV/0! | G9: =E9/C9 -> #DIV/0! | H9: =+H8+I9 -> 2110.54 | I9: =+[3]DailyNov!AI8 -> 2079.89 | J9: =I9/B9 -> #DIV/0! | K9: =I9/C9 -> #DIV/0! | L9: =+L8+M9 -> 6630.54 | M9: =+[3]DailyNov!AJ8 -> 5039.89 | N9: =M9/B9 -> #DIV/0! | O9: =M9/C9 -> #DIV/0! | P9: =+E9+I9+M9 -> 7319.78 | Q9: =P9/B9 -> #DIV/0! | R9: =P9/C9 -> #DIV/0! | V9: Off Reel | W9: Off Rewinder
A10: 45507 | B10: =+Report1!P11 -> 0 | C10: =+Report1!R11 -> 0 | D10: =+D9+E10 -> 800 | E10: =+[3]DailyNov!AH9 -> 300 | F10: =E10/B10 -> #DIV/0! | G10: =E10/C10 -> #DIV/0! | H10: =+H9+I10 -> 2184.08 | I10: =+[3]DailyNov!AI9 -> 73.54 | J10: =I10/B10 -> #DIV/0! | K10: =I10/C10 -> #DIV/0! | L10: =+L9+M10 -> 9764.08 | M10: =+[3]DailyNov!AJ9 -> 3133.54 | N10: =M10/B10 -> #DIV/0! | O10: =M10/C10 -> #DIV/0! | P10: =+E10+I10+M10 -> 3507.08 | Q10: =P10/B10 -> #DIV/0! | R10: =P10/C10 -> #DIV/0! | V10: Off Reel | W10: Off Rewinder
A11: 45508 | B11: =+Report1!P12 -> 0 | C11: =+Report1!R12 -> 0 | D11: =+D10+E11 -> 1000 | E11: =+[3]DailyNov!AH10 -> 200 | F11: =E11/B11 -> #DIV/0! | G11: =E11/C11 -> #DIV/0! | H11: =+H10+I11 -> 2224.95 | I11: =+[3]DailyNov!AI10 -> 40.87 | J11: =I11/B11 -> #DIV/0! | K11: =I11/C11 -> #DIV/0! | L11: =+L10+M11 -> 12864.95 | M11: =+[3]DailyNov!AJ10 -> 3100.87 | N11: =M11/B11 -> #DIV/0! | O11: =M11/C11 -> #DIV/0! | P11: =+E11+I11+M11 -> 3341.74 | Q11: =P11/B11 -> #DIV/0! | R11: =P11/C11 -> #DIV/0! | V11: Off Reel | W11: Off Rewinder
