Workbook

Sheet Report1
A3: PAPER MACHINE 14 DAILY REPORT 1
A6: Date | B6: Grade | C6: GSM | D6: Speed yankee (mpm) | E6: Speed reel (mpm) | F6: Creep ( % ) | G6: Real Eff PM ( % ) | H6: Real Eff PM vs Target (%) | I6: Real Eff FG vs Real Eff PM (%) | J6: Eff FG vs Target (%) | L6: Kapasitas Target (ton) | N6: Kapasitas Teori Real (ton) | P6: PM PROD Timbangan (TON) | R6: FINSHED GOODS (TON) | T6: GAS HOOD | Z6: STEAM (TON) | AF6: POWER (kWh) | BA6: Kapasitas Running (ton) | BC6: Eff FG vs Target Running(%)
T7: CONSUMPTION | V7: /TON PM. | X7: /TON FG. | Z7: CONSUMPTION | AB7: /TON PM. | AD7: /TON FG. | AF7: CONSUMPTION | AH7: /TON PM | AJ7: /TON FG | AL7: Gas based on report DCS | AO7: total | AP7: Flowmeter | AQ7: Selisih | AR7: % pengali | AU7: Adjust | AX7: PEMAKAIAN GAS
J8: TODAY | K8: TODATE | L8: TODAY | M8: TODATE | N8: TODAY | O8: TODATE | P8: TODAY | Q8: TODATE | R8: TODAY | S8: TODATE | T8: TODAY | U8: TODATE | V8: TODAY | W8: TODATE | X8: TODAY | Y8: TODATE | Z8: TODAY | AA8: TODATE | AB8: TODAY | AC8: TODATE | AD8: TODAY | AE8: TODATE | AF8: TODAY | AG8: TODATE | AH8: TODAY | AI8: TODATE | AJ8: TODAY | AK8: TODATE | AL8: 14 | AM8: 15 | AN8: 17 | AP8: PGN | AU8: 14 | AV8: 15 | AW8: 17 | AX8: 14 | AY8: 15 | AZ8: 17 | BA8: TODAY | BB8: TODATE | BC8: TODAY | BD8: TODATE
A9: 45839 | B9: Toilet/Facial | C9: 12,5/13 | D9: =+'1'!F42 -> 1200.9428 | E9: =+'1'!G42 -> 924.72597 | F9: =1-(E9/D9) -> 0.23 | G9: =+P9/N9 -> 0.85281324 | H9: =+P9/L9 -> 0.82669998 | I9: =+R9/P9 -> 0.9629347 | J9: =+R9/L9 -> 0.7960581 | K9: =+S9/M9 -> 0.7960581 | L9: =+SUM(Efficiency1!K6:K7) -> 44.383695 | M9: =L9 -> 44.383695 | N9: =+SUM(Efficiency1!C6:C7) -> 43.02466 | O9: =N9 -> 43.02466 | P9: ='1'!I38 -> 36.692 | Q9: =P9 -> 36.692 | R9: ='1'!I40 -> 35.332 | S9: =R9 -> 35.332 | T9: =+AX9 -> 3947.4227 | U9: =T9 -> 3947.4227 | V9: =T9/P9 -> 107.58265 | W9: =U9/Q9 -> 107.58265 | X9: =IF(AND(R9>0,T9>0),(T9/(R9*1000))*1000,0) -> 111.72373 | Y9: =IF(AND(S9>0,U9>0),U9/S9,0) -> 111.72373 | Z9: 57.7 | AA9: =Z9 -> 57.7 | AB9: =Z9/(P9) -> 1.5725499 | AC9: =AA9/(Q9) -> 1.5725499 | AD9: =IF(AND(R9>0,Z9>0),Z9/(R9),0) -> 1.6330805 | AE9: =IF(AND(S9>0,AA9>0),AA9/(S9),0) -> 1.6330805 | AF9: ='1'!I46 -> 36445.06 | AG9: =AF9 -> 36445.06 | AH9: =IF(AND(L9>0,AF9>0),(AF9/(P9*1000)*1000),0) -> 993.26992 | AI9: =IF(AND(M9>0,AG9>0),(AG9/(Q9*1000)*1000),0) -> 993.26992 | AJ9: =IF(AND(R9>0,AF9>0),(AF9/(R9*1000)*1000),0) -> 1031.5029 | AK9: =IF(AND(S9>0,AG9>0),(AG9/(S9*1000)*1000),0) -> 1031.5029 | AL9: 4106.3 | AM9: 4519.1 | AN9: 2767.4 | AO9: =SUM(AL9:AN9) -> 11392.8 | AP9: =+[1]Jul!N4 -> 10952 | AQ9: =+AP9-AO9 -> -440.8 | AR9: =+AL9/AO9 -> 0.36042939 | AS9: =+AM9/AO9 -> 0.3966628 | AT9: =1-AR9-AS9 -> 0.2429078 | AU9: =+AR9*AQ9 -> -158.87728 | AV9: =+AS9*AQ9 -> -174.84896 | AW9: =+AT9*AQ9 -> -107.07376 | AX9: =+AL9+AU9 -> 3947.4227 | AY9: =+AM9+AV9 -> 4344.251 | AZ9: =+AN9+AW9 -> 2660.3262 | BA9: =+SUM(Efficiency2!K6:K7) -> 42.010499 | BB9: =BA9 -> 42.010499 | BC9: =+R9/BA9 -> 0.84102785 | BD9: =+S9/BB9 -> 0.84102785
A10: =A9+1 -> 45840 | B10: Facial | C10: 13/12 | D10: =+'2'!F42 -> 1216.7306 | E10: =+'2'!G42 -> 936.88258 | F10: =1-(E10/D10) -> 0.23 | G10: =+P10/N10 -> 0.89628352 | H10: =+P10/L10 -> 0.8762102 | I10: =+R10/P10 -> 0.95528539 | J10: =+R10/L10 -> 0.8370308 | K10: =+S10/M10 -> 0.81659189 | L10: =+SUM(Efficiency1!K12:K13) -> 44.589757 | M10: =M9+L10 -> 88.973452 | N10: =+SUM(Efficiency1!C12:C13) -> 43.591117 | O10: =O9+N10 -> 86.615777 | P10: ='2'!I38 -> 39.07 | Q10: =Q9+P10 -> 75.762 | R10: ='2'!I40 -> 37.323 | S10: =S9+R10 -> 72.655 | T10: =+AX10 -> 3750.9815 | U10: =T10+U9 -> 7698.4042 | V10: =T10/P10 -> 96.006694 | W10: =U10/Q10 -> 101.613 | X10: =IF(AND(R10>0,T10>0),(T10/(R10*1000))*1000,0) -> 100.50054 | Y10: =IF(AND(S10>0,U10>0),U10/S10,0) -> 105.95835 | Z10: 59.3 | AA10: =Z10+AA9 -> 117 | AB10: =Z10/(P10) -> 1.5177886 | AC10: =AA10/(Q10) -> 1.5443098 | AD10: =IF(AND(R10>0,Z10>0),Z10/(R10),0) -> 1.5888326 | AE10: =IF(AND(S10>0,AA10>0),AA10/(S10),0) -> 1.6103503 | AF10: ='2'!I46 -> 34580.4 | AG10: =AF10+AG9 -> 71025.46 | AH10: =IF(AND(L10>0,AF10>0),(AF10/(P10*1000)*1000),0) -> 885.0883 | AI10: =IF(AND(M10>0,AG10>0),(AG10/(Q10*1000)*1000),0) -> 937.48132 | AJ10: =IF(AND(R10>0,AF10>0),(AF10/(R10*1000)*1000),0) -> 926.51716 | AK10: =IF(AND(S10>0,AG10>0),(AG10/(S10*1000)*1000),0) -> 977.57154 | AL10: 4230.4 | AM10: 4280.3 | AN10: 2831.7 | AO10: =SUM(AL10:AN10) -> 11342.4 | AP10: =+[1]Jul!N5 -> 10057 | AQ10: =+AP10-AO10 -> -1285.4 | AR10: =+AL10/AO10 -> 0.37297221 | AS10: =+AM10/AO10 -> 0.37737163 | AT10: =1-AR10-AS10 -> 0.24965616 | AU10: =+AR10*AQ10 -> -479.41848 | AV10: =+AS10*AQ10 -> -485.0735 | AW10: =+AT10*AQ10 -> -320.90802 | AX10: =+AL10+AU10 -> 3750.9815 | AY10: =+AM10+AV10 -> 3795.2265 | AZ10: =+AN10+AW10 -> 2510.792 | BA10: =+SUM(Efficiency1!K12:K13) -> 44.589757 | BB10: =BB9+BA10 -> 86.600256 | BC10: =+R10/BA10 -> 0.8370308 | BD10: =+S10/BB10 -> 0.8389698
A11: =A10+1 -> 45841 | B11: Facial | C11: 12 | D11: =+'3'!F42 -> 1230 | E11: =+'3'!G42 -> 947.1 | F11: =1-(E11/D11) -> 0.23 | G11: =+P11/N11 -> 0.96550133 | H11: =+P11/L11 -> 0.96550133 | I11: =+R11/P11 -> 0.9500191 | J11: =+R11/L11 -> 0.91724471 | K11: =+S11/M11 -> 0.84957779 | L11: =+Efficiency1!K17 -> 43.372286 | M11: =M10+L11 -> 132.34574 | N11: =+Efficiency1!C17 -> 43.372286 | O11: =O10+N11 -> 129.98806 | P11: ='3'!I38 -> 41.876 | Q11: =Q10+P11 -> 117.638 | R11: ='3'!I40 -> 39.783 | S11: =S10+R11 -> 112.438 | T11: =+AX11 -> 4079.1682 | U11: =T11+U10 -> 11777.572 | V11: =T11/P11 -> 97.410645 | W11: =U11/Q11 -> 100.11707 | X11: =IF(AND(R11>0,T11>0),(T11/(R11*1000))*1000,0) -> 102.53546 | Y11: =IF(AND(S11>0,U11>0),U11/S11,0) -> 104.74726 | Z11: 61.4 | AA11: =Z11+AA10 -> 178.4 | AB11: =Z11/(P11) -> 1.4662336 | AC11: =AA11/(Q11) -> 1.5165168 | AD11: =IF(AND(R11>0,Z11>0),Z11/(R11),0) -> 1.5433728 | AE11: =IF(AND(S11>0,AA11>0),AA11/(S11),0) -> 1.5866522 | AF11: ='3'!I46 -> 37132.28 | AG11: =AF11+AG10 -> 108157.74 | AH11: =IF(AND(L11>0,AF11>0),(AF11/(P11*1000)*1000),0) -> 886.71984 | AI11: =IF(AND(M11>0,AG11>0),(AG11/(Q11*1000)*1000),0) -> 919.41158 | AJ11: =IF(AND(R11>0,AF11>0),(AF11/(R11*1000)*1000),0) -> 933.37054 | AK11: =IF(AND(S11>0,AG11>0),(AG11/(S11*1000)*1000),0) -> 961.93226 | AL11: 4353.9 | AM11: 3740.6 | AN11: 3412.6 | AO11: =SUM(AL11:AN11) -> 11507.1 | AP11: =+[1]Jul!N6 -> 10781 | AQ11: =+AP11-AO11 -> -726.1 | AR11: =+AL11/AO11 -> 0.3783664 | AS11: =+AM11/AO11 -> 0.32506887 | AT11: =1-AR11-AS11 -> 0.29656473 | AU11: =+AR11*AQ11 -> -274.73184 | AV11: =+AS11*AQ11 -> -236.03251 | AW11: =+AT11*AQ11 -> -215.33565 | AX11: =+AL11+AU11 -> 4079.1682 | AY11: =+AM11+AV11 -> 3504.5675 | AZ11: =+AN11+AW11 -> 3197.2643 | BA11: =+Efficiency2!K17 -> 43.372286 | BB11: =BB10+BA11 -> 129.97254 | BC11: =+R11/BA11 -> 0.91724471 | BD11: =+S11/BB11 -> 0.86509041
A12: =A11+1 -> 45842 | B12: Facial | C12: 12 | D12: =+'4'!F42 -> 1230 | E12: =+'4'!G42 -> 947.1 | F12: =1-(E12/D12) -> 0.23 | G12: =+P12/N12 -> 0.97263559 | H12: =+P12/L12 -> 0.97263559 | I12: =+R12/P12 -> 0.9897029 | J12: =+R12/L12 -> 0.96262026 | K12: =+S12/M12 -> 0.87755786 | L12: =+Efficiency1!K21 -> 43.533262 | M12: =M11+L12 -> 175.879 | N12: =+Efficiency1!C21 -> 43.533262 | O12: =O11+N12 -> 173.52133 | P12: ='4'!I38 -> 42.342 | Q12: =Q11+P12 -> 159.98 | R12: ='4'!I40 -> 41.906 | S12: =S11+R12 -> 154.344 | T12: =+AX12 -> 4306.327 | U12: =T12+U11 -> 16083.899 | V12: =T12/P12 -> 101.70344 | W12: =U12/Q12 -> 100.53694 | X12: =IF(AND(R12>0,T12>0),(T12/(R12*1000))*1000,0) -> 102.76159 | Y12: =IF(AND(S12>0,U12>0),U12/S12,0) -> 104.20813 | Z12: 62.1 | AA12: =Z12+AA11 -> 240.5 | AB12: =Z12/(P12) -> 1.4666289 | AC12: =AA12/(Q12) -> 1.5033129 | AD12: =IF(AND(R12>0,Z12>0),Z12/(R12),0) -> 1.481888 | AE12: =IF(AND(S12>0,AA12>0),AA12/(S12),0) -> 1.5582076 | AF12: ='4'!I46 -> 38589.9 | AG12: =AF12+AG11 -> 146747.64 | AH12: =IF(AND(L12>0,AF12>0),(AF12/(P12*1000)*1000),0) -> 911.38586 | AI12: =IF(AND(M12>0,AG12>0),(AG12/(Q12*1000)*1000),0) -> 917.28741 | AJ12: =IF(AND(R12>0,AF12>0),(AF12/(R12*1000)*1000),0) -> 920.86813 | AK12: =IF(AND(S12>0,AG12>0),(AG12/(S12*1000)*1000),0) -> 950.78293 | AL12: 4368 | AM12: 1733.2 | AN12: 3623.1 | AO12: =SUM(AL12:AN12) -> 9724.3 | AP12: =+[1]Jul!N7 -> 9587 | AQ12: =+AP12-AO12 -> -137.3 | AR12: =+AL12/AO12 -> 0.449184 | AS12: =+AM12/AO12 -> 0.17823391 | AT12: =1-AR12-AS12 -> 0.37258209 | AU12: =+AR12*AQ12 -> -61.672964 | AV12: =+AS12*AQ12 -> -24.471516 | AW12: =+AT12*AQ12 -> -51.155521 | AX12: =+AL12+AU12 -> 4306.327 | AY12: =+AM12+AV12 -> 1708.7285 | AZ12: =+AN12+AW12 -> 3571.9445 | BA12: =+Efficiency2!K21 -> 43.533262 | BB12: =BB11+BA12 -> 173.5058 | BC12: =+R12/BA12 -> 0.96262026 | BD12: =+S12/BB12 -> 0.88956102
A13: =A12+1 -> 45843 | B13: Facial | C13: 12/12,5/13 | D13: =+'5'!F42 -> 1230 | E13: =+'5'!G42 -> 947.1 | F13: =1-(E13/D13) -> 0.23 | G13: =+P13/N13 -> 0.95649458 | H13: =+P13/L13 -> 0.95163911 | I13: =+R13/P13 -> 0.95503024 | J13: =+R13/L13 -> 0.90884413 | K13: =+S13/M13 -> 0.8839903 | L13: =+SUM(Efficiency1!K25:K27) -> 45.519357 | M13: =M12+L13 -> 221.39836 | N13: =+SUM(Efficiency1!C25:C27) -> 45.288286 | O13: =O12+N13 -> 218.80961 | P13: ='5'!I38 -> 43.318 | Q13: =Q12+P13 -> 203.298 | R13: ='5'!I40 -> 41.37 | S13: =S12+R13 -> 195.714 | T13: =+AX13 -> 4276.7356 | U13: =T13+U12 -> 20360.635 | V13: =T13/P13 -> 98.728833 | W13: =U13/Q13 -> 100.15167 | X13: =IF(AND(R13>0,T13>0),(T13/(R13*1000))*1000,0) -> 103.3777 | Y13: =IF(AND(S13>0,U13>0),U13/S13,0) -> 104.03259 | Z13: 61.7 | AA13: =Z13+AA12 -> 302.2 | AB13: =Z13/(P13) -> 1.4243502 | AC13: =AA13/(Q13) -> 1.4864878 | AD13: =IF(AND(R13>0,Z13>0),Z13/(R13),0) -> 1.4914189 | AE13: =IF(AND(S13>0,AA13>0),AA13/(S13),0) -> 1.5440898 | AF13: ='5'!I46 -> 39792.82 | AG13: =AF13+AG12 -> 186540.46 | AH13: =IF(AND(L13>0,AF13>0),(AF13/(P13*1000)*1000),0) -> 918.6209 | AI13: =IF(AND(M13>0,AG13>0),(AG13/(Q13*1000)*1000),0) -> 917.57155 | AJ13: =IF(AND(R13>0,AF13>0),(AF13/(R13*1000)*1000),0) -> 961.87624 | AK13: =IF(AND(S13>0,AG13>0),(AG13/(S13*1000)*1000),0) -> 953.12783 | AL13: 4484.7 | AM13: 4740.3 | AN13: 3681.5 | AO13: =SUM(AL13:AN13) -> 12906.5 | AP13: =+[1]Jul!N8 -> 12308 | AQ13: =+AP13-AO13 -> -598.5 | AR13: =+AL13/AO13 -> 0.34747608 | AS13: =+AM13/AO13 -> 0.36728005 | AT13: =1-AR13-AS13 -> 0.28524387 | AU13: =+AR13*AQ13 -> -207.96443 | AV13: =+AS13*AQ13 -> -219.81711 | AW13: =+AT13*AQ13 -> -170.71846 | AX13: =+AL13+AU13 -> 4276.7356 | AY13: =+AM13+AV13 -> 4520.4829 | AZ13: =+AN13+AW13 -> 3510.7815 | BA13: =+SUM(Efficiency2!K25:K27) -> 45.519357 | BB13: =BB12+BA13 -> 219.02516 | BC13: =+R13/BA13 -> 0.90884413 | BD13: =+S13/BB13 -> 0.89356857
A14: =A13+1 -> 45844 | B14: Facial | C14: 13 | D14: =+'6'!F42 -> 1230 | E14: =+'6'!G42 -> 947.1 | F14: =1-(E14/D14) -> 0.23 | G14: =+P14/N14 -> 0.93403464 | H14: =+P14/L14 -> 0.93403464 | I14: =+R14/P14 -> 0.97493995 | J14: =+R14/L14 -> 0.91062769 | K14: =+S14/M14 -> 0.88860181 | L14: =+Efficiency1!K29 -> 46.353741 | M14: =M13+L14 -> 267.7521 | N14: =+Efficiency1!C29 -> 46.353741 | O14: =O13+N14 -> 265.16335 | P14: ='6'!I38 -> 43.296 | Q14: =Q13+P14 -> 246.594 | R14: ='6'!I40 -> 42.211 | S14: =S13+R14 -> 237.925 | T14: =+AX14 -> 4134.0052 | U14: =T14+U13 -> 24494.64 | V14: =T14/P14 -> 95.482381 | W14: =U14/Q14 -> 99.331858 | X14: =IF(AND(R14>0,T14>0),(T14/(R14*1000))*1000,0) -> 97.936679 | Y14: =IF(AND(S14>0,U14>0),U14/S14,0) -> 102.9511 | Z14: 63 | AA14: =Z14+AA13 -> 365.2 | AB14: =Z14/(P14) -> 1.4550998 | AC14: =AA14/(Q14) -> 1.4809768 | AD14: =IF(AND(R14>0,Z14>0),Z14/(R14),0) -> 1.492502 | AE14: =IF(AND(S14>0,AA14>0),AA14/(S14),0) -> 1.5349375 | AF14: ='6'!I46 -> 37410.66 | AG14: =AF14+AG13 -> 223951.12 | AH14: =IF(AND(L14>0,AF14>0),(AF14/(P14*1000)*1000),0) -> 864.06735 | AI14: =IF(AND(M14>0,AG14>0),(AG14/(Q14*1000)*1000),0) -> 908.17749 | AJ14: =IF(AND(R14>0,AF14>0),(AF14/(R14*1000)*1000),0) -> 886.27751 | AK14: =IF(AND(S14>0,AG14>0),(AG14/(S14*1000)*1000),0) -> 941.26771 | AL14: 4368.5 | AM14: 4174.6 | AN14: 3873.4 | AO14: =SUM(AL14:AN14) -> 12416.5 | AP14: =+[1]Jul!N9 -> 11750 | AQ14: =+AP14-AO14 -> -666.5 | AR14: =+AL14/AO14 -> 0.35183023 | AS14: =+AM14/AO14 -> 0.33621391 | AT14: =1-AR14-AS14 -> 0.31195587 | AU14: =+AR14*AQ14 -> -234.49485 | AV14: =+AS14*AQ14 -> -224.08657 | AW14: =+AT14*AQ14 -> -207.91858 | AX14: =+AL14+AU14 -> 4134.0052 | AY14: =+AM14+AV14 -> 3950.5134 | AZ14: =+AN14+AW14 -> 3665.4814 | BA14: =+Efficiency2!K29 -> 46.353741 | BB14: =BB13+BA14 -> 265.3789 | BC14: =+R14/BA14 -> 0.91062769 | BD14: =+S14/BB14 -> 0.89654829
A15: =A14+1 -> 45845 | B15: Facial/Toilet | C15: 13/13 | D15: =+'7'!F42 -> 1196.9375 | E15: =+'7'!G42 -> 921.64188 | F15: =1-(E15/D15) -> 0.23 | G15: =+P15/N15 -> 0.94990754 | H15: =+P15/L15 -> 0.9245159 | I15: =+R15/P15 -> 0.95442182 | J15: =+R15/L15 -> 0.88237815 | K15: =+S15/M15 -> 0.8876939 | L15: =+SUM(Efficiency1!K33:K34) -> 45.73096 | M15: =M14+L15 -> 313.48306 | N15: =+SUM(Efficiency1!C33:C34) -> 44.508543 | O15: =O14+N15 -> 309.67189 | P15: ='7'!I38 -> 42.279 | Q15: =Q14+P15 -> 288.873 | R15: ='7'!I40 -> 40.352 | S15: =S14+R15 -> 278.277 | T15: =+AX15 -> 4151.3907 | U15: =T15+U14 -> 28646.031 | V15: =T15/P15 -> 98.190372 | W15: =U15/Q15 -> 99.164792 | X15: =IF(AND(R15>0,T15>0),(T15/(R15*1000))*1000,0) -> 102.87943 | Y15: =IF(AND(S15>0,U15>0),U15/S15,0) -> 102.94071 | Z15: 62.3 | AA15: =Z15+AA14 -> 427.5 | AB15: =Z15/(P15) -> 1.4735448 | AC15: =AA15/(Q15) -> 1.4798891 | AD15: =IF(AND(R15>0,Z15>0),Z15/(R15),0) -> 1.5439136 | AE15: =IF(AND(S15>0,AA15>0),AA15/(S15),0) -> 1.5362391 | AF15: ='7'!I46 -> 38100.62 | AG15: =AF15+AG14 -> 262051.74 | AH15: =IF(AND(L15>0,AF15>0),(AF15/(P15*1000)*1000),0) -> 901.17127 | AI15: =IF(AND(M15>0,AG15>0),(AG15/(Q15*1000)*1000),0) -> 907.15207 | AJ15: =IF(AND(R15>0,AF15>0),(AF15/(R15*1000)*1000),0) -> 944.20648 | AK15: =IF(AND(S15>0,AG15>0),(AG15/(S15*1000)*1000),0) -> 941.69385 | AL15: 4358.1 | AM15: 4068.7 | AN15: 3984.9 | AO15: =SUM(AL15:AN15) -> 12411.7 | AP15: =+[1]Jul!N10 -> 11823 | AQ15: =+AP15-AO15 -> -588.7 | AR15: =+AL15/AO15 -> 0.35112837 | AS15: =+AM15/AO15 -> 0.32781166 | AT15: =1-AR15-AS15 -> 0.32105997 | AU15: =+AR15*AQ15 -> -206.70927 | AV15: =+AS15*AQ15 -> -192.98273 | AW15: =+AT15*AQ15 -> -189.008 | AX15: =+AL15+AU15 -> 4151.3907 | AY15: =+AM15+AV15 -> 3875.7173 | AZ15: =+AN15+AW15 -> 3795.892 | BA15: =+SUM(Efficiency2!K33:K34) -> 45.73096 | BB15: =BB14+BA15 -> 311.10986 | BC15: =+R15/BA15 -> 0.88237815 | BD15: =+S15/BB15 -> 0.89446538
A16: =A15+1 -> 45846 | B16: Toilet | C16: 13 | D16: =+'8'!F42 -> 1220 | E16: =+'8'!G42 -> 976 | F16: =1-(E16/D16) -> 0.2 | G16: =+P16/N16 -> 0.90207072 | H16: =+P16/L16 -> 0.89473681 | I16: =+R16/P16 -> 0.91519811 | J16: =+R16/L16 -> 0.81886143 | K16: =+S16/M16 -> 0.87867824 | L16: =+Efficiency1!K37 -> 47.248531 | M16: =M15+L16 -> 360.73159 | N16: =+Efficiency1!C37 -> 46.864397 | O16: =O15+N16 -> 356.53629 | P16: ='8'!I38 -> 42.275 | Q16: =Q15+P16 -> 331.148 | R16: ='8'!I40 -> 38.69 | S16: =S15+R16 -> 316.967 | T16: =+AX16 -> 4353.7087 | U16: =T16+U15 -> 32999.74 | V16: =T16/P16 -> 102.98542 | W16: =U16/Q16 -> 99.652541 | X16: =IF(AND(R16>0,T16>0),(T16/(R16*1000))*1000,0) -> 112.52801 | Y16: =IF(AND(S16>0,U16>0),U16/S16,0) -> 104.11096 | Z16: 62.9 | AA16: =Z16+AA15 -> 490.4 | AB16: =Z16/(P16) -> 1.487877 | AC16: =AA16/(Q16) -> 1.4809088 | AD16: =IF(AND(R16>0,Z16>0),Z16/(R16),0) -> 1.6257431 | AE16: =IF(AND(S16>0,AA16>0),AA16/(S16),0) -> 1.5471642 | AF16: ='8'!I46 -> 36718.62 | AG16: =AF16+AG15 -> 298770.36 | AH16: =IF(AND(L16>0,AF16>0),(AF16/(P16*1000)*1000),0) -> 868.56582 | AI16: =IF(AND(M16>0,AG16>0),(AG16/(Q16*1000)*1000),0) -> 902.22607 | AJ16: =IF(AND(R16>0,AF16>0),(AF16/(R16*1000)*1000),0) -> 949.04678 | AK16: =IF(AND(S16>0,AG16>0),(AG16/(S16*1000)*1000),0) -> 942.59137 | AL16: 4555.2 | AM16: 4321.8 | AN16: 3907.5 | AO16: =SUM(AL16:AN16) -> 12784.5 | AP16: =+[1]Jul!N11 -> 12219 | AQ16: =+AP16-AO16 -> -565.5 | AR16: =+AL16/AO16 -> 0.35630646 | AS16: =+AM16/AO16 -> 0.33804998 | AT16: =1-AR16-AS16 -> 0.30564355 | AU16: =+AR16*AQ16 -> -201.49131 | AV16: =+AS16*AQ16 -> -191.16727 | AW16: =+AT16*AQ16 -> -172.84143 | AX16: =+AL16+AU16 -> 4353.7087 | AY16: =+AM16+AV16 -> 4130.6327 | AZ16: =+AN16+AW16 -> 3734.6586 | BA16: =+Efficiency2!K37 -> 47.248531 | BB16: =BB15+BA16 -> 358.35839 | BC16: =+R16/BA16 -> 0.81886143 | BD16: =+S16/BB16 -> 0.88449721
A17: =A16+1 -> 45847 | B17: Toilet | C17: 13 | D17: =+'9'!F42 -> 1210 | E17: =+'9'!G42 -> 931.7 | F17: =1-(E17/D17) -> 0.23 | G17: =+P17/N17 -> 1.0022317 | H17: =+P17/L17 -> 0.98593528 | I17: =+R17/P17 -> 1.027939 | J17: =+R17/L17 -> 1.0134814 | K17: =+S17/M17 -> 0.89354809 | L17: =+Efficiency1!K41 -> 44.725045 | M17: =M16+L17 -> 405.45664 | N17: =+Efficiency1!C41 -> 43.997809 | O17: =O16+N17 -> 400.5341 | P17: ='9'!I38 -> 44.096 | Q17: =Q16+P17 -> 375.244 | R17: ='9'!I40 -> 45.328 | S17: =S16+R17 -> 362.295 | T17: =+AX17 -> 4492.3171 | U17: =T17+U16 -> 37492.057 | V17: =T17/P17 -> 101.87584 | W17: =U17/Q17 -> 99.913807 | X17: =IF(AND(R17>0,T17>0),(T17/(R17*1000))*1000,0) -> 99.10689 | Y17: =IF(AND(S17>0,U17>0),U17/S17,0) -> 103.48489 | Z17: 62.3 | AA17: =Z17+AA16 -> 552.7 | AB17: =Z17/(P17) -> 1.4128266 | AC17: =AA17/(Q17) -> 1.4729083 | AD17: =IF(AND(R17>0,Z17>0),Z17/(R17),0) -> 1.3744264 | AE17: =IF(AND(S17>0,AA17>0),AA17/(S17),0) -> 1.5255524 | AF17: ='9'!I46 -> 36803.46 | AG17: =AF17+AG16 -> 335573.82 | AH17: =IF(AND(L17>0,AF17>0),(AF17/(P17*1000)*1000),0) -> 834.62128 | AI17: =IF(AND(M17>0,AG17>0),(AG17/(Q17*1000)*1000),0) -> 894.28164 | AJ17: =IF(AND(R17>0,AF17>0),(AF17/(R17*1000)*1000),0) -> 811.93655 | AK17: =IF(AND(S17>0,AG17>0),(AG17/(S17*1000)*1000),0) -> 926.24469 | AL17: 4750.3 | AM17: 4562.5 | AN17: 3791.9 | AO17: =SUM(AL17:AN17) -> 13104.7 | AP17: =+[1]Jul!N12 -> 12393 | AQ17: =+AP17-AO17 -> -711.7 | AR17: =+AL17/AO17 -> 0.36248827 | AS17: =+AM17/AO17 -> 0.34815753 | AT17: =1-AR17-AS17 -> 0.2893542 | AU17: =+AR17*AQ17 -> -257.9829 | AV17: =+AS17*AQ17 -> -247.78372 | AW17: =+AT17*AQ17 -> -205.93338 | AX17: =+AL17+AU17 -> 4492.3171 | AY17: =+AM17+AV17 -> 4314.7163 | AZ17: =+AN17+AW17 -> 3585.9666 | BA17: =+Efficiency2!K41 -> 44.725045 | BB17: =BB16+BA17 -> 403.08344 | BC17: =+R17/BA17 -> 1.0134814 | BD17: =+S17/BB17 -> 0.89880894
A18: =A17+1 -> 45848 | B18: Toilet | C18: 13 | D18: =+'10'!F42 -> 1187.125 | E18: =+'10'!G42 -> 926.08625 | F18: =1-(E18/D18) -> 0.21989154 | G18: =+P18/N18 -> 0.94671419 | H18: =+P18/L18 -> 0.91371389 | I18: =+R18/P18 -> 1.0348151 | J18: =+R18/L18 -> 0.94552493 | K18: =+S18/M18 -> 0.89884313 | L18: =+Efficiency1!K45 -> 45.990326 | M18: =M17+L18 -> 451.44696 | N18: =+Efficiency1!C45 -> 44.387208 | O18: =O17+N18 -> 444.92131 | P18: ='10'!I38 -> 42.022 | Q18: =Q17+P18 -> 417.266 | R18: ='10'!I40 -> 43.485 | S18: =S17+R18 -> 405.78 | T18: =+AX18 -> 4345.6713 | U18: =T18+U17 -> 41837.728 | V18: =T18/P18 -> 103.4142 | W18: =U18/Q18 -> 100.26632 | X18: =IF(AND(R18>0,T18>0),(T18/(R18*1000))*1000,0) -> 99.934951 | Y18: =IF(AND(S18>0,U18>0),U18/S18,0) -> 103.10446 | Z18: 65.5 | AA18: =Z18+AA17 -> 618.2 | AB18: =Z18/(P18) -> 1.5587073 | AC18: =AA18/(Q18) -> 1.4815489 | AD18: =IF(AND(R18>0,Z18>0),Z18/(R18),0) -> 1.5062665 | AE18: =IF(AND(S18>0,AA18>0),AA18/(S18),0) -> 1.5234856 | AF18: ='10'!I46 -> 36389.82 | AG18: =AF18+AG17 -> 371963.64 | AH18: =IF(AND(L18>0,AF18>0),(AF18/(P18*1000)*1000),0) -> 865.97068 | AI18: =IF(AND(M18>0,AG18>0),(AG18/(Q18*1000)*1000),0) -> 891.4305 | AJ18: =IF(AND(R18>0,AF18>0),(AF18/(R18*1000)*1000),0) -> 836.83615 | AK18: =IF(AND(S18>0,AG18>0),(AG18/(S18*1000)*1000),0) -> 916.66332 | AL18: 4567.5 | AM18: 4709.7 | AN18: 3937.6 | AO18: =SUM(AL18:AN18) -> 13214.8 | AP18: =+[1]Jul!N13 -> 12573 | AQ18: =+AP18-AO18 -> -641.8 | AR18: =+AL18/AO18 -> 0.3456352 | AS18: =+AM18/AO18 -> 0.35639586 | AT18: =1-AR18-AS18 -> 0.29796894 | AU18: =+AR18*AQ18 -> -221.82867 | AV18: =+AS18*AQ18 -> -228.73486 | AW18: =+AT18*AQ18 -> -191.23647 | AX18: =+AL18+AU18 -> 4345.6713 | AY18: =+AM18+AV18 -> 4480.9651 | AZ18: =+AN18+AW18 -> 3746.3635 | BA18: =+Efficiency2!K45 -> 45.990326 | BB18: =BB17+BA18 -> 449.07377 | BC18: =+R18/BA18 -> 0.94552493 | BD18: =+S18/BB18 -> 0.9035932
A19: =A18+1 -> 45849 | B19: Toilet | C19: 13 | D19: =+'11'!F42 -> 1200.6042 | E19: =+'11'!G42 -> 924.46521 | F19: =1-(E19/D19) -> 0.23 | G19: =+P19/N19 -> 0.93868282 | H19: =+P19/L19 -> 0.91624919 | I19: =+R19/P19 -> 1.0331189 | J19: =+R19/L19 -> 0.94659439 | K19: =+S19/M19 -> 0.90321316 | L19: =+Efficiency1!K49 -> 45.476711 | M19: =M18+L19 -> 496.92367 | N19: =+Efficiency1!C49 -> 44.389861 | O19: =O18+N19 -> 489.31117 | P19: ='11'!I38 -> 41.668 | Q19: =Q18+P19 -> 458.934 | R19: ='11'!I40 -> 43.048 | S19: =S18+R19 -> 448.828 | T19: =+AX19 -> 4442.0066 | U19: =T19+U18 -> 46279.735 | V19: =T19/P19 -> 106.60475 | W19: =U19/Q19 -> 100.84181 | X19: =IF(AND(R19>0,T19>0),(T19/(R19*1000))*1000,0) -> 103.18729 | Y19: =IF(AND(S19>0,U19>0),U19/S19,0) -> 103.11241 | Z19: 66.6 | AA19: =Z19+AA18 -> 684.8 | AB19: =Z19/(P19) -> 1.5983489 | AC19: =AA19/(Q19) -> 1.4921536 | AD19: =IF(AND(R19>0,Z19>0),Z19/(R19),0) -> 1.5471102 | AE19: =IF(AND(S19>0,AA19>0),AA19/(S19),0) -> 1.5257515 | AF19: ='11'!I46 -> 37610.1 | AG19: =AF19+AG18 -> 409573.74 | AH19: =IF(AND(L19>0,AF19>0),(AF19/(P19*1000)*1000),0) -> 902.61352 | AI19: =IF(AND(M19>0,AG19>0),(AG19/(Q19*1000)*1000),0) -> 892.44584 | AJ19: =IF(AND(R19>0,AF19>0),(AF19/(R19*1000)*1000),0) -> 873.67822 | AK19: =IF(AND(S19>0,AG19>0),(AG19/(S19*1000)*1000),0) -> 912.54053 | AL19: 4660 | AM19: 4924.2 | AN19: 3975.1 | AO19: =SUM(AL19:AN19) -> 13559.3 | AP19: =+[1]Jul!N14 -> 12925 | AQ19: =+AP19-AO19 -> -634.3 | AR19: =+AL19/AO19 -> 0.34367556 | AS19: =+AM19/AO19 -> 0.36316034 | AT19: =1-AR19-AS19 -> 0.2931641 | AU19: =+AR19*AQ19 -> -217.99341 | AV19: =+AS19*AQ19 -> -230.3526 | AW19: =+AT19*AQ19 -> -185.95399 | AX19: =+AL19+AU19 -> 4442.0066 | AY19: =+AM19+AV19 -> 4693.8474 | AZ19: =+AN19+AW19 -> 3789.146 | BA19: =+Efficiency1!K49 -> 45.476711 | BB19: =BB18+BA19 -> 494.55048 | BC19: =+R19/BA19 -> 0.94659439 | BD19: =+S19/BB19 -> 0.9075474
A20: =A19+1 -> 45850 | B20: Toilet | C20: 13 | D20: =+'12'!F42 -> 1200 | E20: =+'12'!G42 -> 932 | F20: =1-(E20/D20) -> 0.22333333 | G20: =+P20/N20 -> 1.0431792 | H20: =+P20/L20 -> 1.0177358 | I20: =+R20/P20 -> 0.93222517 | J20: =+R20/L20 -> 0.94875897 | K20: =+S20/M20 -> 0.90706214 | L20: =+Efficiency1!K53 -> 45.870449 | M20: =M19+L20 -> 542.79412 | N20: =+Efficiency1!C53 -> 44.751658 | O20: =O19+N20 -> 534.06283 | P20: ='12'!I38 -> 46.684 | Q20: =Q19+P20 -> 505.618 | R20: ='12'!I40 -> 43.52 | S20: =S19+R20 -> 492.348 | T20: =+AX20 -> 4270.4265 | U20: =T20+U19 -> 50550.161 | V20: =T20/P20 -> 91.475162 | W20: =U20/Q20 -> 99.976981 | X20: =IF(AND(R20>0,T20>0),(T20/(R20*1000))*1000,0) -> 98.125608 | Y20: =IF(AND(S20>0,U20>0),U20/S20,0) -> 102.67161 | Z20: 66.9 | AA20: =Z20+AA19 -> 751.7 | AB20: =Z20/(P20) -> 1.4330392 | AC20: =AA20/(Q20) -> 1.4866955 | AD20: =IF(AND(R20>0,Z20>0),Z20/(R20),0) -> 1.5372243 | AE20: =IF(AND(S20>0,AA20>0),AA20/(S20),0) -> 1.5267656 | AF20: ='12'!I46 -> 37292.42 | AG20: =AF20+AG19 -> 446866.16 | AH20: =IF(AND(L20>0,AF20>0),(AF20/(P20*1000)*1000),0) -> 798.82658 | AI20: =IF(AND(M20>0,AG20>0),(AG20/(Q20*1000)*1000),0) -> 883.80192 | AJ20: =IF(AND(R20>0,AF20>0),(AF20/(R20*1000)*1000),0) -> 856.90303 | AK20: =IF(AND(S20>0,AG20>0),(AG20/(S20*1000)*1000),0) -> 907.62258 | AL20: 4613.2 | AM20: 4892.6 | AN20: 4098 | AO20: =SUM(AL20:AN20) -> 13603.8 | AP20: =+[1]Jul!N15 -> 12593 | AQ20: =+AP20-AO20 -> -1010.8 | AR20: =+AL20/AO20 -> 0.33911113 | AS20: =+AM20/AO20 -> 0.35964951 | AT20: =1-AR20-AS20 -> 0.30123936 | AU20: =+AR20*AQ20 -> -342.77353 | AV20: =+AS20*AQ20 -> -363.53372 | AW20: =+AT20*AQ20 -> -304.49274 | AX20: =+AL20+AU20 -> 4270.4265 | AY20: =+AM20+AV20 -> 4529.0663 | AZ20: =+AN20+AW20 -> 3793.5073 | BA20: =+Efficiency2!K53 -> 45.870449 | BB20: =BB19+BA20 -> 540.42093 | BC20: =+R20/BA20 -> 0.94875897 | BD20: =+S20/BB20 -> 0.9110454
A21: =A20+1 -> 45851 | B21: Toilet | C21: 13/11,5 | D21: =+'13'!F42 -> 1225.5765 | E21: =+'13'!G42 -> 945.68335 | F21: =1-(E21/D21) -> 0.22837672 | G21: =+P21/N21 -> 0.9245531 | H21: =+P21/L21 -> 0.9214304 | I21: =+R21/P21 -> 0.97315962 | J21: =+R21/L21 -> 0.89669886 | K21: =+S21/M21 -> 0.90627991 | L21: =+SUM(Efficiency1!K57:K58) -> 44.315881 | M21: =M20+L21 -> 587.11 | N21: =+SUM(Efficiency1!C57:C58) -> 44.166203 | O21: =O20+N21 -> 578.22903 | P21: ='13'!I38 -> 40.834 | Q21: =Q20+P21 -> 546.452 | R21: ='13'!I40 -> 39.738 | S21: =S20+R21 -> 532.086 | T21: =+AX21 -> 3965.377 | U21: =T21+U20 -> 54515.538 | V21: =T21/P21 -> 97.109687 | W21: =U21/Q21 -> 99.76272 | X21: =IF(AND(R21>0,T21>0),(T21/(R21*1000))*1000,0) -> 99.788036 | Y21: =IF(AND(S21>0,U21>0),U21/S21,0) -> 102.45625 | Z21: 60.5 | AA21: =Z21+AA20 -> 812.2 | AB21: =Z21/(P21) -> 1.4816085 | AC21: =AA21/(Q21) -> 1.4863154 | AD21: =IF(AND(R21>0,Z21>0),Z21/(R21),0) -> 1.5224722 | AE21: =IF(AND(S21>0,AA21>0),AA21/(S21),0) -> 1.526445 | AF21: ='13'!I46 -> 34840.26 | AG21: =AF21+AG20 -> 481706.42 | AH21: =IF(AND(L21>0,AF21>0),(AF21/(P21*1000)*1000),0) -> 853.21693 | AI21: =IF(AND(M21>0,AG21>0),(AG21/(Q21*1000)*1000),0) -> 881.51644 | AJ21: =IF(AND(R21>0,AF21>0),(AF21/(R21*1000)*1000),0) -> 876.74921 | AK21: =IF(AND(S21>0,AG21>0),(AG21/(S21*1000)*1000),0) -> 905.31685 | AL21: 4139.7 | AM21: 4901.5 | AN21: 4114.8 | AO21: =SUM(AL21:AN21) -> 13156 | AP21: =+[1]Jul!N16 -> 12602 | AQ21: =+AP21-AO21 -> -554 | AR21: =+AL21/AO21 -> 0.31466251 | AS21: =+AM21/AO21 -> 0.37256765 | AT21: =1-AR21-AS21 -> 0.31276984 | AU21: =+AR21*AQ21 -> -174.32303 | AV21: =+AS21*AQ21 -> -206.40248 | AW21: =+AT21*AQ21 -> -173.27449 | AX21: =+AL21+AU21 -> 3965.377 | AY21: =+AM21+AV21 -> 4695.0975 | AZ21: =+AN21+AW21 -> 3941.5255 | BA21: =+SUM(Efficiency2!K57:K58) -> 44.315881 | BB21: =BB20+BA21 -> 584.73681 | BC21: =+R21/BA21 -> 0.89669886 | BD21: =+S21/BB21 -> 0.90995811
A22: =A21+1 -> 45852 | B22: Facial | C22: 12 | D22: =+'14'!F42 -> 967.5226 | E22: =+'14'!G42 -> 744.99241 | F22: =1-(E22/D22) -> 0.23 | G22: =+P22/N22 -> 0.36059475 | H22: =+P22/L22 -> 0.28364518 | I22: =+R22/P22 -> 0.86240687 | J22: =+R22/L22 -> 0.24461755 | K22: =+S22/M22 -> 0.8606054 | L22: =+Efficiency1!K62 -> 43.533262 | M22: =M21+L22 -> 630.64326 | N22: =+Efficiency1!C62 -> 34.243427 | O22: =O21+N22 -> 612.47246 | P22: ='14'!I38 -> 12.348 | Q22: =Q21+P22 -> 558.8 | R22: ='14'!I40 -> 10.649 | S22: =S21+R22 -> 542.735 | T22: =+AX22 -> 1533.3189 | U22: =T22+U21 -> 56048.857 | V22: =T22/P22 -> 124.17549 | W22: =U22/Q22 -> 100.30218 | X22: =IF(AND(R22>0,T22>0),(T22/(R22*1000))*1000,0) -> 143.98713 | Y22: =IF(AND(S22>0,U22>0),U22/S22,0) -> 103.27113 | Z22: 28.3 | AA22: =Z22+AA21 -> 840.5 | AB22: =Z22/(P22) -> 2.2918691 | AC22: =AA22/(Q22) -> 1.504116 | AD22: =IF(AND(R22>0,Z22>0),Z22/(R22),0) -> 2.6575265 | AE22: =IF(AND(S22>0,AA22>0),AA22/(S22),0) -> 1.5486379 | AF22: ='14'!I46 -> 16139.64 | AG22: =AF22+AG21 -> 497846.06 | AH22: =IF(AND(L22>0,AF22>0),(AF22/(P22*1000)*1000),0) -> 1307.0651 | AI22: =IF(AND(M22>0,AG22>0),(AG22/(Q22*1000)*1000),0) -> 890.91994 | AJ22: =IF(AND(R22>0,AF22>0),(AF22/(R22*1000)*1000),0) -> 1515.6015 | AK22: =IF(AND(S22>0,AG22>0),(AG22/(S22*1000)*1000),0) -> 917.29124 | AL22: 1590.4 | AM22: 4915.1 | AN22: 4043.1 | AO22: =SUM(AL22:AN22) -> 10548.6 | AP22: =+[1]Jul!N17 -> 10170 | AQ22: =+AP22-AO22 -> -378.6 | AR22: =+AL22/AO22 -> 0.15076882 | AS22: =+AM22/AO22 -> 0.46594809 | AT22: =1-AR22-AS22 -> 0.38328309 | AU22: =+AR22*AQ22 -> -57.081076 | AV22: =+AS22*AQ22 -> -176.40795 | AW22: =+AT22*AQ22 -> -145.11098 | AX22: =+AL22+AU22 -> 1533.3189 | AY22: =+AM22+AV22 -> 4738.6921 | AZ22: =+AN22+AW22 -> 3897.989 | BA22: =+Efficiency2!K62 -> 43.533262 | BB22: =BB21+BA22 -> 628.27007 | BC22: =+R22/BA22 -> 0.24461755 | BD22: =+S22/BB22 -> 0.86385621
A23: =A22+1 -> 45853 | B23: Facial | C23: 12/13 | D23: =+'15'!F42 -> 1146.8611 | E23: =+'15'!G42 -> 883.08306 | F23: =1-(E23/D23) -> 0.23 | G23: =+P23/N23 -> 0.99295494 | H23: =+P23/L23 -> 0.91500073 | I23: =+R23/P23 -> 0.93511867 | J23: =+R23/L23 -> 0.85563427 | K23: =+S23/M23 -> 0.86026052 | L23: =+SUM(Efficiency1!K67:K68) -> 47.013077 | M23: =M22+L23 -> 677.65634 | N23: =+SUM(Efficiency1!C67:C68) -> 43.322208 | O23: =O22+N23 -> 655.79467 | P23: ='15'!I38 -> 43.017 | Q23: =Q22+P23 -> 601.817 | R23: ='15'!I40 -> 40.226 | S23: =S22+R23 -> 582.961 | T23: =+AX23 -> 4134.2351 | U23: =T23+U22 -> 60183.092 | V23: =T23/P23 -> 96.107007 | W23: =U23/Q23 -> 100.00231 | X23: =IF(AND(R23>0,T23>0),(T23/(R23*1000))*1000,0) -> 102.7752 | Y23: =IF(AND(S23>0,U23>0),U23/S23,0) -> 103.23691 | Z23: 60.6 | AA23: =Z23+AA22 -> 901.1 | AB23: =Z23/(P23) -> 1.4087454 | AC23: =AA23/(Q23) -> 1.497299 | AD23: =IF(AND(R23>0,Z23>0),Z23/(R23),0) -> 1.5064883 | AE23: =IF(AND(S23>0,AA23>0),AA23/(S23),0) -> 1.5457295 | AF23: ='15'!I46 -> 36531.46 | AG23: =AF23+AG22 -> 534377.52 | AH23: =IF(AND(L23>0,AF23>0),(AF23/(P23*1000)*1000),0) -> 849.23309 | AI23: =IF(AND(M23>0,AG23>0),(AG23/(Q23*1000)*1000),0) -> 887.94022 | AJ23: =IF(AND(R23>0,AF23>0),(AF23/(R23*1000)*1000),0) -> 908.15542 | AK23: =IF(AND(S23>0,AG23>0),(AG23/(S23*1000)*1000),0) -> 916.66084 | AL23: 4372.1 | AM23: 5394.7 | AN23: 3972.7 | AO23: =SUM(AL23:AN23) -> 13739.5 | AP23: =+[1]Jul!N18 -> 12992 | AQ23: =+AP23-AO23 -> -747.5 | AR23: =+AL23/AO23 -> 0.31821391 | AS23: =+AM23/AO23 -> 0.39264165 | AT23: =1-AR23-AS23 -> 0.28914444 | AU23: =+AR23*AQ23 -> -237.8649 | AV23: =+AS23*AQ23 -> -293.49964 | AW23: =+AT23*AQ23 -> -216.13547 | AX23: =+AL23+AU23 -> 4134.2351 | AY23: =+AM23+AV23 -> 5101.2004 | AZ23: =+AN23+AW23 -> 3756.5645 | BA23: =+SUM(Efficiency2!K67:K68) -> 47.013077 | BB23: =BB22+BA23 -> 675.28315 | BC23: =+R23/BA23 -> 0.85563427 | BD23: =+S23/BB23 -> 0.8632838
A24: =A23+1 -> 45854 | B24: Facial | C24: 13 | D24: =+'16'!F42 -> 1230 | E24: =+'16'!G42 -> 947.1 | F24: =1-(E24/D24) -> 0.23 | G24: =+P24/N24 -> 0.95549421 | H24: =+P24/L24 -> 0.95549421 | I24: =+R24/P24 -> 0.98654987 | J24: =+R24/L24 -> 0.94264269 | K24: =+S24/M24 -> 0.86544602 | L24: =+Efficiency1!K71 -> 45.519899 | M24: =M23+L24 -> 723.17624 | N24: =+Efficiency1!C71 -> 45.519899 | O24: =O23+N24 -> 701.31456 | P24: ='16'!I38 -> 43.494 | Q24: =Q23+P24 -> 645.311 | R24: ='16'!I40 -> 42.909 | S24: =S23+R24 -> 625.87 | T24: =+AX24 -> 4221.3948 | U24: =T24+U23 -> 64404.487 | V24: =T24/P24 -> 97.056947 | W24: =U24/Q24 -> 99.803795 | X24: =IF(AND(R24>0,T24>0),(T24/(R24*1000))*1000,0) -> 98.380173 | Y24: =IF(AND(S24>0,U24>0),U24/S24,0) -> 102.90394 | Z24: 60.2 | AA24: =Z24+AA23 -> 961.3 | AB24: =Z24/(P24) -> 1.384099 | AC24: =AA24/(Q24) -> 1.4896693 | AD24: =IF(AND(R24>0,Z24>0),Z24/(R24),0) -> 1.4029691 | AE24: =IF(AND(S24>0,AA24>0),AA24/(S24),0) -> 1.535942 | AF24: ='16'!I46 -> 37673.26 | AG24: =AF24+AG23 -> 572050.78 | AH24: =IF(AND(L24>0,AF24>0),(AF24/(P24*1000)*1000),0) -> 866.17143 | AI24: =IF(AND(M24>0,AG24>0),(AG24/(Q24*1000)*1000),0) -> 886.473 | AJ24: =IF(AND(R24>0,AF24>0),(AF24/(R24*1000)*1000),0) -> 877.98038 | AK24: =IF(AND(S24>0,AG24>0),(AG24/(S24*1000)*1000),0) -> 914.00895 | AL24: 4442.4 | AM24: 5087.9 | AN24: =1317.09+1307.39+1321.66 -> 3946.14 | AO24: =SUM(AL24:AN24) -> 13476.44 | AP24: =+[1]Jul!N19 -> 12806 | AQ24: =+AP24-AO24 -> -670.44 | AR24: =+AL24/AO24 -> 0.32964195 | AS24: =+AM24/AO24 -> 0.37754036 | AT24: =1-AR24-AS24 -> 0.29281769 | AU24: =+AR24*AQ24 -> -221.00515 | AV24: =+AS24*AQ24 -> -253.11816 | AW24: =+AT24*AQ24 -> -196.31669 | AX24: =+AL24+AU24 -> 4221.3948 | AY24: =+AM24+AV24 -> 4834.7818 | AZ24: =+AN24+AW24 -> 3749.8233 | BA24: =+Efficiency2!K71 -> 45.519899 | BB24: =BB23+BA24 -> 720.80305 | BC24: =+R24/BA24 -> 0.94264269 | BD24: =+S24/BB24 -> 0.86829544
A25: =A24+1 -> 45855 | B25: Facial | C25: 13 | D25: =+'17'!F42 -> 1230 | E25: =+'17'!G42 -> 947.1 | F25: =1-(E25/D25) -> 0.23 | G25: =+P25/N25 -> 0.99211331 | H25: =+P25/L25 -> 0.99211331 | I25: =+R25/P25 -> 0.96144317 | J25: =+R25/L25 -> 0.95386057 | K25: =+S25/M25 -> 0.87068659 | L25: =+Efficiency1!K75 -> 45.56536 | M25: =M24+L25 -> 768.7416 | N25: =+Efficiency1!C75 -> 45.56536 | O25: =O24+N25 -> 746.87992 | P25: ='17'!I38 -> 45.206 | Q25: =Q24+P25 -> 690.517 | R25: ='17'!I40 -> 43.463 | S25: =S24+R25 -> 669.333 | T25: =+AX25 -> 4001.3637 | U25: =T25+U24 -> 68405.851 | V25: =T25/P25 -> 88.513997 | W25: =U25/Q25 -> 99.064687 | X25: =IF(AND(R25>0,T25>0),(T25/(R25*1000))*1000,0) -> 92.06368 | Y25: =IF(AND(S25>0,U25>0),U25/S25,0) -> 102.20003 | Z25: 61.9 | AA25: =Z25+AA24 -> 1023.2 | AB25: =Z25/(P25) -> 1.3692873 | AC25: =AA25/(Q25) -> 1.4817883 | AD25: =IF(AND(R25>0,Z25>0),Z25/(R25),0) -> 1.4241999 | AE25: =IF(AND(S25>0,AA25>0),AA25/(S25),0) -> 1.528686 | AF25: ='17'!I46 -> 37665.5 | AG25: =AF25+AG24 -> 609716.28 | AH25: =IF(AND(L25>0,AF25>0),(AF25/(P25*1000)*1000),0) -> 833.19692 | AI25: =IF(AND(M25>0,AG25>0),(AG25/(Q25*1000)*1000),0) -> 882.98518 | AJ25: =IF(AND(R25>0,AF25>0),(AF25/(R25*1000)*1000),0) -> 866.61068 | AK25: =IF(AND(S25>0,AG25>0),(AG25/(S25*1000)*1000),0) -> 910.93115 | AL25: 4224.4 | AM25: 5101.5 | AN25: 3898.3 | AO25: =SUM(AL25:AN25) -> 13224.2 | AP25: =+[1]Jul!N20 -> 12526 | AQ25: =+AP25-AO25 -> -698.2 | AR25: =+AL25/AO25 -> 0.31944465 | AS25: =+AM25/AO25 -> 0.38577003 | AT25: =1-AR25-AS25 -> 0.29478532 | AU25: =+AR25*AQ25 -> -223.03626 | AV25: =+AS25*AQ25 -> -269.34463 | AW25: =+AT25*AQ25 -> -205.81911 | AX25: =+AL25+AU25 -> 4001.3637 | AY25: =+AM25+AV25 -> 4832.1554 | AZ25: =+AN25+AW25 -> 3692.4809 | BA25: =+Efficiency2!K75 -> 45.56536 | BB25: =BB24+BA25 -> 766.36841 | BC25: =+R25/BA25 -> 0.95386057 | BD25: =+S25/BB25 -> 0.87338282
A26: =A25+1 -> 45856 | B26: Facial/Toilet | C26: 13/15 | D26: =+'18'!F42 -> 1206.0417 | E26: =+'18'!G42 -> 928.65208 | F26: =1-(E26/D26) -> 0.23 | G26: =+P26/N26 -> 0.96245898 | H26: =+P26/L26 -> 0.95015601 | I26: =+R26/P26 -> 1.0029733 | J26: =+R26/L26 -> 0.95298114 | K26: =+S26/M26 -> 0.87553627 | L26: =+SUM(Efficiency1!K79:K80) -> 48.139463 | M26: =M25+L26 -> 816.88106 | N26: =+SUM(Efficiency1!C79:C80) -> 47.524104 | O26: =O25+N26 -> 794.40403 | P26: ='18'!I38 -> 45.74 | Q26: =Q25+P26 -> 736.257 | R26: ='18'!I40 -> 45.876 | S26: =S25+R26 -> 715.209 | T26: =+AX26 -> 4256.073 | U26: =T26+U25 -> 72661.924 | V26: =T26/P26 -> 93.049257 | W26: =U26/Q26 -> 98.690978 | X26: =IF(AND(R26>0,T26>0),(T26/(R26*1000))*1000,0) -> 92.773412 | Y26: =IF(AND(S26>0,U26>0),U26/S26,0) -> 101.59537 | Z26: 63.4 | AA26: =Z26+AA25 -> 1086.6 | AB26: =Z26/(P26) -> 1.3860953 | AC26: =AA26/(Q26) -> 1.4758434 | AD26: =IF(AND(R26>0,Z26>0),Z26/(R26),0) -> 1.3819862 | AE26: =IF(AND(S26>0,AA26>0),AA26/(S26),0) -> 1.5192762 | AF26: ='18'!I46 -> 36624.74 | AG26: =AF26+AG25 -> 646341.02 | AH26: =IF(AND(L26>0,AF26>0),(AF26/(P26*1000)*1000),0) -> 800.71578 | AI26: =IF(AND(M26>0,AG26>0),(AG26/(Q26*1000)*1000),0) -> 877.87419 | AJ26: =IF(AND(R26>0,AF26>0),(AF26/(R26*1000)*1000),0) -> 798.34205 | AK26: =IF(AND(S26>0,AG26>0),(AG26/(S26*1000)*1000),0) -> 903.70929 | AL26: 4456.7 | AM26: 5108.2 | AN26: 3958.9 | AO26: =SUM(AL26:AN26) -> 13523.8 | AP26: =+[1]Jul!N21 -> 12915 | AQ26: =+AP26-AO26 -> -608.8 | AR26: =+AL26/AO26 -> 0.32954495 | AS26: =+AM26/AO26 -> 0.37771928 | AT26: =1-AR26-AS26 -> 0.29273577 | AU26: =+AR26*AQ26 -> -200.62697 | AV26: =+AS26*AQ26 -> -229.9555 | AW26: =+AT26*AQ26 -> -178.21754 | AX26: =+AL26+AU26 -> 4256.073 | AY26: =+AM26+AV26 -> 4878.2445 | AZ26: =+AN26+AW26 -> 3780.6825 | BA26: =+SUM(Efficiency2!K79:K80) -> 48.139463 | BB26: =BB25+BA26 -> 814.50787 | BC26: =+R26/BA26 -> 0.95298114 | BD26: =+S26/BB26 -> 0.87808728
A27: =A26+1 -> 45857 | B27: Toilet | C27: 15/12,5 | D27: =+'19'!F42 -> 1191.5972 | E27: =+'19'!G42 -> 922.52431 | F27: =1-(E27/D27) -> 0.22580861 | G27: =+P27/N27 -> 0.98831577 | H27: =+P27/L27 -> 0.96981534 | I27: =+R27/P27 -> 0.99582982 | J27: =+R27/L27 -> 0.96577104 | K27: =+S27/M27 -> 0.88051675 | L27: =+SUM(Efficiency1!K83:K84) -> 47.721456 | M27: =M26+L27 -> 864.60252 | N27: =+SUM(Efficiency1!C83:C84) -> 46.828151 | O27: =O26+N27 -> 841.23218 | P27: ='19'!I38 -> 46.281 | Q27: =Q26+P27 -> 782.538 | R27: ='19'!I40 -> 46.088 | S27: =S26+R27 -> 761.297 | T27: =+AX27 -> 4316.479 | U27: =T27+U26 -> 76978.403 | V27: =T27/P27 -> 93.266762 | W27: =U27/Q27 -> 98.370178 | X27: =IF(AND(R27>0,T27>0),(T27/(R27*1000))*1000,0) -> 93.65733 | Y27: =IF(AND(S27>0,U27>0),U27/S27,0) -> 101.11481 | Z27: 64.1 | AA27: =Z27+AA26 -> 1150.7 | AB27: =Z27/(P27) -> 1.3850176 | AC27: =AA27/(Q27) -> 1.4704717 | AD27: =IF(AND(R27>0,Z27>0),Z27/(R27),0) -> 1.3908176 | AE27: =IF(AND(S27>0,AA27>0),AA27/(S27),0) -> 1.5114995 | AF27: ='19'!I46 -> 39685.12 | AG27: =AF27+AG26 -> 686026.14 | AH27: =IF(AND(L27>0,AF27>0),(AF27/(P27*1000)*1000),0) -> 857.4819 | AI27: =IF(AND(M27>0,AG27>0),(AG27/(Q27*1000)*1000),0) -> 876.66815 | AJ27: =IF(AND(R27>0,AF27>0),(AF27/(R27*1000)*1000),0) -> 861.07273 | AK27: =IF(AND(S27>0,AG27>0),(AG27/(S27*1000)*1000),0) -> 901.12813 | AL27: 4547.3 | AM27: 5105.8 | AN27: 3991.5 | AO27: =SUM(AL27:AN27) -> 13644.6 | AP27: =+[1]Jul!N22 -> 12952 | AQ27: =+AP27-AO27 -> -692.6 | AR27: =+AL27/AO27 -> 0.33326737 | AS27: =+AM27/AO27 -> 0.37419932 | AT27: =1-AR27-AS27 -> 0.29253331 | AU27: =+AR27*AQ27 -> -230.82098 | AV27: =+AS27*AQ27 -> -259.17045 | AW27: =+AT27*AQ27 -> -202.60857 | AX27: =+AL27+AU27 -> 4316.479 | AY27: =+AM27+AV27 -> 4846.6296 | AZ27: =+AN27+AW27 -> 3788.8914 | BA27: =+SUM(Efficiency2!K83:K84) -> 47.721456 | BB27: =BB26+BA27 -> 862.22932 | BC27: =+R27/BA27 -> 0.96577104 | BD27: =+S27/BB27 -> 0.88294028
A28: =A27+1 -> 45858 | B28: Toilet | C28: 12,5 | D28: =+'20'!F42 -> 1230 | E28: =+'20'!G42 -> 947.1 | F28: =1-(E28/D28) -> 0.23 | G28: =+P28/N28 -> 1.0184456 | H28: =+P28/L28 -> 1.0184456 | I28: =+R28/P28 -> 0.99569709 | J28: =+R28/L28 -> 1.0140633 | K28: =+S28/M28 -> 0.8869577 | L28: =+Efficiency1!K87 -> 43.812846 | M28: =M27+L28 -> 908.41537 | N28: =+Efficiency1!C87 -> 43.812846 | O28: =O27+N28 -> 885.04502 | P28: ='20'!I38 -> 44.621 | Q28: =Q27+P28 -> 827.159 | R28: ='20'!I40 -> 44.429 | S28: =S27+R28 -> 805.726 | T28: =+AX28 -> 4210.3931 | U28: =T28+U27 -> 81188.796 | V28: =T28/P28 -> 94.359003 | W28: =U28/Q28 -> 98.153796 | X28: =IF(AND(R28>0,T28>0),(T28/(R28*1000))*1000,0) -> 94.766776 | Y28: =IF(AND(S28>0,U28>0),U28/S28,0) -> 100.76477 | Z28: 60.5 | AA28: =Z28+AA27 -> 1211.2 | AB28: =Z28/(P28) -> 1.3558638 | AC28: =AA28/(Q28) -> 1.4642892 | AD28: =IF(AND(R28>0,Z28>0),Z28/(R28),0) -> 1.3617232 | AE28: =IF(AND(S28>0,AA28>0),AA28/(S28),0) -> 1.5032406 | AF28: ='20'!I46 -> 36051.22 | AG28: =AF28+AG27 -> 722077.36 | AH28: =IF(AND(L28>0,AF28>0),(AF28/(P28*1000)*1000),0) -> 807.9429 | AI28: =IF(AND(M28>0,AG28>0),(AG28/(Q28*1000)*1000),0) -> 872.96077 | AJ28: =IF(AND(R28>0,AF28>0),(AF28/(R28*1000)*1000),0) -> 811.43442 | AK28: =IF(AND(S28>0,AG28>0),(AG28/(S28*1000)*1000),0) -> 896.18228 | AL28: 4404.5 | AM28: 5188.3 | AN28: 4026.4 | AO28: =SUM(AL28:AN28) -> 13619.2 | AP28: =+[1]Jul!N23 -> 13019 | AQ28: =+AP28-AO28 -> -600.2 | AR28: =+AL28/AO28 -> 0.32340372 | AS28: =+AM28/AO28 -> 0.38095483 | AT28: =1-AR28-AS28 -> 0.29564145 | AU28: =+AR28*AQ28 -> -194.10692 | AV28: =+AS28*AQ28 -> -228.64909 | AW28: =+AT28*AQ28 -> -177.444 | AX28: =+AL28+AU28 -> 4210.3931 | AY28: =+AM28+AV28 -> 4959.6509 | AZ28: =+AN28+AW28 -> 3848.956 | BA28: =+Efficiency2!K87 -> 43.812846 | BB28: =BB27+BA28 -> 906.04217 | BC28: =+R28/BA28 -> 1.0140633 | BD28: =+S28/BB28 -> 0.8892809
A29: =A28+1 -> 45859 | B29: Toilet/Facial | C29: 12,5/11,5 | D29: =+'21'!F42 -> 1230 | E29: =+'21'!G42 -> 947.1 | F29: =1-(E29/D29) -> 0.23 | G29: =+P29/N29 -> 0.96282191 | H29: =+P29/L29 -> 0.96282191 | I29: =+R29/P29 -> 0.94758597 | J29: =+R29/L29 -> 0.91235653 | K29: =+S29/M29 -> 0.88807274 | L29: =+SUM(Efficiency1!K91:K92) -> 41.711764 | M29: =M28+L29 -> 950.12713 | N29: =+SUM(Efficiency1!C91:C92) -> 41.711764 | O29: =O28+N29 -> 926.75679 | P29: ='21'!I38 -> 40.161 | Q29: =Q28+P29 -> 867.32 | R29: ='21'!I40 -> 38.056 | S29: =S28+R29 -> 843.782 | T29: =+AX29 -> 3958.8362 | U29: =T29+U28 -> 85147.632 | V29: =T29/P29 -> 98.574145 | W29: =U29/Q29 -> 98.17326 | X29: =IF(AND(R29>0,T29>0),(T29/(R29*1000))*1000,0) -> 104.0266 | Y29: =IF(AND(S29>0,U29>0),U29/S29,0) -> 100.91188 | Z29: 59.8 | AA29: =Z29+AA28 -> 1271 | AB29: =Z29/(P29) -> 1.4890067 | AC29: =AA29/(Q29) -> 1.4654337 | AD29: =IF(AND(R29>0,Z29>0),Z29/(R29),0) -> 1.5713685 | AE29: =IF(AND(S29>0,AA29>0),AA29/(S29),0) -> 1.5063132 | AF29: ='21'!I46 -> 38510.48 | AG29: =AF29+AG28 -> 760587.84 | AH29: =IF(AND(L29>0,AF29>0),(AF29/(P29*1000)*1000),0) -> 958.90242 | AI29: =IF(AND(M29>0,AG29>0),(AG29/(Q29*1000)*1000),0) -> 876.94028 | AJ29: =IF(AND(R29>0,AF29>0),(AF29/(R29*1000)*1000),0) -> 1011.9424 | AK29: =IF(AND(S29>0,AG29>0),(AG29/(S29*1000)*1000),0) -> 901.40325 | AL29: 4163.8 | AM29: 5832.8 | AN29: 3967.8 | AO29: =SUM(AL29:AN29) -> 13964.4 | AP29: =+[1]Jul!N24 -> 13277 | AQ29: =+AP29-AO29 -> -687.4 | AR29: =+AL29/AO29 -> 0.2981725 | AS29: =+AM29/AO29 -> 0.4176907 | AT29: =1-AR29-AS29 -> 0.28413681 | AU29: =+AR29*AQ29 -> -204.96377 | AV29: =+AS29*AQ29 -> -287.12059 | AW29: =+AT29*AQ29 -> -195.31564 | AX29: =+AL29+AU29 -> 3958.8362 | AY29: =+AM29+AV29 -> 5545.6794 | AZ29: =+AN29+AW29 -> 3772.4844 | BA29: =+SUM(Efficiency2!K91:K92) -> 41.711764 | BB29: =BB28+BA29 -> 947.75393 | BC29: =+R29/BA29 -> 0.91235653 | BD29: =+S29/BB29 -> 0.89029649
A30: =A29+1 -> 45860 | B30: Facial | C30: 11,5/14 | D30: =+'22'!F42 -> 1217.0139 | E30: =+'22'!G42 -> 914.29792 | F30: =1-(E30/D30) -> 0.24873666 | G30: =+P30/N30 -> 0.92901482 | H30: =+P30/L30 -> 0.91911453 | I30: =+R30/P30 -> 0.93670225 | J30: =+R30/L30 -> 0.86093665 | K30: =+S30/M30 -> 0.88677022 | L30: =+SUM(Efficiency1!K95:K96) -> 47.904802 | M30: =M29+L30 -> 998.03193 | N30: =+SUM(Efficiency1!C95:C96) -> 47.394292 | O30: =O29+N30 -> 974.15108 | P30: ='22'!I38 -> 44.03 | Q30: =Q29+P30 -> 911.35 | R30: ='22'!I40 -> 41.243 | S30: =S29+R30 -> 885.025 | T30: =+AX30 -> 4123.4521 | U30: =T30+U29 -> 89271.084 | V30: =T30/P30 -> 93.650967 | W30: =U30/Q30 -> 97.954775 | X30: =IF(AND(R30>0,T30>0),(T30/(R30*1000))*1000,0) -> 99.97944 | Y30: =IF(AND(S30>0,U30>0),U30/S30,0) -> 100.86843 | Z30: 62.3 | AA30: =Z30+AA29 -> 1333.3 | AB30: =Z30/(P30) -> 1.4149444 | AC30: =AA30/(Q30) -> 1.4629945 | AD30: =IF(AND(R30>0,Z30>0),Z30/(R30),0) -> 1.5105594 | AE30: =IF(AND(S30>0,AA30>0),AA30/(S30),0) -> 1.5065111 | AF30: ='22'!I46 -> 36024.98 | AG30: =AF30+AG29 -> 796612.82 | AH30: =IF(AND(L30>0,AF30>0),(AF30/(P30*1000)*1000),0) -> 818.19169 | AI30: =IF(AND(M30>0,AG30>0),(AG30/(Q30*1000)*1000),0) -> 874.10196 | AJ30: =IF(AND(R30>0,AF30>0),(AF30/(R30*1000)*1000),0) -> 873.48108 | AK30: =IF(AND(S30>0,AG30>0),(AG30/(S30*1000)*1000),0) -> 900.10205 | AL30: 4343.3 | AM30: 5893.1 | AN30: 3928.6 | AO30: =SUM(AL30:AN30) -> 14165 | AP30: =+[1]Jul!N25 -> 13448 | AQ30: =+AP30-AO30 -> -717 | AR30: =+AL30/AO30 -> 0.30662196 | AS30: =+AM30/AO30 -> 0.41603247 | AT30: =1-AR30-AS30 -> 0.27734557 | AU30: =+AR30*AQ30 -> -219.84794 | AV30: =+AS30*AQ30 -> -298.29528 | AW30: =+AT30*AQ30 -> -198.85677 | AX30: =+AL30+AU30 -> 4123.4521 | AY30: =+AM30+AV30 -> 5594.8047 | AZ30: =+AN30+AW30 -> 3729.7432 | BA30: =+SUM(Efficiency2!K95:K96) -> 47.904802 | BB30: =BB29+BA30 -> 995.65874 | BC30: =+R30/BA30 -> 0.86093665 | BD30: =+S30/BB30 -> 0.88888388
A31: =A30+1 -> 45861 | B31: Facial | C31: 14 | D31: =+'23'!F42 -> 1230 | E31: =+'23'!G42 -> 922.5 | F31: =1-(E31/D31) -> 0.25 | G31: =+P31/N31 -> 0.53830354 | H31: =+P31/L31 -> 0.53830354 | I31: =+R31/P31 -> 1.0159053 | J31: =+R31/L31 -> 0.54686544 | K31: =+S31/M31 -> 0.87106313 | L31: =+Efficiency1!K99 -> 48.35376 | M31: =M30+L31 -> 1046.3857 | N31: =+Efficiency1!C99 -> 48.35376 | O31: =O30+N31 -> 1022.5048 | P31: ='23'!I38 -> 26.029 | Q31: =Q30+P31 -> 937.379 | R31: ='23'!I40 -> 26.443 | S31: =S30+R31 -> 911.468 | T31: =+AX31 -> 2112.7659 | U31: =T31+U30 -> 91383.85 | V31: =T31/P31 -> 81.169691 | W31: =U31/Q31 -> 97.488689 | X31: =IF(AND(R31>0,T31>0),(T31/(R31*1000))*1000,0) -> 79.898873 | Y31: =IF(AND(S31>0,U31>0),U31/S31,0) -> 100.26007 | Z31: 35.8 | AA31: =Z31+AA30 -> 1369.1 | AB31: =Z31/(P31) -> 1.375389 | AC31: =AA31/(Q31) -> 1.4605618 | AD31: =IF(AND(R31>0,Z31>0),Z31/(R31),0) -> 1.3538555 | AE31: =IF(AND(S31>0,AA31>0),AA31/(S31),0) -> 1.5020824 | AF31: ='23'!I46 -> 22313.46 | AG31: =AF31+AG30 -> 818926.28 | AH31: =IF(AND(L31>0,AF31>0),(AF31/(P31*1000)*1000),0) -> 857.25383 | AI31: =IF(AND(M31>0,AG31>0),(AG31/(Q31*1000)*1000),0) -> 873.63412 | AJ31: =IF(AND(R31>0,AF31>0),(AF31/(R31*1000)*1000),0) -> 843.83239 | AK31: =IF(AND(S31>0,AG31>0),(AG31/(S31*1000)*1000),0) -> 898.46959 | AL31: 2293.2 | AM31: 5984 | AN31: 3931.4 | AO31: =SUM(AL31:AN31) -> 12208.6 | AP31: =+[1]Jul!N26 -> 11248 | AQ31: =+AP31-AO31 -> -960.6 | AR31: =+AL31/AO31 -> 0.1878348 | AS31: =+AM31/AO31 -> 0.49014629 | AT31: =1-AR31-AS31 -> 0.3220189 | AU31: =+AR31*AQ31 -> -180.43411 | AV31: =+AS31*AQ31 -> -470.83453 | AW31: =+AT31*AQ31 -> -309.33136 | AX31: =+AL31+AU31 -> 2112.7659 | AY31: =+AM31+AV31 -> 5513.1655 | AZ31: =+AN31+AW31 -> 3622.0686 | BA31: =+Efficiency2!K99 -> 48.35376 | BB31: =BB30+BA31 -> 1044.0125 | BC31: =+R31/BA31 -> 0.54686544 | BD31: =+S31/BB31 -> 0.87304319
A32: =A31+1 -> 45862 | B32: Facial | C32: 14 | D32: =+'24'!F42 -> 1219.5714 | E32: =+'24'!G42 -> 914.67857 | F32: =1-(E32/D32) -> 0.25 | G32: =+P32/N32 -> 0.88205372 | H32: =+P32/L32 -> 0.87457521 | I32: =+R32/P32 -> 0.8750266 | J32: =+R32/L32 -> 0.76527658 | K32: =+S32/M32 -> 0.86639063 | L32: =+Efficiency1!K104 -> 48.35376 | M32: =M31+L32 -> 1094.7395 | N32: =+Efficiency1!C104 -> 47.943792 | O32: =O31+N32 -> 1070.4486 | P32: ='24'!I38 -> 42.289 | Q32: =Q31+P32 -> 979.668 | R32: ='24'!I40 -> 37.004 | S32: =S31+R32 -> 948.472 | T32: =+AX32 -> 4181.3367 | U32: =T32+U31 -> 95565.187 | V32: =T32/P32 -> 98.87528 | W32: =U32/Q32 -> 97.548544 | X32: =IF(AND(R32>0,T32>0),(T32/(R32*1000))*1000,0) -> 112.99688 | Y32: =IF(AND(S32>0,U32>0),U32/S32,0) -> 100.75699 | Z32: 64.6 | AA32: =Z32+AA31 -> 1433.7 | AB32: =Z32/(P32) -> 1.527584 | AC32: =AA32/(Q32) -> 1.463455 | AD32: =IF(AND(R32>0,Z32>0),Z32/(R32),0) -> 1.7457572 | AE32: =IF(AND(S32>0,AA32>0),AA32/(S32),0) -> 1.5115892 | AF32: =+'24'!I46 -> 34295.7 | AG32: =AF32+AG31 -> 853221.98 | AH32: =IF(AND(L32>0,AF32>0),(AF32/(P32*1000)*1000),0) -> 810.98394 | AI32: =IF(AND(M32>0,AG32>0),(AG32/(Q32*1000)*1000),0) -> 870.92972 | AJ32: =IF(AND(R32>0,AF32>0),(AF32/(R32*1000)*1000),0) -> 926.81062 | AK32: =IF(AND(S32>0,AG32>0),(AG32/(S32*1000)*1000),0) -> 899.5753 | AL32: 4255.3 | AM32: 5978.8 | AN32: =1282.16+1270.45+1273.68 -> 3826.29 | AO32: =SUM(AL32:AN32) -> 14060.39 | AP32: =+[1]Jul!N27 -> 13816 | AQ32: =+AP32-AO32 -> -244.39 | AR32: =+AL32/AO32 -> 0.30264452 | AS32: =+AM32/AO32 -> 0.42522291 | AT32: =1-AR32-AS32 -> 0.27213257 | AU32: =+AR32*AQ32 -> -73.963295 | AV32: =+AS32*AQ32 -> -103.92023 | AW32: =+AT32*AQ32 -> -66.506478 | AX32: =+AL32+AU32 -> 4181.3367 | AY32: =+AM32+AV32 -> 5874.8798 | AZ32: =+AN32+AW32 -> 3759.7835 | BA32: =+Efficiency2!K104 -> 48.35376 | BB32: =BB31+BA32 -> 1092.3663 | BC32: =+R32/BA32 -> 0.76527658 | BD32: =+S32/BB32 -> 0.86827288
A33: =A32+1 -> 45863 | B33: Facial | C33: 14 | D33: =+'25'!F42 -> 1208.75 | E33: =+'25'!G42 -> 897.55 | F33: =1-(E33/D33) -> 0.25745605 | G33: =+P33/N33 -> 0.92824082 | H33: =+P33/L33 -> 0.92824082 | I33: =+R33/P33 -> 0.97888711 | J33: =+R33/L33 -> 0.90864298 | K33: =+S33/M33 -> 0.86813159 | L33: =+SUM(Efficiency1!K109:K110) -> 47.045981 | M33: =M32+L33 -> 1141.7854 | N33: =+SUM(Efficiency1!C109:C110) -> 47.045981 | O33: =O32+N33 -> 1117.4946 | P33: ='25'!I38 -> 43.67 | Q33: =Q32+P33 -> 1023.338 | R33: ='25'!I40 -> 42.748 | S33: =S32+R33 -> 991.22 | T33: =+AX33 -> 4185.9291 | U33: =T33+U32 -> 99751.116 | V33: =T33/P33 -> 95.853655 | W33: =U33/Q33 -> 97.476216 | X33: =IF(AND(R33>0,T33>0),(T33/(R33*1000))*1000,0) -> 97.921051 | Y33: =IF(AND(S33>0,U33>0),U33/S33,0) -> 100.63469 | Z33: 62.9 | AA33: =Z33+AA32 -> 1496.6 | AB33: =Z33/(P33) -> 1.4403481 | AC33: =AA33/(Q33) -> 1.4624689 | AD33: =IF(AND(R33>0,Z33>0),Z33/(R33),0) -> 1.4714139 | AE33: =IF(AND(S33>0,AA33>0),AA33/(S33),0) -> 1.5098565 | AF33: =+'25'!I46 -> 34188.82 | AG33: =AF33+AG32 -> 887410.8 | AH33: =IF(AND(L33>0,AF33>0),(AF33/(P33*1000)*1000),0) -> 782.89031 | AI33: =IF(AND(M33>0,AG33>0),(AG33/(Q33*1000)*1000),0) -> 867.17272 | AJ33: =IF(AND(R33>0,AF33>0),(AF33/(R33*1000)*1000),0) -> 799.7759 | AK33: =IF(AND(S33>0,AG33>0),(AG33/(S33*1000)*1000),0) -> 895.27128 | AL33: 4418.1 | AM33: 5969.4 | AN33: 3924.6 | AO33: =SUM(AL33:AN33) -> 14312.1 | AP33: =+[1]Jul!N28 -> 13560 | AQ33: =+AP33-AO33 -> -752.1 | AR33: =+AL33/AO33 -> 0.30869684 | AS33: =+AM33/AO33 -> 0.41708764 | AT33: =1-AR33-AS33 -> 0.27421552 | AU33: =+AR33*AQ33 -> -232.17089 | AV33: =+AS33*AQ33 -> -313.69161 | AW33: =+AT33*AQ33 -> -206.2375 | AX33: =+AL33+AU33 -> 4185.9291 | AY33: =+AM33+AV33 -> 5655.7084 | AZ33: =+AN33+AW33 -> 3718.3625 | BA33: =+SUM(Efficiency2!K109:K110) -> 47.045981 | BB33: =BB32+BA33 -> 1139.4122 | BC33: =+R33/BA33 -> 0.90864298 | BD33: =+S33/BB33 -> 0.86993975
A34: =A33+1 -> 45864 | B34: Facial | C34: 14 | D34: =+'26'!F42 -> 1203.7639 | E34: =+'26'!G42 -> 920.97292 | F34: =1-(E34/D34) -> 0.23492229 | G34: =+P34/N34 -> 0.92541042 | H34: =+P34/L34 -> 0.90567125 | I34: =+R34/P34 -> 0.99538871 | J34: =+R34/L34 -> 0.90149494 | K34: =+S34/M34 -> 0.86951322 | L34: =+Efficiency1!K113 -> 49.325845 | M34: =M33+L34 -> 1191.1113 | N34: =+Efficiency1!C113 -> 48.273716 | O34: =O33+N34 -> 1165.7683 | P34: ='26'!I38 -> 44.673 | Q34: =Q33+P34 -> 1068.011 | R34: ='26'!I40 -> 44.467 | S34: =S33+R34 -> 1035.687 | T34: =+AX34 -> 4020.2917 | U34: =T34+U33 -> 103771.41 | V34: =T34/P34 -> 89.99377 | W34: =U34/Q34 -> 97.163238 | X34: =IF(AND(R34>0,T34>0),(T34/(R34*1000))*1000,0) -> 90.41068 | Y34: =IF(AND(S34>0,U34>0),U34/S34,0) -> 100.19572 | Z34: 61.7 | AA34: =Z34+AA33 -> 1558.3 | AB34: =Z34/(P34) -> 1.3811474 | AC34: =AA34/(Q34) -> 1.4590674 | AD34: =IF(AND(R34>0,Z34>0),Z34/(R34),0) -> 1.3875458 | AE34: =IF(AND(S34>0,AA34>0),AA34/(S34),0) -> 1.5046052 | AF34: ='26'!I46 -> 36331.34 | AG34: =AF34+AG33 -> 923742.14 | AH34: =IF(AND(L34>0,AF34>0),(AF34/(P34*1000)*1000),0) -> 813.27289 | AI34: =IF(AND(M34>0,AG34>0),(AG34/(Q34*1000)*1000),0) -> 864.91819 | AJ34: =IF(AND(R34>0,AF34>0),(AF34/(R34*1000)*1000),0) -> 817.0405 | AK34: =IF(AND(S34>0,AG34>0),(AG34/(S34*1000)*1000),0) -> 891.91246 | AL34: 4252.3 | AM34: 5885.8 | AN34: 4089 | AO34: =SUM(AL34:AN34) -> 14227.1 | AP34: =+[1]Jul!N29 -> 13450.86 | AQ34: =+AP34-AO34 -> -776.24 | AR34: =+AL34/AO34 -> 0.29888733 | AS34: =+AM34/AO34 -> 0.41370343 | AT34: =1-AR34-AS34 -> 0.28740924 | AU34: =+AR34*AQ34 -> -232.0083 | AV34: =+AS34*AQ34 -> -321.13315 | AW34: =+AT34*AQ34 -> -223.09855 | AX34: =+AL34+AU34 -> 4020.2917 | AY34: =+AM34+AV34 -> 5564.6669 | AZ34: =+AN34+AW34 -> 3865.9015 | BA34: =+Efficiency1!K113 -> 49.325845 | BB34: =BB33+BA34 -> 1188.7381 | BC34: =+R34/BA34 -> 0.90149494 | BD34: =+S34/BB34 -> 0.87124911
A35: =A34+1 -> 45865 | B35: Facial | C35: 14/12 | D35: =+'27'!F42 -> 1204.0694 | E35: =+'27'!G42 -> 903.9575 | F35: =1-(E35/D35) -> 0.24924804 | G35: =+P35/N35 -> 0.96505259 | H35: =+P35/L35 -> 0.94460454 | I35: =+R35/P35 -> 0.98545495 | J35: =+R35/L35 -> 0.93086522 | K35: =+S35/M35 -> 0.87189508 | L35: =+SUM(Efficiency1!K117:K118) -> 48.11008 | M35: =M34+L35 -> 1239.2214 | N35: =+SUM(Efficiency1!C117:C118) -> 47.090698 | O35: =O34+N35 -> 1212.859 | P35: ='27'!I38 -> 45.445 | Q35: =Q34+P35 -> 1113.456 | R35: ='27'!I40 -> 44.784 | S35: =S34+R35 -> 1080.471 | T35: =+AX35 -> 3828.5367 | U35: =T35+U34 -> 107599.94 | V35: =T35/P35 -> 84.245498 | W35: =U35/Q35 -> 96.636009 | X35: =IF(AND(R35>0,T35>0),(T35/(R35*1000))*1000,0) -> 85.48894 | Y35: =IF(AND(S35>0,U35>0),U35/S35,0) -> 99.586147 | Z35: 62 | AA35: =Z35+AA34 -> 1620.3 | AB35: =Z35/(P35) -> 1.3642865 | AC35: =AA35/(Q35) -> 1.4551989 | AD35: =IF(AND(R35>0,Z35>0),Z35/(R35),0) -> 1.384423 | AE35: =IF(AND(S35>0,AA35>0),AA35/(S35),0) -> 1.4996238 | AF35: ='27'!I46 -> 34511.34 | AG35: =AF35+AG34 -> 958253.48 | AH35: =IF(AND(L35>0,AF35>0),(AF35/(P35*1000)*1000),0) -> 759.40896 | AI35: =IF(AND(M35>0,AG35>0),(AG35/(Q35*1000)*1000),0) -> 860.6119 | AJ35: =IF(AND(R35>0,AF35>0),(AF35/(R35*1000)*1000),0) -> 770.61763 | AK35: =IF(AND(S35>0,AG35>0),(AG35/(S35*1000)*1000),0) -> 886.88496 | AL35: 4022.1 | AM35: 5922.1 | AN35: 4180.7 | AO35: =SUM(AL35:AN35) -> 14124.9 | AP35: =+[1]Jul!N30 -> 13445.14 | AQ35: =+AP35-AO35 -> -679.76 | AR35: =+AL35/AO35 -> 0.28475246 | AS35: =+AM35/AO35 -> 0.41926669 | AT35: =1-AR35-AS35 -> 0.29598086 | AU35: =+AR35*AQ35 -> -193.56333 | AV35: =+AS35*AQ35 -> -285.00072 | AW35: =+AT35*AQ35 -> -201.19595 | AX35: =+AL35+AU35 -> 3828.5367 | AY35: =+AM35+AV35 -> 5637.0993 | AZ35: =+AN35+AW35 -> 3979.5041 | BA35: =+SUM(Efficiency2!K117:K118) -> 48.11008 | BB35: =BB34+BA35 -> 1236.8482 | BC35: =+R35/BA35 -> 0.93086522 | BD35: =+S35/BB35 -> 0.87356802
A36: =A35+1 -> 45866 | B36: Facial | C36: 12 | D36: =+'28'!F42 -> 1230 | E36: =+'28'!G42 -> 947.1 | F36: =1-(E36/D36) -> 0.23 | G36: =+P36/N36 -> 0.99632225 | H36: =+P36/L36 -> 0.99632225 | I36: =+R36/P36 -> 0.96495475 | J36: =+R36/L36 -> 0.9614059 | K36: =+S36/M36 -> 0.87487676 | L36: =+Efficiency1!K121 -> 42.702047 | M36: =M35+L36 -> 1281.9234 | N36: =+Efficiency1!C121 -> 42.702047 | O36: =O35+N36 -> 1255.5611 | P36: ='28'!I38 -> 42.545 | Q36: =Q35+P36 -> 1156.001 | R36: ='28'!I40 -> 41.054 | S36: =S35+R36 -> 1121.525 | T36: =+AX36 -> 3778.128 | U36: =T36+U35 -> 111378.07 | V36: =T36/P36 -> 88.803102 | W36: =U36/Q36 -> 96.34773 | X36: =IF(AND(R36>0,T36>0),(T36/(R36*1000))*1000,0) -> 92.028255 | Y36: =IF(AND(S36>0,U36>0),U36/S36,0) -> 99.309487 | Z36: 59.4 | AA36: =Z36+AA35 -> 1679.7 | AB36: =Z36/(P36) -> 1.3961688 | AC36: =AA36/(Q36) -> 1.4530264 | AD36: =IF(AND(R36>0,Z36>0),Z36/(R36),0) -> 1.4468748 | AE36: =IF(AND(S36>0,AA36>0),AA36/(S36),0) -> 1.4976929 | AF36: ='28'!I46 -> 36738.5 | AG36: =AF36+AG35 -> 994991.98 | AH36: =IF(AND(L36>0,AF36>0),(AF36/(P36*1000)*1000),0) -> 863.52098 | AI36: =IF(AND(M36>0,AG36>0),(AG36/(Q36*1000)*1000),0) -> 860.71896 | AJ36: =IF(AND(R36>0,AF36>0),(AF36/(R36*1000)*1000),0) -> 894.88235 | AK36: =IF(AND(S36>0,AG36>0),(AG36/(S36*1000)*1000),0) -> 887.17771 | AL36: 3974.8 | AM36: 5808.4 | AN36: 4190.2 | AO36: =SUM(AL36:AN36) -> 13973.4 | AP36: =+[1]Jul!N31 -> 13282 | AQ36: =+AP36-AO36 -> -691.4 | AR36: =+AL36/AO36 -> 0.28445475 | AS36: =+AM36/AO36 -> 0.4156755 | AT36: =1-AR36-AS36 -> 0.29986975 | AU36: =+AR36*AQ36 -> -196.67201 | AV36: =+AS36*AQ36 -> -287.39804 | AW36: =+AT36*AQ36 -> -207.32995 | AX36: =+AL36+AU36 -> 3778.128 | AY36: =+AM36+AV36 -> 5521.002 | AZ36: =+AN36+AW36 -> 3982.8701 | BA36: =+Efficiency2!K121 -> 42.702047 | BB36: =BB35+BA36 -> 1279.5502 | BC36: =+R36/BA36 -> 0.9614059 | BD36: =+S36/BB36 -> 0.87649941
A37: =A36+1 -> 45867 | B37: Facial | C37: 12/13 | D37: =+'29'!F42 -> 1230 | E37: =+'29'!G42 -> 947.1 | F37: =1-(E37/D37) -> 0.23 | G37: =+P37/N37 -> 0.96829147 | H37: =+P37/L37 -> 0.96829147 | I37: =+R37/P37 -> 0.96809253 | J37: =+R37/L37 -> 0.93739574 | K37: =+S37/M37 -> 0.87696851 | L37: =+SUM(Efficiency1!K125:K126) -> 44.375068 | M37: =M36+L37 -> 1326.2985 | N37: =+SUM(Efficiency1!C125:C126) -> 44.375068 | O37: =O36+N37 -> 1299.9361 | P37: ='29'!I38 -> 42.968 | Q37: =Q36+P37 -> 1198.969 | R37: ='29'!I40 -> 41.597 | S37: =S36+R37 -> 1163.122 | T37: =+AX37 -> 3825.5265 | U37: =T37+U36 -> 115203.6 | V37: =T37/P37 -> 89.03199 | W37: =U37/Q37 -> 96.085552 | X37: =IF(AND(R37>0,T37>0),(T37/(R37*1000))*1000,0) -> 91.966405 | Y37: =IF(AND(S37>0,U37>0),U37/S37,0) -> 99.046874 | Z37: 60.6 | AA37: =Z37+AA36 -> 1740.3 | AB37: =Z37/(P37) -> 1.4103519 | AC37: =AA37/(Q37) -> 1.4514971 | AD37: =IF(AND(R37>0,Z37>0),Z37/(R37),0) -> 1.4568358 | AE37: =IF(AND(S37>0,AA37>0),AA37/(S37),0) -> 1.4962317 | AF37: ='29'!I46 -> 39176.9 | AG37: =AF37+AG36 -> 1034168.9 | AH37: =IF(AND(L37>0,AF37>0),(AF37/(P37*1000)*1000),0) -> 911.76922 | AI37: =IF(AND(M37>0,AG37>0),(AG37/(Q37*1000)*1000),0) -> 862.54847 | AJ37: =IF(AND(R37>0,AF37>0),(AF37/(R37*1000)*1000),0) -> 941.82032 | AK37: =IF(AND(S37>0,AG37>0),(AG37/(S37*1000)*1000),0) -> 889.13191 | AL37: 4030.1 | AM37: 5692.9 | AN37: 4218.7 | AO37: =SUM(AL37:AN37) -> 13941.7 | AP37: =+[1]Jul!N32 -> 13234 | AQ37: =+AP37-AO37 -> -707.7 | AR37: =+AL37/AO37 -> 0.28906805 | AS37: =+AM37/AO37 -> 0.40833614 | AT37: =1-AR37-AS37 -> 0.30259581 | AU37: =+AR37*AQ37 -> -204.57346 | AV37: =+AS37*AQ37 -> -288.97949 | AW37: =+AT37*AQ37 -> -214.14705 | AX37: =+AL37+AU37 -> 3825.5265 | AY37: =+AM37+AV37 -> 5403.9205 | AZ37: =+AN37+AW37 -> 4004.5529 | BA37: =+SUM(Efficiency2!K125:K126) -> 44.375068 | BB37: =BB36+BA37 -> 1323.9253 | BC37: =+R37/BA37 -> 0.93739574 | BD37: =+S37/BB37 -> 0.87854052
A38: =A37+1 -> 45868 | B38: Facial/Toilet | C38: 13/13 | D38: =+'30'!F42 -> 1230 | E38: =+'30'!G42 -> 947.1 | F38: =1-(E38/D38) -> 0.23 | G38: =+P38/N38 -> 1.0246069 | H38: =+P38/L38 -> 1.0246069 | I38: =+R38/P38 -> 0.91174599 | J38: =+R38/L38 -> 0.9341812 | K38: =+S38/M38 -> 0.87894881 | L38: =+SUM(Efficiency1!K129:K130) -> 47.552873 | M38: =M37+L38 -> 1373.8513 | N38: =+SUM(Efficiency1!C129:C130) -> 47.552873 | O38: =O37+N38 -> 1347.489 | P38: ='30'!I38 -> 48.723 | Q38: =Q37+P38 -> 1247.692 | R38: ='30'!I40 -> 44.423 | S38: =S37+R38 -> 1207.545 | T38: =+AX38 -> 4131.4278 | U38: =T38+U37 -> 119335.03 | V38: =T38/P38 -> 84.794201 | W38: =U38/Q38 -> 95.644619 | X38: =IF(AND(R38>0,T38>0),(T38/(R38*1000))*1000,0) -> 93.002 | Y38: =IF(AND(S38>0,U38>0),U38/S38,0) -> 98.824496 | Z38: 62.3 | AA38: =Z38+AA37 -> 1802.6 | AB38: =Z38/(P38) -> 1.2786569 | AC38: =AA38/(Q38) -> 1.4447476 | AD38: =IF(AND(R38>0,Z38>0),Z38/(R38),0) -> 1.4024267 | AE38: =IF(AND(S38>0,AA38>0),AA38/(S38),0) -> 1.4927808 | AF38: ='30'!I46 -> 37362.64 | AG38: =AF38+AG37 -> 1071531.5 | AH38: =IF(AND(L38>0,AF38>0),(AF38/(P38*1000)*1000),0) -> 766.83784 | AI38: =IF(AND(M38>0,AG38>0),(AG38/(Q38*1000)*1000),0) -> 858.81092 | AJ38: =IF(AND(R38>0,AF38>0),(AF38/(R38*1000)*1000),0) -> 841.06521 | AK38: =IF(AND(S38>0,AG38>0),(AG38/(S38*1000)*1000),0) -> 887.36363 | AL38: 4337 | AM38: 5846.5 | AN38: 4356.7 | AO38: =SUM(AL38:AN38) -> 14540.2 | AP38: =+[1]Jul!N33 -> 13851 | AQ38: =+AP38-AO38 -> -689.2 | AR38: =+AL38/AO38 -> 0.2982765 | AS38: =+AM38/AO38 -> 0.40209213 | AT38: =1-AR38-AS38 -> 0.29963137 | AU38: =+AR38*AQ38 -> -205.57217 | AV38: =+AS38*AQ38 -> -277.1219 | AW38: =+AT38*AQ38 -> -206.50594 | AX38: =+AL38+AU38 -> 4131.4278 | AY38: =+AM38+AV38 -> 5569.3781 | AZ38: =+AN38+AW38 -> 4150.1941 | BA38: =+SUM(Efficiency2!K129:K130) -> 47.552873 | BB38: =BB37+BA38 -> 1371.4782 | BC38: =+R38/BA38 -> 0.9341812 | BD38: =+S38/BB38 -> 0.88046973
