Workbook

Sheet Report1
A3: PAPER MACHINE 14 DAILY REPORT 1
A6: Date | B6: Grade | C6: GSM | D6: Speed yankee (mpm) | E6: Speed reel (mpm) | F6: Creep ( % ) | G6: Real Eff PM ( % ) | H6: Real Eff PM vs Target (%) | I6: Real Eff FG vs Real Eff PM (%) | J6: Eff FG vs Target (%) | L6: Kapasitas Target (ton) | N6: Kapasitas Teori Real (ton) | P6: PM PROD Timbangan (TON) | R6: FINSHED GOODS (TON) | T6: GAS HOOD | Z6: STEAM (TON) | AF6: POWER (kWh) | BA6: Kapasitas Running (ton) | BC6: Eff FG vs Target Running(%)
T7: CONSUMPTION | V7: /TON PM. | X7: /TON FG. | Z7: CONSUMPTION | AB7: /TON PM. | AD7: /TON FG. | AF7: CONSUMPTION | AH7: /TON PM | AJ7: /TON FG | AL7: Gas based on report DCS | AO7: total | AP7: Flowmeter | AQ7: Selisih | AR7: % pengali | AU7: Adjust | AX7: PEMAKAIAN GAS
J8: TODAY | K8: TODATE | L8: TODAY | M8: TODATE | N8: TODAY | O8: TODATE | P8: TODAY | Q8: TODATE | R8: TODAY | S8: TODATE | T8: TODAY | U8: TODATE | V8: TODAY | W8: TODATE | X8: TODAY | Y8: TODATE | Z8: TODAY | AA8: TODATE | AB8: TODAY | AC8: TODATE | AD8: TODAY | AE8: TODATE | AF8: TODAY | AG8: TODATE | AH8: TODAY | AI8: TODATE | AJ8: TODAY | AK8: TODATE | AL8: 14 | AM8: 15 | AN8: 17 | AP8: PGN | AU8: 14 | AV8: 15 | AW8: 17 | AX8: 14 | AY8: 15 | AZ8: 17 | BA8: TODAY | BB8: TODATE | BC8: TODAY | BD8: TODATE
A9: 45931 | B9: Facial | C9: 12 | D9: =+'1'!F42 -> 1092.6998 | E9: =+'1'!G42 -> 841.37888 | F9: =1-(E9/D9) -> 0.23 | G9: =+P9/N9 -> 0.43093761 | H9: =+P9/L9 -> 0.3828337 | I9: =+R9/P9 -> 0.53480139 | J9: =+R9/L9 -> 0.20474 | K9: =+S9/M9 -> 0.20474 | L9: =+Efficiency1!K6 -> 43.533262 | M9: =L9 -> 43.533262 | N9: =+Efficiency1!C6 -> 38.673812 | O9: =N9 -> 38.673812 | P9: ='1'!I38 -> 16.666 | Q9: =P9 -> 16.666 | R9: ='1'!I40 -> 8.913 | S9: =R9 -> 8.913 | T9: =+AX9 -> 2177.5973 | U9: =T9 -> 2177.5973 | V9: =T9/P9 -> 130.66106 | W9: =U9/Q9 -> 130.66106 | X9: =IF(AND(R9>0,T9>0),(T9/(R9*1000))*1000,0) -> 244.31698 | Y9: =IF(AND(S9>0,U9>0),U9/S9,0) -> 244.31698 | Z9: 39.2 | AA9: =Z9 -> 39.2 | AB9: =Z9/(P9) -> 2.3520941 | AC9: =AA9/(Q9) -> 2.3520941 | AD9: =IF(AND(R9>0,Z9>0),Z9/(R9),0) -> 4.3980702 | AE9: =IF(AND(S9>0,AA9>0),AA9/(S9),0) -> 4.3980702 | AF9: ='1'!I46 -> 24597.3 | AG9: =AF9 -> 24597.3 | AH9: =IF(AND(L9>0,AF9>0),(AF9/(P9*1000)*1000),0) -> 1475.897 | AI9: =IF(AND(M9>0,AG9>0),(AG9/(Q9*1000)*1000),0) -> 1475.897 | AJ9: =IF(AND(R9>0,AF9>0),(AF9/(R9*1000)*1000),0) -> 2759.7105 | AK9: =IF(AND(S9>0,AG9>0),(AG9/(S9*1000)*1000),0) -> 2759.7105 | AL9: 2226 | AM9: 4134.3 | AN9: 0 | AO9: =SUM(AL9:AN9) -> 6360.3 | AP9: =+[1]Okt!N4 -> 6222 | AQ9: =+AP9-AO9 -> -138.3 | AR9: =+AL9/AO9 -> 0.34998349 | AS9: =+AM9/AO9 -> 0.65001651 | AT9: =1-AR9-AS9 -> 0 | AU9: =+AR9*AQ9 -> -48.402717 | AV9: =+AS9*AQ9 -> -89.897283 | AW9: =+AT9*AQ9 -> 0 | AX9: =+AL9+AU9 -> 2177.5973 | AY9: =+AM9+AV9 -> 4044.4027 | AZ9: =+AN9+AW9 -> 0 | BA9: =+Efficiency2!K6 -> 21.766631 | BB9: =BA9 -> 21.766631 | BC9: =+R9/BA9 -> 0.40948 | BD9: =+S9/BB9 -> 0.40948
A10: =A9+1 -> 45932 | B10: Facial | C10: 12 | D10: =+'2'!F42 -> 1215.9375 | E10: =+'2'!G42 -> 936.27188 | F10: =1-(E10/D10) -> 0.23 | G10: =+P10/N10 -> 0.94537097 | H10: =+P10/L10 -> 0.93456261 | I10: =+R10/P10 -> 0.90811388 | J10: =+R10/L10 -> 0.84868927 | K10: =+S10/M10 -> 0.52514178 | L10: =+Efficiency1!K12 -> 43.110006 | M10: =M9+L10 -> 86.643268 | N10: =+Efficiency1!C12 -> 42.617133 | O10: =O9+N10 -> 81.290945 | P10: ='2'!I38 -> 40.289 | Q10: =Q9+P10 -> 56.955 | R10: ='2'!I40 -> 36.587 | S10: =S9+R10 -> 45.5 | T10: =+AX10 -> 4583.8842 | U10: =T10+U9 -> 6761.4814 | V10: =T10/P10 -> 113.77508 | W10: =U10/Q10 -> 118.7162 | X10: =IF(AND(R10>0,T10>0),(T10/(R10*1000))*1000,0) -> 125.28724 | Y10: =IF(AND(S10>0,U10>0),U10/S10,0) -> 148.60399 | Z10: 60.6 | AA10: =Z10+AA9 -> 99.8 | AB10: =Z10/(P10) -> 1.5041326 | AC10: =AA10/(Q10) -> 1.7522606 | AD10: =IF(AND(R10>0,Z10>0),Z10/(R10),0) -> 1.656326 | AE10: =IF(AND(S10>0,AA10>0),AA10/(S10),0) -> 2.1934066 | AF10: ='2'!I46 -> 40714.18 | AG10: =AF10+AG9 -> 65311.48 | AH10: =IF(AND(L10>0,AF10>0),(AF10/(P10*1000)*1000),0) -> 1010.5533 | AI10: =IF(AND(M10>0,AG10>0),(AG10/(Q10*1000)*1000),0) -> 1146.7207 | AJ10: =IF(AND(R10>0,AF10>0),(AF10/(R10*1000)*1000),0) -> 1112.8045 | AK10: =IF(AND(S10>0,AG10>0),(AG10/(S10*1000)*1000),0) -> 1435.4171 | AL10: 4823.4 | AM10: 5878 | AN10: 0 | AO10: =SUM(AL10:AN10) -> 10701.4 | AP10: =+[1]Okt!N5 -> 10170 | AQ10: =+AP10-AO10 -> -531.4 | AR10: =+AL10/AO10 -> 0.45072607 | AS10: =+AM10/AO10 -> 0.54927393 | AT10: =1-AR10-AS10 -> 0 | AU10: =+AR10*AQ10 -> -239.51584 | AV10: =+AS10*AQ10 -> -291.88416 | AW10: =+AT10*AQ10 -> 0 | AX10: =+AL10+AU10 -> 4583.8842 | AY10: =+AM10+AV10 -> 5586.1158 | AZ10: =+AN10+AW10 -> 0 | BA10: =+Efficiency2!K12 -> 43.110006 | BB10: =BB9+BA10 -> 64.876637 | BC10: =+R10/BA10 -> 0.84868927 | BD10: =+S10/BB10 -> 0.70133105
A11: =A10+1 -> 45933 | B11: Facial | C11: 12 | D11: =+'3'!F42 -> 1222.6389 | E11: =+'3'!G42 -> 941.43194 | F11: =1-(E11/D11) -> 0.23 | G11: =+P11/N11 -> 0.89120524 | H11: =+P11/L11 -> 0.88587169 | I11: =+R11/P11 -> 0.96784719 | J11: =+R11/L11 -> 0.85738843 | K11: =+S11/M11 -> 0.63456998 | L11: =+Efficiency1!K16 -> 42.551309 | M11: =M10+L11 -> 129.19458 | N11: =+Efficiency1!C16 -> 42.296654 | O11: =O10+N11 -> 123.5876 | P11: ='3'!I38 -> 37.695 | Q11: =Q10+P11 -> 94.65 | R11: ='3'!I40 -> 36.483 | S11: =S10+R11 -> 81.983 | T11: =+AX11 -> 4518.3479 | U11: =T11+U10 -> 11279.829 | V11: =T11/P11 -> 119.86597 | W11: =U11/Q11 -> 119.17411 | X11: =IF(AND(R11>0,T11>0),(T11/(R11*1000))*1000,0) -> 123.84804 | Y11: =IF(AND(S11>0,U11>0),U11/S11,0) -> 137.58742 | Z11: 55.7 | AA11: =Z11+AA10 -> 155.5 | AB11: =Z11/(P11) -> 1.4776496 | AC11: =AA11/(Q11) -> 1.6428949 | AD11: =IF(AND(R11>0,Z11>0),Z11/(R11),0) -> 1.5267385 | AE11: =IF(AND(S11>0,AA11>0),AA11/(S11),0) -> 1.8967347 | AF11: ='3'!I46 -> 39132.22 | AG11: =AF11+AG10 -> 104443.7 | AH11: =IF(AND(L11>0,AF11>0),(AF11/(P11*1000)*1000),0) -> 1038.1276 | AI11: =IF(AND(M11>0,AG11>0),(AG11/(Q11*1000)*1000),0) -> 1103.4728 | AJ11: =IF(AND(R11>0,AF11>0),(AF11/(R11*1000)*1000),0) -> 1072.6152 | AK11: =IF(AND(S11>0,AG11>0),(AG11/(S11*1000)*1000),0) -> 1273.9678 | AL11: 4743.4 | AM11: 6494.8 | AN11: 0 | AO11: =SUM(AL11:AN11) -> 11238.2 | AP11: =+[1]Okt!N6 -> 10705 | AQ11: =+AP11-AO11 -> -533.2 | AR11: =+AL11/AO11 -> 0.42207827 | AS11: =+AM11/AO11 -> 0.57792173 | AT11: =1-AR11-AS11 -> 0 | AU11: =+AR11*AQ11 -> -225.05213 | AV11: =+AS11*AQ11 -> -308.14787 | AW11: =+AT11*AQ11 -> 0 | AX11: =+AL11+AU11 -> 4518.3479 | AY11: =+AM11+AV11 -> 6186.6521 | AZ11: =+AN11+AW11 -> 0 | BA11: =+Efficiency2!K16 -> 42.551309 | BB11: =BB10+BA11 -> 107.42795 | BC11: =+R11/BA11 -> 0.85738843 | BD11: =+S11/BB11 -> 0.76314407
A12: =A11+1 -> 45934 | B12: Facial/Toilet | C12: 12/12,5/13 | D12: =+'4'!F42 -> 1216.1875 | E12: =+'4'!G42 -> 936.46438 | F12: =1-(E12/D12) -> 0.23 | G12: =+P12/N12 -> 0.95155376 | H12: =+P12/L12 -> 0.94113387 | I12: =+R12/P12 -> 0.96847165 | J12: =+R12/L12 -> 0.91146148 | K12: =+S12/M12 -> 0.70620875 | L12: =+SUM(Efficiency1!K20:K22) -> 45.092416 | M12: =M11+L12 -> 174.28699 | N12: =+SUM(Efficiency1!C20:C22) -> 44.598636 | O12: =O11+N12 -> 168.18624 | P12: ='4'!I38 -> 42.438 | Q12: =Q11+P12 -> 137.088 | R12: ='4'!I40 -> 41.1 | S12: =S11+R12 -> 123.083 | T12: =+AX12 -> 4445.8054 | U12: =T12+U11 -> 15725.635 | V12: =T12/P12 -> 104.76001 | W12: =U12/Q12 -> 114.71197 | X12: =IF(AND(R12>0,T12>0),(T12/(R12*1000))*1000,0) -> 108.17045 | Y12: =IF(AND(S12>0,U12>0),U12/S12,0) -> 127.76447 | Z12: 60.8 | AA12: =Z12+AA11 -> 216.3 | AB12: =Z12/(P12) -> 1.4326783 | AC12: =AA12/(Q12) -> 1.5778186 | AD12: =IF(AND(R12>0,Z12>0),Z12/(R12),0) -> 1.4793187 | AE12: =IF(AND(S12>0,AA12>0),AA12/(S12),0) -> 1.7573507 | AF12: ='4'!I46 -> 37086.44 | AG12: =AF12+AG11 -> 141530.14 | AH12: =IF(AND(L12>0,AF12>0),(AF12/(P12*1000)*1000),0) -> 873.89698 | AI12: =IF(AND(M12>0,AG12>0),(AG12/(Q12*1000)*1000),0) -> 1032.4036 | AJ12: =IF(AND(R12>0,AF12>0),(AF12/(R12*1000)*1000),0) -> 902.34647 | AK12: =IF(AND(S12>0,AG12>0),(AG12/(S12*1000)*1000),0) -> 1149.8756 | AL12: 4506.9 | AM12: 5946.2 | AN12: 0 | AO12: =SUM(AL12:AN12) -> 10453.1 | AP12: =+[1]Okt!N7 -> 10311.4 | AQ12: =+AP12-AO12 -> -141.7 | AR12: =+AL12/AO12 -> 0.43115439 | AS12: =+AM12/AO12 -> 0.56884561 | AT12: =1-AR12-AS12 -> 0 | AU12: =+AR12*AQ12 -> -61.094578 | AV12: =+AS12*AQ12 -> -80.605422 | AW12: =+AT12*AQ12 -> 0 | AX12: =+AL12+AU12 -> 4445.8054 | AY12: =+AM12+AV12 -> 5865.5946 | AZ12: =+AN12+AW12 -> 0 | BA12: =+SUM(Efficiency2!K20:K22) -> 45.092416 | BB12: =BB11+BA12 -> 152.52036 | BC12: =+R12/BA12 -> 0.91146148 | BD12: =+S12/BB12 -> 0.80699389
A13: =A12+1 -> 45935 | B13: Toilet | C13: 13 | D13: =+'5'!F42 -> 1166.6667 | E13: =+'5'!G42 -> 898.33333 | F13: =1-(E13/D13) -> 0.23 | G13: =+P13/N13 -> 0.9587358 | H13: =+P13/L13 -> 0.9587358 | I13: =+R13/P13 -> 0.96939683 | J13: =+R13/L13 -> 0.92939545 | K13: =+S13/M13 -> 0.75069483 | L13: =+Efficiency1!K24 -> 43.387344 | M13: =M12+L13 -> 217.67434 | N13: =+Efficiency1!C24 -> 43.387344 | O13: =O12+N13 -> 211.57358 | P13: ='5'!I38 -> 41.597 | Q13: =Q12+P13 -> 178.685 | R13: ='5'!I40 -> 40.324 | S13: =S12+R13 -> 163.407 | T13: =+AX13 -> 4238.7397 | U13: =T13+U12 -> 19964.374 | V13: =T13/P13 -> 101.90013 | W13: =U13/Q13 -> 111.72944 | X13: =IF(AND(R13>0,T13>0),(T13/(R13*1000))*1000,0) -> 105.11704 | Y13: =IF(AND(S13>0,U13>0),U13/S13,0) -> 122.17576 | Z13: 60.5 | AA13: =Z13+AA12 -> 276.8 | AB13: =Z13/(P13) -> 1.4544318 | AC13: =AA13/(Q13) -> 1.5490948 | AD13: =IF(AND(R13>0,Z13>0),Z13/(R13),0) -> 1.5003472 | AE13: =IF(AND(S13>0,AA13>0),AA13/(S13),0) -> 1.6939299 | AF13: ='5'!I46 -> 39380.48 | AG13: =AF13+AG12 -> 180910.62 | AH13: =IF(AND(L13>0,AF13>0),(AF13/(P13*1000)*1000),0) -> 946.71443 | AI13: =IF(AND(M13>0,AG13>0),(AG13/(Q13*1000)*1000),0) -> 1012.4556 | AJ13: =IF(AND(R13>0,AF13>0),(AF13/(R13*1000)*1000),0) -> 976.60153 | AK13: =IF(AND(S13>0,AG13>0),(AG13/(S13*1000)*1000),0) -> 1107.1167 | AL13: 4573.2 | AM13: 5285.3 | AN13: 0 | AO13: =SUM(AL13:AN13) -> 9858.5 | AP13: =+[1]Okt!N8 -> 9137.5 | AQ13: =+AP13-AO13 -> -721 | AR13: =+AL13/AO13 -> 0.46388396 | AS13: =+AM13/AO13 -> 0.53611604 | AT13: =1-AR13-AS13 -> 0 | AU13: =+AR13*AQ13 -> -334.46033 | AV13: =+AS13*AQ13 -> -386.53967 | AW13: =+AT13*AQ13 -> 0 | AX13: =+AL13+AU13 -> 4238.7397 | AY13: =+AM13+AV13 -> 4898.7603 | AZ13: =+AN13+AW13 -> 0 | BA13: =+Efficiency2!K24 -> 43.387344 | BB13: =BB12+BA13 -> 195.90771 | BC13: =+R13/BA13 -> 0.92939545 | BD13: =+S13/BB13 -> 0.83410195
A14: =A13+1 -> 45936 | B14: Toilet | C14: 13 | D14: =+'6'!F42 -> 1180 | E14: =+'6'!G42 -> 908.6 | F14: =1-(E14/D14) -> 0.23 | G14: =+P14/N14 -> 0.97893956 | H14: =+P14/L14 -> 0.97893956 | I14: =+R14/P14 -> 0.97113527 | J14: =+R14/L14 -> 0.95068274 | K14: =+S14/M14 -> 0.7842481 | L14: =+Efficiency1!K28 -> 43.883199 | M14: =M13+L14 -> 261.55754 | N14: =+Efficiency1!C28 -> 43.883199 | O14: =O13+N14 -> 255.45678 | P14: ='6'!I38 -> 42.959 | Q14: =Q13+P14 -> 221.644 | R14: ='6'!I40 -> 41.719 | S14: =S13+R14 -> 205.126 | T14: =+AX14 -> 4467.8397 | U14: =T14+U13 -> 24432.214 | V14: =T14/P14 -> 104.00241 | W14: =U14/Q14 -> 110.23179 | X14: =IF(AND(R14>0,T14>0),(T14/(R14*1000))*1000,0) -> 107.09364 | Y14: =IF(AND(S14>0,U14>0),U14/S14,0) -> 119.10832 | Z14: 59.1 | AA14: =Z14+AA13 -> 335.9 | AB14: =Z14/(P14) -> 1.3757303 | AC14: =AA14/(Q14) -> 1.5154933 | AD14: =IF(AND(R14>0,Z14>0),Z14/(R14),0) -> 1.4166207 | AE14: =IF(AND(S14>0,AA14>0),AA14/(S14),0) -> 1.6375301 | AF14: ='6'!I46 -> 37424.74 | AG14: =AF14+AG13 -> 218335.36 | AH14: =IF(AND(L14>0,AF14>0),(AF14/(P14*1000)*1000),0) -> 871.17344 | AI14: =IF(AND(M14>0,AG14>0),(AG14/(Q14*1000)*1000),0) -> 985.07228 | AJ14: =IF(AND(R14>0,AF14>0),(AF14/(R14*1000)*1000),0) -> 897.06704 | AK14: =IF(AND(S14>0,AG14>0),(AG14/(S14*1000)*1000),0) -> 1064.3963 | AL14: 4540.4 | AM14: 5083.5 | AN14: 0 | AO14: =SUM(AL14:AN14) -> 9623.9 | AP14: =+[1]Okt!N9 -> 9470.1 | AQ14: =+AP14-AO14 -> -153.8 | AR14: =+AL14/AO14 -> 0.47178379 | AS14: =+AM14/AO14 -> 0.52821621 | AT14: =1-AR14-AS14 -> 0 | AU14: =+AR14*AQ14 -> -72.560347 | AV14: =+AS14*AQ14 -> -81.239653 | AW14: =+AT14*AQ14 -> 0 | AX14: =+AL14+AU14 -> 4467.8397 | AY14: =+AM14+AV14 -> 5002.2603 | AZ14: =+AN14+AW14 -> 0 | BA14: =+Efficiency2!K28 -> 43.883199 | BB14: =BB13+BA14 -> 239.79091 | BC14: =+R14/BA14 -> 0.95068274 | BD14: =+S14/BB14 -> 0.85543695
A15: =A14+1 -> 45937 | B15: Toilet | C15: 13/12,5 | D15: =+'7'!F42 -> 1211.7083 | E15: =+'7'!G42 -> 933.01542 | F15: =1-(E15/D15) -> 0.23 | G15: =+P15/N15 -> 0.99278718 | H15: =+P15/L15 -> 0.98096726 | I15: =+R15/P15 -> 0.98576214 | J15: =+R15/L15 -> 0.96700039 | K15: =+S15/M15 -> 0.81047101 | L15: =+SUM(Efficiency1!K32:K33) -> 43.817976 | M15: =M14+L15 -> 305.37551 | N15: =+SUM(Efficiency1!C32:C33) -> 43.296288 | O15: =O14+N15 -> 298.75307 | P15: ='7'!I38 -> 42.984 | Q15: =Q14+P15 -> 264.628 | R15: ='7'!I40 -> 42.372 | S15: =S14+R15 -> 247.498 | T15: =+AX15 -> 4214.2 | U15: =T15+U14 -> 28646.414 | V15: =T15/P15 -> 98.041132 | W15: =U15/Q15 -> 108.25164 | X15: =IF(AND(R15>0,T15>0),(T15/(R15*1000))*1000,0) -> 99.457189 | Y15: =IF(AND(S15>0,U15>0),U15/S15,0) -> 115.74402 | Z15: 58.9 | AA15: =Z15+AA14 -> 394.8 | AB15: =Z15/(P15) -> 1.3702773 | AC15: =AA15/(Q15) -> 1.4919056 | AD15: =IF(AND(R15>0,Z15>0),Z15/(R15),0) -> 1.3900689 | AE15: =IF(AND(S15>0,AA15>0),AA15/(S15),0) -> 1.5951644 | AF15: ='7'!I46 -> 39433.3 | AG15: =AF15+AG14 -> 257768.66 | AH15: =IF(AND(L15>0,AF15>0),(AF15/(P15*1000)*1000),0) -> 917.39484 | AI15: =IF(AND(M15>0,AG15>0),(AG15/(Q15*1000)*1000),0) -> 974.07931 | AJ15: =IF(AND(R15>0,AF15>0),(AF15/(R15*1000)*1000),0) -> 930.64524 | AK15: =IF(AND(S15>0,AG15>0),(AG15/(S15*1000)*1000),0) -> 1041.498 | AL15: 4415.4 | AM15: 5218.6 | AN15: 0 | AO15: =SUM(AL15:AN15) -> 9634 | AP15: =+[1]Okt!N10 -> 9195 | AQ15: =+AP15-AO15 -> -439 | AR15: =+AL15/AO15 -> 0.4583143 | AS15: =+AM15/AO15 -> 0.5416857 | AT15: =1-AR15-AS15 -> 0 | AU15: =+AR15*AQ15 -> -201.19998 | AV15: =+AS15*AQ15 -> -237.80002 | AW15: =+AT15*AQ15 -> 0 | AX15: =+AL15+AU15 -> 4214.2 | AY15: =+AM15+AV15 -> 4980.8 | AZ15: =+AN15+AW15 -> 0 | BA15: =+SUM(Efficiency2!K32:K33) -> 43.817976 | BB15: =BB14+BA15 -> 283.60888 | BC15: =+R15/BA15 -> 0.96700039 | BD15: =+S15/BB15 -> 0.87267366
A16: =A15+1 -> 45938 | B16: Toilet | C16: 12,5 | D16: =+'8'!F42 -> 1220 | E16: =+'8'!G42 -> 939.4 | F16: =1-(E16/D16) -> 0.23 | G16: =+P16/N16 -> 0.96970212 | H16: =+P16/L16 -> 0.96181837 | I16: =+R16/P16 -> 1.0248458 | J16: =+R16/L16 -> 0.98571547 | K16: =+S16/M16 -> 0.83245902 | L16: =+Efficiency1!K36 -> 43.812846 | M16: =M15+L16 -> 349.18836 | N16: =+Efficiency1!C36 -> 43.456644 | O16: =O15+N16 -> 342.20971 | P16: ='8'!I38 -> 42.14 | Q16: =Q15+P16 -> 306.768 | R16: ='8'!I40 -> 43.187 | S16: =S15+R16 -> 290.685 | T16: =+AX16 -> 4448.3363 | U16: =T16+U15 -> 33094.75 | V16: =T16/P16 -> 105.5609 | W16: =U16/Q16 -> 107.88202 | X16: =IF(AND(R16>0,T16>0),(T16/(R16*1000))*1000,0) -> 103.00174 | Y16: =IF(AND(S16>0,U16>0),U16/S16,0) -> 113.85091 | Z16: 59.2 | AA16: =Z16+AA15 -> 454 | AB16: =Z16/(P16) -> 1.404841 | AC16: =AA16/(Q16) -> 1.4799458 | AD16: =IF(AND(R16>0,Z16>0),Z16/(R16),0) -> 1.3707829 | AE16: =IF(AND(S16>0,AA16>0),AA16/(S16),0) -> 1.5618281 | AF16: ='8'!I46 -> 37804.26 | AG16: =AF16+AG15 -> 295572.92 | AH16: =IF(AND(L16>0,AF16>0),(AF16/(P16*1000)*1000),0) -> 897.11106 | AI16: =IF(AND(M16>0,AG16>0),(AG16/(Q16*1000)*1000),0) -> 963.50636 | AJ16: =IF(AND(R16>0,AF16>0),(AF16/(R16*1000)*1000),0) -> 875.36203 | AK16: =IF(AND(S16>0,AG16>0),(AG16/(S16*1000)*1000),0) -> 1016.8152 | AL16: 4490.4 | AM16: 5939.3 | AN16: 0 | AO16: =SUM(AL16:AN16) -> 10429.7 | AP16: =+[1]Okt!N11 -> 10332 | AQ16: =+AP16-AO16 -> -97.7 | AR16: =+AL16/AO16 -> 0.43053971 | AS16: =+AM16/AO16 -> 0.56946029 | AT16: =1-AR16-AS16 -> 0 | AU16: =+AR16*AQ16 -> -42.06373 | AV16: =+AS16*AQ16 -> -55.63627 | AW16: =+AT16*AQ16 -> 0 | AX16: =+AL16+AU16 -> 4448.3363 | AY16: =+AM16+AV16 -> 5883.6637 | AZ16: =+AN16+AW16 -> 0 | BA16: =+Efficiency2!K36 -> 43.812846 | BB16: =BB15+BA16 -> 327.42173 | BC16: =+R16/BA16 -> 0.98571547 | BD16: =+S16/BB16 -> 0.88779997
A17: =A16+1 -> 45939 | B17: Toilet | C17: 12,5 | D17: =+'9'!F42 -> 1215.6944 | E17: =+'9'!G42 -> 936.08472 | F17: =1-(E17/D17) -> 0.23 | G17: =+P17/N17 -> 0.88930015 | H17: =+P17/L17 -> 0.88207007 | I17: =+R17/P17 -> 0.94558298 | J17: =+R17/L17 -> 0.83407045 | K17: =+S17/M17 -> 0.83263867 | L17: =+Efficiency1!K40 -> 43.812846 | M17: =M16+L17 -> 393.0012 | N17: =+Efficiency1!C40 -> 43.456644 | O17: =O16+N17 -> 385.66636 | P17: ='9'!I38 -> 38.646 | Q17: =Q16+P17 -> 345.414 | R17: ='9'!I40 -> 36.543 | S17: =S16+R17 -> 327.228 | T17: =+AX17 -> 4318.1632 | U17: =T17+U16 -> 37412.913 | V17: =T17/P17 -> 111.73635 | W17: =U17/Q17 -> 108.31325 | X17: =IF(AND(R17>0,T17>0),(T17/(R17*1000))*1000,0) -> 118.16663 | Y17: =IF(AND(S17>0,U17>0),U17/S17,0) -> 114.33286 | Z17: 58.3 | AA17: =Z17+AA16 -> 512.3 | AB17: =Z17/(P17) -> 1.5085649 | AC17: =AA17/(Q17) -> 1.4831478 | AD17: =IF(AND(R17>0,Z17>0),Z17/(R17),0) -> 1.5953808 | AE17: =IF(AND(S17>0,AA17>0),AA17/(S17),0) -> 1.5655751 | AF17: ='9'!I46 -> 37619.86 | AG17: =AF17+AG16 -> 333192.78 | AH17: =IF(AND(L17>0,AF17>0),(AF17/(P17*1000)*1000),0) -> 973.4477 | AI17: =IF(AND(M17>0,AG17>0),(AG17/(Q17*1000)*1000),0) -> 964.61863 | AJ17: =IF(AND(R17>0,AF17>0),(AF17/(R17*1000)*1000),0) -> 1029.4683 | AK17: =IF(AND(S17>0,AG17>0),(AG17/(S17*1000)*1000),0) -> 1018.2282 | AL17: 4402.7 | AM17: 4586.4 | AN17: 2822.7 | AO17: =SUM(AL17:AN17) -> 11811.8 | AP17: =+[1]Okt!N12 -> 11585 | AQ17: =+AP17-AO17 -> -226.8 | AR17: =+AL17/AO17 -> 0.37273743 | AS17: =+AM17/AO17 -> 0.38828968 | AT17: =1-AR17-AS17 -> 0.23897289 | AU17: =+AR17*AQ17 -> -84.53685 | AV17: =+AS17*AQ17 -> -88.064099 | AW17: =+AT17*AQ17 -> -54.199052 | AX17: =+AL17+AU17 -> 4318.1632 | AY17: =+AM17+AV17 -> 4498.3359 | AZ17: =+AN17+AW17 -> 2768.5009 | BA17: =+Efficiency2!K40 -> 43.812846 | BB17: =BB16+BA17 -> 371.23457 | BC17: =+R17/BA17 -> 0.83407045 | BD17: =+S17/BB17 -> 0.88145885
A18: =A17+1 -> 45940 | B18: Toilet | C18: 12,5 | D18: =+'10'!F42 -> 1215.0625 | E18: =+'10'!G42 -> 935.59812 | F18: =1-(E18/D18) -> 0.23 | G18: =+P18/N18 -> 0.9298356 | H18: =+P18/L18 -> 0.91854339 | I18: =+R18/P18 -> 0.89310208 | J18: =+R18/L18 -> 0.82035301 | K18: =+S18/M18 -> 0.83140641 | L18: =+Efficiency1!K44 -> 43.812846 | M18: =M17+L18 -> 436.81405 | N18: =+Efficiency1!C44 -> 43.280769 | O18: =O17+N18 -> 428.94712 | P18: ='10'!I38 -> 40.244 | Q18: =Q17+P18 -> 385.658 | R18: ='10'!I40 -> 35.942 | S18: =S17+R18 -> 363.17 | T18: =+AX18 -> 4182.7571 | U18: =T18+U17 -> 41595.671 | V18: =T18/P18 -> 103.93492 | W18: =U18/Q18 -> 107.85637 | X18: =IF(AND(R18>0,T18>0),(T18/(R18*1000))*1000,0) -> 116.37519 | Y18: =IF(AND(S18>0,U18>0),U18/S18,0) -> 114.53499 | Z18: 58.9 | AA18: =Z18+AA17 -> 571.2 | AB18: =Z18/(P18) -> 1.4635722 | AC18: =AA18/(Q18) -> 1.481105 | AD18: =IF(AND(R18>0,Z18>0),Z18/(R18),0) -> 1.6387513 | AE18: =IF(AND(S18>0,AA18>0),AA18/(S18),0) -> 1.5728171 | AF18: ='10'!I46 -> 38977.34 | AG18: =AF18+AG17 -> 372170.12 | AH18: =IF(AND(L18>0,AF18>0),(AF18/(P18*1000)*1000),0) -> 968.52549 | AI18: =IF(AND(M18>0,AG18>0),(AG18/(Q18*1000)*1000),0) -> 965.02632 | AJ18: =IF(AND(R18>0,AF18>0),(AF18/(R18*1000)*1000),0) -> 1084.4511 | AK18: =IF(AND(S18>0,AG18>0),(AG18/(S18*1000)*1000),0) -> 1024.7821 | AL18: 4378.8 | AM18: 5420.6 | AN18: 3977.4 | AO18: =SUM(AL18:AN18) -> 13776.8 | AP18: =+[1]Okt!N13 -> 13160 | AQ18: =+AP18-AO18 -> -616.8 | AR18: =+AL18/AO18 -> 0.31783869 | AS18: =+AM18/AO18 -> 0.39345857 | AT18: =1-AR18-AS18 -> 0.28870275 | AU18: =+AR18*AQ18 -> -196.0429 | AV18: =+AS18*AQ18 -> -242.68524 | AW18: =+AT18*AQ18 -> -178.07185 | AX18: =+AL18+AU18 -> 4182.7571 | AY18: =+AM18+AV18 -> 5177.9148 | AZ18: =+AN18+AW18 -> 3799.3281 | BA18: =+Efficiency2!K44 -> 43.812846 | BB18: =BB17+BA18 -> 415.04742 | BC18: =+R18/BA18 -> 0.82035301 | BD18: =+S18/BB18 -> 0.87500845
A19: =A18+1 -> 45941 | B19: Toilet | C19: 12,5/12 | D19: =+'11'!F42 -> 1192.8958 | E19: =+'11'!G42 -> 918.52979 | F19: =1-(E19/D19) -> 0.23 | G19: =+P19/N19 -> 0.93202562 | H19: =+P19/L19 -> 0.90391084 | I19: =+R19/P19 -> 1.0150727 | J19: =+R19/L19 -> 0.91753522 | K19: =+S19/M19 -> 0.83925863 | L19: =+SUM(Efficiency1!K48:K49) -> 43.818481 | M19: =M18+L19 -> 480.63253 | N19: =+SUM(Efficiency1!C48:C49) -> 42.496686 | O19: =O18+N19 -> 471.44381 | P19: ='11'!I38 -> 39.608 | Q19: =Q18+P19 -> 425.266 | R19: ='11'!I40 -> 40.205 | S19: =S18+R19 -> 403.375 | T19: =+AX19 -> 4123.4125 | U19: =T19+U18 -> 45719.083 | V19: =T19/P19 -> 104.10555 | W19: =U19/Q19 -> 107.50703 | X19: =IF(AND(R19>0,T19>0),(T19/(R19*1000))*1000,0) -> 102.55969 | Y19: =IF(AND(S19>0,U19>0),U19/S19,0) -> 113.34139 | Z19: 59.1 | AA19: =Z19+AA18 -> 630.3 | AB19: =Z19/(P19) -> 1.4921228 | AC19: =AA19/(Q19) -> 1.4821312 | AD19: =IF(AND(R19>0,Z19>0),Z19/(R19),0) -> 1.4699664 | AE19: =IF(AND(S19>0,AA19>0),AA19/(S19),0) -> 1.5625659 | AF19: ='11'!I46 -> 38902.78 | AG19: =AF19+AG18 -> 411072.9 | AH19: =IF(AND(L19>0,AF19>0),(AF19/(P19*1000)*1000),0) -> 982.19501 | AI19: =IF(AND(M19>0,AG19>0),(AG19/(Q19*1000)*1000),0) -> 966.62536 | AJ19: =IF(AND(R19>0,AF19>0),(AF19/(R19*1000)*1000),0) -> 967.6105 | AK19: =IF(AND(S19>0,AG19>0),(AG19/(S19*1000)*1000),0) -> 1019.0837 | AL19: 4306.9 | AM19: 5661.5 | AN19: 4300.5 | AO19: =SUM(AL19:AN19) -> 14268.9 | AP19: =+[1]Okt!N14 -> 13661 | AQ19: =+AP19-AO19 -> -607.9 | AR19: =+AL19/AO19 -> 0.30183826 | AS19: =+AM19/AO19 -> 0.396772 | AT19: =1-AR19-AS19 -> 0.30138974 | AU19: =+AR19*AQ19 -> -183.48748 | AV19: =+AS19*AQ19 -> -241.1977 | AW19: =+AT19*AQ19 -> -183.21482 | AX19: =+AL19+AU19 -> 4123.4125 | AY19: =+AM19+AV19 -> 5420.3023 | AZ19: =+AN19+AW19 -> 4117.2852 | BA19: =+SUM(Efficiency2!K48:K49) -> 43.818481 | BB19: =BB18+BA19 -> 458.8659 | BC19: =+R19/BA19 -> 0.91753522 | BD19: =+S19/BB19 -> 0.87906946
A20: =A19+1 -> 45942 | B20: Toilet | C20: 12/12,5 | D20: =+'12'!F42 -> 1171.7986 | E20: =+'12'!G42 -> 923.28757 | F20: =1-(E20/D20) -> 0.21207658 | G20: =+P20/N20 -> 0.96239948 | H20: =+P20/L20 -> 0.9167236 | I20: =+R20/P20 -> 0.95710626 | J20: =+R20/L20 -> 0.8774019 | K20: =+S20/M20 -> 0.84261756 | L20: =+SUM(Efficiency1!K52:K53) -> 46.412026 | M20: =M19+L20 -> 527.04456 | N20: =+SUM(Efficiency1!C52:C53) -> 44.209292 | O20: =O19+N20 -> 515.6531 | P20: ='12'!I38 -> 42.547 | Q20: =Q19+P20 -> 467.813 | R20: ='12'!I40 -> 40.722 | S20: =S19+R20 -> 444.097 | T20: =+AX20 -> 4182.6529 | U20: =T20+U19 -> 49901.736 | V20: =T20/P20 -> 98.306648 | W20: =U20/Q20 -> 106.67026 | X20: =IF(AND(R20>0,T20>0),(T20/(R20*1000))*1000,0) -> 102.71237 | Y20: =IF(AND(S20>0,U20>0),U20/S20,0) -> 112.36675 | Z20: 60.4 | AA20: =Z20+AA19 -> 690.7 | AB20: =Z20/(P20) -> 1.4196066 | AC20: =AA20/(Q20) -> 1.4764446 | AD20: =IF(AND(R20>0,Z20>0),Z20/(R20),0) -> 1.4832277 | AE20: =IF(AND(S20>0,AA20>0),AA20/(S20),0) -> 1.5552908 | AF20: ='12'!I46 -> 37891.08 | AG20: =AF20+AG19 -> 448963.98 | AH20: =IF(AND(L20>0,AF20>0),(AF20/(P20*1000)*1000),0) -> 890.56996 | AI20: =IF(AND(M20>0,AG20>0),(AG20/(Q20*1000)*1000),0) -> 959.70822 | AJ20: =IF(AND(R20>0,AF20>0),(AF20/(R20*1000)*1000),0) -> 930.4818 | AK20: =IF(AND(S20>0,AG20>0),(AG20/(S20*1000)*1000),0) -> 1010.9593 | AL20: 4451.9 | AM20: 5604.5 | AN20: 3814.5 | AO20: =SUM(AL20:AN20) -> 13870.9 | AP20: =+[1]Okt!N15 -> 13032 | AQ20: =+AP20-AO20 -> -838.9 | AR20: =+AL20/AO20 -> 0.3209525 | AS20: =+AM20/AO20 -> 0.40404732 | AT20: =1-AR20-AS20 -> 0.27500018 | AU20: =+AR20*AQ20 -> -269.24705 | AV20: =+AS20*AQ20 -> -338.9553 | AW20: =+AT20*AQ20 -> -230.69765 | AX20: =+AL20+AU20 -> 4182.6529 | AY20: =+AM20+AV20 -> 5265.5447 | AZ20: =+AN20+AW20 -> 3583.8023 | BA20: =+SUM(Efficiency2!K52:K53) -> 46.412026 | BB20: =BB19+BA20 -> 505.27793 | BC20: =+R20/BA20 -> 0.8774019 | BD20: =+S20/BB20 -> 0.87891629
A21: =A20+1 -> 45943 | B21: Toilet | C21: 12,5 | D21: =+'13'!F42 -> 1184.7083 | E21: =+'13'!G42 -> 928.02542 | F21: =1-(E21/D21) -> 0.21666338 | G21: =+P21/N21 -> 0.91511603 | H21: =+P21/L21 -> 0.88141918 | I21: =+R21/P21 -> 0.96849198 | J21: =+R21/L21 -> 0.8536474 | K21: =+S21/M21 -> 0.84350837 | L21: =+Efficiency1!K56 -> 46.306004 | M21: =M20+L21 -> 573.35056 | N21: =+Efficiency1!C56 -> 44.600902 | O21: =O20+N21 -> 560.254 | P21: ='13'!I38 -> 40.815 | Q21: =Q20+P21 -> 508.628 | R21: ='13'!I40 -> 39.529 | S21: =S20+R21 -> 483.626 | T21: =+AX21 -> 4251.7673 | U21: =T21+U20 -> 54153.503 | V21: =T21/P21 -> 104.17168 | W21: =U21/Q21 -> 106.46976 | X21: =IF(AND(R21>0,T21>0),(T21/(R21*1000))*1000,0) -> 107.56071 | Y21: =IF(AND(S21>0,U21>0),U21/S21,0) -> 111.97393 | Z21: 61 | AA21: =Z21+AA20 -> 751.7 | AB21: =Z21/(P21) -> 1.4945486 | AC21: =AA21/(Q21) -> 1.4778974 | AD21: =IF(AND(R21>0,Z21>0),Z21/(R21),0) -> 1.5431708 | AE21: =IF(AND(S21>0,AA21>0),AA21/(S21),0) -> 1.5543002 | AF21: ='13'!I46 -> 37582.94 | AG21: =AF21+AG20 -> 486546.92 | AH21: =IF(AND(L21>0,AF21>0),(AF21/(P21*1000)*1000),0) -> 920.81196 | AI21: =IF(AND(M21>0,AG21>0),(AG21/(Q21*1000)*1000),0) -> 956.58698 | AJ21: =IF(AND(R21>0,AF21>0),(AF21/(R21*1000)*1000),0) -> 950.7688 | AK21: =IF(AND(S21>0,AG21>0),(AG21/(S21*1000)*1000),0) -> 1006.0396 | AL21: 4409.2 | AM21: 4895.5 | AN21: 4113.4 | AO21: =SUM(AL21:AN21) -> 13418.1 | AP21: =+[1]Okt!N16 -> 12939 | AQ21: =+AP21-AO21 -> -479.1 | AR21: =+AL21/AO21 -> 0.32860092 | AS21: =+AM21/AO21 -> 0.36484301 | AT21: =1-AR21-AS21 -> 0.30655607 | AU21: =+AR21*AQ21 -> -157.4327 | AV21: =+AS21*AQ21 -> -174.79629 | AW21: =+AT21*AQ21 -> -146.87101 | AX21: =+AL21+AU21 -> 4251.7673 | AY21: =+AM21+AV21 -> 4720.7037 | AZ21: =+AN21+AW21 -> 3966.529 | BA21: =+Efficiency2!K56 -> 46.306004 | BB21: =BB20+BA21 -> 551.58393 | BC21: =+R21/BA21 -> 0.8536474 | BD21: =+S21/BB21 -> 0.87679494
A22: =A21+1 -> 45944 | B22: Toilet | C22: 12,5 | D22: =+'14'!F42 -> 1186.4583 | E22: =+'14'!G42 -> 934.21097 | F22: =1-(E22/D22) -> 0.21260533 | G22: =+P22/N22 -> 0.88745247 | H22: =+P22/L22 -> 0.85603689 | I22: =+R22/P22 -> 0.87421257 | J22: =+R22/L22 -> 0.74835821 | K22: =+S22/M22 -> 0.83636388 | L22: =+Efficiency1!K60 -> 46.545891 | M22: =M21+L22 -> 619.89645 | N22: =+Efficiency1!C60 -> 44.898179 | O22: =O21+N22 -> 605.15218 | P22: ='14'!I38 -> 39.845 | Q22: =Q21+P22 -> 548.473 | R22: ='14'!I40 -> 34.833 | S22: =S21+R22 -> 518.459 | T22: =+AX22 -> 4089.8407 | U22: =T22+U21 -> 58243.344 | V22: =T22/P22 -> 102.64376 | W22: =U22/Q22 -> 106.19182 | X22: =IF(AND(R22>0,T22>0),(T22/(R22*1000))*1000,0) -> 117.41282 | Y22: =IF(AND(S22>0,U22>0),U22/S22,0) -> 112.33934 | Z22: 59.7 | AA22: =Z22+AA21 -> 811.4 | AB22: =Z22/(P22) -> 1.4983059 | AC22: =AA22/(Q22) -> 1.47938 | AD22: =IF(AND(R22>0,Z22>0),Z22/(R22),0) -> 1.713892 | AE22: =IF(AND(S22>0,AA22>0),AA22/(S22),0) -> 1.5650225 | AF22: ='14'!I46 -> 37272.4 | AG22: =AF22+AG21 -> 523819.32 | AH22: =IF(AND(L22>0,AF22>0),(AF22/(P22*1000)*1000),0) -> 935.43481 | AI22: =IF(AND(M22>0,AG22>0),(AG22/(Q22*1000)*1000),0) -> 955.05033 | AJ22: =IF(AND(R22>0,AF22>0),(AF22/(R22*1000)*1000),0) -> 1070.0313 | AK22: =IF(AND(S22>0,AG22>0),(AG22/(S22*1000)*1000),0) -> 1010.3389 | AL22: 4334.3 | AM22: 5648.2 | AN22: 4354.1 | AO22: =SUM(AL22:AN22) -> 14336.6 | AP22: =+[1]Okt!N17 -> 13528 | AQ22: =+AP22-AO22 -> -808.6 | AR22: =+AL22/AO22 -> 0.30232412 | AS22: =+AM22/AO22 -> 0.39397068 | AT22: =1-AR22-AS22 -> 0.3037052 | AU22: =+AR22*AQ22 -> -244.45928 | AV22: =+AS22*AQ22 -> -318.56469 | AW22: =+AT22*AQ22 -> -245.57603 | AX22: =+AL22+AU22 -> 4089.8407 | AY22: =+AM22+AV22 -> 5329.6353 | AZ22: =+AN22+AW22 -> 4108.524 | BA22: =+Efficiency2!K60 -> 46.545891 | BB22: =BB21+BA22 -> 598.12982 | BC22: =+R22/BA22 -> 0.74835821 | BD22: =+S22/BB22 -> 0.86680012
A23: =A22+1 -> 45945 | B23: Toilet/Facial | C23: 12,5/12,5 | D23: =+'15'!F42 -> 1194.7228 | E23: =+'15'!G42 -> 919.50495 | F23: =1-(E23/D23) -> 0.23036128 | G23: =+P23/N23 -> 0.78355259 | H23: =+P23/L23 -> 0.76125701 | I23: =+R23/P23 -> 1.0134456 | J23: =+R23/L23 -> 0.77149255 | K23: =+S23/M23 -> 0.83197873 | L23: =+SUM(Efficiency1!K64:K65) -> 44.941458 | M23: =M22+L23 -> 664.83791 | N23: =+SUM(Efficiency1!C64:C65) -> 43.662672 | O23: =O22+N23 -> 648.81486 | P23: ='15'!I38 -> 34.212 | Q23: =Q22+P23 -> 582.685 | R23: ='15'!I40 -> 34.672 | S23: =S22+R23 -> 553.131 | T23: =+AX23 -> 3585.3573 | U23: =T23+U22 -> 61828.701 | V23: =T23/P23 -> 104.79824 | W23: =U23/Q23 -> 106.10999 | X23: =IF(AND(R23>0,T23>0),(T23/(R23*1000))*1000,0) -> 103.40786 | Y23: =IF(AND(S23>0,U23>0),U23/S23,0) -> 111.77949 | Z23: 57.3 | AA23: =Z23+AA22 -> 868.7 | AB23: =Z23/(P23) -> 1.6748509 | AC23: =AA23/(Q23) -> 1.490857 | AD23: =IF(AND(R23>0,Z23>0),Z23/(R23),0) -> 1.6526304 | AE23: =IF(AND(S23>0,AA23>0),AA23/(S23),0) -> 1.570514 | AF23: ='15'!I46 -> 38927.2 | AG23: =AF23+AG22 -> 562746.52 | AH23: =IF(AND(L23>0,AF23>0),(AF23/(P23*1000)*1000),0) -> 1137.823 | AI23: =IF(AND(M23>0,AG23>0),(AG23/(Q23*1000)*1000),0) -> 965.78172 | AJ23: =IF(AND(R23>0,AF23>0),(AF23/(R23*1000)*1000),0) -> 1122.7273 | AK23: =IF(AND(S23>0,AG23>0),(AG23/(S23*1000)*1000),0) -> 1017.3838 | AL23: 3727.4 | AM23: 3122.3 | AN23: 4074.6 | AO23: =SUM(AL23:AN23) -> 10924.3 | AP23: =+[1]Okt!N18 -> 10508 | AQ23: =+AP23-AO23 -> -416.3 | AR23: =+AL23/AO23 -> 0.34120264 | AS23: =+AM23/AO23 -> 0.28581236 | AT23: =1-AR23-AS23 -> 0.372985 | AU23: =+AR23*AQ23 -> -142.04266 | AV23: =+AS23*AQ23 -> -118.98369 | AW23: =+AT23*AQ23 -> -155.27365 | AX23: =+AL23+AU23 -> 3585.3573 | AY23: =+AM23+AV23 -> 3003.3163 | AZ23: =+AN23+AW23 -> 3919.3263 | BA23: =+SUM(Efficiency2!K64:K65) -> 44.941458 | BB23: =BB22+BA23 -> 643.07128 | BC23: =+R23/BA23 -> 0.77149255 | BD23: =+S23/BB23 -> 0.86013949
A24: =A23+1 -> 45946 | B24: Facial | C24: 12,5/13 | D24: =+'16'!F42 -> 1227.3958 | E24: =+'16'!G42 -> 945.09479 | F24: =1-(E24/D24) -> 0.23 | G24: =+P24/N24 -> 0.8936512 | H24: =+P24/L24 -> 0.8917769 | I24: =+R24/P24 -> 0.9525096 | J24: =+R24/L24 -> 0.84942606 | K24: =+S24/M24 -> 0.83309035 | L24: =+SUM(Efficiency1!K69:K70) -> 45.241136 | M24: =M23+L24 -> 710.07905 | N24: =+SUM(Efficiency1!C69:C70) -> 45.146249 | O24: =O23+N24 -> 693.96111 | P24: ='16'!I38 -> 40.345 | Q24: =Q23+P24 -> 623.03 | R24: ='16'!I40 -> 38.429 | S24: =S23+R24 -> 591.56 | T24: =+AX24 -> 3564.7565 | U24: =T24+U23 -> 65393.458 | V24: =T24/P24 -> 88.356834 | W24: =U24/Q24 -> 104.96037 | X24: =IF(AND(R24>0,T24>0),(T24/(R24*1000))*1000,0) -> 92.762145 | Y24: =IF(AND(S24>0,U24>0),U24/S24,0) -> 110.54408 | Z24: 62.6 | AA24: =Z24+AA23 -> 931.3 | AB24: =Z24/(P24) -> 1.5516173 | AC24: =AA24/(Q24) -> 1.4947916 | AD24: =IF(AND(R24>0,Z24>0),Z24/(R24),0) -> 1.6289781 | AE24: =IF(AND(S24>0,AA24>0),AA24/(S24),0) -> 1.574312 | AF24: ='16'!I46 -> 34790.4 | AG24: =AF24+AG23 -> 597536.92 | AH24: =IF(AND(L24>0,AF24>0),(AF24/(P24*1000)*1000),0) -> 862.32247 | AI24: =IF(AND(M24>0,AG24>0),(AG24/(Q24*1000)*1000),0) -> 959.0821 | AJ24: =IF(AND(R24>0,AF24>0),(AF24/(R24*1000)*1000),0) -> 905.3163 | AK24: =IF(AND(S24>0,AG24>0),(AG24/(S24*1000)*1000),0) -> 1010.1037 | AL24: 3787.7 | AM24: 4341.1 | AN24: 4173.3 | AO24: =SUM(AL24:AN24) -> 12302.1 | AP24: =+[1]Okt!N19 -> 11578 | AQ24: =+AP24-AO24 -> -724.1 | AR24: =+AL24/AO24 -> 0.30789052 | AS24: =+AM24/AO24 -> 0.35287471 | AT24: =1-AR24-AS24 -> 0.33923476 | AU24: =+AR24*AQ24 -> -222.94353 | AV24: =+AS24*AQ24 -> -255.51658 | AW24: =+AT24*AQ24 -> -245.63989 | AX24: =+AL24+AU24 -> 3564.7565 | AY24: =+AM24+AV24 -> 4085.5834 | AZ24: =+AN24+AW24 -> 3927.6601 | BA24: =+SUM(Efficiency2!K69:K70) -> 45.241136 | BB24: =BB23+BA24 -> 688.31242 | BC24: =+R24/BA24 -> 0.84942606 | BD24: =+S24/BB24 -> 0.85943532
A25: =A24+1 -> 45947 | B25: Facial | C25: 13/11/12 | D25: =+'17'!F42 -> 1222.8932 | E25: =+'17'!G42 -> 941.801 | F25: =1-(E25/D25) -> 0.22985831 | G25: =+P25/N25 -> 0.9051437 | H25: =+P25/L25 -> 0.89871234 | I25: =+R25/P25 -> 0.96631936 | J25: =+R25/L25 -> 0.86844313 | K25: =+S25/M25 -> 0.83503483 | L25: =+SUM(Efficiency1!K73:K75) -> 41.329131 | M25: =M24+L25 -> 751.40818 | N25: =+SUM(Efficiency1!C73:C75) -> 41.035473 | O25: =O24+N25 -> 734.99658 | P25: ='17'!I38 -> 37.143 | Q25: =Q24+P25 -> 660.173 | R25: ='17'!I40 -> 35.892 | S25: =S24+R25 -> 627.452 | T25: =+AX25 -> 3330.3376 | U25: =T25+U24 -> 68723.795 | V25: =T25/P25 -> 89.662591 | W25: =U25/Q25 -> 104.09968 | X25: =IF(AND(R25>0,T25>0),(T25/(R25*1000))*1000,0) -> 92.787741 | Y25: =IF(AND(S25>0,U25>0),U25/S25,0) -> 109.52837 | Z25: 59.3 | AA25: =Z25+AA24 -> 990.6 | AB25: =Z25/(P25) -> 1.5965323 | AC25: =AA25/(Q25) -> 1.5005158 | AD25: =IF(AND(R25>0,Z25>0),Z25/(R25),0) -> 1.6521788 | AE25: =IF(AND(S25>0,AA25>0),AA25/(S25),0) -> 1.5787662 | AF25: ='17'!I46 -> 39718.76 | AG25: =AF25+AG24 -> 637255.68 | AH25: =IF(AND(L25>0,AF25>0),(AF25/(P25*1000)*1000),0) -> 1069.3471 | AI25: =IF(AND(M25>0,AG25>0),(AG25/(Q25*1000)*1000),0) -> 965.28589 | AJ25: =IF(AND(R25>0,AF25>0),(AF25/(R25*1000)*1000),0) -> 1106.6187 | AK25: =IF(AND(S25>0,AG25>0),(AG25/(S25*1000)*1000),0) -> 1015.6246 | AL25: 3500 | AM25: 4664.2 | AN25: 4353.6 | AO25: =SUM(AL25:AN25) -> 12517.8 | AP25: =+[1]Okt!N20 -> 11911 | AQ25: =+AP25-AO25 -> -606.8 | AR25: =+AL25/AO25 -> 0.27960185 | AS25: =+AM25/AO25 -> 0.37260541 | AT25: =1-AR25-AS25 -> 0.34779274 | AU25: =+AR25*AQ25 -> -169.6624 | AV25: =+AS25*AQ25 -> -226.09696 | AW25: =+AT25*AQ25 -> -211.04064 | AX25: =+AL25+AU25 -> 3330.3376 | AY25: =+AM25+AV25 -> 4438.103 | AZ25: =+AN25+AW25 -> 4142.5594 | BA25: =+SUM(Efficiency2!K73:K75) -> 41.329131 | BB25: =BB24+BA25 -> 729.64155 | BC25: =+R25/BA25 -> 0.86844313 | BD25: =+S25/BB25 -> 0.85994555
A26: =A25+1 -> 45948 | B26: Facial | C26: 12 | D26: =+'18'!F42 -> 1223.3333 | E26: =+'18'!G42 -> 941.96667 | F26: =1-(E26/D26) -> 0.23 | G26: =+P26/N26 -> 0.88430387 | H26: =+P26/L26 -> 0.8795109 | I26: =+R26/P26 -> 0.94477772 | J26: =+R26/L26 -> 0.8309423 | K26: =+S26/M26 -> 0.83481596 | L26: =+Efficiency1!K77 -> 42.455415 | M26: =M25+L26 -> 793.86359 | N26: =+Efficiency1!C77 -> 42.225304 | O26: =O25+N26 -> 777.22188 | P26: ='18'!I38 -> 37.34 | Q26: =Q25+P26 -> 697.513 | R26: ='18'!I40 -> 35.278 | S26: =S25+R26 -> 662.73 | T26: =+AX26 -> 3170.1144 | U26: =T26+U25 -> 71893.91 | V26: =T26/P26 -> 84.898618 | W26: =U26/Q26 -> 103.07178 | X26: =IF(AND(R26>0,T26>0),(T26/(R26*1000))*1000,0) -> 89.860944 | Y26: =IF(AND(S26>0,U26>0),U26/S26,0) -> 108.48145 | Z26: 60.5 | AA26: =Z26+AA25 -> 1051.1 | AB26: =Z26/(P26) -> 1.6202464 | AC26: =AA26/(Q26) -> 1.5069253 | AD26: =IF(AND(R26>0,Z26>0),Z26/(R26),0) -> 1.7149498 | AE26: =IF(AND(S26>0,AA26>0),AA26/(S26),0) -> 1.5860154 | AF26: ='18'!I46 -> 37297.98 | AG26: =AF26+AG25 -> 674553.66 | AH26: =IF(AND(L26>0,AF26>0),(AF26/(P26*1000)*1000),0) -> 998.87467 | AI26: =IF(AND(M26>0,AG26>0),(AG26/(Q26*1000)*1000),0) -> 967.084 | AJ26: =IF(AND(R26>0,AF26>0),(AF26/(R26*1000)*1000),0) -> 1057.2589 | AK26: =IF(AND(S26>0,AG26>0),(AG26/(S26*1000)*1000),0) -> 1017.8408 | AL26: 3580.9 | AM26: 4857.2 | AN26: 4384.9 | AO26: =SUM(AL26:AN26) -> 12823 | AP26: =+[1]Okt!N21 -> 11352 | AQ26: =+AP26-AO26 -> -1471 | AR26: =+AL26/AO26 -> 0.27925602 | AS26: =+AM26/AO26 -> 0.37878812 | AT26: =1-AR26-AS26 -> 0.34195586 | AU26: =+AR26*AQ26 -> -410.78561 | AV26: =+AS26*AQ26 -> -557.19732 | AW26: =+AT26*AQ26 -> -503.01707 | AX26: =+AL26+AU26 -> 3170.1144 | AY26: =+AM26+AV26 -> 4300.0027 | AZ26: =+AN26+AW26 -> 3881.8829 | BA26: =+Efficiency2!K77 -> 42.455415 | BB26: =BB25+BA26 -> 772.09696 | BC26: =+R26/BA26 -> 0.8309423 | BD26: =+S26/BB26 -> 0.85835074
A27: =A26+1 -> 45949 | B27: Facial | C27: 12 | D27: =+'19'!F42 -> 1230 | E27: =+'19'!G42 -> 947.1 | F27: =1-(E27/D27) -> 0.23 | G27: =+P27/N27 -> 0.024691296 | H27: =+P27/L27 -> 0.024557467 | I27: =+R27/P27 -> 2.6739336 | J27: =+R27/L27 -> 0.065665039 | K27: =+S27/M27 -> 0.79532968 | L27: =+Efficiency1!K81 -> 42.960456 | M27: =M26+L27 -> 836.82405 | N27: =+Efficiency1!C81 -> 42.727608 | O27: =O26+N27 -> 819.94949 | P27: ='19'!I38 -> 1.055 | Q27: =Q26+P27 -> 698.568 | R27: ='19'!I40 -> 2.821 | S27: =S26+R27 -> 665.551 | T27: =+AX27 -> 0 | U27: =T27+U26 -> 71893.91 | V27: =T27/P27 -> 0 | W27: =U27/Q27 -> 102.91612 | X27: =IF(AND(R27>0,T27>0),(T27/(R27*1000))*1000,0) -> 0 | Y27: =IF(AND(S27>0,U27>0),U27/S27,0) -> 108.02164 | Z27: 16.7 | AA27: =Z27+AA26 -> 1067.8 | AB27: =Z27/(P27) -> 15.829384 | AC27: =AA27/(Q27) -> 1.5285556 | AD27: =IF(AND(R27>0,Z27>0),Z27/(R27),0) -> 5.9198866 | AE27: =IF(AND(S27>0,AA27>0),AA27/(S27),0) -> 1.6043849 | AF27: ='19'!I46 -> 8166.58 | AG27: =AF27+AG26 -> 682720.24 | AH27: =IF(AND(L27>0,AF27>0),(AF27/(P27*1000)*1000),0) -> 7740.8341 | AI27: =IF(AND(M27>0,AG27>0),(AG27/(Q27*1000)*1000),0) -> 977.31393 | AJ27: =IF(AND(R27>0,AF27>0),(AF27/(R27*1000)*1000),0) -> 2894.9238 | AK27: =IF(AND(S27>0,AG27>0),(AG27/(S27*1000)*1000),0) -> 1025.797 | AL27: 0 | AM27: 5204 | AN27: 4519.6 | AO27: =SUM(AL27:AN27) -> 9723.6 | AP27: =+[1]Okt!N22 -> 10235 | AQ27: =+AP27-AO27 -> 511.4 | AR27: =+AL27/AO27 -> 0 | AS27: =+AM27/AO27 -> 0.53519273 | AT27: =1-AR27-AS27 -> 0.46480727 | AU27: =+AR27*AQ27 -> 0 | AV27: =+AS27*AQ27 -> 273.69756 | AW27: =+AT27*AQ27 -> 237.70244 | AX27: =+AL27+AU27 -> 0 | AY27: =+AM27+AV27 -> 5477.6976 | AZ27: =+AN27+AW27 -> 4757.3024 | BA27: =+Efficiency2!K81 -> 0.7756749 | BB27: =BB26+BA27 -> 772.87264 | BC27: =+R27/BA27 -> 3.6368329 | BD27: =+S27/BB27 -> 0.8611393
A28: =A27+1 -> 45950 | B28: Facial | C28: 12 | D28: =+'20'!F42 -> 0 | E28: =+'20'!G42 -> 0 | F28: =1-(E28/D28) -> #DIV/0! | G28: =+P28/N28 -> 0 | H28: =+P28/L28 -> 0 | I28: =+R28/P28 -> #DIV/0! | J28: =+R28/L28 -> 0 | K28: =+S28/M28 -> 0.75649321 | L28: =+Efficiency1!K86 -> 42.960456 | M28: =M27+L28 -> 879.78451 | N28: =+Efficiency1!C86 -> 42.727608 | O28: =O27+N28 -> 862.6771 | P28: ='20'!I38 -> 0 | Q28: =Q27+P28 -> 698.568 | R28: ='20'!I40 -> 0 | S28: =S27+R28 -> 665.551 | T28: =+AX28 -> 0 | U28: =T28+U27 -> 71893.91 | V28: =T28/P28 -> #DIV/0! | W28: =U28/Q28 -> 102.91612 | X28: =IF(AND(R28>0,T28>0),(T28/(R28*1000))*1000,0) -> 0 | Y28: =IF(AND(S28>0,U28>0),U28/S28,0) -> 108.02164 | Z28: 34.2 | AA28: =Z28+AA27 -> 1102 | AB28: =Z28/(P28) -> #DIV/0! | AC28: =AA28/(Q28) -> 1.5775129 | AD28: =IF(AND(R28>0,Z28>0),Z28/(R28),0) -> 0 | AE28: =IF(AND(S28>0,AA28>0),AA28/(S28),0) -> 1.6557709 | AF28: ='20'!I46 -> 5005.22 | AG28: =AF28+AG27 -> 687725.46 | AH28: =IF(AND(L28>0,AF28>0),(AF28/(P28*1000)*1000),0) -> #DIV/0! | AI28: =IF(AND(M28>0,AG28>0),(AG28/(Q28*1000)*1000),0) -> 984.47891 | AJ28: =IF(AND(R28>0,AF28>0),(AF28/(R28*1000)*1000),0) -> 0 | AK28: =IF(AND(S28>0,AG28>0),(AG28/(S28*1000)*1000),0) -> 1033.3174 | AL28: 0 | AM28: 5534.8 | AN28: 4526.7 | AO28: =SUM(AL28:AN28) -> 10061.5 | AP28: =+[1]Okt!N23 -> 10155 | AQ28: =+AP28-AO28 -> 93.5 | AR28: =+AL28/AO28 -> 0 | AS28: =+AM28/AO28 -> 0.5500969 | AT28: =1-AR28-AS28 -> 0.4499031 | AU28: =+AR28*AQ28 -> 0 | AV28: =+AS28*AQ28 -> 51.434061 | AW28: =+AT28*AQ28 -> 42.065939 | AX28: =+AL28+AU28 -> 0 | AY28: =+AM28+AV28 -> 5586.2341 | AZ28: =+AN28+AW28 -> 4568.7659 | BA28: =+Efficiency2!K86 -> 0 | BB28: =BB27+BA28 -> 772.87264 | BC28: =+R28/BA28 -> #DIV/0! | BD28: =+S28/BB28 -> 0.8611393
A29: =A28+1 -> 45951 | B29: Facial | C29: 12 | D29: =+'21'!F42 -> 0 | E29: =+'21'!G42 -> 0 | F29: =1-(E29/D29) -> #DIV/0! | G29: =+P29/N29 -> 0 | H29: =+P29/L29 -> 0 | I29: =+R29/P29 -> #DIV/0! | J29: =+R29/L29 -> 0 | K29: =+S29/M29 -> 0.72127297 | L29: =+Efficiency1!K91 -> 42.960456 | M29: =M28+L29 -> 922.74496 | N29: =+Efficiency1!C91 -> 42.727608 | O29: =O28+N29 -> 905.40471 | P29: ='21'!I38 -> 0 | Q29: =Q28+P29 -> 698.568 | R29: ='21'!I40 -> 0 | S29: =S28+R29 -> 665.551 | T29: =+AX29 -> 0 | U29: =T29+U28 -> 71893.91 | V29: =T29/P29 -> #DIV/0! | W29: =U29/Q29 -> 102.91612 | X29: =IF(AND(R29>0,T29>0),(T29/(R29*1000))*1000,0) -> 0 | Y29: =IF(AND(S29>0,U29>0),U29/S29,0) -> 108.02164 | Z29: 36.9 | AA29: =Z29+AA28 -> 1138.9 | AB29: =Z29/(P29) -> #DIV/0! | AC29: =AA29/(Q29) -> 1.6303352 | AD29: =IF(AND(R29>0,Z29>0),Z29/(R29),0) -> 0 | AE29: =IF(AND(S29>0,AA29>0),AA29/(S29),0) -> 1.7112137 | AF29: ='21'!I46 -> 6204.86 | AG29: =AF29+AG28 -> 693930.32 | AH29: =IF(AND(L29>0,AF29>0),(AF29/(P29*1000)*1000),0) -> #DIV/0! | AI29: =IF(AND(M29>0,AG29>0),(AG29/(Q29*1000)*1000),0) -> 993.36116 | AJ29: =IF(AND(R29>0,AF29>0),(AF29/(R29*1000)*1000),0) -> 0 | AK29: =IF(AND(S29>0,AG29>0),(AG29/(S29*1000)*1000),0) -> 1042.6403 | AL29: 0 | AM29: 5595.2 | AN29: 4367.9 | AO29: =SUM(AL29:AN29) -> 9963.1 | AP29: =+[1]Okt!N24 -> 10321 | AQ29: =+AP29-AO29 -> 357.9 | AR29: =+AL29/AO29 -> 0 | AS29: =+AM29/AO29 -> 0.56159228 | AT29: =1-AR29-AS29 -> 0.43840772 | AU29: =+AR29*AQ29 -> 0 | AV29: =+AS29*AQ29 -> 200.99388 | AW29: =+AT29*AQ29 -> 156.90612 | AX29: =+AL29+AU29 -> 0 | AY29: =+AM29+AV29 -> 5796.1939 | AZ29: =+AN29+AW29 -> 4524.8061 | BA29: =+Efficiency2!K91 -> 0 | BB29: =BB28+BA29 -> 772.87264 | BC29: =+R29/BA29 -> #DIV/0! | BD29: =+S29/BB29 -> 0.8611393
A30: =A29+1 -> 45952 | B30: Facial | C30: 12 | D30: =+'22'!F42 -> 0 | E30: =+'22'!G42 -> 0 | F30: =1-(E30/D30) -> #DIV/0! | G30: =+P30/N30 -> 0 | H30: =+P30/L30 -> 0 | I30: =+R30/P30 -> #DIV/0! | J30: =+R30/L30 -> 0 | K30: =+S30/M30 -> 0.68918636 | L30: =+Efficiency1!K96 -> 42.960456 | M30: =M29+L30 -> 965.70542 | N30: =+Efficiency1!C96 -> 42.727608 | O30: =O29+N30 -> 948.13232 | P30: ='22'!I38 -> 0 | Q30: =Q29+P30 -> 698.568 | R30: ='22'!I40 -> 0 | S30: =S29+R30 -> 665.551 | T30: =+AX30 -> 0 | U30: =T30+U29 -> 71893.91 | V30: =T30/P30 -> #DIV/0! | W30: =U30/Q30 -> 102.91612 | X30: =IF(AND(R30>0,T30>0),(T30/(R30*1000))*1000,0) -> 0 | Y30: =IF(AND(S30>0,U30>0),U30/S30,0) -> 108.02164 | Z30: 16.9 | AA30: =Z30+AA29 -> 1155.8 | AB30: =Z30/(P30) -> #DIV/0! | AC30: =AA30/(Q30) -> 1.6545275 | AD30: =IF(AND(R30>0,Z30>0),Z30/(R30),0) -> 0 | AE30: =IF(AND(S30>0,AA30>0),AA30/(S30),0) -> 1.7366062 | AF30: ='22'!I46 -> 6077.48 | AG30: =AF30+AG29 -> 700007.8 | AH30: =IF(AND(L30>0,AF30>0),(AF30/(P30*1000)*1000),0) -> #DIV/0! | AI30: =IF(AND(M30>0,AG30>0),(AG30/(Q30*1000)*1000),0) -> 1002.0611 | AJ30: =IF(AND(R30>0,AF30>0),(AF30/(R30*1000)*1000),0) -> 0 | AK30: =IF(AND(S30>0,AG30>0),(AG30/(S30*1000)*1000),0) -> 1051.7718 | AL30: 0 | AM30: 5494.5 | AN30: 4432.7 | AO30: =SUM(AL30:AN30) -> 9927.2 | AP30: =+[1]Okt!N25 -> 10307 | AQ30: =+AP30-AO30 -> 379.8 | AR30: =+AL30/AO30 -> 0 | AS30: =+AM30/AO30 -> 0.55347933 | AT30: =1-AR30-AS30 -> 0.44652067 | AU30: =+AR30*AQ30 -> 0 | AV30: =+AS30*AQ30 -> 210.21145 | AW30: =+AT30*AQ30 -> 169.58855 | AX30: =+AL30+AU30 -> 0 | AY30: =+AM30+AV30 -> 5704.7114 | AZ30: =+AN30+AW30 -> 4602.2886 | BA30: =+Efficiency2!K96 -> 0 | BB30: =BB29+BA30 -> 772.87264 | BC30: =+R30/BA30 -> #DIV/0! | BD30: =+S30/BB30 -> 0.8611393
A31: =A30+1 -> 45953 | B31: Facial | C31: 12 | D31: =+'23'!F42 -> 0 | E31: =+'23'!G42 -> 0 | F31: =1-(E31/D31) -> #DIV/0! | G31: =+P31/N31 -> 0 | H31: =+P31/L31 -> 0 | I31: =+R31/P31 -> #DIV/0! | J31: =+R31/L31 -> 0 | K31: =+S31/M31 -> 0.65983297 | L31: =+Efficiency1!K101 -> 42.960456 | M31: =M30+L31 -> 1008.6659 | N31: =+Efficiency1!C101 -> 42.727608 | O31: =O30+N31 -> 990.85992 | P31: ='23'!I38 -> 0 | Q31: =Q30+P31 -> 698.568 | R31: ='23'!I40 -> 0 | S31: =S30+R31 -> 665.551 | T31: =+AX31 -> 0 | U31: =T31+U30 -> 71893.91 | V31: =T31/P31 -> #DIV/0! | W31: =U31/Q31 -> 102.91612 | X31: =IF(AND(R31>0,T31>0),(T31/(R31*1000))*1000,0) -> 0 | Y31: =IF(AND(S31>0,U31>0),U31/S31,0) -> 108.02164 | Z31: 17.2 | AA31: =Z31+AA30 -> 1173 | AB31: =Z31/(P31) -> #DIV/0! | AC31: =AA31/(Q31) -> 1.6791493 | AD31: =IF(AND(R31>0,Z31>0),Z31/(R31),0) -> 0 | AE31: =IF(AND(S31>0,AA31>0),AA31/(S31),0) -> 1.7624495 | AF31: ='23'!I46 -> 4543.94 | AG31: =AF31+AG30 -> 704551.74 | AH31: =IF(AND(L31>0,AF31>0),(AF31/(P31*1000)*1000),0) -> #DIV/0! | AI31: =IF(AND(M31>0,AG31>0),(AG31/(Q31*1000)*1000),0) -> 1008.5657 | AJ31: =IF(AND(R31>0,AF31>0),(AF31/(R31*1000)*1000),0) -> 0 | AK31: =IF(AND(S31>0,AG31>0),(AG31/(S31*1000)*1000),0) -> 1058.5992 | AL31: 0 | AM31: 5482.2 | AN31: 4481.7 | AO31: =SUM(AL31:AN31) -> 9963.9 | AP31: =+[1]Okt!N26 -> 10405 | AQ31: =+AP31-AO31 -> 441.1 | AR31: =+AL31/AO31 -> 0 | AS31: =+AM31/AO31 -> 0.55020624 | AT31: =1-AR31-AS31 -> 0.44979376 | AU31: =+AR31*AQ31 -> 0 | AV31: =+AS31*AQ31 -> 242.69597 | AW31: =+AT31*AQ31 -> 198.40403 | AX31: =+AL31+AU31 -> 0 | AY31: =+AM31+AV31 -> 5724.896 | AZ31: =+AN31+AW31 -> 4680.104 | BA31: =+Efficiency2!K101 -> 0 | BB31: =BB30+BA31 -> 772.87264 | BC31: =+R31/BA31 -> #DIV/0! | BD31: =+S31/BB31 -> 0.8611393
A32: =A31+1 -> 45954 | B32: Facial | C32: 12 | D32: =+'24'!F42 -> 0 | E32: =+'24'!G42 -> 0 | F32: =1-(E32/D32) -> #DIV/0! | G32: =+P32/N32 -> 0 | H32: =+P32/L32 -> 0 | I32: =+R32/P32 -> #DIV/0! | J32: =+R32/L32 -> 0 | K32: =+S32/M32 -> 0.63287784 | L32: =+Efficiency1!K106 -> 42.960456 | M32: =M31+L32 -> 1051.6263 | N32: =+Efficiency1!C106 -> 42.727608 | O32: =O31+N32 -> 1033.5875 | P32: ='24'!I38 -> 0 | Q32: =Q31+P32 -> 698.568 | R32: ='24'!I40 -> 0 | S32: =S31+R32 -> 665.551 | T32: =+AX32 -> 0 | U32: =T32+U31 -> 71893.91 | V32: =T32/P32 -> #DIV/0! | W32: =U32/Q32 -> 102.91612 | X32: =IF(AND(R32>0,T32>0),(T32/(R32*1000))*1000,0) -> 0 | Y32: =IF(AND(S32>0,U32>0),U32/S32,0) -> 108.02164 | Z32: 17.2 | AA32: =Z32+AA31 -> 1190.2 | AB32: =Z32/(P32) -> #DIV/0! | AC32: =AA32/(Q32) -> 1.7037711 | AD32: =IF(AND(R32>0,Z32>0),Z32/(R32),0) -> 0 | AE32: =IF(AND(S32>0,AA32>0),AA32/(S32),0) -> 1.7882927 | AF32: =+'24'!I46 -> 7185.46 | AG32: =AF32+AG31 -> 711737.2 | AH32: =IF(AND(L32>0,AF32>0),(AF32/(P32*1000)*1000),0) -> #DIV/0! | AI32: =IF(AND(M32>0,AG32>0),(AG32/(Q32*1000)*1000),0) -> 1018.8517 | AJ32: =IF(AND(R32>0,AF32>0),(AF32/(R32*1000)*1000),0) -> 0 | AK32: =IF(AND(S32>0,AG32>0),(AG32/(S32*1000)*1000),0) -> 1069.3954 | AL32: 0 | AM32: 5473.8 | AN32: 4361.8 | AO32: =SUM(AL32:AN32) -> 9835.6 | AP32: =+[1]Okt!N27 -> 9612 | AQ32: =+AP32-AO32 -> -223.6 | AR32: =+AL32/AO32 -> 0 | AS32: =+AM32/AO32 -> 0.55652934 | AT32: =1-AR32-AS32 -> 0.44347066 | AU32: =+AR32*AQ32 -> 0 | AV32: =+AS32*AQ32 -> -124.43996 | AW32: =+AT32*AQ32 -> -99.160039 | AX32: =+AL32+AU32 -> 0 | AY32: =+AM32+AV32 -> 5349.36 | AZ32: =+AN32+AW32 -> 4262.64 | BA32: =+Efficiency2!K106 -> 0 | BB32: =BB31+BA32 -> 772.87264 | BC32: =+R32/BA32 -> #DIV/0! | BD32: =+S32/BB32 -> 0.8611393
A33: =A32+1 -> 45955 | B33: Facial | C33: 12 | D33: =+'25'!F42 -> 0 | E33: =+'25'!G42 -> 0 | F33: =1-(E33/D33) -> #DIV/0! | G33: =+P33/N33 -> 0 | H33: =+P33/L33 -> 0 | I33: =+R33/P33 -> #DIV/0! | J33: =+R33/L33 -> 0 | K33: =+S33/M33 -> 0.60803859 | L33: =+Efficiency1!K111 -> 42.960456 | M33: =M32+L33 -> 1094.5868 | N33: =+Efficiency1!C111 -> 42.727608 | O33: =O32+N33 -> 1076.3151 | P33: ='25'!I38 -> 0 | Q33: =Q32+P33 -> 698.568 | R33: ='25'!I40 -> 0 | S33: =S32+R33 -> 665.551 | T33: =+AX33 -> 0 | U33: =T33+U32 -> 71893.91 | V33: =T33/P33 -> #DIV/0! | W33: =U33/Q33 -> 102.91612 | X33: =IF(AND(R33>0,T33>0),(T33/(R33*1000))*1000,0) -> 0 | Y33: =IF(AND(S33>0,U33>0),U33/S33,0) -> 108.02164 | Z33: 13.7 | AA33: =Z33+AA32 -> 1203.9 | AB33: =Z33/(P33) -> #DIV/0! | AC33: =AA33/(Q33) -> 1.7233827 | AD33: =IF(AND(R33>0,Z33>0),Z33/(R33),0) -> 0 | AE33: =IF(AND(S33>0,AA33>0),AA33/(S33),0) -> 1.8088772 | AF33: =+'25'!I46 -> 5950.64 | AG33: =AF33+AG32 -> 717687.84 | AH33: =IF(AND(L33>0,AF33>0),(AF33/(P33*1000)*1000),0) -> #DIV/0! | AI33: =IF(AND(M33>0,AG33>0),(AG33/(Q33*1000)*1000),0) -> 1027.37 | AJ33: =IF(AND(R33>0,AF33>0),(AF33/(R33*1000)*1000),0) -> 0 | AK33: =IF(AND(S33>0,AG33>0),(AG33/(S33*1000)*1000),0) -> 1078.3364 | AL33: 0 | AM33: 4273 | AN33: 3610.5 | AO33: =SUM(AL33:AN33) -> 7883.5 | AP33: =+[1]Okt!N28 -> 6796 | AQ33: =+AP33-AO33 -> -1087.5 | AR33: =+AL33/AO33 -> 0 | AS33: =+AM33/AO33 -> 0.54201814 | AT33: =1-AR33-AS33 -> 0.45798186 | AU33: =+AR33*AQ33 -> 0 | AV33: =+AS33*AQ33 -> -589.44473 | AW33: =+AT33*AQ33 -> -498.05527 | AX33: =+AL33+AU33 -> 0 | AY33: =+AM33+AV33 -> 3683.5553 | AZ33: =+AN33+AW33 -> 3112.4447 | BA33: =+Efficiency2!K111 -> 0 | BB33: =BB32+BA33 -> 772.87264 | BC33: =+R33/BA33 -> #DIV/0! | BD33: =+S33/BB33 -> 0.8611393
A34: =A33+1 -> 45956 | B34: Facial | C34: 12 | D34: =+'26'!F42 -> 0 | E34: =+'26'!G42 -> 0 | F34: =1-(E34/D34) -> #DIV/0! | G34: =+P34/N34 -> 0 | H34: =+P34/L34 -> 0 | I34: =+R34/P34 -> #DIV/0! | J34: =+R34/L34 -> 0 | K34: =+S34/M34 -> 0.58507548 | L34: =+Efficiency1!K116 -> 42.960456 | M34: =M33+L34 -> 1137.5472 | N34: =+Efficiency1!C116 -> 42.727608 | O34: =O33+N34 -> 1119.0427 | P34: ='26'!I38 -> 0 | Q34: =Q33+P34 -> 698.568 | R34: ='26'!I40 -> 0 | S34: =S33+R34 -> 665.551 | T34: =+AX34 -> 87.298903 | U34: =T34+U33 -> 71981.209 | V34: =T34/P34 -> #DIV/0! | W34: =U34/Q34 -> 103.04109 | X34: =IF(AND(R34>0,T34>0),(T34/(R34*1000))*1000,0) -> 0 | Y34: =IF(AND(S34>0,U34>0),U34/S34,0) -> 108.15281 | Z34: 27 | AA34: =Z34+AA33 -> 1230.9 | AB34: =Z34/(P34) -> #DIV/0! | AC34: =AA34/(Q34) -> 1.7620332 | AD34: =IF(AND(R34>0,Z34>0),Z34/(R34),0) -> 0 | AE34: =IF(AND(S34>0,AA34>0),AA34/(S34),0) -> 1.849445 | AF34: ='26'!I46 -> 4700.22 | AG34: =AF34+AG33 -> 722388.06 | AH34: =IF(AND(L34>0,AF34>0),(AF34/(P34*1000)*1000),0) -> #DIV/0! | AI34: =IF(AND(M34>0,AG34>0),(AG34/(Q34*1000)*1000),0) -> 1034.0984 | AJ34: =IF(AND(R34>0,AF34>0),(AF34/(R34*1000)*1000),0) -> 0 | AK34: =IF(AND(S34>0,AG34>0),(AG34/(S34*1000)*1000),0) -> 1085.3985 | AL34: 58.8 | AM34: 1243.1 | AN34: 831.9 | AO34: =SUM(AL34:AN34) -> 2133.8 | AP34: =+[1]Okt!N29 -> 3168 | AQ34: =+AP34-AO34 -> 1034.2 | AR34: =+AL34/AO34 -> 0.027556472 | AS34: =+AM34/AO34 -> 0.58257569 | AT34: =1-AR34-AS34 -> 0.38986784 | AU34: =+AR34*AQ34 -> 28.498903 | AV34: =+AS34*AQ34 -> 602.49978 | AW34: =+AT34*AQ34 -> 403.20132 | AX34: =+AL34+AU34 -> 87.298903 | AY34: =+AM34+AV34 -> 1845.5998 | AZ34: =+AN34+AW34 -> 1235.1013 | BA34: =+Efficiency2!K116 -> 0 | BB34: =BB33+BA34 -> 772.87264 | BC34: =+R34/BA34 -> #DIV/0! | BD34: =+S34/BB34 -> 0.8611393
A35: =A34+1 -> 45957 | B35: Facial | C35: 14 | D35: =+'27'!F42 -> 887.89474 | E35: =+'27'!G42 -> 698.04737 | F35: =1-(E35/D35) -> 0.21381743 | G35: =+P35/N35 -> 0.54021551 | H35: =+P35/L35 -> 0.38996301 | I35: =+R35/P35 -> 0.71526061 | J35: =+R35/L35 -> 0.27892518 | K35: =+S35/M35 -> 0.57172779 | L35: =+Efficiency1!K121 -> 51.8562 | M35: =M34+L35 -> 1189.4034 | N35: =+Efficiency1!C121 -> 37.433209 | O35: =O34+N35 -> 1156.476 | P35: ='27'!I38 -> 20.222 | Q35: =Q34+P35 -> 718.79 | R35: ='27'!I40 -> 14.464 | S35: =S34+R35 -> 680.015 | T35: =+AX35 -> 2773.7318 | U35: =T35+U34 -> 74754.941 | V35: =T35/P35 -> 137.16407 | W35: =U35/Q35 -> 104.00109 | X35: =IF(AND(R35>0,T35>0),(T35/(R35*1000))*1000,0) -> 191.76796 | Y35: =IF(AND(S35>0,U35>0),U35/S35,0) -> 109.93131 | Z35: 46.5 | AA35: =Z35+AA34 -> 1277.4 | AB35: =Z35/(P35) -> 2.2994758 | AC35: =AA35/(Q35) -> 1.7771533 | AD35: =IF(AND(R35>0,Z35>0),Z35/(R35),0) -> 3.2148783 | AE35: =IF(AND(S35>0,AA35>0),AA35/(S35),0) -> 1.878488 | AF35: ='27'!I46 -> 23771.82 | AG35: =AF35+AG34 -> 746159.88 | AH35: =IF(AND(L35>0,AF35>0),(AF35/(P35*1000)*1000),0) -> 1175.5425 | AI35: =IF(AND(M35>0,AG35>0),(AG35/(Q35*1000)*1000),0) -> 1038.0777 | AJ35: =IF(AND(R35>0,AF35>0),(AF35/(R35*1000)*1000),0) -> 1643.5163 | AK35: =IF(AND(S35>0,AG35>0),(AG35/(S35*1000)*1000),0) -> 1097.2697 | AL35: 2893.7 | AM35: 5928.5 | AN35: 3421.4 | AO35: =SUM(AL35:AN35) -> 12243.6 | AP35: =+[1]Okt!N30 -> 11736 | AQ35: =+AP35-AO35 -> -507.6 | AR35: =+AL35/AO35 -> 0.23634389 | AS35: =+AM35/AO35 -> 0.48421216 | AT35: =1-AR35-AS35 -> 0.27944395 | AU35: =+AR35*AQ35 -> -119.96816 | AV35: =+AS35*AQ35 -> -245.78609 | AW35: =+AT35*AQ35 -> -141.84575 | AX35: =+AL35+AU35 -> 2773.7318 | AY35: =+AM35+AV35 -> 5682.7139 | AZ35: =+AN35+AW35 -> 3279.5542 | BA35: =+Efficiency2!K121 -> 32.84226 | BB35: =BB34+BA35 -> 805.7149 | BC35: =+R35/BA35 -> 0.44040818 | BD35: =+S35/BB35 -> 0.84398961
A36: =A35+1 -> 45958 | B36: Facial | C36: 14/12 | D36: =+'28'!F42 -> 734.59399 | E36: =+'28'!G42 -> 587.67519 | F36: =1-(E36/D36) -> 0.2 | G36: =+P36/N36 -> 0.54688352 | H36: =+P36/L36 -> 0.33788475 | I36: =+R36/P36 -> 0.60445633 | J36: =+R36/L36 -> 0.20423658 | K36: =+S36/M36 -> 0.55695657 | L36: =+SUM(Efficiency1!K126:K127) -> 49.809883 | M36: =M35+L36 -> 1239.2133 | N36: =+SUM(Efficiency1!C126:C127) -> 30.774378 | O36: =O35+N36 -> 1187.2503 | P36: ='28'!I38 -> 16.83 | Q36: =Q35+P36 -> 735.62 | R36: ='28'!I40 -> 10.173 | S36: =S35+R36 -> 690.188 | T36: =+AX36 -> 1947.9531 | U36: =T36+U35 -> 76702.894 | V36: =T36/P36 -> 115.74291 | W36: =U36/Q36 -> 104.26972 | X36: =IF(AND(R36>0,T36>0),(T36/(R36*1000))*1000,0) -> 191.48266 | Y36: =IF(AND(S36>0,U36>0),U36/S36,0) -> 111.13333 | Z36: 37.5 | AA36: =Z36+AA35 -> 1314.9 | AB36: =Z36/(P36) -> 2.228164 | AC36: =AA36/(Q36) -> 1.7874718 | AD36: =IF(AND(R36>0,Z36>0),Z36/(R36),0) -> 3.6862283 | AE36: =IF(AND(S36>0,AA36>0),AA36/(S36),0) -> 1.9051331 | AF36: ='28'!I46 -> 19308.78 | AG36: =AF36+AG35 -> 765468.66 | AH36: =IF(AND(L36>0,AF36>0),(AF36/(P36*1000)*1000),0) -> 1147.2834 | AI36: =IF(AND(M36>0,AG36>0),(AG36/(Q36*1000)*1000),0) -> 1040.5762 | AJ36: =IF(AND(R36>0,AF36>0),(AF36/(R36*1000)*1000),0) -> 1898.0419 | AK36: =IF(AND(S36>0,AG36>0),(AG36/(S36*1000)*1000),0) -> 1109.0727 | AL36: 2015.8 | AM36: 6051.2 | AN36: 4126.4 | AO36: =SUM(AL36:AN36) -> 12193.4 | AP36: =+[1]Okt!N31 -> 11783 | AQ36: =+AP36-AO36 -> -410.4 | AR36: =+AL36/AO36 -> 0.16531894 | AS36: =+AM36/AO36 -> 0.49626847 | AT36: =1-AR36-AS36 -> 0.33841258 | AU36: =+AR36*AQ36 -> -67.846894 | AV36: =+AS36*AQ36 -> -203.66858 | AW36: =+AT36*AQ36 -> -138.88452 | AX36: =+AL36+AU36 -> 1947.9531 | AY36: =+AM36+AV36 -> 5847.5314 | AZ36: =+AN36+AW36 -> 3987.5155 | BA36: =+SUM(Efficiency2!K126:K127) -> 49.809883 | BB36: =BB35+BA36 -> 855.52478 | BC36: =+R36/BA36 -> 0.20423658 | BD36: =+S36/BB36 -> 0.80674227
A37: =A36+1 -> 45959 | B37: Facial | C37: 12 | D37: =+'29'!F42 -> 700 | E37: =+'29'!G42 -> 560 | F37: =1-(E37/D37) -> 0.2 | G37: =+P37/N37 -> 0.2846122 | H37: =+P37/L37 -> 0.16197442 | I37: =+R37/P37 -> 1.4200109 | J37: =+R37/L37 -> 0.23000545 | K37: =+S37/M37 -> 0.54544357 | L37: =+Efficiency1!K131 -> 45.229363 | M37: =M36+L37 -> 1284.4427 | N37: =+Efficiency1!C131 -> 25.740288 | O37: =O36+N37 -> 1212.9906 | P37: ='29'!I38 -> 7.326 | Q37: =Q36+P37 -> 742.946 | R37: ='29'!I40 -> 10.403 | S37: =S36+R37 -> 700.591 | T37: =+AX37 -> 589.01261 | U37: =T37+U36 -> 77291.906 | V37: =T37/P37 -> 80.400302 | W37: =U37/Q37 -> 104.03435 | X37: =IF(AND(R37>0,T37>0),(T37/(R37*1000))*1000,0) -> 56.619495 | Y37: =IF(AND(S37>0,U37>0),U37/S37,0) -> 110.32386 | Z37: 13.9 | AA37: =Z37+AA36 -> 1328.8 | AB37: =Z37/(P37) -> 1.8973519 | AC37: =AA37/(Q37) -> 1.7885553 | AD37: =IF(AND(R37>0,Z37>0),Z37/(R37),0) -> 1.336153 | AE37: =IF(AND(S37>0,AA37>0),AA37/(S37),0) -> 1.8966844 | AF37: ='29'!I46 -> 14019.16 | AG37: =AF37+AG36 -> 779487.82 | AH37: =IF(AND(L37>0,AF37>0),(AF37/(P37*1000)*1000),0) -> 1913.6173 | AI37: =IF(AND(M37>0,AG37>0),(AG37/(Q37*1000)*1000),0) -> 1049.185 | AJ37: =IF(AND(R37>0,AF37>0),(AF37/(R37*1000)*1000),0) -> 1347.6074 | AK37: =IF(AND(S37>0,AG37>0),(AG37/(S37*1000)*1000),0) -> 1112.6147 | AL37: 610.6 | AM37: 5759.2 | AN37: 4288 | AO37: =SUM(AL37:AN37) -> 10657.8 | AP37: =+[1]Okt!N32 -> 10281 | AQ37: =+AP37-AO37 -> -376.8 | AR37: =+AL37/AO37 -> 0.057291373 | AS37: =+AM37/AO37 -> 0.54037419 | AT37: =1-AR37-AS37 -> 0.40233444 | AU37: =+AR37*AQ37 -> -21.58739 | AV37: =+AS37*AQ37 -> -203.61299 | AW37: =+AT37*AQ37 -> -151.59962 | AX37: =+AL37+AU37 -> 589.01261 | AY37: =+AM37+AV37 -> 5555.587 | AZ37: =+AN37+AW37 -> 4136.4004 | BA37: =+Efficiency2!K131 -> 12.092573 | BB37: =BB36+BA37 -> 867.61735 | BC37: =+R37/BA37 -> 0.86028012 | BD37: =+S37/BB37 -> 0.80748846
A38: =A37+1 -> 45960 | B38: Facial | C38: 12 | D38: =+'30'!F42 -> 0 | E38: =+'30'!G42 -> 0 | F38: =1-(E38/D38) -> #DIV/0! | G38: =+P38/N38 -> 0 | H38: =+P38/L38 -> 0 | I38: =+R38/P38 -> #DIV/0! | J38: =+R38/L38 -> 0 | K38: =+S38/M38 -> 0.52756302 | L38: =+Efficiency1!K136 -> 43.533262 | M38: =M37+L38 -> 1327.9759 | N38: =+Efficiency1!C136 -> 43.297309 | O38: =O37+N38 -> 1256.2879 | P38: ='30'!I38 -> 0 | Q38: =Q37+P38 -> 742.946 | R38: ='30'!I40 -> 0 | S38: =S37+R38 -> 700.591 | T38: =+AX38 -> 0 | U38: =T38+U37 -> 77291.906 | V38: =T38/P38 -> #DIV/0! | W38: =U38/Q38 -> 104.03435 | X38: =IF(AND(R38>0,T38>0),(T38/(R38*1000))*1000,0) -> 0 | Y38: =IF(AND(S38>0,U38>0),U38/S38,0) -> 110.32386 | Z38: 14.4 | AA38: =Z38+AA37 -> 1343.2 | AB38: =Z38/(P38) -> #DIV/0! | AC38: =AA38/(Q38) -> 1.8079376 | AD38: =IF(AND(R38>0,Z38>0),Z38/(R38),0) -> 0 | AE38: =IF(AND(S38>0,AA38>0),AA38/(S38),0) -> 1.9172384 | AF38: ='30'!I46 -> 5070.6 | AG38: =AF38+AG37 -> 784558.42 | AH38: =IF(AND(L38>0,AF38>0),(AF38/(P38*1000)*1000),0) -> #DIV/0! | AI38: =IF(AND(M38>0,AG38>0),(AG38/(Q38*1000)*1000),0) -> 1056.01 | AJ38: =IF(AND(R38>0,AF38>0),(AF38/(R38*1000)*1000),0) -> 0 | AK38: =IF(AND(S38>0,AG38>0),(AG38/(S38*1000)*1000),0) -> 1119.8523 | AL38: 0 | AM38: 5794.8 | AN38: 4261.5 | AO38: =SUM(AL38:AN38) -> 10056.3 | AP38: =+[1]Okt!N33 -> 9687 | AQ38: =+AP38-AO38 -> -369.3 | AR38: =+AL38/AO38 -> 0 | AS38: =+AM38/AO38 -> 0.57623579 | AT38: =1-AR38-AS38 -> 0.42376421 | AU38: =+AR38*AQ38 -> 0 | AV38: =+AS38*AQ38 -> -212.80388 | AW38: =+AT38*AQ38 -> -156.49612 | AX38: =+AL38+AU38 -> 0 | AY38: =+AM38+AV38 -> 5581.9961 | AZ38: =+AN38+AW38 -> 4105.0039 | BA38: =+Efficiency2!K136 -> 0 | BB38: =BB37+BA38 -> 867.61735 | BC38: =+R38/BA38 -> #DIV/0! | BD38: =+S38/BB38 -> 0.80748846
A39: =A38+1 -> 45961 | B39: Facial | C39: 12 | D39: =+'31'!F42 -> 0 | E39: =+'31'!G42 -> 0 | F39: =1-(E39/D39) -> #DIV/0! | G39: =+P39/N39 -> 0 | H39: =+P39/L39 -> 0 | I39: =+R39/P39 -> #DIV/0! | J39: =+R39/L39 -> 0 | K39: =+S39/M39 -> 0.51081757 | L39: =+Efficiency1!K141 -> 43.533262 | M39: =M38+L39 -> 1371.5092 | N39: =+Efficiency1!C141 -> 43.297309 | O39: =O38+N39 -> 1299.5852 | P39: ='31'!I38 -> 0 | Q39: =Q38+P39 -> 742.946 | R39: ='31'!I40 -> 0 | S39: =S38+R39 -> 700.591 | T39: =+AX39 -> 0 | U39: =T39+U38 -> 77291.906 | V39: =T39/P39 -> #DIV/0! | W39: =U39/Q39 -> 104.03435 | X39: =IF(AND(R39>0,T39>0),(T39/(R39*1000))*1000,0) -> 0 | Y39: =IF(AND(S39>0,U39>0),U39/S39,0) -> 110.32386 | Z39: 17.2 | AA39: =Z39+AA38 -> 1360.4 | AB39: =Z39/(P39) -> #DIV/0! | AC39: =AA39/(Q39) -> 1.8310887 | AD39: =IF(AND(R39>0,Z39>0),Z39/(R39),0) -> 0 | AE39: =IF(AND(S39>0,AA39>0),AA39/(S39),0) -> 1.9417891 | AF39: ='31'!I46 -> 5629.98 | AG39: =AF39+AG38 -> 790188.4 | AH39: =IF(AND(L39>0,AF39>0),(AF39/(P39*1000)*1000),0) -> #DIV/0! | AI39: =IF(AND(M39>0,AG39>0),(AG39/(Q39*1000)*1000),0) -> 1063.5879 | AJ39: =IF(AND(R39>0,AF39>0),(AF39/(R39*1000)*1000),0) -> 0 | AK39: =IF(AND(S39>0,AG39>0),(AG39/(S39*1000)*1000),0) -> 1127.8883 | AL39: 0 | AM39: 5295.8 | AN39: 3404.9 | AO39: =SUM(AL39:AN39) -> 8700.7 | AP39: =+[1]Okt!N34 -> 8568 | AQ39: =+AP39-AO39 -> -132.7 | AR39: =+AL39/AO39 -> 0 | AS39: =+AM39/AO39 -> 0.60866367 | AT39: =1-AR39-AS39 -> 0.39133633 | AU39: =+AR39*AQ39 -> 0 | AV39: =+AS39*AQ39 -> -80.769669 | AW39: =+AT39*AQ39 -> -51.930331 | AX39: =+AL39+AU39 -> 0 | AY39: =+AM39+AV39 -> 5215.0303 | AZ39: =+AN39+AW39 -> 3352.9697 | BA39: =+Efficiency2!K141 -> 0 | BB39: =BB38+BA39 -> 867.61735 | BC39: =+R39/BA39 -> #DIV/0! | BD39: =+S39/BB39 -> 0.80748846
G41: =+P41/N41 -> 0.57167931 | H41: =+P41/L41 -> 0.54169961 | I41: =+R41/P41 -> 0.94299047 | J41: =+R41/L41 -> 0.51081757 | L41: =SUM(L9:L39) -> 1371.5092 | N41: =SUM(N9:N39) -> 1299.5852 | P41: =SUM(P9:P39) -> 742.946 | R41: =SUM(R9:R39) -> 700.591 | T41: =SUM(T9:T39) -> 77291.906 | V41: =T41/P41 -> 104.03435 | X41: =IF(AND(R41>0,T41>0),(T41/(R41*1000))*1000,0) -> 110.32386 | Z41: =SUM(Z9:Z40) -> 1360.4 | AB41: =Z41/P41 -> 1.8310887 | AD41: =Z41/R41 -> 1.9417891 | AF41: =SUM(AF9:AF39) -> 790188.4 | AH41: =AF41/P41 -> 1063.5879 | AJ41: =AF41/R41 -> 1127.8883 | AP41: =SUM(AP9:AP40) -> 321851 | AX41: =SUM(AX9:AX39) -> 77291.906 | AY41: =SUM(AY9:AY39) -> 155738.8 | AZ41: =SUM(AZ9:AZ39) -> 88820.295 | BA41: =SUM(BA9:BA39) -> 867.61735 | BC41: =+R41/BA41 -> 0.80748846
AY43: =SUM(AX41:AZ41) -> 321851

Sheet GRAFIK

Sheet Listrik
A2: MACHINE POWER CONSUMPTION (PER PANEL)
A4: Date | B4: PM (TON) | C4: FINSHED GOODS (TON) | P4: Total PM14
D5: Trafo (2500 A) | H5: Trafo (2500 B) | L5: Trafo (2500 A)
D6: KWH | E6: Consumption | F6: /TON PM | G6: /TON FG | H6: KWH | I6: Consumption | J6: /TON PM | K6: /TON FG | L6: KWH | M6: Consumption | N6: /TON PM | O6: /TON FG | P6: Consumption | Q6: /TON PM | R6: /TON FG
A7: =A8-1 -> 45930 | B7: 0 | C7: 0
