Workbook

Sheet Report1
A3: PAPER MACHINE 14 DAILY REPORT 1
A6: Date | B6: Grade | C6: GSM | D6: Speed yankee (mpm) | E6: Speed reel (mpm) | F6: Creep ( % ) | G6: Real Eff PM ( % ) | H6: Real Eff PM vs Target (%) | I6: Real Eff FG vs Real Eff PM (%) | J6: Eff FG vs Target (%) | L6: Kapasitas Target (ton) | N6: Kapasitas Teori Real (ton) | P6: PM PROD Timbangan (TON) | R6: FINSHED GOODS (TON) | T6: GAS HOOD | Z6: STEAM (TON) | AF6: POWER (kWh) | BA6: Kapasitas Running (ton) | BC6: Eff FG vs Target Running(%)
T7: CONSUMPTION | V7: /TON PM. | X7: /TON FG. | Z7: CONSUMPTION | AB7: /TON PM. | AD7: /TON FG. | AF7: CONSUMPTION | AH7: /TON PM | AJ7: /TON FG | AL7: Gas based on report DCS | AO7: total | AP7: Flowmeter | AQ7: Selisih | AR7: % pengali | AU7: Adjust | AX7: PEMAKAIAN GAS
J8: TODAY | K8: TODATE | L8: TODAY | M8: TODATE | N8: TODAY | O8: TODATE | P8: TODAY | Q8: TODATE | R8: TODAY | S8: TODATE | T8: TODAY | U8: TODATE | V8: TODAY | W8: TODATE | X8: TODAY | Y8: TODATE | Z8: TODAY | AA8: TODATE | AB8: TODAY | AC8: TODATE | AD8: TODAY | AE8: TODATE | AF8: TODAY | AG8: TODATE | AH8: TODAY | AI8: TODATE | AJ8: TODAY | AK8: TODATE | AL8: 14 | AM8: 15 | AN8: 17 | AP8: PGN | AU8: 14 | AV8: 15 | AW8: 17 | AX8: 14 | AY8: 15 | AZ8: 17 | BA8: TODAY | BB8: TODATE | BC8: TODAY | BD8: TODATE
A9: 45992 | B9: Facial | C9: 14 | D9: =+'1'!F42 -> 1144.9714 | E9: =+'1'!G42 -> 870.17829 | F9: =1-(E9/D9) -> 0.24 | G9: =+P9/N9 -> 0.54265103 | H9: =+P9/L9 -> 0.54265103 | I9: =+R9/P9 -> 0.94093168 | J9: =+R9/L9 -> 0.51059755 | K9: =+S9/M9 -> 0.51059755 | L9: =+Efficiency1!K6 -> 45.611265 | M9: =L9 -> 45.611265 | N9: =+Efficiency1!C6 -> 45.611265 | O9: =N9 -> 45.611265 | P9: ='1'!I38 -> 24.751 | Q9: =P9 -> 24.751 | R9: ='1'!I40 -> 23.289 | S9: =R9 -> 23.289 | T9: =+AX9 -> 2979.9449 | U9: =T9 -> 2979.9449 | V9: =T9/P9 -> 120.39695 | W9: =U9/Q9 -> 120.39695 | X9: =IF(AND(R9>0,T9>0),(T9/(R9*1000))*1000,0) -> 127.95504 | Y9: =IF(AND(S9>0,U9>0),U9/S9,0) -> 127.95504 | Z9: 35.7 | AA9: =Z9 -> 35.7 | AB9: =Z9/(P9) -> 1.442366 | AC9: =AA9/(Q9) -> 1.442366 | AD9: =IF(AND(R9>0,Z9>0),Z9/(R9),0) -> 1.5329125 | AE9: =IF(AND(S9>0,AA9>0),AA9/(S9),0) -> 1.5329125 | AF9: ='1'!I46 -> 37346.66 | AG9: =AF9 -> 37346.66 | AH9: =IF(AND(L9>0,AF9>0),(AF9/(P9*1000)*1000),0) -> 1508.895 | AI9: =IF(AND(M9>0,AG9>0),(AG9/(Q9*1000)*1000),0) -> 1508.895 | AJ9: =IF(AND(R9>0,AF9>0),(AF9/(R9*1000)*1000),0) -> 1603.618 | AK9: =IF(AND(S9>0,AG9>0),(AG9/(S9*1000)*1000),0) -> 1603.618 | AL9: 2916.1 | AM9: 4471.7 | AN9: 3875.6 | AO9: =SUM(AL9:AN9) -> 11263.4 | AP9: =+[1]Des!N4 -> 11510 | AQ9: =+AP9-AO9 -> 246.6 | AR9: =+AL9/AO9 -> 0.25890051 | AS9: =+AM9/AO9 -> 0.39701156 | AT9: =1-AR9-AS9 -> 0.34408793 | AU9: =+AR9*AQ9 -> 63.844866 | AV9: =+AS9*AQ9 -> 97.903051 | AW9: =+AT9*AQ9 -> 84.852084 | AX9: =+AL9+AU9 -> 2979.9449 | AY9: =+AM9+AV9 -> 4569.6031 | AZ9: =+AN9+AW9 -> 3960.4521 | BA9: =+Efficiency2!K6 -> 45.611265 | BB9: =BA9 -> 45.611265 | BC9: =+R9/BA9 -> 0.51059755 | BD9: =+S9/BB9 -> 0.51059755
A10: =A9+1 -> 45993 | B10: Facial | C10: 14/15 | D10: =+'2'!F42 -> 1111.6667 | E10: =+'2'!G42 -> 844.86667 | F10: =1-(E10/D10) -> 0.24 | G10: =+P10/N10 -> 0.95800192 | H10: =+P10/L10 -> 0.95800192 | I10: =+R10/P10 -> 0.95611441 | J10: =+R10/L10 -> 0.91595944 | K10: =+S10/M10 -> 0.71466356 | L10: =+SUM(Efficiency1!K12:K13) -> 46.238947 | M10: =M9+L10 -> 91.850212 | N10: =+SUM(Efficiency1!C12:C13) -> 46.238947 | O10: =O9+N10 -> 91.850212 | P10: ='2'!I38 -> 44.297 | Q10: =Q9+P10 -> 69.048 | R10: ='2'!I40 -> 42.353 | S10: =S9+R10 -> 65.642 | T10: =+AX10 -> 4610.0129 | U10: =T10+U9 -> 7589.9578 | V10: =T10/P10 -> 104.07055 | W10: =U10/Q10 -> 109.92292 | X10: =IF(AND(R10>0,T10>0),(T10/(R10*1000))*1000,0) -> 108.84738 | Y10: =IF(AND(S10>0,U10>0),U10/S10,0) -> 115.62655 | Z10: 54.4 | AA10: =Z10+AA9 -> 90.1 | AB10: =Z10/(P10) -> 1.2280741 | AC10: =AA10/(Q10) -> 1.3048894 | AD10: =IF(AND(R10>0,Z10>0),Z10/(R10),0) -> 1.2844427 | AE10: =IF(AND(S10>0,AA10>0),AA10/(S10),0) -> 1.3725968 | AF10: ='2'!I46 -> 33715.9 | AG10: =AF10+AG9 -> 71062.56 | AH10: =IF(AND(L10>0,AF10>0),(AF10/(P10*1000)*1000),0) -> 761.13281 | AI10: =IF(AND(M10>0,AG10>0),(AG10/(Q10*1000)*1000),0) -> 1029.1762 | AJ10: =IF(AND(R10>0,AF10>0),(AF10/(R10*1000)*1000),0) -> 796.06876 | AK10: =IF(AND(S10>0,AG10>0),(AG10/(S10*1000)*1000),0) -> 1082.5776 | AL10: 4886.6 | AM10: 5539.8 | AN10: 3818.9 | AO10: =SUM(AL10:AN10) -> 14245.3 | AP10: =+[1]Des!N5 -> 13439 | AQ10: =+AP10-AO10 -> -806.3 | AR10: =+AL10/AO10 -> 0.34303244 | AS10: =+AM10/AO10 -> 0.38888616 | AT10: =1-AR10-AS10 -> 0.2680814 | AU10: =+AR10*AQ10 -> -276.58706 | AV10: =+AS10*AQ10 -> -313.55891 | AW10: =+AT10*AQ10 -> -216.15403 | AX10: =+AL10+AU10 -> 4610.0129 | AY10: =+AM10+AV10 -> 5226.2411 | AZ10: =+AN10+AW10 -> 3602.746 | BA10: =+SUM(Efficiency2!K12:K13) -> 46.238947 | BB10: =BB9+BA10 -> 91.850212 | BC10: =+R10/BA10 -> 0.91595944 | BD10: =+S10/BB10 -> 0.71466356
A11: =A10+1 -> 45994 | B11: Facial | C11: 15 | D11: =+'3'!F42 -> 1090 | E11: =+'3'!G42 -> 828.4 | F11: =1-(E11/D11) -> 0.24 | G11: =+P11/N11 -> 0.95794971 | H11: =+P11/L11 -> 0.95794971 | I11: =+R11/P11 -> 0.95660992 | J11: =+R11/L11 -> 0.9163842 | K11: =+S11/M11 -> 0.7817886 | L11: =+Efficiency1!K16 -> 45.807206 | M11: =M10+L11 -> 137.65742 | N11: =+Efficiency1!C16 -> 45.807206 | O11: =O10+N11 -> 137.65742 | P11: ='3'!I38 -> 43.881 | Q11: =Q10+P11 -> 112.929 | R11: ='3'!I40 -> 41.977 | S11: =S10+R11 -> 107.619 | T11: =+AX11 -> 4861.9607 | U11: =T11+U10 -> 12451.919 | V11: =T11/P11 -> 110.79877 | W11: =U11/Q11 -> 110.26325 | X11: =IF(AND(R11>0,T11>0),(T11/(R11*1000))*1000,0) -> 115.8244 | Y11: =IF(AND(S11>0,U11>0),U11/S11,0) -> 115.70372 | Z11: 52.6 | AA11: =Z11+AA10 -> 142.7 | AB11: =Z11/(P11) -> 1.1986965 | AC11: =AA11/(Q11) -> 1.2636258 | AD11: =IF(AND(R11>0,Z11>0),Z11/(R11),0) -> 1.2530672 | AE11: =IF(AND(S11>0,AA11>0),AA11/(S11),0) -> 1.325974 | AF11: ='3'!I46 -> 40608.84 | AG11: =AF11+AG10 -> 111671.4 | AH11: =IF(AND(L11>0,AF11>0),(AF11/(P11*1000)*1000),0) -> 925.43105 | AI11: =IF(AND(M11>0,AG11>0),(AG11/(Q11*1000)*1000),0) -> 988.8638 | AJ11: =IF(AND(R11>0,AF11>0),(AF11/(R11*1000)*1000),0) -> 967.40691 | AK11: =IF(AND(S11>0,AG11>0),(AG11/(S11*1000)*1000),0) -> 1037.6551 | AL11: 5147.9 | AM11: 5599.4 | AN11: 3774.3 | AO11: =SUM(AL11:AN11) -> 14521.6 | AP11: =+[1]Des!N6 -> 13715 | AQ11: =+AP11-AO11 -> -806.6 | AR11: =+AL11/AO11 -> 0.3544995 | AS11: =+AM11/AO11 -> 0.38559112 | AT11: =1-AR11-AS11 -> 0.25990938 | AU11: =+AR11*AQ11 -> -285.9393 | AV11: =+AS11*AQ11 -> -311.0178 | AW11: =+AT11*AQ11 -> -209.6429 | AX11: =+AL11+AU11 -> 4861.9607 | AY11: =+AM11+AV11 -> 5288.3822 | AZ11: =+AN11+AW11 -> 3564.6571 | BA11: =+Efficiency2!K16 -> 45.807206 | BB11: =BB10+BA11 -> 137.65742 | BC11: =+R11/BA11 -> 0.9163842 | BD11: =+S11/BB11 -> 0.7817886
A12: =A11+1 -> 45995 | B12: Facial | C12: 15/14 | D12: =+'4'!F42 -> 1100.2083 | E12: =+'4'!G42 -> 836.15833 | F12: =1-(E12/D12) -> 0.24 | G12: =+P12/N12 -> 0.98384602 | H12: =+P12/L12 -> 0.98384602 | I12: =+R12/P12 -> 0.90973339 | J12: =+R12/L12 -> 0.89503757 | K12: =+S12/M12 -> 0.80962902 | L12: =+SUM(Efficiency1!K20:K21) -> 44.871859 | M12: =M11+L12 -> 182.52928 | N12: =+SUM(Efficiency1!C20:C21) -> 44.871859 | O12: =O11+N12 -> 182.52928 | P12: ='4'!I38 -> 44.147 | Q12: =Q11+P12 -> 157.076 | R12: ='4'!I40 -> 40.162 | S12: =S11+R12 -> 147.781 | T12: =+AX12 -> 4821.1627 | U12: =T12+U11 -> 17273.081 | V12: =T12/P12 -> 109.20703 | W12: =U12/Q12 -> 109.96639 | X12: =IF(AND(R12>0,T12>0),(T12/(R12*1000))*1000,0) -> 120.04289 | Y12: =IF(AND(S12>0,U12>0),U12/S12,0) -> 116.88296 | Z12: 51.8 | AA12: =Z12+AA11 -> 194.5 | AB12: =Z12/(P12) -> 1.1733527 | AC12: =AA12/(Q12) -> 1.2382541 | AD12: =IF(AND(R12>0,Z12>0),Z12/(R12),0) -> 1.2897764 | AE12: =IF(AND(S12>0,AA12>0),AA12/(S12),0) -> 1.3161367 | AF12: ='4'!I46 -> 32531.52 | AG12: =AF12+AG11 -> 144202.92 | AH12: =IF(AND(L12>0,AF12>0),(AF12/(P12*1000)*1000),0) -> 736.89084 | AI12: =IF(AND(M12>0,AG12>0),(AG12/(Q12*1000)*1000),0) -> 918.04553 | AJ12: =IF(AND(R12>0,AF12>0),(AF12/(R12*1000)*1000),0) -> 810.00747 | AK12: =IF(AND(S12>0,AG12>0),(AG12/(S12*1000)*1000),0) -> 975.78796 | AL12: 5114.6 | AM12: 5480.3 | AN12: 3739.5 | AO12: =SUM(AL12:AN12) -> 14334.4 | AP12: =+[1]Des!N7 -> 13512 | AQ12: =+AP12-AO12 -> -822.4 | AR12: =+AL12/AO12 -> 0.35680601 | AS12: =+AM12/AO12 -> 0.38231806 | AT12: =1-AR12-AS12 -> 0.26087593 | AU12: =+AR12*AQ12 -> -293.43726 | AV12: =+AS12*AQ12 -> -314.41837 | AW12: =+AT12*AQ12 -> -214.54437 | AX12: =+AL12+AU12 -> 4821.1627 | AY12: =+AM12+AV12 -> 5165.8816 | AZ12: =+AN12+AW12 -> 3524.9556 | BA12: =+SUM(Efficiency2!K20:K21) -> 44.871859 | BB12: =BB11+BA12 -> 182.52928 | BC12: =+R12/BA12 -> 0.89503757 | BD12: =+S12/BB12 -> 0.80962902
A13: =A12+1 -> 45996 | B13: Facial | C13: 14 | D13: =+'5'!F42 -> 1100 | E13: =+'5'!G42 -> 836 | F13: =1-(E13/D13) -> 0.24 | G13: =+P13/N13 -> 0.97655828 | H13: =+P13/L13 -> 0.97655828 | I13: =+R13/P13 -> 1.059571 | J13: =+R13/L13 -> 1.0347328 | K13: =+S13/M13 -> 0.85309468 | L13: =+Efficiency1!K24 -> 43.678909 | M13: =M12+L13 -> 226.20819 | N13: =+Efficiency1!C24 -> 43.678909 | O13: =O12+N13 -> 226.20819 | P13: ='5'!I38 -> 42.655 | Q13: =Q12+P13 -> 199.731 | R13: ='5'!I40 -> 45.196 | S13: =S12+R13 -> 192.977 | T13: =+AX13 -> 4780.3968 | U13: =T13+U12 -> 22053.478 | V13: =T13/P13 -> 112.07119 | W13: =U13/Q13 -> 110.4159 | X13: =IF(AND(R13>0,T13>0),(T13/(R13*1000))*1000,0) -> 105.77035 | Y13: =IF(AND(S13>0,U13>0),U13/S13,0) -> 114.28034 | Z13: 54.4 | AA13: =Z13+AA12 -> 248.9 | AB13: =Z13/(P13) -> 1.2753487 | AC13: =AA13/(Q13) -> 1.2461761 | AD13: =IF(AND(R13>0,Z13>0),Z13/(R13),0) -> 1.2036463 | AE13: =IF(AND(S13>0,AA13>0),AA13/(S13),0) -> 1.289791 | AF13: ='5'!I46 -> 34323.82 | AG13: =AF13+AG12 -> 178526.74 | AH13: =IF(AND(L13>0,AF13>0),(AF13/(P13*1000)*1000),0) -> 804.68456 | AI13: =IF(AND(M13>0,AG13>0),(AG13/(Q13*1000)*1000),0) -> 893.83591 | AJ13: =IF(AND(R13>0,AF13>0),(AF13/(R13*1000)*1000),0) -> 759.44376 | AK13: =IF(AND(S13>0,AG13>0),(AG13/(S13*1000)*1000),0) -> 925.11926 | AL13: 4900.7 | AM13: 5554.9 | AN13: 1744.9 | AO13: =SUM(AL13:AN13) -> 12200.5 | AP13: =+[1]Des!N8 -> 11901 | AQ13: =+AP13-AO13 -> -299.5 | AR13: =+AL13/AO13 -> 0.40168026 | AS13: =+AM13/AO13 -> 0.45530101 | AT13: =1-AR13-AS13 -> 0.14301873 | AU13: =+AR13*AQ13 -> -120.30324 | AV13: =+AS13*AQ13 -> -136.36265 | AW13: =+AT13*AQ13 -> -42.834109 | AX13: =+AL13+AU13 -> 4780.3968 | AY13: =+AM13+AV13 -> 5418.5373 | AZ13: =+AN13+AW13 -> 1702.0659 | BA13: =+Efficiency2!K24 -> 43.678909 | BB13: =BB12+BA13 -> 226.20819 | BC13: =+R13/BA13 -> 1.0347328 | BD13: =+S13/BB13 -> 0.85309468
A14: =A13+1 -> 45997 | B14: Facial | C14: 14 | D14: =+'6'!F42 -> 1100 | E14: =+'6'!G42 -> 836 | F14: =1-(E14/D14) -> 0.24 | G14: =+P14/N14 -> 0.96226938 | H14: =+P14/L14 -> 0.96226938 | I14: =+R14/P14 -> 0.9654991 | J14: =+R14/L14 -> 0.92907022 | K14: =+S14/M14 -> 0.86534015 | L14: =+Efficiency1!K28 -> 43.46496 | M14: =M13+L14 -> 269.67315 | N14: =+Efficiency1!C28 -> 43.46496 | O14: =O13+N14 -> 269.67315 | P14: ='6'!I38 -> 41.825 | Q14: =Q13+P14 -> 241.556 | R14: ='6'!I40 -> 40.382 | S14: =S13+R14 -> 233.359 | T14: =+AX14 -> 4624.4872 | U14: =T14+U13 -> 26677.965 | V14: =T14/P14 -> 110.56754 | W14: =U14/Q14 -> 110.44216 | X14: =IF(AND(R14>0,T14>0),(T14/(R14*1000))*1000,0) -> 114.51853 | Y14: =IF(AND(S14>0,U14>0),U14/S14,0) -> 114.32156 | Z14: 55.6 | AA14: =Z14+AA13 -> 304.5 | AB14: =Z14/(P14) -> 1.3293485 | AC14: =AA14/(Q14) -> 1.2605773 | AD14: =IF(AND(R14>0,Z14>0),Z14/(R14),0) -> 1.3768511 | AE14: =IF(AND(S14>0,AA14>0),AA14/(S14),0) -> 1.3048565 | AF14: ='6'!I46 -> 33993.98 | AG14: =AF14+AG13 -> 212520.72 | AH14: =IF(AND(L14>0,AF14>0),(AF14/(P14*1000)*1000),0) -> 812.76701 | AI14: =IF(AND(M14>0,AG14>0),(AG14/(Q14*1000)*1000),0) -> 879.79897 | AJ14: =IF(AND(R14>0,AF14>0),(AF14/(R14*1000)*1000),0) -> 841.81021 | AK14: =IF(AND(S14>0,AG14>0),(AG14/(S14*1000)*1000),0) -> 910.70291 | AL14: 4905.3 | AM14: 5494.7 | AN14: 3918.7 | AO14: =SUM(AL14:AN14) -> 14318.7 | AP14: =+[1]Des!N9 -> 13499 | AQ14: =+AP14-AO14 -> -819.7 | AR14: =+AL14/AO14 -> 0.34257998 | AS14: =+AM14/AO14 -> 0.38374294 | AT14: =1-AR14-AS14 -> 0.27367708 | AU14: =+AR14*AQ14 -> -280.81281 | AV14: =+AS14*AQ14 -> -314.55409 | AW14: =+AT14*AQ14 -> -224.3331 | AX14: =+AL14+AU14 -> 4624.4872 | AY14: =+AM14+AV14 -> 5180.1459 | AZ14: =+AN14+AW14 -> 3694.3669 | BA14: =+Efficiency2!K28 -> 43.46496 | BB14: =BB13+BA14 -> 269.67315 | BC14: =+R14/BA14 -> 0.92907022 | BD14: =+S14/BB14 -> 0.86534015
A15: =A14+1 -> 45998 | B15: Facial | C15: 14 | D15: =+'7'!F42 -> 1071.0278 | E15: =+'7'!G42 -> 813.98111 | F15: =1-(E15/D15) -> 0.24 | G15: =+P15/N15 -> 0.97807055 | H15: =+P15/L15 -> 0.97807055 | I15: =+R15/P15 -> 0.99942487 | J15: =+R15/L15 -> 0.97750804 | K15: =+S15/M15 -> 0.88066234 | L15: =+Efficiency1!K32 -> 42.665634 | M15: =M14+L15 -> 312.33878 | N15: =+Efficiency1!C32 -> 42.665634 | O15: =O14+N15 -> 312.33878 | P15: ='7'!I38 -> 41.73 | Q15: =Q14+P15 -> 283.286 | R15: ='7'!I40 -> 41.706 | S15: =S14+R15 -> 275.065 | T15: =+AX15 -> 4795.9417 | U15: =T15+U14 -> 31473.907 | V15: =T15/P15 -> 114.92791 | W15: =U15/Q15 -> 111.10294 | X15: =IF(AND(R15>0,T15>0),(T15/(R15*1000))*1000,0) -> 114.99405 | Y15: =IF(AND(S15>0,U15>0),U15/S15,0) -> 114.42352 | Z15: 54.6 | AA15: =Z15+AA14 -> 359.1 | AB15: =Z15/(P15) -> 1.3084112 | AC15: =AA15/(Q15) -> 1.2676235 | AD15: =IF(AND(R15>0,Z15>0),Z15/(R15),0) -> 1.3091641 | AE15: =IF(AND(S15>0,AA15>0),AA15/(S15),0) -> 1.3055096 | AF15: ='7'!I46 -> 38483.58 | AG15: =AF15+AG14 -> 251004.3 | AH15: =IF(AND(L15>0,AF15>0),(AF15/(P15*1000)*1000),0) -> 922.20417 | AI15: =IF(AND(M15>0,AG15>0),(AG15/(Q15*1000)*1000),0) -> 886.04555 | AJ15: =IF(AND(R15>0,AF15>0),(AF15/(R15*1000)*1000),0) -> 922.73486 | AK15: =IF(AND(S15>0,AG15>0),(AG15/(S15*1000)*1000),0) -> 912.52722 | AL15: 4965.7 | AM15: 4865.2 | AN15: 4005.1 | AO15: =SUM(AL15:AN15) -> 13836 | AP15: =+[1]Des!N10 -> 13363 | AQ15: =+AP15-AO15 -> -473 | AR15: =+AL15/AO15 -> 0.35889708 | AS15: =+AM15/AO15 -> 0.35163342 | AT15: =1-AR15-AS15 -> 0.2894695 | AU15: =+AR15*AQ15 -> -169.75832 | AV15: =+AS15*AQ15 -> -166.32261 | AW15: =+AT15*AQ15 -> -136.91907 | AX15: =+AL15+AU15 -> 4795.9417 | AY15: =+AM15+AV15 -> 4698.8774 | AZ15: =+AN15+AW15 -> 3868.1809 | BA15: =+Efficiency2!K32 -> 42.665634 | BB15: =BB14+BA15 -> 312.33878 | BC15: =+R15/BA15 -> 0.97750804 | BD15: =+S15/BB15 -> 0.88066234
A16: =A15+1 -> 45999 | B16: Facial/Toilet | C16: 14/12/13 | D16: =+'8'!F42 -> 1156.5278 | E16: =+'8'!G42 -> 919.31111 | F16: =1-(E16/D16) -> 0.20511108 | G16: =+P16/N16 -> 0.915493 | H16: =+P16/L16 -> 0.88801259 | I16: =+R16/P16 -> 0.9627206 | J16: =+R16/L16 -> 0.85490802 | K16: =+S16/M16 -> 0.87750063 | L16: =+SUM(Efficiency1!K36:K38) -> 43.709966 | M16: =M15+L16 -> 356.04875 | N16: =+SUM(Efficiency1!C36:C38) -> 42.397921 | O16: =O15+N16 -> 354.7367 | P16: ='8'!I38 -> 38.815 | Q16: =Q15+P16 -> 322.101 | R16: ='8'!I40 -> 37.368 | S16: =S15+R16 -> 312.433 | T16: =+AX16 -> 5056.3638 | U16: =T16+U15 -> 36530.271 | V16: =T16/P16 -> 130.26829 | W16: =U16/Q16 -> 113.41247 | X16: =IF(AND(R16>0,T16>0),(T16/(R16*1000))*1000,0) -> 135.31267 | Y16: =IF(AND(S16>0,U16>0),U16/S16,0) -> 116.92193 | Z16: 57 | AA16: =Z16+AA15 -> 416.1 | AB16: =Z16/(P16) -> 1.4685044 | AC16: =AA16/(Q16) -> 1.2918308 | AD16: =IF(AND(R16>0,Z16>0),Z16/(R16),0) -> 1.5253693 | AE16: =IF(AND(S16>0,AA16>0),AA16/(S16),0) -> 1.3318055 | AF16: ='8'!I46 -> 36590.38 | AG16: =AF16+AG15 -> 287594.68 | AH16: =IF(AND(L16>0,AF16>0),(AF16/(P16*1000)*1000),0) -> 942.68659 | AI16: =IF(AND(M16>0,AG16>0),(AG16/(Q16*1000)*1000),0) -> 892.87112 | AJ16: =IF(AND(R16>0,AF16>0),(AF16/(R16*1000)*1000),0) -> 979.19022 | AK16: =IF(AND(S16>0,AG16>0),(AG16/(S16*1000)*1000),0) -> 920.50033 | AL16: 5320.1 | AM16: 5397.7 | AN16: 3949.3 | AO16: =SUM(AL16:AN16) -> 14667.1 | AP16: =+[1]Des!N11 -> 13940 | AQ16: =+AP16-AO16 -> -727.1 | AR16: =+AL16/AO16 -> 0.36272337 | AS16: =+AM16/AO16 -> 0.36801413 | AT16: =1-AR16-AS16 -> 0.2692625 | AU16: =+AR16*AQ16 -> -263.73617 | AV16: =+AS16*AQ16 -> -267.58307 | AW16: =+AT16*AQ16 -> -195.78076 | AX16: =+AL16+AU16 -> 5056.3638 | AY16: =+AM16+AV16 -> 5130.1169 | AZ16: =+AN16+AW16 -> 3753.5192 | BA16: =+SUM(Efficiency2!K36:K38) -> 43.709966 | BB16: =BB15+BA16 -> 356.04875 | BC16: =+R16/BA16 -> 0.85490802 | BD16: =+S16/BB16 -> 0.87750063
A17: =A16+1 -> 46000 | B17: Toilet | C17: 13 | D17: =+'9'!F42 -> 1112.4653 | E17: =+'9'!G42 -> 846.10722 | F17: =1-(E17/D17) -> 0.23943044 | G17: =+P17/N17 -> 0.93351397 | H17: =+P17/L17 -> 0.93351397 | I17: =+R17/P17 -> 0.97457272 | J17: =+R17/L17 -> 0.90977725 | K17: =+S17/M17 -> 0.88082373 | L17: =+Efficiency1!K40 -> 40.864948 | M17: =M16+L17 -> 396.91369 | N17: =+Efficiency1!C40 -> 40.864948 | O17: =O16+N17 -> 395.60165 | P17: ='9'!I38 -> 38.148 | Q17: =Q16+P17 -> 360.249 | R17: ='9'!I40 -> 37.178 | S17: =S16+R17 -> 349.611 | T17: =+AX17 -> 5276.7246 | U17: =T17+U16 -> 41806.995 | V17: =T17/P17 -> 138.32244 | W17: =U17/Q17 -> 116.05027 | X17: =IF(AND(R17>0,T17>0),(T17/(R17*1000))*1000,0) -> 141.93137 | Y17: =IF(AND(S17>0,U17>0),U17/S17,0) -> 119.58146 | Z17: 54.1 | AA17: =Z17+AA16 -> 470.2 | AB17: =Z17/(P17) -> 1.4181608 | AC17: =AA17/(Q17) -> 1.3052083 | AD17: =IF(AND(R17>0,Z17>0),Z17/(R17),0) -> 1.4551617 | AE17: =IF(AND(S17>0,AA17>0),AA17/(S17),0) -> 1.3449234 | AF17: ='9'!I46 -> 39758.32 | AG17: =AF17+AG16 -> 327353 | AH17: =IF(AND(L17>0,AF17>0),(AF17/(P17*1000)*1000),0) -> 1042.2124 | AI17: =IF(AND(M17>0,AG17>0),(AG17/(Q17*1000)*1000),0) -> 908.68538 | AJ17: =IF(AND(R17>0,AF17>0),(AF17/(R17*1000)*1000),0) -> 1069.4045 | AK17: =IF(AND(S17>0,AG17>0),(AG17/(S17*1000)*1000),0) -> 936.33496 | AL17: 5463.3 | AM17: 4762.9 | AN17: 3937.5 | AO17: =SUM(AL17:AN17) -> 14163.7 | AP17: =+[1]Des!N12 -> 13680 | AQ17: =+AP17-AO17 -> -483.7 | AR17: =+AL17/AO17 -> 0.38572548 | AS17: =+AM17/AO17 -> 0.33627513 | AT17: =1-AR17-AS17 -> 0.27799939 | AU17: =+AR17*AQ17 -> -186.57542 | AV17: =+AS17*AQ17 -> -162.65628 | AW17: =+AT17*AQ17 -> -134.46831 | AX17: =+AL17+AU17 -> 5276.7246 | AY17: =+AM17+AV17 -> 4600.2437 | AZ17: =+AN17+AW17 -> 3803.0317 | BA17: =+Efficiency2!K40 -> 40.864948 | BB17: =BB16+BA17 -> 396.91369 | BC17: =+R17/BA17 -> 0.90977725 | BD17: =+S17/BB17 -> 0.88082373
A18: =A17+1 -> 46001 | B18: Toilet | C18: 13 | D18: =+'10'!F42 -> 1103.3333 | E18: =+'10'!G42 -> 845.86667 | F18: =1-(E18/D18) -> 0.23335347 | G18: =+P18/N18 -> 0.9494942 | H18: =+P18/L18 -> 0.9494942 | I18: =+R18/P18 -> 0.96994071 | J18: =+R18/L18 -> 0.92095308 | K18: =+S18/M18 -> 0.88456868 | L18: =+Efficiency1!K44 -> 40.85333 | M18: =M17+L18 -> 437.76702 | N18: =+Efficiency1!C44 -> 40.85333 | O18: =O17+N18 -> 436.45498 | P18: ='10'!I38 -> 38.79 | Q18: =Q17+P18 -> 399.039 | R18: ='10'!I40 -> 37.624 | S18: =S17+R18 -> 387.235 | T18: =+AX18 -> 5137.1497 | U18: =T18+U17 -> 46944.145 | V18: =T18/P18 -> 132.4349 | W18: =U18/Q18 -> 117.643 | X18: =IF(AND(R18>0,T18>0),(T18/(R18*1000))*1000,0) -> 136.53917 | Y18: =IF(AND(S18>0,U18>0),U18/S18,0) -> 121.22909 | Z18: 53.8 | AA18: =Z18+AA17 -> 524 | AB18: =Z18/(P18) -> 1.3869554 | AC18: =AA18/(Q18) -> 1.3131549 | AD18: =IF(AND(R18>0,Z18>0),Z18/(R18),0) -> 1.4299383 | AE18: =IF(AND(S18>0,AA18>0),AA18/(S18),0) -> 1.3531835 | AF18: ='10'!I46 -> 39012.6 | AG18: =AF18+AG17 -> 366365.6 | AH18: =IF(AND(L18>0,AF18>0),(AF18/(P18*1000)*1000),0) -> 1005.7386 | AI18: =IF(AND(M18>0,AG18>0),(AG18/(Q18*1000)*1000),0) -> 918.11978 | AJ18: =IF(AND(R18>0,AF18>0),(AF18/(R18*1000)*1000),0) -> 1036.9073 | AK18: =IF(AND(S18>0,AG18>0),(AG18/(S18*1000)*1000),0) -> 946.10663 | AL18: 5389.8 | AM18: 5098.8 | AN18: 4244 | AO18: =SUM(AL18:AN18) -> 14732.6 | AP18: =+[1]Des!N13 -> 14042 | AQ18: =+AP18-AO18 -> -690.6 | AR18: =+AL18/AO18 -> 0.36584174 | AS18: =+AM18/AO18 -> 0.34608962 | AT18: =1-AR18-AS18 -> 0.28806864 | AU18: =+AR18*AQ18 -> -252.6503 | AV18: =+AS18*AQ18 -> -239.00949 | AW18: =+AT18*AQ18 -> -198.9402 | AX18: =+AL18+AU18 -> 5137.1497 | AY18: =+AM18+AV18 -> 4859.7905 | AZ18: =+AN18+AW18 -> 4045.0598 | BA18: =+Efficiency2!K44 -> 40.85333 | BB18: =BB17+BA18 -> 437.76702 | BC18: =+R18/BA18 -> 0.92095308 | BD18: =+S18/BB18 -> 0.88456868
A19: =A18+1 -> 46002 | B19: Toilet | C19: 13/15 | D19: =+'11'!F42 -> 1100.6111 | E19: =+'11'!G42 -> 836.46444 | F19: =1-(E19/D19) -> 0.24 | G19: =+P19/N19 -> 0.90882766 | H19: =+P19/L19 -> 0.90882766 | I19: =+R19/P19 -> 0.98985774 | J19: =+R19/L19 -> 0.89961009 | K19: =+S19/M19 -> 0.88584767 | L19: =+SUM(Efficiency1!K48:K49) -> 40.683181 | M19: =M18+L19 -> 478.45021 | N19: =+SUM(Efficiency1!C48:C49) -> 40.683181 | O19: =O18+N19 -> 477.13816 | P19: ='11'!I38 -> 36.974 | Q19: =Q18+P19 -> 436.013 | R19: ='11'!I40 -> 36.599 | S19: =S18+R19 -> 423.834 | T19: =+AX19 -> 5162.7172 | U19: =T19+U18 -> 52106.862 | V19: =T19/P19 -> 139.63102 | W19: =U19/Q19 -> 119.50759 | X19: =IF(AND(R19>0,T19>0),(T19/(R19*1000))*1000,0) -> 141.0617 | Y19: =IF(AND(S19>0,U19>0),U19/S19,0) -> 122.94168 | Z19: 52.8 | AA19: =Z19+AA18 -> 576.8 | AB19: =Z19/(P19) -> 1.4280305 | AC19: =AA19/(Q19) -> 1.3228963 | AD19: =IF(AND(R19>0,Z19>0),Z19/(R19),0) -> 1.4426624 | AE19: =IF(AND(S19>0,AA19>0),AA19/(S19),0) -> 1.3609102 | AF19: ='11'!I46 -> 34865.24 | AG19: =AF19+AG18 -> 401230.84 | AH19: =IF(AND(L19>0,AF19>0),(AF19/(P19*1000)*1000),0) -> 942.96641 | AI19: =IF(AND(M19>0,AG19>0),(AG19/(Q19*1000)*1000),0) -> 920.22678 | AJ19: =IF(AND(R19>0,AF19>0),(AF19/(R19*1000)*1000),0) -> 952.62821 | AK19: =IF(AND(S19>0,AG19>0),(AG19/(S19*1000)*1000),0) -> 946.66978 | AL19: 5414.7 | AM19: 4329 | AN19: 4204.4 | AO19: =SUM(AL19:AN19) -> 13948.1 | AP19: =+[1]Des!N14 -> 13299 | AQ19: =+AP19-AO19 -> -649.1 | AR19: =+AL19/AO19 -> 0.38820341 | AS19: =+AM19/AO19 -> 0.31036485 | AT19: =1-AR19-AS19 -> 0.30143174 | AU19: =+AR19*AQ19 -> -251.98283 | AV19: =+AS19*AQ19 -> -201.45783 | AW19: =+AT19*AQ19 -> -195.65934 | AX19: =+AL19+AU19 -> 5162.7172 | AY19: =+AM19+AV19 -> 4127.5422 | AZ19: =+AN19+AW19 -> 4008.7407 | BA19: =+SUM(Efficiency2!K48:K49) -> 40.683181 | BB19: =BB18+BA19 -> 478.45021 | BC19: =+R19/BA19 -> 0.89961009 | BD19: =+S19/BB19 -> 0.88584767
A20: =A19+1 -> 46003 | B20: Toilet | C20: 15/12 | D20: =+'12'!F42 -> 1085.1389 | E20: =+'12'!G42 -> 823.49028 | F20: =1-(E20/D20) -> 0.24111993 | G20: =+P20/N20 -> 0.99600974 | H20: =+P20/L20 -> 0.98630598 | I20: =+R20/P20 -> 0.97688814 | J20: =+R20/L20 -> 0.96351061 | K20: =+S20/M20 -> 0.89226272 | L20: =+SUM(Efficiency1!K52:K53) -> 43.078924 | M20: =M19+L20 -> 521.52913 | N20: =+SUM(Efficiency1!C52:C53) -> 42.659221 | O20: =O19+N20 -> 519.79738 | P20: ='12'!I38 -> 42.489 | Q20: =Q19+P20 -> 478.502 | R20: ='12'!I40 -> 41.507 | S20: =S19+R20 -> 465.341 | T20: =+AX20 -> 5272.5428 | U20: =T20+U19 -> 57379.405 | V20: =T20/P20 -> 124.09195 | W20: =U20/Q20 -> 119.91466 | X20: =IF(AND(R20>0,T20>0),(T20/(R20*1000))*1000,0) -> 127.0278 | Y20: =IF(AND(S20>0,U20>0),U20/S20,0) -> 123.30615 | Z20: 52 | AA20: =Z20+AA19 -> 628.8 | AB20: =Z20/(P20) -> 1.2238462 | AC20: =AA20/(Q20) -> 1.3141011 | AD20: =IF(AND(R20>0,Z20>0),Z20/(R20),0) -> 1.2528007 | AE20: =IF(AND(S20>0,AA20>0),AA20/(S20),0) -> 1.3512671 | AF20: ='12'!I46 -> 41938.48 | AG20: =AF20+AG19 -> 443169.32 | AH20: =IF(AND(L20>0,AF20>0),(AF20/(P20*1000)*1000),0) -> 987.04323 | AI20: =IF(AND(M20>0,AG20>0),(AG20/(Q20*1000)*1000),0) -> 926.15981 | AJ20: =IF(AND(R20>0,AF20>0),(AF20/(R20*1000)*1000),0) -> 1010.3954 | AK20: =IF(AND(S20>0,AG20>0),(AG20/(S20*1000)*1000),0) -> 952.35391 | AL20: 5487.1 | AM20: 5093.5 | AN20: 4129.6 | AO20: =SUM(AL20:AN20) -> 14710.2 | AP20: =+[1]Des!N15 -> 14135 | AQ20: =+AP20-AO20 -> -575.2 | AR20: =+AL20/AO20 -> 0.37301328 | AS20: =+AM20/AO20 -> 0.34625634 | AT20: =1-AR20-AS20 -> 0.28073038 | AU20: =+AR20*AQ20 -> -214.55724 | AV20: =+AS20*AQ20 -> -199.16665 | AW20: =+AT20*AQ20 -> -161.47611 | AX20: =+AL20+AU20 -> 5272.5428 | AY20: =+AM20+AV20 -> 4894.3334 | AZ20: =+AN20+AW20 -> 3968.1239 | BA20: =+SUM(Efficiency2!K52:K53) -> 43.078924 | BB20: =BB19+BA20 -> 521.52913 | BC20: =+R20/BA20 -> 0.96351061 | BD20: =+S20/BB20 -> 0.89226272
A21: =A20+1 -> 46004 | B21: Toilet/Facial | C21: 12/12 | D21: =+'13'!F42 -> 1205.9653 | E21: =+'13'!G42 -> 912.46694 | F21: =1-(E21/D21) -> 0.24337213 | G21: =+P21/N21 -> 0.8776762 | H21: =+P21/L21 -> 0.86052922 | I21: =+R21/P21 -> 0.95096616 | J21: =+R21/L21 -> 0.81833417 | K21: =+S21/M21 -> 0.88679943 | L21: =+SUM(Efficiency1!K56:K57) -> 41.616251 | M21: =M20+L21 -> 563.14538 | N21: =+SUM(Efficiency1!C56:C57) -> 40.803203 | O21: =O20+N21 -> 560.60058 | P21: ='13'!I38 -> 35.812 | Q21: =Q20+P21 -> 514.314 | R21: ='13'!I40 -> 34.056 | S21: =S20+R21 -> 499.397 | T21: =+AX21 -> 4948.3811 | U21: =T21+U20 -> 62327.786 | V21: =T21/P21 -> 138.17662 | W21: =U21/Q21 -> 121.18625 | X21: =IF(AND(R21>0,T21>0),(T21/(R21*1000))*1000,0) -> 145.3013 | Y21: =IF(AND(S21>0,U21>0),U21/S21,0) -> 124.80609 | Z21: 51.3 | AA21: =Z21+AA20 -> 680.1 | AB21: =Z21/(P21) -> 1.4324807 | AC21: =AA21/(Q21) -> 1.3223439 | AD21: =IF(AND(R21>0,Z21>0),Z21/(R21),0) -> 1.5063425 | AE21: =IF(AND(S21>0,AA21>0),AA21/(S21),0) -> 1.3618424 | AF21: ='13'!I46 -> 40970.82 | AG21: =AF21+AG20 -> 484140.14 | AH21: =IF(AND(L21>0,AF21>0),(AF21/(P21*1000)*1000),0) -> 1144.0528 | AI21: =IF(AND(M21>0,AG21>0),(AG21/(Q21*1000)*1000),0) -> 941.33183 | AJ21: =IF(AND(R21>0,AF21>0),(AF21/(R21*1000)*1000),0) -> 1203.0426 | AK21: =IF(AND(S21>0,AG21>0),(AG21/(S21*1000)*1000),0) -> 969.44944 | AL21: 5554.2 | AM21: 5158.4 | AN21: 4036.1 | AO21: =SUM(AL21:AN21) -> 14748.7 | AP21: =+[1]Des!N16 -> 13140 | AQ21: =+AP21-AO21 -> -1608.7 | AR21: =+AL21/AO21 -> 0.37658912 | AS21: =+AM21/AO21 -> 0.34975286 | AT21: =1-AR21-AS21 -> 0.27365802 | AU21: =+AR21*AQ21 -> -605.81892 | AV21: =+AS21*AQ21 -> -562.64743 | AW21: =+AT21*AQ21 -> -440.23365 | AX21: =+AL21+AU21 -> 4948.3811 | AY21: =+AM21+AV21 -> 4595.7526 | AZ21: =+AN21+AW21 -> 3595.8663 | BA21: =+SUM(Efficiency2!K56:K57) -> 41.616251 | BB21: =BB20+BA21 -> 563.14538 | BC21: =+R21/BA21 -> 0.81833417 | BD21: =+S21/BB21 -> 0.88679943
A22: =A21+1 -> 46005 | B22: Facial | C22: 12 | D22: =+'14'!F42 -> 1195.75 | E22: =+'14'!G42 -> 882.72833 | F22: =1-(E22/D22) -> 0.26177852 | G22: =+P22/N22 -> 0.93714325 | H22: =+P22/L22 -> 0.88494106 | I22: =+R22/P22 -> 0.90602842 | J22: =+R22/L22 -> 0.80178174 | K22: =+S22/M22 -> 0.88095179 | L22: =+Efficiency1!K60 -> 41.594861 | M22: =M21+L22 -> 604.74024 | N22: =+Efficiency1!C60 -> 39.27788 | O22: =O21+N22 -> 599.87846 | P22: ='14'!I38 -> 36.809 | Q22: =Q21+P22 -> 551.123 | R22: ='14'!I40 -> 33.35 | S22: =S21+R22 -> 532.747 | T22: =+AX22 -> 4993.65 | U22: =T22+U21 -> 67321.436 | V22: =T22/P22 -> 135.66383 | W22: =U22/Q22 -> 122.1532 | X22: =IF(AND(R22>0,T22>0),(T22/(R22*1000))*1000,0) -> 149.73463 | Y22: =IF(AND(S22>0,U22>0),U22/S22,0) -> 126.36662 | Z22: 55.3 | AA22: =Z22+AA21 -> 735.4 | AB22: =Z22/(P22) -> 1.50235 | AC22: =AA22/(Q22) -> 1.3343664 | AD22: =IF(AND(R22>0,Z22>0),Z22/(R22),0) -> 1.6581709 | AE22: =IF(AND(S22>0,AA22>0),AA22/(S22),0) -> 1.3803926 | AF22: ='14'!I46 -> 34866.82 | AG22: =AF22+AG21 -> 519006.96 | AH22: =IF(AND(L22>0,AF22>0),(AF22/(P22*1000)*1000),0) -> 947.23627 | AI22: =IF(AND(M22>0,AG22>0),(AG22/(Q22*1000)*1000),0) -> 941.72618 | AJ22: =IF(AND(R22>0,AF22>0),(AF22/(R22*1000)*1000),0) -> 1045.4819 | AK22: =IF(AND(S22>0,AG22>0),(AG22/(S22*1000)*1000),0) -> 974.20907 | AL22: 4817.9 | AM22: 4510.5 | AN22: 4200.1 | AO22: =SUM(AL22:AN22) -> 13528.5 | AP22: =+[1]Des!N17 -> 14022 | AQ22: =+AP22-AO22 -> 493.5 | AR22: =+AL22/AO22 -> 0.35612965 | AS22: =+AM22/AO22 -> 0.33340725 | AT22: =1-AR22-AS22 -> 0.3104631 | AU22: =+AR22*AQ22 -> 175.74998 | AV22: =+AS22*AQ22 -> 164.53648 | AW22: =+AT22*AQ22 -> 153.21354 | AX22: =+AL22+AU22 -> 4993.65 | AY22: =+AM22+AV22 -> 4675.0365 | AZ22: =+AN22+AW22 -> 4353.3135 | BA22: =+Efficiency2!K60 -> 41.594861 | BB22: =BB21+BA22 -> 604.74024 | BC22: =+R22/BA22 -> 0.80178174 | BD22: =+S22/BB22 -> 0.88095179
A23: =A22+1 -> 46006 | B23: Facial | C23: 12/13 | D23: =+'15'!F42 -> 1165.5417 | E23: =+'15'!G42 -> 877.42833 | F23: =1-(E23/D23) -> 0.24719265 | G23: =+P23/N23 -> 0.92823356 | H23: =+P23/L23 -> 0.85754487 | I23: =+R23/P23 -> 0.9724533 | J23: =+R23/L23 -> 0.83392235 | K23: =+S23/M23 -> 0.87772318 | L23: =+SUM(Efficiency1!K64:K65) -> 44.576093 | M23: =M22+L23 -> 649.31633 | N23: =+SUM(Efficiency1!C64:C65) -> 41.181446 | O23: =O22+N23 -> 641.05991 | P23: ='15'!I38 -> 38.226 | Q23: =Q22+P23 -> 589.349 | R23: ='15'!I40 -> 37.173 | S23: =S22+R23 -> 569.92 | T23: =+AX23 -> 5032.1333 | U23: =T23+U22 -> 72353.569 | V23: =T23/P23 -> 131.64164 | W23: =U23/Q23 -> 122.76863 | X23: =IF(AND(R23>0,T23>0),(T23/(R23*1000))*1000,0) -> 135.37065 | Y23: =IF(AND(S23>0,U23>0),U23/S23,0) -> 126.9539 | Z23: 51 | AA23: =Z23+AA22 -> 786.4 | AB23: =Z23/(P23) -> 1.3341705 | AC23: =AA23/(Q23) -> 1.3343537 | AD23: =IF(AND(R23>0,Z23>0),Z23/(R23),0) -> 1.3719635 | AE23: =IF(AND(S23>0,AA23>0),AA23/(S23),0) -> 1.3798428 | AF23: ='15'!I46 -> 37221.1 | AG23: =AF23+AG22 -> 556228.06 | AH23: =IF(AND(L23>0,AF23>0),(AF23/(P23*1000)*1000),0) -> 973.71161 | AI23: =IF(AND(M23>0,AG23>0),(AG23/(Q23*1000)*1000),0) -> 943.8008 | AJ23: =IF(AND(R23>0,AF23>0),(AF23/(R23*1000)*1000),0) -> 1001.2939 | AK23: =IF(AND(S23>0,AG23>0),(AG23/(S23*1000)*1000),0) -> 975.97568 | AL23: 5218 | AM23: 5086.6 | AN23: 4173.1 | AO23: =SUM(AL23:AN23) -> 14477.7 | AP23: =+[1]Des!N18 -> 13962 | AQ23: =+AP23-AO23 -> -515.7 | AR23: =+AL23/AO23 -> 0.36041636 | AS23: =+AM23/AO23 -> 0.35134034 | AT23: =1-AR23-AS23 -> 0.2882433 | AU23: =+AR23*AQ23 -> -185.86672 | AV23: =+AS23*AQ23 -> -181.18621 | AW23: =+AT23*AQ23 -> -148.64707 | AX23: =+AL23+AU23 -> 5032.1333 | AY23: =+AM23+AV23 -> 4905.4138 | AZ23: =+AN23+AW23 -> 4024.4529 | BA23: =+SUM(Efficiency2!K64:K65) -> 44.576093 | BB23: =BB22+BA23 -> 649.31633 | BC23: =+R23/BA23 -> 0.83392235 | BD23: =+S23/BB23 -> 0.87772318
A24: =A23+1 -> 46007 | B24: Facial | C24: 13/12 | D24: =+'16'!F42 -> 1164.3353 | E24: =+'16'!G42 -> 881.62613 | F24: =1-(E24/D24) -> 0.24280738 | G24: =+P24/N24 -> 0.86683853 | H24: =+P24/L24 -> 0.81392039 | I24: =+R24/P24 -> 0.87901348 | J24: =+R24/L24 -> 0.71544699 | K24: =+S24/M24 -> 0.86770078 | L24: =+SUM(Efficiency1!K68:K69) -> 42.74251 | M24: =M23+L24 -> 692.05884 | N24: =+SUM(Efficiency1!C68:C69) -> 40.133195 | O24: =O23+N24 -> 681.19311 | P24: ='16'!I38 -> 34.789 | Q24: =Q23+P24 -> 624.138 | R24: ='16'!I40 -> 30.58 | S24: =S23+R24 -> 600.5 | T24: =+AX24 -> 4078.4179 | U24: =T24+U23 -> 76431.987 | V24: =T24/P24 -> 117.23297 | W24: =U24/Q24 -> 122.46008 | X24: =IF(AND(R24>0,T24>0),(T24/(R24*1000))*1000,0) -> 133.3688 | Y24: =IF(AND(S24>0,U24>0),U24/S24,0) -> 127.28058 | Z24: 45.1 | AA24: =Z24+AA23 -> 831.5 | AB24: =Z24/(P24) -> 1.2963868 | AC24: =AA24/(Q24) -> 1.3322374 | AD24: =IF(AND(R24>0,Z24>0),Z24/(R24),0) -> 1.4748201 | AE24: =IF(AND(S24>0,AA24>0),AA24/(S24),0) -> 1.3846794 | AF24: ='16'!I46 -> 37053.54 | AG24: =AF24+AG23 -> 593281.6 | AH24: =IF(AND(L24>0,AF24>0),(AF24/(P24*1000)*1000),0) -> 1065.0936 | AI24: =IF(AND(M24>0,AG24>0),(AG24/(Q24*1000)*1000),0) -> 950.56157 | AJ24: =IF(AND(R24>0,AF24>0),(AF24/(R24*1000)*1000),0) -> 1211.692 | AK24: =IF(AND(S24>0,AG24>0),(AG24/(S24*1000)*1000),0) -> 987.97935 | AL24: 5030.4 | AM24: 4725.4 | AN24: 4088.1 | AO24: =SUM(AL24:AN24) -> 13843.9 | AP24: =+[1]Des!$M$19 -> 11224 | AQ24: =+AP24-AO24 -> -2619.9 | AR24: =+AL24/AO24 -> 0.36336581 | AS24: =+AM24/AO24 -> 0.34133445 | AT24: =1-AR24-AS24 -> 0.29529973 | AU24: =+AR24*AQ24 -> -951.9821 | AV24: =+AS24*AQ24 -> -894.26213 | AW24: =+AT24*AQ24 -> -773.65578 | AX24: =+AL24+AU24 -> 4078.4179 | AY24: =+AM24+AV24 -> 3831.1379 | AZ24: =+AN24+AW24 -> 3314.4442 | BA24: =+SUM(Efficiency2!K68:K69) -> 42.74251 | BB24: =BB23+BA24 -> 692.05884 | BC24: =+R24/BA24 -> 0.71544699 | BD24: =+S24/BB24 -> 0.86770078
A25: =A24+1 -> 46008 | B25: Facial | C25: 12/11,5 | D25: =+'17'!F42 -> 1185.6786 | E25: =+'17'!G42 -> 897.39679 | F25: =1-(E25/D25) -> 0.24313654 | G25: =+P25/N25 -> 0.9295737 | H25: =+P25/L25 -> 0.89634276 | I25: =+R25/P25 -> 0.92920139 | J25: =+R25/L25 -> 0.83288294 | K25: =+S25/M25 -> 0.86574272 | L25: =+SUM(Efficiency1!K73:K74) -> 41.238689 | M25: =M24+L25 -> 733.29753 | N25: =+SUM(Efficiency1!C73:C74) -> 39.764464 | O25: =O24+N25 -> 720.95757 | P25: ='17'!I38 -> 36.964 | Q25: =Q24+P25 -> 661.102 | R25: ='17'!I40 -> 34.347 | S25: =S24+R25 -> 634.847 | T25: =+AX25 -> 5011.8453 | U25: =T25+U24 -> 81443.832 | V25: =T25/P25 -> 135.5872 | W25: =U25/Q25 -> 123.19405 | X25: =IF(AND(R25>0,T25>0),(T25/(R25*1000))*1000,0) -> 145.91799 | Y25: =IF(AND(S25>0,U25>0),U25/S25,0) -> 128.28891 | Z25: 46.3 | AA25: =Z25+AA24 -> 877.8 | AB25: =Z25/(P25) -> 1.2525701 | AC25: =AA25/(Q25) -> 1.327783 | AD25: =IF(AND(R25>0,Z25>0),Z25/(R25),0) -> 1.3480071 | AE25: =IF(AND(S25>0,AA25>0),AA25/(S25),0) -> 1.3826954 | AF25: ='17'!I46 -> 39145.12 | AG25: =AF25+AG24 -> 632426.72 | AH25: =IF(AND(L25>0,AF25>0),(AF25/(P25*1000)*1000),0) -> 1059.0066 | AI25: =IF(AND(M25>0,AG25>0),(AG25/(Q25*1000)*1000),0) -> 956.62503 | AJ25: =IF(AND(R25>0,AF25>0),(AF25/(R25*1000)*1000),0) -> 1139.6955 | AK25: =IF(AND(S25>0,AG25>0),(AG25/(S25*1000)*1000),0) -> 996.18762 | AL25: 5218.3 | AM25: 4924 | AN25: 4009.6 | AO25: =SUM(AL25:AN25) -> 14151.9 | AP25: =+[1]Des!N20 -> 13592 | AQ25: =+AP25-AO25 -> -559.9 | AR25: =+AL25/AO25 -> 0.36873494 | AS25: =+AM25/AO25 -> 0.34793915 | AT25: =1-AR25-AS25 -> 0.28332591 | AU25: =+AR25*AQ25 -> -206.45469 | AV25: =+AS25*AQ25 -> -194.81113 | AW25: =+AT25*AQ25 -> -158.63418 | AX25: =+AL25+AU25 -> 5011.8453 | AY25: =+AM25+AV25 -> 4729.1889 | AZ25: =+AN25+AW25 -> 3850.9658 | BA25: =+SUM(Efficiency2!K73:K74) -> 41.238689 | BB25: =BB24+BA25 -> 733.29753 | BC25: =+R25/BA25 -> 0.83288294 | BD25: =+S25/BB25 -> 0.86574272
A26: =A25+1 -> 46009 | B26: Facial | C26: 11,5 | D26: =+'18'!F42 -> 1213.3889 | E26: =+'18'!G42 -> 922.17556 | F26: =1-(E26/D26) -> 0.24 | G26: =+P26/N26 -> 0.85601425 | H26: =+P26/L26 -> 0.8444538 | I26: =+R26/P26 -> 1.0196381 | J26: =+R26/L26 -> 0.86103724 | K26: =+S26/M26 -> 0.86549076 | L26: =+Efficiency1!K78 -> 41.487172 | M26: =M25+L26 -> 774.7847 | N26: =+Efficiency1!C78 -> 40.926889 | O26: =O25+N26 -> 761.88446 | P26: ='18'!I38 -> 35.034 | Q26: =Q25+P26 -> 696.136 | R26: ='18'!I40 -> 35.722 | S26: =S25+R26 -> 670.569 | T26: =+AX26 -> 5048.4638 | U26: =T26+U25 -> 86492.296 | V26: =T26/P26 -> 144.10184 | W26: =U26/Q26 -> 124.24626 | X26: =IF(AND(R26>0,T26>0),(T26/(R26*1000))*1000,0) -> 141.32646 | Y26: =IF(AND(S26>0,U26>0),U26/S26,0) -> 128.98344 | Z26: 47.3 | AA26: =Z26+AA25 -> 925.1 | AB26: =Z26/(P26) -> 1.350117 | AC26: =AA26/(Q26) -> 1.328907 | AD26: =IF(AND(R26>0,Z26>0),Z26/(R26),0) -> 1.324114 | AE26: =IF(AND(S26>0,AA26>0),AA26/(S26),0) -> 1.3795747 | AF26: ='18'!I46 -> 38651.8 | AG26: =AF26+AG25 -> 671078.52 | AH26: =IF(AND(L26>0,AF26>0),(AF26/(P26*1000)*1000),0) -> 1103.2654 | AI26: =IF(AND(M26>0,AG26>0),(AG26/(Q26*1000)*1000),0) -> 964.00491 | AJ26: =IF(AND(R26>0,AF26>0),(AF26/(R26*1000)*1000),0) -> 1082.0167 | AK26: =IF(AND(S26>0,AG26>0),(AG26/(S26*1000)*1000),0) -> 1000.7598 | AL26: 5274.8 | AM26: 4625.6 | AN26: 4243.5 | AO26: =SUM(AL26:AN26) -> 14143.9 | AP26: =+[1]Des!N21 -> 13537 | AQ26: =+AP26-AO26 -> -606.9 | AR26: =+AL26/AO26 -> 0.37293816 | AS26: =+AM26/AO26 -> 0.32703851 | AT26: =1-AR26-AS26 -> 0.30002333 | AU26: =+AR26*AQ26 -> -226.33617 | AV26: =+AS26*AQ26 -> -198.47967 | AW26: =+AT26*AQ26 -> -182.08416 | AX26: =+AL26+AU26 -> 5048.4638 | AY26: =+AM26+AV26 -> 4427.1203 | AZ26: =+AN26+AW26 -> 4061.4158 | BA26: =+Efficiency2!K78 -> 41.487172 | BB26: =BB25+BA26 -> 774.7847 | BC26: =+R26/BA26 -> 0.86103724 | BD26: =+S26/BB26 -> 0.86549076
A27: =A26+1 -> 46010 | B27: Facial/Toilet | C27: 11,5/14/13 | D27: =+'19'!F42 -> 1163.7431 | E27: =+'19'!G42 -> 877.01764 | F27: =1-(E27/D27) -> 0.24638206 | G27: =+P27/N27 -> 0.94535287 | H27: =+P27/L27 -> 0.93220125 | I27: =+R27/P27 -> 0.93416991 | J27: =+R27/L27 -> 0.87083436 | K27: =+S27/M27 -> 0.86577014 | L27: =+SUM(Efficiency1!K82:K84) -> 42.742916 | M27: =M26+L27 -> 817.52762 | N27: =+SUM(Efficiency1!C82:C84) -> 42.148283 | O27: =O26+N27 -> 804.03274 | P27: ='19'!I38 -> 39.845 | Q27: =Q26+P27 -> 735.981 | R27: ='19'!I40 -> 37.222 | S27: =S26+R27 -> 707.791 | T27: =+AX27 -> 5249.5582 | U27: =T27+U26 -> 91741.854 | V27: =T27/P27 -> 131.74948 | W27: =U27/Q27 -> 124.65248 | X27: =IF(AND(R27>0,T27>0),(T27/(R27*1000))*1000,0) -> 141.03375 | Y27: =IF(AND(S27>0,U27>0),U27/S27,0) -> 129.61715 | Z27: 50.7 | AA27: =Z27+AA26 -> 975.8 | AB27: =Z27/(P27) -> 1.2724307 | AC27: =AA27/(Q27) -> 1.3258494 | AD27: =IF(AND(R27>0,Z27>0),Z27/(R27),0) -> 1.3620977 | AE27: =IF(AND(S27>0,AA27>0),AA27/(S27),0) -> 1.3786556 | AF27: ='19'!I46 -> 39865.46 | AG27: =AF27+AG26 -> 710943.98 | AH27: =IF(AND(L27>0,AF27>0),(AF27/(P27*1000)*1000),0) -> 1000.5135 | AI27: =IF(AND(M27>0,AG27>0),(AG27/(Q27*1000)*1000),0) -> 965.98143 | AJ27: =IF(AND(R27>0,AF27>0),(AF27/(R27*1000)*1000),0) -> 1071.0188 | AK27: =IF(AND(S27>0,AG27>0),(AG27/(S27*1000)*1000),0) -> 1004.4547 | AL27: 5526 | AM27: 5325.4 | AN27: 4344.8 | AO27: =SUM(AL27:AN27) -> 15196.2 | AP27: =+[1]Des!N22 -> 14436 | AQ27: =+AP27-AO27 -> -760.2 | AR27: =+AL27/AO27 -> 0.36364354 | AS27: =+AM27/AO27 -> 0.35044287 | AT27: =1-AR27-AS27 -> 0.28591358 | AU27: =+AR27*AQ27 -> -276.44182 | AV27: =+AS27*AQ27 -> -266.40667 | AW27: =+AT27*AQ27 -> -217.35151 | AX27: =+AL27+AU27 -> 5249.5582 | AY27: =+AM27+AV27 -> 5058.9933 | AZ27: =+AN27+AW27 -> 4127.4485 | BA27: =+SUM(Efficiency2!K82:K84) -> 42.742916 | BB27: =BB26+BA27 -> 817.52762 | BC27: =+R27/BA27 -> 0.87083436 | BD27: =+S27/BB27 -> 0.86577014
A28: =A27+1 -> 46011 | B28: Toilet | C28: 13 | D28: =+'20'!F42 -> 1150 | E28: =+'20'!G42 -> 862.5 | F28: =1-(E28/D28) -> 0.25 | G28: =+P28/N28 -> 0.97532977 | H28: =+P28/L28 -> 0.97532977 | I28: =+R28/P28 -> 0.97669153 | J28: =+R28/L28 -> 0.95259632 | K28: =+S28/M28 -> 0.86997982 | L28: =+Efficiency1!K86 -> 41.65668 | M28: =M27+L28 -> 859.1843 | N28: =+Efficiency1!C86 -> 41.65668 | O28: =O27+N28 -> 845.68942 | P28: ='20'!I38 -> 40.629 | Q28: =Q27+P28 -> 776.61 | R28: ='20'!I40 -> 39.682 | S28: =S27+R28 -> 747.473 | T28: =+AX28 -> 5162.6465 | U28: =T28+U27 -> 96904.501 | V28: =T28/P28 -> 127.06802 | W28: =U28/Q28 -> 124.77885 | X28: =IF(AND(R28>0,T28>0),(T28/(R28*1000))*1000,0) -> 130.10046 | Y28: =IF(AND(S28>0,U28>0),U28/S28,0) -> 129.64281 | Z28: 50.4 | AA28: =Z28+AA27 -> 1026.2 | AB28: =Z28/(P28) -> 1.2404932 | AC28: =AA28/(Q28) -> 1.321384 | AD28: =IF(AND(R28>0,Z28>0),Z28/(R28),0) -> 1.2700973 | AE28: =IF(AND(S28>0,AA28>0),AA28/(S28),0) -> 1.3728924 | AF28: ='20'!I46 -> 37893.72 | AG28: =AF28+AG27 -> 748837.7 | AH28: =IF(AND(L28>0,AF28>0),(AF28/(P28*1000)*1000),0) -> 932.67666 | AI28: =IF(AND(M28>0,AG28>0),(AG28/(Q28*1000)*1000),0) -> 964.23906 | AJ28: =IF(AND(R28>0,AF28>0),(AF28/(R28*1000)*1000),0) -> 954.93473 | AK28: =IF(AND(S28>0,AG28>0),(AG28/(S28*1000)*1000),0) -> 1001.8258 | AL28: 5573.2 | AM28: 5428.6 | AN28: 4324.2 | AO28: =SUM(AL28:AN28) -> 15326 | AP28: =+[1]Des!N23 -> 14197 | AQ28: =+AP28-AO28 -> -1129 | AR28: =+AL28/AO28 -> 0.36364348 | AS28: =+AM28/AO28 -> 0.35420853 | AT28: =1-AR28-AS28 -> 0.28214798 | AU28: =+AR28*AQ28 -> -410.55349 | AV28: =+AS28*AQ28 -> -399.90144 | AW28: =+AT28*AQ28 -> -318.54507 | AX28: =+AL28+AU28 -> 5162.6465 | AY28: =+AM28+AV28 -> 5028.6986 | AZ28: =+AN28+AW28 -> 4005.6549 | BA28: =+Efficiency2!K86 -> 41.65668 | BB28: =BB27+BA28 -> 859.1843 | BC28: =+R28/BA28 -> 0.95259632 | BD28: =+S28/BB28 -> 0.86997982
A29: =A28+1 -> 46012 | B29: Toilet | C29: 13 | D29: =+'21'!F42 -> 1150 | E29: =+'21'!G42 -> 862.5 | F29: =1-(E29/D29) -> 0.25 | G29: =+P29/N29 -> 0.92575789 | H29: =+P29/L29 -> 0.92575789 | I29: =+R29/P29 -> 0.98444145 | J29: =+R29/L29 -> 0.91135443 | K29: =+S29/M29 -> 0.87189306 | L29: =+Efficiency1!K90 -> 41.65668 | M29: =M28+L29 -> 900.84098 | N29: =+Efficiency1!C90 -> 41.65668 | O29: =O28+N29 -> 887.3461 | P29: ='21'!I38 -> 38.564 | Q29: =Q28+P29 -> 815.174 | R29: ='21'!I40 -> 37.964 | S29: =S28+R29 -> 785.437 | T29: =+AX29 -> 5502.9763 | U29: =T29+U28 -> 102407.48 | V29: =T29/P29 -> 142.69724 | W29: =U29/Q29 -> 125.62653 | X29: =IF(AND(R29>0,T29>0),(T29/(R29*1000))*1000,0) -> 144.95249 | Y29: =IF(AND(S29>0,U29>0),U29/S29,0) -> 130.3828 | Z29: 48 | AA29: =Z29+AA28 -> 1074.2 | AB29: =Z29/(P29) -> 1.2446842 | AC29: =AA29/(Q29) -> 1.3177555 | AD29: =IF(AND(R29>0,Z29>0),Z29/(R29),0) -> 1.2643557 | AE29: =IF(AND(S29>0,AA29>0),AA29/(S29),0) -> 1.3676463 | AF29: ='21'!I46 -> 38539.18 | AG29: =AF29+AG28 -> 787376.88 | AH29: =IF(AND(L29>0,AF29>0),(AF29/(P29*1000)*1000),0) -> 999.35639 | AI29: =IF(AND(M29>0,AG29>0),(AG29/(Q29*1000)*1000),0) -> 965.90038 | AJ29: =IF(AND(R29>0,AF29>0),(AF29/(R29*1000)*1000),0) -> 1015.1507 | AK29: =IF(AND(S29>0,AG29>0),(AG29/(S29*1000)*1000),0) -> 1002.4698 | AL29: 5650.8 | AM29: 4875.1 | AN29: 4470.4 | AO29: =SUM(AL29:AN29) -> 14996.3 | AP29: =+[1]Des!N24 -> 14604 | AQ29: =+AP29-AO29 -> -392.3 | AR29: =+AL29/AO29 -> 0.37681295 | AS29: =+AM29/AO29 -> 0.32508685 | AT29: =1-AR29-AS29 -> 0.2981002 | AU29: =+AR29*AQ29 -> -147.82372 | AV29: =+AS29*AQ29 -> -127.53157 | AW29: =+AT29*AQ29 -> -116.94471 | AX29: =+AL29+AU29 -> 5502.9763 | AY29: =+AM29+AV29 -> 4747.5684 | AZ29: =+AN29+AW29 -> 4353.4553 | BA29: =+Efficiency2!K90 -> 41.65668 | BB29: =BB28+BA29 -> 900.84098 | BC29: =+R29/BA29 -> 0.91135443 | BD29: =+S29/BB29 -> 0.87189306
A30: =A29+1 -> 46013 | B30: Toilet | C30: 13/15 | D30: =+'22'!F42 -> 1104.1667 | E30: =+'22'!G42 -> 837.75 | F30: =1-(E30/D30) -> 0.24128302 | G30: =+P30/N30 -> 0.97929483 | H30: =+P30/L30 -> 0.97929483 | I30: =+R30/P30 -> 0.94553931 | J30: =+R30/L30 -> 0.92596176 | K30: =+S30/M30 -> 0.87437652 | L30: =+SUM(Efficiency1!K94:K95) -> 43.368962 | M30: =M29+L30 -> 944.20994 | N30: =+SUM(Efficiency1!C94:C95) -> 43.368962 | O30: =O29+N30 -> 930.71506 | P30: ='22'!I38 -> 42.471 | Q30: =Q29+P30 -> 857.645 | R30: ='22'!I40 -> 40.158 | S30: =S29+R30 -> 825.595 | T30: =+AX30 -> 5407.8162 | U30: =T30+U29 -> 107815.29 | V30: =T30/P30 -> 127.32962 | W30: =U30/Q30 -> 125.71086 | X30: =IF(AND(R30>0,T30>0),(T30/(R30*1000))*1000,0) -> 134.66348 | Y30: =IF(AND(S30>0,U30>0),U30/S30,0) -> 130.59102 | Z30: 49.5 | AA30: =Z30+AA29 -> 1123.7 | AB30: =Z30/(P30) -> 1.1655012 | AC30: =AA30/(Q30) -> 1.3102158 | AD30: =IF(AND(R30>0,Z30>0),Z30/(R30),0) -> 1.2326311 | AE30: =IF(AND(S30>0,AA30>0),AA30/(S30),0) -> 1.361079 | AF30: ='22'!I46 -> 35520.78 | AG30: =AF30+AG29 -> 822897.66 | AH30: =IF(AND(L30>0,AF30>0),(AF30/(P30*1000)*1000),0) -> 836.35375 | AI30: =IF(AND(M30>0,AG30>0),(AG30/(Q30*1000)*1000),0) -> 959.48517 | AJ30: =IF(AND(R30>0,AF30>0),(AF30/(R30*1000)*1000),0) -> 884.52562 | AK30: =IF(AND(S30>0,AG30>0),(AG30/(S30*1000)*1000),0) -> 996.73285 | AL30: 5583.5 | AM30: 4632.4 | AN30: 4301.9 | AO30: =SUM(AL30:AN30) -> 14517.8 | AP30: =+[1]Des!N25 -> 14061 | AQ30: =+AP30-AO30 -> -456.8 | AR30: =+AL30/AO30 -> 0.38459684 | AS30: =+AM30/AO30 -> 0.31908416 | AT30: =1-AR30-AS30 -> 0.296319 | AU30: =+AR30*AQ30 -> -175.68384 | AV30: =+AS30*AQ30 -> -145.75764 | AW30: =+AT30*AQ30 -> -135.35852 | AX30: =+AL30+AU30 -> 5407.8162 | AY30: =+AM30+AV30 -> 4486.6424 | AZ30: =+AN30+AW30 -> 4166.5415 | BA30: =+SUM(Efficiency2!K94:K95) -> 43.368962 | BB30: =BB29+BA30 -> 944.20994 | BC30: =+R30/BA30 -> 0.92596176 | BD30: =+S30/BB30 -> 0.87437652
A31: =A30+1 -> 46014 | B31: Toilet | C31: 15/14 | D31: =+'23'!F42 -> 1053.4028 | E31: =+'23'!G42 -> 811.12014 | F31: =1-(E31/D31) -> 0.23 | G31: =+P31/N31 -> 0.96180176 | H31: =+P31/L31 -> 0.96180176 | I31: =+R31/P31 -> 0.96984209 | J31: =+R31/L31 -> 0.93279582 | K31: =+S31/M31 -> 0.87700632 | L31: =+SUM(Efficiency1!K98:K99) -> 44.508133 | M31: =M30+L31 -> 988.71807 | N31: =+SUM(Efficiency1!C98:C99) -> 44.508133 | O31: =O30+N31 -> 975.2232 | P31: ='23'!I38 -> 42.808 | Q31: =Q30+P31 -> 900.453 | R31: ='23'!I40 -> 41.517 | S31: =S30+R31 -> 867.112 | T31: =+AX31 -> 5141.0223 | U31: =T31+U30 -> 112956.32 | V31: =T31/P31 -> 120.0949 | W31: =U31/Q31 -> 125.44388 | X31: =IF(AND(R31>0,T31>0),(T31/(R31*1000))*1000,0) -> 123.82933 | Y31: =IF(AND(S31>0,U31>0),U31/S31,0) -> 130.26727 | Z31: 50.4 | AA31: =Z31+AA30 -> 1174.1 | AB31: =Z31/(P31) -> 1.17735 | AC31: =AA31/(Q31) -> 1.3038993 | AD31: =IF(AND(R31>0,Z31>0),Z31/(R31),0) -> 1.2139605 | AE31: =IF(AND(S31>0,AA31>0),AA31/(S31),0) -> 1.354035 | AF31: ='23'!I46 -> 38342.4 | AG31: =AF31+AG30 -> 861240.06 | AH31: =IF(AND(L31>0,AF31>0),(AF31/(P31*1000)*1000),0) -> 895.68305 | AI31: =IF(AND(M31>0,AG31>0),(AG31/(Q31*1000)*1000),0) -> 956.45199 | AJ31: =IF(AND(R31>0,AF31>0),(AF31/(R31*1000)*1000),0) -> 923.53494 | AK31: =IF(AND(S31>0,AG31>0),(AG31/(S31*1000)*1000),0) -> 993.22816 | AL31: 5394.4 | AM31: 4981.3 | AN31: 4382.5 | AO31: =SUM(AL31:AN31) -> 14758.2 | AP31: =+[1]Des!N26 -> 14065 | AQ31: =+AP31-AO31 -> -693.2 | AR31: =+AL31/AO31 -> 0.36551883 | AS31: =+AM31/AO31 -> 0.33752761 | AT31: =1-AR31-AS31 -> 0.29695356 | AU31: =+AR31*AQ31 -> -253.37765 | AV31: =+AS31*AQ31 -> -233.97414 | AW31: =+AT31*AQ31 -> -205.84821 | AX31: =+AL31+AU31 -> 5141.0223 | AY31: =+AM31+AV31 -> 4747.3259 | AZ31: =+AN31+AW31 -> 4176.6518 | BA31: =+SUM(Efficiency2!K98:K99) -> 44.508133 | BB31: =BB30+BA31 -> 988.71807 | BC31: =+R31/BA31 -> 0.93279582 | BD31: =+S31/BB31 -> 0.87700632
A32: =A31+1 -> 46015 | B32: Toilet | C32: 14 | D32: =+'24'!F42 -> 1096.25 | E32: =+'24'!G42 -> 844.1125 | F32: =1-(E32/D32) -> 0.23 | G32: =+P32/N32 -> 0.9534582 | H32: =+P32/L32 -> 0.9534582 | I32: =+R32/P32 -> 0.9627569 | J32: =+R32/L32 -> 0.91794846 | K32: =+S32/M32 -> 0.87874062 | L32: =+Efficiency1!K102 -> 43.734482 | M32: =M31+L32 -> 1032.4526 | N32: =+Efficiency1!C102 -> 43.734482 | O32: =O31+N32 -> 1018.9577 | P32: ='24'!I38 -> 41.699 | Q32: =Q31+P32 -> 942.152 | R32: ='24'!I40 -> 40.146 | S32: =S31+R32 -> 907.258 | T32: =+AX32 -> 5296.3109 | U32: =T32+U31 -> 118252.63 | V32: =T32/P32 -> 127.0129 | W32: =U32/Q32 -> 125.51332 | X32: =IF(AND(R32>0,T32>0),(T32/(R32*1000))*1000,0) -> 131.92624 | Y32: =IF(AND(S32>0,U32>0),U32/S32,0) -> 130.34068 | Z32: 50 | AA32: =Z32+AA31 -> 1224.1 | AB32: =Z32/(P32) -> 1.1990695 | AC32: =AA32/(Q32) -> 1.2992596 | AD32: =IF(AND(R32>0,Z32>0),Z32/(R32),0) -> 1.2454541 | AE32: =IF(AND(S32>0,AA32>0),AA32/(S32),0) -> 1.3492303 | AF32: =+'24'!I46 -> 39339.38 | AG32: =AF32+AG31 -> 900579.44 | AH32: =IF(AND(L32>0,AF32>0),(AF32/(P32*1000)*1000),0) -> 943.41303 | AI32: =IF(AND(M32>0,AG32>0),(AG32/(Q32*1000)*1000),0) -> 955.87489 | AJ32: =IF(AND(R32>0,AF32>0),(AF32/(R32*1000)*1000),0) -> 979.90784 | AK32: =IF(AND(S32>0,AG32>0),(AG32/(S32*1000)*1000),0) -> 992.63874 | AL32: 5529.7 | AM32: 4869 | AN32: 4390.5 | AO32: =SUM(AL32:AN32) -> 14789.2 | AP32: =+[1]Des!N27 -> 14165 | AQ32: =+AP32-AO32 -> -624.2 | AR32: =+AL32/AO32 -> 0.37390123 | AS32: =+AM32/AO32 -> 0.32922673 | AT32: =1-AR32-AS32 -> 0.29687204 | AU32: =+AR32*AQ32 -> -233.38914 | AV32: =+AS32*AQ32 -> -205.50333 | AW32: =+AT32*AQ32 -> -185.30753 | AX32: =+AL32+AU32 -> 5296.3109 | AY32: =+AM32+AV32 -> 4663.4967 | AZ32: =+AN32+AW32 -> 4205.1925 | BA32: =+Efficiency2!K102 -> 43.734482 | BB32: =BB31+BA32 -> 1032.4526 | BC32: =+R32/BA32 -> 0.91794846 | BD32: =+S32/BB32 -> 0.87874062
A33: =A32+1 -> 46016 | B33: Toilet | C33: 14/13 | D33: =+'25'!F42 -> 1151.6667 | E33: =+'25'!G42 -> 886.78333 | F33: =1-(E33/D33) -> 0.23 | G33: =+P33/N33 -> 0.95289543 | H33: =+P33/L33 -> 0.95289543 | I33: =+R33/P33 -> 0.97755353 | J33: =+R33/L33 -> 0.93150629 | K33: =+S33/M33 -> 0.88087736 | L33: =+SUM(Efficiency1!K106:K107) -> 43.573512 | M33: =M32+L33 -> 1076.0261 | N33: =+SUM(Efficiency1!C106:C107) -> 43.573512 | O33: =O32+N33 -> 1062.5312 | P33: ='25'!I38 -> 41.521 | Q33: =Q32+P33 -> 983.673 | R33: ='25'!I40 -> 40.589 | S33: =S32+R33 -> 947.847 | T33: =+AX33 -> 5087.3924 | U33: =T33+U32 -> 123340.02 | V33: =T33/P33 -> 122.52577 | W33: =U33/Q33 -> 125.38722 | X33: =IF(AND(R33>0,T33>0),(T33/(R33*1000))*1000,0) -> 125.33919 | Y33: =IF(AND(S33>0,U33>0),U33/S33,0) -> 130.12651 | Z33: 52.3 | AA33: =Z33+AA32 -> 1276.4 | AB33: =Z33/(P33) -> 1.2596036 | AC33: =AA33/(Q33) -> 1.2975857 | AD33: =IF(AND(R33>0,Z33>0),Z33/(R33),0) -> 1.2885264 | AE33: =IF(AND(S33>0,AA33>0),AA33/(S33),0) -> 1.3466308 | AF33: =+'25'!I46 -> 38475.86 | AG33: =AF33+AG32 -> 939055.3 | AH33: =IF(AND(L33>0,AF33>0),(AF33/(P33*1000)*1000),0) -> 926.66024 | AI33: =IF(AND(M33>0,AG33>0),(AG33/(Q33*1000)*1000),0) -> 954.64174 | AJ33: =IF(AND(R33>0,AF33>0),(AF33/(R33*1000)*1000),0) -> 947.93811 | AK33: =IF(AND(S33>0,AG33>0),(AG33/(S33*1000)*1000),0) -> 990.72456 | AL33: 5263.1 | AM33: 5106.1 | AN33: 4460.9 | AO33: =SUM(AL33:AN33) -> 14830.1 | AP33: =+[1]Des!N28 -> 14335 | AQ33: =+AP33-AO33 -> -495.1 | AR33: =+AL33/AO33 -> 0.35489309 | AS33: =+AM33/AO33 -> 0.34430651 | AT33: =1-AR33-AS33 -> 0.3008004 | AU33: =+AR33*AQ33 -> -175.70757 | AV33: =+AS33*AQ33 -> -170.46615 | AW33: =+AT33*AQ33 -> -148.92628 | AX33: =+AL33+AU33 -> 5087.3924 | AY33: =+AM33+AV33 -> 4935.6338 | AZ33: =+AN33+AW33 -> 4311.9737 | BA33: =+SUM(Efficiency2!K106:K107) -> 43.573512 | BB33: =BB32+BA33 -> 1076.0261 | BC33: =+R33/BA33 -> 0.93150629 | BD33: =+S33/BB33 -> 0.88087736
A34: =A33+1 -> 46017 | B34: Toilet | C34: 13 | D34: =+'26'!F42 -> 1177.3611 | E34: =+'26'!G42 -> 906.56806 | F34: =1-(E34/D34) -> 0.23 | G34: =+P34/N34 -> 0.96357065 | H34: =+P34/L34 -> 0.96357065 | I34: =+R34/P34 -> 0.92078692 | J34: =+R34/L34 -> 0.88724325 | K34: =+S34/M34 -> 0.88112627 | L34: =+Efficiency1!K110 -> 43.785061 | M34: =M33+L34 -> 1119.8111 | N34: =+Efficiency1!C110 -> 43.785061 | O34: =O33+N34 -> 1106.3163 | P34: ='26'!I38 -> 42.19 | Q34: =Q33+P34 -> 1025.863 | R34: ='26'!I40 -> 38.848 | S34: =S33+R34 -> 986.695 | T34: =+AX34 -> 5425.6102 | U34: =T34+U33 -> 128765.63 | V34: =T34/P34 -> 128.59944 | W34: =U34/Q34 -> 125.51932 | X34: =IF(AND(R34>0,T34>0),(T34/(R34*1000))*1000,0) -> 139.66254 | Y34: =IF(AND(S34>0,U34>0),U34/S34,0) -> 130.50196 | Z34: 51.1 | AA34: =Z34+AA33 -> 1327.5 | AB34: =Z34/(P34) -> 1.2111875 | AC34: =AA34/(Q34) -> 1.2940324 | AD34: =IF(AND(R34>0,Z34>0),Z34/(R34),0) -> 1.315383 | AE34: =IF(AND(S34>0,AA34>0),AA34/(S34),0) -> 1.3454006 | AF34: ='26'!I46 -> 40503.36 | AG34: =AF34+AG33 -> 979558.66 | AH34: =IF(AND(L34>0,AF34>0),(AF34/(P34*1000)*1000),0) -> 960.02275 | AI34: =IF(AND(M34>0,AG34>0),(AG34/(Q34*1000)*1000),0) -> 954.86304 | AJ34: =IF(AND(R34>0,AF34>0),(AF34/(R34*1000)*1000),0) -> 1042.6112 | AK34: =IF(AND(S34>0,AG34>0),(AG34/(S34*1000)*1000),0) -> 992.76743 | AL34: 5691.5 | AM34: 4813.2 | AN34: 4646.1 | AO34: =SUM(AL34:AN34) -> 15150.8 | AP34: =+[1]Des!N29 -> 14443 | AQ34: =+AP34-AO34 -> -707.8 | AR34: =+AL34/AO34 -> 0.37565673 | AS34: =+AM34/AO34 -> 0.31768619 | AT34: =1-AR34-AS34 -> 0.30665707 | AU34: =+AR34*AQ34 -> -265.88983 | AV34: =+AS34*AQ34 -> -224.85829 | AW34: =+AT34*AQ34 -> -217.05188 | AX34: =+AL34+AU34 -> 5425.6102 | AY34: =+AM34+AV34 -> 4588.3417 | AZ34: =+AN34+AW34 -> 4429.0481 | BA34: =+Efficiency2!K110 -> 43.785061 | BB34: =BB33+BA34 -> 1119.8111 | BC34: =+R34/BA34 -> 0.88724325 | BD34: =+S34/BB34 -> 0.88112627
A35: =A34+1 -> 46018 | B35: Toilet | C35: 13 | D35: =+'27'!F42 -> 1183.3333 | E35: =+'27'!G42 -> 911.16667 | F35: =1-(E35/D35) -> 0.23 | G35: =+P35/N35 -> 0.92696273 | H35: =+P35/L35 -> 0.92696273 | I35: =+R35/P35 -> 1.0501066 | J35: =+R35/L35 -> 0.97340971 | K35: =+S35/M35 -> 0.88461576 | L35: =+Efficiency1!K114 -> 44.007163 | M35: =M34+L35 -> 1163.8183 | N35: =+Efficiency1!C114 -> 44.007163 | O35: =O34+N35 -> 1150.3234 | P35: ='27'!I38 -> 40.793 | Q35: =Q34+P35 -> 1066.656 | R35: ='27'!I40 -> 42.837 | S35: =S34+R35 -> 1029.532 | T35: =+AX35 -> 5256.4294 | U35: =T35+U34 -> 134022.06 | V35: =T35/P35 -> 128.85616 | W35: =U35/Q35 -> 125.64694 | X35: =IF(AND(R35>0,T35>0),(T35/(R35*1000))*1000,0) -> 122.70769 | Y35: =IF(AND(S35>0,U35>0),U35/S35,0) -> 130.17765 | Z35: 52.7 | AA35: =Z35+AA34 -> 1380.2 | AB35: =Z35/(P35) -> 1.2918883 | AC35: =AA35/(Q35) -> 1.2939504 | AD35: =IF(AND(R35>0,Z35>0),Z35/(R35),0) -> 1.2302449 | AE35: =IF(AND(S35>0,AA35>0),AA35/(S35),0) -> 1.3406091 | AF35: ='27'!I46 -> 40855.06 | AG35: =AF35+AG34 -> 1020413.7 | AH35: =IF(AND(L35>0,AF35>0),(AF35/(P35*1000)*1000),0) -> 1001.5213 | AI35: =IF(AND(M35>0,AG35>0),(AG35/(Q35*1000)*1000),0) -> 956.64743 | AJ35: =IF(AND(R35>0,AF35>0),(AF35/(R35*1000)*1000),0) -> 953.73299 | AK35: =IF(AND(S35>0,AG35>0),(AG35/(S35*1000)*1000),0) -> 991.14328 | AL35: 5734.4 | AM35: 5302.6 | AN35: 4588.4 | AO35: =SUM(AL35:AN35) -> 15625.4 | AP35: =+[1]Des!N30 -> 14323 | AQ35: =+AP35-AO35 -> -1302.4 | AR35: =+AL35/AO35 -> 0.3669922 | AS35: =+AM35/AO35 -> 0.33935771 | AT35: =1-AR35-AS35 -> 0.29365008 | AU35: =+AR35*AQ35 -> -477.97065 | AV35: =+AS35*AQ35 -> -441.97948 | AW35: =+AT35*AQ35 -> -382.44987 | AX35: =+AL35+AU35 -> 5256.4294 | AY35: =+AM35+AV35 -> 4860.6205 | AZ35: =+AN35+AW35 -> 4205.9501 | BA35: =+Efficiency2!K114 -> 44.007163 | BB35: =BB34+BA35 -> 1163.8183 | BC35: =+R35/BA35 -> 0.97340971 | BD35: =+S35/BB35 -> 0.88461576
A36: =A35+1 -> 46019 | B36: Toilet | C36: 13/12,5 | D36: =+'28'!F42 -> 1190 | E36: =+'28'!G42 -> 920.26667 | F36: =1-(E36/D36) -> 0.22666667 | G36: =+P36/N36 -> 0.99041577 | H36: =+P36/L36 -> 0.95589271 | I36: =+R36/P36 -> 0.92781261 | J36: =+R36/L36 -> 0.88688931 | K36: =+S36/M36 -> 0.88469897 | L36: =+SUM(Efficiency1!K118:K119) -> 44.215213 | M36: =M35+L36 -> 1208.0335 | N36: =+SUM(Efficiency1!C118:C119) -> 42.673997 | O36: =O35+N36 -> 1192.9974 | P36: ='28'!I38 -> 42.265 | Q36: =Q35+P36 -> 1108.921 | R36: ='28'!I40 -> 39.214 | S36: =S35+R36 -> 1068.746 | T36: =+AX36 -> 5627.5976 | U36: =T36+U35 -> 139649.66 | V36: =T36/P36 -> 133.1503 | W36: =U36/Q36 -> 125.93292 | X36: =IF(AND(R36>0,T36>0),(T36/(R36*1000))*1000,0) -> 143.50991 | Y36: =IF(AND(S36>0,U36>0),U36/S36,0) -> 130.66683 | Z36: 52.7 | AA36: =Z36+AA35 -> 1432.9 | AB36: =Z36/(P36) -> 1.2468946 | AC36: =AA36/(Q36) -> 1.292157 | AD36: =IF(AND(R36>0,Z36>0),Z36/(R36),0) -> 1.3439078 | AE36: =IF(AND(S36>0,AA36>0),AA36/(S36),0) -> 1.3407302 | AF36: ='28'!I46 -> 39469.66 | AG36: =AF36+AG35 -> 1059883.4 | AH36: =IF(AND(L36>0,AF36>0),(AF36/(P36*1000)*1000),0) -> 933.86159 | AI36: =IF(AND(M36>0,AG36>0),(AG36/(Q36*1000)*1000),0) -> 955.77898 | AJ36: =IF(AND(R36>0,AF36>0),(AF36/(R36*1000)*1000),0) -> 1006.5196 | AK36: =IF(AND(S36>0,AG36>0),(AG36/(S36*1000)*1000),0) -> 991.70746 | AL36: 5683.8 | AM36: 5261.6 | AN36: 4497.3 | AO36: =SUM(AL36:AN36) -> 15442.7 | AP36: =+[1]Des!N31 -> 15290 | AQ36: =+AP36-AO36 -> -152.7 | AR36: =+AL36/AO36 -> 0.3680574 | AS36: =+AM36/AO36 -> 0.34071762 | AT36: =1-AR36-AS36 -> 0.29122498 | AU36: =+AR36*AQ36 -> -56.202365 | AV36: =+AS36*AQ36 -> -52.027581 | AW36: =+AT36*AQ36 -> -44.470054 | AX36: =+AL36+AU36 -> 5627.5976 | AY36: =+AM36+AV36 -> 5209.5724 | AZ36: =+AN36+AW36 -> 4452.8299 | BA36: =+SUM(Efficiency2!K118:K119) -> 44.215213 | BB36: =BB35+BA36 -> 1208.0335 | BC36: =+R36/BA36 -> 0.88688931 | BD36: =+S36/BB36 -> 0.88469897
A37: =A36+1 -> 46020 | B37: Toilet | C37: 12,5/13 | D37: =+'29'!F42 -> 1190 | E37: =+'29'!G42 -> 926.66292 | F37: =1-(E37/D37) -> 0.22129167 | G37: =+P37/N37 -> 0.96147211 | H37: =+P37/L37 -> 0.93220147 | I37: =+R37/P37 -> 0.99018941 | J37: =+R37/L37 -> 0.92305602 | K37: =+S37/M37 -> 0.88605212 | L37: =+SUM(Efficiency1!K122:K123) -> 44.175 | M37: =M36+L37 -> 1252.2085 | N37: =+SUM(Efficiency1!C122:C123) -> 42.830155 | O37: =O36+N37 -> 1235.8276 | P37: ='29'!I38 -> 41.18 | Q37: =Q36+P37 -> 1150.101 | R37: ='29'!I40 -> 40.776 | S37: =S36+R37 -> 1109.522 | T37: =+AX37 -> 5312.0585 | U37: =T37+U36 -> 144961.71 | V37: =T37/P37 -> 128.99608 | W37: =U37/Q37 -> 126.0426 | X37: =IF(AND(R37>0,T37>0),(T37/(R37*1000))*1000,0) -> 130.27415 | Y37: =IF(AND(S37>0,U37>0),U37/S37,0) -> 130.6524 | Z37: 52.9 | AA37: =Z37+AA36 -> 1485.8 | AB37: =Z37/(P37) -> 1.2846042 | AC37: =AA37/(Q37) -> 1.2918865 | AD37: =IF(AND(R37>0,Z37>0),Z37/(R37),0) -> 1.2973318 | AE37: =IF(AND(S37>0,AA37>0),AA37/(S37),0) -> 1.3391352 | AF37: ='29'!I46 -> 39331 | AG37: =AF37+AG36 -> 1099214.4 | AH37: =IF(AND(L37>0,AF37>0),(AF37/(P37*1000)*1000),0) -> 955.09956 | AI37: =IF(AND(M37>0,AG37>0),(AG37/(Q37*1000)*1000),0) -> 955.75465 | AJ37: =IF(AND(R37>0,AF37>0),(AF37/(R37*1000)*1000),0) -> 964.56249 | AK37: =IF(AND(S37>0,AG37>0),(AG37/(S37*1000)*1000),0) -> 990.70986 | AL37: 5636 | AM37: 5295.7 | AN37: 4578.8 | AO37: =SUM(AL37:AN37) -> 15510.5 | AP37: =+[1]Des!N32 -> 14619 | AQ37: =+AP37-AO37 -> -891.5 | AR37: =+AL37/AO37 -> 0.36336675 | AS37: =+AM37/AO37 -> 0.34142678 | AT37: =1-AR37-AS37 -> 0.29520647 | AU37: =+AR37*AQ37 -> -323.94146 | AV37: =+AS37*AQ37 -> -304.38197 | AW37: =+AT37*AQ37 -> -263.17657 | AX37: =+AL37+AU37 -> 5312.0585 | AY37: =+AM37+AV37 -> 4991.318 | AZ37: =+AN37+AW37 -> 4315.6234 | BA37: =+SUM(Efficiency2!K122:K123) -> 44.175 | BB37: =BB36+BA37 -> 1252.2085 | BC37: =+R37/BA37 -> 0.92305602 | BD37: =+S37/BB37 -> 0.88605212
A38: =A37+1 -> 46021 | B38: Toilet | C38: 13 | D38: =+'30'!F42 -> 1180 | E38: =+'30'!G42 -> 896.8 | F38: =1-(E38/D38) -> 0.24 | G38: =+P38/N38 -> 0.96554665 | H38: =+P38/L38 -> 0.96554665 | I38: =+R38/P38 -> 0.93610865 | J38: =+R38/L38 -> 0.90385658 | K38: =+S38/M38 -> 0.88664738 | L38: =+Efficiency1!K126 -> 43.313288 | M38: =M37+L38 -> 1295.5218 | N38: =+Efficiency1!C126 -> 43.313288 | O38: =O37+N38 -> 1279.1409 | P38: ='30'!I38 -> 41.821 | Q38: =Q37+P38 -> 1191.922 | R38: ='30'!I40 -> 39.149 | S38: =S37+R38 -> 1148.671 | T38: =+AX38 -> 5381.6547 | U38: =T38+U37 -> 150343.37 | V38: =T38/P38 -> 128.68307 | W38: =U38/Q38 -> 126.13524 | X38: =IF(AND(R38>0,T38>0),(T38/(R38*1000))*1000,0) -> 137.46595 | Y38: =IF(AND(S38>0,U38>0),U38/S38,0) -> 130.88462 | Z38: 51.4 | AA38: =Z38+AA37 -> 1537.2 | AB38: =Z38/(P38) -> 1.2290476 | AC38: =AA38/(Q38) -> 1.2896817 | AD38: =IF(AND(R38>0,Z38>0),Z38/(R38),0) -> 1.3129326 | AE38: =IF(AND(S38>0,AA38>0),AA38/(S38),0) -> 1.3382422 | AF38: ='30'!I46 -> 37989 | AG38: =AF38+AG37 -> 1137203.4 | AH38: =IF(AND(L38>0,AF38>0),(AF38/(P38*1000)*1000),0) -> 908.37139 | AI38: =IF(AND(M38>0,AG38>0),(AG38/(Q38*1000)*1000),0) -> 954.09211 | AJ38: =IF(AND(R38>0,AF38>0),(AF38/(R38*1000)*1000),0) -> 970.36961 | AK38: =IF(AND(S38>0,AG38>0),(AG38/(S38*1000)*1000),0) -> 990.01662 | AL38: 5594.7 | AM38: 5042.1 | AN38: 4528.7 | AO38: =SUM(AL38:AN38) -> 15165.5 | AP38: =+[1]Des!N33 -> 14588 | AQ38: =+AP38-AO38 -> -577.5 | AR38: =+AL38/AO38 -> 0.3689097 | AS38: =+AM38/AO38 -> 0.33247173 | AT38: =1-AR38-AS38 -> 0.29861858 | AU38: =+AR38*AQ38 -> -213.04535 | AV38: =+AS38*AQ38 -> -192.00242 | AW38: =+AT38*AQ38 -> -172.45223 | AX38: =+AL38+AU38 -> 5381.6547 | AY38: =+AM38+AV38 -> 4850.0976 | AZ38: =+AN38+AW38 -> 4356.2478 | BA38: =+Efficiency2!K126 -> 43.313288 | BB38: =BB37+BA38 -> 1295.5218 | BC38: =+R38/BA38 -> 0.90385658 | BD38: =+S38/BB38 -> 0.88664738
