Workbook

Sheet eff all value

Sheet Report1
A3: PAPER MACHINE 14 DAILY REPORT 1
A6: Date | B6: Grade | C6: GSM | D6: Speed yankee (mpm) | E6: Speed reel (mpm) | F6: Creep ( % ) | G6: Real Eff PM ( % ) | H6: Real Eff PM vs Target (%) | I6: Real Eff FG vs Real Eff PM (%) | J6: Eff FG vs Target (%) | L6: Kapasitas Target (ton) | N6: Kapasitas Teori Real (ton) | P6: PM PROD Timbangan (TON) | R6: FINSHED GOODS (TON) | T6: GAS HOOD | Z6: STEAM (TON) | AF6: POWER (kWh) | BA6: Kapasitas Running (ton) | BC6: Eff FG vs Target Running(%)
T7: CONSUMPTION | V7: /TON PM. | X7: /TON FG. | Z7: CONSUMPTION | AB7: /TON PM. | AD7: /TON FG. | AF7: CONSUMPTION | AH7: /TON PM | AJ7: /TON FG | AL7: Gas based on report DCS | AO7: total | AP7: Flowmeter | AQ7: Selisih | AR7: % pengali | AU7: Adjust | AX7: PEMAKAIAN GAS
J8: TODAY | K8: TODATE | L8: TODAY | M8: TODATE | N8: TODAY | O8: TODATE | P8: TODAY | Q8: TODATE | R8: TODAY | S8: TODATE | T8: TODAY | U8: TODATE | V8: TODAY | W8: TODATE | X8: TODAY | Y8: TODATE | Z8: TODAY | AA8: TODATE | AB8: TODAY | AC8: TODATE | AD8: TODAY | AE8: TODATE | AF8: TODAY | AG8: TODATE | AH8: TODAY | AI8: TODATE | AJ8: TODAY | AK8: TODATE | AL8: 14 | AM8: 15 | AN8: 17 | AP8: PGN | AU8: 14 | AV8: 15 | AW8: 17 | AX8: 14 | AY8: 15 | AZ8: 17 | BA8: TODAY | BB8: TODATE | BC8: TODAY | BD8: TODATE
A9: 46113 | B9: Facial | C9: 11.5 | D9: =+'1'!F42 -> 1216.6667 | E9: =+'1'!G42 -> 924.66667 | F9: =1-(E9/D9) -> 0.24 | G9: =+P9/N9 -> 0.90643052 | H9: =+P9/L9 -> 0.8849605 | I9: =+R9/P9 -> 0.94666847 | J9: =+R9/L9 -> 0.8377642 | K9: =+S9/M9 -> 0.8377642 | L9: =+Efficiency1!K6 -> 41.719376 | M9: =L9 -> 41.719376 | N9: =+Efficiency1!C6 -> 40.731197 | O9: =N9 -> 40.731197 | P9: ='1'!I38 -> 36.92 | Q9: =P9 -> 36.92 | R9: ='1'!I40 -> 34.951 | S9: =R9 -> 34.951 | T9: =+AX9 -> 5302.8351 | U9: =T9 -> 5302.8351 | V9: =T9/P9 -> 143.63042 | W9: =U9/Q9 -> 143.63042 | X9: =IF(AND(R9>0,T9>0),(T9/(R9*1000))*1000,0) -> 151.72198 | Y9: =IF(AND(S9>0,U9>0),U9/S9,0) -> 151.72198 | Z9: 54.2 | AA9: =Z9 -> 54.2 | AB9: =Z9/(P9) -> 1.468039 | AC9: =AA9/(Q9) -> 1.468039 | AD9: =IF(AND(R9>0,Z9>0),Z9/(R9),0) -> 1.5507425 | AE9: =IF(AND(S9>0,AA9>0),AA9/(S9),0) -> 1.5507425 | AF9: ='1'!I46 -> 36826.02 | AG9: =AF9 -> 36826.02 | AH9: =IF(AND(L9>0,AF9>0),(AF9/(P9*1000)*1000),0) -> 997.4545 | AI9: =IF(AND(M9>0,AG9>0),(AG9/(Q9*1000)*1000),0) -> 997.4545 | AJ9: =IF(AND(R9>0,AF9>0),(AF9/(R9*1000)*1000),0) -> 1053.6471 | AK9: =IF(AND(S9>0,AG9>0),(AG9/(S9*1000)*1000),0) -> 1053.6471 | AL9: 5217.9 | AM9: 1646.5 | AN9: 3837.4 | AO9: =SUM(AL9:AN9) -> 10701.8 | AP9: =+[1]Apr!N4 -> 10876 | AQ9: =+AP9-AO9 -> 174.2 | AR9: =+AL9/AO9 -> 0.48757218 | AS9: =+AM9/AO9 -> 0.15385262 | AT9: =1-AR9-AS9 -> 0.35857519 | AU9: =+AR9*AQ9 -> 84.935074 | AV9: =+AS9*AQ9 -> 26.801127 | AW9: =+AT9*AQ9 -> 62.463799 | AX9: =IFERROR(+AL9+AU9,"-") -> 5302.8351 | AY9: =IFERROR(+AM9+AV9,"-") -> 1673.3011 | AZ9: =IFERROR(+AN9+AW9,"-") -> 3899.8638 | BA9: =+Efficiency2!K6 -> 41.719376 | BB9: =BA9 -> 41.719376 | BC9: =+R9/BA9 -> 0.8377642 | BD9: =+S9/BB9 -> 0.8377642
A10: =A9+1 -> 46114 | B10: Facial | C10: 11.5 | D10: =+'2'!F42 -> 1230 | E10: =+'2'!G42 -> 934.8 | F10: =1-(E10/D10) -> 0.24 | G10: =+P10/N10 -> 0.93116237 | H10: =+P10/L10 -> 0.91906935 | I10: =+R10/P10 -> 0.97146806 | J10: =+R10/L10 -> 0.89284652 | K10: =+S10/M10 -> 0.86530536 | L10: =+Efficiency1!K11 -> 41.719376 | M10: =M9+L10 -> 83.438752 | N10: =+Efficiency1!C11 -> 41.177566 | O10: =O9+N10 -> 81.908763 | P10: ='2'!I38 -> 38.343 | Q10: =Q9+P10 -> 75.263 | R10: ='2'!I40 -> 37.249 | S10: =S9+R10 -> 72.2 | T10: =+AX10 -> 5521.5772 | U10: =T10+U9 -> 10824.412 | V10: =T10/P10 -> 144.00483 | W10: =U10/Q10 -> 143.82116 | X10: =IF(AND(R10>0,T10>0),(T10/(R10*1000))*1000,0) -> 148.23424 | Y10: =IF(AND(S10>0,U10>0),U10/S10,0) -> 149.92261 | Z10: 53.3 | AA10: =Z10+AA9 -> 107.5 | AB10: =Z10/(P10) -> 1.3900842 | AC10: =AA10/(Q10) -> 1.4283247 | AD10: =IF(AND(R10>0,Z10>0),Z10/(R10),0) -> 1.4309109 | AE10: =IF(AND(S10>0,AA10>0),AA10/(S10),0) -> 1.4889197 | AF10: ='2'!I46 -> 38770.42 | AG10: =AF10+AG9 -> 75596.44 | AH10: =IF(AND(L10>0,AF10>0),(AF10/(P10*1000)*1000),0) -> 1011.1473 | AI10: =IF(AND(M10>0,AG10>0),(AG10/(Q10*1000)*1000),0) -> 1004.4303 | AJ10: =IF(AND(R10>0,AF10>0),(AF10/(R10*1000)*1000),0) -> 1040.8446 | AK10: =IF(AND(S10>0,AG10>0),(AG10/(S10*1000)*1000),0) -> 1047.0421 | AL10: 5210.5 | AM10: 5072.4 | AN10: 1984.7 | AO10: =SUM(AL10:AN10) -> 12267.6 | AP10: =+[1]Apr!N5 -> 13000 | AQ10: =+AP10-AO10 -> 732.4 | AR10: =+AL10/AO10 -> 0.4247367 | AS10: =+AM10/AO10 -> 0.41347941 | AT10: =1-AR10-AS10 -> 0.16178389 | AU10: =+AR10*AQ10 -> 311.07716 | AV10: =+AS10*AQ10 -> 302.83232 | AW10: =+AT10*AQ10 -> 118.49052 | AX10: =IFERROR(+AL10+AU10,"-") -> 5521.5772 | AY10: =IFERROR(+AM10+AV10,"-") -> 5375.2323 | AZ10: =IFERROR(+AN10+AW10,"-") -> 2103.1905 | BA10: =+Efficiency2!K11 -> 41.719376 | BB10: =BB9+BA10 -> 83.438752 | BC10: =+R10/BA10 -> 0.89284652 | BD10: =+S10/BB10 -> 0.86530536
A11: =A10+1 -> 46115 | B11: Facial | C11: 11.5 | D11: =+'3'!F42 -> 1230 | E11: =+'3'!G42 -> 934.8 | F11: =1-(E11/D11) -> 0.24 | G11: =+P11/N11 -> 0.91001008 | H11: =+P11/L11 -> 0.89819176 | I11: =+R11/P11 -> 0.99890585 | J11: =+R11/L11 -> 0.89720901 | K11: =+S11/M11 -> 0.87593991 | L11: =+Efficiency1!K16 -> 41.719376 | M11: =M10+L11 -> 125.15813 | N11: =+Efficiency1!C16 -> 41.177566 | O11: =O10+N11 -> 123.08633 | P11: ='3'!I38 -> 37.472 | Q11: =Q10+P11 -> 112.735 | R11: ='3'!I40 -> 37.431 | S11: =S10+R11 -> 109.631 | T11: =+AX11 -> 4681.461 | U11: =T11+U10 -> 15505.873 | V11: =T11/P11 -> 124.93224 | W11: =U11/Q11 -> 137.54267 | X11: =IF(AND(R11>0,T11>0),(T11/(R11*1000))*1000,0) -> 125.06909 | Y11: =IF(AND(S11>0,U11>0),U11/S11,0) -> 141.43694 | Z11: 57.9 | AA11: =Z11+AA10 -> 165.4 | AB11: =Z11/(P11) -> 1.5451537 | AC11: =AA11/(Q11) -> 1.4671575 | AD11: =IF(AND(R11>0,Z11>0),Z11/(R11),0) -> 1.5468462 | AE11: =IF(AND(S11>0,AA11>0),AA11/(S11),0) -> 1.5086974 | AF11: ='3'!I46 -> 39462.22 | AG11: =AF11+AG10 -> 115058.66 | AH11: =IF(AND(L11>0,AF11>0),(AF11/(P11*1000)*1000),0) -> 1053.1122 | AI11: =IF(AND(M11>0,AG11>0),(AG11/(Q11*1000)*1000),0) -> 1020.6117 | AJ11: =IF(AND(R11>0,AF11>0),(AF11/(R11*1000)*1000),0) -> 1054.2657 | AK11: =IF(AND(S11>0,AG11>0),(AG11/(S11*1000)*1000),0) -> 1049.5084 | AL11: 5238.8 | AM11: 5942.4 | AN11: 3414.6 | AO11: =SUM(AL11:AN11) -> 14595.8 | AP11: =+[1]Apr!N6 -> 13043 | AQ11: =+AP11-AO11 -> -1552.8 | AR11: =+AL11/AO11 -> 0.35892517 | AS11: =+AM11/AO11 -> 0.40713082 | AT11: =1-AR11-AS11 -> 0.23394401 | AU11: =+AR11*AQ11 -> -557.339 | AV11: =+AS11*AQ11 -> -632.19273 | AW11: =+AT11*AQ11 -> -363.26826 | AX11: =IFERROR(+AL11+AU11,"-") -> 4681.461 | AY11: =IFERROR(+AM11+AV11,"-") -> 5310.2073 | AZ11: =IFERROR(+AN11+AW11,"-") -> 3051.3317 | BA11: =+Efficiency2!K16 -> 41.719376 | BB11: =BB10+BA11 -> 125.15813 | BC11: =+R11/BA11 -> 0.89720901 | BD11: =+S11/BB11 -> 0.87593991
A12: =A11+1 -> 46116 | B12: Facial | C12: 11,5/14/13 | D12: =+'4'!F42 -> 1212.8958 | E12: =+'4'!G42 -> 915.86806 | F12: =1-(E12/D12) -> 0.24489142 | G12: =+P12/N12 -> 0.96184175 | H12: =+P12/L12 -> 0.92834966 | I12: =+R12/P12 -> 0.98834334 | J12: =+R12/L12 -> 0.91752821 | K12: =+S12/M12 -> 0.88707124 | L12: =+SUM(Efficiency1!K21:K23) -> 45.742463 | M12: =M11+L12 -> 170.90059 | N12: =+SUM(Efficiency1!C21:C23) -> 44.149674 | O12: =O11+N12 -> 167.236 | P12: ='4'!I38 -> 42.465 | Q12: =Q11+P12 -> 155.2 | R12: ='4'!I40 -> 41.97 | S12: =S11+R12 -> 151.601 | T12: =+AX12 -> 5076.3321 | U12: =T12+U11 -> 20582.205 | V12: =T12/P12 -> 119.54155 | W12: =U12/Q12 -> 132.6173 | X12: =IF(AND(R12>0,T12>0),(T12/(R12*1000))*1000,0) -> 120.95144 | Y12: =IF(AND(S12>0,U12>0),U12/S12,0) -> 135.76563 | Z12: 57.8 | AA12: =Z12+AA11 -> 223.2 | AB12: =Z12/(P12) -> 1.3611209 | AC12: =AA12/(Q12) -> 1.4381443 | AD12: =IF(AND(R12>0,Z12>0),Z12/(R12),0) -> 1.3771742 | AE12: =IF(AND(S12>0,AA12>0),AA12/(S12),0) -> 1.4722858 | AF12: ='4'!I46 -> 37387.38 | AG12: =AF12+AG11 -> 152446.04 | AH12: =IF(AND(L12>0,AF12>0),(AF12/(P12*1000)*1000),0) -> 880.42812 | AI12: =IF(AND(M12>0,AG12>0),(AG12/(Q12*1000)*1000),0) -> 982.25541 | AJ12: =IF(AND(R12>0,AF12>0),(AF12/(R12*1000)*1000),0) -> 890.81201 | AK12: =IF(AND(S12>0,AG12>0),(AG12/(S12*1000)*1000),0) -> 1005.5741 | AL12: 5363.6 | AM12: 5901.6 | AN12: =1214.4+1249.46+1272.4 -> 3736.26 | AO12: =SUM(AL12:AN12) -> 15001.46 | AP12: =+[1]Apr!N7 -> 14198 | AQ12: =+AP12-AO12 -> -803.46 | AR12: =+AL12/AO12 -> 0.35753853 | AS12: =+AM12/AO12 -> 0.39340171 | AT12: =1-AR12-AS12 -> 0.24905976 | AU12: =+AR12*AQ12 -> -287.26791 | AV12: =+AS12*AQ12 -> -316.08254 | AW12: =+AT12*AQ12 -> -200.10955 | AX12: =IFERROR(+AL12+AU12,"-") -> 5076.3321 | AY12: =IFERROR(+AM12+AV12,"-") -> 5585.5175 | AZ12: =IFERROR(+AN12+AW12,"-") -> 3536.1504 | BA12: =+SUM(Efficiency2!K21:K23) -> 45.742463 | BB12: =BB11+BA12 -> 170.90059 | BC12: =+R12/BA12 -> 0.91752821 | BD12: =+S12/BB12 -> 0.88707124
A13: =A12+1 -> 46117 | B13: Facial | C13: 11,5 | D13: =+'5'!F42 -> 1230 | E13: =+'5'!G42 -> 934.8 | F13: =1-(E13/D13) -> 0.24 | G13: =+P13/N13 -> 0.94808906 | H13: =+P13/L13 -> 0.93577622 | I13: =+R13/P13 -> 1.0063781 | J13: =+R13/L13 -> 0.94174467 | K13: =+S13/M13 -> 0.89779903 | L13: =+Efficiency1!K26 -> 41.719376 | M13: =M12+L13 -> 212.61997 | N13: =+Efficiency1!C26 -> 41.177566 | O13: =O12+N13 -> 208.41357 | P13: ='5'!I38 -> 39.04 | Q13: =Q12+P13 -> 194.24 | R13: ='5'!I40 -> 39.289 | S13: =S12+R13 -> 190.89 | T13: =+AX13 -> 5122.2748 | U13: =T13+U12 -> 25704.48 | V13: =T13/P13 -> 131.20581 | W13: =U13/Q13 -> 132.33361 | X13: =IF(AND(R13>0,T13>0),(T13/(R13*1000))*1000,0) -> 130.37427 | Y13: =IF(AND(S13>0,U13>0),U13/S13,0) -> 134.65598 | Z13: 57.5 | AA13: =Z13+AA12 -> 280.7 | AB13: =Z13/(P13) -> 1.4728484 | AC13: =AA13/(Q13) -> 1.4451194 | AD13: =IF(AND(R13>0,Z13>0),Z13/(R13),0) -> 1.463514 | AE13: =IF(AND(S13>0,AA13>0),AA13/(S13),0) -> 1.4704804 | AF13: ='5'!I46 -> 38874.88 | AG13: =AF13+AG12 -> 191320.92 | AH13: =IF(AND(L13>0,AF13>0),(AF13/(P13*1000)*1000),0) -> 995.77049 | AI13: =IF(AND(M13>0,AG13>0),(AG13/(Q13*1000)*1000),0) -> 984.97179 | AJ13: =IF(AND(R13>0,AF13>0),(AF13/(R13*1000)*1000),0) -> 989.45965 | AK13: =IF(AND(S13>0,AG13>0),(AG13/(S13*1000)*1000),0) -> 1002.2574 | AL13: 5413.4 | AM13: 5904.6 | AN13: =1221.41+1098.43+1271.99 -> 3591.83 | AO13: =SUM(AL13:AN13) -> 14909.83 | AP13: =+[1]Apr!N8 -> 14108 | AQ13: =+AP13-AO13 -> -801.83 | AR13: =+AL13/AO13 -> 0.3630759 | AS13: =+AM13/AO13 -> 0.39602061 | AT13: =1-AR13-AS13 -> 0.24090348 | AU13: =+AR13*AQ13 -> -291.12515 | AV13: =+AS13*AQ13 -> -317.54121 | AW13: =+AT13*AQ13 -> -193.16364 | AX13: =IFERROR(+AL13+AU13,"-") -> 5122.2748 | AY13: =IFERROR(+AM13+AV13,"-") -> 5587.0588 | AZ13: =IFERROR(+AN13+AW13,"-") -> 3398.6664 | BA13: =+Efficiency2!K26 -> 41.719376 | BB13: =BB12+BA13 -> 212.61997 | BC13: =+R13/BA13 -> 0.94174467 | BD13: =+S13/BB13 -> 0.89779903
A14: =A13+1 -> 46118 | B14: Facial | C14: 11,5/12/14 | D14: =+'6'!F42 -> 1170.5 | E14: =+'6'!G42 -> 881.02688 | F14: =1-(E14/D14) -> 0.24730724 | G14: =+P14/N14 -> 0.93506328 | H14: =+P14/L14 -> 0.88710293 | I14: =+R14/P14 -> 0.93972365 | J14: =+R14/L14 -> 0.83363161 | K14: =+S14/M14 -> 0.88621722 | L14: =+SUM(Efficiency1!K31:K33) -> 46.828839 | M14: =M13+L14 -> 259.44881 | N14: =+SUM(Efficiency1!C31:C33) -> 44.42694 | O14: =O13+N14 -> 252.84051 | P14: ='6'!I38 -> 41.542 | Q14: =Q13+P14 -> 235.782 | R14: ='6'!I40 -> 39.038 | S14: =S13+R14 -> 229.928 | T14: =+AX14 -> 5263.1643 | U14: =T14+U13 -> 30967.644 | V14: =T14/P14 -> 126.69501 | W14: =U14/Q14 -> 131.34016 | X14: =IF(AND(R14>0,T14>0),(T14/(R14*1000))*1000,0) -> 134.82157 | Y14: =IF(AND(S14>0,U14>0),U14/S14,0) -> 134.68409 | Z14: 55.5 | AA14: =Z14+AA13 -> 336.2 | AB14: =Z14/(P14) -> 1.3359973 | AC14: =AA14/(Q14) -> 1.4258934 | AD14: =IF(AND(R14>0,Z14>0),Z14/(R14),0) -> 1.4216917 | AE14: =IF(AND(S14>0,AA14>0),AA14/(S14),0) -> 1.4621969 | AF14: ='6'!I46 -> 37800.9 | AG14: =AF14+AG13 -> 229121.82 | AH14: =IF(AND(L14>0,AF14>0),(AF14/(P14*1000)*1000),0) -> 909.94415 | AI14: =IF(AND(M14>0,AG14>0),(AG14/(Q14*1000)*1000),0) -> 971.75281 | AJ14: =IF(AND(R14>0,AF14>0),(AF14/(R14*1000)*1000),0) -> 968.31036 | AK14: =IF(AND(S14>0,AG14>0),(AG14/(S14*1000)*1000),0) -> 996.49377 | AL14: 5537.9 | AM14: 5781.1 | AN14: 3748.5 | AO14: =SUM(AL14:AN14) -> 15067.5 | AP14: =+[1]Apr!N9 -> 14320 | AQ14: =+AP14-AO14 -> -747.5 | AR14: =+AL14/AO14 -> 0.36753941 | AS14: =+AM14/AO14 -> 0.38368011 | AT14: =1-AR14-AS14 -> 0.24878049 | AU14: =+AR14*AQ14 -> -274.73571 | AV14: =+AS14*AQ14 -> -286.80088 | AW14: =+AT14*AQ14 -> -185.96341 | AX14: =IFERROR(+AL14+AU14,"-") -> 5263.1643 | AY14: =IFERROR(+AM14+AV14,"-") -> 5494.2991 | AZ14: =IFERROR(+AN14+AW14,"-") -> 3562.5366 | BA14: =+SUM(Efficiency2!K31:K33) -> 46.828839 | BB14: =BB13+BA14 -> 259.44881 | BC14: =+R14/BA14 -> 0.83363161 | BD14: =+S14/BB14 -> 0.88621722
A15: =A14+1 -> 46119 | B15: Facial | C15: 14/16 | D15: =+'7'!F42 -> 1142.2569 | E15: =+'7'!G42 -> 856.69271 | F15: =1-(E15/D15) -> 0.25 | G15: =+P15/N15 -> 0.93800318 | H15: =+P15/L15 -> 0.8784989 | I15: =+R15/P15 -> 0.91731903 | J15: =+R15/L15 -> 0.80586376 | K15: =+S15/M15 -> 0.87335628 | L15: =+SUM(Efficiency1!K36:K37) -> 49.438878 | M15: =M14+L15 -> 308.88768 | N15: =+SUM(Efficiency1!C36:C37) -> 46.302615 | O15: =O14+N15 -> 299.14312 | P15: ='7'!I38 -> 43.432 | Q15: =Q14+P15 -> 279.214 | R15: ='7'!I40 -> 39.841 | S15: =S14+R15 -> 269.769 | T15: =+AX15 -> 5253.6523 | U15: =T15+U14 -> 36221.297 | V15: =T15/P15 -> 120.96271 | W15: =U15/Q15 -> 129.72593 | X15: =IF(AND(R15>0,T15>0),(T15/(R15*1000))*1000,0) -> 131.86547 | Y15: =IF(AND(S15>0,U15>0),U15/S15,0) -> 134.26782 | Z15: 53.2 | AA15: =Z15+AA14 -> 389.4 | AB15: =Z15/(P15) -> 1.2249033 | AC15: =AA15/(Q15) -> 1.3946292 | AD15: =IF(AND(R15>0,Z15>0),Z15/(R15),0) -> 1.3353078 | AE15: =IF(AND(S15>0,AA15>0),AA15/(S15),0) -> 1.4434572 | AF15: ='7'!I46 -> 35942.3 | AG15: =AF15+AG14 -> 265064.12 | AH15: =IF(AND(L15>0,AF15>0),(AF15/(P15*1000)*1000),0) -> 827.55342 | AI15: =IF(AND(M15>0,AG15>0),(AG15/(Q15*1000)*1000),0) -> 949.32246 | AJ15: =IF(AND(R15>0,AF15>0),(AF15/(R15*1000)*1000),0) -> 902.14352 | AK15: =IF(AND(S15>0,AG15>0),(AG15/(S15*1000)*1000),0) -> 982.5596 | AL15: 5502.1 | AM15: 5893.7 | AN15: 3736.5 | AO15: =SUM(AL15:AN15) -> 15132.3 | AP15: =+[1]Apr!N10 -> 14449 | AQ15: =+AP15-AO15 -> -683.3 | AR15: =+AL15/AO15 -> 0.36359972 | AS15: =+AM15/AO15 -> 0.38947814 | AT15: =1-AR15-AS15 -> 0.24692215 | AU15: =+AR15*AQ15 -> -248.44769 | AV15: =+AS15*AQ15 -> -266.13041 | AW15: =+AT15*AQ15 -> -168.7219 | AX15: =IFERROR(+AL15+AU15,"-") -> 5253.6523 | AY15: =IFERROR(+AM15+AV15,"-") -> 5627.5696 | AZ15: =IFERROR(+AN15+AW15,"-") -> 3567.7781 | BA15: =+SUM(Efficiency2!K36:K37) -> 49.438878 | BB15: =BB14+BA15 -> 308.88768 | BC15: =+R15/BA15 -> 0.80586376 | BD15: =+S15/BB15 -> 0.87335628
A16: =A15+1 -> 46120 | B16: Facial | C16: 14/16/15 | D16: =+'8'!F42 -> 1068.4306 | E16: =+'8'!G42 -> 801.32292 | F16: =1-(E16/D16) -> 0.25 | G16: =+P16/N16 -> 0.88555597 | H16: =+P16/L16 -> 0.8024395 | I16: =+R16/P16 -> 1.0180029 | J16: =+R16/L16 -> 0.81688571 | K16: =+S16/M16 -> 0.86494481 | L16: =+SUM(Efficiency1!K41:K43) -> 54.062643 | M16: =M15+L16 -> 362.95033 | N16: =+SUM(Efficiency1!C41:C43) -> 48.988434 | O16: =O15+N16 -> 348.13156 | P16: ='8'!I38 -> 43.382 | Q16: =Q15+P16 -> 322.596 | R16: ='8'!I40 -> 44.163 | S16: =S15+R16 -> 313.932 | T16: =+AX16 -> 4908.8077 | U16: =T16+U15 -> 41130.105 | V16: =T16/P16 -> 113.1531 | W16: =U16/Q16 -> 127.49726 | X16: =IF(AND(R16>0,T16>0),(T16/(R16*1000))*1000,0) -> 111.15204 | Y16: =IF(AND(S16>0,U16>0),U16/S16,0) -> 131.01597 | Z16: 53 | AA16: =Z16+AA15 -> 442.4 | AB16: =Z16/(P16) -> 1.2217049 | AC16: =AA16/(Q16) -> 1.3713747 | AD16: =IF(AND(R16>0,Z16>0),Z16/(R16),0) -> 1.2000996 | AE16: =IF(AND(S16>0,AA16>0),AA16/(S16),0) -> 1.4092224 | AF16: ='8'!I46 -> 34232.92 | AG16: =AF16+AG15 -> 299297.04 | AH16: =IF(AND(L16>0,AF16>0),(AF16/(P16*1000)*1000),0) -> 789.10424 | AI16: =IF(AND(M16>0,AG16>0),(AG16/(Q16*1000)*1000),0) -> 927.77666 | AJ16: =IF(AND(R16>0,AF16>0),(AF16/(R16*1000)*1000),0) -> 775.14933 | AK16: =IF(AND(S16>0,AG16>0),(AG16/(S16*1000)*1000),0) -> 953.38175 | AL16: 5014.1 | AM16: 5359.2 | AN16: 3465.3 | AO16: =SUM(AL16:AN16) -> 13838.6 | AP16: =+[1]Apr!N11 -> 13548 | AQ16: =+AP16-AO16 -> -290.6 | AR16: =+AL16/AO16 -> 0.36232711 | AS16: =+AM16/AO16 -> 0.38726461 | AT16: =1-AR16-AS16 -> 0.25040828 | AU16: =+AR16*AQ16 -> -105.29226 | AV16: =+AS16*AQ16 -> -112.53909 | AW16: =+AT16*AQ16 -> -72.768646 | AX16: =IFERROR(+AL16+AU16,"-") -> 4908.8077 | AY16: =IFERROR(+AM16+AV16,"-") -> 5246.6609 | AZ16: =IFERROR(+AN16+AW16,"-") -> 3392.5314 | BA16: =+SUM(Efficiency2!K41:K43) -> 54.062643 | BB16: =BB15+BA16 -> 362.95033 | BC16: =+R16/BA16 -> 0.81688571 | BD16: =+S16/BB16 -> 0.86494481
A17: =A16+1 -> 46121 | B17: Facial/Toilet | C17: 15/14 | D17: =+'9'!F42 -> 828.96194 | E17: =+'9'!G42 -> 627.53045 | F17: =1-(E17/D17) -> 0.24299244 | G17: =+P17/N17 -> 0.12979927 | H17: =+P17/L17 -> 0.10809239 | I17: =+R17/P17 -> 0.70502092 | J17: =+R17/L17 -> 0.076207397 | K17: =+S17/M17 -> 0.76433591 | L17: =+SUM(Efficiency1!K46:K47) -> 53.065715 | M17: =M16+L17 -> 416.01604 | N17: =+SUM(Efficiency1!C46:C47) -> 44.191313 | O17: =O16+N17 -> 392.32287 | P17: ='9'!I38 -> 5.736 | Q17: =Q16+P17 -> 328.332 | R17: ='9'!I40 -> 4.044 | S17: =S16+R17 -> 317.976 | T17: =+AX17 -> 1236.6417 | U17: =T17+U16 -> 42366.746 | V17: =T17/P17 -> 215.59305 | W17: =U17/Q17 -> 129.0363 | X17: =IF(AND(R17>0,T17>0),(T17/(R17*1000))*1000,0) -> 305.79666 | Y17: =IF(AND(S17>0,U17>0),U17/S17,0) -> 133.23882 | Z17: 18.8 | AA17: =Z17+AA16 -> 461.2 | AB17: =Z17/(P17) -> 3.2775453 | AC17: =AA17/(Q17) -> 1.4046758 | AD17: =IF(AND(R17>0,Z17>0),Z17/(R17),0) -> 4.6488625 | AE17: =IF(AND(S17>0,AA17>0),AA17/(S17),0) -> 1.4504239 | AF17: ='9'!I46 -> 13614.78 | AG17: =AF17+AG16 -> 312911.82 | AH17: =IF(AND(L17>0,AF17>0),(AF17/(P17*1000)*1000),0) -> 2373.5669 | AI17: =IF(AND(M17>0,AG17>0),(AG17/(Q17*1000)*1000),0) -> 953.03479 | AJ17: =IF(AND(R17>0,AF17>0),(AF17/(R17*1000)*1000),0) -> 3366.6617 | AK17: =IF(AND(S17>0,AG17>0),(AG17/(S17*1000)*1000),0) -> 984.0737 | AL17: 1217.7 | AM17: 5022.5 | AN17: 3962.1 | AO17: =SUM(AL17:AN17) -> 10202.3 | AP17: =+[1]Apr!N12 -> 10361 | AQ17: =+AP17-AO17 -> 158.7 | AR17: =+AL17/AO17 -> 0.11935544 | AS17: =+AM17/AO17 -> 0.49229095 | AT17: =1-AR17-AS17 -> 0.38835361 | AU17: =+AR17*AQ17 -> 18.941708 | AV17: =+AS17*AQ17 -> 78.126574 | AW17: =+AT17*AQ17 -> 61.631717 | AX17: =IFERROR(+AL17+AU17,"-") -> 1236.6417 | AY17: =IFERROR(+AM17+AV17,"-") -> 5100.6266 | AZ17: =IFERROR(+AN17+AW17,"-") -> 4023.7317 | BA17: =+SUM(Efficiency2!K46:K47) -> 53.065715 | BB17: =BB16+BA17 -> 416.01604 | BC17: =+R17/BA17 -> 0.076207397 | BD17: =+S17/BB17 -> 0.76433591
A18: =A17+1 -> 46122 | B18: Toilet | C18: 14/13 | D18: =+'10'!F42 -> 1061.6319 | E18: =+'10'!G42 -> 795.1634 | F18: =1-(E18/D18) -> 0.25099899 | G18: =+P18/N18 -> 0.93970913 | H18: =+P18/L18 -> 0.80862187 | I18: =+R18/P18 -> 0.83141404 | J18: =+R18/L18 -> 0.67229958 | K18: =+S18/M18 -> 0.75535286 | L18: =+SUM(Efficiency1!K54:K55) -> 44.99631 | M18: =M17+L18 -> 461.01235 | N18: =+SUM(Efficiency1!C54:C55) -> 38.719428 | O18: =O17+N18 -> 431.0423 | P18: ='10'!I38 -> 36.385 | Q18: =Q17+P18 -> 364.717 | R18: ='10'!I40 -> 30.251 | S18: =S17+R18 -> 348.227 | T18: =+AX18 -> 4963.7775 | U18: =T18+U17 -> 47330.524 | V18: =T18/P18 -> 136.42373 | W18: =U18/Q18 -> 129.77329 | X18: =IF(AND(R18>0,T18>0),(T18/(R18*1000))*1000,0) -> 164.08639 | Y18: =IF(AND(S18>0,U18>0),U18/S18,0) -> 135.91859 | Z18: 59.3 | AA18: =Z18+AA17 -> 520.5 | AB18: =Z18/(P18) -> 1.6297925 | AC18: =AA18/(Q18) -> 1.4271339 | AD18: =IF(AND(R18>0,Z18>0),Z18/(R18),0) -> 1.9602658 | AE18: =IF(AND(S18>0,AA18>0),AA18/(S18),0) -> 1.4947147 | AF18: ='10'!I46 -> 33661.14 | AG18: =AF18+AG17 -> 346572.96 | AH18: =IF(AND(L18>0,AF18>0),(AF18/(P18*1000)*1000),0) -> 925.13783 | AI18: =IF(AND(M18>0,AG18>0),(AG18/(Q18*1000)*1000),0) -> 950.25173 | AJ18: =IF(AND(R18>0,AF18>0),(AF18/(R18*1000)*1000),0) -> 1112.7282 | AK18: =IF(AND(S18>0,AG18>0),(AG18/(S18*1000)*1000),0) -> 995.25011 | AL18: 5204.9 | AM18: 5839 | AN18: 3982.2 | AO18: =SUM(AL18:AN18) -> 15026.1 | AP18: =+[1]Apr!N13 -> 14330 | AQ18: =+AP18-AO18 -> -696.1 | AR18: =+AL18/AO18 -> 0.34639061 | AS18: =+AM18/AO18 -> 0.38859052 | AT18: =1-AR18-AS18 -> 0.26501887 | AU18: =+AR18*AQ18 -> -241.12251 | AV18: =+AS18*AQ18 -> -270.49786 | AW18: =+AT18*AQ18 -> -184.47963 | AX18: =IFERROR(+AL18+AU18,"-") -> 4963.7775 | AY18: =IFERROR(+AM18+AV18,"-") -> 5568.5021 | AZ18: =IFERROR(+AN18+AW18,"-") -> 3797.7204 | BA18: =+SUM(Efficiency2!K54:K55) -> 44.99631 | BB18: =BB17+BA18 -> 461.01235 | BC18: =+R18/BA18 -> 0.67229958 | BD18: =+S18/BB18 -> 0.75535286
A19: =A18+1 -> 46123 | B19: Toilet | C19: 13 | D19: =+'11'!F42 -> 1150.3403 | E19: =+'11'!G42 -> 862.75521 | F19: =1-(E19/D19) -> 0.25 | G19: =+P19/N19 -> 0.90342928 | H19: =+P19/L19 -> 0.84491958 | I19: =+R19/P19 -> 1.0446806 | J19: =+R19/L19 -> 0.88267107 | K19: =+S19/M19 -> 0.76657315 | L19: =+Efficiency1!K59 -> 44.554536 | M19: =M18+L19 -> 505.56689 | N19: =+Efficiency1!C59 -> 41.669006 | O19: =O18+N19 -> 472.7113 | P19: ='11'!I38 -> 37.645 | Q19: =Q18+P19 -> 402.362 | R19: ='11'!I40 -> 39.327 | S19: =S18+R19 -> 387.554 | T19: =+AX19 -> 5423.9287 | U19: =T19+U18 -> 52754.452 | V19: =T19/P19 -> 144.08099 | W19: =U19/Q19 -> 131.11192 | X19: =IF(AND(R19>0,T19>0),(T19/(R19*1000))*1000,0) -> 137.9187 | Y19: =IF(AND(S19>0,U19>0),U19/S19,0) -> 136.12155 | Z19: 58 | AA19: =Z19+AA18 -> 578.5 | AB19: =Z19/(P19) -> 1.5407093 | AC19: =AA19/(Q19) -> 1.43776 | AD19: =IF(AND(R19>0,Z19>0),Z19/(R19),0) -> 1.4748137 | AE19: =IF(AND(S19>0,AA19>0),AA19/(S19),0) -> 1.4926952 | AF19: ='11'!I46 -> 35799.66 | AG19: =AF19+AG18 -> 382372.62 | AH19: =IF(AND(L19>0,AF19>0),(AF19/(P19*1000)*1000),0) -> 950.98048 | AI19: =IF(AND(M19>0,AG19>0),(AG19/(Q19*1000)*1000),0) -> 950.31991 | AJ19: =IF(AND(R19>0,AF19>0),(AF19/(R19*1000)*1000),0) -> 910.30742 | AK19: =IF(AND(S19>0,AG19>0),(AG19/(S19*1000)*1000),0) -> 986.63056 | AL19: 5733.2 | AM19: 5877.2 | AN19: 4094.8 | AO19: =SUM(AL19:AN19) -> 15705.2 | AP19: =+[1]Apr!N14 -> 14858 | AQ19: =+AP19-AO19 -> -847.2 | AR19: =+AL19/AO19 -> 0.36505107 | AS19: =+AM19/AO19 -> 0.37422 | AT19: =1-AR19-AS19 -> 0.26072893 | AU19: =+AR19*AQ19 -> -309.27126 | AV19: =+AS19*AQ19 -> -317.03919 | AW19: =+AT19*AQ19 -> -220.88955 | AX19: =IFERROR(+AL19+AU19,"-") -> 5423.9287 | AY19: =IFERROR(+AM19+AV19,"-") -> 5560.1608 | AZ19: =IFERROR(+AN19+AW19,"-") -> 3873.9105 | BA19: =+Efficiency2!K59 -> 44.554536 | BB19: =BB18+BA19 -> 505.56689 | BC19: =+R19/BA19 -> 0.88267107 | BD19: =+S19/BB19 -> 0.76657315
A20: =A19+1 -> 46124 | B20: Toilet | C20: 13 | D20: =+'12'!F42 -> 1153.3333 | E20: =+'12'!G42 -> 865 | F20: =1-(E20/D20) -> 0.25 | G20: =+P20/N20 -> 0.92329771 | H20: =+P20/L20 -> 0.86574799 | I20: =+R20/P20 -> 0.91854406 | J20: =+R20/L20 -> 0.79522767 | K20: =+S20/M20 -> 0.76889389 | L20: =+Efficiency1!K64 -> 44.554536 | M20: =M19+L20 -> 550.12142 | N20: =+Efficiency1!C64 -> 41.777424 | O20: =O19+N20 -> 514.48873 | P20: ='12'!I38 -> 38.573 | Q20: =Q19+P20 -> 440.935 | R20: ='12'!I40 -> 35.431 | S20: =S19+R20 -> 422.985 | T20: =+AX20 -> 5412.663 | U20: =T20+U19 -> 58167.115 | V20: =T20/P20 -> 140.32258 | W20: =U20/Q20 -> 131.91766 | X20: =IF(AND(R20>0,T20>0),(T20/(R20*1000))*1000,0) -> 152.76631 | Y20: =IF(AND(S20>0,U20>0),U20/S20,0) -> 137.51579 | Z20: 57.9 | AA20: =Z20+AA19 -> 636.4 | AB20: =Z20/(P20) -> 1.50105 | AC20: =AA20/(Q20) -> 1.4432966 | AD20: =IF(AND(R20>0,Z20>0),Z20/(R20),0) -> 1.6341622 | AE20: =IF(AND(S20>0,AA20>0),AA20/(S20),0) -> 1.5045451 | AF20: ='12'!I46 -> 37064.16 | AG20: =AF20+AG19 -> 419436.78 | AH20: =IF(AND(L20>0,AF20>0),(AF20/(P20*1000)*1000),0) -> 960.88352 | AI20: =IF(AND(M20>0,AG20>0),(AG20/(Q20*1000)*1000),0) -> 951.24402 | AJ20: =IF(AND(R20>0,AF20>0),(AF20/(R20*1000)*1000),0) -> 1046.0941 | AK20: =IF(AND(S20>0,AG20>0),(AG20/(S20*1000)*1000),0) -> 991.61148 | AL20: 5685.8 | AM20: 5708.2 | AN20: 4047.8 | AO20: =SUM(AL20:AN20) -> 15441.8 | AP20: =+[1]Apr!N15 -> 14700 | AQ20: =+AP20-AO20 -> -741.8 | AR20: =+AL20/AO20 -> 0.36820837 | AS20: =+AM20/AO20 -> 0.36965898 | AT20: =1-AR20-AS20 -> 0.26213265 | AU20: =+AR20*AQ20 -> -273.13697 | AV20: =+AS20*AQ20 -> -274.21303 | AW20: =+AT20*AQ20 -> -194.45 | AX20: =IFERROR(+AL20+AU20,"-") -> 5412.663 | AY20: =IFERROR(+AM20+AV20,"-") -> 5433.987 | AZ20: =IFERROR(+AN20+AW20,"-") -> 3853.35 | BA20: =+Efficiency2!K64 -> 44.554536 | BB20: =BB19+BA20 -> 550.12142 | BC20: =+R20/BA20 -> 0.79522767 | BD20: =+S20/BB20 -> 0.76889389
A21: =A20+1 -> 46125 | B21: Toilet | C21: 13/12 | D21: =+'13'!F42 -> 1175.6071 | E21: =+'13'!G42 -> 881.70533 | F21: =1-(E21/D21) -> 0.25 | G21: =+P21/N21 -> 0.65726539 | H21: =+P21/L21 -> 0.62760289 | I21: =+R21/P21 -> 0.90486106 | J21: =+R21/L21 -> 0.56789342 | K21: =+S21/M21 -> 0.75388855 | L21: =+SUM(Efficiency1!K69:K70) -> 44.381567 | M21: =M20+L21 -> 594.50299 | N21: =+SUM(Efficiency1!C69:C70) -> 42.37862 | O21: =O20+N21 -> 556.86735 | P21: ='13'!I38 -> 27.854 | Q21: =Q20+P21 -> 468.789 | R21: ='13'!I40 -> 25.204 | S21: =S20+R21 -> 448.189 | T21: =+AX21 -> 4004.4803 | U21: =T21+U20 -> 62171.596 | V21: =T21/P21 -> 143.76679 | W21: =U21/Q21 -> 132.6217 | X21: =IF(AND(R21>0,T21>0),(T21/(R21*1000))*1000,0) -> 158.88273 | Y21: =IF(AND(S21>0,U21>0),U21/S21,0) -> 138.71736 | Z21: 41.6 | AA21: =Z21+AA20 -> 678 | AB21: =Z21/(P21) -> 1.4935018 | AC21: =AA21/(Q21) -> 1.4462797 | AD21: =IF(AND(R21>0,Z21>0),Z21/(R21),0) -> 1.6505317 | AE21: =IF(AND(S21>0,AA21>0),AA21/(S21),0) -> 1.5127547 | AF21: ='13'!I46 -> 30629.14 | AG21: =AF21+AG20 -> 450065.92 | AH21: =IF(AND(L21>0,AF21>0),(AF21/(P21*1000)*1000),0) -> 1099.6317 | AI21: =IF(AND(M21>0,AG21>0),(AG21/(Q21*1000)*1000),0) -> 960.06075 | AJ21: =IF(AND(R21>0,AF21>0),(AF21/(R21*1000)*1000),0) -> 1215.2492 | AK21: =IF(AND(S21>0,AG21>0),(AG21/(S21*1000)*1000),0) -> 1004.1878 | AL21: 4037.1 | AM21: 3057.9 | AN21: 1506.5 | AO21: =SUM(AL21:AN21) -> 8601.5 | AP21: =+[1]Apr!N16 -> 8532 | AQ21: =+AP21-AO21 -> -69.5 | AR21: =+AL21/AO21 -> 0.46934837 | AS21: =+AM21/AO21 -> 0.35550776 | AT21: =1-AR21-AS21 -> 0.17514387 | AU21: =+AR21*AQ21 -> -32.619712 | AV21: =+AS21*AQ21 -> -24.707789 | AW21: =+AT21*AQ21 -> -12.172499 | AX21: =IFERROR(+AL21+AU21,"-") -> 4004.4803 | AY21: =IFERROR(+AM21+AV21,"-") -> 3033.1922 | AZ21: =IFERROR(+AN21+AW21,"-") -> 1494.3275 | BA21: =+SUM(Efficiency2!K69:K70) -> 37.512743 | BB21: =BB20+BA21 -> 587.63417 | BC21: =+R21/BA21 -> 0.67187835 | BD21: =+S21/BB21 -> 0.76270072
A22: =A21+1 -> 46126 | B22: Toilet | C22: 12/13 | D22: =+'14'!F42 -> 1197.6667 | E22: =+'14'!G42 -> 927.805 | F22: =1-(E22/D22) -> 0.22532285 | G22: =+P22/N22 -> 0.97434424 | H22: =+P22/L22 -> 0.94870607 | I22: =+R22/P22 -> 1.0628406 | J22: =+R22/L22 -> 1.0083233 | K22: =+S22/M22 -> 0.77196118 | L22: =+SUM(Efficiency1!K75:K76) -> 45.45665 | M22: =M21+L22 -> 639.95964 | N22: =+SUM(Efficiency1!C75:C76) -> 44.260538 | O22: =O21+N22 -> 601.12789 | P22: ='14'!I38 -> 43.125 | Q22: =Q21+P22 -> 511.914 | R22: ='14'!I40 -> 45.835 | S22: =S21+R22 -> 494.024 | T22: =+AX22 -> 5600.2625 | U22: =T22+U21 -> 67771.858 | V22: =T22/P22 -> 129.86116 | W22: =U22/Q22 -> 132.38915 | X22: =IF(AND(R22>0,T22>0),(T22/(R22*1000))*1000,0) -> 122.1831 | Y22: =IF(AND(S22>0,U22>0),U22/S22,0) -> 137.18333 | Z22: 57.1 | AA22: =Z22+AA21 -> 735.1 | AB22: =Z22/(P22) -> 1.324058 | AC22: =AA22/(Q22) -> 1.4359834 | AD22: =IF(AND(R22>0,Z22>0),Z22/(R22),0) -> 1.2457729 | AE22: =IF(AND(S22>0,AA22>0),AA22/(S22),0) -> 1.4879844 | AF22: ='14'!I46 -> 37382.34 | AG22: =AF22+AG21 -> 487448.26 | AH22: =IF(AND(L22>0,AF22>0),(AF22/(P22*1000)*1000),0) -> 866.83687 | AI22: =IF(AND(M22>0,AG22>0),(AG22/(Q22*1000)*1000),0) -> 952.20732 | AJ22: =IF(AND(R22>0,AF22>0),(AF22/(R22*1000)*1000),0) -> 815.58503 | AK22: =IF(AND(S22>0,AG22>0),(AG22/(S22*1000)*1000),0) -> 986.68943 | AL22: 5853.7 | AM22: 4960.8 | AN22: 3535.8 | AO22: =SUM(AL22:AN22) -> 14350.3 | AP22: =+[1]Apr!N17 -> 13729 | AQ22: =+AP22-AO22 -> -621.3 | AR22: =+AL22/AO22 -> 0.40791482 | AS22: =+AM22/AO22 -> 0.34569312 | AT22: =1-AR22-AS22 -> 0.24639206 | AU22: =+AR22*AQ22 -> -253.43748 | AV22: =+AS22*AQ22 -> -214.77914 | AW22: =+AT22*AQ22 -> -153.08339 | AX22: =IFERROR(+AL22+AU22,"-") -> 5600.2625 | AY22: =IFERROR(+AM22+AV22,"-") -> 4746.0209 | AZ22: =IFERROR(+AN22+AW22,"-") -> 3382.7166 | BA22: =+SUM(Efficiency2!K75:K76) -> 45.45665 | BB22: =BB21+BA22 -> 633.09082 | BC22: =+R22/BA22 -> 1.0083233 | BD22: =+S22/BB22 -> 0.7803367
A23: =A22+1 -> 46127 | B23: Toilet | C23: 13 | D23: =+'15'!F42 -> 1200 | E23: =+'15'!G42 -> 936 | F23: =1-(E23/D23) -> 0.22 | G23: =+P23/N23 -> 1.0241697 | H23: =+P23/L23 -> 0.99918993 | I23: =+R23/P23 -> 0.95720182 | J23: =+R23/L23 -> 0.95642642 | K23: =+S23/M23 -> 0.78434819 | L23: =+Efficiency1!K80 -> 46.067318 | M23: =M22+L23 -> 686.02696 | N23: =+Efficiency1!C80 -> 44.943725 | O23: =O22+N23 -> 646.07161 | P23: ='15'!I38 -> 46.03 | Q23: =Q22+P23 -> 557.944 | R23: ='15'!I40 -> 44.06 | S23: =S22+R23 -> 538.084 | T23: =+AX23 -> 5610.6426 | U23: =T23+U22 -> 73382.501 | V23: =T23/P23 -> 121.891 | W23: =U23/Q23 -> 131.52306 | X23: =IF(AND(R23>0,T23>0),(T23/(R23*1000))*1000,0) -> 127.34096 | Y23: =IF(AND(S23>0,U23>0),U23/S23,0) -> 136.37741 | Z23: 59.4 | AA23: =Z23+AA22 -> 794.5 | AB23: =Z23/(P23) -> 1.2904627 | AC23: =AA23/(Q23) -> 1.423978 | AD23: =IF(AND(R23>0,Z23>0),Z23/(R23),0) -> 1.3481616 | AE23: =IF(AND(S23>0,AA23>0),AA23/(S23),0) -> 1.4765353 | AF23: ='15'!I46 -> 35852.36 | AG23: =AF23+AG22 -> 523300.62 | AH23: =IF(AND(L23>0,AF23>0),(AF23/(P23*1000)*1000),0) -> 778.89116 | AI23: =IF(AND(M23>0,AG23>0),(AG23/(Q23*1000)*1000),0) -> 937.90886 | AJ23: =IF(AND(R23>0,AF23>0),(AF23/(R23*1000)*1000),0) -> 813.71675 | AK23: =IF(AND(S23>0,AG23>0),(AG23/(S23*1000)*1000),0) -> 972.52589 | AL23: 5863.2 | AM23: 4593.9 | AN23: 4119.8 | AO23: =SUM(AL23:AN23) -> 14576.9 | AP23: =+[1]Apr!N18 -> 13949 | AQ23: =+AP23-AO23 -> -627.9 | AR23: =+AL23/AO23 -> 0.40222544 | AS23: =+AM23/AO23 -> 0.31514931 | AT23: =1-AR23-AS23 -> 0.28262525 | AU23: =+AR23*AQ23 -> -252.55735 | AV23: =+AS23*AQ23 -> -197.88225 | AW23: =+AT23*AQ23 -> -177.46039 | AX23: =IFERROR(+AL23+AU23,"-") -> 5610.6426 | AY23: =IFERROR(+AM23+AV23,"-") -> 4396.0177 | AZ23: =IFERROR(+AN23+AW23,"-") -> 3942.3396 | BA23: =+Efficiency2!K80 -> 46.067318 | BB23: =BB22+BA23 -> 679.15813 | BC23: =+R23/BA23 -> 0.95642642 | BD23: =+S23/BB23 -> 0.79228087
A24: =A23+1 -> 46128 | B24: Toilet | C24: 13 | D24: =+'16'!F42 -> 1200 | E24: =+'16'!G42 -> 936 | F24: =1-(E24/D24) -> 0.22 | G24: =+P24/N24 -> 1.0023424 | H24: =+P24/L24 -> 0.977895 | I24: =+R24/P24 -> 1.0353393 | J24: =+R24/L24 -> 1.0124531 | K24: =+S24/M24 -> 0.79870178 | L24: =+Efficiency1!K85 -> 46.067318 | M24: =M23+L24 -> 732.09428 | N24: =+Efficiency1!C85 -> 44.943725 | O24: =O23+N24 -> 691.01533 | P24: ='16'!I38 -> 45.049 | Q24: =Q23+P24 -> 602.993 | R24: ='16'!I40 -> 46.641 | S24: =S23+R24 -> 584.725 | T24: =+AX24 -> 5525.4348 | U24: =T24+U23 -> 78907.936 | V24: =T24/P24 -> 122.65388 | W24: =U24/Q24 -> 130.86045 | X24: =IF(AND(R24>0,T24>0),(T24/(R24*1000))*1000,0) -> 118.46733 | Y24: =IF(AND(S24>0,U24>0),U24/S24,0) -> 134.9488 | Z24: 59.6 | AA24: =Z24+AA23 -> 854.1 | AB24: =Z24/(P24) -> 1.3230038 | AC24: =AA24/(Q24) -> 1.4164344 | AD24: =IF(AND(R24>0,Z24>0),Z24/(R24),0) -> 1.2778457 | AE24: =IF(AND(S24>0,AA24>0),AA24/(S24),0) -> 1.4606866 | AF24: ='16'!I46 -> 38166.34 | AG24: =AF24+AG23 -> 561466.96 | AH24: =IF(AND(L24>0,AF24>0),(AF24/(P24*1000)*1000),0) -> 847.21836 | AI24: =IF(AND(M24>0,AG24>0),(AG24/(Q24*1000)*1000),0) -> 931.13346 | AJ24: =IF(AND(R24>0,AF24>0),(AF24/(R24*1000)*1000),0) -> 818.30021 | AK24: =IF(AND(S24>0,AG24>0),(AG24/(S24*1000)*1000),0) -> 960.22397 | AL24: 5815.7 | AM24: 5255.2 | AN24: 4202.4 | AO24: =SUM(AL24:AN24) -> 15273.3 | AP24: =+[1]Apr!N19 -> 14511 | AQ24: =+AP24-AO24 -> -762.3 | AR24: =+AL24/AO24 -> 0.3807756 | AS24: =+AM24/AO24 -> 0.34407757 | AT24: =1-AR24-AS24 -> 0.27514682 | AU24: =+AR24*AQ24 -> -290.26524 | AV24: =+AS24*AQ24 -> -262.29033 | AW24: =+AT24*AQ24 -> -209.74442 | AX24: =IFERROR(+AL24+AU24,"-") -> 5525.4348 | AY24: =IFERROR(+AM24+AV24,"-") -> 4992.9097 | AZ24: =IFERROR(+AN24+AW24,"-") -> 3992.6556 | BA24: =+Efficiency2!K85 -> 46.067318 | BB24: =BB23+BA24 -> 725.22545 | BC24: =+R24/BA24 -> 1.0124531 | BD24: =+S24/BB24 -> 0.80626652
A25: =A24+1 -> 46129 | B25: Toilet | C25: 13 | D25: =+'17'!F42 -> 1200 | E25: =+'17'!G42 -> 936 | F25: =1-(E25/D25) -> 0.22 | G25: =+P25/N25 -> 0.96013404 | H25: =+P25/L25 -> 0.93671614 | I25: =+R25/P25 -> 0.99089266 | J25: =+R25/L25 -> 0.92818514 | K25: =+S25/M25 -> 0.80636722 | L25: =+Efficiency1!K90 -> 46.067318 | M25: =M24+L25 -> 778.16159 | N25: =+Efficiency1!C90 -> 44.943725 | O25: =O24+N25 -> 735.95906 | P25: ='17'!I38 -> 43.152 | Q25: =Q24+P25 -> 646.145 | R25: ='17'!I40 -> 42.759 | S25: =S24+R25 -> 627.484 | T25: =+AX25 -> 5611.4259 | U25: =T25+U24 -> 84519.362 | V25: =T25/P25 -> 130.0386 | W25: =U25/Q25 -> 130.80556 | X25: =IF(AND(R25>0,T25>0),(T25/(R25*1000))*1000,0) -> 131.2338 | Y25: =IF(AND(S25>0,U25>0),U25/S25,0) -> 134.69564 | Z25: 60.1 | AA25: =Z25+AA24 -> 914.2 | AB25: =Z25/(P25) -> 1.3927512 | AC25: =AA25/(Q25) -> 1.4148527 | AD25: =IF(AND(R25>0,Z25>0),Z25/(R25),0) -> 1.405552 | AE25: =IF(AND(S25>0,AA25>0),AA25/(S25),0) -> 1.4569296 | AF25: ='17'!I46 -> 35349.84 | AG25: =AF25+AG24 -> 596816.8 | AH25: =IF(AND(L25>0,AF25>0),(AF25/(P25*1000)*1000),0) -> 819.19355 | AI25: =IF(AND(M25>0,AG25>0),(AG25/(Q25*1000)*1000),0) -> 923.65769 | AJ25: =IF(AND(R25>0,AF25>0),(AF25/(R25*1000)*1000),0) -> 826.7228 | AK25: =IF(AND(S25>0,AG25>0),(AG25/(S25*1000)*1000),0) -> 951.12672 | AL25: 5894.6 | AM25: 5313.4 | AN25: 4191.8 | AO25: =SUM(AL25:AN25) -> 15399.8 | AP25: =+[1]Apr!N20 -> 14660 | AQ25: =+AP25-AO25 -> -739.8 | AR25: =+AL25/AO25 -> 0.3827712 | AS25: =+AM25/AO25 -> 0.34503045 | AT25: =1-AR25-AS25 -> 0.27219834 | AU25: =+AR25*AQ25 -> -283.17414 | AV25: =+AS25*AQ25 -> -255.25353 | AW25: =+AT25*AQ25 -> -201.37233 | AX25: =IFERROR(+AL25+AU25,"-") -> 5611.4259 | AY25: =IFERROR(+AM25+AV25,"-") -> 5058.1465 | AZ25: =IFERROR(+AN25+AW25,"-") -> 3990.4277 | BA25: =+Efficiency2!K85 -> 46.067318 | BB25: =BB24+BA25 -> 771.29277 | BC25: =+R25/BA25 -> 0.92818514 | BD25: =+S25/BB25 -> 0.8135484
A26: =A25+1 -> 46130 | B26: Toilet | C26: 13/12/12,5 | D26: =+'18'!F42 -> 1196.9931 | E26: =+'18'!G42 -> 913.44587 | F26: =1-(E26/D26) -> 0.2368829 | G26: =+P26/N26 -> 0.95271096 | H26: =+P26/L26 -> 0.92714191 | I26: =+R26/P26 -> 0.8964115 | J26: =+R26/L26 -> 0.83110067 | K26: =+S26/M26 -> 0.80768412 | L26: =+SUM(Efficiency1!K95:K97) -> 43.762448 | M26: =M25+L26 -> 821.92404 | N26: =+SUM(Efficiency1!C95:C97) -> 42.587943 | O26: =O25+N26 -> 778.547 | P26: ='18'!I38 -> 40.574 | Q26: =Q25+P26 -> 686.719 | R26: ='18'!I40 -> 36.371 | S26: =S25+R26 -> 663.855 | T26: =+AX26 -> 5628.2594 | U26: =T26+U25 -> 90147.621 | V26: =T26/P26 -> 138.71591 | W26: =U26/Q26 -> 131.27294 | X26: =IF(AND(R26>0,T26>0),(T26/(R26*1000))*1000,0) -> 154.7458 | Y26: =IF(AND(S26>0,U26>0),U26/S26,0) -> 135.79414 | Z26: 58.8 | AA26: =Z26+AA25 -> 973 | AB26: =Z26/(P26) -> 1.4492039 | AC26: =AA26/(Q26) -> 1.4168823 | AD26: =IF(AND(R26>0,Z26>0),Z26/(R26),0) -> 1.6166726 | AE26: =IF(AND(S26>0,AA26>0),AA26/(S26),0) -> 1.4656815 | AF26: ='18'!I46 -> 34893.78 | AG26: =AF26+AG25 -> 631710.58 | AH26: =IF(AND(L26>0,AF26>0),(AF26/(P26*1000)*1000),0) -> 860.00345 | AI26: =IF(AND(M26>0,AG26>0),(AG26/(Q26*1000)*1000),0) -> 919.89676 | AJ26: =IF(AND(R26>0,AF26>0),(AF26/(R26*1000)*1000),0) -> 959.38467 | AK26: =IF(AND(S26>0,AG26>0),(AG26/(S26*1000)*1000),0) -> 951.57916 | AL26: 5927.8 | AM26: 5580.6 | AN26: 3468.4 | AO26: =SUM(AL26:AN26) -> 14976.8 | AP26: =+[1]Apr!N21 -> 14220 | AQ26: =+AP26-AO26 -> -756.8 | AR26: =+AL26/AO26 -> 0.39579884 | AS26: =+AM26/AO26 -> 0.37261631 | AT26: =1-AR26-AS26 -> 0.23158485 | AU26: =+AR26*AQ26 -> -299.54056 | AV26: =+AS26*AQ26 -> -281.99603 | AW26: =+AT26*AQ26 -> -175.26342 | AX26: =IFERROR(+AL26+AU26,"-") -> 5628.2594 | AY26: =IFERROR(+AM26+AV26,"-") -> 5298.604 | AZ26: =IFERROR(+AN26+AW26,"-") -> 3293.1366 | BA26: =+SUM(Efficiency2!K95:K97) -> 43.762448 | BB26: =BB25+BA26 -> 815.05522 | BC26: =+R26/BA26 -> 0.83110067 | BD26: =+S26/BB26 -> 0.81449083
A27: =A26+1 -> 46131 | B27: Toilet | C27: 12,5/13,5 | D27: =+'19'!F42 -> 1161.1806 | E27: =+'19'!G42 -> 891.0375 | F27: =1-(E27/D27) -> 0.23264518 | G27: =+P27/N27 -> 1.0056189 | H27: =+P27/L27 -> 0.9473721 | I27: =+R27/P27 -> 0.95480332 | J27: =+R27/L27 -> 0.90455403 | K27: =+S27/M27 -> 0.81271535 | L27: =+SUM(Efficiency1!K100:K101) -> 45.027714 | M27: =M26+L27 -> 866.95176 | N27: =+SUM(Efficiency1!C100:C101) -> 42.419649 | O27: =O26+N27 -> 820.96665 | P27: ='19'!I38 -> 42.658 | Q27: =Q26+P27 -> 729.377 | R27: ='19'!I40 -> 40.73 | S27: =S26+R27 -> 704.585 | T27: =+AX27 -> 5750.4909 | U27: =T27+U26 -> 95898.112 | V27: =T27/P27 -> 134.80451 | W27: =U27/Q27 -> 131.47948 | X27: =IF(AND(R27>0,T27>0),(T27/(R27*1000))*1000,0) -> 141.18563 | Y27: =IF(AND(S27>0,U27>0),U27/S27,0) -> 136.10581 | Z27: 58.1 | AA27: =Z27+AA26 -> 1031.1 | AB27: =Z27/(P27) -> 1.3619954 | AC27: =AA27/(Q27) -> 1.4136722 | AD27: =IF(AND(R27>0,Z27>0),Z27/(R27),0) -> 1.426467 | AE27: =IF(AND(S27>0,AA27>0),AA27/(S27),0) -> 1.4634146 | AF27: ='19'!I46 -> 38584.46 | AG27: =AF27+AG26 -> 670295.04 | AH27: =IF(AND(L27>0,AF27>0),(AF27/(P27*1000)*1000),0) -> 904.50701 | AI27: =IF(AND(M27>0,AG27>0),(AG27/(Q27*1000)*1000),0) -> 918.99668 | AJ27: =IF(AND(R27>0,AF27>0),(AF27/(R27*1000)*1000),0) -> 947.32286 | AK27: =IF(AND(S27>0,AG27>0),(AG27/(S27*1000)*1000),0) -> 951.33311 | AL27: 6002.3 | AM27: 5304.9 | AN27: 3524 | AO27: =SUM(AL27:AN27) -> 14831.2 | AP27: =+[1]Apr!N22 -> 14209 | AQ27: =+AP27-AO27 -> -622.2 | AR27: =+AL27/AO27 -> 0.40470764 | AS27: =+AM27/AO27 -> 0.35768515 | AT27: =1-AR27-AS27 -> 0.23760721 | AU27: =+AR27*AQ27 -> -251.8091 | AV27: =+AS27*AQ27 -> -222.5517 | AW27: =+AT27*AQ27 -> -147.8392 | AX27: =IFERROR(+AL27+AU27,"-") -> 5750.4909 | AY27: =IFERROR(+AM27+AV27,"-") -> 5082.3483 | AZ27: =IFERROR(+AN27+AW27,"-") -> 3376.1608 | BA27: =+SUM(Efficiency2!K100:K101) -> 45.027714 | BB27: =BB26+BA27 -> 860.08293 | BC27: =+R27/BA27 -> 0.90455403 | BD27: =+S27/BB27 -> 0.81920588
A28: =A27+1 -> 46132 | B28: Toilet/Facial | C28: 13,5/12/14,5 | D28: =+'20'!F42 -> 1151.8194 | E28: =+'20'!G42 -> 864.58524 | F28: =1-(E28/D28) -> 0.24937433 | G28: =+P28/N28 -> 0.93833127 | H28: =+P28/L28 -> 0.93344688 | I28: =+R28/P28 -> 0.96290648 | J28: =+R28/L28 -> 0.89882205 | K28: =+S28/M28 -> 0.81702354 | L28: =+SUM(Efficiency1!K105:K107) -> 45.660874 | M28: =M27+L28 -> 912.61263 | N28: =+SUM(Efficiency1!C105:C107) -> 45.423191 | O28: =O27+N28 -> 866.38984 | P28: ='20'!I38 -> 42.622 | Q28: =Q27+P28 -> 771.999 | R28: ='20'!I40 -> 41.041 | S28: =S27+R28 -> 745.626 | T28: =+AX28 -> 5611.1479 | U28: =T28+U27 -> 101509.26 | V28: =T28/P28 -> 131.6491 | W28: =U28/Q28 -> 131.48885 | X28: =IF(AND(R28>0,T28>0),(T28/(R28*1000))*1000,0) -> 136.72054 | Y28: =IF(AND(S28>0,U28>0),U28/S28,0) -> 136.13965 | Z28: 57.1 | AA28: =Z28+AA27 -> 1088.2 | AB28: =Z28/(P28) -> 1.3396837 | AC28: =AA28/(Q28) -> 1.4095873 | AD28: =IF(AND(R28>0,Z28>0),Z28/(R28),0) -> 1.3912916 | AE28: =IF(AND(S28>0,AA28>0),AA28/(S28),0) -> 1.4594448 | AF28: ='20'!I46 -> 35544.18 | AG28: =AF28+AG27 -> 705839.22 | AH28: =IF(AND(L28>0,AF28>0),(AF28/(P28*1000)*1000),0) -> 833.93975 | AI28: =IF(AND(M28>0,AG28>0),(AG28/(Q28*1000)*1000),0) -> 914.30069 | AJ28: =IF(AND(R28>0,AF28>0),(AF28/(R28*1000)*1000),0) -> 866.06515 | AK28: =IF(AND(S28>0,AG28>0),(AG28/(S28*1000)*1000),0) -> 946.63976 | AL28: 5908.8 | AM28: 5987.3 | AN28: 3502.6 | AO28: =SUM(AL28:AN28) -> 15398.7 | AP28: =+[1]Apr!N23 -> 14623 | AQ28: =+AP28-AO28 -> -775.7 | AR28: =+AL28/AO28 -> 0.3837207 | AS28: =+AM28/AO28 -> 0.38881854 | AT28: =1-AR28-AS28 -> 0.22746076 | AU28: =+AR28*AQ28 -> -297.65215 | AV28: =+AS28*AQ28 -> -301.60654 | AW28: =+AT28*AQ28 -> -176.44131 | AX28: =IFERROR(+AL28+AU28,"-") -> 5611.1479 | AY28: =IFERROR(+AM28+AV28,"-") -> 5685.6935 | AZ28: =IFERROR(+AN28+AW28,"-") -> 3326.1587 | BA28: =+SUM(Efficiency2!K105:K107) -> 45.660874 | BB28: =BB27+BA28 -> 905.74381 | BC28: =+R28/BA28 -> 0.89882205 | BD28: =+S28/BB28 -> 0.82321954
A29: =A28+1 -> 46133 | B29: Facial | C29: 14,5 | D29: =+'21'!F42 -> 1140 | E29: =+'21'!G42 -> 855 | F29: =1-(E29/D29) -> 0.25 | G29: =+P29/N29 -> 0.96232031 | H29: =+P29/L29 -> 0.96232031 | I29: =+R29/P29 -> 0.97769255 | J29: =+R29/L29 -> 0.9408534 | K29: =+S29/M29 -> 0.82293998 | L29: =+Efficiency1!K110 -> 45.791406 | M29: =M28+L29 -> 958.40404 | N29: =+Efficiency1!C110 -> 45.791406 | O29: =O28+N29 -> 912.18125 | P29: ='21'!I38 -> 44.066 | Q29: =Q28+P29 -> 816.065 | R29: ='21'!I40 -> 43.083 | S29: =S28+R29 -> 788.709 | T29: =+AX29 -> 5839.532 | U29: =T29+U28 -> 107348.79 | V29: =T29/P29 -> 132.51786 | W29: =U29/Q29 -> 131.54441 | X29: =IF(AND(R29>0,T29>0),(T29/(R29*1000))*1000,0) -> 135.54144 | Y29: =IF(AND(S29>0,U29>0),U29/S29,0) -> 136.10697 | Z29: 56.7 | AA29: =Z29+AA28 -> 1144.9 | AB29: =Z29/(P29) -> 1.2867063 | AC29: =AA29/(Q29) -> 1.402952 | AD29: =IF(AND(R29>0,Z29>0),Z29/(R29),0) -> 1.3160643 | AE29: =IF(AND(S29>0,AA29>0),AA29/(S29),0) -> 1.4516127 | AF29: ='21'!I46 -> 36187.34 | AG29: =AF29+AG28 -> 742026.56 | AH29: =IF(AND(L29>0,AF29>0),(AF29/(P29*1000)*1000),0) -> 821.20773 | AI29: =IF(AND(M29>0,AG29>0),(AG29/(Q29*1000)*1000),0) -> 909.27384 | AJ29: =IF(AND(R29>0,AF29>0),(AF29/(R29*1000)*1000),0) -> 839.94476 | AK29: =IF(AND(S29>0,AG29>0),(AG29/(S29*1000)*1000),0) -> 940.81158 | AL29: 6118.9 | AM29: 6105.3 | AN29: 3547.9 | AO29: =SUM(AL29:AN29) -> 15772.1 | AP29: =+[1]Apr!N24 -> 15052 | AQ29: =+AP29-AO29 -> -720.1 | AR29: =+AL29/AO29 -> 0.38795722 | AS29: =+AM29/AO29 -> 0.38709493 | AT29: =1-AR29-AS29 -> 0.22494785 | AU29: =+AR29*AQ29 -> -279.36799 | AV29: =+AS29*AQ29 -> -278.74706 | AW29: =+AT29*AQ29 -> -161.98495 | AX29: =IFERROR(+AL29+AU29,"-") -> 5839.532 | AY29: =IFERROR(+AM29+AV29,"-") -> 5826.5529 | AZ29: =IFERROR(+AN29+AW29,"-") -> 3385.9151 | BA29: =+Efficiency2!K110 -> 45.791406 | BB29: =BB28+BA29 -> 951.53521 | BC29: =+R29/BA29 -> 0.9408534 | BD29: =+S29/BB29 -> 0.82888052
A30: =A29+1 -> 46134 | B30: Facial | C30: 14,5 | D30: =+'22'!F42 -> 1143.3333 | E30: =+'22'!G42 -> 857.5 | F30: =1-(E30/D30) -> 0.25 | G30: =+P30/N30 -> 0.92289002 | H30: =+P30/L30 -> 0.92289002 | I30: =+R30/P30 -> 0.97258399 | J30: =+R30/L30 -> 0.89758806 | K30: =+S30/M30 -> 0.82635344 | L30: =+Efficiency1!K115 -> 45.925299 | M30: =M29+L30 -> 1004.3293 | N30: =+Efficiency1!C115 -> 45.925299 | O30: =O29+N30 -> 958.10655 | P30: ='22'!I38 -> 42.384 | Q30: =Q29+P30 -> 858.449 | R30: ='22'!I40 -> 41.222 | S30: =S29+R30 -> 829.931 | T30: =+AX30 -> 5984.8748 | U30: =T30+U29 -> 113333.67 | V30: =T30/P30 -> 141.20599 | W30: =U30/Q30 -> 132.02143 | X30: =IF(AND(R30>0,T30>0),(T30/(R30*1000))*1000,0) -> 145.18642 | Y30: =IF(AND(S30>0,U30>0),U30/S30,0) -> 136.55794 | Z30: 57.5 | AA30: =Z30+AA29 -> 1202.4 | AB30: =Z30/(P30) -> 1.356644 | AC30: =AA30/(Q30) -> 1.4006656 | AD30: =IF(AND(R30>0,Z30>0),Z30/(R30),0) -> 1.3948862 | AE30: =IF(AND(S30>0,AA30>0),AA30/(S30),0) -> 1.4487951 | AF30: ='22'!I46 -> 35446.2 | AG30: =AF30+AG29 -> 777472.76 | AH30: =IF(AND(L30>0,AF30>0),(AF30/(P30*1000)*1000),0) -> 836.31087 | AI30: =IF(AND(M30>0,AG30>0),(AG30/(Q30*1000)*1000),0) -> 905.67146 | AJ30: =IF(AND(R30>0,AF30>0),(AF30/(R30*1000)*1000),0) -> 859.8855 | AK30: =IF(AND(S30>0,AG30>0),(AG30/(S30*1000)*1000),0) -> 936.79205 | AL30: 6253.2 | AM30: 6193.9 | AN30: 3560.8 | AO30: =SUM(AL30:AN30) -> 16007.9 | AP30: =+[1]Apr!N25 -> 15321 | AQ30: =+AP30-AO30 -> -686.9 | AR30: =+AL30/AO30 -> 0.39063213 | AS30: =+AM30/AO30 -> 0.3869277 | AT30: =1-AR30-AS30 -> 0.22244017 | AU30: =+AR30*AQ30 -> -268.32521 | AV30: =+AS30*AQ30 -> -265.78064 | AW30: =+AT30*AQ30 -> -152.79415 | AX30: =IFERROR(+AL30+AU30,"-") -> 5984.8748 | AY30: =IFERROR(+AM30+AV30,"-") -> 5928.1194 | AZ30: =IFERROR(+AN30+AW30,"-") -> 3408.0058 | BA30: =+Efficiency2!K115 -> 45.925299 | BB30: =BB29+BA30 -> 997.46051 | BC30: =+R30/BA30 -> 0.89758806 | BD30: =+S30/BB30 -> 0.83204397
A31: =A30+1 -> 46135 | B31: Facial | C31: 14,5/14 | D31: =+'23'!F42 -> 1150 | E31: =+'23'!G42 -> 862.5 | F31: =1-(E31/D31) -> 0.25 | G31: =+P31/N31 -> 0.95518896 | H31: =+P31/L31 -> 0.95518896 | I31: =+R31/P31 -> 0.95309875 | J31: =+R31/L31 -> 0.91038941 | K31: =+S31/M31 -> 0.83004277 | L31: =+SUM(Efficiency1!K120:K121) -> 46.116529 | M31: =M30+L31 -> 1050.4459 | N31: =+SUM(Efficiency1!C120:C121) -> 46.116529 | O31: =O30+N31 -> 1004.2231 | P31: ='23'!I38 -> 44.05 | Q31: =Q30+P31 -> 902.499 | R31: ='23'!I40 -> 41.984 | S31: =S30+R31 -> 871.915 | T31: =+AX31 -> 5864.5523 | U31: =T31+U30 -> 119198.22 | V31: =T31/P31 -> 133.13399 | W31: =U31/Q31 -> 132.07574 | X31: =IF(AND(R31>0,T31>0),(T31/(R31*1000))*1000,0) -> 139.68541 | Y31: =IF(AND(S31>0,U31>0),U31/S31,0) -> 136.70853 | Z31: 56.8 | AA31: =Z31+AA30 -> 1259.2 | AB31: =Z31/(P31) -> 1.2894438 | AC31: =AA31/(Q31) -> 1.395237 | AD31: =IF(AND(R31>0,Z31>0),Z31/(R31),0) -> 1.3528963 | AE31: =IF(AND(S31>0,AA31>0),AA31/(S31),0) -> 1.4441775 | AF31: ='23'!I46 -> 34824.44 | AG31: =AF31+AG30 -> 812297.2 | AH31: =IF(AND(L31>0,AF31>0),(AF31/(P31*1000)*1000),0) -> 790.56617 | AI31: =IF(AND(M31>0,AG31>0),(AG31/(Q31*1000)*1000),0) -> 900.0533 | AJ31: =IF(AND(R31>0,AF31>0),(AF31/(R31*1000)*1000),0) -> 829.46932 | AK31: =IF(AND(S31>0,AG31>0),(AG31/(S31*1000)*1000),0) -> 931.6243 | AL31: 6188.2 | AM31: 6084 | AN31: 3574.6 | AO31: =SUM(AL31:AN31) -> 15846.8 | AP31: =+[1]Apr!N26 -> 15018 | AQ31: =+AP31-AO31 -> -828.8 | AR31: =+AL31/AO31 -> 0.39050155 | AS31: =+AM31/AO31 -> 0.38392609 | AT31: =1-AR31-AS31 -> 0.22557236 | AU31: =+AR31*AQ31 -> -323.64769 | AV31: =+AS31*AQ31 -> -318.19795 | AW31: =+AT31*AQ31 -> -186.95437 | AX31: =IFERROR(+AL31+AU31,"-") -> 5864.5523 | AY31: =IFERROR(+AM31+AV31,"-") -> 5765.8021 | AZ31: =IFERROR(+AN31+AW31,"-") -> 3387.6456 | BA31: =+SUM(Efficiency2!K120:K121) -> 46.116529 | BB31: =BB30+BA31 -> 1043.577 | BC31: =+R31/BA31 -> 0.91038941 | BD31: =+S31/BB31 -> 0.83550612
A32: =A31+1 -> 46136 | B32: Facial | C32: 14/13 | D32: =+'24'!F42 -> 1167.9167 | E32: =+'24'!G42 -> 862.43472 | F32: =1-(E32/D32) -> 0.26156142 | G32: =+P32/N32 -> 0.9036751 | H32: =+P32/L32 -> 0.84636768 | I32: =+R32/P32 -> 1.0101111 | J32: =+R32/L32 -> 0.85492536 | K32: =+S32/M32 -> 0.83106723 | L32: =+SUM(Efficiency1!K125:K126) -> 45.105692 | M32: =M31+L32 -> 1095.5516 | N32: =+SUM(Efficiency1!C125:C126) -> 42.245272 | O32: =O31+N32 -> 1046.4683 | P32: ='24'!I38 -> 38.176 | Q32: =Q31+P32 -> 940.675 | R32: ='24'!I40 -> 38.562 | S32: =S31+R32 -> 910.477 | T32: =+AX32 -> 5338.0832 | U32: =T32+U31 -> 124536.3 | V32: =T32/P32 -> 139.82825 | W32: =U32/Q32 -> 132.39036 | X32: =IF(AND(R32>0,T32>0),(T32/(R32*1000))*1000,0) -> 138.42859 | Y32: =IF(AND(S32>0,U32>0),U32/S32,0) -> 136.78138 | Z32: 51.8 | AA32: =Z32+AA31 -> 1311 | AB32: =Z32/(P32) -> 1.3568734 | AC32: =AA32/(Q32) -> 1.3936801 | AD32: =IF(AND(R32>0,Z32>0),Z32/(R32),0) -> 1.3432913 | AE32: =IF(AND(S32>0,AA32>0),AA32/(S32),0) -> 1.4399046 | AF32: =+'24'!I46 -> 35587.62 | AG32: =AF32+AG31 -> 847884.82 | AH32: =IF(AND(L32>0,AF32>0),(AF32/(P32*1000)*1000),0) -> 932.19876 | AI32: =IF(AND(M32>0,AG32>0),(AG32/(Q32*1000)*1000),0) -> 901.35788 | AJ32: =IF(AND(R32>0,AF32>0),(AF32/(R32*1000)*1000),0) -> 922.86759 | AK32: =IF(AND(S32>0,AG32>0),(AG32/(S32*1000)*1000),0) -> 931.25342 | AL32: 5483.2 | AM32: 4697.9 | AN32: 3580.1 | AO32: =SUM(AL32:AN32) -> 13761.2 | AP32: =+[1]Apr!N27 -> 13397 | AQ32: =+AP32-AO32 -> -364.2 | AR32: =+AL32/AO32 -> 0.39845362 | AS32: =+AM32/AO32 -> 0.34138738 | AT32: =1-AR32-AS32 -> 0.260159 | AU32: =+AR32*AQ32 -> -145.11681 | AV32: =+AS32*AQ32 -> -124.33328 | AW32: =+AT32*AQ32 -> -94.749907 | AX32: =IFERROR(+AL32+AU32,"-") -> 5338.0832 | AY32: =IFERROR(+AM32+AV32,"-") -> 4573.5667 | AZ32: =IFERROR(+AN32+AW32,"-") -> 3485.3501 | BA32: =+SUM(Efficiency2!K125:K126) -> 45.105692 | BB32: =BB31+BA32 -> 1088.6827 | BC32: =+R32/BA32 -> 0.85492536 | BD32: =+S32/BB32 -> 0.83631068
A33: =A32+1 -> 46137 | B33: Facial | C33: 13/12 | D33: =+'25'!F42 -> 1207.3958 | E33: =+'25'!G42 -> 881.39896 | F33: =1-(E33/D33) -> 0.27 | G33: =+P33/N33 -> 0.95286495 | H33: =+P33/L33 -> 0.89783459 | I33: =+R33/P33 -> 0.98045101 | J33: =+R33/L33 -> 0.88028284 | K33: =+S33/M33 -> 0.83297397 | L33: =+SUM(Efficiency1!K130:K131) -> 44.155126 | M33: =M32+L33 -> 1139.7067 | N33: =+SUM(Efficiency1!C130:C131) -> 41.605057 | O33: =O32+N33 -> 1088.0734 | P33: ='25'!I38 -> 39.644 | Q33: =Q32+P33 -> 980.319 | R33: ='25'!I40 -> 38.869 | S33: =S32+R33 -> 949.346 | T33: =+AX33 -> 5705.5333 | U33: =T33+U32 -> 130241.84 | V33: =T33/P33 -> 143.91921 | W33: =U33/Q33 -> 132.85659 | X33: =IF(AND(R33>0,T33>0),(T33/(R33*1000))*1000,0) -> 146.78879 | Y33: =IF(AND(S33>0,U33>0),U33/S33,0) -> 137.19111 | Z33: 49.9 | AA33: =Z33+AA32 -> 1360.9 | AB33: =Z33/(P33) -> 1.2587025 | AC33: =AA33/(Q33) -> 1.3882216 | AD33: =IF(AND(R33>0,Z33>0),Z33/(R33),0) -> 1.2837994 | AE33: =IF(AND(S33>0,AA33>0),AA33/(S33),0) -> 1.4335132 | AF33: =+'25'!I46 -> 36967.4 | AG33: =AF33+AG32 -> 884852.22 | AH33: =IF(AND(L33>0,AF33>0),(AF33/(P33*1000)*1000),0) -> 932.48411 | AI33: =IF(AND(M33>0,AG33>0),(AG33/(Q33*1000)*1000),0) -> 902.61662 | AJ33: =IF(AND(R33>0,AF33>0),(AF33/(R33*1000)*1000),0) -> 951.07669 | AK33: =IF(AND(S33>0,AG33>0),(AG33/(S33*1000)*1000),0) -> 932.06504 | AL33: 5810.9 | AM33: 5277.2 | AN33: 3465.8 | AO33: =SUM(AL33:AN33) -> 14553.9 | AP33: =+[1]Apr!N28 -> 14290 | AQ33: =+AP33-AO33 -> -263.9 | AR33: =+AL33/AO33 -> 0.39926755 | AS33: =+AM33/AO33 -> 0.36259697 | AT33: =1-AR33-AS33 -> 0.23813548 | AU33: =+AR33*AQ33 -> -105.36671 | AV33: =+AS33*AQ33 -> -95.68934 | AW33: =+AT33*AQ33 -> -62.843954 | AX33: =IFERROR(+AL33+AU33,"-") -> 5705.5333 | AY33: =IFERROR(+AM33+AV33,"-") -> 5181.5107 | AZ33: =IFERROR(+AN33+AW33,"-") -> 3402.956 | BA33: =+SUM(Efficiency2!K130:K131) -> 44.155126 | BB33: =BB32+BA33 -> 1132.8379 | BC33: =+R33/BA33 -> 0.88028284 | BD33: =+S33/BB33 -> 0.83802461
A34: =A33+1 -> 46138 | B34: Facial/Toilet | C34: 12/15 | D34: =+'26'!F42 -> 1150.7083 | E34: =+'26'!G42 -> 852.75312 | F34: =1-(E34/D34) -> 0.258932 | G34: =+P34/N34 -> 0.9624294 | H34: =+P34/L34 -> 0.87481938 | I34: =+R34/P34 -> 0.96003682 | J34: =+R34/L34 -> 0.83985882 | K34: =+S34/M34 -> 0.83325458 | L34: =+SUM(Efficiency1!K135:K136) -> 48.425996 | M34: =M33+L34 -> 1188.1327 | N34: =+SUM(Efficiency1!C135:C136) -> 44.017774 | O34: =O33+N34 -> 1132.0912 | P34: ='26'!I38 -> 42.364 | Q34: =Q33+P34 -> 1022.683 | R34: ='26'!I40 -> 40.671 | S34: =S33+R34 -> 990.017 | T34: =+AX34 -> 5538.3492 | U34: =T34+U33 -> 135780.18 | V34: =T34/P34 -> 130.73244 | W34: =U34/Q34 -> 132.76859 | X34: =IF(AND(R34>0,T34>0),(T34/(R34*1000))*1000,0) -> 136.1744 | Y34: =IF(AND(S34>0,U34>0),U34/S34,0) -> 137.14935 | Z34: 49.7 | AA34: =Z34+AA33 -> 1410.6 | AB34: =Z34/(P34) -> 1.1731659 | AC34: =AA34/(Q34) -> 1.379313 | AD34: =IF(AND(R34>0,Z34>0),Z34/(R34),0) -> 1.2220009 | AE34: =IF(AND(S34>0,AA34>0),AA34/(S34),0) -> 1.424824 | AF34: ='26'!I46 -> 35779.22 | AG34: =AF34+AG33 -> 920631.44 | AH34: =IF(AND(L34>0,AF34>0),(AF34/(P34*1000)*1000),0) -> 844.56661 | AI34: =IF(AND(M34>0,AG34>0),(AG34/(Q34*1000)*1000),0) -> 900.21193 | AJ34: =IF(AND(R34>0,AF34>0),(AF34/(R34*1000)*1000),0) -> 879.72314 | AK34: =IF(AND(S34>0,AG34>0),(AG34/(S34*1000)*1000),0) -> 929.91478 | AL34: 5806 | AM34: 5673.9 | AN34: 3557.3 | AO34: =SUM(AL34:AN34) -> 15037.2 | AP34: =+[1]Apr!N29 -> 14344 | AQ34: =+AP34-AO34 -> -693.2 | AR34: =+AL34/AO34 -> 0.38610912 | AS34: =+AM34/AO34 -> 0.37732424 | AT34: =1-AR34-AS34 -> 0.23656665 | AU34: =+AR34*AQ34 -> -267.65084 | AV34: =+AS34*AQ34 -> -261.56116 | AW34: =+AT34*AQ34 -> -163.988 | AX34: =IFERROR(+AL34+AU34,"-") -> 5538.3492 | AY34: =IFERROR(+AM34+AV34,"-") -> 5412.3388 | AZ34: =IFERROR(+AN34+AW34,"-") -> 3393.312 | BA34: =+SUM(Efficiency2!K135:K136) -> 48.425996 | BB34: =BB33+BA34 -> 1181.2639 | BC34: =+R34/BA34 -> 0.83985882 | BD34: =+S34/BB34 -> 0.8380998
A35: =A34+1 -> 46139 | B35: Toilet | C35: 15/13,5/13 | D35: =+'27'!F42 -> 1180.0694 | E35: =+'27'!G42 -> 892.86736 | F35: =1-(E35/D35) -> 0.24337727 | G35: =+P35/N35 -> 0.89623763 | H35: =+P35/L35 -> 0.85534755 | I35: =+R35/P35 -> 0.94602671 | J35: =+R35/L35 -> 0.80918163 | K35: =+S35/M35 -> 0.83228094 | L35: =+SUM(Efficiency1!K140:K142) -> 50.080227 | M35: =M34+L35 -> 1238.2129 | N35: =+SUM(Efficiency1!C140:C142) -> 47.79536 | O35: =O34+N35 -> 1179.8865 | P35: ='27'!I38 -> 42.836 | Q35: =Q34+P35 -> 1065.519 | R35: ='27'!I40 -> 40.524 | S35: =S34+R35 -> 1030.541 | T35: =+AX35 -> 5748.0465 | U35: =T35+U34 -> 141528.23 | V35: =T35/P35 -> 134.18728 | W35: =U35/Q35 -> 132.82563 | X35: =IF(AND(R35>0,T35>0),(T35/(R35*1000))*1000,0) -> 141.84302 | Y35: =IF(AND(S35>0,U35>0),U35/S35,0) -> 137.33392 | Z35: 55.1 | AA35: =Z35+AA34 -> 1465.7 | AB35: =Z35/(P35) -> 1.2863012 | AC35: =AA35/(Q35) -> 1.3755738 | AD35: =IF(AND(R35>0,Z35>0),Z35/(R35),0) -> 1.3596881 | AE35: =IF(AND(S35>0,AA35>0),AA35/(S35),0) -> 1.4222627 | AF35: ='27'!I46 -> 35671.7 | AG35: =AF35+AG34 -> 956303.14 | AH35: =IF(AND(L35>0,AF35>0),(AF35/(P35*1000)*1000),0) -> 832.75049 | AI35: =IF(AND(M35>0,AG35>0),(AG35/(Q35*1000)*1000),0) -> 897.49985 | AJ35: =IF(AND(R35>0,AF35>0),(AF35/(R35*1000)*1000),0) -> 880.26108 | AK35: =IF(AND(S35>0,AG35>0),(AG35/(S35*1000)*1000),0) -> 927.96225 | AL35: 6046.9 | AM35: 5971.3 | AN35: 3612.3 | AO35: =SUM(AL35:AN35) -> 15630.5 | AP35: =+[1]Apr!N30 -> 14858 | AQ35: =+AP35-AO35 -> -772.5 | AR35: =+AL35/AO35 -> 0.38686542 | AS35: =+AM35/AO35 -> 0.38202873 | AT35: =1-AR35-AS35 -> 0.23110585 | AU35: =+AR35*AQ35 -> -298.85354 | AV35: =+AS35*AQ35 -> -295.11719 | AW35: =+AT35*AQ35 -> -178.52927 | AX35: =IFERROR(+AL35+AU35,"-") -> 5748.0465 | AY35: =IFERROR(+AM35+AV35,"-") -> 5676.1828 | AZ35: =IFERROR(+AN35+AW35,"-") -> 3433.7707 | BA35: =+SUM(Efficiency2!K140:K142) -> 50.080227 | BB35: =BB34+BA35 -> 1231.3441 | BC35: =+R35/BA35 -> 0.80918163 | BD35: =+S35/BB35 -> 0.83692366
A36: =A35+1 -> 46140 | B36: Toilet | C36: 13/12,5 | D36: =+'28'!F42 -> 1216.9375 | E36: =+'28'!G42 -> 921.88292 | F36: =1-(E36/D36) -> 0.24245664 | G36: =+P36/N36 -> 0.95326141 | H36: =+P36/L36 -> 0.94010252 | I36: =+R36/P36 -> 0.98658416 | J36: =+R36/L36 -> 0.92749025 | K36: =+S36/M36 -> 0.83554845 | L36: =+SUM(Efficiency1!K145:K146) -> 44.004775 | M36: =M35+L36 -> 1282.2177 | N36: =+SUM(Efficiency1!C145:C146) -> 43.39733 | O36: =O35+N36 -> 1223.2839 | P36: ='28'!I38 -> 41.369 | Q36: =Q35+P36 -> 1106.888 | R36: ='28'!I40 -> 40.814 | S36: =S35+R36 -> 1071.355 | T36: =+AX36 -> 5377.2349 | U36: =T36+U35 -> 146905.47 | V36: =T36/P36 -> 129.98223 | W36: =U36/Q36 -> 132.71936 | X36: =IF(AND(R36>0,T36>0),(T36/(R36*1000))*1000,0) -> 131.74976 | Y36: =IF(AND(S36>0,U36>0),U36/S36,0) -> 137.12118 | Z36: 53.6 | AA36: =Z36+AA35 -> 1519.3 | AB36: =Z36/(P36) -> 1.2956562 | AC36: =AA36/(Q36) -> 1.3725869 | AD36: =IF(AND(R36>0,Z36>0),Z36/(R36),0) -> 1.3132749 | AE36: =IF(AND(S36>0,AA36>0),AA36/(S36),0) -> 1.4181107 | AF36: ='28'!I46 -> 38094.12 | AG36: =AF36+AG35 -> 994397.26 | AH36: =IF(AND(L36>0,AF36>0),(AF36/(P36*1000)*1000),0) -> 920.83734 | AI36: =IF(AND(M36>0,AG36>0),(AG36/(Q36*1000)*1000),0) -> 898.37207 | AJ36: =IF(AND(R36>0,AF36>0),(AF36/(R36*1000)*1000),0) -> 933.35914 | AK36: =IF(AND(S36>0,AG36>0),(AG36/(S36*1000)*1000),0) -> 928.16784 | AL36: 5597.4 | AM36: 5318.8 | AN36: 3618.5 | AO36: =SUM(AL36:AN36) -> 14534.7 | AP36: =+[1]Apr!N31 -> 13963 | AQ36: =+AP36-AO36 -> -571.7 | AR36: =+AL36/AO36 -> 0.38510599 | AS36: =+AM36/AO36 -> 0.36593807 | AT36: =1-AR36-AS36 -> 0.24895595 | AU36: =+AR36*AQ36 -> -220.16509 | AV36: =+AS36*AQ36 -> -209.20679 | AW36: =+AT36*AQ36 -> -142.32811 | AX36: =IFERROR(+AL36+AU36,"-") -> 5377.2349 | AY36: =IFERROR(+AM36+AV36,"-") -> 5109.5932 | AZ36: =IFERROR(+AN36+AW36,"-") -> 3476.1719 | BA36: =+SUM(Efficiency2!K145:K146) -> 43.79538 | BB36: =BB35+BA36 -> 1275.1395 | BC36: =+R36/BA36 -> 0.93192478 | BD36: =+S36/BB36 -> 0.84018653
A37: =A36+1 -> 46141 | B37: Toilet | C37: 12,5 | D37: =+'29'!F42 -> 1193.7957 | E37: =+'29'!G42 -> 893.59759 | F37: =1-(E37/D37) -> 0.25146522 | G37: =+P37/N37 -> 0.70381939 | H37: =+P37/L37 -> 0.67279773 | I37: =+R37/P37 -> 0.97304389 | J37: =+R37/L37 -> 0.65466172 | K37: =+S37/M37 -> 0.82959796 | L37: =+Efficiency1!K150 -> 43.614892 | M37: =M36+L37 -> 1325.8326 | N37: =+Efficiency1!C150 -> 41.692514 | O37: =O36+N37 -> 1264.9764 | P37: ='29'!I38 -> 29.344 | Q37: =Q36+P37 -> 1136.232 | R37: ='29'!I40 -> 28.553 | S37: =S36+R37 -> 1099.908 | T37: =+AX37 -> 4486.6732 | U37: =T37+U36 -> 151392.14 | V37: =T37/P37 -> 152.89917 | W37: =U37/Q37 -> 133.24052 | X37: =IF(AND(R37>0,T37>0),(T37/(R37*1000))*1000,0) -> 157.13491 | Y37: =IF(AND(S37>0,U37>0),U37/S37,0) -> 137.64073 | Z37: 48.6 | AA37: =Z37+AA36 -> 1567.9 | AB37: =Z37/(P37) -> 1.6562159 | AC37: =AA37/(Q37) -> 1.3799118 | AD37: =IF(AND(R37>0,Z37>0),Z37/(R37),0) -> 1.7020979 | AE37: =IF(AND(S37>0,AA37>0),AA37/(S37),0) -> 1.4254829 | AF37: ='29'!I46 -> 32807.74 | AG37: =AF37+AG36 -> 1027205 | AH37: =IF(AND(L37>0,AF37>0),(AF37/(P37*1000)*1000),0) -> 1118.0391 | AI37: =IF(AND(M37>0,AG37>0),(AG37/(Q37*1000)*1000),0) -> 904.04512 | AJ37: =IF(AND(R37>0,AF37>0),(AF37/(R37*1000)*1000),0) -> 1149.012 | AK37: =IF(AND(S37>0,AG37>0),(AG37/(S37*1000)*1000),0) -> 933.90084 | AL37: 4676 | AM37: 2285.8 | AN37: 2722.3 | AO37: =SUM(AL37:AN37) -> 9684.1 | AP37: =+[1]Apr!N32 -> 9292 | AQ37: =+AP37-AO37 -> -392.1 | AR37: =+AL37/AO37 -> 0.48285334 | AS37: =+AM37/AO37 -> 0.23603639 | AT37: =1-AR37-AS37 -> 0.28111027 | AU37: =+AR37*AQ37 -> -189.32679 | AV37: =+AS37*AQ37 -> -92.549868 | AW37: =+AT37*AQ37 -> -110.22334 | AX37: =IFERROR(+AL37+AU37,"-") -> 4486.6732 | AY37: =IFERROR(+AM37+AV37,"-") -> 2193.2501 | AZ37: =IFERROR(+AN37+AW37,"-") -> 2612.0767 | BA37: =+Efficiency2!K150 -> 35.255371 | BB37: =BB36+BA37 -> 1310.3948 | BC37: =+R37/BA37 -> 0.80989079 | BD37: =+S37/BB37 -> 0.83937144
A38: =A37+1 -> 46142 | B38: Toilet/Facial | C38: 12,5/12 | D38: =+'30'!F42 -> 1208.0837 | E38: =+'30'!G42 -> 901.30918 | F38: =1-(E38/D38) -> 0.25393485 | G38: =+P38/N38 -> 0.81458588 | H38: =+P38/L38 -> 0.77863675 | I38: =+R38/P38 -> 0.87826887 | J38: =+R38/L38 -> 0.68385242 | K38: =+S38/M38 -> 0.82499207 | L38: =+SUM(Efficiency1!K156:K157) -> 43.266645 | M38: =M37+L38 -> 1369.0992 | N38: =+SUM(Efficiency1!C156:C157) -> 41.357211 | O38: =O37+N38 -> 1306.3336 | P38: ='30'!I38 -> 33.689 | Q38: =Q37+P38 -> 1169.921 | R38: ='30'!I40 -> 29.588 | S38: =S37+R38 -> 1129.496 | T38: =+AX38 -> 4742.5324 | U38: =T38+U37 -> 156134.67 | V38: =T38/P38 -> 140.77391 | W38: =U38/Q38 -> 133.45745 | X38: =IF(AND(R38>0,T38>0),(T38/(R38*1000))*1000,0) -> 160.28567 | Y38: =IF(AND(S38>0,U38>0),U38/S38,0) -> 138.23393 | Z38: 47.7 | AA38: =Z38+AA37 -> 1615.6 | AB38: =Z38/(P38) -> 1.4158924 | AC38: =AA38/(Q38) -> 1.3809479 | AD38: =IF(AND(R38>0,Z38>0),Z38/(R38),0) -> 1.6121401 | AE38: =IF(AND(S38>0,AA38>0),AA38/(S38),0) -> 1.4303725 | AF38: ='30'!I46 -> 37686.18 | AG38: =AF38+AG37 -> 1064891.2 | AH38: =IF(AND(L38>0,AF38>0),(AF38/(P38*1000)*1000),0) -> 1118.6494 | AI38: =IF(AND(M38>0,AG38>0),(AG38/(Q38*1000)*1000),0) -> 910.22486 | AJ38: =IF(AND(R38>0,AF38>0),(AF38/(R38*1000)*1000),0) -> 1273.6981 | AK38: =IF(AND(S38>0,AG38>0),(AG38/(S38*1000)*1000),0) -> 942.80208 | AL38: 4929.6 | AM38: 4616.4 | AN38: 3369.1 | AO38: =SUM(AL38:AN38) -> 12915.1 | AP38: =+[1]Apr!N33 -> 12425 | AQ38: =+AP38-AO38 -> -490.1 | AR38: =+AL38/AO38 -> 0.38169275 | AS38: =+AM38/AO38 -> 0.35744206 | AT38: =1-AR38-AS38 -> 0.26086519 | AU38: =+AR38*AQ38 -> -187.06762 | AV38: =+AS38*AQ38 -> -175.18236 | AW38: =+AT38*AQ38 -> -127.85003 | AX38: =IFERROR(+AL38+AU38,"-") -> 4742.5324 | AY38: =IFERROR(+AM38+AV38,"-") -> 4441.2176 | AZ38: =IFERROR(+AN38+AW38,"-") -> 3241.25 | BA38: =+SUM(Efficiency2!K156:K157) -> 37.20185 | BB38: =BB37+BA38 -> 1347.5967 | BC38: =+R38/BA38 -> 0.7953368 | BD38: =+S38/BB38 -> 0.83815582
