Workbook

Sheet Report1
A3: PAPER MACHINE 14 DAILY REPORT 1
A6: Date | B6: Grade | C6: GSM | D6: Speed yankee (mpm) | E6: Speed reel (mpm) | F6: Creep ( % ) | G6: Real Eff PM ( % ) | H6: Real Eff PM vs Target (%) | I6: Real Eff FG vs Real Eff PM (%) | J6: Eff FG vs Target (%) | L6: Kapasitas Target (ton) | N6: Kapasitas Teori Real (ton) | P6: PM PROD Timbangan (TON) | R6: FINSHED GOODS (TON) | T6: GAS HOOD | Z6: STEAM (TON) | AF6: POWER (kWh) | BA6: Kapasitas Running (ton) | BC6: Eff FG vs Target Running(%)
T7: CONSUMPTION | V7: /TON PM. | X7: /TON FG. | Z7: CONSUMPTION | AB7: /TON PM. | AD7: /TON FG. | AF7: CONSUMPTION | AH7: /TON PM | AJ7: /TON FG | AL7: Gas based on report DCS | AO7: total | AP7: Flowmeter | AQ7: Selisih | AR7: % pengali | AU7: Adjust | AX7: PEMAKAIAN GAS
J8: TODAY | K8: TODATE | L8: TODAY | M8: TODATE | N8: TODAY | O8: TODATE | P8: TODAY | Q8: TODATE | R8: TODAY | S8: TODATE | T8: TODAY | U8: TODATE | V8: TODAY | W8: TODATE | X8: TODAY | Y8: TODATE | Z8: TODAY | AA8: TODATE | AB8: TODAY | AC8: TODATE | AD8: TODAY | AE8: TODATE | AF8: TODAY | AG8: TODATE | AH8: TODAY | AI8: TODATE | AJ8: TODAY | AK8: TODATE | AL8: 14 | AM8: 15 | AN8: 17 | AP8: PGN | AU8: 14 | AV8: 15 | AW8: 17 | AX8: 14 | AY8: 15 | AZ8: 17 | BA8: TODAY | BB8: TODATE | BC8: TODAY | BD8: TODATE
A9: 46082 | B9: Facial | C9: 12 | D9: =+'1'!F42 -> 1174.6806 | E9: =+'1'!G42 -> 873.01042 | F9: =1-(E9/D9) -> 0.25681036 | G9: =+P9/N9 -> 0.89828661 | H9: =+P9/L9 -> 0.83891053 | I9: =+R9/P9 -> 1.0143191 | J9: =+R9/L9 -> 0.85092297 | K9: =+S9/M9 -> 0.85092297 | L9: =+Efficiency1!K6 -> 43.371729 | M9: =L9 -> 43.371729 | N9: =+Efficiency1!C6 -> 40.50489 | O9: =N9 -> 40.50489 | P9: ='1'!I38 -> 36.385 | Q9: =P9 -> 36.385 | R9: ='1'!I40 -> 36.906 | S9: =R9 -> 36.906 | T9: =+AX9 -> 4546.1087 | U9: =T9 -> 4546.1087 | V9: =T9/P9 -> 124.94458 | W9: =U9/Q9 -> 124.94458 | X9: =IF(AND(R9>0,T9>0),(T9/(R9*1000))*1000,0) -> 123.18075 | Y9: =IF(AND(S9>0,U9>0),U9/S9,0) -> 123.18075 | Z9: 47.2 | AA9: =Z9 -> 47.2 | AB9: =Z9/(P9) -> 1.2972379 | AC9: =AA9/(Q9) -> 1.2972379 | AD9: =IF(AND(R9>0,Z9>0),Z9/(R9),0) -> 1.2789248 | AE9: =IF(AND(S9>0,AA9>0),AA9/(S9),0) -> 1.2789248 | AF9: ='1'!I46 -> 36530.9 | AG9: =AF9 -> 36530.9 | AH9: =IF(AND(L9>0,AF9>0),(AF9/(P9*1000)*1000),0) -> 1004.0099 | AI9: =IF(AND(M9>0,AG9>0),(AG9/(Q9*1000)*1000),0) -> 1004.0099 | AJ9: =IF(AND(R9>0,AF9>0),(AF9/(R9*1000)*1000),0) -> 989.83634 | AK9: =IF(AND(S9>0,AG9>0),(AG9/(S9*1000)*1000),0) -> 989.83634 | AL9: 4876.5 | AM9: 4523.3 | AN9: 4006.5 | AO9: =SUM(AL9:AN9) -> 13406.3 | AP9: =+[1]Mar!N4 -> 12498 | AQ9: =+AP9-AO9 -> -908.3 | AR9: =+AL9/AO9 -> 0.3637469 | AS9: =+AM9/AO9 -> 0.33740107 | AT9: =1-AR9-AS9 -> 0.29885203 | AU9: =+AR9*AQ9 -> -330.3913 | AV9: =+AS9*AQ9 -> -306.46139 | AW9: =+AT9*AQ9 -> -271.4473 | AX9: =+AL9+AU9 -> 4546.1087 | AY9: =+AM9+AV9 -> 4216.8386 | AZ9: =+AN9+AW9 -> 3735.0527 | BA9: =+Efficiency2!K6 -> 43.371729 | BB9: =BA9 -> 43.371729 | BC9: =+R9/BA9 -> 0.85092297 | BD9: =+S9/BB9 -> 0.85092297
A10: =A9+1 -> 46083 | B10: Facial | C10: 12/14/16 | D10: =+'2'!F42 -> 1189.0069 | E10: =+'2'!G42 -> 891.41181 | F10: =1-(E10/D10) -> 0.25028881 | G10: =+P10/N10 -> 0.86019756 | H10: =+P10/L10 -> 0.85654391 | I10: =+R10/P10 -> 1.0459028 | J10: =+R10/L10 -> 0.89586171 | K10: =+S10/M10 -> 0.87586495 | L10: =+SUM(Efficiency1!K11:K13) -> 54.097635 | M10: =M9+L10 -> 97.469364 | N10: =+SUM(Efficiency1!C11:C13) -> 53.867858 | O10: =O9+N10 -> 94.372748 | P10: ='2'!I38 -> 46.337 | Q10: =Q9+P10 -> 82.722 | R10: ='2'!I40 -> 48.464 | S10: =S9+R10 -> 85.37 | T10: =+AX10 -> 4967.2758 | U10: =T10+U9 -> 9513.3844 | V10: =T10/P10 -> 107.19891 | W10: =U10/Q10 -> 115.00428 | X10: =IF(AND(R10>0,T10>0),(T10/(R10*1000))*1000,0) -> 102.49413 | Y10: =IF(AND(S10>0,U10>0),U10/S10,0) -> 111.43709 | Z10: 54.3 | AA10: =Z10+AA9 -> 101.5 | AB10: =Z10/(P10) -> 1.1718497 | AC10: =AA10/(Q10) -> 1.2270013 | AD10: =IF(AND(R10>0,Z10>0),Z10/(R10),0) -> 1.1204193 | AE10: =IF(AND(S10>0,AA10>0),AA10/(S10),0) -> 1.1889423 | AF10: ='2'!I46 -> 34471.7 | AG10: =AF10+AG9 -> 71002.6 | AH10: =IF(AND(L10>0,AF10>0),(AF10/(P10*1000)*1000),0) -> 743.93465 | AI10: =IF(AND(M10>0,AG10>0),(AG10/(Q10*1000)*1000),0) -> 858.32789 | AJ10: =IF(AND(R10>0,AF10>0),(AF10/(R10*1000)*1000),0) -> 711.28466 | AK10: =IF(AND(S10>0,AG10>0),(AG10/(S10*1000)*1000),0) -> 831.70435 | AL10: 5034.4 | AM10: 3355.8 | AN10: 4000 | AO10: =SUM(AL10:AN10) -> 12390.2 | AP10: =+[1]Mar!N5 -> 12225 | AQ10: =+AP10-AO10 -> -165.2 | AR10: =+AL10/AO10 -> 0.40632112 | AS10: =+AM10/AO10 -> 0.27084309 | AT10: =1-AR10-AS10 -> 0.32283579 | AU10: =+AR10*AQ10 -> -67.12425 | AV10: =+AS10*AQ10 -> -44.743278 | AW10: =+AT10*AQ10 -> -53.332472 | AX10: =+AL10+AU10 -> 4967.2758 | AY10: =+AM10+AV10 -> 3311.0567 | AZ10: =+AN10+AW10 -> 3946.6675 | BA10: =+SUM(Efficiency2!K11:K13) -> 54.097635 | BB10: =BB9+BA10 -> 97.469364 | BC10: =+R10/BA10 -> 0.89586171 | BD10: =+S10/BB10 -> 0.87586495
A11: =A10+1 -> 46084 | B11: Facial | C11: 16/14 | D11: =+'3'!F42 -> 1105.5694 | E11: =+'3'!G42 -> 829.17708 | F11: =1-(E11/D11) -> 0.25 | G11: =+P11/N11 -> 0.8857369 | H11: =+P11/L11 -> 0.8857369 | I11: =+R11/P11 -> 0.88079513 | J11: =+R11/L11 -> 0.78015275 | K11: =+S11/M11 -> 0.84258028 | L11: =+SUM(Efficiency1!K16:K17) -> 51.968028 | M11: =M10+L11 -> 149.43739 | N11: =+SUM(Efficiency1!C16:C17) -> 51.968028 | O11: =O10+N11 -> 146.34078 | P11: ='3'!I38 -> 46.03 | Q11: =Q10+P11 -> 128.752 | R11: ='3'!I40 -> 40.543 | S11: =S10+R11 -> 125.913 | T11: =+AX11 -> 4610.1847 | U11: =T11+U10 -> 14123.569 | V11: =T11/P11 -> 100.15609 | W11: =U11/Q11 -> 109.69592 | X11: =IF(AND(R11>0,T11>0),(T11/(R11*1000))*1000,0) -> 113.71099 | Y11: =IF(AND(S11>0,U11>0),U11/S11,0) -> 112.16927 | Z11: 51.2 | AA11: =Z11+AA10 -> 152.7 | AB11: =Z11/(P11) -> 1.1123181 | AC11: =AA11/(Q11) -> 1.186001 | AD11: =IF(AND(R11>0,Z11>0),Z11/(R11),0) -> 1.2628567 | AE11: =IF(AND(S11>0,AA11>0),AA11/(S11),0) -> 1.2127421 | AF11: ='3'!I46 -> 33956.98 | AG11: =AF11+AG10 -> 104959.58 | AH11: =IF(AND(L11>0,AF11>0),(AF11/(P11*1000)*1000),0) -> 737.7141 | AI11: =IF(AND(M11>0,AG11>0),(AG11/(Q11*1000)*1000),0) -> 815.20738 | AJ11: =IF(AND(R11>0,AF11>0),(AF11/(R11*1000)*1000),0) -> 837.5547 | AK11: =IF(AND(S11>0,AG11>0),(AG11/(S11*1000)*1000),0) -> 833.58811 | AL11: 4915.9 | AM11: 4575.3 | AN11: 3876.1 | AO11: =SUM(AL11:AN11) -> 13367.3 | AP11: =+[1]Mar!N6 -> 12536 | AQ11: =+AP11-AO11 -> -831.3 | AR11: =+AL11/AO11 -> 0.36775564 | AS11: =+AM11/AO11 -> 0.34227555 | AT11: =1-AR11-AS11 -> 0.2899688 | AU11: =+AR11*AQ11 -> -305.71527 | AV11: =+AS11*AQ11 -> -284.53367 | AW11: =+AT11*AQ11 -> -241.05107 | AX11: =+AL11+AU11 -> 4610.1847 | AY11: =+AM11+AV11 -> 4290.7663 | AZ11: =+AN11+AW11 -> 3635.0489 | BA11: =+SUM(Efficiency2!K16:K17) -> 51.968028 | BB11: =BB10+BA11 -> 149.43739 | BC11: =+R11/BA11 -> 0.78015275 | BD11: =+S11/BB11 -> 0.84258028
A12: =A11+1 -> 46085 | B12: Facial | C12: 14 | D12: =+'4'!F42 -> 1196.7778 | E12: =+'4'!G42 -> 897.58333 | F12: =1-(E12/D12) -> 0.25 | G12: =+P12/N12 -> 0.90212645 | H12: =+P12/L12 -> 0.90212645 | I12: =+R12/P12 -> 0.936668 | J12: =+R12/L12 -> 0.84499298 | K12: =+S12/M12 -> 0.843158 | L12: =+Efficiency1!K21 -> 47.047728 | M12: =M11+L12 -> 196.48512 | N12: =+Efficiency1!C21 -> 47.047728 | O12: =O11+N12 -> 193.3885 | P12: ='4'!I38 -> 42.443 | Q12: =Q11+P12 -> 171.195 | R12: ='4'!I40 -> 39.755 | S12: =S11+R12 -> 165.668 | T12: =+AX12 -> 5068.7437 | U12: =T12+U11 -> 19192.313 | V12: =T12/P12 -> 119.42473 | W12: =U12/Q12 -> 112.10791 | X12: =IF(AND(R12>0,T12>0),(T12/(R12*1000))*1000,0) -> 127.49953 | Y12: =IF(AND(S12>0,U12>0),U12/S12,0) -> 115.84804 | Z12: 52 | AA12: =Z12+AA11 -> 204.7 | AB12: =Z12/(P12) -> 1.2251726 | AC12: =AA12/(Q12) -> 1.1957125 | AD12: =IF(AND(R12>0,Z12>0),Z12/(R12),0) -> 1.3080116 | AE12: =IF(AND(S12>0,AA12>0),AA12/(S12),0) -> 1.2356037 | AF12: ='4'!I46 -> 36603.36 | AG12: =AF12+AG11 -> 141562.94 | AH12: =IF(AND(L12>0,AF12>0),(AF12/(P12*1000)*1000),0) -> 862.41218 | AI12: =IF(AND(M12>0,AG12>0),(AG12/(Q12*1000)*1000),0) -> 826.91048 | AJ12: =IF(AND(R12>0,AF12>0),(AF12/(R12*1000)*1000),0) -> 920.72343 | AK12: =IF(AND(S12>0,AG12>0),(AG12/(S12*1000)*1000),0) -> 854.49779 | AL12: 5260.4 | AM12: 3916.8 | AN12: 3237.1 | AO12: =SUM(AL12:AN12) -> 12414.3 | AP12: =+[1]Mar!N7 -> 11962 | AQ12: =+AP12-AO12 -> -452.3 | AR12: =+AL12/AO12 -> 0.42373714 | AS12: =+AM12/AO12 -> 0.31550712 | AT12: =1-AR12-AS12 -> 0.26075574 | AU12: =+AR12*AQ12 -> -191.65631 | AV12: =+AS12*AQ12 -> -142.70387 | AW12: =+AT12*AQ12 -> -117.93982 | AX12: =+AL12+AU12 -> 5068.7437 | AY12: =+AM12+AV12 -> 3774.0961 | AZ12: =+AN12+AW12 -> 3119.1602 | BA12: =+SUM(Efficiency2!K21) -> 47.047728 | BB12: =BB11+BA12 -> 196.48512 | BC12: =+R12/BA12 -> 0.84499298 | BD12: =+S12/BB12 -> 0.843158
A13: =A12+1 -> 46086 | B13: Facial | C13: 14/13,5/16 | D13: =+'5'!F42 -> 1159.3943 | E13: =+'5'!G42 -> 877.79401 | F13: =1-(E13/D13) -> 0.24288571 | G13: =+P13/N13 -> 0.92203133 | H13: =+P13/L13 -> 0.90832138 | I13: =+R13/P13 -> 0.90526732 | J13: =+R13/L13 -> 0.82227366 | K13: =+S13/M13 -> 0.83910599 | L13: =+SUM(Efficiency1!K26:K28) -> 47.299338 | M13: =M12+L13 -> 243.78446 | N13: =+SUM(Efficiency1!C26:C28) -> 46.59603 | O13: =O12+N13 -> 239.98453 | P13: ='5'!I38 -> 42.963 | Q13: =Q12+P13 -> 214.158 | R13: ='5'!I40 -> 38.893 | S13: =S12+R13 -> 204.561 | T13: =+AX13 -> 4994.4936 | U13: =T13+U12 -> 24186.806 | V13: =T13/P13 -> 116.25104 | W13: =U13/Q13 -> 112.93908 | X13: =IF(AND(R13>0,T13>0),(T13/(R13*1000))*1000,0) -> 128.41626 | Y13: =IF(AND(S13>0,U13>0),U13/S13,0) -> 118.23762 | Z13: 50.5 | AA13: =Z13+AA12 -> 255.2 | AB13: =Z13/(P13) -> 1.17543 | AC13: =AA13/(Q13) -> 1.1916436 | AD13: =IF(AND(R13>0,Z13>0),Z13/(R13),0) -> 1.2984342 | AE13: =IF(AND(S13>0,AA13>0),AA13/(S13),0) -> 1.2475496 | AF13: ='5'!I46 -> 34597.42 | AG13: =AF13+AG12 -> 176160.36 | AH13: =IF(AND(L13>0,AF13>0),(AF13/(P13*1000)*1000),0) -> 805.28408 | AI13: =IF(AND(M13>0,AG13>0),(AG13/(Q13*1000)*1000),0) -> 822.57193 | AJ13: =IF(AND(R13>0,AF13>0),(AF13/(R13*1000)*1000),0) -> 889.5539 | AK13: =IF(AND(S13>0,AG13>0),(AG13/(S13*1000)*1000),0) -> 861.16298 | AL13: 5308.4 | AM13: 4348.6 | AN13: 4064.4 | AO13: =SUM(AL13:AN13) -> 13721.4 | AP13: =+[1]Mar!N8 -> 12910 | AQ13: =+AP13-AO13 -> -811.4 | AR13: =+AL13/AO13 -> 0.38687014 | AS13: =+AM13/AO13 -> 0.31692101 | AT13: =1-AR13-AS13 -> 0.29620884 | AU13: =+AR13*AQ13 -> -313.90644 | AV13: =+AS13*AQ13 -> -257.14971 | AW13: =+AT13*AQ13 -> -240.34385 | AX13: =IFERROR(+AL13+AU13,"-") -> 4994.4936 | AY13: =IFERROR(+AM13+AV13,"-") -> 4091.4503 | AZ13: =IFERROR(+AN13+AW13,"-") -> 3824.0561 | BA13: =+SUM(Efficiency2!K26:K28) -> 47.299338 | BB13: =BB12+BA13 -> 243.78446 | BC13: =+R13/BA13 -> 0.82227366 | BD13: =+S13/BB13 -> 0.83910599
A14: =A13+1 -> 46087 | B14: Facial | C14: 16/13 | D14: =+'6'!F42 -> 1121.1111 | E14: =+'6'!G42 -> 860.72222 | F14: =1-(E14/D14) -> 0.23225966 | G14: =+P14/N14 -> 0.60752378 | H14: =+P14/L14 -> 0.59063966 | I14: =+R14/P14 -> 0.98923072 | J14: =+R14/L14 -> 0.58427889 | K14: =+S14/M14 -> 0.79699275 | L14: =+SUM(Efficiency1!K31:K32) -> 48.264622 | M14: =M13+L14 -> 292.04908 | N14: =+SUM(Efficiency1!C31:C32) -> 46.923266 | O14: =O13+N14 -> 286.9078 | P14: ='6'!I38 -> 28.507 | Q14: =Q13+P14 -> 242.665 | R14: ='6'!I40 -> 28.2 | S14: =S13+R14 -> 232.761 | T14: =+AX14 -> 3033.4509 | U14: =T14+U13 -> 27220.257 | V14: =T14/P14 -> 106.41074 | W14: =U14/Q14 -> 112.17216 | X14: =IF(AND(R14>0,T14>0),(T14/(R14*1000))*1000,0) -> 107.56918 | Y14: =IF(AND(S14>0,U14>0),U14/S14,0) -> 116.9451 | Z14: 38.5 | AA14: =Z14+AA13 -> 293.7 | AB14: =Z14/(P14) -> 1.3505455 | AC14: =AA14/(Q14) -> 1.2103105 | AD14: =IF(AND(R14>0,Z14>0),Z14/(R14),0) -> 1.3652482 | AE14: =IF(AND(S14>0,AA14>0),AA14/(S14),0) -> 1.2618093 | AF14: ='6'!I46 -> 24649.02 | AG14: =AF14+AG13 -> 200809.38 | AH14: =IF(AND(L14>0,AF14>0),(AF14/(P14*1000)*1000),0) -> 864.66552 | AI14: =IF(AND(M14>0,AG14>0),(AG14/(Q14*1000)*1000),0) -> 827.51686 | AJ14: =IF(AND(R14>0,AF14>0),(AF14/(R14*1000)*1000),0) -> 874.07872 | AK14: =IF(AND(S14>0,AG14>0),(AG14/(S14*1000)*1000),0) -> 862.72778 | AL14: 3354.5 | AM14: 2543.3 | AN14: 2287.6 | AO14: =SUM(AL14:AN14) -> 8185.4 | AP14: =+[1]Mar!N9 -> 7402 | AQ14: =+AP14-AO14 -> -783.4 | AR14: =+AL14/AO14 -> 0.40981504 | AS14: =+AM14/AO14 -> 0.31071176 | AT14: =1-AR14-AS14 -> 0.27947321 | AU14: =+AR14*AQ14 -> -321.0491 | AV14: =+AS14*AQ14 -> -243.41159 | AW14: =+AT14*AQ14 -> -218.93931 | AX14: =IFERROR(+AL14+AU14,"-") -> 3033.4509 | AY14: =IFERROR(+AM14+AV14,"-") -> 2299.8884 | AZ14: =IFERROR(+AN14+AW14,"-") -> 2068.6607 | BA14: =+SUM(Efficiency2!K31:K32) -> 38.364184 | BB14: =BB13+BA14 -> 282.14864 | BC14: =+R14/BA14 -> 0.73506061 | BD14: =+S14/BB14 -> 0.82495878
A15: =A14+1 -> 46088 | B15: Toilet/Facial | C15: 14/13 | D15: =+'7'!F42 -> 1150.8477 | E15: =+'7'!G42 -> 870.86843 | F15: =1-(E15/D15) -> 0.24328088 | G15: =+P15/N15 -> 0.49277197 | H15: =+P15/L15 -> 0.47939984 | I15: =+R15/P15 -> 0.79000364 | J15: =+R15/L15 -> 0.37872762 | K15: =+S15/M15 -> 0.74031027 | L15: =+SUM(Efficiency1!K37:K38) -> 45.782243 | M15: =M14+L15 -> 337.83132 | N15: =+SUM(Efficiency1!C37:C38) -> 44.539871 | O15: =O14+N15 -> 331.44767 | P15: ='7'!I38 -> 21.948 | Q15: =Q14+P15 -> 264.613 | R15: ='7'!I40 -> 17.339 | S15: =S14+R15 -> 250.1 | T15: =+AX15 -> 3661.664 | U15: =T15+U14 -> 30881.921 | V15: =T15/P15 -> 166.83361 | W15: =U15/Q15 -> 116.70599 | X15: =IF(AND(R15>0,T15>0),(T15/(R15*1000))*1000,0) -> 211.18081 | Y15: =IF(AND(S15>0,U15>0),U15/S15,0) -> 123.47829 | Z15: 44.3 | AA15: =Z15+AA14 -> 338 | AB15: =Z15/(P15) -> 2.0184071 | AC15: =AA15/(Q15) -> 1.2773371 | AD15: =IF(AND(R15>0,Z15>0),Z15/(R15),0) -> 2.554934 | AE15: =IF(AND(S15>0,AA15>0),AA15/(S15),0) -> 1.3514594 | AF15: ='7'!I46 -> 24519.02 | AG15: =AF15+AG14 -> 225328.4 | AH15: =IF(AND(L15>0,AF15>0),(AF15/(P15*1000)*1000),0) -> 1117.1414 | AI15: =IF(AND(M15>0,AG15>0),(AG15/(Q15*1000)*1000),0) -> 851.53942 | AJ15: =IF(AND(R15>0,AF15>0),(AF15/(R15*1000)*1000),0) -> 1414.0965 | AK15: =IF(AND(S15>0,AG15>0),(AG15/(S15*1000)*1000),0) -> 900.95322 | AL15: 3462.3 | AM15: 4113.6 | AN15: 3780.2 | AO15: =SUM(AL15:AN15) -> 11356.1 | AP15: =+[1]Mar!N10 -> 12010 | AQ15: =+AP15-AO15 -> 653.9 | AR15: =+AL15/AO15 -> 0.3048846 | AS15: =+AM15/AO15 -> 0.36223704 | AT15: =1-AR15-AS15 -> 0.33287836 | AU15: =+AR15*AQ15 -> 199.36404 | AV15: =+AS15*AQ15 -> 236.8668 | AW15: =+AT15*AQ15 -> 217.66916 | AX15: =IFERROR(+AL15+AU15,"-") -> 3661.664 | AY15: =IFERROR(+AM15+AV15,"-") -> 4350.4668 | AZ15: =IFERROR(+AN15+AW15,"-") -> 3997.8692 | BA15: =+SUM(Efficiency2!K37:K38) -> 32.675968 | BB15: =BB14+BA15 -> 314.82461 | BC15: =+R15/BA15 -> 0.53063463 | BD15: =+S15/BB15 -> 0.79441058
A16: =A15+1 -> 46089 | B16: Facial | C16: 13/11,5 | D16: =+'8'!F42 -> 1197.4361 | E16: =+'8'!G42 -> 908.30426 | F16: =1-(E16/D16) -> 0.24145908 | G16: =+P16/N16 -> 0.91459257 | H16: =+P16/L16 -> 0.88879472 | I16: =+R16/P16 -> 0.96398414 | J16: =+R16/L16 -> 0.85678401 | K16: =+S16/M16 -> 0.75310883 | L16: =+SUM(Efficiency1!K45:K46) -> 41.704793 | M16: =M15+L16 -> 379.53612 | N16: =+SUM(Efficiency1!C45:C46) -> 40.528429 | O16: =O15+N16 -> 371.9761 | P16: ='8'!I38 -> 37.067 | Q16: =Q15+P16 -> 301.68 | R16: ='8'!I40 -> 35.732 | S16: =S15+R16 -> 285.832 | T16: =+AX16 -> 4586.0856 | U16: =T16+U15 -> 35468.007 | V16: =T16/P16 -> 123.72422 | W16: =U16/Q16 -> 117.56831 | X16: =IF(AND(R16>0,T16>0),(T16/(R16*1000))*1000,0) -> 128.34674 | Y16: =IF(AND(S16>0,U16>0),U16/S16,0) -> 124.0869 | Z16: 53.3 | AA16: =Z16+AA15 -> 391.3 | AB16: =Z16/(P16) -> 1.4379367 | AC16: =AA16/(Q16) -> 1.2970697 | AD16: =IF(AND(R16>0,Z16>0),Z16/(R16),0) -> 1.4916601 | AE16: =IF(AND(S16>0,AA16>0),AA16/(S16),0) -> 1.368986 | AF16: ='8'!I46 -> 36406.46 | AG16: =AF16+AG15 -> 261734.86 | AH16: =IF(AND(L16>0,AF16>0),(AF16/(P16*1000)*1000),0) -> 982.17984 | AI16: =IF(AND(M16>0,AG16>0),(AG16/(Q16*1000)*1000),0) -> 867.59102 | AJ16: =IF(AND(R16>0,AF16>0),(AF16/(R16*1000)*1000),0) -> 1018.8755 | AK16: =IF(AND(S16>0,AG16>0),(AG16/(S16*1000)*1000),0) -> 915.69474 | AL16: 5112.9 | AM16: 4411.6 | AN16: 3968.8 | AO16: =SUM(AL16:AN16) -> 13493.3 | AP16: =+[1]Mar!N11 -> 12103 | AQ16: =+AP16-AO16 -> -1390.3 | AR16: =+AL16/AO16 -> 0.37892139 | AS16: =+AM16/AO16 -> 0.32694745 | AT16: =1-AR16-AS16 -> 0.29413116 | AU16: =+AR16*AQ16 -> -526.81441 | AV16: =+AS16*AQ16 -> -454.55504 | AW16: =+AT16*AQ16 -> -408.93055 | AX16: =IFERROR(+AL16+AU16,"-") -> 4586.0856 | AY16: =IFERROR(+AM16+AV16,"-") -> 3957.045 | AZ16: =IFERROR(+AN16+AW16,"-") -> 3559.8694 | BA16: =+SUM(Efficiency2!K45:K46) -> 41.704793 | BB16: =BB15+BA16 -> 356.5294 | BC16: =+R16/BA16 -> 0.85678401 | BD16: =+S16/BB16 -> 0.80170667
A17: =A16+1 -> 46090 | B17: Facial | C17: 11,5/12 | D17: =+'9'!F42 -> 1230 | E17: =+'9'!G42 -> 934.8 | F17: =1-(E17/D17) -> 0.24 | G17: =+P17/N17 -> 0.881744 | H17: =+P17/L17 -> 0.881744 | I17: =+R17/P17 -> 1.1156246 | J17: =+R17/L17 -> 0.98369528 | K17: =+S17/M17 -> 0.77625743 | L17: =+SUM(Efficiency1!K52:K53) -> 42.353563 | M17: =M16+L17 -> 421.88968 | N17: =+SUM(Efficiency1!C52:C53) -> 42.353563 | O17: =O16+N17 -> 414.32966 | P17: ='9'!I38 -> 37.345 | Q17: =Q16+P17 -> 339.025 | R17: ='9'!I40 -> 41.663 | S17: =S16+R17 -> 327.495 | T17: =+AX17 -> 4861.1351 | U17: =T17+U16 -> 40329.142 | V17: =T17/P17 -> 130.1683 | W17: =U17/Q17 -> 118.95625 | X17: =IF(AND(R17>0,T17>0),(T17/(R17*1000))*1000,0) -> 116.67751 | Y17: =IF(AND(S17>0,U17>0),U17/S17,0) -> 123.1443 | Z17: 55.8 | AA17: =Z17+AA16 -> 447.1 | AB17: =Z17/(P17) -> 1.4941759 | AC17: =AA17/(Q17) -> 1.3187818 | AD17: =IF(AND(R17>0,Z17>0),Z17/(R17),0) -> 1.3393179 | AE17: =IF(AND(S17>0,AA17>0),AA17/(S17),0) -> 1.3652117 | AF17: ='9'!I46 -> 38745.1 | AG17: =AF17+AG16 -> 300479.96 | AH17: =IF(AND(L17>0,AF17>0),(AF17/(P17*1000)*1000),0) -> 1037.491 | AI17: =IF(AND(M17>0,AG17>0),(AG17/(Q17*1000)*1000),0) -> 886.3062 | AJ17: =IF(AND(R17>0,AF17>0),(AF17/(R17*1000)*1000),0) -> 929.96424 | AK17: =IF(AND(S17>0,AG17>0),(AG17/(S17*1000)*1000),0) -> 917.51007 | AL17: 5073.6 | AM17: 4663.6 | AN17: 4019.9 | AO17: =SUM(AL17:AN17) -> 13757.1 | AP17: =+[1]Mar!N12 -> 13181 | AQ17: =+AP17-AO17 -> -576.1 | AR17: =+AL17/AO17 -> 0.36879866 | AS17: =+AM17/AO17 -> 0.33899586 | AT17: =1-AR17-AS17 -> 0.29220548 | AU17: =+AR17*AQ17 -> -212.46491 | AV17: =+AS17*AQ17 -> -195.29552 | AW17: =+AT17*AQ17 -> -168.33958 | AX17: =IFERROR(+AL17+AU17,"-") -> 4861.1351 | AY17: =IFERROR(+AM17+AV17,"-") -> 4468.3045 | AZ17: =IFERROR(+AN17+AW17,"-") -> 3851.5604 | BA17: =+SUM(Efficiency2!K52:K53) -> 42.353563 | BB17: =BB16+BA17 -> 398.88297 | BC17: =+R17/BA17 -> 0.98369528 | BD17: =+S17/BB17 -> 0.8210303
A18: =A17+1 -> 46091 | B18: Facial | C18: 12 | D18: =+'10'!F42 -> 1230 | E18: =+'10'!G42 -> 934.8 | F18: =1-(E18/D18) -> 0.24 | G18: =+P18/N18 -> 0.89690407 | H18: =+P18/L18 -> 0.89690407 | I18: =+R18/P18 -> 1.0295668 | J18: =+R18/L18 -> 0.92342264 | K18: =+S18/M18 -> 0.79027667 | L18: =+Efficiency1!K56 -> 44.421696 | M18: =M17+L18 -> 466.31138 | N18: =+Efficiency1!C56 -> 44.421696 | O18: =O17+N18 -> 458.75136 | P18: ='10'!I38 -> 39.842 | Q18: =Q17+P18 -> 378.867 | R18: ='10'!I40 -> 41.02 | S18: =S17+R18 -> 368.515 | T18: =+AX18 -> 4821.6019 | U18: =T18+U17 -> 45150.744 | V18: =T18/P18 -> 121.01807 | W18: =U18/Q18 -> 119.17307 | X18: =IF(AND(R18>0,T18>0),(T18/(R18*1000))*1000,0) -> 117.54271 | Y18: =IF(AND(S18>0,U18>0),U18/S18,0) -> 122.52078 | Z18: 55.8 | AA18: =Z18+AA17 -> 502.9 | AB18: =Z18/(P18) -> 1.4005321 | AC18: =AA18/(Q18) -> 1.3273787 | AD18: =IF(AND(R18>0,Z18>0),Z18/(R18),0) -> 1.360312 | AE18: =IF(AND(S18>0,AA18>0),AA18/(S18),0) -> 1.3646663 | AF18: ='10'!I46 -> 37094.32 | AG18: =AF18+AG17 -> 337574.28 | AH18: =IF(AND(L18>0,AF18>0),(AF18/(P18*1000)*1000),0) -> 931.03559 | AI18: =IF(AND(M18>0,AG18>0),(AG18/(Q18*1000)*1000),0) -> 891.00999 | AJ18: =IF(AND(R18>0,AF18>0),(AF18/(R18*1000)*1000),0) -> 904.29839 | AK18: =IF(AND(S18>0,AG18>0),(AG18/(S18*1000)*1000),0) -> 916.03946 | AL18: 5083.4 | AM18: 4677 | AN18: 3967.6 | AO18: =SUM(AL18:AN18) -> 13728 | AP18: =+[1]Mar!N13 -> 13021 | AQ18: =+AP18-AO18 -> -707 | AR18: =+AL18/AO18 -> 0.37029429 | AS18: =+AM18/AO18 -> 0.34069056 | AT18: =1-AR18-AS18 -> 0.28901515 | AU18: =+AR18*AQ18 -> -261.79806 | AV18: =+AS18*AQ18 -> -240.86823 | AW18: =+AT18*AQ18 -> -204.33371 | AX18: =IFERROR(+AL18+AU18,"-") -> 4821.6019 | AY18: =IFERROR(+AM18+AV18,"-") -> 4436.1318 | AZ18: =IFERROR(+AN18+AW18,"-") -> 3763.2663 | BA18: =+Efficiency2!K56 -> 44.421696 | BB18: =BB17+BA18 -> 443.30466 | BC18: =+R18/BA18 -> 0.92342264 | BD18: =+S18/BB18 -> 0.8312906
A19: =A18+1 -> 46092 | B19: Facial | C19: 12/12,5 | D19: =+'11'!F42 -> 1228.0486 | E19: =+'11'!G42 -> 933.31694 | F19: =1-(E19/D19) -> 0.24 | G19: =+P19/N19 -> 0.91371891 | H19: =+P19/L19 -> 0.91229882 | I19: =+R19/P19 -> 0.95861779 | J19: =+R19/L19 -> 0.87454588 | K19: =+S19/M19 -> 0.79758993 | L19: =+SUM(Efficiency1!K60:K61) -> 44.314428 | M19: =M18+L19 -> 510.6258 | N19: =+SUM(Efficiency1!C60:C61) -> 44.245555 | O19: =O18+N19 -> 502.99691 | P19: ='11'!I38 -> 40.428 | Q19: =Q18+P19 -> 419.295 | R19: ='11'!I40 -> 38.755 | S19: =S18+R19 -> 407.27 | T19: =+AX19 -> 4807.0687 | U19: =T19+U18 -> 49957.813 | V19: =T19/P19 -> 118.90444 | W19: =U19/Q19 -> 119.14717 | X19: =IF(AND(R19>0,T19>0),(T19/(R19*1000))*1000,0) -> 124.03738 | Y19: =IF(AND(S19>0,U19>0),U19/S19,0) -> 122.66509 | Z19: 56.5 | AA19: =Z19+AA18 -> 559.4 | AB19: =Z19/(P19) -> 1.3975463 | AC19: =AA19/(Q19) -> 1.3341442 | AD19: =IF(AND(R19>0,Z19>0),Z19/(R19),0) -> 1.4578764 | AE19: =IF(AND(S19>0,AA19>0),AA19/(S19),0) -> 1.373536 | AF19: ='11'!I46 -> 37873.74 | AG19: =AF19+AG18 -> 375448.02 | AH19: =IF(AND(L19>0,AF19>0),(AF19/(P19*1000)*1000),0) -> 936.81953 | AI19: =IF(AND(M19>0,AG19>0),(AG19/(Q19*1000)*1000),0) -> 895.4269 | AJ19: =IF(AND(R19>0,AF19>0),(AF19/(R19*1000)*1000),0) -> 977.26074 | AK19: =IF(AND(S19>0,AG19>0),(AG19/(S19*1000)*1000),0) -> 921.86515 | AL19: 5041.2 | AM19: 4638.3 | AN19: 3850.9 | AO19: =SUM(AL19:AN19) -> 13530.4 | AP19: =+[1]Mar!N14 -> 12902 | AQ19: =+AP19-AO19 -> -628.4 | AR19: =+AL19/AO19 -> 0.37258322 | AS19: =+AM19/AO19 -> 0.34280583 | AT19: =1-AR19-AS19 -> 0.28461095 | AU19: =+AR19*AQ19 -> -234.1313 | AV19: =+AS19*AQ19 -> -215.41918 | AW19: =+AT19*AQ19 -> -178.84952 | AX19: =IFERROR(+AL19+AU19,"-") -> 4807.0687 | AY19: =IFERROR(+AM19+AV19,"-") -> 4422.8808 | AZ19: =IFERROR(+AN19+AW19,"-") -> 3672.0505 | BA19: =+SUM(Efficiency2!K60:K61) -> 44.314428 | BB19: =BB18+BA19 -> 487.61909 | BC19: =+R19/BA19 -> 0.87454588 | BD19: =+S19/BB19 -> 0.83522161
A20: =A19+1 -> 46093 | B20: Facial/Toilet | C20: 12,5/14/13 | D20: =+'12'!F42 -> 1187.8542 | E20: =+'12'!G42 -> 882.20007 | F20: =1-(E20/D20) -> 0.25731618 | G20: =+P20/N20 -> 0.9468428 | H20: =+P20/L20 -> 0.93474697 | I20: =+R20/P20 -> 0.93692489 | J20: =+R20/L20 -> 0.8757877 | K20: =+S20/M20 -> 0.80410222 | L20: =+SUM(Efficiency1!K64:K66) -> 46.387955 | M20: =M19+L20 -> 557.01376 | N20: =+SUM(Efficiency1!C64:C66) -> 45.795353 | O20: =O19+N20 -> 548.79227 | P20: ='12'!I38 -> 43.361 | Q20: =Q19+P20 -> 462.656 | R20: ='12'!I40 -> 40.626 | S20: =S19+R20 -> 447.896 | T20: =+AX20 -> 5126.5101 | U20: =T20+U19 -> 55084.323 | V20: =T20/P20 -> 118.22859 | W20: =U20/Q20 -> 119.06108 | X20: =IF(AND(R20>0,T20>0),(T20/(R20*1000))*1000,0) -> 126.18791 | Y20: =IF(AND(S20>0,U20>0),U20/S20,0) -> 122.98463 | Z20: 56.2 | AA20: =Z20+AA19 -> 615.6 | AB20: =Z20/(P20) -> 1.2960956 | AC20: =AA20/(Q20) -> 1.3305782 | AD20: =IF(AND(R20>0,Z20>0),Z20/(R20),0) -> 1.3833506 | AE20: =IF(AND(S20>0,AA20>0),AA20/(S20),0) -> 1.3744262 | AF20: ='12'!I46 -> 34967.78 | AG20: =AF20+AG19 -> 410415.8 | AH20: =IF(AND(L20>0,AF20>0),(AF20/(P20*1000)*1000),0) -> 806.43389 | AI20: =IF(AND(M20>0,AG20>0),(AG20/(Q20*1000)*1000),0) -> 887.0863 | AJ20: =IF(AND(R20>0,AF20>0),(AF20/(R20*1000)*1000),0) -> 860.72417 | AK20: =IF(AND(S20>0,AG20>0),(AG20/(S20*1000)*1000),0) -> 916.31941 | AL20: 5443.7 | AM20: 4611.1 | AN20: =1306.13+1278.79+1333.46 -> 3918.38 | AO20: =SUM(AL20:AN20) -> 13973.18 | AP20: =+[1]Mar!N15 -> 13159 | AQ20: =+AP20-AO20 -> -814.18 | AR20: =+AL20/AO20 -> 0.38958204 | AS20: =+AM20/AO20 -> 0.32999646 | AT20: =1-AR20-AS20 -> 0.28042149 | AU20: =+AR20*AQ20 -> -317.18991 | AV20: =+AS20*AQ20 -> -268.67652 | AW20: =+AT20*AQ20 -> -228.31357 | AX20: =IFERROR(+AL20+AU20,"-") -> 5126.5101 | AY20: =IFERROR(+AM20+AV20,"-") -> 4342.4235 | AZ20: =IFERROR(+AN20+AW20,"-") -> 3690.0664 | BA20: =+SUM(Efficiency2!K64:K66) -> 46.387955 | BB20: =BB19+BA20 -> 534.00704 | BC20: =+R20/BA20 -> 0.8757877 | BD20: =+S20/BB20 -> 0.83874549
A21: =A20+1 -> 46094 | B21: Toilet | C21: 13/12,5 | D21: =+'13'!F42 -> 1193.3333 | E21: =+'13'!G42 -> 918.86667 | F21: =1-(E21/D21) -> 0.23 | G21: =+P21/N21 -> 0.94375772 | H21: =+P21/L21 -> 0.91563283 | I21: =+R21/P21 -> 0.96642042 | J21: =+R21/L21 -> 0.88488626 | K21: =+S21/M21 -> 0.81000485 | L21: =+SUM(Efficiency1!K68:K69) -> 43.907338 | M21: =M20+L21 -> 600.9211 | N21: =+SUM(Efficiency1!C68:C69) -> 42.598857 | O21: =O20+N21 -> 591.39112 | P21: ='13'!I38 -> 40.203 | Q21: =Q20+P21 -> 502.859 | R21: ='13'!I40 -> 38.853 | S21: =S20+R21 -> 486.749 | T21: =+AX21 -> 5376.9995 | U21: =T21+U20 -> 60461.322 | V21: =T21/P21 -> 133.74623 | W21: =U21/Q21 -> 120.23514 | X21: =IF(AND(R21>0,T21>0),(T21/(R21*1000))*1000,0) -> 138.39342 | Y21: =IF(AND(S21>0,U21>0),U21/S21,0) -> 124.21458 | Z21: 57.8 | AA21: =Z21+AA20 -> 673.4 | AB21: =Z21/(P21) -> 1.4377037 | AC21: =AA21/(Q21) -> 1.3391428 | AD21: =IF(AND(R21>0,Z21>0),Z21/(R21),0) -> 1.4876586 | AE21: =IF(AND(S21>0,AA21>0),AA21/(S21),0) -> 1.3834646 | AF21: ='13'!I46 -> 37785.78 | AG21: =AF21+AG20 -> 448201.58 | AH21: =IF(AND(L21>0,AF21>0),(AF21/(P21*1000)*1000),0) -> 939.87464 | AI21: =IF(AND(M21>0,AG21>0),(AG21/(Q21*1000)*1000),0) -> 891.30667 | AJ21: =IF(AND(R21>0,AF21>0),(AF21/(R21*1000)*1000),0) -> 972.53185 | AK21: =IF(AND(S21>0,AG21>0),(AG21/(S21*1000)*1000),0) -> 920.80637 | AL21: 5667 | AM21: 4599.2 | AN21: 3653.1 | AO21: =SUM(AL21:AN21) -> 13919.3 | AP21: =+[1]Mar!N16 -> 13207 | AQ21: =+AP21-AO21 -> -712.3 | AR21: =+AL21/AO21 -> 0.40713254 | AS21: =+AM21/AO21 -> 0.33041891 | AT21: =1-AR21-AS21 -> 0.26244854 | AU21: =+AR21*AQ21 -> -290.00051 | AV21: =+AS21*AQ21 -> -235.35739 | AW21: =+AT21*AQ21 -> -186.9421 | AX21: =IFERROR(+AL21+AU21,"-") -> 5376.9995 | AY21: =IFERROR(+AM21+AV21,"-") -> 4363.8426 | AZ21: =IFERROR(+AN21+AW21,"-") -> 3466.1579 | BA21: =+SUM(Efficiency2!K68:K69) -> 43.907338 | BB21: =BB20+BA21 -> 577.91438 | BC21: =+R21/BA21 -> 0.88488626 | BD21: =+S21/BB21 -> 0.84225106
A22: =A21+1 -> 46095 | B22: Toilet | C22: 12,5/13 | D22: =+'14'!F42 -> 1169.5417 | E22: =+'14'!G42 -> 939.25542 | F22: =1-(E22/D22) -> 0.19690299 | G22: =+P22/N22 -> 0.90737417 | H22: =+P22/L22 -> 0.86272903 | I22: =+R22/P22 -> 0.98559424 | J22: =+R22/L22 -> 0.85030076 | K22: =+S22/M22 -> 0.81294586 | L22: =+SUM(Efficiency1!K72:K73) -> 47.311495 | M22: =M21+L22 -> 648.23259 | N22: =+SUM(Efficiency1!C72:C73) -> 44.983648 | O22: =O21+N22 -> 636.37477 | P22: ='14'!I38 -> 40.817 | Q22: =Q21+P22 -> 543.676 | R22: ='14'!I40 -> 40.229 | S22: =S21+R22 -> 526.978 | T22: =+AX22 -> 5754.6129 | U22: =T22+U21 -> 66215.935 | V22: =T22/P22 -> 140.98569 | W22: =U22/Q22 -> 121.79301 | X22: =IF(AND(R22>0,T22>0),(T22/(R22*1000))*1000,0) -> 143.04638 | Y22: =IF(AND(S22>0,U22>0),U22/S22,0) -> 125.65218 | Z22: 57.5 | AA22: =Z22+AA21 -> 730.9 | AB22: =Z22/(P22) -> 1.4087268 | AC22: =AA22/(Q22) -> 1.3443669 | AD22: =IF(AND(R22>0,Z22>0),Z22/(R22),0) -> 1.4293172 | AE22: =IF(AND(S22>0,AA22>0),AA22/(S22),0) -> 1.3869649 | AF22: ='14'!I46 -> 36824.6 | AG22: =AF22+AG21 -> 485026.18 | AH22: =IF(AND(L22>0,AF22>0),(AF22/(P22*1000)*1000),0) -> 902.18781 | AI22: =IF(AND(M22>0,AG22>0),(AG22/(Q22*1000)*1000),0) -> 892.12358 | AJ22: =IF(AND(R22>0,AF22>0),(AF22/(R22*1000)*1000),0) -> 915.37448 | AK22: =IF(AND(S22>0,AG22>0),(AG22/(S22*1000)*1000),0) -> 920.39171 | AL22: 5973.3 | AM22: 4556.3 | AN22: 3632.9 | AO22: =SUM(AL22:AN22) -> 14162.5 | AP22: =+[1]Mar!N17 -> 13644 | AQ22: =+AP22-AO22 -> -518.5 | AR22: =+AL22/AO22 -> 0.42176876 | AS22: =+AM22/AO22 -> 0.3217158 | AT22: =1-AR22-AS22 -> 0.25651545 | AU22: =+AR22*AQ22 -> -218.6871 | AV22: =+AS22*AQ22 -> -166.80964 | AW22: =+AT22*AQ22 -> -133.00326 | AX22: =IFERROR(+AL22+AU22,"-") -> 5754.6129 | AY22: =IFERROR(+AM22+AV22,"-") -> 4389.4904 | AZ22: =IFERROR(+AN22+AW22,"-") -> 3499.8967 | BA22: =+SUM(Efficiency2!K72:K73) -> 47.311495 | BB22: =BB21+BA22 -> 625.22588 | BC22: =+R22/BA22 -> 0.85030076 | BD22: =+S22/BB22 -> 0.84286019
A23: =A22+1 -> 46096 | B23: Toilet | C23: 13 | D23: =+'15'!F42 -> 1183.3333 | E23: =+'15'!G42 -> 953.93333 | F23: =1-(E23/D23) -> 0.19385915 | G23: =+P23/N23 -> 0.90235033 | H23: =+P23/L23 -> 0.86811482 | I23: =+R23/P23 -> 0.98608826 | J23: =+R23/L23 -> 0.85603783 | K23: =+S23/M23 -> 0.81589431 | L23: =+Efficiency1!K77 -> 47.611214 | M23: =M22+L23 -> 695.8438 | N23: =+Efficiency1!C77 -> 45.804826 | O23: =O22+N23 -> 682.1796 | P23: ='15'!I38 -> 41.332 | Q23: =Q22+P23 -> 585.008 | R23: ='15'!I40 -> 40.757 | S23: =S22+R23 -> 567.735 | T23: =+AX23 -> 5476.8082 | U23: =T23+U22 -> 71692.743 | V23: =T23/P23 -> 132.5077 | W23: =U23/Q23 -> 122.55002 | X23: =IF(AND(R23>0,T23>0),(T23/(R23*1000))*1000,0) -> 134.37712 | Y23: =IF(AND(S23>0,U23>0),U23/S23,0) -> 126.27853 | Z23: 56.8 | AA23: =Z23+AA22 -> 787.7 | AB23: =Z23/(P23) -> 1.3742379 | AC23: =AA23/(Q23) -> 1.3464773 | AD23: =IF(AND(R23>0,Z23>0),Z23/(R23),0) -> 1.3936256 | AE23: =IF(AND(S23>0,AA23>0),AA23/(S23),0) -> 1.3874431 | AF23: ='15'!I46 -> 35543.7 | AG23: =AF23+AG22 -> 520569.88 | AH23: =IF(AND(L23>0,AF23>0),(AF23/(P23*1000)*1000),0) -> 859.95597 | AI23: =IF(AND(M23>0,AG23>0),(AG23/(Q23*1000)*1000),0) -> 889.85087 | AJ23: =IF(AND(R23>0,AF23>0),(AF23/(R23*1000)*1000),0) -> 872.08823 | AK23: =IF(AND(S23>0,AG23>0),(AG23/(S23*1000)*1000),0) -> 916.92406 | AL23: 5920.5 | AM23: 4728.8 | AN23: 3652.5 | AO23: =SUM(AL23:AN23) -> 14301.8 | AP23: =+[1]Mar!N18 -> 13230 | AQ23: =+AP23-AO23 -> -1071.8 | AR23: =+AL23/AO23 -> 0.41396887 | AS23: =+AM23/AO23 -> 0.3306437 | AT23: =1-AR23-AS23 -> 0.25538743 | AU23: =+AR23*AQ23 -> -443.69184 | AV23: =+AS23*AQ23 -> -354.38391 | AW23: =+AT23*AQ23 -> -273.72425 | AX23: =IFERROR(+AL23+AU23,"-") -> 5476.8082 | AY23: =IFERROR(+AM23+AV23,"-") -> 4374.4161 | AZ23: =IFERROR(+AN23+AW23,"-") -> 3378.7757 | BA23: =+Efficiency2!K77 -> 47.611214 | BB23: =BB22+BA23 -> 672.83709 | BC23: =+R23/BA23 -> 0.85603783 | BD23: =+S23/BB23 -> 0.84379266
A24: =A23+1 -> 46097 | B24: Toilet | C24: 13/12,5 | D24: =+'16'!F42 -> 1190 | E24: =+'16'!G42 -> 940.98125 | F24: =1-(E24/D24) -> 0.20925945 | G24: =+P24/N24 -> 0.93293531 | H24: =+P24/L24 -> 0.90210539 | I24: =+R24/P24 -> 0.94511568 | J24: =+R24/L24 -> 0.85259395 | K24: =+S24/M24 -> 0.8181854 | L24: =+SUM(Efficiency1!K82:K83) -> 46.332724 | M24: =M23+L24 -> 742.17653 | N24: =+SUM(Efficiency1!C82:C83) -> 44.801606 | O24: =O23+N24 -> 726.9812 | P24: ='16'!I38 -> 41.797 | Q24: =Q23+P24 -> 626.805 | R24: ='16'!I40 -> 39.503 | S24: =S23+R24 -> 607.238 | T24: =+AX24 -> 4975.5712 | U24: =T24+U23 -> 76668.315 | V24: =T24/P24 -> 119.04135 | W24: =U24/Q24 -> 122.31605 | X24: =IF(AND(R24>0,T24>0),(T24/(R24*1000))*1000,0) -> 125.95426 | Y24: =IF(AND(S24>0,U24>0),U24/S24,0) -> 126.25744 | Z24: 56.4 | AA24: =Z24+AA23 -> 844.1 | AB24: =Z24/(P24) -> 1.3493791 | AC24: =AA24/(Q24) -> 1.3466708 | AD24: =IF(AND(R24>0,Z24>0),Z24/(R24),0) -> 1.4277397 | AE24: =IF(AND(S24>0,AA24>0),AA24/(S24),0) -> 1.3900645 | AF24: ='16'!I46 -> 38006.8 | AG24: =AF24+AG23 -> 558576.68 | AH24: =IF(AND(L24>0,AF24>0),(AF24/(P24*1000)*1000),0) -> 909.31885 | AI24: =IF(AND(M24>0,AG24>0),(AG24/(Q24*1000)*1000),0) -> 891.14905 | AJ24: =IF(AND(R24>0,AF24>0),(AF24/(R24*1000)*1000),0) -> 962.1244 | AK24: =IF(AND(S24>0,AG24>0),(AG24/(S24*1000)*1000),0) -> 919.8645 | AL24: 5958.6 | AM24: 4629.7 | AN24: 3611.3 | AO24: =SUM(AL24:AN24) -> 14199.6 | AP24: =+[1]Mar!N19 -> 11857 | AQ24: =+AP24-AO24 -> -2342.6 | AR24: =+AL24/AO24 -> 0.41963154 | AS24: =+AM24/AO24 -> 0.3260444 | AT24: =1-AR24-AS24 -> 0.25432407 | AU24: =+AR24*AQ24 -> -983.02884 | AV24: =+AS24*AQ24 -> -763.7916 | AW24: =+AT24*AQ24 -> -595.77956 | AX24: =IFERROR(+AL24+AU24,"-") -> 4975.5712 | AY24: =IFERROR(+AM24+AV24,"-") -> 3865.9084 | AZ24: =IFERROR(+AN24+AW24,"-") -> 3015.5204 | BA24: =+SUM(Efficiency2!K82:K83) -> 46.332724 | BB24: =BB23+BA24 -> 719.16981 | BC24: =+R24/BA24 -> 0.85259395 | BD24: =+S24/BB24 -> 0.84435969
A25: =A24+1 -> 46098 | B25: Toilet | C25: 12,5 | D25: =+'17'!F42 -> 1230 | E25: =+'17'!G42 -> 959.4 | F25: =1-(E25/D25) -> 0.22 | G25: =+P25/N25 -> 0.12167138 | H25: =+P25/L25 -> 0.12167138 | I25: =+R25/P25 -> 1.085 | J25: =+R25/L25 -> 0.13201344 | K25: =+S25/M25 -> 0.7794679 | L25: =+Efficiency1!K87 -> 44.381844 | M25: =M24+L25 -> 786.55837 | N25: =+Efficiency1!C87 -> 44.381844 | O25: =O24+N25 -> 771.36305 | P25: ='17'!I38 -> 5.4 | Q25: =Q24+P25 -> 632.205 | R25: ='17'!I40 -> 5.859 | S25: =S24+R25 -> 613.097 | T25: =+AX25 -> 502.6425 | U25: =T25+U24 -> 77170.957 | V25: =T25/P25 -> 93.081944 | W25: =U25/Q25 -> 122.06635 | X25: =IF(AND(R25>0,T25>0),(T25/(R25*1000))*1000,0) -> 85.78981 | Y25: =IF(AND(S25>0,U25>0),U25/S25,0) -> 125.87071 | Z25: 8.6 | AA25: =Z25+AA24 -> 852.7 | AB25: =Z25/(P25) -> 1.5925926 | AC25: =AA25/(Q25) -> 1.3487714 | AD25: =IF(AND(R25>0,Z25>0),Z25/(R25),0) -> 1.4678273 | AE25: =IF(AND(S25>0,AA25>0),AA25/(S25),0) -> 1.3908077 | AF25: ='17'!I46 -> 11728.06 | AG25: =AF25+AG24 -> 570304.74 | AH25: =IF(AND(L25>0,AF25>0),(AF25/(P25*1000)*1000),0) -> 2171.863 | AI25: =IF(AND(M25>0,AG25>0),(AG25/(Q25*1000)*1000),0) -> 902.08831 | AJ25: =IF(AND(R25>0,AF25>0),(AF25/(R25*1000)*1000),0) -> 2001.717 | AK25: =IF(AND(S25>0,AG25>0),(AG25/(S25*1000)*1000),0) -> 930.20312 | AL25: 395.3 | AM25: 4837.3 | AN25: 3747.8 | AO25: =SUM(AL25:AN25) -> 8980.4 | AP25: =+[1]Mar!N20 -> 11419 | AQ25: =+AP25-AO25 -> 2438.6 | AR25: =+AL25/AO25 -> 0.044018084 | AS25: =+AM25/AO25 -> 0.53865084 | AT25: =1-AR25-AS25 -> 0.41733108 | AU25: =+AR25*AQ25 -> 107.3425 | AV25: =+AS25*AQ25 -> 1313.5539 | AW25: =+AT25*AQ25 -> 1017.7036 | AX25: =IFERROR(+AL25+AU25,"-") -> 502.6425 | AY25: =IFERROR(+AM25+AV25,"-") -> 6150.8539 | AZ25: =IFERROR(+AN25+AW25,"-") -> 4765.5036 | BA25: =+Efficiency2!K87 -> 5.3936269 | BB25: =BB24+BA25 -> 724.56344 | BC25: =+R25/BA25 -> 1.086282 | BD25: =+S25/BB25 -> 0.84616055
A26: =A25+1 -> 46099 | B26: Toilet | C26: 12,5 | D26: =+'18'!F42 -> 0 | E26: =+'18'!G42 -> 0 | F26: =1-(E26/D26) -> #DIV/0! | G26: =+P26/N26 -> 0 | H26: =+P26/L26 -> 0 | I26: =+R26/P26 -> #DIV/0! | J26: =+R26/L26 -> 0 | K26: =+S26/M26 -> 0.73798865 | L26: =+Efficiency1!K92 -> 44.209152 | M26: =M25+L26 -> 830.76752 | N26: =+Efficiency1!C92 -> 44.209152 | O26: =O25+N26 -> 815.5722 | P26: ='18'!I38 -> 0 | Q26: =Q25+P26 -> 632.205 | R26: ='18'!I40 -> 0 | S26: =S25+R26 -> 613.097 | T26: =+AX26 -> 0 | U26: =T26+U25 -> 77170.957 | V26: =T26/P26 -> #DIV/0! | W26: =U26/Q26 -> 122.06635 | X26: =IF(AND(R26>0,T26>0),(T26/(R26*1000))*1000,0) -> 0 | Y26: =IF(AND(S26>0,U26>0),U26/S26,0) -> 125.87071 | Z26: 2.1 | AA26: =Z26+AA25 -> 854.8 | AB26: =Z26/(P26) -> #DIV/0! | AC26: =AA26/(Q26) -> 1.3520931 | AD26: =IF(AND(R26>0,Z26>0),Z26/(R26),0) -> 0 | AE26: =IF(AND(S26>0,AA26>0),AA26/(S26),0) -> 1.3942329 | AF26: ='18'!I46 -> 5911.28 | AG26: =AF26+AG25 -> 576216.02 | AH26: =IF(AND(L26>0,AF26>0),(AF26/(P26*1000)*1000),0) -> #DIV/0! | AI26: =IF(AND(M26>0,AG26>0),(AG26/(Q26*1000)*1000),0) -> 911.43857 | AJ26: =IF(AND(R26>0,AF26>0),(AF26/(R26*1000)*1000),0) -> 0 | AK26: =IF(AND(S26>0,AG26>0),(AG26/(S26*1000)*1000),0) -> 939.84479 | AL26: 0 | AM26: 5129.9 | AN26: 3830.8 | AO26: =SUM(AL26:AN26) -> 8960.7 | AP26: =+[1]Mar!N21 -> 9202 | AQ26: =+AP26-AO26 -> 241.3 | AR26: =+AL26/AO26 -> 0 | AS26: =+AM26/AO26 -> 0.57248876 | AT26: =1-AR26-AS26 -> 0.42751124 | AU26: =+AR26*AQ26 -> 0 | AV26: =+AS26*AQ26 -> 138.14154 | AW26: =+AT26*AQ26 -> 103.15846 | AX26: =IFERROR(+AL26+AU26,"-") -> 0 | AY26: =IFERROR(+AM26+AV26,"-") -> 5268.0415 | AZ26: =IFERROR(+AN26+AW26,"-") -> 3933.9585 | BA26: =+Efficiency2!K92 -> 0 | BB26: =BB25+BA26 -> 724.56344 | BC26: =+R26/BA26 -> #DIV/0! | BD26: =+S26/BB26 -> 0.84616055
A27: =A26+1 -> 46100 | B27: Toilet | C27: 12,5 | D27: =+'19'!F42 -> 0 | E27: =+'19'!G42 -> 0 | F27: =1-(E27/D27) -> #DIV/0! | G27: =+P27/N27 -> 0 | H27: =+P27/L27 -> 0 | I27: =+R27/P27 -> #DIV/0! | J27: =+R27/L27 -> 0 | K27: =+S27/M27 -> 0.70070096 | L27: =+Efficiency1!K97 -> 44.209152 | M27: =M26+L27 -> 874.97668 | N27: =+Efficiency1!C97 -> 44.209152 | O27: =O26+N27 -> 859.78135 | P27: ='19'!I38 -> 0 | Q27: =Q26+P27 -> 632.205 | R27: ='19'!I40 -> 0 | S27: =S26+R27 -> 613.097 | T27: =+AX27 -> 0 | U27: =T27+U26 -> 77170.957 | V27: =T27/P27 -> #DIV/0! | W27: =U27/Q27 -> 122.06635 | X27: =IF(AND(R27>0,T27>0),(T27/(R27*1000))*1000,0) -> 0 | Y27: =IF(AND(S27>0,U27>0),U27/S27,0) -> 125.87071 | Z27: 3.2 | AA27: =Z27+AA26 -> 858 | AB27: =Z27/(P27) -> #DIV/0! | AC27: =AA27/(Q27) -> 1.3571547 | AD27: =IF(AND(R27>0,Z27>0),Z27/(R27),0) -> 0 | AE27: =IF(AND(S27>0,AA27>0),AA27/(S27),0) -> 1.3994523 | AF27: ='19'!I46 -> 3665.16 | AG27: =AF27+AG26 -> 579881.18 | AH27: =IF(AND(L27>0,AF27>0),(AF27/(P27*1000)*1000),0) -> #DIV/0! | AI27: =IF(AND(M27>0,AG27>0),(AG27/(Q27*1000)*1000),0) -> 917.23599 | AJ27: =IF(AND(R27>0,AF27>0),(AF27/(R27*1000)*1000),0) -> 0 | AK27: =IF(AND(S27>0,AG27>0),(AG27/(S27*1000)*1000),0) -> 945.8229 | AL27: 0 | AM27: 5487.3 | AN27: 3886.9 | AO27: =SUM(AL27:AN27) -> 9374.2 | AP27: =+[1]Mar!N22 -> 9050 | AQ27: =+AP27-AO27 -> -324.2 | AR27: =+AL27/AO27 -> 0 | AS27: =+AM27/AO27 -> 0.58536195 | AT27: =1-AR27-AS27 -> 0.41463805 | AU27: =+AR27*AQ27 -> 0 | AV27: =+AS27*AQ27 -> -189.77434 | AW27: =+AT27*AQ27 -> -134.42566 | AX27: =IFERROR(+AL27+AU27,"-") -> 0 | AY27: =IFERROR(+AM27+AV27,"-") -> 5297.5257 | AZ27: =IFERROR(+AN27+AW27,"-") -> 3752.4743 | BA27: =+Efficiency2!K97 -> 0 | BB27: =BB26+BA27 -> 724.56344 | BC27: =+R27/BA27 -> #DIV/0! | BD27: =+S27/BB27 -> 0.84616055
A28: =A27+1 -> 46101 | B28: Toilet | C28: 12,5 | D28: =+'20'!F42 -> 0 | E28: =+'20'!G42 -> 0 | F28: =1-(E28/D28) -> #DIV/0! | G28: =+P28/N28 -> 0 | H28: =+P28/L28 -> 0 | I28: =+R28/P28 -> #DIV/0! | J28: =+R28/L28 -> 0 | K28: =+S28/M28 -> 0.66700006 | L28: =+Efficiency1!K102 -> 44.209152 | M28: =M27+L28 -> 919.18583 | N28: =+Efficiency1!C102 -> 44.209152 | O28: =O27+N28 -> 903.9905 | P28: ='20'!I38 -> 0 | Q28: =Q27+P28 -> 632.205 | R28: ='20'!I40 -> 0 | S28: =S27+R28 -> 613.097 | T28: =+AX28 -> 0 | U28: =T28+U27 -> 77170.957 | V28: =T28/P28 -> #DIV/0! | W28: =U28/Q28 -> 122.06635 | X28: =IF(AND(R28>0,T28>0),(T28/(R28*1000))*1000,0) -> 0 | Y28: =IF(AND(S28>0,U28>0),U28/S28,0) -> 125.87071 | Z28: 4 | AA28: =Z28+AA27 -> 862 | AB28: =Z28/(P28) -> #DIV/0! | AC28: =AA28/(Q28) -> 1.3634818 | AD28: =IF(AND(R28>0,Z28>0),Z28/(R28),0) -> 0 | AE28: =IF(AND(S28>0,AA28>0),AA28/(S28),0) -> 1.4059765 | AF28: ='20'!I46 -> 6014.98 | AG28: =AF28+AG27 -> 585896.16 | AH28: =IF(AND(L28>0,AF28>0),(AF28/(P28*1000)*1000),0) -> #DIV/0! | AI28: =IF(AND(M28>0,AG28>0),(AG28/(Q28*1000)*1000),0) -> 926.75028 | AJ28: =IF(AND(R28>0,AF28>0),(AF28/(R28*1000)*1000),0) -> 0 | AK28: =IF(AND(S28>0,AG28>0),(AG28/(S28*1000)*1000),0) -> 955.63371 | AL28: 0 | AM28: 5476.9 | AN28: 3877.3 | AO28: =SUM(AL28:AN28) -> 9354.2 | AP28: =+[1]Mar!N23 -> 9530 | AQ28: =+AP28-AO28 -> 175.8 | AR28: =+AL28/AO28 -> 0 | AS28: =+AM28/AO28 -> 0.5855017 | AT28: =1-AR28-AS28 -> 0.4144983 | AU28: =+AR28*AQ28 -> 0 | AV28: =+AS28*AQ28 -> 102.9312 | AW28: =+AT28*AQ28 -> 72.868801 | AX28: =IFERROR(+AL28+AU28,"-") -> 0 | AY28: =IFERROR(+AM28+AV28,"-") -> 5579.8312 | AZ28: =IFERROR(+AN28+AW28,"-") -> 3950.1688 | BA28: =+Efficiency2!K102 -> 0 | BB28: =BB27+BA28 -> 724.56344 | BC28: =+R28/BA28 -> #DIV/0! | BD28: =+S28/BB28 -> 0.84616055
A29: =A28+1 -> 46102 | B29: Toilet | C29: 12,5 | D29: =+'21'!F42 -> 0 | E29: =+'21'!G42 -> 0 | F29: =1-(E29/D29) -> #DIV/0! | G29: =+P29/N29 -> 0 | H29: =+P29/L29 -> 0 | I29: =+R29/P29 -> #DIV/0! | J29: =+R29/L29 -> 0 | K29: =+S29/M29 -> 0.63639215 | L29: =+Efficiency1!K107 -> 44.209152 | M29: =M28+L29 -> 963.39498 | N29: =+Efficiency1!C107 -> 44.209152 | O29: =O28+N29 -> 948.19966 | P29: ='21'!I38 -> 0 | Q29: =Q28+P29 -> 632.205 | R29: ='21'!I40 -> 0 | S29: =S28+R29 -> 613.097 | T29: =+AX29 -> 0 | U29: =T29+U28 -> 77170.957 | V29: =T29/P29 -> #DIV/0! | W29: =U29/Q29 -> 122.06635 | X29: =IF(AND(R29>0,T29>0),(T29/(R29*1000))*1000,0) -> 0 | Y29: =IF(AND(S29>0,U29>0),U29/S29,0) -> 125.87071 | Z29: 5 | AA29: =Z29+AA28 -> 867 | AB29: =Z29/(P29) -> #DIV/0! | AC29: =AA29/(Q29) -> 1.3713906 | AD29: =IF(AND(R29>0,Z29>0),Z29/(R29),0) -> 0 | AE29: =IF(AND(S29>0,AA29>0),AA29/(S29),0) -> 1.4141319 | AF29: ='21'!I46 -> 5326.54 | AG29: =AF29+AG28 -> 591222.7 | AH29: =IF(AND(L29>0,AF29>0),(AF29/(P29*1000)*1000),0) -> #DIV/0! | AI29: =IF(AND(M29>0,AG29>0),(AG29/(Q29*1000)*1000),0) -> 935.17562 | AJ29: =IF(AND(R29>0,AF29>0),(AF29/(R29*1000)*1000),0) -> 0 | AK29: =IF(AND(S29>0,AG29>0),(AG29/(S29*1000)*1000),0) -> 964.32163 | AL29: 0 | AM29: 5527.2 | AN29: 3886.5 | AO29: =SUM(AL29:AN29) -> 9413.7 | AP29: =+[1]Mar!N24 -> 9711 | AQ29: =+AP29-AO29 -> 297.3 | AR29: =+AL29/AO29 -> 0 | AS29: =+AM29/AO29 -> 0.58714427 | AT29: =1-AR29-AS29 -> 0.41285573 | AU29: =+AR29*AQ29 -> 0 | AV29: =+AS29*AQ29 -> 174.55799 | AW29: =+AT29*AQ29 -> 122.74201 | AX29: =IFERROR(+AL29+AU29,"-") -> 0 | AY29: =IFERROR(+AM29+AV29,"-") -> 5701.758 | AZ29: =IFERROR(+AN29+AW29,"-") -> 4009.242 | BA29: =+Efficiency2!K107 -> 0 | BB29: =BB28+BA29 -> 724.56344 | BC29: =+R29/BA29 -> #DIV/0! | BD29: =+S29/BB29 -> 0.84616055
A30: =A29+1 -> 46103 | B30: Toilet | C30: 12,5 | D30: =+'22'!F42 -> 0 | E30: =+'22'!G42 -> 0 | F30: =1-(E30/D30) -> #DIV/0! | G30: =+P30/N30 -> 0 | H30: =+P30/L30 -> 0 | I30: =+R30/P30 -> #DIV/0! | J30: =+R30/L30 -> 0 | K30: =+S30/M30 -> 0.60847011 | L30: =+Efficiency1!K112 -> 44.209152 | M30: =M29+L30 -> 1007.6041 | N30: =+Efficiency1!C112 -> 44.209152 | O30: =O29+N30 -> 992.40881 | P30: ='22'!I38 -> 0 | Q30: =Q29+P30 -> 632.205 | R30: ='22'!I40 -> 0 | S30: =S29+R30 -> 613.097 | T30: =+AX30 -> 0 | U30: =T30+U29 -> 77170.957 | V30: =T30/P30 -> #DIV/0! | W30: =U30/Q30 -> 122.06635 | X30: =IF(AND(R30>0,T30>0),(T30/(R30*1000))*1000,0) -> 0 | Y30: =IF(AND(S30>0,U30>0),U30/S30,0) -> 125.87071 | Z30: 4.5 | AA30: =Z30+AA29 -> 871.5 | AB30: =Z30/(P30) -> #DIV/0! | AC30: =AA30/(Q30) -> 1.3785086 | AD30: =IF(AND(R30>0,Z30>0),Z30/(R30),0) -> 0 | AE30: =IF(AND(S30>0,AA30>0),AA30/(S30),0) -> 1.4214716 | AF30: ='22'!I46 -> 4580.3 | AG30: =AF30+AG29 -> 595803 | AH30: =IF(AND(L30>0,AF30>0),(AF30/(P30*1000)*1000),0) -> #DIV/0! | AI30: =IF(AND(M30>0,AG30>0),(AG30/(Q30*1000)*1000),0) -> 942.42058 | AJ30: =IF(AND(R30>0,AF30>0),(AF30/(R30*1000)*1000),0) -> 0 | AK30: =IF(AND(S30>0,AG30>0),(AG30/(S30*1000)*1000),0) -> 971.79239 | AL30: 0 | AM30: 5500.8 | AN30: 3883.9 | AO30: =SUM(AL30:AN30) -> 9384.7 | AP30: =+[1]Mar!N25 -> 9715 | AQ30: =+AP30-AO30 -> 330.3 | AR30: =+AL30/AO30 -> 0 | AS30: =+AM30/AO30 -> 0.58614553 | AT30: =1-AR30-AS30 -> 0.41385447 | AU30: =+AR30*AQ30 -> 0 | AV30: =+AS30*AQ30 -> 193.60387 | AW30: =+AT30*AQ30 -> 136.69613 | AX30: =IFERROR(+AL30+AU30,"-") -> 0 | AY30: =IFERROR(+AM30+AV30,"-") -> 5694.4039 | AZ30: =IFERROR(+AN30+AW30,"-") -> 4020.5961 | BA30: =+Efficiency2!K112 -> 0 | BB30: =BB29+BA30 -> 724.56344 | BC30: =+R30/BA30 -> #DIV/0! | BD30: =+S30/BB30 -> 0.84616055
A31: =A30+1 -> 46104 | B31: Toilet | C31: 12,5 | D31: =+'23'!F42 -> 0 | E31: =+'23'!G42 -> 0 | F31: =1-(E31/D31) -> #DIV/0! | G31: =+P31/N31 -> 0 | H31: =+P31/L31 -> 0 | I31: =+R31/P31 -> #DIV/0! | J31: =+R31/L31 -> 0 | K31: =+S31/M31 -> 0.58289528 | L31: =+Efficiency1!K117 -> 44.209152 | M31: =M30+L31 -> 1051.8133 | N31: =+Efficiency1!C117 -> 44.209152 | O31: =O30+N31 -> 1036.618 | P31: ='23'!I38 -> 0 | Q31: =Q30+P31 -> 632.205 | R31: ='23'!I40 -> 0 | S31: =S30+R31 -> 613.097 | T31: =+AX31 -> 8.3748172 | U31: =T31+U30 -> 77179.332 | V31: =T31/P31 -> #DIV/0! | W31: =U31/Q31 -> 122.0796 | X31: =IF(AND(R31>0,T31>0),(T31/(R31*1000))*1000,0) -> 0 | Y31: =IF(AND(S31>0,U31>0),U31/S31,0) -> 125.88437 | Z31: 12.3 | AA31: =Z31+AA30 -> 883.8 | AB31: =Z31/(P31) -> #DIV/0! | AC31: =AA31/(Q31) -> 1.3979643 | AD31: =IF(AND(R31>0,Z31>0),Z31/(R31),0) -> 0 | AE31: =IF(AND(S31>0,AA31>0),AA31/(S31),0) -> 1.4415337 | AF31: ='23'!I46 -> 5654.02 | AG31: =AF31+AG30 -> 601457.02 | AH31: =IF(AND(L31>0,AF31>0),(AF31/(P31*1000)*1000),0) -> #DIV/0! | AI31: =IF(AND(M31>0,AG31>0),(AG31/(Q31*1000)*1000),0) -> 951.36391 | AJ31: =IF(AND(R31>0,AF31>0),(AF31/(R31*1000)*1000),0) -> 0 | AK31: =IF(AND(S31>0,AG31>0),(AG31/(S31*1000)*1000),0) -> 981.01446 | AL31: 8.2 | AM31: 5258.4 | AN31: 3828.5 | AO31: =SUM(AL31:AN31) -> 9095.1 | AP31: =+[1]Mar!N26 -> 9289 | AQ31: =+AP31-AO31 -> 193.9 | AR31: =+AL31/AO31 -> 0.00090158437 | AS31: =+AM31/AO31 -> 0.57815747 | AT31: =1-AR31-AS31 -> 0.42094095 | AU31: =+AR31*AQ31 -> 0.17481721 | AV31: =+AS31*AQ31 -> 112.10473 | AW31: =+AT31*AQ31 -> 81.620449 | AX31: =IFERROR(+AL31+AU31,"-") -> 8.3748172 | AY31: =IFERROR(+AM31+AV31,"-") -> 5370.5047 | AZ31: =IFERROR(+AN31+AW31,"-") -> 3910.1204 | BA31: =+Efficiency2!K117 -> 0 | BB31: =BB30+BA31 -> 724.56344 | BC31: =+R31/BA31 -> #DIV/0! | BD31: =+S31/BB31 -> 0.84616055
A32: =A31+1 -> 46105 | B32: Toilet | C32: 14/12,5 | D32: =+'24'!F42 -> 1130.7064 | E32: =+'24'!G42 -> 868.59205 | F32: =1-(E32/D32) -> 0.23181469 | G32: =+P32/N32 -> 0.84219107 | H32: =+P32/L32 -> 0.71891646 | I32: =+R32/P32 -> 0.72941006 | J32: =+R32/L32 -> 0.5243849 | K32: =+S32/M32 -> 0.58034259 | L32: =+SUM(Efficiency1!K122:K123) -> 47.981931 | M32: =M31+L32 -> 1099.7952 | N32: =+SUM(Efficiency1!C122:C123) -> 40.958639 | O32: =O31+N32 -> 1077.5766 | P32: ='24'!I38 -> 34.495 | Q32: =Q31+P32 -> 666.7 | R32: ='24'!I40 -> 25.161 | S32: =S31+R32 -> 638.258 | T32: =+AX32 -> 5296.8762 | U32: =T32+U31 -> 82476.208 | V32: =T32/P32 -> 153.5549 | W32: =U32/Q32 -> 123.70813 | X32: =IF(AND(R32>0,T32>0),(T32/(R32*1000))*1000,0) -> 210.5193 | Y32: =IF(AND(S32>0,U32>0),U32/S32,0) -> 129.2208 | Z32: 58.3 | AA32: =Z32+AA31 -> 942.1 | AB32: =Z32/(P32) -> 1.6901 | AC32: =AA32/(Q32) -> 1.4130793 | AD32: =IF(AND(R32>0,Z32>0),Z32/(R32),0) -> 2.317078 | AE32: =IF(AND(S32>0,AA32>0),AA32/(S32),0) -> 1.4760489 | AF32: =+'24'!I46 -> 34527.66 | AG32: =AF32+AG31 -> 635984.68 | AH32: =IF(AND(L32>0,AF32>0),(AF32/(P32*1000)*1000),0) -> 1000.9468 | AI32: =IF(AND(M32>0,AG32>0),(AG32/(Q32*1000)*1000),0) -> 953.92932 | AJ32: =IF(AND(R32>0,AF32>0),(AF32/(R32*1000)*1000),0) -> 1372.269 | AK32: =IF(AND(S32>0,AG32>0),(AG32/(S32*1000)*1000),0) -> 996.43824 | AL32: 5600.2 | AM32: 5330.5 | AN32: 3826.6 | AO32: =SUM(AL32:AN32) -> 14757.3 | AP32: =+[1]Mar!N27 -> 13958 | AQ32: =+AP32-AO32 -> -799.3 | AR32: =+AL32/AO32 -> 0.37948676 | AS32: =+AM32/AO32 -> 0.36121106 | AT32: =1-AR32-AS32 -> 0.25930218 | AU32: =+AR32*AQ32 -> -303.32377 | AV32: =+AS32*AQ32 -> -288.716 | AW32: =+AT32*AQ32 -> -207.26023 | AX32: =IFERROR(+AL32+AU32,"-") -> 5296.8762 | AY32: =IFERROR(+AM32+AV32,"-") -> 5041.784 | AZ32: =IFERROR(+AN32+AW32,"-") -> 3619.3398 | BA32: =+SUM(Efficiency2!K122:K123) -> 41.506908 | BB32: =BB31+BA32 -> 766.07035 | BC32: =+R32/BA32 -> 0.60618826 | BD32: =+S32/BB32 -> 0.83315847
A33: =A32+1 -> 46106 | B33: Toilet | C33: 12,5 | D33: =+'25'!F42 -> 1146.0417 | E33: =+'25'!G42 -> 878.55208 | F33: =1-(E33/D33) -> 0.23340302 | G33: =+P33/N33 -> 0.93381835 | H33: =+P33/L33 -> 0.87007702 | I33: =+R33/P33 -> 1.0086218 | J33: =+R33/L33 -> 0.87757867 | K33: =+S33/M33 -> 0.5916744 | L33: =+Efficiency1!K130 -> 43.590394 | M33: =M32+L33 -> 1143.3856 | N33: =+Efficiency1!C130 -> 40.614966 | O33: =O32+N33 -> 1118.1916 | P33: ='25'!I38 -> 37.927 | Q33: =Q32+P33 -> 704.627 | R33: ='25'!I40 -> 38.254 | S33: =S32+R33 -> 676.512 | T33: =+AX33 -> 5296.476 | U33: =T33+U32 -> 87772.684 | V33: =T33/P33 -> 139.64922 | W33: =U33/Q33 -> 124.56617 | X33: =IF(AND(R33>0,T33>0),(T33/(R33*1000))*1000,0) -> 138.45548 | Y33: =IF(AND(S33>0,U33>0),U33/S33,0) -> 129.74298 | Z33: 58.7 | AA33: =Z33+AA32 -> 1000.8 | AB33: =Z33/(P33) -> 1.5477101 | AC33: =AA33/(Q33) -> 1.4203259 | AD33: =IF(AND(R33>0,Z33>0),Z33/(R33),0) -> 1.5344801 | AE33: =IF(AND(S33>0,AA33>0),AA33/(S33),0) -> 1.4793529 | AF33: =+'25'!I46 -> 34704.02 | AG33: =AF33+AG32 -> 670688.7 | AH33: =IF(AND(L33>0,AF33>0),(AF33/(P33*1000)*1000),0) -> 915.02149 | AI33: =IF(AND(M33>0,AG33>0),(AG33/(Q33*1000)*1000),0) -> 951.83508 | AJ33: =IF(AND(R33>0,AF33>0),(AF33/(R33*1000)*1000),0) -> 907.19977 | AK33: =IF(AND(S33>0,AG33>0),(AG33/(S33*1000)*1000),0) -> 991.39217 | AL33: 5593.5 | AM33: 5453.3 | AN33: 3822.8 | AO33: =SUM(AL33:AN33) -> 14869.6 | AP33: =+[1]Mar!N28 -> 14080 | AQ33: =+AP33-AO33 -> -789.6 | AR33: =+AL33/AO33 -> 0.37617017 | AS33: =+AM33/AO33 -> 0.36674154 | AT33: =1-AR33-AS33 -> 0.25708829 | AU33: =+AR33*AQ33 -> -297.02397 | AV33: =+AS33*AQ33 -> -289.57912 | AW33: =+AT33*AQ33 -> -202.99691 | AX33: =IFERROR(+AL33+AU33,"-") -> 5296.476 | AY33: =IFERROR(+AM33+AV33,"-") -> 5163.7209 | AZ33: =IFERROR(+AN33+AW33,"-") -> 3619.8031 | BA33: =+Efficiency2!K130 -> 43.590394 | BB33: =BB32+BA33 -> 809.66074 | BC33: =+R33/BA33 -> 0.87757867 | BD33: =+S33/BB33 -> 0.83554996
A34: =A33+1 -> 46107 | B34: Toilet | C34: 12,5/13 | D34: =+'26'!F42 -> 1152.5417 | E34: =+'26'!G42 -> 897.16167 | F34: =1-(E34/D34) -> 0.22157984 | G34: =+P34/N34 -> 0.89766352 | H34: =+P34/L34 -> 0.84114342 | I34: =+R34/P34 -> 1.0529702 | J34: =+R34/L34 -> 0.88569892 | K34: =+S34/M34 -> 0.60300564 | L34: =+SUM(Efficiency1!K135:K136) -> 45.830472 | M34: =M33+L34 -> 1189.2161 | N34: =+SUM(Efficiency1!C135:C136) -> 42.944822 | O34: =O33+N34 -> 1161.1364 | P34: ='26'!I38 -> 38.55 | Q34: =Q33+P34 -> 743.177 | R34: ='26'!I40 -> 40.592 | S34: =S33+R34 -> 717.104 | T34: =+AX34 -> 5482.2038 | U34: =T34+U33 -> 93254.888 | V34: =T34/P34 -> 142.21022 | W34: =U34/Q34 -> 125.4814 | X34: =IF(AND(R34>0,T34>0),(T34/(R34*1000))*1000,0) -> 135.05626 | Y34: =IF(AND(S34>0,U34>0),U34/S34,0) -> 130.04374 | Z34: 60.5 | AA34: =Z34+AA33 -> 1061.3 | AB34: =Z34/(P34) -> 1.5693904 | AC34: =AA34/(Q34) -> 1.4280582 | AD34: =IF(AND(R34>0,Z34>0),Z34/(R34),0) -> 1.4904415 | AE34: =IF(AND(S34>0,AA34>0),AA34/(S34),0) -> 1.4799806 | AF34: ='26'!I46 -> 37028.6 | AG34: =AF34+AG33 -> 707717.3 | AH34: =IF(AND(L34>0,AF34>0),(AF34/(P34*1000)*1000),0) -> 960.53437 | AI34: =IF(AND(M34>0,AG34>0),(AG34/(Q34*1000)*1000),0) -> 952.28633 | AJ34: =IF(AND(R34>0,AF34>0),(AF34/(R34*1000)*1000),0) -> 912.21423 | AK34: =IF(AND(S34>0,AG34>0),(AG34/(S34*1000)*1000),0) -> 986.91027 | AL34: 5775.8 | AM34: 5473.8 | AN34: 3778.3 | AO34: =SUM(AL34:AN34) -> 15027.9 | AP34: =+[1]Mar!N29 -> 14264 | AQ34: =+AP34-AO34 -> -763.9 | AR34: =+AL34/AO34 -> 0.38433846 | AS34: =+AM34/AO34 -> 0.36424251 | AT34: =1-AR34-AS34 -> 0.25141903 | AU34: =+AR34*AQ34 -> -293.59615 | AV34: =+AS34*AQ34 -> -278.24485 | AW34: =+AT34*AQ34 -> -192.05899 | AX34: =IFERROR(+AL34+AU34,"-") -> 5482.2038 | AY34: =IFERROR(+AM34+AV34,"-") -> 5195.5551 | AZ34: =IFERROR(+AN34+AW34,"-") -> 3586.241 | BA34: =+SUM(Efficiency2!K135:K136) -> 45.830472 | BB34: =BB33+BA34 -> 855.49122 | BC34: =+R34/BA34 -> 0.88569892 | BD34: =+S34/BB34 -> 0.83823654
A35: =A34+1 -> 46108 | B35: Toilet | C35: 13 | D35: =+'27'!F42 -> 1140 | E35: =+'27'!G42 -> 889.2 | F35: =1-(E35/D35) -> 0.22 | G35: =+P35/N35 -> 0.95027075 | H35: =+P35/L35 -> 0.88073875 | I35: =+R35/P35 -> 1.0048418 | J35: =+R35/L35 -> 0.88500309 | K35: =+S35/M35 -> 0.61349912 | L35: =+Efficiency1!K139 -> 45.962551 | M35: =M34+L35 -> 1235.1786 | N35: =+Efficiency1!C139 -> 42.599438 | O35: =O34+N35 -> 1203.7358 | P35: ='27'!I38 -> 40.481 | Q35: =Q34+P35 -> 783.658 | R35: ='27'!I40 -> 40.677 | S35: =S34+R35 -> 757.781 | T35: =+AX35 -> 5535.0344 | U35: =T35+U34 -> 98789.922 | V35: =T35/P35 -> 136.73166 | W35: =U35/Q35 -> 126.06255 | X35: =IF(AND(R35>0,T35>0),(T35/(R35*1000))*1000,0) -> 136.07283 | Y35: =IF(AND(S35>0,U35>0),U35/S35,0) -> 130.36738 | Z35: 58.8 | AA35: =Z35+AA34 -> 1120.1 | AB35: =Z35/(P35) -> 1.4525333 | AC35: =AA35/(Q35) -> 1.4293225 | AD35: =IF(AND(R35>0,Z35>0),Z35/(R35),0) -> 1.4455343 | AE35: =IF(AND(S35>0,AA35>0),AA35/(S35),0) -> 1.4781315 | AF35: ='27'!I46 -> 35518.96 | AG35: =AF35+AG34 -> 743236.26 | AH35: =IF(AND(L35>0,AF35>0),(AF35/(P35*1000)*1000),0) -> 877.42299 | AI35: =IF(AND(M35>0,AG35>0),(AG35/(Q35*1000)*1000),0) -> 948.41916 | AJ35: =IF(AND(R35>0,AF35>0),(AF35/(R35*1000)*1000),0) -> 873.19517 | AK35: =IF(AND(S35>0,AG35>0),(AG35/(S35*1000)*1000),0) -> 980.80614 | AL35: 5834.3 | AM35: 5120.7 | AN35: 3842 | AO35: =SUM(AL35:AN35) -> 14797 | AP35: =+[1]Mar!N30 -> 14038 | AQ35: =+AP35-AO35 -> -759 | AR35: =+AL35/AO35 -> 0.39428938 | AS35: =+AM35/AO35 -> 0.34606339 | AT35: =1-AR35-AS35 -> 0.25964723 | AU35: =+AR35*AQ35 -> -299.26564 | AV35: =+AS35*AQ35 -> -262.66211 | AW35: =+AT35*AQ35 -> -197.07224 | AX35: =IFERROR(+AL35+AU35,"-") -> 5535.0344 | AY35: =IFERROR(+AM35+AV35,"-") -> 4858.0379 | AZ35: =IFERROR(+AN35+AW35,"-") -> 3644.9278 | BA35: =+Efficiency2!K139 -> 45.962551 | BB35: =BB34+BA35 -> 901.45377 | BC35: =+R35/BA35 -> 0.88500309 | BD35: =+S35/BB35 -> 0.84062104
A36: =A35+1 -> 46109 | B36: Toilet | C36: 13 | D36: =+'28'!F42 -> 1146.6667 | E36: =+'28'!G42 -> 894.4 | F36: =1-(E36/D36) -> 0.22 | G36: =+P36/N36 -> 0.96276213 | H36: =+P36/L36 -> 0.89753434 | I36: =+R36/P36 -> 0.95382978 | J36: =+R36/L36 -> 0.85609499 | K36: =+S36/M36 -> 0.62222167 | L36: =+Efficiency1!K143 -> 46.067318 | M36: =M35+L36 -> 1281.246 | N36: =+Efficiency1!C143 -> 42.946226 | O36: =O35+N36 -> 1246.682 | P36: ='28'!I38 -> 41.347 | Q36: =Q35+P36 -> 825.005 | R36: ='28'!I40 -> 39.438 | S36: =S35+R36 -> 797.219 | T36: =+AX36 -> 5487.2415 | U36: =T36+U35 -> 104277.16 | V36: =T36/P36 -> 132.71196 | W36: =U36/Q36 -> 126.3958 | X36: =IF(AND(R36>0,T36>0),(T36/(R36*1000))*1000,0) -> 139.1359 | Y36: =IF(AND(S36>0,U36>0),U36/S36,0) -> 130.80115 | Z36: 59.6 | AA36: =Z36+AA35 -> 1179.7 | AB36: =Z36/(P36) -> 1.4414589 | AC36: =AA36/(Q36) -> 1.4299307 | AD36: =IF(AND(R36>0,Z36>0),Z36/(R36),0) -> 1.5112328 | AE36: =IF(AND(S36>0,AA36>0),AA36/(S36),0) -> 1.479769 | AF36: ='28'!I46 -> 35419.08 | AG36: =AF36+AG35 -> 778655.34 | AH36: =IF(AND(L36>0,AF36>0),(AF36/(P36*1000)*1000),0) -> 856.62999 | AI36: =IF(AND(M36>0,AG36>0),(AG36/(Q36*1000)*1000),0) -> 943.81893 | AJ36: =IF(AND(R36>0,AF36>0),(AF36/(R36*1000)*1000),0) -> 898.09524 | AK36: =IF(AND(S36>0,AG36>0),(AG36/(S36*1000)*1000),0) -> 976.71448 | AL36: 5782.2 | AM36: 5216.1 | AN36: 3965 | AO36: =SUM(AL36:AN36) -> 14963.3 | AP36: =+[1]Mar!N31 -> 14200 | AQ36: =+AP36-AO36 -> -763.3 | AR36: =+AL36/AO36 -> 0.38642545 | AS36: =+AM36/AO36 -> 0.34859289 | AT36: =1-AR36-AS36 -> 0.26498166 | AU36: =+AR36*AQ36 -> -294.95855 | AV36: =+AS36*AQ36 -> -266.08095 | AW36: =+AT36*AQ36 -> -202.2605 | AX36: =IFERROR(+AL36+AU36,"-") -> 5487.2415 | AY36: =IFERROR(+AM36+AV36,"-") -> 4950.019 | AZ36: =IFERROR(+AN36+AW36,"-") -> 3762.7395 | BA36: =+Efficiency2!K143 -> 46.067318 | BB36: =BB35+BA36 -> 947.52108 | BC36: =+R36/BA36 -> 0.85609499 | BD36: =+S36/BB36 -> 0.84137336
A37: =A36+1 -> 46110 | B37: Toilet | C37: 13 | D37: =+'29'!F42 -> 1127.0833 | E37: =+'29'!G42 -> 879.125 | F37: =1-(E37/D37) -> 0.22 | G37: =+P37/N37 -> 0.94362442 | H37: =+P37/L37 -> 0.8646694 | I37: =+R37/P37 -> 0.95468581 | J37: =+R37/L37 -> 0.82548761 | K37: =+S37/M37 -> 0.62927646 | L37: =+Efficiency1!K147 -> 46.067318 | M37: =M36+L37 -> 1327.3133 | N37: =+Efficiency1!C147 -> 42.212769 | O37: =O36+N37 -> 1288.8948 | P37: ='29'!I38 -> 39.833 | Q37: =Q36+P37 -> 864.838 | R37: ='29'!I40 -> 38.028 | S37: =S36+R37 -> 835.247 | T37: =+AX37 -> 5408.0459 | U37: =T37+U36 -> 109685.21 | V37: =T37/P37 -> 135.76798 | W37: =U37/Q37 -> 126.82746 | X37: =IF(AND(R37>0,T37>0),(T37/(R37*1000))*1000,0) -> 142.21221 | Y37: =IF(AND(S37>0,U37>0),U37/S37,0) -> 131.32069 | Z37: 56.4 | AA37: =Z37+AA36 -> 1236.1 | AB37: =Z37/(P37) -> 1.4159114 | AC37: =AA37/(Q37) -> 1.429285 | AD37: =IF(AND(R37>0,Z37>0),Z37/(R37),0) -> 1.4831177 | AE37: =IF(AND(S37>0,AA37>0),AA37/(S37),0) -> 1.4799215 | AF37: ='29'!I46 -> 36792.52 | AG37: =AF37+AG36 -> 815447.86 | AH37: =IF(AND(L37>0,AF37>0),(AF37/(P37*1000)*1000),0) -> 923.66932 | AI37: =IF(AND(M37>0,AG37>0),(AG37/(Q37*1000)*1000),0) -> 942.89088 | AJ37: =IF(AND(R37>0,AF37>0),(AF37/(R37*1000)*1000),0) -> 967.51131 | AK37: =IF(AND(S37>0,AG37>0),(AG37/(S37*1000)*1000),0) -> 976.29547 | AL37: 5692.7 | AM37: 5286.6 | AN37: 3959.7 | AO37: =SUM(AL37:AN37) -> 14939 | AP37: =+[1]Mar!N32 -> 14192 | AQ37: =+AP37-AO37 -> -747 | AR37: =+AL37/AO37 -> 0.38106299 | AS37: =+AM37/AO37 -> 0.35387911 | AT37: =1-AR37-AS37 -> 0.2650579 | AU37: =+AR37*AQ37 -> -284.65405 | AV37: =+AS37*AQ37 -> -264.34769 | AW37: =+AT37*AQ37 -> -197.99825 | AX37: =IFERROR(+AL37+AU37,"-") -> 5408.0459 | AY37: =IFERROR(+AM37+AV37,"-") -> 5022.2523 | AZ37: =IFERROR(+AN37+AW37,"-") -> 3761.7017 | BA37: =+Efficiency2!K147 -> 46.067318 | BB37: =BB36+BA37 -> 993.5884 | BC37: =+R37/BA37 -> 0.82548761 | BD37: =+S37/BB37 -> 0.84063682
A38: =A37+1 -> 46111 | B38: Toilet/Facial | C38: 13/11,5 | D38: =+'30'!F42 -> 1189.5417 | E38: =+'30'!G42 -> 910.72118 | F38: =1-(E38/D38) -> 0.23439321 | G38: =+P38/N38 -> 0.92745756 | H38: =+P38/L38 -> 0.89056066 | I38: =+R38/P38 -> 0.92521588 | J38: =+R38/L38 -> 0.82396086 | K38: =+S38/M38 -> 0.63531989 | L38: =+SUM(Efficiency1!K151:K152) -> 42.522651 | M38: =M37+L38 -> 1369.8359 | N38: =+SUM(Efficiency1!C151:C152) -> 40.830979 | O38: =O37+N38 -> 1329.7258 | P38: ='30'!I38 -> 37.869 | Q38: =Q37+P38 -> 902.707 | R38: ='30'!I40 -> 35.037 | S38: =S37+R38 -> 870.284 | T38: =+AX38 -> 5181.0149 | U38: =T38+U37 -> 114866.22 | V38: =T38/P38 -> 136.81415 | W38: =U38/Q38 -> 127.24641 | X38: =IF(AND(R38>0,T38>0),(T38/(R38*1000))*1000,0) -> 147.87267 | Y38: =IF(AND(S38>0,U38>0),U38/S38,0) -> 131.98706 | Z38: 55.4 | AA38: =Z38+AA37 -> 1291.5 | AB38: =Z38/(P38) -> 1.462938 | AC38: =AA38/(Q38) -> 1.4306968 | AD38: =IF(AND(R38>0,Z38>0),Z38/(R38),0) -> 1.5811856 | AE38: =IF(AND(S38>0,AA38>0),AA38/(S38),0) -> 1.4839983 | AF38: ='30'!I46 -> 37779.08 | AG38: =AF38+AG37 -> 853226.94 | AH38: =IF(AND(L38>0,AF38>0),(AF38/(P38*1000)*1000),0) -> 997.6255 | AI38: =IF(AND(M38>0,AG38>0),(AG38/(Q38*1000)*1000),0) -> 945.18702 | AJ38: =IF(AND(R38>0,AF38>0),(AF38/(R38*1000)*1000),0) -> 1078.2624 | AK38: =IF(AND(S38>0,AG38>0),(AG38/(S38*1000)*1000),0) -> 980.40058 | AL38: 5380.1 | AM38: 4883.3 | AN38: 3854 | AO38: =SUM(AL38:AN38) -> 14117.4 | AP38: =+[1]Mar!N33 -> 13595 | AQ38: =+AP38-AO38 -> -522.4 | AR38: =+AL38/AO38 -> 0.38109709 | AS38: =+AM38/AO38 -> 0.34590647 | AT38: =1-AR38-AS38 -> 0.27299644 | AU38: =+AR38*AQ38 -> -199.08512 | AV38: =+AS38*AQ38 -> -180.70154 | AW38: =+AT38*AQ38 -> -142.61334 | AX38: =IFERROR(+AL38+AU38,"-") -> 5181.0149 | AY38: =IFERROR(+AM38+AV38,"-") -> 4702.5985 | AZ38: =IFERROR(+AN38+AW38,"-") -> 3711.3867 | BA38: =+SUM(Efficiency2!K151:K152) -> 42.522651 | BB38: =BB37+BA38 -> 1036.1111 | BC38: =+R38/BA38 -> 0.82396086 | BD38: =+S38/BB38 -> 0.83995243
