Workbook

Sheet Report1
A3: PAPER MACHINE 14 DAILY REPORT 1
A6: Date | B6: Grade | C6: GSM | D6: Speed yankee (mpm) | E6: Speed reel (mpm) | F6: Creep ( % ) | G6: Real Eff PM ( % ) | H6: Real Eff PM vs Target (%) | I6: Real Eff FG vs Real Eff PM (%) | J6: Eff FG vs Target (%) | L6: Kapasitas Target (ton) | N6: Kapasitas Teori Real (ton) | P6: PM PROD Timbangan (TON) | R6: FINSHED GOODS (TON) | T6: GAS HOOD | Z6: STEAM (TON) | AF6: POWER (kWh) | BA6: Kapasitas Running (ton) | BC6: Eff FG vs Target Running(%)
T7: CONSUMPTION | V7: /TON PM. | X7: /TON FG. | Z7: CONSUMPTION | AB7: /TON PM. | AD7: /TON FG. | AF7: CONSUMPTION | AH7: /TON PM | AJ7: /TON FG | AL7: Gas based on report DCS | AO7: total | AP7: Flowmeter | AQ7: Selisih | AR7: % pengali | AU7: Adjust | AX7: PEMAKAIAN GAS
J8: TODAY | K8: TODATE | L8: TODAY | M8: TODATE | N8: TODAY | O8: TODATE | P8: TODAY | Q8: TODATE | R8: TODAY | S8: TODATE | T8: TODAY | U8: TODATE | V8: TODAY | W8: TODATE | X8: TODAY | Y8: TODATE | Z8: TODAY | AA8: TODATE | AB8: TODAY | AC8: TODATE | AD8: TODAY | AE8: TODATE | AF8: TODAY | AG8: TODATE | AH8: TODAY | AI8: TODATE | AJ8: TODAY | AK8: TODATE | AL8: 14 | AM8: 15 | AN8: 17 | AP8: PGN | AU8: 14 | AV8: 15 | AW8: 17 | AX8: 14 | AY8: 15 | AZ8: 17 | BA8: TODAY | BB8: TODATE | BC8: TODAY | BD8: TODATE
A9: 45870 | B9: Toilet | C9: 13 | D9: =+'1'!F42 -> 1230 | E9: =+'1'!G42 -> 947.1 | F9: =1-(E9/D9) -> 0.23 | G9: =+P9/N9 -> 0.95571827 | H9: =+P9/L9 -> 0.95571827 | I9: =+R9/P9 -> 0.97907023 | J9: =+R9/L9 -> 0.9357153 | K9: =+S9/M9 -> 0.9357153 | L9: =+Efficiency1!K6 -> 47.692925 | M9: =L9 -> 47.692925 | N9: =+Efficiency1!C6 -> 47.692925 | O9: =N9 -> 47.692925 | P9: ='1'!I38 -> 45.581 | Q9: =P9 -> 45.581 | R9: ='1'!I40 -> 44.627 | S9: =R9 -> 44.627 | T9: =+AX9 -> 4127.5496 | U9: =T9 -> 4127.5496 | V9: =T9/P9 -> 90.554168 | W9: =U9/Q9 -> 90.554168 | X9: =IF(AND(R9>0,T9>0),(T9/(R9*1000))*1000,0) -> 92.489962 | Y9: =IF(AND(S9>0,U9>0),U9/S9,0) -> 92.489962 | Z9: 59.5 | AA9: =Z9 -> 59.5 | AB9: =Z9/(P9) -> 1.3053685 | AC9: =AA9/(Q9) -> 1.3053685 | AD9: =IF(AND(R9>0,Z9>0),Z9/(R9),0) -> 1.3332736 | AE9: =IF(AND(S9>0,AA9>0),AA9/(S9),0) -> 1.3332736 | AF9: ='1'!I46 -> 37566.02 | AG9: =AF9 -> 37566.02 | AH9: =IF(AND(L9>0,AF9>0),(AF9/(P9*1000)*1000),0) -> 824.15963 | AI9: =IF(AND(M9>0,AG9>0),(AG9/(Q9*1000)*1000),0) -> 824.15963 | AJ9: =IF(AND(R9>0,AF9>0),(AF9/(R9*1000)*1000),0) -> 841.77785 | AK9: =IF(AND(S9>0,AG9>0),(AG9/(S9*1000)*1000),0) -> 841.77785 | AL9: 4353.7 | AM9: 5728.1 | AN9: 3888.9 | AO9: =SUM(AL9:AN9) -> 13970.7 | AP9: =+[1]Aug!N4 -> 13245 | AQ9: =+AP9-AO9 -> -725.7 | AR9: =+AL9/AO9 -> 0.31163077 | AS9: =+AM9/AO9 -> 0.41000809 | AT9: =1-AR9-AS9 -> 0.27836114 | AU9: =+AR9*AQ9 -> -226.15045 | AV9: =+AS9*AQ9 -> -297.54287 | AW9: =+AT9*AQ9 -> -202.00668 | AX9: =+AL9+AU9 -> 4127.5496 | AY9: =+AM9+AV9 -> 5430.5571 | AZ9: =+AN9+AW9 -> 3686.8933 | BA9: =+Efficiency2!K6 -> 47.692925 | BB9: =BA9 -> 47.692925 | BC9: =+R9/BA9 -> 0.9357153 | BD9: =+S9/BB9 -> 0.9357153
A10: =A9+1 -> 45871 | B10: Toilet | C10: 13 | D10: =+'2'!F42 -> 1230 | E10: =+'2'!G42 -> 947.1 | F10: =1-(E10/D10) -> 0.23 | G10: =+P10/N10 -> 0.99442422 | H10: =+P10/L10 -> 0.99442422 | I10: =+R10/P10 -> 0.96466148 | J10: =+R10/L10 -> 0.95928274 | K10: =+S10/M10 -> 0.94749902 | L10: =+Efficiency1!K11 -> 47.692925 | M10: =M9+L10 -> 95.385851 | N10: =+Efficiency1!C11 -> 47.692925 | O10: =O9+N10 -> 95.385851 | P10: ='2'!I38 -> 47.427 | Q10: =Q9+P10 -> 93.008 | R10: ='2'!I40 -> 45.751 | S10: =S9+R10 -> 90.378 | T10: =+AX10 -> 4040.0906 | U10: =T10+U9 -> 8167.6401 | V10: =T10/P10 -> 85.185455 | W10: =U10/Q10 -> 87.816533 | X10: =IF(AND(R10>0,T10>0),(T10/(R10*1000))*1000,0) -> 88.30606 | Y10: =IF(AND(S10>0,U10>0),U10/S10,0) -> 90.371994 | Z10: 60.7 | AA10: =Z10+AA9 -> 120.2 | AB10: =Z10/(P10) -> 1.2798617 | AC10: =AA10/(Q10) -> 1.2923619 | AD10: =IF(AND(R10>0,Z10>0),Z10/(R10),0) -> 1.326747 | AE10: =IF(AND(S10>0,AA10>0),AA10/(S10),0) -> 1.3299697 | AF10: ='2'!I46 -> 39041.46 | AG10: =AF10+AG9 -> 76607.48 | AH10: =IF(AND(L10>0,AF10>0),(AF10/(P10*1000)*1000),0) -> 823.19059 | AI10: =IF(AND(M10>0,AG10>0),(AG10/(Q10*1000)*1000),0) -> 823.66549 | AJ10: =IF(AND(R10>0,AF10>0),(AF10/(R10*1000)*1000),0) -> 853.34659 | AK10: =IF(AND(S10>0,AG10>0),(AG10/(S10*1000)*1000),0) -> 847.63416 | AL10: 4259.6 | AM10: 5714.8 | AN10: 3908 | AO10: =SUM(AL10:AN10) -> 13882.4 | AP10: =+[1]Aug!N5 -> 13167 | AQ10: =+AP10-AO10 -> -715.4 | AR10: =+AL10/AO10 -> 0.30683455 | AS10: =+AM10/AO10 -> 0.41165793 | AT10: =1-AR10-AS10 -> 0.28150752 | AU10: =+AR10*AQ10 -> -219.50944 | AV10: =+AS10*AQ10 -> -294.50008 | AW10: =+AT10*AQ10 -> -201.39048 | AX10: =+AL10+AU10 -> 4040.0906 | AY10: =+AM10+AV10 -> 5420.2999 | AZ10: =+AN10+AW10 -> 3706.6095 | BA10: =+Efficiency2!K11 -> 47.692925 | BB10: =BB9+BA10 -> 95.385851 | BC10: =+R10/BA10 -> 0.95928274 | BD10: =+S10/BB10 -> 0.94749902
A11: =A10+1 -> 45872 | B11: Toilet | C11: 13 | D11: =+'3'!F42 -> 1209.1675 | E11: =+'3'!G42 -> 931.05896 | F11: =1-(E11/D11) -> 0.23 | G11: =+P11/N11 -> 0.6190436 | H11: =+P11/L11 -> 0.6190436 | I11: =+R11/P11 -> 1.0154112 | J11: =+R11/L11 -> 0.6285838 | K11: =+S11/M11 -> 0.84119395 | L11: =+Efficiency1!K16 -> 47.692925 | M11: =M10+L11 -> 143.07878 | N11: =+Efficiency1!C16 -> 47.692925 | O11: =O10+N11 -> 143.07878 | P11: ='3'!I38 -> 29.524 | Q11: =Q10+P11 -> 122.532 | R11: ='3'!I40 -> 29.979 | S11: =S10+R11 -> 120.357 | T11: =+AX11 -> 2905.2292 | U11: =T11+U10 -> 11072.869 | V11: =T11/P11 -> 98.402289 | W11: =U11/Q11 -> 90.367164 | X11: =IF(AND(R11>0,T11>0),(T11/(R11*1000))*1000,0) -> 96.908809 | Y11: =IF(AND(S11>0,U11>0),U11/S11,0) -> 92.00021 | Z11: 47.3 | AA11: =Z11+AA10 -> 167.5 | AB11: =Z11/(P11) -> 1.6020864 | AC11: =AA11/(Q11) -> 1.3669898 | AD11: =IF(AND(R11>0,Z11>0),Z11/(R11),0) -> 1.5777711 | AE11: =IF(AND(S11>0,AA11>0),AA11/(S11),0) -> 1.391693 | AF11: ='3'!I46 -> 29073.5 | AG11: =AF11+AG10 -> 105680.98 | AH11: =IF(AND(L11>0,AF11>0),(AF11/(P11*1000)*1000),0) -> 984.74123 | AI11: =IF(AND(M11>0,AG11>0),(AG11/(Q11*1000)*1000),0) -> 862.47658 | AJ11: =IF(AND(R11>0,AF11>0),(AF11/(R11*1000)*1000),0) -> 969.79552 | AK11: =IF(AND(S11>0,AG11>0),(AG11/(S11*1000)*1000),0) -> 878.0626 | AL11: 3053.5 | AM11: 5703.1 | AN11: 4028.2 | AO11: =SUM(AL11:AN11) -> 12784.8 | AP11: =+[1]Aug!N6 -> 12164 | AQ11: =+AP11-AO11 -> -620.8 | AR11: =+AL11/AO11 -> 0.23883831 | AS11: =+AM11/AO11 -> 0.44608441 | AT11: =1-AR11-AS11 -> 0.31507728 | AU11: =+AR11*AQ11 -> -148.27082 | AV11: =+AS11*AQ11 -> -276.9292 | AW11: =+AT11*AQ11 -> -195.59997 | AX11: =+AL11+AU11 -> 2905.2292 | AY11: =+AM11+AV11 -> 5426.1708 | AZ11: =+AN11+AW11 -> 3832.6 | BA11: =+Efficiency2!K16 -> 47.692925 | BB11: =BB10+BA11 -> 143.07878 | BC11: =+R11/BA11 -> 0.6285838 | BD11: =+S11/BB11 -> 0.84119395
A12: =A11+1 -> 45873 | B12: Toilet | C12: 13 | D12: =+'4'!F42 -> 1224.3264 | E12: =+'4'!G42 -> 942.73132 | F12: =1-(E12/D12) -> 0.23 | G12: =+P12/N12 -> 0.95231109 | H12: =+P12/L12 -> 0.94791837 | I12: =+R12/P12 -> 0.97823442 | J12: =+R12/L12 -> 0.92728638 | K12: =+S12/M12 -> 0.86271705 | L12: =+Efficiency1!K23 -> 47.692925 | M12: =M11+L12 -> 190.7717 | N12: =+Efficiency1!C23 -> 47.472933 | O12: =O11+N12 -> 190.55171 | P12: ='4'!I38 -> 45.209 | Q12: =Q11+P12 -> 167.741 | R12: ='4'!I40 -> 44.225 | S12: =S11+R12 -> 164.582 | T12: =+AX12 -> 4264.5633 | U12: =T12+U11 -> 15337.433 | V12: =T12/P12 -> 94.329962 | W12: =U12/Q12 -> 91.435204 | X12: =IF(AND(R12>0,T12>0),(T12/(R12*1000))*1000,0) -> 96.42879 | Y12: =IF(AND(S12>0,U12>0),U12/S12,0) -> 93.190218 | Z12: 59.3 | AA12: =Z12+AA11 -> 226.8 | AB12: =Z12/(P12) -> 1.3116857 | AC12: =AA12/(Q12) -> 1.3520845 | AD12: =IF(AND(R12>0,Z12>0),Z12/(R12),0) -> 1.3408705 | AE12: =IF(AND(S12>0,AA12>0),AA12/(S12),0) -> 1.3780365 | AF12: ='4'!I46 -> 36624.46 | AG12: =AF12+AG11 -> 142305.44 | AH12: =IF(AND(L12>0,AF12>0),(AF12/(P12*1000)*1000),0) -> 810.11436 | AI12: =IF(AND(M12>0,AG12>0),(AG12/(Q12*1000)*1000),0) -> 848.36409 | AJ12: =IF(AND(R12>0,AF12>0),(AF12/(R12*1000)*1000),0) -> 828.13929 | AK12: =IF(AND(S12>0,AG12>0),(AG12/(S12*1000)*1000),0) -> 864.64765 | AL12: 4492.2 | AM12: 5688.4 | AN12: 4067.4 | AO12: =SUM(AL12:AN12) -> 14248 | AP12: =+[1]Aug!N7 -> 13526 | AQ12: =+AP12-AO12 -> -722 | AR12: =+AL12/AO12 -> 0.31528636 | AS12: =+AM12/AO12 -> 0.399242 | AT12: =1-AR12-AS12 -> 0.28547165 | AU12: =+AR12*AQ12 -> -227.63675 | AV12: =+AS12*AQ12 -> -288.25272 | AW12: =+AT12*AQ12 -> -206.11053 | AX12: =+AL12+AU12 -> 4264.5633 | AY12: =+AM12+AV12 -> 5400.1473 | AZ12: =+AN12+AW12 -> 3861.2895 | BA12: =+Efficiency2!K23 -> 47.692925 | BB12: =BB11+BA12 -> 190.7717 | BC12: =+R12/BA12 -> 0.92728638 | BD12: =+S12/BB12 -> 0.86271705
A13: =A12+1 -> 45874 | B13: Toilet | C13: 13 | D13: =+'5'!F42 -> 1230 | E13: =+'5'!G42 -> 947.1 | F13: =1-(E13/D13) -> 0.23 | G13: =+P13/N13 -> 0.96509073 | H13: =+P13/L13 -> 0.96509073 | I13: =+R13/P13 -> 0.92943426 | J13: =+R13/L13 -> 0.89698838 | K13: =+S13/M13 -> 0.86957132 | L13: =+Efficiency1!K28 -> 47.692925 | M13: =M12+L13 -> 238.46463 | N13: =+Efficiency1!C28 -> 47.692925 | O13: =O12+N13 -> 238.24463 | P13: ='5'!I38 -> 46.028 | Q13: =Q12+P13 -> 213.769 | R13: ='5'!I40 -> 42.78 | S13: =S12+R13 -> 207.362 | T13: =+AX13 -> 4143.047 | U13: =T13+U12 -> 19480.48 | V13: =T13/P13 -> 90.011449 | W13: =U13/Q13 -> 91.128646 | X13: =IF(AND(R13>0,T13>0),(T13/(R13*1000))*1000,0) -> 96.845417 | Y13: =IF(AND(S13>0,U13>0),U13/S13,0) -> 93.944308 | Z13: 55.5 | AA13: =Z13+AA12 -> 282.3 | AB13: =Z13/(P13) -> 1.2057878 | AC13: =AA13/(Q13) -> 1.3205844 | AD13: =IF(AND(R13>0,Z13>0),Z13/(R13),0) -> 1.2973352 | AE13: =IF(AND(S13>0,AA13>0),AA13/(S13),0) -> 1.3613873 | AF13: ='5'!I46 -> 36297.9 | AG13: =AF13+AG12 -> 178603.34 | AH13: =IF(AND(L13>0,AF13>0),(AF13/(P13*1000)*1000),0) -> 788.60476 | AI13: =IF(AND(M13>0,AG13>0),(AG13/(Q13*1000)*1000),0) -> 835.49691 | AJ13: =IF(AND(R13>0,AF13>0),(AF13/(R13*1000)*1000),0) -> 848.47826 | AK13: =IF(AND(S13>0,AG13>0),(AG13/(S13*1000)*1000),0) -> 861.31181 | AL13: 4347.9 | AM13: 5768.9 | AN13: 4065.4 | AO13: =SUM(AL13:AN13) -> 14182.2 | AP13: =+[1]Aug!N8 -> 13514 | AQ13: =+AP13-AO13 -> -668.2 | AR13: =+AL13/AO13 -> 0.30657444 | AS13: =+AM13/AO13 -> 0.40677046 | AT13: =1-AR13-AS13 -> 0.2866551 | AU13: =+AR13*AQ13 -> -204.85304 | AV13: =+AS13*AQ13 -> -271.80402 | AW13: =+AT13*AQ13 -> -191.54294 | AX13: =+AL13+AU13 -> 4143.047 | AY13: =+AM13+AV13 -> 5497.096 | AZ13: =+AN13+AW13 -> 3873.8571 | BA13: =+Efficiency2!K28 -> 47.692925 | BB13: =BB12+BA13 -> 238.46463 | BC13: =+R13/BA13 -> 0.89698838 | BD13: =+S13/BB13 -> 0.86957132
A14: =A13+1 -> 45875 | B14: Toilet | C14: 13/15,5 | D14: =+'6'!F42 -> 1213.3333 | E14: =+'6'!G42 -> 942.13333 | F14: =1-(E14/D14) -> 0.22351648 | G14: =+P14/N14 -> 0.94998438 | H14: =+P14/L14 -> 0.94998438 | I14: =+R14/P14 -> 0.937089 | J14: =+R14/L14 -> 0.89021991 | K14: =+S14/M14 -> 0.87303251 | L14: =+SUM(Efficiency1!K33:K34) -> 48.021842 | M14: =M13+L14 -> 286.48647 | N14: =+SUM(Efficiency1!C33:C34) -> 48.021842 | O14: =O13+N14 -> 286.26648 | P14: ='6'!I38 -> 45.62 | Q14: =Q13+P14 -> 259.389 | R14: ='6'!I40 -> 42.75 | S14: =S13+R14 -> 250.112 | T14: =+AX14 -> 4058.9853 | U14: =T14+U13 -> 23539.465 | V14: =T14/P14 -> 88.973812 | W14: =U14/Q14 -> 90.749665 | X14: =IF(AND(R14>0,T14>0),(T14/(R14*1000))*1000,0) -> 94.947025 | Y14: =IF(AND(S14>0,U14>0),U14/S14,0) -> 94.115695 | Z14: 57.9 | AA14: =Z14+AA13 -> 340.2 | AB14: =Z14/(P14) -> 1.2691802 | AC14: =AA14/(Q14) -> 1.3115437 | AD14: =IF(AND(R14>0,Z14>0),Z14/(R14),0) -> 1.354386 | AE14: =IF(AND(S14>0,AA14>0),AA14/(S14),0) -> 1.3601906 | AF14: ='6'!I46 -> 39098.98 | AG14: =AF14+AG13 -> 217702.32 | AH14: =IF(AND(L14>0,AF14>0),(AF14/(P14*1000)*1000),0) -> 857.05787 | AI14: =IF(AND(M14>0,AG14>0),(AG14/(Q14*1000)*1000),0) -> 839.28894 | AJ14: =IF(AND(R14>0,AF14>0),(AF14/(R14*1000)*1000),0) -> 914.59602 | AK14: =IF(AND(S14>0,AG14>0),(AG14/(S14*1000)*1000),0) -> 870.41933 | AL14: 4268.5 | AM14: 5830 | AN14: 3912.2 | AO14: =SUM(AL14:AN14) -> 14010.7 | AP14: =+[1]Aug!N9 -> 13323 | AQ14: =+AP14-AO14 -> -687.7 | AR14: =+AL14/AO14 -> 0.30466001 | AS14: =+AM14/AO14 -> 0.41611054 | AT14: =1-AR14-AS14 -> 0.27922945 | AU14: =+AR14*AQ14 -> -209.51469 | AV14: =+AS14*AQ14 -> -286.15922 | AW14: =+AT14*AQ14 -> -192.02609 | AX14: =+AL14+AU14 -> 4058.9853 | AY14: =+AM14+AV14 -> 5543.8408 | AZ14: =+AN14+AW14 -> 3720.1739 | BA14: =+SUM(Efficiency2!K33:K34) -> 48.021842 | BB14: =BB13+BA14 -> 286.48647 | BC14: =+R14/BA14 -> 0.89021991 | BD14: =+S14/BB14 -> 0.87303251
A15: =A14+1 -> 45876 | B15: Toilet | C15: 15,5 | D15: =+'7'!F42 -> 1176.6667 | E15: =+'7'!G42 -> 929.56667 | F15: =1-(E15/D15) -> 0.21 | G15: =+P15/N15 -> 0.93258559 | H15: =+P15/L15 -> 0.93258559 | I15: =+R15/P15 -> 0.98919934 | J15: =+R15/L15 -> 0.92251305 | K15: =+S15/M15 -> 0.88077142 | L15: =+Efficiency1!K38 -> 53.114696 | M15: =M14+L15 -> 339.60116 | N15: =+Efficiency1!C38 -> 53.114696 | O15: =O14+N15 -> 339.38117 | P15: ='7'!I38 -> 49.534 | Q15: =Q14+P15 -> 308.923 | R15: ='7'!I40 -> 48.999 | S15: =S14+R15 -> 299.111 | T15: =+AX15 -> 4697.9637 | U15: =T15+U14 -> 28237.429 | V15: =T15/P15 -> 94.843213 | W15: =U15/Q15 -> 91.406041 | X15: =IF(AND(R15>0,T15>0),(T15/(R15*1000))*1000,0) -> 95.878767 | Y15: =IF(AND(S15>0,U15>0),U15/S15,0) -> 94.404514 | Z15: 61.7 | AA15: =Z15+AA14 -> 401.9 | AB15: =Z15/(P15) -> 1.2456091 | AC15: =AA15/(Q15) -> 1.3009714 | AD15: =IF(AND(R15>0,Z15>0),Z15/(R15),0) -> 1.2592094 | AE15: =IF(AND(S15>0,AA15>0),AA15/(S15),0) -> 1.3436483 | AF15: ='7'!I46 -> 35759.34 | AG15: =AF15+AG14 -> 253461.66 | AH15: =IF(AND(L15>0,AF15>0),(AF15/(P15*1000)*1000),0) -> 721.91505 | AI15: =IF(AND(M15>0,AG15>0),(AG15/(Q15*1000)*1000),0) -> 820.46873 | AJ15: =IF(AND(R15>0,AF15>0),(AF15/(R15*1000)*1000),0) -> 729.79734 | AK15: =IF(AND(S15>0,AG15>0),(AG15/(S15*1000)*1000),0) -> 847.38328 | AL15: 4855.8 | AM15: 5240.2 | AN15: 3637.4 | AO15: =SUM(AL15:AN15) -> 13733.4 | AP15: =+[1]Aug!N10 -> 13287 | AQ15: =+AP15-AO15 -> -446.4 | AR15: =+AL15/AO15 -> 0.35357595 | AS15: =+AM15/AO15 -> 0.38156611 | AT15: =1-AR15-AS15 -> 0.26485794 | AU15: =+AR15*AQ15 -> -157.83631 | AV15: =+AS15*AQ15 -> -170.33111 | AW15: =+AT15*AQ15 -> -118.23258 | AX15: =+AL15+AU15 -> 4697.9637 | AY15: =+AM15+AV15 -> 5069.8689 | AZ15: =+AN15+AW15 -> 3519.1674 | BA15: =+Efficiency2!K38 -> 53.114696 | BB15: =BB14+BA15 -> 339.60116 | BC15: =+R15/BA15 -> 0.92251305 | BD15: =+S15/BB15 -> 0.88077142
A16: =A15+1 -> 45877 | B16: Toilet/Facial | C16: 15,5/19/15 | D16: =+'8'!F42 -> 1106.6632 | E16: =+'8'!G42 -> 859.44222 | F16: =1-(E16/D16) -> 0.22339315 | G16: =+P16/N16 -> 0.94575278 | H16: =+P16/L16 -> 0.92281083 | I16: =+R16/P16 -> 0.89585934 | J16: =+R16/L16 -> 0.82670871 | K16: =+S16/M16 -> 0.87347982 | L16: =+SUM(Efficiency1!K43:K45) -> 52.943678 | M16: =M15+L16 -> 392.54484 | N16: =+SUM(Efficiency1!C43:C45) -> 51.659377 | O16: =O15+N16 -> 391.04055 | P16: ='8'!I38 -> 48.857 | Q16: =Q15+P16 -> 357.78 | R16: ='8'!I40 -> 43.769 | S16: =S15+R16 -> 342.88 | T16: =+AX16 -> 4524.3758 | U16: =T16+U15 -> 32761.804 | V16: =T16/P16 -> 92.604453 | W16: =U16/Q16 -> 91.569692 | X16: =IF(AND(R16>0,T16>0),(T16/(R16*1000))*1000,0) -> 103.36941 | Y16: =IF(AND(S16>0,U16>0),U16/S16,0) -> 95.548893 | Z16: 56.9 | AA16: =Z16+AA15 -> 458.8 | AB16: =Z16/(P16) -> 1.1646233 | AC16: =AA16/(Q16) -> 1.2823523 | AD16: =IF(AND(R16>0,Z16>0),Z16/(R16),0) -> 1.3000069 | AE16: =IF(AND(S16>0,AA16>0),AA16/(S16),0) -> 1.3380775 | AF16: ='8'!I46 -> 35500.54 | AG16: =AF16+AG15 -> 288962.2 | AH16: =IF(AND(L16>0,AF16>0),(AF16/(P16*1000)*1000),0) -> 726.62136 | AI16: =IF(AND(M16>0,AG16>0),(AG16/(Q16*1000)*1000),0) -> 807.65331 | AJ16: =IF(AND(R16>0,AF16>0),(AF16/(R16*1000)*1000),0) -> 811.08867 | AK16: =IF(AND(S16>0,AG16>0),(AG16/(S16*1000)*1000),0) -> 842.75023 | AL16: 4886.1 | AM16: 1910.8 | AN16: 991.7 | AO16: =SUM(AL16:AN16) -> 7788.6 | AP16: =+[1]Aug!N11 -> 7212 | AQ16: =+AP16-AO16 -> -576.6 | AR16: =+AL16/AO16 -> 0.62733996 | AS16: =+AM16/AO16 -> 0.24533292 | AT16: =1-AR16-AS16 -> 0.12732712 | AU16: =+AR16*AQ16 -> -361.72422 | AV16: =+AS16*AQ16 -> -141.45896 | AW16: =+AT16*AQ16 -> -73.416817 | AX16: =+AL16+AU16 -> 4524.3758 | AY16: =+AM16+AV16 -> 1769.341 | AZ16: =+AN16+AW16 -> 918.28318 | BA16: =+SUM(Efficiency2!K43:K45) -> 52.943678 | BB16: =BB15+BA16 -> 392.54484 | BC16: =+R16/BA16 -> 0.82670871 | BD16: =+S16/BB16 -> 0.87347982
A17: =A16+1 -> 45878 | B17: Facial | C17: 15/13,5/13/12 | D17: =+'9'!F42 -> 1217.6389 | E17: =+'9'!G42 -> 937.63604 | F17: =1-(E17/D17) -> 0.22995557 | G17: =+P17/N17 -> 0.91497456 | H17: =+P17/L17 -> 0.89951138 | I17: =+R17/P17 -> 1.0638794 | J17: =+R17/L17 -> 0.9569716 | K17: =+S17/M17 -> 0.88236428 | L17: =+SUM(Efficiency1!K48:K51) -> 46.745379 | M17: =M16+L17 -> 439.29022 | N17: =+SUM(Efficiency1!C48:C51) -> 45.955376 | O17: =O16+N17 -> 436.99593 | P17: ='9'!I38 -> 42.048 | Q17: =Q16+P17 -> 399.828 | R17: ='9'!I40 -> 44.734 | S17: =S16+R17 -> 387.614 | T17: =+AX17 -> 4194.3675 | U17: =T17+U16 -> 36956.172 | V17: =T17/P17 -> 99.751891 | W17: =U17/Q17 -> 92.430174 | X17: =IF(AND(R17>0,T17>0),(T17/(R17*1000))*1000,0) -> 93.762407 | Y17: =IF(AND(S17>0,U17>0),U17/S17,0) -> 95.342717 | Z17: 54.1 | AA17: =Z17+AA16 -> 512.9 | AB17: =Z17/(P17) -> 1.2866248 | AC17: =AA17/(Q17) -> 1.2828016 | AD17: =IF(AND(R17>0,Z17>0),Z17/(R17),0) -> 1.2093709 | AE17: =IF(AND(S17>0,AA17>0),AA17/(S17),0) -> 1.3232236 | AF17: ='9'!I46 -> 38913.42 | AG17: =AF17+AG16 -> 327875.62 | AH17: =IF(AND(L17>0,AF17>0),(AF17/(P17*1000)*1000),0) -> 925.45234 | AI17: =IF(AND(M17>0,AG17>0),(AG17/(Q17*1000)*1000),0) -> 820.04167 | AJ17: =IF(AND(R17>0,AF17>0),(AF17/(R17*1000)*1000),0) -> 869.88465 | AK17: =IF(AND(S17>0,AG17>0),(AG17/(S17*1000)*1000),0) -> 845.88178 | AL17: 4372.6 | AM17: 5399.8 | AN17: 4226.2 | AO17: =SUM(AL17:AN17) -> 13998.6 | AP17: =+[1]Aug!N12 -> 13428 | AQ17: =+AP17-AO17 -> -570.6 | AR17: =+AL17/AO17 -> 0.31235981 | AS17: =+AM17/AO17 -> 0.38573857 | AT17: =1-AR17-AS17 -> 0.30190162 | AU17: =+AR17*AQ17 -> -178.23251 | AV17: =+AS17*AQ17 -> -220.10243 | AW17: =+AT17*AQ17 -> -172.26506 | AX17: =+AL17+AU17 -> 4194.3675 | AY17: =+AM17+AV17 -> 5179.6976 | AZ17: =+AN17+AW17 -> 4053.9349 | BA17: =+SUM(Efficiency2!K48:K51) -> 46.745379 | BB17: =BB16+BA17 -> 439.29022 | BC17: =+R17/BA17 -> 0.9569716 | BD17: =+S17/BB17 -> 0.88236428
A18: =A17+1 -> 45879 | B18: Facial | C18: 12 | D18: =+'10'!F42 -> 1230 | E18: =+'10'!G42 -> 947.1 | F18: =1-(E18/D18) -> 0.23 | G18: =+P18/N18 -> 0.96407089 | H18: =+P18/L18 -> 0.96407089 | I18: =+R18/P18 -> 0.94499842 | J18: =+R18/L18 -> 0.91104547 | K18: =+S18/M18 -> 0.88490805 | L18: =+Efficiency1!K54 -> 42.75308 | M18: =M17+L18 -> 482.0433 | N18: =+Efficiency1!C54 -> 42.75308 | O18: =O17+N18 -> 479.74901 | P18: ='10'!I38 -> 41.217 | Q18: =Q17+P18 -> 441.045 | R18: ='10'!I40 -> 38.95 | S18: =S17+R18 -> 426.564 | T18: =+AX18 -> 3959.0462 | U18: =T18+U17 -> 40915.218 | V18: =T18/P18 -> 96.053721 | W18: =U18/Q18 -> 92.768806 | X18: =IF(AND(R18>0,T18>0),(T18/(R18*1000))*1000,0) -> 101.64432 | Y18: =IF(AND(S18>0,U18>0),U18/S18,0) -> 95.918123 | Z18: 51.6 | AA18: =Z18+AA17 -> 564.5 | AB18: =Z18/(P18) -> 1.2519106 | AC18: =AA18/(Q18) -> 1.2799147 | AD18: =IF(AND(R18>0,Z18>0),Z18/(R18),0) -> 1.3247754 | AE18: =IF(AND(S18>0,AA18>0),AA18/(S18),0) -> 1.3233653 | AF18: ='10'!I46 -> 36702.54 | AG18: =AF18+AG17 -> 364578.16 | AH18: =IF(AND(L18>0,AF18>0),(AF18/(P18*1000)*1000),0) -> 890.47092 | AI18: =IF(AND(M18>0,AG18>0),(AG18/(Q18*1000)*1000),0) -> 826.6235 | AJ18: =IF(AND(R18>0,AF18>0),(AF18/(R18*1000)*1000),0) -> 942.29884 | AK18: =IF(AND(S18>0,AG18>0),(AG18/(S18*1000)*1000),0) -> 854.68572 | AL18: 4220.2 | AM18: 5311.4 | AN18: 4370.7 | AO18: =SUM(AL18:AN18) -> 13902.3 | AP18: =+[1]Aug!N13 -> 13042 | AQ18: =+AP18-AO18 -> -860.3 | AR18: =+AL18/AO18 -> 0.30356128 | AS18: =+AM18/AO18 -> 0.38205189 | AT18: =1-AR18-AS18 -> 0.31438683 | AU18: =+AR18*AQ18 -> -261.15377 | AV18: =+AS18*AQ18 -> -328.67924 | AW18: =+AT18*AQ18 -> -270.46699 | AX18: =+AL18+AU18 -> 3959.0462 | AY18: =+AM18+AV18 -> 4982.7208 | AZ18: =+AN18+AW18 -> 4100.233 | BA18: =+Efficiency2!K54 -> 42.75308 | BB18: =BB17+BA18 -> 482.0433 | BC18: =+R18/BA18 -> 0.91104547 | BD18: =+S18/BB18 -> 0.88490805
A19: =A18+1 -> 45880 | B19: Facial | C19: 12/13 | D19: =+'11'!F42 -> 1230 | E19: =+'11'!G42 -> 947.1 | F19: =1-(E19/D19) -> 0.23 | G19: =+P19/N19 -> 0.88078763 | H19: =+P19/L19 -> 0.87655348 | I19: =+R19/P19 -> 1.0339566 | J19: =+R19/L19 -> 0.90631825 | K19: =+S19/M19 -> 0.88672809 | L19: =+SUM(Efficiency1!K59:K60) -> 44.784489 | M19: =M18+L19 -> 526.82779 | N19: =+SUM(Efficiency1!C59:C60) -> 44.5692 | O19: =O18+N19 -> 524.31821 | P19: ='11'!I38 -> 39.256 | Q19: =Q18+P19 -> 480.301 | R19: ='11'!I40 -> 40.589 | S19: =S18+R19 -> 467.153 | T19: =+AX19 -> 3997.9468 | U19: =T19+U18 -> 44913.165 | V19: =T19/P19 -> 101.84295 | W19: =U19/Q19 -> 93.510454 | X19: =IF(AND(R19>0,T19>0),(T19/(R19*1000))*1000,0) -> 98.498282 | Y19: =IF(AND(S19>0,U19>0),U19/S19,0) -> 96.142302 | Z19: 52.6 | AA19: =Z19+AA18 -> 617.1 | AB19: =Z19/(P19) -> 1.3399226 | AC19: =AA19/(Q19) -> 1.2848193 | AD19: =IF(AND(R19>0,Z19>0),Z19/(R19),0) -> 1.2959176 | AE19: =IF(AND(S19>0,AA19>0),AA19/(S19),0) -> 1.3209805 | AF19: ='11'!I46 -> 39128.22 | AG19: =AF19+AG18 -> 403706.38 | AH19: =IF(AND(L19>0,AF19>0),(AF19/(P19*1000)*1000),0) -> 996.74496 | AI19: =IF(AND(M19>0,AG19>0),(AG19/(Q19*1000)*1000),0) -> 840.52788 | AJ19: =IF(AND(R19>0,AF19>0),(AF19/(R19*1000)*1000),0) -> 964.01045 | AK19: =IF(AND(S19>0,AG19>0),(AG19/(S19*1000)*1000),0) -> 864.1845 | AL19: 4204 | AM19: 5216.3 | AN19: 3657.7 | AO19: =SUM(AL19:AN19) -> 13078 | AP19: =+[1]Aug!N14 -> 12437 | AQ19: =+AP19-AO19 -> -641 | AR19: =+AL19/AO19 -> 0.32145588 | AS19: =+AM19/AO19 -> 0.39886068 | AT19: =1-AR19-AS19 -> 0.27968344 | AU19: =+AR19*AQ19 -> -206.05322 | AV19: =+AS19*AQ19 -> -255.6697 | AW19: =+AT19*AQ19 -> -179.27708 | AX19: =+AL19+AU19 -> 3997.9468 | AY19: =+AM19+AV19 -> 4960.6303 | AZ19: =+AN19+AW19 -> 3478.4229 | BA19: =+SUM(Efficiency2!K59:K60) -> 44.784489 | BB19: =BB18+BA19 -> 526.82779 | BC19: =+R19/BA19 -> 0.90631825 | BD19: =+S19/BB19 -> 0.88672809
A20: =A19+1 -> 45881 | B20: Facial | C20: 13/12 | D20: =+'12'!F42 -> 1230 | E20: =+'12'!G42 -> 947.1 | F20: =1-(E20/D20) -> 0.23 | G20: =+P20/N20 -> 0.96777003 | H20: =+P20/L20 -> 0.9630504 | I20: =+R20/P20 -> 0.95148565 | J20: =+R20/L20 -> 0.91632864 | K20: =+S20/M20 -> 0.88905804 | L20: =+SUM(Efficiency1!K64:K66) -> 45.011144 | M20: =M19+L20 -> 571.83893 | N20: =+SUM(Efficiency1!C64:C66) -> 44.791633 | O20: =O19+N20 -> 569.10984 | P20: ='12'!I38 -> 43.348 | Q20: =Q19+P20 -> 523.649 | R20: ='12'!I40 -> 41.245 | S20: =S19+R20 -> 508.398 | T20: =+AX20 -> 3796.7779 | U20: =T20+U19 -> 48709.943 | V20: =T20/P20 -> 87.588306 | W20: =U20/Q20 -> 93.020215 | X20: =IF(AND(R20>0,T20>0),(T20/(R20*1000))*1000,0) -> 92.054258 | Y20: =IF(AND(S20>0,U20>0),U20/S20,0) -> 95.81065 | Z20: 54.7 | AA20: =Z20+AA19 -> 671.8 | AB20: =Z20/(P20) -> 1.2618806 | AC20: =AA20/(Q20) -> 1.2829204 | AD20: =IF(AND(R20>0,Z20>0),Z20/(R20),0) -> 1.3262214 | AE20: =IF(AND(S20>0,AA20>0),AA20/(S20),0) -> 1.3214057 | AF20: ='12'!I46 -> 39363.52 | AG20: =AF20+AG19 -> 443069.9 | AH20: =IF(AND(L20>0,AF20>0),(AF20/(P20*1000)*1000),0) -> 908.08157 | AI20: =IF(AND(M20>0,AG20>0),(AG20/(Q20*1000)*1000),0) -> 846.12002 | AJ20: =IF(AND(R20>0,AF20>0),(AF20/(R20*1000)*1000),0) -> 954.38283 | AK20: =IF(AND(S20>0,AG20>0),(AG20/(S20*1000)*1000),0) -> 871.50205 | AL20: 4062.5 | AM20: 5115.8 | AN20: 4015.7 | AO20: =SUM(AL20:AN20) -> 13194 | AP20: =+[1]Aug!N15 -> 12331 | AQ20: =+AP20-AO20 -> -863 | AR20: =+AL20/AO20 -> 0.30790511 | AS20: =+AM20/AO20 -> 0.38773685 | AT20: =1-AR20-AS20 -> 0.30435804 | AU20: =+AR20*AQ20 -> -265.72211 | AV20: =+AS20*AQ20 -> -334.6169 | AW20: =+AT20*AQ20 -> -262.66099 | AX20: =+AL20+AU20 -> 3796.7779 | AY20: =+AM20+AV20 -> 4781.1831 | AZ20: =+AN20+AW20 -> 3753.039 | BA20: =+SUM(Efficiency2!K64:K66) -> 45.011144 | BB20: =BB19+BA20 -> 571.83893 | BC20: =+R20/BA20 -> 0.91632864 | BD20: =+S20/BB20 -> 0.88905804
A21: =A20+1 -> 45882 | B21: Facial | C21: 13/12 | D21: =+'13'!F42 -> 1230 | E21: =+'13'!G42 -> 947.1 | F21: =1-(E21/D21) -> 0.23 | G21: =+P21/N21 -> 0.96215226 | H21: =+P21/L21 -> 0.95108692 | I21: =+R21/P21 -> 0.99888106 | J21: =+R21/L21 -> 0.95002271 | K21: =+S21/M21 -> 0.89368668 | L21: =+SUM(Efficiency1!K69:K70) -> 46.983087 | M21: =M20+L21 -> 618.82202 | N21: =+SUM(Efficiency1!C69:C70) -> 46.442753 | O21: =O20+N21 -> 615.55259 | P21: ='13'!I38 -> 44.685 | Q21: =Q20+P21 -> 568.334 | R21: ='13'!I40 -> 44.635 | S21: =S20+R21 -> 553.033 | T21: =+AX21 -> 3793.2205 | U21: =T21+U20 -> 52503.163 | V21: =T21/P21 -> 84.888005 | W21: =U21/Q21 -> 92.380824 | X21: =IF(AND(R21>0,T21>0),(T21/(R21*1000))*1000,0) -> 84.983097 | Y21: =IF(AND(S21>0,U21>0),U21/S21,0) -> 94.936764 | Z21: 57.2 | AA21: =Z21+AA20 -> 729 | AB21: =Z21/(P21) -> 1.2800716 | AC21: =AA21/(Q21) -> 1.2826964 | AD21: =IF(AND(R21>0,Z21>0),Z21/(R21),0) -> 1.2815055 | AE21: =IF(AND(S21>0,AA21>0),AA21/(S21),0) -> 1.3181854 | AF21: ='13'!I46 -> 37563.82 | AG21: =AF21+AG20 -> 480633.72 | AH21: =IF(AND(L21>0,AF21>0),(AF21/(P21*1000)*1000),0) -> 840.63601 | AI21: =IF(AND(M21>0,AG21>0),(AG21/(Q21*1000)*1000),0) -> 845.68884 | AJ21: =IF(AND(R21>0,AF21>0),(AF21/(R21*1000)*1000),0) -> 841.57769 | AK21: =IF(AND(S21>0,AG21>0),(AG21/(S21*1000)*1000),0) -> 869.08687 | AL21: 4190.3 | AM21: 4609 | AN21: 4132.1 | AO21: =SUM(AL21:AN21) -> 12931.4 | AP21: =+[1]Aug!N16 -> 11706 | AQ21: =+AP21-AO21 -> -1225.4 | AR21: =+AL21/AO21 -> 0.32404071 | AS21: =+AM21/AO21 -> 0.35641926 | AT21: =1-AR21-AS21 -> 0.31954003 | AU21: =+AR21*AQ21 -> -397.07948 | AV21: =+AS21*AQ21 -> -436.75616 | AW21: =+AT21*AQ21 -> -391.56436 | AX21: =+AL21+AU21 -> 3793.2205 | AY21: =+AM21+AV21 -> 4172.2438 | AZ21: =+AN21+AW21 -> 3740.5356 | BA21: =+SUM(Efficiency2!K69:K70) -> 46.983087 | BB21: =BB20+BA21 -> 618.82202 | BC21: =+R21/BA21 -> 0.95002271 | BD21: =+S21/BB21 -> 0.89368668
A22: =A21+1 -> 45883 | B22: Facial | C22: 13/12,5 | D22: =+'14'!F42 -> 1230 | E22: =+'14'!G42 -> 947.1 | F22: =1-(E22/D22) -> 0.23 | G22: =+P22/N22 -> 0.9610295 | H22: =+P22/L22 -> 0.94870861 | I22: =+R22/P22 -> 0.96228315 | J22: =+R22/L22 -> 0.91292631 | K22: =+S22/M22 -> 0.89501942 | L22: =+SUM(Efficiency1!K74:K75) -> 46.056291 | M22: =M21+L22 -> 664.87831 | N22: =+SUM(Efficiency1!C74:C75) -> 45.465826 | O22: =O21+N22 -> 661.01842 | P22: ='14'!I38 -> 43.694 | Q22: =Q21+P22 -> 612.028 | R22: ='14'!I40 -> 42.046 | S22: =S21+R22 -> 595.079 | T22: =+AX22 -> 4189.5462 | U22: =T22+U21 -> 56692.709 | V22: =T22/P22 -> 95.883788 | W22: =U22/Q22 -> 92.630908 | X22: =IF(AND(R22>0,T22>0),(T22/(R22*1000))*1000,0) -> 99.641969 | Y22: =IF(AND(S22>0,U22>0),U22/S22,0) -> 95.269215 | Z22: 57.5 | AA22: =Z22+AA21 -> 786.5 | AB22: =Z22/(P22) -> 1.3159702 | AC22: =AA22/(Q22) -> 1.2850719 | AD22: =IF(AND(R22>0,Z22>0),Z22/(R22),0) -> 1.3675498 | AE22: =IF(AND(S22>0,AA22>0),AA22/(S22),0) -> 1.3216733 | AF22: ='14'!I46 -> 38432.16 | AG22: =AF22+AG21 -> 519065.88 | AH22: =IF(AND(L22>0,AF22>0),(AF22/(P22*1000)*1000),0) -> 879.57523 | AI22: =IF(AND(M22>0,AG22>0),(AG22/(Q22*1000)*1000),0) -> 848.10806 | AJ22: =IF(AND(R22>0,AF22>0),(AF22/(R22*1000)*1000),0) -> 914.05033 | AK22: =IF(AND(S22>0,AG22>0),(AG22/(S22*1000)*1000),0) -> 872.26382 | AL22: 4165.6 | AM22: 3656.9 | AN22: 4180.5 | AO22: =SUM(AL22:AN22) -> 12003 | AP22: =+[1]Aug!N17 -> 12072 | AQ22: =+AP22-AO22 -> 69 | AR22: =+AL22/AO22 -> 0.34704657 | AS22: =+AM22/AO22 -> 0.3046655 | AT22: =1-AR22-AS22 -> 0.34828793 | AU22: =+AR22*AQ22 -> 23.946213 | AV22: =+AS22*AQ22 -> 21.02192 | AW22: =+AT22*AQ22 -> 24.031867 | AX22: =+AL22+AU22 -> 4189.5462 | AY22: =+AM22+AV22 -> 3677.9219 | AZ22: =+AN22+AW22 -> 4204.5319 | BA22: =+SUM(Efficiency2!K74:K75) -> 46.056291 | BB22: =BB21+BA22 -> 664.87831 | BC22: =+R22/BA22 -> 0.91292631 | BD22: =+S22/BB22 -> 0.89501942
A23: =A22+1 -> 45884 | B23: Facial | C23: 13,5 | D23: =+'15'!F42 -> 1230 | E23: =+'15'!G42 -> 947.1 | F23: =1-(E23/D23) -> 0.23 | G23: =+P23/N23 -> 0.94360542 | H23: =+P23/L23 -> 0.93150792 | I23: =+R23/P23 -> 0.97212905 | J23: =+R23/L23 -> 0.90554591 | K23: =+S23/M23 -> 0.89575033 | L23: =+Efficiency1!K79 -> 49.610958 | M23: =M22+L23 -> 714.48927 | N23: =+Efficiency1!C79 -> 48.97492 | O23: =O22+N23 -> 709.99334 | P23: ='15'!I38 -> 46.213 | Q23: =Q22+P23 -> 658.241 | R23: ='15'!I40 -> 44.925 | S23: =S22+R23 -> 640.004 | T23: =+AX23 -> 4106.7766 | U23: =T23+U22 -> 60799.486 | V23: =T23/P23 -> 88.866264 | W23: =U23/Q23 -> 92.366604 | X23: =IF(AND(R23>0,T23>0),(T23/(R23*1000))*1000,0) -> 91.41406 | Y23: =IF(AND(S23>0,U23>0),U23/S23,0) -> 94.998603 | Z23: 60.6 | AA23: =Z23+AA22 -> 847.1 | AB23: =Z23/(P23) -> 1.3113193 | AC23: =AA23/(Q23) -> 1.2869147 | AD23: =IF(AND(R23>0,Z23>0),Z23/(R23),0) -> 1.3489149 | AE23: =IF(AND(S23>0,AA23>0),AA23/(S23),0) -> 1.3235855 | AF23: ='15'!I46 -> 37218.46 | AG23: =AF23+AG22 -> 556284.34 | AH23: =IF(AND(L23>0,AF23>0),(AF23/(P23*1000)*1000),0) -> 805.36775 | AI23: =IF(AND(M23>0,AG23>0),(AG23/(Q23*1000)*1000),0) -> 845.1074 | AJ23: =IF(AND(R23>0,AF23>0),(AF23/(R23*1000)*1000),0) -> 828.45765 | AK23: =IF(AND(S23>0,AG23>0),(AG23/(S23*1000)*1000),0) -> 869.18885 | AL23: 4193.8 | AM23: 5172.6 | AN23: 4035.7 | AO23: =SUM(AL23:AN23) -> 13402.1 | AP23: =+[1]Aug!N18 -> 13124 | AQ23: =+AP23-AO23 -> -278.1 | AR23: =+AL23/AO23 -> 0.31292111 | AS23: =+AM23/AO23 -> 0.38595444 | AT23: =1-AR23-AS23 -> 0.30112445 | AU23: =+AR23*AQ23 -> -87.023361 | AV23: =+AS23*AQ23 -> -107.33393 | AW23: =+AT23*AQ23 -> -83.74271 | AX23: =+AL23+AU23 -> 4106.7766 | AY23: =+AM23+AV23 -> 5065.2661 | AZ23: =+AN23+AW23 -> 3951.9573 | BA23: =+Efficiency2!K79 -> 49.610958 | BB23: =BB22+BA23 -> 714.48927 | BC23: =+R23/BA23 -> 0.90554591 | BD23: =+S23/BB23 -> 0.89575033
A24: =A23+1 -> 45885 | B24: Facial | C24: 13,5 | D24: =+'16'!F42 -> 1230 | E24: =+'16'!G42 -> 947.1 | F24: =1-(E24/D24) -> 0.23 | G24: =+P24/N24 -> 0.97515218 | H24: =+P24/L24 -> 0.96265023 | I24: =+R24/P24 -> 0.9622681 | J24: =+R24/L24 -> 0.92632761 | K24: =+S24/M24 -> 0.89773563 | L24: =+Efficiency1!K84 -> 49.610958 | M24: =M23+L24 -> 764.10023 | N24: =+Efficiency1!C84 -> 48.97492 | O24: =O23+N24 -> 758.96826 | P24: ='16'!I38 -> 47.758 | Q24: =Q23+P24 -> 705.999 | R24: ='16'!I40 -> 45.956 | S24: =S23+R24 -> 685.96 | T24: =+AX24 -> 4247.3598 | U24: =T24+U23 -> 65046.846 | V24: =T24/P24 -> 88.935043 | W24: =U24/Q24 -> 92.134473 | X24: =IF(AND(R24>0,T24>0),(T24/(R24*1000))*1000,0) -> 92.422312 | Y24: =IF(AND(S24>0,U24>0),U24/S24,0) -> 94.826004 | Z24: 59.6 | AA24: =Z24+AA23 -> 906.7 | AB24: =Z24/(P24) -> 1.2479585 | AC24: =AA24/(Q24) -> 1.2842794 | AD24: =IF(AND(R24>0,Z24>0),Z24/(R24),0) -> 1.2968927 | AE24: =IF(AND(S24>0,AA24>0),AA24/(S24),0) -> 1.3217972 | AF24: ='16'!I46 -> 37046.8 | AG24: =AF24+AG23 -> 593331.14 | AH24: =IF(AND(L24>0,AF24>0),(AF24/(P24*1000)*1000),0) -> 775.71925 | AI24: =IF(AND(M24>0,AG24>0),(AG24/(Q24*1000)*1000),0) -> 840.41357 | AJ24: =IF(AND(R24>0,AF24>0),(AF24/(R24*1000)*1000),0) -> 806.1363 | AK24: =IF(AND(S24>0,AG24>0),(AG24/(S24*1000)*1000),0) -> 864.96463 | AL24: 4220.9 | AM24: 5385.2 | AN24: 3857.5 | AO24: =SUM(AL24:AN24) -> 13463.6 | AP24: =+[1]Aug!N19 -> 13548 | AQ24: =+AP24-AO24 -> 84.4 | AR24: =+AL24/AO24 -> 0.31350456 | AS24: =+AM24/AO24 -> 0.39998217 | AT24: =1-AR24-AS24 -> 0.28651327 | AU24: =+AR24*AQ24 -> 26.459785 | AV24: =+AS24*AQ24 -> 33.758495 | AW24: =+AT24*AQ24 -> 24.18172 | AX24: =+AL24+AU24 -> 4247.3598 | AY24: =+AM24+AV24 -> 5418.9585 | AZ24: =+AN24+AW24 -> 3881.6817 | BA24: =+Efficiency2!K84 -> 49.610958 | BB24: =BB23+BA24 -> 764.10023 | BC24: =+R24/BA24 -> 0.92632761 | BD24: =+S24/BB24 -> 0.89773563
A25: =A24+1 -> 45886 | B25: Facial | C25: 13,5/12 | D25: =+'17'!F42 -> 1230 | E25: =+'17'!G42 -> 947.1 | F25: =1-(E25/D25) -> 0.23 | G25: =+P25/N25 -> 0.95478212 | H25: =+P25/L25 -> 0.9467675 | I25: =+R25/P25 -> 0.98089129 | J25: =+R25/L25 -> 0.92867599 | K25: =+S25/M25 -> 0.89953187 | L25: =+SUM(Efficiency1!K89:K90) -> 47.093928 | M25: =M24+L25 -> 811.19416 | N25: =+SUM(Efficiency1!C89:C90) -> 46.698612 | O25: =O24+N25 -> 805.66687 | P25: ='17'!I38 -> 44.587 | Q25: =Q24+P25 -> 750.586 | R25: ='17'!I40 -> 43.735 | S25: =S24+R25 -> 729.695 | T25: =+AX25 -> 4164.44 | U25: =T25+U24 -> 69211.286 | V25: =T25/P25 -> 93.400318 | W25: =U25/Q25 -> 92.209668 | X25: =IF(AND(R25>0,T25>0),(T25/(R25*1000))*1000,0) -> 95.219846 | Y25: =IF(AND(S25>0,U25>0),U25/S25,0) -> 94.84961 | Z25: 59.2 | AA25: =Z25+AA24 -> 965.9 | AB25: =Z25/(P25) -> 1.3277413 | AC25: =AA25/(Q25) -> 1.2868612 | AD25: =IF(AND(R25>0,Z25>0),Z25/(R25),0) -> 1.353607 | AE25: =IF(AND(S25>0,AA25>0),AA25/(S25),0) -> 1.3237037 | AF25: ='17'!I46 -> 37209.54 | AG25: =AF25+AG24 -> 630540.68 | AH25: =IF(AND(L25>0,AF25>0),(AF25/(P25*1000)*1000),0) -> 834.53787 | AI25: =IF(AND(M25>0,AG25>0),(AG25/(Q25*1000)*1000),0) -> 840.06454 | AJ25: =IF(AND(R25>0,AF25>0),(AF25/(R25*1000)*1000),0) -> 850.79547 | AK25: =IF(AND(S25>0,AG25>0),(AG25/(S25*1000)*1000),0) -> 864.11539 | AL25: 4186 | AM25: 5353.1 | AN25: 3935.3 | AO25: =SUM(AL25:AN25) -> 13474.4 | AP25: =+[1]Aug!N20 -> 13405 | AQ25: =+AP25-AO25 -> -69.4 | AR25: =+AL25/AO25 -> 0.31066318 | AS25: =+AM25/AO25 -> 0.39727929 | AT25: =1-AR25-AS25 -> 0.29205753 | AU25: =+AR25*AQ25 -> -21.560025 | AV25: =+AS25*AQ25 -> -27.571182 | AW25: =+AT25*AQ25 -> -20.268793 | AX25: =+AL25+AU25 -> 4164.44 | AY25: =+AM25+AV25 -> 5325.5288 | AZ25: =+AN25+AW25 -> 3915.0312 | BA25: =+SUM(Efficiency2!K89:K90) -> 47.093928 | BB25: =BB24+BA25 -> 811.19416 | BC25: =+R25/BA25 -> 0.92867599 | BD25: =+S25/BB25 -> 0.89953187
A26: =A25+1 -> 45887 | B26: Facial | C26: 12/13 | D26: =+'18'!F42 -> 1230 | E26: =+'18'!G42 -> 947.1 | F26: =1-(E26/D26) -> 0.23 | G26: =+P26/N26 -> 0.95140395 | H26: =+P26/L26 -> 0.94992396 | I26: =+R26/P26 -> 1.0514397 | J26: =+R26/L26 -> 0.99878775 | K26: =+S26/M26 -> 0.9045642 | L26: =+SUM(Efficiency1!K94:K95) -> 43.32452 | M26: =M25+L26 -> 854.51868 | N26: =+SUM(Efficiency1!C94:C95) -> 43.257126 | O26: =O25+N26 -> 848.92399 | P26: ='18'!I38 -> 41.155 | Q26: =Q25+P26 -> 791.741 | R26: ='18'!I40 -> 43.272 | S26: =S25+R26 -> 772.967 | T26: =+AX26 -> 3160.9695 | U26: =T26+U25 -> 72372.255 | V26: =T26/P26 -> 76.806452 | W26: =U26/Q26 -> 91.409003 | X26: =IF(AND(R26>0,T26>0),(T26/(R26*1000))*1000,0) -> 73.048843 | Y26: =IF(AND(S26>0,U26>0),U26/S26,0) -> 93.629166 | Z26: 55.8 | AA26: =Z26+AA25 -> 1021.7 | AB26: =Z26/(P26) -> 1.3558498 | AC26: =AA26/(Q26) -> 1.2904473 | AD26: =IF(AND(R26>0,Z26>0),Z26/(R26),0) -> 1.2895175 | AE26: =IF(AND(S26>0,AA26>0),AA26/(S26),0) -> 1.3217899 | AF26: ='18'!I46 -> 36478.58 | AG26: =AF26+AG25 -> 667019.26 | AH26: =IF(AND(L26>0,AF26>0),(AF26/(P26*1000)*1000),0) -> 886.37055 | AI26: =IF(AND(M26>0,AG26>0),(AG26/(Q26*1000)*1000),0) -> 842.47154 | AJ26: =IF(AND(R26>0,AF26>0),(AF26/(R26*1000)*1000),0) -> 843.00656 | AK26: =IF(AND(S26>0,AG26>0),(AG26/(S26*1000)*1000),0) -> 862.93368 | AL26: 3980.8 | AM26: 4424.1 | AN26: 4040.1 | AO26: =SUM(AL26:AN26) -> 12445 | AP26: =+[1]Aug!N21 -> 9882 | AQ26: =+AP26-AO26 -> -2563 | AR26: =+AL26/AO26 -> 0.31987143 | AS26: =+AM26/AO26 -> 0.35549217 | AT26: =1-AR26-AS26 -> 0.3246364 | AU26: =+AR26*AQ26 -> -819.83049 | AV26: =+AS26*AQ26 -> -911.12642 | AW26: =+AT26*AQ26 -> -832.04309 | AX26: =+AL26+AU26 -> 3160.9695 | AY26: =+AM26+AV26 -> 3512.9736 | AZ26: =+AN26+AW26 -> 3208.0569 | BA26: =+SUM(Efficiency2!K94:K95) -> 43.32452 | BB26: =BB25+BA26 -> 854.51868 | BC26: =+R26/BA26 -> 0.99878775 | BD26: =+S26/BB26 -> 0.9045642
A27: =A26+1 -> 45888 | B27: Facial | C27: 13 | D27: =+'19'!F42 -> 1214.8178 | E27: =+'19'!G42 -> 935.40972 | F27: =1-(E27/D27) -> 0.23 | G27: =+P27/N27 -> 0.82381319 | H27: =+P27/L27 -> 0.80345138 | I27: =+R27/P27 -> 0.93752191 | J27: =+R27/L27 -> 0.75325327 | K27: =+S27/M27 -> 0.89680993 | L27: =+Efficiency1!K99 -> 46.157118 | M27: =M26+L27 -> 900.67579 | N27: =+Efficiency1!C99 -> 45.016274 | O27: =O26+N27 -> 893.94027 | P27: ='19'!I38 -> 37.085 | Q27: =Q26+P27 -> 828.826 | R27: ='19'!I40 -> 34.768 | S27: =S26+R27 -> 807.735 | T27: =+AX27 -> 3462.3535 | U27: =T27+U26 -> 75834.609 | V27: =T27/P27 -> 93.362641 | W27: =U27/Q27 -> 91.496416 | X27: =IF(AND(R27>0,T27>0),(T27/(R27*1000))*1000,0) -> 99.584489 | Y27: =IF(AND(S27>0,U27>0),U27/S27,0) -> 93.885506 | Z27: 52.7 | AA27: =Z27+AA26 -> 1074.4 | AB27: =Z27/(P27) -> 1.4210597 | AC27: =AA27/(Q27) -> 1.2962914 | AD27: =IF(AND(R27>0,Z27>0),Z27/(R27),0) -> 1.5157616 | AE27: =IF(AND(S27>0,AA27>0),AA27/(S27),0) -> 1.3301392 | AF27: ='19'!I46 -> 34346.46 | AG27: =AF27+AG26 -> 701365.72 | AH27: =IF(AND(L27>0,AF27>0),(AF27/(P27*1000)*1000),0) -> 926.15505 | AI27: =IF(AND(M27>0,AG27>0),(AG27/(Q27*1000)*1000),0) -> 846.21588 | AJ27: =IF(AND(R27>0,AF27>0),(AF27/(R27*1000)*1000),0) -> 987.87563 | AK27: =IF(AND(S27>0,AG27>0),(AG27/(S27*1000)*1000),0) -> 868.31166 | AL27: 3626.1 | AM27: 4975.5 | AN27: 4109.4 | AO27: =SUM(AL27:AN27) -> 12711 | AP27: =+[1]Aug!N22 -> 12137 | AQ27: =+AP27-AO27 -> -574 | AR27: =+AL27/AO27 -> 0.2852726 | AS27: =+AM27/AO27 -> 0.39143262 | AT27: =1-AR27-AS27 -> 0.32329478 | AU27: =+AR27*AQ27 -> -163.74647 | AV27: =+AS27*AQ27 -> -224.68232 | AW27: =+AT27*AQ27 -> -185.57121 | AX27: =+AL27+AU27 -> 3462.3535 | AY27: =+AM27+AV27 -> 4750.8177 | AZ27: =+AN27+AW27 -> 3923.8288 | BA27: =+Efficiency2!K99 -> 46.157118 | BB27: =BB26+BA27 -> 900.67579 | BC27: =+R27/BA27 -> 0.75325327 | BD27: =+S27/BB27 -> 0.89680993
A28: =A27+1 -> 45889 | B28: Facial | C28: 13/12 | D28: =+'20'!F42 -> 1230 | E28: =+'20'!G42 -> 947.1 | F28: =1-(E28/D28) -> 0.23 | G28: =+P28/N28 -> 1.0108609 | H28: =+P28/L28 -> 1.0055202 | I28: =+R28/P28 -> 0.92810945 | J28: =+R28/L28 -> 0.93323278 | K28: =+S28/M28 -> 0.89850556 | L28: =+SUM(Efficiency1!K105:K106) -> 43.977238 | M28: =M27+L28 -> 944.65303 | N28: =+SUM(Efficiency1!C105:C106) -> 43.74489 | O28: =O27+N28 -> 937.68516 | P28: ='20'!I38 -> 44.22 | Q28: =Q27+P28 -> 873.046 | R28: ='20'!I40 -> 41.041 | S28: =S27+R28 -> 848.776 | T28: =+AX28 -> 3761.0336 | U28: =T28+U27 -> 79595.642 | V28: =T28/P28 -> 85.052773 | W28: =U28/Q28 -> 91.170044 | X28: =IF(AND(R28>0,T28>0),(T28/(R28*1000))*1000,0) -> 91.640887 | Y28: =IF(AND(S28>0,U28>0),U28/S28,0) -> 93.776971 | Z28: 57.8 | AA28: =Z28+AA27 -> 1132.2 | AB28: =Z28/(P28) -> 1.3071009 | AC28: =AA28/(Q28) -> 1.2968389 | AD28: =IF(AND(R28>0,Z28>0),Z28/(R28),0) -> 1.4083477 | AE28: =IF(AND(S28>0,AA28>0),AA28/(S28),0) -> 1.3339208 | AF28: ='20'!I46 -> 36876.8 | AG28: =AF28+AG27 -> 738242.52 | AH28: =IF(AND(L28>0,AF28>0),(AF28/(P28*1000)*1000),0) -> 833.93939 | AI28: =IF(AND(M28>0,AG28>0),(AG28/(Q28*1000)*1000),0) -> 845.59407 | AJ28: =IF(AND(R28>0,AF28>0),(AF28/(R28*1000)*1000),0) -> 898.53561 | AK28: =IF(AND(S28>0,AG28>0),(AG28/(S28*1000)*1000),0) -> 869.77309 | AL28: 3978.7 | AM28: 4839.2 | AN28: 4119.9 | AO28: =SUM(AL28:AN28) -> 12937.8 | AP28: =+[1]Aug!N23 -> 12230 | AQ28: =+AP28-AO28 -> -707.8 | AR28: =+AL28/AO28 -> 0.30752524 | AS28: =+AM28/AO28 -> 0.37403577 | AT28: =1-AR28-AS28 -> 0.31843899 | AU28: =+AR28*AQ28 -> -217.66636 | AV28: =+AS28*AQ28 -> -264.74252 | AW28: =+AT28*AQ28 -> -225.39112 | AX28: =+AL28+AU28 -> 3761.0336 | AY28: =+AM28+AV28 -> 4574.4575 | AZ28: =+AN28+AW28 -> 3894.5089 | BA28: =+SUM(Efficiency2!K105:K106) -> 43.977238 | BB28: =BB27+BA28 -> 944.65303 | BC28: =+R28/BA28 -> 0.93323278 | BD28: =+S28/BB28 -> 0.89850556
A29: =A28+1 -> 45890 | B29: Facial | C29: 13/12 | D29: =+'21'!F42 -> 1230 | E29: =+'21'!G42 -> 947.1 | F29: =1-(E29/D29) -> 0.23 | G29: =+P29/N29 -> 0.95986212 | H29: =+P29/L29 -> 0.95669601 | I29: =+R29/P29 -> 0.99499027 | J29: =+R29/L29 -> 0.95190322 | K29: =+S29/M29 -> 0.90088328 | L29: =+SUM(Efficiency1!K109:K110) -> 44.024434 | M29: =M28+L29 -> 988.67747 | N29: =+SUM(Efficiency1!C109:C110) -> 43.879219 | O29: =O28+N29 -> 981.56438 | P29: ='21'!I38 -> 42.118 | Q29: =Q28+P29 -> 915.164 | R29: ='21'!I40 -> 41.907 | S29: =S28+R29 -> 890.683 | T29: =+AX29 -> 3638.8274 | U29: =T29+U28 -> 83234.47 | V29: =T29/P29 -> 86.396017 | W29: =U29/Q29 -> 90.950332 | X29: =IF(AND(R29>0,T29>0),(T29/(R29*1000))*1000,0) -> 86.831017 | Y29: =IF(AND(S29>0,U29>0),U29/S29,0) -> 93.450161 | Z29: 56.3 | AA29: =Z29+AA28 -> 1188.5 | AB29: =Z29/(P29) -> 1.3367206 | AC29: =AA29/(Q29) -> 1.2986743 | AD29: =IF(AND(R29>0,Z29>0),Z29/(R29),0) -> 1.343451 | AE29: =IF(AND(S29>0,AA29>0),AA29/(S29),0) -> 1.3343692 | AF29: ='21'!I46 -> 35401.9 | AG29: =AF29+AG28 -> 773644.42 | AH29: =IF(AND(L29>0,AF29>0),(AF29/(P29*1000)*1000),0) -> 840.54086 | AI29: =IF(AND(M29>0,AG29>0),(AG29/(Q29*1000)*1000),0) -> 845.36151 | AJ29: =IF(AND(R29>0,AF29>0),(AF29/(R29*1000)*1000),0) -> 844.77295 | AK29: =IF(AND(S29>0,AG29>0),(AG29/(S29*1000)*1000),0) -> 868.59682 | AL29: 3847 | AM29: 4860.1 | AN29: 4140.1 | AO29: =SUM(AL29:AN29) -> 12847.2 | AP29: =+[1]Aug!N24 -> 12152 | AQ29: =+AP29-AO29 -> -695.2 | AR29: =+AL29/AO29 -> 0.29944268 | AS29: =+AM29/AO29 -> 0.37830033 | AT29: =1-AR29-AS29 -> 0.32225699 | AU29: =+AR29*AQ29 -> -208.17255 | AV29: =+AS29*AQ29 -> -262.99439 | AW29: =+AT29*AQ29 -> -224.03306 | AX29: =+AL29+AU29 -> 3638.8274 | AY29: =+AM29+AV29 -> 4597.1056 | AZ29: =+AN29+AW29 -> 3916.0669 | BA29: =+SUM(Efficiency2!K109:K110) -> 44.024434 | BB29: =BB28+BA29 -> 988.67747 | BC29: =+R29/BA29 -> 0.95190322 | BD29: =+S29/BB29 -> 0.90088328
A30: =A29+1 -> 45891 | B30: Facial/Toilet | C30: 12/13 | D30: =+'22'!F42 -> 1230 | E30: =+'22'!G42 -> 952.38729 | F30: =1-(E30/D30) -> 0.22570139 | G30: =+P30/N30 -> 1.0117786 | H30: =+P30/L30 -> 1.0117786 | I30: =+R30/P30 -> 0.99356371 | J30: =+R30/L30 -> 1.0052665 | K30: =+S30/M30 -> 0.90538231 | L30: =+SUM(Efficiency1!K113:K114) -> 44.532472 | M30: =M29+L30 -> 1033.2099 | N30: =+SUM(Efficiency1!C113:C114) -> 44.532472 | O30: =O29+N30 -> 1026.0968 | P30: ='22'!I38 -> 45.057 | Q30: =Q29+P30 -> 960.221 | R30: ='22'!I40 -> 44.767 | S30: =S29+R30 -> 935.45 | T30: =+AX30 -> 3777.3498 | U30: =T30+U29 -> 87011.82 | V30: =T30/P30 -> 83.834915 | W30: =U30/Q30 -> 90.616452 | X30: =IF(AND(R30>0,T30>0),(T30/(R30*1000))*1000,0) -> 84.377996 | Y30: =IF(AND(S30>0,U30>0),U30/S30,0) -> 93.016003 | Z30: 59.1 | AA30: =Z30+AA29 -> 1247.6 | AB30: =Z30/(P30) -> 1.3116719 | AC30: =AA30/(Q30) -> 1.2992842 | AD30: =IF(AND(R30>0,Z30>0),Z30/(R30),0) -> 1.3201689 | AE30: =IF(AND(S30>0,AA30>0),AA30/(S30),0) -> 1.3336897 | AF30: ='22'!I46 -> 37575.12 | AG30: =AF30+AG29 -> 811219.54 | AH30: =IF(AND(L30>0,AF30>0),(AF30/(P30*1000)*1000),0) -> 833.94633 | AI30: =IF(AND(M30>0,AG30>0),(AG30/(Q30*1000)*1000),0) -> 844.82587 | AJ30: =IF(AND(R30>0,AF30>0),(AF30/(R30*1000)*1000),0) -> 839.34863 | AK30: =IF(AND(S30>0,AG30>0),(AG30/(S30*1000)*1000),0) -> 867.19711 | AL30: 3991.9 | AM30: 4909.9 | AN30: 3967.9 | AO30: =SUM(AL30:AN30) -> 12869.7 | AP30: =+[1]Aug!N25 -> 12178 | AQ30: =+AP30-AO30 -> -691.7 | AR30: =+AL30/AO30 -> 0.31017817 | AS30: =+AM30/AO30 -> 0.3815085 | AT30: =1-AR30-AS30 -> 0.30831333 | AU30: =+AR30*AQ30 -> -214.55024 | AV30: =+AS30*AQ30 -> -263.88943 | AW30: =+AT30*AQ30 -> -213.26033 | AX30: =+AL30+AU30 -> 3777.3498 | AY30: =+AM30+AV30 -> 4646.0106 | AZ30: =+AN30+AW30 -> 3754.6397 | BA30: =++SUM(Efficiency2!K113:K114) -> 44.532472 | BB30: =BB29+BA30 -> 1033.2099 | BC30: =+R30/BA30 -> 1.0052665 | BD30: =+S30/BB30 -> 0.90538231
A31: =A30+1 -> 45892 | B31: Toilet | C31: 13 | D31: =+'23'!F42 -> 1230 | E31: =+'23'!G42 -> 955.3 | F31: =1-(E31/D31) -> 0.22333333 | G31: =+P31/N31 -> 0.9878259 | H31: =+P31/L31 -> 0.9878259 | I31: =+R31/P31 -> 0.9196744 | J31: =+R31/L31 -> 0.90847819 | K31: =+S31/M31 -> 0.90551465 | L31: =+Efficiency1!K117 -> 46.138697 | M31: =M30+L31 -> 1079.3486 | N31: =+Efficiency1!C117 -> 46.138697 | O31: =O30+N31 -> 1072.2355 | P31: ='23'!I38 -> 45.577 | Q31: =Q30+P31 -> 1005.798 | R31: ='23'!I40 -> 41.916 | S31: =S30+R31 -> 977.366 | T31: =+AX31 -> 4005.5209 | U31: =T31+U30 -> 91017.341 | V31: =T31/P31 -> 87.884699 | W31: =U31/Q31 -> 90.492664 | X31: =IF(AND(R31>0,T31>0),(T31/(R31*1000))*1000,0) -> 95.560668 | Y31: =IF(AND(S31>0,U31>0),U31/S31,0) -> 93.125135 | Z31: 59.7 | AA31: =Z31+AA30 -> 1307.3 | AB31: =Z31/(P31) -> 1.3098712 | AC31: =AA31/(Q31) -> 1.299764 | AD31: =IF(AND(R31>0,Z31>0),Z31/(R31),0) -> 1.4242771 | AE31: =IF(AND(S31>0,AA31>0),AA31/(S31),0) -> 1.3375747 | AF31: ='23'!I46 -> 37109.54 | AG31: =AF31+AG30 -> 848329.08 | AH31: =IF(AND(L31>0,AF31>0),(AF31/(P31*1000)*1000),0) -> 814.21638 | AI31: =IF(AND(M31>0,AG31>0),(AG31/(Q31*1000)*1000),0) -> 843.43882 | AJ31: =IF(AND(R31>0,AF31>0),(AF31/(R31*1000)*1000),0) -> 885.33114 | AK31: =IF(AND(S31>0,AG31>0),(AG31/(S31*1000)*1000),0) -> 867.97482 | AL31: 4258.9 | AM31: 4911.8 | AN31: 4094.5 | AO31: =SUM(AL31:AN31) -> 13265.2 | AP31: =+[1]Aug!N26 -> 12476 | AQ31: =+AP31-AO31 -> -789.2 | AR31: =+AL31/AO31 -> 0.32105811 | AS31: =+AM31/AO31 -> 0.37027712 | AT31: =1-AR31-AS31 -> 0.30866478 | AU31: =+AR31*AQ31 -> -253.37906 | AV31: =+AS31*AQ31 -> -292.2227 | AW31: =+AT31*AQ31 -> -243.59824 | AX31: =+AL31+AU31 -> 4005.5209 | AY31: =+AM31+AV31 -> 4619.5773 | AZ31: =+AN31+AW31 -> 3850.9018 | BA31: =+Efficiency2!K117 -> 46.138697 | BB31: =BB30+BA31 -> 1079.3486 | BC31: =+R31/BA31 -> 0.90847819 | BD31: =+S31/BB31 -> 0.90551465
A32: =A31+1 -> 45893 | B32: Toilet | C32: 13 | D32: =+'24'!F42 -> 1230 | E32: =+'24'!G42 -> 959.4 | F32: =1-(E32/D32) -> 0.22 | G32: =+P32/N32 -> 0.95289443 | H32: =+P32/L32 -> 0.95289443 | I32: =+R32/P32 -> 1.0157404 | J32: =+R32/L32 -> 0.96789334 | K32: =+S32/M32 -> 0.90808235 | L32: =+Efficiency1!K122 -> 46.336717 | M32: =M31+L32 -> 1125.6854 | N32: =+Efficiency1!C122 -> 46.336717 | O32: =O31+N32 -> 1118.5723 | P32: ='24'!I38 -> 44.154 | Q32: =Q31+P32 -> 1049.952 | R32: ='24'!I40 -> 44.849 | S32: =S31+R32 -> 1022.215 | T32: =+AX32 -> 3983.3025 | U32: =T32+U31 -> 95000.643 | V32: =T32/P32 -> 90.213854 | W32: =U32/Q32 -> 90.480939 | X32: =IF(AND(R32>0,T32>0),(T32/(R32*1000))*1000,0) -> 88.81586 | Y32: =IF(AND(S32>0,U32>0),U32/S32,0) -> 92.936068 | Z32: 60.1 | AA32: =Z32+AA31 -> 1367.4 | AB32: =Z32/(P32) -> 1.3611451 | AC32: =AA32/(Q32) -> 1.3023453 | AD32: =IF(AND(R32>0,Z32>0),Z32/(R32),0) -> 1.3400522 | AE32: =IF(AND(S32>0,AA32>0),AA32/(S32),0) -> 1.3376834 | AF32: =+'24'!I46 -> 36643.12 | AG32: =AF32+AG31 -> 884972.2 | AH32: =IF(AND(L32>0,AF32>0),(AF32/(P32*1000)*1000),0) -> 829.89355 | AI32: =IF(AND(M32>0,AG32>0),(AG32/(Q32*1000)*1000),0) -> 842.8692 | AJ32: =IF(AND(R32>0,AF32>0),(AF32/(R32*1000)*1000),0) -> 817.03316 | AK32: =IF(AND(S32>0,AG32>0),(AG32/(S32*1000)*1000),0) -> 865.73979 | AL32: 4224 | AM32: 4952.1 | AN32: 4147.1 | AO32: =SUM(AL32:AN32) -> 13323.2 | AP32: =+[1]Aug!N27 -> 12564 | AQ32: =+AP32-AO32 -> -759.2 | AR32: =+AL32/AO32 -> 0.31704095 | AS32: =+AM32/AO32 -> 0.37168998 | AT32: =1-AR32-AS32 -> 0.31126906 | AU32: =+AR32*AQ32 -> -240.69749 | AV32: =+AS32*AQ32 -> -282.18704 | AW32: =+AT32*AQ32 -> -236.31547 | AX32: =+AL32+AU32 -> 3983.3025 | AY32: =+AM32+AV32 -> 4669.913 | AZ32: =+AN32+AW32 -> 3910.7845 | BA32: =+Efficiency2!K122 -> 46.336717 | BB32: =BB31+BA32 -> 1125.6854 | BC32: =+R32/BA32 -> 0.96789334 | BD32: =+S32/BB32 -> 0.90808235
A33: =A32+1 -> 45894 | B33: Toilet | C33: 13 | D33: =+'25'!F42 -> 1226.8125 | E33: =+'25'!G42 -> 947.37896 | F33: =1-(E33/D33) -> 0.227772 | G33: =+P33/N33 -> 0.96070188 | H33: =+P33/L33 -> 0.95821225 | I33: =+R33/P33 -> 0.93072933 | J33: =+R33/L33 -> 0.89183625 | K33: =+S33/M33 -> 0.9074462 | L33: =+Efficiency1!K127 -> 45.875013 | M33: =M32+L33 -> 1171.5604 | N33: =+Efficiency1!C127 -> 45.75613 | O33: =O32+N33 -> 1164.3284 | P33: ='25'!I38 -> 43.958 | Q33: =Q32+P33 -> 1093.91 | R33: ='25'!I40 -> 40.913 | S33: =S32+R33 -> 1063.128 | T33: =+AX33 -> 4139.0121 | U33: =T33+U32 -> 99139.655 | V33: =T33/P33 -> 94.158335 | W33: =U33/Q33 -> 90.628713 | X33: =IF(AND(R33>0,T33>0),(T33/(R33*1000))*1000,0) -> 101.16618 | Y33: =IF(AND(S33>0,U33>0),U33/S33,0) -> 93.252793 | Z33: 60.7 | AA33: =Z33+AA32 -> 1428.1 | AB33: =Z33/(P33) -> 1.3808636 | AC33: =AA33/(Q33) -> 1.3055005 | AD33: =IF(AND(R33>0,Z33>0),Z33/(R33),0) -> 1.483636 | AE33: =IF(AND(S33>0,AA33>0),AA33/(S33),0) -> 1.3433001 | AF33: =+'25'!I46 -> 35649.18 | AG33: =AF33+AG32 -> 920621.38 | AH33: =IF(AND(L33>0,AF33>0),(AF33/(P33*1000)*1000),0) -> 810.98276 | AI33: =IF(AND(M33>0,AG33>0),(AG33/(Q33*1000)*1000),0) -> 841.58786 | AJ33: =IF(AND(R33>0,AF33>0),(AF33/(R33*1000)*1000),0) -> 871.34114 | AK33: =IF(AND(S33>0,AG33>0),(AG33/(S33*1000)*1000),0) -> 865.95535 | AL33: 4257.5 | AM33: 5387 | AN33: 4081.5 | AO33: =SUM(AL33:AN33) -> 13726 | AP33: =+[1]Aug!N28 -> 13344 | AQ33: =+AP33-AO33 -> -382 | AR33: =+AL33/AO33 -> 0.31017776 | AS33: =+AM33/AO33 -> 0.39246685 | AT33: =1-AR33-AS33 -> 0.29735538 | AU33: =+AR33*AQ33 -> -118.48791 | AV33: =+AS33*AQ33 -> -149.92234 | AW33: =+AT33*AQ33 -> -113.58976 | AX33: =+AL33+AU33 -> 4139.0121 | AY33: =+AM33+AV33 -> 5237.0777 | AZ33: =+AN33+AW33 -> 3967.9102 | BA33: =+Efficiency2!K127 -> 45.875013 | BB33: =BB32+BA33 -> 1171.5604 | BC33: =+R33/BA33 -> 0.89183625 | BD33: =+S33/BB33 -> 0.9074462
A34: =A33+1 -> 45895 | B34: Toilet/Facial | C34: 13/12 | D34: =+'26'!F42 -> 1218.0278 | E34: =+'26'!G42 -> 937.88139 | F34: =1-(E34/D34) -> 0.23 | G34: =+P34/N34 -> 0.93728236 | H34: =+P34/L34 -> 0.92825065 | I34: =+R34/P34 -> 0.95413041 | J34: =+R34/L34 -> 0.88567217 | K34: =+S34/M34 -> 0.90663959 | L34: =+SUM(Efficiency1!K132:K133) -> 45.069723 | M34: =M33+L34 -> 1216.6301 | N34: =+SUM(Efficiency1!C132:C133) -> 44.635429 | O34: =O33+N34 -> 1208.9638 | P34: ='26'!I38 -> 41.836 | Q34: =Q33+P34 -> 1135.746 | R34: ='26'!I40 -> 39.917 | S34: =S33+R34 -> 1103.045 | T34: =+AX34 -> 4099.3081 | U34: =T34+U33 -> 103238.96 | V34: =T34/P34 -> 97.985184 | W34: =U34/Q34 -> 90.899694 | X34: =IF(AND(R34>0,T34>0),(T34/(R34*1000))*1000,0) -> 102.6958 | Y34: =IF(AND(S34>0,U34>0),U34/S34,0) -> 93.594516 | Z34: 59.9 | AA34: =Z34+AA33 -> 1488 | AB34: =Z34/(P34) -> 1.4317812 | AC34: =AA34/(Q34) -> 1.3101521 | AD34: =IF(AND(R34>0,Z34>0),Z34/(R34),0) -> 1.5006138 | AE34: =IF(AND(S34>0,AA34>0),AA34/(S34),0) -> 1.348993 | AF34: ='26'!I46 -> 37913.06 | AG34: =AF34+AG33 -> 958534.44 | AH34: =IF(AND(L34>0,AF34>0),(AF34/(P34*1000)*1000),0) -> 906.23052 | AI34: =IF(AND(M34>0,AG34>0),(AG34/(Q34*1000)*1000),0) -> 843.96902 | AJ34: =IF(AND(R34>0,AF34>0),(AF34/(R34*1000)*1000),0) -> 949.79733 | AK34: =IF(AND(S34>0,AG34>0),(AG34/(S34*1000)*1000),0) -> 868.98942 | AL34: 4147 | AM34: 5413 | AN34: 4065.7 | AO34: 13625.7 | AP34: =+[1]Aug!N29 -> 13469 | AQ34: =+AP34-AO34 -> -156.7 | AR34: =+AL34/AO34 -> 0.30435134 | AS34: =+AM34/AO34 -> 0.39726399 | AT34: =1-AR34-AS34 -> 0.29838467 | AU34: =+AR34*AQ34 -> -47.691854 | AV34: =+AS34*AQ34 -> -62.251268 | AW34: =+AT34*AQ34 -> -46.756878 | AX34: =+AL34+AU34 -> 4099.3081 | AY34: =+AM34+AV34 -> 5350.7487 | AZ34: =+AN34+AW34 -> 4018.9431 | BA34: =+SUM(Efficiency2!K132:K133) -> 45.069723 | BB34: =BB33+BA34 -> 1216.6301 | BC34: =+R34/BA34 -> 0.88567217 | BD34: =+S34/BB34 -> 0.90663959
A35: =A34+1 -> 45896 | B35: Facial | C35: 12 | D35: =+'27'!F42 -> 1229.8403 | E35: =+'27'!G42 -> 946.97701 | F35: =1-(E35/D35) -> 0.23 | G35: =+P35/N35 -> 0.98191371 | H35: =+P35/L35 -> 0.9817862 | I35: =+R35/P35 -> 0.95725972 | J35: =+R35/L35 -> 0.93982438 | K35: =+S35/M35 -> 0.90777766 | L35: =+Efficiency1!K137 -> 43.205944 | M35: =M34+L35 -> 1259.836 | N35: =+Efficiency1!C137 -> 43.200334 | O35: =O34+N35 -> 1252.1642 | P35: ='27'!I38 -> 42.419 | Q35: =Q34+P35 -> 1178.165 | R35: ='27'!I40 -> 40.606 | S35: =S34+R35 -> 1143.651 | T35: =+AX35 -> 4095.1513 | U35: =T35+U34 -> 107334.11 | V35: =T35/P35 -> 96.540497 | W35: =U35/Q35 -> 91.102787 | X35: =IF(AND(R35>0,T35>0),(T35/(R35*1000))*1000,0) -> 100.85089 | Y35: =IF(AND(S35>0,U35>0),U35/S35,0) -> 93.852158 | Z35: 57.5 | AA35: =Z35+AA34 -> 1545.5 | AB35: =Z35/(P35) -> 1.3555246 | AC35: =AA35/(Q35) -> 1.3117857 | AD35: =IF(AND(R35>0,Z35>0),Z35/(R35),0) -> 1.4160469 | AE35: =IF(AND(S35>0,AA35>0),AA35/(S35),0) -> 1.3513738 | AF35: ='27'!I46 -> 34560.62 | AG35: =AF35+AG34 -> 993095.06 | AH35: =IF(AND(L35>0,AF35>0),(AF35/(P35*1000)*1000),0) -> 814.74386 | AI35: =IF(AND(M35>0,AG35>0),(AG35/(Q35*1000)*1000),0) -> 842.91679 | AJ35: =IF(AND(R35>0,AF35>0),(AF35/(R35*1000)*1000),0) -> 851.12102 | AK35: =IF(AND(S35>0,AG35>0),(AG35/(S35*1000)*1000),0) -> 868.355 | AL35: 4019.5 | AM35: 5402.3 | AN35: 3951.5 | AO35: =SUM(AL35:AN35) -> 13373.3 | AP35: =+[1]Aug!N30 -> 13625 | AQ35: =+AP35-AO35 -> 251.7 | AR35: =+AL35/AO35 -> 0.30056157 | AS35: =+AM35/AO35 -> 0.40396163 | AT35: =1-AR35-AS35 -> 0.29547681 | AU35: =+AR35*AQ35 -> 75.651346 | AV35: =+AS35*AQ35 -> 101.67714 | AW35: =+AT35*AQ35 -> 74.371513 | AX35: =+AL35+AU35 -> 4095.1513 | AY35: =+AM35+AV35 -> 5503.9771 | AZ35: =+AN35+AW35 -> 4025.8715 | BA35: =+Efficiency2!K137 -> 43.205944 | BB35: =BB34+BA35 -> 1259.836 | BC35: =+R35/BA35 -> 0.93982438 | BD35: =+S35/BB35 -> 0.90777766
A36: =A35+1 -> 45897 | B36: Facial | C36: 12 | D36: =+'28'!F42 -> 1216.4722 | E36: =+'28'!G42 -> 936.68361 | F36: =1-(E36/D36) -> 0.23 | G36: =+P36/N36 -> 0.91783827 | H36: =+P36/L36 -> 0.90774371 | I36: =+R36/P36 -> 1.0177625 | J36: =+R36/L36 -> 0.9238675 | K36: =+S36/M36 -> 0.90831142 | L36: =+Efficiency1!K142 -> 43.22806 | M36: =M35+L36 -> 1303.0641 | N36: =+Efficiency1!C142 -> 42.75263 | O36: =O35+N36 -> 1294.9168 | P36: ='28'!I38 -> 39.24 | Q36: =Q35+P36 -> 1217.405 | R36: ='28'!I40 -> 39.937 | S36: =S35+R36 -> 1183.588 | T36: =+AX36 -> 3288.1688 | U36: =T36+U35 -> 110622.28 | V36: =T36/P36 -> 83.796351 | W36: =U36/Q36 -> 90.867282 | X36: =IF(AND(R36>0,T36>0),(T36/(R36*1000))*1000,0) -> 82.333896 | Y36: =IF(AND(S36>0,U36>0),U36/S36,0) -> 93.463506 | Z36: 56.9 | AA36: =Z36+AA35 -> 1602.4 | AB36: =Z36/(P36) -> 1.450051 | AC36: =AA36/(Q36) -> 1.3162423 | AD36: =IF(AND(R36>0,Z36>0),Z36/(R36),0) -> 1.424744 | AE36: =IF(AND(S36>0,AA36>0),AA36/(S36),0) -> 1.3538495 | AF36: ='28'!I46 -> 35104.6 | AG36: =AF36+AG35 -> 1028199.7 | AH36: =IF(AND(L36>0,AF36>0),(AF36/(P36*1000)*1000),0) -> 894.61264 | AI36: =IF(AND(M36>0,AG36>0),(AG36/(Q36*1000)*1000),0) -> 844.58308 | AJ36: =IF(AND(R36>0,AF36>0),(AF36/(R36*1000)*1000),0) -> 878.99942 | AK36: =IF(AND(S36>0,AG36>0),(AG36/(S36*1000)*1000),0) -> 868.71416 | AL36: 4002.7 | AM36: 5460.9 | AN36: 3945 | AO36: =SUM(AL36:AN36) -> 13408.6 | AP36: =+[1]Aug!N31 -> 11015 | AQ36: =+AP36-AO36 -> -2393.6 | AR36: =+AL36/AO36 -> 0.29851737 | AS36: =+AM36/AO36 -> 0.40726847 | AT36: =1-AR36-AS36 -> 0.29421416 | AU36: =+AR36*AQ36 -> -714.53118 | AV36: =+AS36*AQ36 -> -974.83781 | AW36: =+AT36*AQ36 -> -704.23102 | AX36: =+AL36+AU36 -> 3288.1688 | AY36: =+AM36+AV36 -> 4486.0622 | AZ36: =+AN36+AW36 -> 3240.769 | BA36: =+Efficiency2!K142 -> 43.22806 | BB36: =BB35+BA36 -> 1303.0641 | BC36: =+R36/BA36 -> 0.9238675 | BD36: =+S36/BB36 -> 0.90831142
A37: =A36+1 -> 45898 | B37: Facial | C37: 12/13 | D37: =+'29'!F42 -> 1230 | E37: =+'29'!G42 -> 947.1 | F37: =1-(E37/D37) -> 0.23 | G37: =+P37/N37 -> 0.90792976 | H37: =+P37/L37 -> 0.90160528 | I37: =+R37/P37 -> 0.91344822 | J37: =+R37/L37 -> 0.82356974 | K37: =+S37/M37 -> 0.90544419 | L37: =+SUM(Efficiency1!K147:K148) -> 45.633051 | M37: =M36+L37 -> 1348.6971 | N37: =+SUM(Efficiency1!C147:C148) -> 45.315179 | O37: =O36+N37 -> 1340.232 | P37: ='29'!I38 -> 41.143 | Q37: =Q36+P37 -> 1258.548 | R37: ='29'!I40 -> 37.582 | S37: =S36+R37 -> 1221.17 | T37: =+AX37 -> 3948.1171 | U37: =T37+U36 -> 114570.4 | V37: =T37/P37 -> 95.960846 | W37: =U37/Q37 -> 91.033795 | X37: =IF(AND(R37>0,T37>0),(T37/(R37*1000))*1000,0) -> 105.05341 | Y37: =IF(AND(S37>0,U37>0),U37/S37,0) -> 93.820189 | Z37: 56 | AA37: =Z37+AA36 -> 1658.4 | AB37: =Z37/(P37) -> 1.3611064 | AC37: =AA37/(Q37) -> 1.317709 | AD37: =IF(AND(R37>0,Z37>0),Z37/(R37),0) -> 1.490075 | AE37: =IF(AND(S37>0,AA37>0),AA37/(S37),0) -> 1.3580419 | AF37: ='29'!I46 -> 34260.68 | AG37: =AF37+AG36 -> 1062460.3 | AH37: =IF(AND(L37>0,AF37>0),(AF37/(P37*1000)*1000),0) -> 832.72197 | AI37: =IF(AND(M37>0,AG37>0),(AG37/(Q37*1000)*1000),0) -> 844.19533 | AJ37: =IF(AND(R37>0,AF37>0),(AF37/(R37*1000)*1000),0) -> 911.62471 | AK37: =IF(AND(S37>0,AG37>0),(AG37/(S37*1000)*1000),0) -> 870.03475 | AL37: 4178.7 | AM37: 5108.5 | AN37: 3956.6 | AO37: =SUM(AL37:AN37) -> 13243.8 | AP37: =+[1]Aug!N32 -> 12513 | AQ37: =+AP37-AO37 -> -730.8 | AR37: =+AL37/AO37 -> 0.31552123 | AS37: =+AM37/AO37 -> 0.38572766 | AT37: =1-AR37-AS37 -> 0.29875111 | AU37: =+AR37*AQ37 -> -230.58291 | AV37: =+AS37*AQ37 -> -281.88977 | AW37: =+AT37*AQ37 -> -218.32731 | AX37: =+AL37+AU37 -> 3948.1171 | AY37: =+AM37+AV37 -> 4826.6102 | AZ37: =+AN37+AW37 -> 3738.2727 | BA37: =+SUM(Efficiency2!K147:K148) -> 45.633051 | BB37: =BB36+BA37 -> 1348.6971 | BC37: =+R37/BA37 -> 0.82356974 | BD37: =+S37/BB37 -> 0.90544419
A38: =A37+1 -> 45899 | B38: Facial | C38: 13/12 | D38: =+'30'!F42 -> 1230 | E38: =+'30'!G42 -> 947.1 | F38: =1-(E38/D38) -> 0.23 | G38: =+P38/N38 -> 0.97409953 | H38: =+P38/L38 -> 0.9663693 | I38: =+R38/P38 -> 0.90520752 | J38: =+R38/L38 -> 0.87476476 | K38: =+S38/M38 -> 0.90444878 | L38: =+SUM(Efficiency1!K152:K153) -> 45.227016 | M38: =M37+L38 -> 1393.9242 | N38: =+SUM(Efficiency1!C152:C153) -> 44.868105 | O38: =O37+N38 -> 1385.1001 | P38: ='30'!I38 -> 43.706 | Q38: =Q37+P38 -> 1302.254 | R38: ='30'!I40 -> 39.563 | S38: =S37+R38 -> 1260.733 | T38: =+AX38 -> 3954.7052 | U38: =T38+U37 -> 118525.11 | V38: =T38/P38 -> 90.484263 | W38: =U38/Q38 -> 91.015352 | X38: =IF(AND(R38>0,T38>0),(T38/(R38*1000))*1000,0) -> 99.959689 | Y38: =IF(AND(S38>0,U38>0),U38/S38,0) -> 94.012853 | Z38: 58.1 | AA38: =Z38+AA37 -> 1716.5 | AB38: =Z38/(P38) -> 1.3293369 | AC38: =AA38/(Q38) -> 1.3180992 | AD38: =IF(AND(R38>0,Z38>0),Z38/(R38),0) -> 1.4685438 | AE38: =IF(AND(S38>0,AA38>0),AA38/(S38),0) -> 1.3615095 | AF38: ='30'!I46 -> 36664.94 | AG38: =AF38+AG37 -> 1099125.3 | AH38: =IF(AND(L38>0,AF38>0),(AF38/(P38*1000)*1000),0) -> 838.89946 | AI38: =IF(AND(M38>0,AG38>0),(AG38/(Q38*1000)*1000),0) -> 844.01759 | AJ38: =IF(AND(R38>0,AF38>0),(AF38/(R38*1000)*1000),0) -> 926.74822 | AK38: =IF(AND(S38>0,AG38>0),(AG38/(S38*1000)*1000),0) -> 871.81448 | AL38: 4117.6 | AM38: 5425.3 | AN38: 3912.4 | AO38: =SUM(AL38:AN38) -> 13455.3 | AP38: =+[1]Aug!N33 -> 12923 | AQ38: =+AP38-AO38 -> -532.3 | AR38: =+AL38/AO38 -> 0.30602068 | AS38: =+AM38/AO38 -> 0.40320914 | AT38: =1-AR38-AS38 -> 0.29077018 | AU38: =+AR38*AQ38 -> -162.89481 | AV38: =+AS38*AQ38 -> -214.62823 | AW38: =+AT38*AQ38 -> -154.77697 | AX38: =+AL38+AU38 -> 3954.7052 | AY38: =+AM38+AV38 -> 5210.6718 | AZ38: =+AN38+AW38 -> 3757.623 | BA38: =+SUM(Efficiency2!K152:K153) -> 45.227016 | BB38: =BB37+BA38 -> 1393.9242 | BC38: =+R38/BA38 -> 0.87476476 | BD38: =+S38/BB38 -> 0.90444878
