Workbook

Sheet Report1
A3: PAPER MACHINE 14 DAILY REPORT 1
A6: Date | B6: Grade | C6: GSM | D6: Speed yankee (mpm) | E6: Speed reel (mpm) | F6: Creep ( % ) | G6: Real Eff PM ( % ) | H6: Real Eff PM vs Target (%) | I6: Real Eff FG vs Real Eff PM (%) | J6: Eff FG vs Target (%) | L6: Kapasitas Target (ton) | N6: Kapasitas Teori Real (ton) | P6: PM PROD Timbangan (TON) | R6: FINSHED GOODS (TON) | T6: GAS HOOD | Z6: STEAM (TON) | AF6: POWER (kWh) | BA6: Kapasitas Running (ton) | BC6: Eff FG vs Target Running(%)
T7: CONSUMPTION | V7: /TON PM. | X7: /TON FG. | Z7: CONSUMPTION | AB7: /TON PM. | AD7: /TON FG. | AF7: CONSUMPTION | AH7: /TON PM | AJ7: /TON FG | AL7: Gas based on report DCS | AO7: total | AP7: Flowmeter | AQ7: Selisih | AR7: % pengali | AU7: Adjust | AX7: PEMAKAIAN GAS
J8: TODAY | K8: TODATE | L8: TODAY | M8: TODATE | N8: TODAY | O8: TODATE | P8: TODAY | Q8: TODATE | R8: TODAY | S8: TODATE | T8: TODAY | U8: TODATE | V8: TODAY | W8: TODATE | X8: TODAY | Y8: TODATE | Z8: TODAY | AA8: TODATE | AB8: TODAY | AC8: TODATE | AD8: TODAY | AE8: TODATE | AF8: TODAY | AG8: TODATE | AH8: TODAY | AI8: TODATE | AJ8: TODAY | AK8: TODATE | AL8: 14 | AM8: 15 | AN8: 17 | AP8: PGN | AU8: 14 | AV8: 15 | AW8: 17 | AX8: 14 | AY8: 15 | AZ8: 17 | BA8: TODAY | BB8: TODATE | BC8: TODAY | BD8: TODATE
A9: 46023 | B9: Toilet | C9: 13 | D9: =+'1'!F42 -> 1176.1736 | E9: =+'1'!G42 -> 878.23514 | F9: =1-(E9/D9) -> 0.25331164 | G9: =+P9/N9 -> 0.92091197 | H9: =+P9/L9 -> 0.92091197 | I9: =+R9/P9 -> 1.0052225 | J9: =+R9/L9 -> 0.9257214 | K9: =+S9/M9 -> 0.9257214 | L9: =+Efficiency1!K6 -> 42.416649 | M9: =L9 -> 42.416649 | N9: =+Efficiency1!C6 -> 42.416649 | O9: =N9 -> 42.416649 | P9: ='1'!I38 -> 39.062 | Q9: =P9 -> 39.062 | R9: ='1'!I40 -> 39.266 | S9: =R9 -> 39.266 | T9: =+AX9 -> 5387.3708 | U9: =T9 -> 5387.3708 | V9: =T9/P9 -> 137.91846 | W9: =U9/Q9 -> 137.91846 | X9: =IF(AND(R9>0,T9>0),(T9/(R9*1000))*1000,0) -> 137.20193 | Y9: =IF(AND(S9>0,U9>0),U9/S9,0) -> 137.20193 | Z9: 50.3 | AA9: =Z9 -> 50.3 | AB9: =Z9/(P9) -> 1.2876965 | AC9: =AA9/(Q9) -> 1.2876965 | AD9: =IF(AND(R9>0,Z9>0),Z9/(R9),0) -> 1.2810065 | AE9: =IF(AND(S9>0,AA9>0),AA9/(S9),0) -> 1.2810065 | AF9: ='1'!I46 -> 38461.28 | AG9: =AF9 -> 38461.28 | AH9: =IF(AND(L9>0,AF9>0),(AF9/(P9*1000)*1000),0) -> 984.62137 | AI9: =IF(AND(M9>0,AG9>0),(AG9/(Q9*1000)*1000),0) -> 984.62137 | AJ9: =IF(AND(R9>0,AF9>0),(AF9/(R9*1000)*1000),0) -> 979.50593 | AK9: =IF(AND(S9>0,AG9>0),(AG9/(S9*1000)*1000),0) -> 979.50593 | AL9: 5632.1 | AM9: 4819.2 | AN9: 4440.8 | AO9: =SUM(AL9:AN9) -> 14892.1 | AP9: =+[1]Jan!N5 -> 14245 | AQ9: =+AP9-AO9 -> -647.1 | AR9: =+AL9/AO9 -> 0.37819381 | AS9: =+AM9/AO9 -> 0.32360782 | AT9: =1-AR9-AS9 -> 0.29819837 | AU9: =+AR9*AQ9 -> -244.72921 | AV9: =+AS9*AQ9 -> -209.40662 | AW9: =+AT9*AQ9 -> -192.96417 | AX9: =+AL9+AU9 -> 5387.3708 | AY9: =+AM9+AV9 -> 4609.7934 | AZ9: =+AN9+AW9 -> 4247.8358 | BA9: =+Efficiency2!K6 -> 42.416649 | BB9: =BA9 -> 42.416649 | BC9: =+R9/BA9 -> 0.9257214 | BD9: =+S9/BB9 -> 0.9257214
A10: =A9+1 -> 46024 | B10: Toilet | C10: 13 | D10: =+'2'!F42 -> 1170 | E10: =+'2'!G42 -> 865.8 | F10: =1-(E10/D10) -> 0.26 | G10: =+P10/N10 -> 0.93208203 | H10: =+P10/L10 -> 0.93208203 | I10: =+R10/P10 -> 0.9294181 | J10: =+R10/L10 -> 0.86629391 | K10: =+S10/M10 -> 0.89621952 | L10: =+Efficiency1!K11 -> 41.816062 | M10: =M9+L10 -> 84.232712 | N10: =+Efficiency1!C11 -> 41.816062 | O10: =O9+N10 -> 84.232712 | P10: ='2'!I38 -> 38.976 | Q10: =Q9+P10 -> 78.038 | R10: ='2'!I40 -> 36.225 | S10: =S9+R10 -> 75.491 | T10: =+AX10 -> 5472.3172 | U10: =T10+U9 -> 10859.688 | V10: =T10/P10 -> 140.40223 | W10: =U10/Q10 -> 139.15897 | X10: =IF(AND(R10>0,T10>0),(T10/(R10*1000))*1000,0) -> 151.06466 | Y10: =IF(AND(S10>0,U10>0),U10/S10,0) -> 143.85407 | Z10: 47.5 | AA10: =Z10+AA9 -> 97.8 | AB10: =Z10/(P10) -> 1.2186987 | AC10: =AA10/(Q10) -> 1.2532356 | AD10: =IF(AND(R10>0,Z10>0),Z10/(R10),0) -> 1.3112491 | AE10: =IF(AND(S10>0,AA10>0),AA10/(S10),0) -> 1.2955187 | AF10: ='2'!I46 -> 40110.8 | AG10: =AF10+AG9 -> 78572.08 | AH10: =IF(AND(L10>0,AF10>0),(AF10/(P10*1000)*1000),0) -> 1029.1154 | AI10: =IF(AND(M10>0,AG10>0),(AG10/(Q10*1000)*1000),0) -> 1006.8438 | AJ10: =IF(AND(R10>0,AF10>0),(AF10/(R10*1000)*1000),0) -> 1107.2685 | AK10: =IF(AND(S10>0,AG10>0),(AG10/(S10*1000)*1000),0) -> 1040.8139 | AL10: 5718.7 | AM10: 5450.5 | AN10: 3288.7 | AO10: =SUM(AL10:AN10) -> 14457.9 | AP10: =+[1]Jan!N6 -> 13835 | AQ10: =+AP10-AO10 -> -622.9 | AR10: =+AL10/AO10 -> 0.39554154 | AS10: =+AM10/AO10 -> 0.37699113 | AT10: =1-AR10-AS10 -> 0.22746734 | AU10: =+AR10*AQ10 -> -246.38282 | AV10: =+AS10*AQ10 -> -234.82777 | AW10: =+AT10*AQ10 -> -141.6894 | AX10: =+AL10+AU10 -> 5472.3172 | AY10: =+AM10+AV10 -> 5215.6722 | AZ10: =+AN10+AW10 -> 3147.0106 | BA10: =+Efficiency2!K11 -> 41.816062 | BB10: =BB9+BA10 -> 84.232712 | BC10: =+R10/BA10 -> 0.86629391 | BD10: =+S10/BB10 -> 0.89621952
A11: =A10+1 -> 46025 | B11: Toilet/Facial | C11: 13/12 | D11: =+'3'!F42 -> 1216.5278 | E11: =+'3'!G42 -> 916.41458 | F11: =1-(E11/D11) -> 0.24669654 | G11: =+P11/N11 -> 0.9373055 | H11: =+P11/L11 -> 0.91934953 | I11: =+R11/P11 -> 0.97734678 | J11: =+R11/L11 -> 0.8985233 | K11: =+S11/M11 -> 0.89699087 | L11: =+SUM(Efficiency1!K16:K18) -> 42.398455 | M11: =M10+L11 -> 126.63117 | N11: =+SUM(Efficiency1!C16:C18) -> 41.586228 | O11: =O10+N11 -> 125.81894 | P11: ='3'!I38 -> 38.979 | Q11: =Q10+P11 -> 117.017 | R11: ='3'!I40 -> 38.096 | S11: =S10+R11 -> 113.587 | T11: =+AX11 -> 5163.867 | U11: =T11+U10 -> 16023.555 | V11: =T11/P11 -> 132.47818 | W11: =U11/Q11 -> 136.93356 | X11: =IF(AND(R11>0,T11>0),(T11/(R11*1000))*1000,0) -> 135.5488 | Y11: =IF(AND(S11>0,U11>0),U11/S11,0) -> 141.06856 | Z11: 47.2 | AA11: =Z11+AA10 -> 145 | AB11: =Z11/(P11) -> 1.2109084 | AC11: =AA11/(Q11) -> 1.2391362 | AD11: =IF(AND(R11>0,Z11>0),Z11/(R11),0) -> 1.2389752 | AE11: =IF(AND(S11>0,AA11>0),AA11/(S11),0) -> 1.2765545 | AF11: ='3'!I46 -> 37896.56 | AG11: =AF11+AG10 -> 116468.64 | AH11: =IF(AND(L11>0,AF11>0),(AF11/(P11*1000)*1000),0) -> 972.23018 | AI11: =IF(AND(M11>0,AG11>0),(AG11/(Q11*1000)*1000),0) -> 995.31384 | AJ11: =IF(AND(R11>0,AF11>0),(AF11/(R11*1000)*1000),0) -> 994.7648 | AK11: =IF(AND(S11>0,AG11>0),(AG11/(S11*1000)*1000),0) -> 1025.3695 | AL11: 5409.1 | AM11: 5038.3 | AN11: 4494 | AO11: =SUM(AL11:AN11) -> 14941.4 | AP11: =+[1]Jan!N7 -> 14264 | AQ11: =+AP11-AO11 -> -677.4 | AR11: =+AL11/AO11 -> 0.36202096 | AS11: =+AM11/AO11 -> 0.33720401 | AT11: =1-AR11-AS11 -> 0.30077503 | AU11: =+AR11*AQ11 -> -245.233 | AV11: =+AS11*AQ11 -> -228.422 | AW11: =+AT11*AQ11 -> -203.745 | AX11: =+AL11+AU11 -> 5163.867 | AY11: =+AM11+AV11 -> 4809.878 | AZ11: =+AN11+AW11 -> 4290.255 | BA11: =+SUM(Efficiency2!K16:K17) -> 42.398455 | BB11: =BB10+BA11 -> 126.63117 | BC11: =+R11/BA11 -> 0.8985233 | BD11: =+S11/BB11 -> 0.89699087
A12: =A11+1 -> 46026 | B12: Facial | C12: 12 | D12: =+'4'!F42 -> 1230 | E12: =+'4'!G42 -> 934.8 | F12: =1-(E12/D12) -> 0.24 | G12: =+P12/N12 -> 0.92999172 | H12: =+P12/L12 -> 0.92999172 | I12: =+R12/P12 -> 0.96246894 | J12: =+R12/L12 -> 0.89508814 | K12: =+S12/M12 -> 0.89651356 | L12: =+Efficiency1!K21 -> 42.402528 | M12: =M11+L12 -> 169.03369 | N12: =+Efficiency1!C21 -> 42.402528 | O12: =O11+N12 -> 168.22147 | P12: ='4'!I38 -> 39.434 | Q12: =Q11+P12 -> 156.451 | R12: ='4'!I40 -> 37.954 | S12: =S11+R12 -> 151.541 | T12: =+AX12 -> 5173.5018 | U12: =T12+U11 -> 21197.057 | V12: =T12/P12 -> 131.19394 | W12: =U12/Q12 -> 135.48687 | X12: =IF(AND(R12>0,T12>0),(T12/(R12*1000))*1000,0) -> 136.30979 | Y12: =IF(AND(S12>0,U12>0),U12/S12,0) -> 139.87671 | Z12: 48.2 | AA12: =Z12+AA11 -> 193.2 | AB12: =Z12/(P12) -> 1.2222955 | AC12: =AA12/(Q12) -> 1.2348914 | AD12: =IF(AND(R12>0,Z12>0),Z12/(R12),0) -> 1.2699584 | AE12: =IF(AND(S12>0,AA12>0),AA12/(S12),0) -> 1.2749025 | AF12: ='4'!I46 -> 40047 | AG12: =AF12+AG11 -> 156515.64 | AH12: =IF(AND(L12>0,AF12>0),(AF12/(P12*1000)*1000),0) -> 1015.545 | AI12: =IF(AND(M12>0,AG12>0),(AG12/(Q12*1000)*1000),0) -> 1000.4132 | AJ12: =IF(AND(R12>0,AF12>0),(AF12/(R12*1000)*1000),0) -> 1055.1457 | AK12: =IF(AND(S12>0,AG12>0),(AG12/(S12*1000)*1000),0) -> 1032.827 | AL12: 5418.3 | AM12: 5188.8 | AN12: 4718.3 | AO12: =SUM(AL12:AN12) -> 15325.4 | AP12: =+[1]Jan!N8 -> 14633 | AQ12: =+AP12-AO12 -> -692.4 | AR12: =+AL12/AO12 -> 0.35355032 | AS12: =+AM12/AO12 -> 0.33857518 | AT12: =1-AR12-AS12 -> 0.30787451 | AU12: =+AR12*AQ12 -> -244.79824 | AV12: =+AS12*AQ12 -> -234.42945 | AW12: =+AT12*AQ12 -> -213.17231 | AX12: =+AL12+AU12 -> 5173.5018 | AY12: =+AM12+AV12 -> 4954.3705 | AZ12: =+AN12+AW12 -> 4505.1277 | BA12: =+Efficiency2!K21 -> 42.402528 | BB12: =BB11+BA12 -> 169.03369 | BC12: =+R12/BA12 -> 0.89508814 | BD12: =+S12/BB12 -> 0.89651356
A13: =A12+1 -> 46027 | B13: Facial | C13: 12/13,5/12,5 | D13: =+'5'!F42 -> 1223.0833 | E13: =+'5'!G42 -> 940.61 | F13: =1-(E13/D13) -> 0.23095183 | G13: =+P13/N13 -> 0.91366027 | H13: =+P13/L13 -> 0.90798196 | I13: =+R13/P13 -> 0.97933163 | J13: =+R13/L13 -> 0.88921545 | K13: =+S13/M13 -> 0.8949513 | L13: =+SUM(Efficiency1!K26:K28) -> 46.039461 | M13: =M12+L13 -> 215.07316 | N13: =+SUM(Efficiency1!C26:C28) -> 45.75333 | O13: =O12+N13 -> 213.9748 | P13: ='5'!I38 -> 41.803 | Q13: =Q12+P13 -> 198.254 | R13: ='5'!I40 -> 40.939 | S13: =S12+R13 -> 192.48 | T13: =+AX13 -> 5355.5718 | U13: =T13+U12 -> 26552.629 | V13: =T13/P13 -> 128.11453 | W13: =U13/Q13 -> 133.93237 | X13: =IF(AND(R13>0,T13>0),(T13/(R13*1000))*1000,0) -> 130.81833 | Y13: =IF(AND(S13>0,U13>0),U13/S13,0) -> 137.95007 | Z13: 53 | AA13: =Z13+AA12 -> 246.2 | AB13: =Z13/(P13) -> 1.2678516 | AC13: =AA13/(Q13) -> 1.2418413 | AD13: =IF(AND(R13>0,Z13>0),Z13/(R13),0) -> 1.2946091 | AE13: =IF(AND(S13>0,AA13>0),AA13/(S13),0) -> 1.2790939 | AF13: ='5'!I46 -> 37287.78 | AG13: =AF13+AG12 -> 193803.42 | AH13: =IF(AND(L13>0,AF13>0),(AF13/(P13*1000)*1000),0) -> 891.98813 | AI13: =IF(AND(M13>0,AG13>0),(AG13/(Q13*1000)*1000),0) -> 977.55112 | AJ13: =IF(AND(R13>0,AF13>0),(AF13/(R13*1000)*1000),0) -> 910.81316 | AK13: =IF(AND(S13>0,AG13>0),(AG13/(S13*1000)*1000),0) -> 1006.8756 | AL13: 5613 | AM13: 5501 | AN13: 4694 | AO13: =SUM(AL13:AN13) -> 15808 | AP13: =+[1]Jan!N9 -> 15083 | AQ13: =+AP13-AO13 -> -725 | AR13: =+AL13/AO13 -> 0.35507338 | AS13: =+AM13/AO13 -> 0.34798836 | AT13: =1-AR13-AS13 -> 0.29693826 | AU13: =+AR13*AQ13 -> -257.4282 | AV13: =+AS13*AQ13 -> -252.29156 | AW13: =+AT13*AQ13 -> -215.28024 | AX13: =+AL13+AU13 -> 5355.5718 | AY13: =+AM13+AV13 -> 5248.7084 | AZ13: =+AN13+AW13 -> 4478.7198 | BA13: =+SUM(Efficiency2!K26:K28) -> 46.039461 | BB13: =BB12+BA13 -> 215.07316 | BC13: =+R13/BA13 -> 0.88921545 | BD13: =+S13/BB13 -> 0.8949513
A14: =A13+1 -> 46028 | B14: Facial | C14: 12,5/12 | D14: =+'6'!F42 -> 1230 | E14: =+'6'!G42 -> 934.8 | F14: =1-(E14/D14) -> 0.24 | G14: =+P14/N14 -> 0.94196116 | H14: =+P14/L14 -> 0.94196116 | I14: =+R14/P14 -> 0.89613568 | J14: =+R14/L14 -> 0.84412501 | K14: =+S14/M14 -> 0.88642059 | L14: =+SUM(Efficiency1!K31:K32) -> 43.378646 | M14: =M13+L14 -> 258.4518 | N14: =+SUM(Efficiency1!C31:C32) -> 43.378646 | O14: =O13+N14 -> 257.35344 | P14: ='6'!I38 -> 40.861 | Q14: =Q13+P14 -> 239.115 | R14: ='6'!I40 -> 36.617 | S14: =S13+R14 -> 229.097 | T14: =+AX14 -> 5569.0332 | U14: =T14+U13 -> 32121.662 | V14: =T14/P14 -> 136.29214 | W14: =U14/Q14 -> 134.33562 | X14: =IF(AND(R14>0,T14>0),(T14/(R14*1000))*1000,0) -> 152.08873 | Y14: =IF(AND(S14>0,U14>0),U14/S14,0) -> 140.20987 | Z14: 50.9 | AA14: =Z14+AA13 -> 297.1 | AB14: =Z14/(P14) -> 1.2456866 | AC14: =AA14/(Q14) -> 1.2424984 | AD14: =IF(AND(R14>0,Z14>0),Z14/(R14),0) -> 1.3900647 | AE14: =IF(AND(S14>0,AA14>0),AA14/(S14),0) -> 1.2968306 | AF14: ='6'!I46 -> 40858.38 | AG14: =AF14+AG13 -> 234661.8 | AH14: =IF(AND(L14>0,AF14>0),(AF14/(P14*1000)*1000),0) -> 999.93588 | AI14: =IF(AND(M14>0,AG14>0),(AG14/(Q14*1000)*1000),0) -> 981.37633 | AJ14: =IF(AND(R14>0,AF14>0),(AF14/(R14*1000)*1000),0) -> 1115.8309 | AK14: =IF(AND(S14>0,AG14>0),(AG14/(S14*1000)*1000),0) -> 1024.2901 | AL14: 5594.8 | AM14: 2273 | AN14: 4986.4 | AO14: =SUM(AL14:AN14) -> 12854.2 | AP14: =+[1]Jan!N10 -> 12795 | AQ14: =+AP14-AO14 -> -59.2 | AR14: =+AL14/AO14 -> 0.43525074 | AS14: =+AM14/AO14 -> 0.17682936 | AT14: =1-AR14-AS14 -> 0.3879199 | AU14: =+AR14*AQ14 -> -25.766844 | AV14: =+AS14*AQ14 -> -10.468298 | AW14: =+AT14*AQ14 -> -22.964858 | AX14: =+AL14+AU14 -> 5569.0332 | AY14: =+AM14+AV14 -> 2262.5317 | AZ14: =+AN14+AW14 -> 4963.4351 | BA14: =+SUM(Efficiency2!K31:K32) -> 43.378646 | BB14: =BB13+BA14 -> 258.4518 | BC14: =+R14/BA14 -> 0.84412501 | BD14: =+S14/BB14 -> 0.88642059
A15: =A14+1 -> 46029 | B15: Facial | C15: 12 | D15: =+'7'!F42 -> 1230 | E15: =+'7'!G42 -> 934.8 | F15: =1-(E15/D15) -> 0.24 | G15: =+P15/N15 -> 0.94631883 | H15: =+P15/L15 -> 0.94631883 | I15: =+R15/P15 -> 0.95881815 | J15: =+R15/L15 -> 0.90734767 | K15: =+S15/M15 -> 0.88932167 | L15: =+Efficiency1!K36 -> 41.594861 | M15: =M14+L15 -> 300.04666 | N15: =+Efficiency1!C36 -> 41.594861 | O15: =O14+N15 -> 298.9483 | P15: ='7'!I38 -> 39.362 | Q15: =Q14+P15 -> 278.477 | R15: ='7'!I40 -> 37.741 | S15: =S14+R15 -> 266.838 | T15: =+AX15 -> 5682.3678 | U15: =T15+U14 -> 37804.029 | V15: =T15/P15 -> 144.36176 | W15: =U15/Q15 -> 135.75279 | X15: =IF(AND(R15>0,T15>0),(T15/(R15*1000))*1000,0) -> 150.56219 | Y15: =IF(AND(S15>0,U15>0),U15/S15,0) -> 141.67408 | Z15: 48.7 | AA15: =Z15+AA14 -> 345.8 | AB15: =Z15/(P15) -> 1.2372339 | AC15: =AA15/(Q15) -> 1.2417543 | AD15: =IF(AND(R15>0,Z15>0),Z15/(R15),0) -> 1.2903739 | AE15: =IF(AND(S15>0,AA15>0),AA15/(S15),0) -> 1.2959174 | AF15: ='7'!I46 -> 41157.44 | AG15: =AF15+AG14 -> 275819.24 | AH15: =IF(AND(L15>0,AF15>0),(AF15/(P15*1000)*1000),0) -> 1045.6135 | AI15: =IF(AND(M15>0,AG15>0),(AG15/(Q15*1000)*1000),0) -> 990.45609 | AJ15: =IF(AND(R15>0,AF15>0),(AF15/(R15*1000)*1000),0) -> 1090.5233 | AK15: =IF(AND(S15>0,AG15>0),(AG15/(S15*1000)*1000),0) -> 1033.658 | AL15: 5959.7 | AM15: 5069.6 | AN15: 5173.7 | AO15: =SUM(AL15:AN15) -> 16203 | AP15: =+[1]Jan!N11 -> 15449 | AQ15: =+AP15-AO15 -> -754 | AR15: =+AL15/AO15 -> 0.3678146 | AS15: =+AM15/AO15 -> 0.31288033 | AT15: =1-AR15-AS15 -> 0.31930507 | AU15: =+AR15*AQ15 -> -277.33221 | AV15: =+AS15*AQ15 -> -235.91177 | AW15: =+AT15*AQ15 -> -240.75602 | AX15: =+AL15+AU15 -> 5682.3678 | AY15: =+AM15+AV15 -> 4833.6882 | AZ15: =+AN15+AW15 -> 4932.944 | BA15: =+Efficiency2!K36 -> 41.594861 | BB15: =BB14+BA15 -> 300.04666 | BC15: =+R15/BA15 -> 0.90734767 | BD15: =+S15/BB15 -> 0.88932167
A16: =A15+1 -> 46030 | B16: Facial | C16: 12 | D16: =+'8'!F42 -> 1230 | E16: =+'8'!G42 -> 934.8 | F16: =1-(E16/D16) -> 0.24 | G16: =+P16/N16 -> 0.89345478 | H16: =+P16/L16 -> 0.89345478 | I16: =+R16/P16 -> 0.9784298 | J16: =+R16/L16 -> 0.87418278 | K16: =+S16/M16 -> 0.88747168 | L16: =+Efficiency1!K41 -> 41.770441 | M16: =M15+L16 -> 341.8171 | N16: =+Efficiency1!C41 -> 41.770441 | O16: =O15+N16 -> 340.71874 | P16: ='8'!I38 -> 37.32 | Q16: =Q15+P16 -> 315.797 | R16: ='8'!I40 -> 36.515 | S16: =S15+R16 -> 303.353 | T16: =+AX16 -> 5709.9831 | U16: =T16+U15 -> 43514.013 | V16: =T16/P16 -> 153.00062 | W16: =U16/Q16 -> 137.79109 | X16: =IF(AND(R16>0,T16>0),(T16/(R16*1000))*1000,0) -> 156.37363 | Y16: =IF(AND(S16>0,U16>0),U16/S16,0) -> 143.44349 | Z16: 47.4 | AA16: =Z16+AA15 -> 393.2 | AB16: =Z16/(P16) -> 1.2700965 | AC16: =AA16/(Q16) -> 1.2451037 | AD16: =IF(AND(R16>0,Z16>0),Z16/(R16),0) -> 1.2980967 | AE16: =IF(AND(S16>0,AA16>0),AA16/(S16),0) -> 1.2961797 | AF16: ='8'!I46 -> 37269.14 | AG16: =AF16+AG15 -> 313088.38 | AH16: =IF(AND(L16>0,AF16>0),(AF16/(P16*1000)*1000),0) -> 998.63719 | AI16: =IF(AND(M16>0,AG16>0),(AG16/(Q16*1000)*1000),0) -> 991.42291 | AJ16: =IF(AND(R16>0,AF16>0),(AF16/(R16*1000)*1000),0) -> 1020.6529 | AK16: =IF(AND(S16>0,AG16>0),(AG16/(S16*1000)*1000),0) -> 1032.0926 | AL16: 5979.3 | AM16: 5268.9 | AN16: 5194.4 | AO16: =SUM(AL16:AN16) -> 16442.6 | AP16: =+[1]Jan!N12 -> 15702 | AQ16: =+AP16-AO16 -> -740.6 | AR16: =+AL16/AO16 -> 0.36364687 | AS16: =+AM16/AO16 -> 0.32044202 | AT16: =1-AR16-AS16 -> 0.31591111 | AU16: =+AR16*AQ16 -> -269.31687 | AV16: =+AS16*AQ16 -> -237.31936 | AW16: =+AT16*AQ16 -> -233.96377 | AX16: =+AL16+AU16 -> 5709.9831 | AY16: =+AM16+AV16 -> 5031.5806 | AZ16: =+AN16+AW16 -> 4960.4362 | BA16: =+Efficiency2!K41 -> 41.770441 | BB16: =BB15+BA16 -> 341.8171 | BC16: =+R16/BA16 -> 0.87418278 | BD16: =+S16/BB16 -> 0.88747168
A17: =A16+1 -> 46031 | B17: Facial | C17: 12/13,5 | D17: =+'9'!F42 -> 1087.8484 | E17: =+'9'!G42 -> 826.76477 | F17: =1-(E17/D17) -> 0.24 | G17: =+P17/N17 -> 0.61950859 | H17: =+P17/L17 -> 0.53490385 | I17: =+R17/P17 -> 1.0024555 | J17: =+R17/L17 -> 0.53621733 | K17: =+S17/M17 -> 0.84485121 | L17: =+SUM(Efficiency1!K46:K47) -> 47.202876 | M17: =M16+L17 -> 389.01998 | N17: =+SUM(Efficiency1!C46:C47) -> 40.756497 | O17: =O16+N17 -> 381.47524 | P17: ='9'!I38 -> 25.249 | Q17: =Q16+P17 -> 341.046 | R17: ='9'!I40 -> 25.311 | S17: =S16+R17 -> 328.664 | T17: =+AX17 -> 2522.5856 | U17: =T17+U16 -> 46036.598 | V17: =T17/P17 -> 99.908338 | W17: =U17/Q17 -> 134.98648 | X17: =IF(AND(R17>0,T17>0),(T17/(R17*1000))*1000,0) -> 99.66361 | Y17: =IF(AND(S17>0,U17>0),U17/S17,0) -> 140.07192 | Z17: 39.9 | AA17: =Z17+AA16 -> 433.1 | AB17: =Z17/(P17) -> 1.5802606 | AC17: =AA17/(Q17) -> 1.2699167 | AD17: =IF(AND(R17>0,Z17>0),Z17/(R17),0) -> 1.5763897 | AE17: =IF(AND(S17>0,AA17>0),AA17/(S17),0) -> 1.3177592 | AF17: ='9'!I46 -> 24652.36 | AG17: =AF17+AG16 -> 337740.74 | AH17: =IF(AND(L17>0,AF17>0),(AF17/(P17*1000)*1000),0) -> 976.36976 | AI17: =IF(AND(M17>0,AG17>0),(AG17/(Q17*1000)*1000),0) -> 990.30846 | AJ17: =IF(AND(R17>0,AF17>0),(AF17/(R17*1000)*1000),0) -> 973.97811 | AK17: =IF(AND(S17>0,AG17>0),(AG17/(S17*1000)*1000),0) -> 1027.6171 | AL17: 2675.3 | AM17: 4110.5 | AN17: 4590.6 | AO17: =SUM(AL17:AN17) -> 11376.4 | AP17: =+[1]Jan!N13 -> 10727 | AQ17: =+AP17-AO17 -> -649.4 | AR17: =+AL17/AO17 -> 0.23516227 | AS17: =+AM17/AO17 -> 0.36131817 | AT17: =1-AR17-AS17 -> 0.40351957 | AU17: =+AR17*AQ17 -> -152.71438 | AV17: =+AS17*AQ17 -> -234.64002 | AW17: =+AT17*AQ17 -> -262.04561 | AX17: =+AL17+AU17 -> 2522.5856 | AY17: =+AM17+AV17 -> 3875.86 | AZ17: =+AN17+AW17 -> 4328.5544 | BA17: =+SUM(Efficiency2!K46:K47) -> 25.495137 | BB17: =BB16+BA17 -> 367.31224 | BC17: =+R17/BA17 -> 0.99277757 | BD17: =+S17/BB17 -> 0.89478096
A18: =A17+1 -> 46032 | B18: Facial | C18: 12/13,5 | D18: =+'10'!F42 -> 1071.2804 | E18: =+'10'!G42 -> 814.17307 | F18: =1-(E18/D18) -> 0.24 | G18: =+P18/N18 -> 0.86970669 | H18: =+P18/L18 -> 0.75623749 | I18: =+R18/P18 -> 0.88173928 | J18: =+R18/L18 -> 0.6668043 | K18: =+S18/M18 -> 0.82574194 | L18: =+SUM(Efficiency1!K53:K54) -> 46.772344 | M18: =M17+L18 -> 435.79232 | N18: =+SUM(Efficiency1!C53:C54) -> 40.670033 | O18: =O17+N18 -> 422.14528 | P18: ='10'!I38 -> 35.371 | Q18: =Q17+P18 -> 376.417 | R18: ='10'!I40 -> 31.188 | S18: =S17+R18 -> 359.852 | T18: =+AX18 -> 4453.5488 | U18: =T18+U17 -> 50490.147 | V18: =T18/P18 -> 125.90961 | W18: =U18/Q18 -> 134.13355 | X18: =IF(AND(R18>0,T18>0),(T18/(R18*1000))*1000,0) -> 142.79687 | Y18: =IF(AND(S18>0,U18>0),U18/S18,0) -> 140.30809 | Z18: 56.6 | AA18: =Z18+AA17 -> 489.7 | AB18: =Z18/(P18) -> 1.6001809 | AC18: =AA18/(Q18) -> 1.3009508 | AD18: =IF(AND(R18>0,Z18>0),Z18/(R18),0) -> 1.8148006 | AE18: =IF(AND(S18>0,AA18>0),AA18/(S18),0) -> 1.3608372 | AF18: ='10'!I46 -> 32748.46 | AG18: =AF18+AG17 -> 370489.2 | AH18: =IF(AND(L18>0,AF18>0),(AF18/(P18*1000)*1000),0) -> 925.85621 | AI18: =IF(AND(M18>0,AG18>0),(AG18/(Q18*1000)*1000),0) -> 984.25204 | AJ18: =IF(AND(R18>0,AF18>0),(AF18/(R18*1000)*1000),0) -> 1050.034 | AK18: =IF(AND(S18>0,AG18>0),(AG18/(S18*1000)*1000),0) -> 1029.5599 | AL18: 4135.1 | AM18: 4298.3 | AN18: 4668.6 | AO18: =SUM(AL18:AN18) -> 13102 | AP18: =+[1]Jan!N14 -> 14111 | AQ18: =+AP18-AO18 -> 1009 | AR18: =+AL18/AO18 -> 0.3156083 | AS18: =+AM18/AO18 -> 0.32806442 | AT18: =1-AR18-AS18 -> 0.35632728 | AU18: =+AR18*AQ18 -> 318.44878 | AV18: =+AS18*AQ18 -> 331.017 | AW18: =+AT18*AQ18 -> 359.53422 | AX18: =+AL18+AU18 -> 4453.5488 | AY18: =+AM18+AV18 -> 4629.317 | AZ18: =+AN18+AW18 -> 5028.1342 | BA18: =+SUM(Efficiency2!K53:K54) -> 38.705038 | BB18: =BB17+BA18 -> 406.01728 | BC18: =+R18/BA18 -> 0.80578657 | BD18: =+S18/BB18 -> 0.88629726
A19: =A18+1 -> 46033 | B19: Facial | C19: 13,5 | D19: =+'11'!F42 -> 1200 | E19: =+'11'!G42 -> 912 | F19: =1-(E19/D19) -> 0.24 | G19: =+P19/N19 -> 0.93132119 | H19: =+P19/L19 -> 0.90860604 | I19: =+R19/P19 -> 1.0305776 | J19: =+R19/L19 -> 0.93638906 | K19: =+S19/M19 -> 0.83678969 | L19: =+Efficiency1!K60 -> 48.338882 | M19: =M18+L19 -> 484.1312 | N19: =+Efficiency1!C60 -> 47.159885 | O19: =O18+N19 -> 469.30516 | P19: ='11'!I38 -> 43.921 | Q19: =Q18+P19 -> 420.338 | R19: ='11'!I40 -> 45.264 | S19: =S18+R19 -> 405.116 | T19: =+AX19 -> 5404.6366 | U19: =T19+U18 -> 55894.784 | V19: =T19/P19 -> 123.05359 | W19: =U19/Q19 -> 132.9758 | X19: =IF(AND(R19>0,T19>0),(T19/(R19*1000))*1000,0) -> 119.40254 | Y19: =IF(AND(S19>0,U19>0),U19/S19,0) -> 137.97229 | Z19: 54.8 | AA19: =Z19+AA18 -> 544.5 | AB19: =Z19/(P19) -> 1.2476947 | AC19: =AA19/(Q19) -> 1.2953861 | AD19: =IF(AND(R19>0,Z19>0),Z19/(R19),0) -> 1.2106752 | AE19: =IF(AND(S19>0,AA19>0),AA19/(S19),0) -> 1.3440595 | AF19: ='11'!I46 -> 39524.34 | AG19: =AF19+AG18 -> 410013.54 | AH19: =IF(AND(L19>0,AF19>0),(AF19/(P19*1000)*1000),0) -> 899.89618 | AI19: =IF(AND(M19>0,AG19>0),(AG19/(Q19*1000)*1000),0) -> 975.43772 | AJ19: =IF(AND(R19>0,AF19>0),(AF19/(R19*1000)*1000),0) -> 873.19592 | AK19: =IF(AND(S19>0,AG19>0),(AG19/(S19*1000)*1000),0) -> 1012.0892 | AL19: 6160.6 | AM19: 5979.3 | AN19: 5289.9 | AO19: =SUM(AL19:AN19) -> 17429.8 | AP19: =+[1]Jan!N15 -> 15291 | AQ19: =+AP19-AO19 -> -2138.8 | AR19: =+AL19/AO19 -> 0.35345213 | AS19: =+AM19/AO19 -> 0.34305041 | AT19: =1-AR19-AS19 -> 0.30349746 | AU19: =+AR19*AQ19 -> -755.96342 | AV19: =+AS19*AQ19 -> -733.71621 | AW19: =+AT19*AQ19 -> -649.12036 | AX19: =+AL19+AU19 -> 5404.6366 | AY19: =+AM19+AV19 -> 5245.5838 | AZ19: =+AN19+AW19 -> 4640.7796 | BA19: =+Efficiency2!K60 -> 48.338882 | BB19: =BB18+BA19 -> 454.35616 | BC19: =+R19/BA19 -> 0.93638906 | BD19: =+S19/BB19 -> 0.89162652
A20: =A19+1 -> 46034 | B20: Facial | C20: 13,5/12 | D20: =+'12'!F42 -> 1221.2083 | E20: =+'12'!G42 -> 931.635 | F20: =1-(E20/D20) -> 0.23712034 | G20: =+P20/N20 -> 0.93185084 | H20: =+P20/L20 -> 0.92442517 | I20: =+R20/P20 -> 0.95791573 | J20: =+R20/L20 -> 0.88552141 | K20: =+S20/M20 -> 0.84084364 | L20: =+SUM(Efficiency1!K65:K66) -> 43.928921 | M20: =M19+L20 -> 528.06013 | N20: =+SUM(Efficiency1!C65:C66) -> 43.578863 | O20: =O19+N20 -> 512.88402 | P20: ='12'!I38 -> 40.609 | Q20: =Q19+P20 -> 460.947 | R20: ='12'!I40 -> 38.9 | S20: =S19+R20 -> 444.016 | T20: =+AX20 -> 5666.3387 | U20: =T20+U19 -> 61561.122 | V20: =T20/P20 -> 139.53406 | W20: =U20/Q20 -> 133.55358 | X20: =IF(AND(R20>0,T20>0),(T20/(R20*1000))*1000,0) -> 145.66423 | Y20: =IF(AND(S20>0,U20>0),U20/S20,0) -> 138.64618 | Z20: 51.4 | AA20: =Z20+AA19 -> 595.9 | AB20: =Z20/(P20) -> 1.2657293 | AC20: =AA20/(Q20) -> 1.2927734 | AD20: =IF(AND(R20>0,Z20>0),Z20/(R20),0) -> 1.3213368 | AE20: =IF(AND(S20>0,AA20>0),AA20/(S20),0) -> 1.3420688 | AF20: ='12'!I46 -> 38692.88 | AG20: =AF20+AG19 -> 448706.42 | AH20: =IF(AND(L20>0,AF20>0),(AF20/(P20*1000)*1000),0) -> 952.81539 | AI20: =IF(AND(M20>0,AG20>0),(AG20/(Q20*1000)*1000),0) -> 973.44471 | AJ20: =IF(AND(R20>0,AF20>0),(AF20/(R20*1000)*1000),0) -> 994.67558 | AK20: =IF(AND(S20>0,AG20>0),(AG20/(S20*1000)*1000),0) -> 1010.5636 | AL20: 5877.5 | AM20: 6056.9 | AN20: 5236.5 | AO20: =SUM(AL20:AN20) -> 17170.9 | AP20: =+[1]Jan!N16 -> 16554 | AQ20: =+AP20-AO20 -> -616.9 | AR20: =+AL20/AO20 -> 0.34229423 | AS20: =+AM20/AO20 -> 0.35274214 | AT20: =1-AR20-AS20 -> 0.30496363 | AU20: =+AR20*AQ20 -> -211.16131 | AV20: =+AS20*AQ20 -> -217.60663 | AW20: =+AT20*AQ20 -> -188.13206 | AX20: =+AL20+AU20 -> 5666.3387 | AY20: =+AM20+AV20 -> 5839.2934 | AZ20: =+AN20+AW20 -> 5048.3679 | BA20: =+SUM(Efficiency2!K65:K66) -> 43.928921 | BB20: =BB19+BA20 -> 498.28508 | BC20: =+R20/BA20 -> 0.88552141 | BD20: =+S20/BB20 -> 0.89108829
A21: =A20+1 -> 46035 | B21: Facial | C21: 12/14 | D21: =+'13'!F42 -> 1212.2569 | E21: =+'13'!G42 -> 904.56583 | F21: =1-(E21/D21) -> 0.25381674 | G21: =+P21/N21 -> 0.95065588 | H21: =+P21/L21 -> 0.95065588 | I21: =+R21/P21 -> 0.93899882 | J21: =+R21/L21 -> 0.89266475 | K21: =+S21/M21 -> 0.84479973 | L21: =+SUM(Efficiency1!K70:K71) -> 43.644605 | M21: =M20+L21 -> 571.70473 | N21: =+SUM(Efficiency1!C70:C71) -> 43.644605 | O21: =O20+N21 -> 556.52863 | P21: ='13'!I38 -> 41.491 | Q21: =Q20+P21 -> 502.438 | R21: ='13'!I40 -> 38.96 | S21: =S20+R21 -> 482.976 | T21: =+AX21 -> 5614.3242 | U21: =T21+U20 -> 67175.446 | V21: =T21/P21 -> 135.31427 | W21: =U21/Q21 -> 133.69898 | X21: =IF(AND(R21>0,T21>0),(T21/(R21*1000))*1000,0) -> 144.10483 | Y21: =IF(AND(S21>0,U21>0),U21/S21,0) -> 139.08651 | Z21: 50 | AA21: =Z21+AA20 -> 645.9 | AB21: =Z21/(P21) -> 1.2050806 | AC21: =AA21/(Q21) -> 1.2855317 | AD21: =IF(AND(R21>0,Z21>0),Z21/(R21),0) -> 1.2833676 | AE21: =IF(AND(S21>0,AA21>0),AA21/(S21),0) -> 1.3373335 | AF21: ='13'!I46 -> 38028.86 | AG21: =AF21+AG20 -> 486735.28 | AH21: =IF(AND(L21>0,AF21>0),(AF21/(P21*1000)*1000),0) -> 916.55684 | AI21: =IF(AND(M21>0,AG21>0),(AG21/(Q21*1000)*1000),0) -> 968.74695 | AJ21: =IF(AND(R21>0,AF21>0),(AF21/(R21*1000)*1000),0) -> 976.1001 | AK21: =IF(AND(S21>0,AG21>0),(AG21/(S21*1000)*1000),0) -> 1007.7836 | AL21: 5809 | AM21: 5521.3 | AN21: 5200.7 | AO21: =SUM(AL21:AN21) -> 16531 | AP21: =+[1]Jan!N17 -> 15977 | AQ21: =+AP21-AO21 -> -554 | AR21: =+AL21/AO21 -> 0.3514004 | AS21: =+AM21/AO21 -> 0.33399673 | AT21: =1-AR21-AS21 -> 0.31460287 | AU21: =+AR21*AQ21 -> -194.67582 | AV21: =+AS21*AQ21 -> -185.03419 | AW21: =+AT21*AQ21 -> -174.28999 | AX21: =+AL21+AU21 -> 5614.3242 | AY21: =+AM21+AV21 -> 5336.2658 | AZ21: =+AN21+AW21 -> 5026.41 | BA21: =+SUM(Efficiency2!K70:K71) -> 43.644605 | BB21: =BB20+BA21 -> 541.92969 | BC21: =+R21/BA21 -> 0.89266475 | BD21: =+S21/BB21 -> 0.89121525
A22: =A21+1 -> 46036 | B22: Facial | C22: 12/13 | D22: =+'14'!F42 -> 1227.5417 | E22: =+'14'!G42 -> 932.93167 | F22: =1-(E22/D22) -> 0.24 | G22: =+P22/N22 -> 0.93094702 | H22: =+P22/L22 -> 0.92900787 | I22: =+R22/P22 -> 0.94603056 | J22: =+R22/L22 -> 0.87886984 | K22: =+S22/M22 -> 0.84719952 | L22: =+SUM(Efficiency1!K75:K76) -> 43.320408 | M22: =M21+L22 -> 615.02514 | N22: =+SUM(Efficiency1!C75:C76) -> 43.230172 | O22: =O21+N22 -> 599.7588 | P22: ='14'!I38 -> 40.245 | Q22: =Q21+P22 -> 542.683 | R22: ='14'!I40 -> 38.073 | S22: =S21+R22 -> 521.049 | T22: =+AX22 -> 5374.615 | U22: =T22+U21 -> 72550.061 | V22: =T22/P22 -> 133.5474 | W22: =U22/Q22 -> 133.68774 | X22: =IF(AND(R22>0,T22>0),(T22/(R22*1000))*1000,0) -> 141.16605 | Y22: =IF(AND(S22>0,U22>0),U22/S22,0) -> 139.23846 | Z22: 53 | AA22: =Z22+AA21 -> 698.9 | AB22: =Z22/(P22) -> 1.3169338 | AC22: =AA22/(Q22) -> 1.2878605 | AD22: =IF(AND(R22>0,Z22>0),Z22/(R22),0) -> 1.3920626 | AE22: =IF(AND(S22>0,AA22>0),AA22/(S22),0) -> 1.3413326 | AF22: ='14'!I46 -> 39390.38 | AG22: =AF22+AG21 -> 526125.66 | AH22: =IF(AND(L22>0,AF22>0),(AF22/(P22*1000)*1000),0) -> 978.76457 | AI22: =IF(AND(M22>0,AG22>0),(AG22/(Q22*1000)*1000),0) -> 969.48985 | AJ22: =IF(AND(R22>0,AF22>0),(AF22/(R22*1000)*1000),0) -> 1034.6014 | AK22: =IF(AND(S22>0,AG22>0),(AG22/(S22*1000)*1000),0) -> 1009.7432 | AL22: 5594.4 | AM22: 6001.1 | AN22: 5046.3 | AO22: =SUM(AL22:AN22) -> 16641.8 | AP22: =+[1]Jan!N18 -> 15988 | AQ22: =+AP22-AO22 -> -653.8 | AR22: =+AL22/AO22 -> 0.33616556 | AS22: =+AM22/AO22 -> 0.36060402 | AT22: =1-AR22-AS22 -> 0.30323042 | AU22: =+AR22*AQ22 -> -219.78504 | AV22: =+AS22*AQ22 -> -235.76291 | AW22: =+AT22*AQ22 -> -198.25205 | AX22: =+AL22+AU22 -> 5374.615 | AY22: =+AM22+AV22 -> 5765.3371 | AZ22: =+AN22+AW22 -> 4848.048 | BA22: =+SUM(Efficiency2!K75:K76) -> 43.320408 | BB22: =BB21+BA22 -> 585.25009 | BC22: =+R22/BA22 -> 0.87886984 | BD22: =+S22/BB22 -> 0.89030144
A23: =A22+1 -> 46037 | B23: Facial | C23: 12/13/16 | D23: =+'15'!F42 -> 1107.8958 | E23: =+'15'!G42 -> 825.05292 | F23: =1-(E23/D23) -> 0.25529739 | G23: =+P23/N23 -> 0.94455752 | H23: =+P23/L23 -> 0.8754591 | I23: =+R23/P23 -> 0.94968866 | J23: =+R23/L23 -> 0.83141358 | K23: =+S23/M23 -> 0.84595075 | L23: =+SUM(Efficiency1!K80:K82) -> 52.831709 | M23: =M22+L23 -> 667.85685 | N23: =+SUM(Efficiency1!C80:C82) -> 48.966843 | O23: =O22+N23 -> 648.72564 | P23: ='15'!I38 -> 46.252 | Q23: =Q22+P23 -> 588.935 | R23: ='15'!I40 -> 43.925 | S23: =S22+R23 -> 564.974 | T23: =+AX23 -> 4986.9277 | U23: =T23+U22 -> 77536.989 | V23: =T23/P23 -> 107.8208 | W23: =U23/Q23 -> 131.65628 | X23: =IF(AND(R23>0,T23>0),(T23/(R23*1000))*1000,0) -> 113.53279 | Y23: =IF(AND(S23>0,U23>0),U23/S23,0) -> 137.23992 | Z23: 52.3 | AA23: =Z23+AA22 -> 751.2 | AB23: =Z23/(P23) -> 1.1307619 | AC23: =AA23/(Q23) -> 1.2755228 | AD23: =IF(AND(R23>0,Z23>0),Z23/(R23),0) -> 1.1906659 | AE23: =IF(AND(S23>0,AA23>0),AA23/(S23),0) -> 1.3296187 | AF23: ='15'!I46 -> 35513.52 | AG23: =AF23+AG22 -> 561639.18 | AH23: =IF(AND(L23>0,AF23>0),(AF23/(P23*1000)*1000),0) -> 767.82669 | AI23: =IF(AND(M23>0,AG23>0),(AG23/(Q23*1000)*1000),0) -> 953.65224 | AJ23: =IF(AND(R23>0,AF23>0),(AF23/(R23*1000)*1000),0) -> 808.50359 | AK23: =IF(AND(S23>0,AG23>0),(AG23/(S23*1000)*1000),0) -> 994.09739 | AL23: 5286.7 | AM23: 5943.4 | AN23: 4915.4 | AO23: =SUM(AL23:AN23) -> 16145.5 | AP23: =+[1]Jan!N19 -> 15230 | AQ23: =+AP23-AO23 -> -915.5 | AR23: =+AL23/AO23 -> 0.32744108 | AS23: =+AM23/AO23 -> 0.36811495 | AT23: =1-AR23-AS23 -> 0.30444396 | AU23: =+AR23*AQ23 -> -299.77231 | AV23: =+AS23*AQ23 -> -337.00924 | AW23: =+AT23*AQ23 -> -278.71845 | AX23: =+AL23+AU23 -> 4986.9277 | AY23: =+AM23+AV23 -> 5606.3908 | AZ23: =+AN23+AW23 -> 4636.6816 | BA23: =+SUM(Efficiency2!K80:K82) -> 52.831709 | BB23: =BB22+BA23 -> 638.0818 | BC23: =+R23/BA23 -> 0.83141358 | BD23: =+S23/BB23 -> 0.88542566
A24: =A23+1 -> 46038 | B24: Facial | C24: 16/13 | D24: =+'16'!F42 -> 1179.1667 | E24: =+'16'!G42 -> 887.07833 | F24: =1-(E24/D24) -> 0.24770742 | G24: =+P24/N24 -> 0.94963607 | H24: =+P24/L24 -> 0.91643247 | I24: =+R24/P24 -> 0.88451966 | J24: =+R24/L24 -> 0.81060254 | K24: =+S24/M24 -> 0.84357005 | L24: =+SUM(Efficiency1!K85:K86) -> 48.228322 | M24: =M23+L24 -> 716.08517 | N24: =+SUM(Efficiency1!C85:C86) -> 46.54204 | O24: =O23+N24 -> 695.26768 | P24: ='16'!I38 -> 44.198 | Q24: =Q23+P24 -> 633.133 | R24: ='16'!I40 -> 39.094 | S24: =S23+R24 -> 604.068 | T24: =+AX24 -> 5332.2498 | U24: =T24+U23 -> 82869.239 | V24: =T24/P24 -> 120.64459 | W24: =U24/Q24 -> 130.88757 | X24: =IF(AND(R24>0,T24>0),(T24/(R24*1000))*1000,0) -> 136.39561 | Y24: =IF(AND(S24>0,U24>0),U24/S24,0) -> 137.18528 | Z24: 54.8 | AA24: =Z24+AA23 -> 806 | AB24: =Z24/(P24) -> 1.2398751 | AC24: =AA24/(Q24) -> 1.2730343 | AD24: =IF(AND(R24>0,Z24>0),Z24/(R24),0) -> 1.4017496 | AE24: =IF(AND(S24>0,AA24>0),AA24/(S24),0) -> 1.3342869 | AF24: ='16'!I46 -> 37061.78 | AG24: =AF24+AG23 -> 598700.96 | AH24: =IF(AND(L24>0,AF24>0),(AF24/(P24*1000)*1000),0) -> 838.53975 | AI24: =IF(AND(M24>0,AG24>0),(AG24/(Q24*1000)*1000),0) -> 945.61642 | AJ24: =IF(AND(R24>0,AF24>0),(AF24/(R24*1000)*1000),0) -> 948.01709 | AK24: =IF(AND(S24>0,AG24>0),(AG24/(S24*1000)*1000),0) -> 991.11517 | AL24: 5398 | AM24: 5900.1 | AN24: 4768.6 | AO24: =SUM(AL24:AN24) -> 16066.7 | AP24: =+[1]Jan!N20 -> 15871 | AQ24: =+AP24-AO24 -> -195.7 | AR24: =+AL24/AO24 -> 0.33597441 | AS24: =+AM24/AO24 -> 0.36722538 | AT24: =1-AR24-AS24 -> 0.29680021 | AU24: =+AR24*AQ24 -> -65.750191 | AV24: =+AS24*AQ24 -> -71.866007 | AW24: =+AT24*AQ24 -> -58.083802 | AX24: =+AL24+AU24 -> 5332.2498 | AY24: =+AM24+AV24 -> 5828.234 | AZ24: =+AN24+AW24 -> 4710.5162 | BA24: =+SUM(Efficiency2!K85:K86) -> 48.228322 | BB24: =BB23+BA24 -> 686.31012 | BC24: =+R24/BA24 -> 0.81060254 | BD24: =+S24/BB24 -> 0.88016769
A25: =A24+1 -> 46039 | B25: Facial | C25: 13 | D25: =+'17'!F42 -> 1224.9583 | E25: =+'17'!G42 -> 930.96833 | F25: =1-(E25/D25) -> 0.24 | G25: =+P25/N25 -> 1.0209196 | H25: =+P25/L25 -> 1.0167349 | I25: =+R25/P25 -> 0.94984868 | J25: =+R25/L25 -> 0.96574431 | K25: =+S25/M25 -> 0.85086899 | L25: =+Efficiency1!K90 -> 45.498586 | M25: =M24+L25 -> 761.58375 | N25: =+Efficiency1!C90 -> 45.312091 | O25: =O24+N25 -> 740.57977 | P25: ='17'!I38 -> 46.26 | Q25: =Q24+P25 -> 679.393 | R25: ='17'!I40 -> 43.94 | S25: =S24+R25 -> 648.008 | T25: =+AX25 -> 5587.7336 | U25: =T25+U24 -> 88456.973 | V25: =T25/P25 -> 120.78975 | W25: =U25/Q25 -> 130.20001 | X25: =IF(AND(R25>0,T25>0),(T25/(R25*1000))*1000,0) -> 127.16736 | Y25: =IF(AND(S25>0,U25>0),U25/S25,0) -> 136.50599 | Z25: 56 | AA25: =Z25+AA24 -> 862 | AB25: =Z25/(P25) -> 1.2105491 | AC25: =AA25/(Q25) -> 1.2687796 | AD25: =IF(AND(R25>0,Z25>0),Z25/(R25),0) -> 1.2744652 | AE25: =IF(AND(S25>0,AA25>0),AA25/(S25),0) -> 1.3302305 | AF25: ='17'!I46 -> 36600.24 | AG25: =AF25+AG24 -> 635301.2 | AH25: =IF(AND(L25>0,AF25>0),(AF25/(P25*1000)*1000),0) -> 791.18547 | AI25: =IF(AND(M25>0,AG25>0),(AG25/(Q25*1000)*1000),0) -> 935.10119 | AJ25: =IF(AND(R25>0,AF25>0),(AF25/(R25*1000)*1000),0) -> 832.95949 | AK25: =IF(AND(S25>0,AG25>0),(AG25/(S25*1000)*1000),0) -> 980.39098 | AL25: 5716.1 | AM25: 5329.9 | AN25: 4837.7 | AO25: =SUM(AL25:AN25) -> 15883.7 | AP25: =+[1]Jan!N21 -> 15527 | AQ25: =+AP25-AO25 -> -356.7 | AR25: =+AL25/AO25 -> 0.35987207 | AS25: =+AM25/AO25 -> 0.33555784 | AT25: =1-AR25-AS25 -> 0.30457009 | AU25: =+AR25*AQ25 -> -128.36637 | AV25: =+AS25*AQ25 -> -119.69348 | AW25: =+AT25*AQ25 -> -108.64015 | AX25: =+AL25+AU25 -> 5587.7336 | AY25: =+AM25+AV25 -> 5210.2065 | AZ25: =+AN25+AW25 -> 4729.0598 | BA25: =+Efficiency2!K90 -> 45.498586 | BB25: =BB24+BA25 -> 731.80871 | BC25: =+R25/BA25 -> 0.96574431 | BD25: =+S25/BB25 -> 0.88548823
A26: =A25+1 -> 46040 | B26: Facial | C26: 13/13,5 | D26: =+'18'!F42 -> 1230 | E26: =+'18'!G42 -> 934.8 | F26: =1-(E26/D26) -> 0.24 | G26: =+P26/N26 -> 0.92774924 | H26: =+P26/L26 -> 0.92774924 | I26: =+R26/P26 -> 0.94727984 | J26: =+R26/L26 -> 0.87883815 | K26: =+S26/M26 -> 0.8525075 | L26: =+SUM(Efficiency1!K95:K96) -> 47.392116 | M26: =M25+L26 -> 808.97587 | N26: =+SUM(Efficiency1!C95:C96) -> 47.392116 | O26: =O25+N26 -> 787.97189 | P26: ='18'!I38 -> 43.968 | Q26: =Q25+P26 -> 723.361 | R26: ='18'!I40 -> 41.65 | S26: =S25+R26 -> 689.658 | T26: =+AX26 -> 5314.1827 | U26: =T26+U25 -> 93771.155 | V26: =T26/P26 -> 120.86478 | W26: =U26/Q26 -> 129.63258 | X26: =IF(AND(R26>0,T26>0),(T26/(R26*1000))*1000,0) -> 127.59142 | Y26: =IF(AND(S26>0,U26>0),U26/S26,0) -> 135.96762 | Z26: 53.7 | AA26: =Z26+AA25 -> 915.7 | AB26: =Z26/(P26) -> 1.2213428 | AC26: =AA26/(Q26) -> 1.2658963 | AD26: =IF(AND(R26>0,Z26>0),Z26/(R26),0) -> 1.2893157 | AE26: =IF(AND(S26>0,AA26>0),AA26/(S26),0) -> 1.3277596 | AF26: ='18'!I46 -> 39292.02 | AG26: =AF26+AG25 -> 674593.22 | AH26: =IF(AND(L26>0,AF26>0),(AF26/(P26*1000)*1000),0) -> 893.65038 | AI26: =IF(AND(M26>0,AG26>0),(AG26/(Q26*1000)*1000),0) -> 932.58168 | AJ26: =IF(AND(R26>0,AF26>0),(AF26/(R26*1000)*1000),0) -> 943.38583 | AK26: =IF(AND(S26>0,AG26>0),(AG26/(S26*1000)*1000),0) -> 978.15616 | AL26: 5747 | AM26: 5820.3 | AN26: 4665.2 | AO26: =SUM(AL26:AN26) -> 16232.5 | AP26: =+[1]Jan!N22 -> 15010 | AQ26: =+AP26-AO26 -> -1222.5 | AR26: =+AL26/AO26 -> 0.35404282 | AS26: =+AM26/AO26 -> 0.35855845 | AT26: =1-AR26-AS26 -> 0.28739874 | AU26: =+AR26*AQ26 -> -432.81734 | AV26: =+AS26*AQ26 -> -438.3377 | AW26: =+AT26*AQ26 -> -351.34496 | AX26: =+AL26+AU26 -> 5314.1827 | AY26: =+AM26+AV26 -> 5381.9623 | AZ26: =+AN26+AW26 -> 4313.855 | BA26: =+SUM(Efficiency2!K95:K96) -> 47.392116 | BB26: =BB25+BA26 -> 779.20083 | BC26: =+R26/BA26 -> 0.87883815 | BD26: =+S26/BB26 -> 0.88508376
A27: =A26+1 -> 46041 | B27: Facial | C27: 13,5 | D27: =+'19'!F42 -> 1208.8889 | E27: =+'19'!G42 -> 918.75556 | F27: =1-(E27/D27) -> 0.24 | G27: =+P27/N27 -> 0.93468178 | H27: =+P27/L27 -> 0.91863937 | I27: =+R27/P27 -> 0.97966491 | J27: =+R27/L27 -> 0.89995876 | K27: =+S27/M27 -> 0.855183 | L27: =+Efficiency1!K100 -> 48.338882 | M27: =M26+L27 -> 857.31475 | N27: =+Efficiency1!C100 -> 47.509217 | O27: =O26+N27 -> 835.48111 | P27: ='19'!I38 -> 44.406 | Q27: =Q26+P27 -> 767.767 | R27: ='19'!I40 -> 43.503 | S27: =S26+R27 -> 733.161 | T27: =+AX27 -> 5468.3955 | U27: =T27+U26 -> 99239.551 | V27: =T27/P27 -> 123.14542 | W27: =U27/Q27 -> 129.25738 | X27: =IF(AND(R27>0,T27>0),(T27/(R27*1000))*1000,0) -> 125.70157 | Y27: =IF(AND(S27>0,U27>0),U27/S27,0) -> 135.35847 | Z27: 54.4 | AA27: =Z27+AA26 -> 970.1 | AB27: =Z27/(P27) -> 1.2250597 | AC27: =AA27/(Q27) -> 1.2635344 | AD27: =IF(AND(R27>0,Z27>0),Z27/(R27),0) -> 1.2504885 | AE27: =IF(AND(S27>0,AA27>0),AA27/(S27),0) -> 1.3231746 | AF27: ='19'!I46 -> 38192.98 | AG27: =AF27+AG26 -> 712786.2 | AH27: =IF(AND(L27>0,AF27>0),(AF27/(P27*1000)*1000),0) -> 860.08602 | AI27: =IF(AND(M27>0,AG27>0),(AG27/(Q27*1000)*1000),0) -> 928.38869 | AJ27: =IF(AND(R27>0,AF27>0),(AF27/(R27*1000)*1000),0) -> 877.93899 | AK27: =IF(AND(S27>0,AG27>0),(AG27/(S27*1000)*1000),0) -> 972.20965 | AL27: 5717.3 | AM27: 6078 | AN27: 4051.6 | AO27: =SUM(AL27:AN27) -> 15846.9 | AP27: =+[1]Jan!N23 -> 15157 | AQ27: =+AP27-AO27 -> -689.9 | AR27: =+AL27/AO27 -> 0.3607835 | AS27: =+AM27/AO27 -> 0.38354505 | AT27: =1-AR27-AS27 -> 0.25567146 | AU27: =+AR27*AQ27 -> -248.90453 | AV27: =+AS27*AQ27 -> -264.60773 | AW27: =+AT27*AQ27 -> -176.38774 | AX27: =+AL27+AU27 -> 5468.3955 | AY27: =+AM27+AV27 -> 5813.3923 | AZ27: =+AN27+AW27 -> 3875.2123 | BA27: =+Efficiency2!K100 -> 48.338882 | BB27: =BB26+BA27 -> 827.53971 | BC27: =+R27/BA27 -> 0.89995876 | BD27: =+S27/BB27 -> 0.88595265
A28: =A27+1 -> 46042 | B28: Facial | C28: 13,5/13 | D28: =+'20'!F42 -> 1225.375 | E28: =+'20'!G42 -> 931.285 | F28: =1-(E28/D28) -> 0.24 | G28: =+P28/N28 -> 0.97326292 | H28: =+P28/L28 -> 0.96951172 | I28: =+R28/P28 -> 1.0133855 | J28: =+R28/L28 -> 0.98248915 | K28: =+S28/M28 -> 0.86182068 | L28: =+SUM(Efficiency1!K105:K106) -> 47.15879 | M28: =M27+L28 -> 904.47354 | N28: =+SUM(Efficiency1!C105:C106) -> 46.977028 | O28: =O27+N28 -> 882.45814 | P28: ='20'!I38 -> 45.721 | Q28: =Q27+P28 -> 813.488 | R28: ='20'!I40 -> 46.333 | S28: =S27+R28 -> 779.494 | T28: =+AX28 -> 5498.6401 | U28: =T28+U27 -> 104738.19 | V28: =T28/P28 -> 120.26509 | W28: =U28/Q28 -> 128.75198 | X28: =IF(AND(R28>0,T28>0),(T28/(R28*1000))*1000,0) -> 118.67654 | Y28: =IF(AND(S28>0,U28>0),U28/S28,0) -> 134.3669 | Z28: 54.3 | AA28: =Z28+AA27 -> 1024.4 | AB28: =Z28/(P28) -> 1.1876381 | AC28: =AA28/(Q28) -> 1.2592687 | AD28: =IF(AND(R28>0,Z28>0),Z28/(R28),0) -> 1.1719509 | AE28: =IF(AND(S28>0,AA28>0),AA28/(S28),0) -> 1.3141859 | AF28: ='20'!I46 -> 39205.32 | AG28: =AF28+AG27 -> 751991.52 | AH28: =IF(AND(L28>0,AF28>0),(AF28/(P28*1000)*1000),0) -> 857.49043 | AI28: =IF(AND(M28>0,AG28>0),(AG28/(Q28*1000)*1000),0) -> 924.40395 | AJ28: =IF(AND(R28>0,AF28>0),(AF28/(R28*1000)*1000),0) -> 846.16407 | AK28: =IF(AND(S28>0,AG28>0),(AG28/(S28*1000)*1000),0) -> 964.71752 | AL28: 5796.5 | AM28: 6106.5 | AN28: 3860 | AO28: =SUM(AL28:AN28) -> 15763 | AP28: =+[1]Jan!N24 -> 14953 | AQ28: =+AP28-AO28 -> -810 | AR28: =+AL28/AO28 -> 0.36772822 | AS28: =+AM28/AO28 -> 0.38739453 | AT28: =1-AR28-AS28 -> 0.24487724 | AU28: =+AR28*AQ28 -> -297.85986 | AV28: =+AS28*AQ28 -> -313.78957 | AW28: =+AT28*AQ28 -> -198.35057 | AX28: =+AL28+AU28 -> 5498.6401 | AY28: =+AM28+AV28 -> 5792.7104 | AZ28: =+AN28+AW28 -> 3661.6494 | BA28: =+SUM(Efficiency2!K105:K106) -> 47.15879 | BB28: =BB27+BA28 -> 874.6985 | BC28: =+R28/BA28 -> 0.98248915 | BD28: =+S28/BB28 -> 0.89115735
A29: =A28+1 -> 46043 | B29: Facial | C29: 13/11/14 | D29: =+'21'!F42 -> 1228.3333 | E29: =+'21'!G42 -> 933.53333 | F29: =1-(E29/D29) -> 0.24 | G29: =+P29/N29 -> 0.96690557 | H29: =+P29/L29 -> 0.9653767 | I29: =+R29/P29 -> 0.94547997 | J29: =+R29/L29 -> 0.91274434 | K29: =+S29/M29 -> 0.86412965 | L29: =+SUM(Efficiency1!K110:K112) -> 42.95836 | M29: =M28+L29 -> 947.4319 | N29: =+SUM(Efficiency1!C110:C112) -> 42.890434 | O29: =O28+N29 -> 925.34857 | P29: ='21'!I38 -> 41.471 | Q29: =Q28+P29 -> 854.959 | R29: ='21'!I40 -> 39.21 | S29: =S28+R29 -> 818.704 | T29: =+AX29 -> 5231.3554 | U29: =T29+U28 -> 109969.55 | V29: =T29/P29 -> 126.14491 | W29: =U29/Q29 -> 128.62552 | X29: =IF(AND(R29>0,T29>0),(T29/(R29*1000))*1000,0) -> 133.41891 | Y29: =IF(AND(S29>0,U29>0),U29/S29,0) -> 134.3215 | Z29: 54.4 | AA29: =Z29+AA28 -> 1078.8 | AB29: =Z29/(P29) -> 1.31176 | AC29: =AA29/(Q29) -> 1.2618149 | AD29: =IF(AND(R29>0,Z29>0),Z29/(R29),0) -> 1.3874012 | AE29: =IF(AND(S29>0,AA29>0),AA29/(S29),0) -> 1.3176924 | AF29: ='21'!I46 -> 38765.38 | AG29: =AF29+AG28 -> 790756.9 | AH29: =IF(AND(L29>0,AF29>0),(AF29/(P29*1000)*1000),0) -> 934.75875 | AI29: =IF(AND(M29>0,AG29>0),(AG29/(Q29*1000)*1000),0) -> 924.90622 | AJ29: =IF(AND(R29>0,AF29>0),(AF29/(R29*1000)*1000),0) -> 988.66055 | AK29: =IF(AND(S29>0,AG29>0),(AG29/(S29*1000)*1000),0) -> 965.86422 | AL29: 5481.5 | AM29: 5700.1 | AN29: 3861.9 | AO29: =SUM(AL29:AN29) -> 15043.5 | AP29: =+[1]Jan!N25 -> 14357 | AQ29: =+AP29-AO29 -> -686.5 | AR29: =+AL29/AO29 -> 0.36437664 | AS29: =+AM29/AO29 -> 0.37890783 | AT29: =1-AR29-AS29 -> 0.25671552 | AU29: =+AR29*AQ29 -> -250.14456 | AV29: =+AS29*AQ29 -> -260.12023 | AW29: =+AT29*AQ29 -> -176.23521 | AX29: =+AL29+AU29 -> 5231.3554 | AY29: =+AM29+AV29 -> 5439.9798 | AZ29: =+AN29+AW29 -> 3685.6648 | BA29: =+SUM(Efficiency2!K110:K112) -> 42.95836 | BB29: =BB28+BA29 -> 917.65686 | BC29: =+R29/BA29 -> 0.91274434 | BD29: =+S29/BB29 -> 0.89216791
A30: =A29+1 -> 46044 | B30: Facial/Toilet | C30: 14/13 | D30: =+'22'!F42 -> 1221.1111 | E30: =+'22'!G42 -> 928.04444 | F30: =1-(E30/D30) -> 0.24 | G30: =+P30/N30 -> 0.96004106 | H30: =+P30/L30 -> 0.95243101 | I30: =+R30/P30 -> 0.97792226 | J30: =+R30/L30 -> 0.93140348 | K30: =+S30/M30 -> 0.86722546 | L30: =+SUM(Efficiency1!K114:K115) -> 45.701998 | M30: =M29+L30 -> 993.1339 | N30: =+SUM(Efficiency1!C114:C115) -> 45.339727 | O30: =O29+N30 -> 970.6883 | P30: ='22'!I38 -> 43.528 | Q30: =Q29+P30 -> 898.487 | R30: ='22'!I40 -> 42.567 | S30: =S29+R30 -> 861.271 | T30: =+AX30 -> 5611.1446 | U30: =T30+U29 -> 115580.69 | V30: =T30/P30 -> 128.90886 | W30: =U30/Q30 -> 128.63925 | X30: =IF(AND(R30>0,T30>0),(T30/(R30*1000))*1000,0) -> 131.81912 | Y30: =IF(AND(S30>0,U30>0),U30/S30,0) -> 134.19782 | Z30: 56.3 | AA30: =Z30+AA29 -> 1135.1 | AB30: =Z30/(P30) -> 1.2934203 | AC30: =AA30/(Q30) -> 1.263346 | AD30: =IF(AND(R30>0,Z30>0),Z30/(R30),0) -> 1.3226208 | AE30: =IF(AND(S30>0,AA30>0),AA30/(S30),0) -> 1.3179359 | AF30: ='22'!I46 -> 41312.34 | AG30: =AF30+AG29 -> 832069.24 | AH30: =IF(AND(L30>0,AF30>0),(AF30/(P30*1000)*1000),0) -> 949.09805 | AI30: =IF(AND(M30>0,AG30>0),(AG30/(Q30*1000)*1000),0) -> 926.07822 | AJ30: =IF(AND(R30>0,AF30>0),(AF30/(R30*1000)*1000),0) -> 970.52505 | AK30: =IF(AND(S30>0,AG30>0),(AG30/(S30*1000)*1000),0) -> 966.09457 | AL30: 5897.3 | AM30: 5999.3 | AN30: 3957.7 | AO30: =SUM(AL30:AN30) -> 15854.3 | AP30: =+[1]Jan!N26 -> 15085 | AQ30: =+AP30-AO30 -> -769.3 | AR30: =+AL30/AO30 -> 0.37196849 | AS30: =+AM30/AO30 -> 0.37840207 | AT30: =1-AR30-AS30 -> 0.24962944 | AU30: =+AR30*AQ30 -> -286.15536 | AV30: =+AS30*AQ30 -> -291.10472 | AW30: =+AT30*AQ30 -> -192.03993 | AX30: =+AL30+AU30 -> 5611.1446 | AY30: =+AM30+AV30 -> 5708.1953 | AZ30: =+AN30+AW30 -> 3765.6601 | BA30: =+SUM(Efficiency2!K114:K115) -> 45.701998 | BB30: =BB29+BA30 -> 963.35886 | BC30: =+R30/BA30 -> 0.93140348 | BD30: =+S30/BB30 -> 0.89402925
A31: =A30+1 -> 46045 | B31: Toilet | C31: 13 | D31: =+'23'!F42 -> 1042.0833 | E31: =+'23'!G42 -> 791.98333 | F31: =1-(E31/D31) -> 0.24 | G31: =+P31/N31 -> 0.93827872 | H31: =+P31/L31 -> 0.79493058 | I31: =+R31/P31 -> 1.0063527 | J31: =+R31/L31 -> 0.79998057 | K31: =+S31/M31 -> 0.86430138 | L31: =+Efficiency1!K118 -> 45.148596 | M31: =M30+L31 -> 1038.2825 | N31: =+Efficiency1!C118 -> 38.250894 | O31: =O30+N31 -> 1008.9392 | P31: ='23'!I38 -> 35.89 | Q31: =Q30+P31 -> 934.377 | R31: ='23'!I40 -> 36.118 | S31: =S30+R31 -> 897.389 | T31: =+AX31 -> 3241.8264 | U31: =T31+U30 -> 118822.52 | V31: =T31/P31 -> 90.326733 | W31: =U31/Q31 -> 127.16764 | X31: =IF(AND(R31>0,T31>0),(T31/(R31*1000))*1000,0) -> 89.756533 | Y31: =IF(AND(S31>0,U31>0),U31/S31,0) -> 132.40915 | Z31: 57.9 | AA31: =Z31+AA30 -> 1193 | AB31: =Z31/(P31) -> 1.6132627 | AC31: =AA31/(Q31) -> 1.2767866 | AD31: =IF(AND(R31>0,Z31>0),Z31/(R31),0) -> 1.6030788 | AE31: =IF(AND(S31>0,AA31>0),AA31/(S31),0) -> 1.3294123 | AF31: ='23'!I46 -> 37009.68 | AG31: =AF31+AG30 -> 869078.92 | AH31: =IF(AND(L31>0,AF31>0),(AF31/(P31*1000)*1000),0) -> 1031.1975 | AI31: =IF(AND(M31>0,AG31>0),(AG31/(Q31*1000)*1000),0) -> 930.11592 | AJ31: =IF(AND(R31>0,AF31>0),(AF31/(R31*1000)*1000),0) -> 1024.688 | AK31: =IF(AND(S31>0,AG31>0),(AG31/(S31*1000)*1000),0) -> 968.45283 | AL31: 3443.1 | AM31: 4324 | AN31: 3950.9 | AO31: =SUM(AL31:AN31) -> 11718 | AP31: =+[1]Jan!N27 -> 11033 | AQ31: =+AP31-AO31 -> -685 | AR31: =+AL31/AO31 -> 0.29383001 | AS31: =+AM31/AO31 -> 0.36900495 | AT31: =1-AR31-AS31 -> 0.33716505 | AU31: =+AR31*AQ31 -> -201.27355 | AV31: =+AS31*AQ31 -> -252.76839 | AW31: =+AT31*AQ31 -> -230.95806 | AX31: =+AL31+AU31 -> 3241.8264 | AY31: =+AM31+AV31 -> 4071.2316 | AZ31: =+AN31+AW31 -> 3719.9419 | BA31: =+Efficiency2!K118 -> 38.250894 | BB31: =BB30+BA31 -> 1001.6098 | BC31: =+R31/BA31 -> 0.94423936 | BD31: =+S31/BB31 -> 0.89594675
A32: =A31+1 -> 46046 | B32: Toilet | C32: 13 | D32: =+'24'!F42 -> 989.21528 | E32: =+'24'!G42 -> 751.80361 | F32: =1-(E32/D32) -> 0.24 | G32: =+P32/N32 -> 0.98517473 | H32: =+P32/L32 -> 0.79231699 | I32: =+R32/P32 -> 0.92474561 | J32: =+R32/L32 -> 0.73269166 | K32: =+S32/M32 -> 0.85881696 | L32: =+Efficiency1!K123 -> 45.148596 | M32: =M31+L32 -> 1083.4311 | N32: =+Efficiency1!C123 -> 36.31031 | O32: =O31+N32 -> 1045.2495 | P32: ='24'!I38 -> 35.772 | Q32: =Q31+P32 -> 970.149 | R32: ='24'!I40 -> 33.08 | S32: =S31+R32 -> 930.469 | T32: =+AX32 -> 2886.1894 | U32: =T32+U31 -> 121708.71 | V32: =T32/P32 -> 80.682919 | W32: =U32/Q32 -> 125.45362 | X32: =IF(AND(R32>0,T32>0),(T32/(R32*1000))*1000,0) -> 87.248772 | Y32: =IF(AND(S32>0,U32>0),U32/S32,0) -> 130.80361 | Z32: 52.9 | AA32: =Z32+AA31 -> 1245.9 | AB32: =Z32/(P32) -> 1.4788102 | AC32: =AA32/(Q32) -> 1.2842357 | AD32: =IF(AND(R32>0,Z32>0),Z32/(R32),0) -> 1.5991536 | AE32: =IF(AND(S32>0,AA32>0),AA32/(S32),0) -> 1.3390022 | AF32: =+'24'!I46 -> 36510.9 | AG32: =AF32+AG31 -> 905589.82 | AH32: =IF(AND(L32>0,AF32>0),(AF32/(P32*1000)*1000),0) -> 1020.6558 | AI32: =IF(AND(M32>0,AG32>0),(AG32/(Q32*1000)*1000),0) -> 933.45437 | AJ32: =IF(AND(R32>0,AF32>0),(AF32/(R32*1000)*1000),0) -> 1103.7152 | AK32: =IF(AND(S32>0,AG32>0),(AG32/(S32*1000)*1000),0) -> 973.26168 | AL32: 4078.9 | AM32: 4709.8 | AN32: 3948.9 | AO32: =SUM(AL32:AN32) -> 12737.6 | AP32: =+[1]Jan!N28 -> 9013 | AQ32: =+AP32-AO32 -> -3724.6 | AR32: =+AL32/AO32 -> 0.32022516 | AS32: =+AM32/AO32 -> 0.36975568 | AT32: =1-AR32-AS32 -> 0.31001916 | AU32: =+AR32*AQ32 -> -1192.7106 | AV32: =+AS32*AQ32 -> -1377.192 | AW32: =+AT32*AQ32 -> -1154.6973 | AX32: =+AL32+AU32 -> 2886.1894 | AY32: =+AM32+AV32 -> 3332.608 | AZ32: =+AN32+AW32 -> 2794.2027 | BA32: =+Efficiency2!K123 -> 36.31031 | BB32: =BB31+BA32 -> 1037.9201 | BC32: =+R32/BA32 -> 0.91103601 | BD32: =+S32/BB32 -> 0.89647463
A33: =A32+1 -> 46047 | B33: Toilet | C33: 13 | D33: =+'25'!F42 -> 1116.1762 | E33: =+'25'!G42 -> 848.29394 | F33: =1-(E33/D33) -> 0.24 | G33: =+P33/N33 -> 0.8922504 | H33: =+P33/L33 -> 0.80968187 | I33: =+R33/P33 -> 0.94329248 | J33: =+R33/L33 -> 0.76376682 | K33: =+S33/M33 -> 0.8550145 | L33: =+Efficiency1!K128 -> 45.148596 | M33: =M32+L33 -> 1128.5797 | N33: =+Efficiency1!C128 -> 40.970561 | O33: =O32+N33 -> 1086.2201 | P33: ='25'!I38 -> 36.556 | Q33: =Q32+P33 -> 1006.705 | R33: ='25'!I40 -> 34.483 | S33: =S32+R33 -> 964.952 | T33: =+AX33 -> 0 | U33: =T33+U32 -> 121708.71 | V33: =T33/P33 -> 0 | W33: =U33/Q33 -> 120.89809 | X33: =IF(AND(R33>0,T33>0),(T33/(R33*1000))*1000,0) -> 0 | Y33: =IF(AND(S33>0,U33>0),U33/S33,0) -> 126.12929 | Z33: 49.6 | AA33: =Z33+AA32 -> 1295.5 | AB33: =Z33/(P33) -> 1.3568224 | AC33: =AA33/(Q33) -> 1.2868715 | AD33: =IF(AND(R33>0,Z33>0),Z33/(R33),0) -> 1.4383899 | AE33: =IF(AND(S33>0,AA33>0),AA33/(S33),0) -> 1.3425538 | AF33: =+'25'!I46 -> 35651.6 | AG33: =AF33+AG32 -> 941241.42 | AH33: =IF(AND(L33>0,AF33>0),(AF33/(P33*1000)*1000),0) -> 975.25988 | AI33: =IF(AND(M33>0,AG33>0),(AG33/(Q33*1000)*1000),0) -> 934.97243 | AJ33: =IF(AND(R33>0,AF33>0),(AF33/(R33*1000)*1000),0) -> 1033.8892 | AK33: =IF(AND(S33>0,AG33>0),(AG33/(S33*1000)*1000),0) -> 975.42823 | AL33: 4516.3 | AM33: 4379.5 | AN33: 3475.9 | AO33: =SUM(AL33:AN33) -> 12371.7 | AP33: =+[1]Jan!N29 -> 0 | AQ33: =+AP33-AO33 -> -12371.7 | AR33: =+AL33/AO33 -> 0.36505088 | AS33: =+AM33/AO33 -> 0.35399339 | AT33: =1-AR33-AS33 -> 0.28095573 | AU33: =+AR33*AQ33 -> -4516.3 | AV33: =+AS33*AQ33 -> -4379.5 | AW33: =+AT33*AQ33 -> -3475.9 | AX33: =+AL33+AU33 -> 0 | AY33: =+AM33+AV33 -> 0 | AZ33: =+AN33+AW33 -> 0 | BA33: =+Efficiency2!K128 -> 40.970561 | BB33: =BB32+BA33 -> 1078.8906 | BC33: =+R33/BA33 -> 0.8416531 | BD33: =+S33/BB33 -> 0.8943928
A34: =A33+1 -> 46048 | B34: Toilet | C34: 13 | D34: =+'26'!F42 -> 814.00438 | E34: =+'26'!G42 -> 618.64333 | F34: =1-(E34/D34) -> 0.24 | G34: =+P34/N34 -> 1.0226585 | H34: =+P34/L34 -> 0.67678737 | I34: =+R34/P34 -> 1.0527883 | J34: =+R34/L34 -> 0.71251384 | K34: =+S34/M34 -> 0.84953307 | L34: =+Efficiency1!K134 -> 45.148596 | M34: =M33+L34 -> 1173.7283 | N34: =+Efficiency1!C134 -> 29.878988 | O34: =O33+N34 -> 1116.0991 | P34: ='26'!I38 -> 30.556 | Q34: =Q33+P34 -> 1037.261 | R34: ='26'!I40 -> 32.169 | S34: =S33+R34 -> 997.121 | T34: =+AX34 -> 1540.5817 | U34: =T34+U33 -> 123249.29 | V34: =T34/P34 -> 50.418305 | W34: =U34/Q34 -> 118.82187 | X34: =IF(AND(R34>0,T34>0),(T34/(R34*1000))*1000,0) -> 47.890258 | Y34: =IF(AND(S34>0,U34>0),U34/S34,0) -> 123.60515 | Z34: 51.7 | AA34: =Z34+AA33 -> 1347.2 | AB34: =Z34/(P34) -> 1.6919754 | AC34: =AA34/(Q34) -> 1.2988052 | AD34: =IF(AND(R34>0,Z34>0),Z34/(R34),0) -> 1.6071373 | AE34: =IF(AND(S34>0,AA34>0),AA34/(S34),0) -> 1.3510898 | AF34: ='26'!I46 -> 31840.26 | AG34: =AF34+AG33 -> 973081.68 | AH34: =IF(AND(L34>0,AF34>0),(AF34/(P34*1000)*1000),0) -> 1042.0297 | AI34: =IF(AND(M34>0,AG34>0),(AG34/(Q34*1000)*1000),0) -> 938.12616 | AJ34: =IF(AND(R34>0,AF34>0),(AF34/(R34*1000)*1000),0) -> 989.78084 | AK34: =IF(AND(S34>0,AG34>0),(AG34/(S34*1000)*1000),0) -> 975.89127 | AL34: 2566.2 | AM34: 1221.1 | AN34: 3776.8 | AO34: =SUM(AL34:AN34) -> 7564.1 | AP34: =+[1]Jan!N30 -> 4541 | AQ34: =+AP34-AO34 -> -3023.1 | AR34: =+AL34/AO34 -> 0.33926045 | AS34: =+AM34/AO34 -> 0.16143361 | AT34: =1-AR34-AS34 -> 0.49930593 | AU34: =+AR34*AQ34 -> -1025.6183 | AV34: =+AS34*AQ34 -> -488.02996 | AW34: =+AT34*AQ34 -> -1509.4518 | AX34: =+AL34+AU34 -> 1540.5817 | AY34: =+AM34+AV34 -> 733.07004 | AZ34: =+AN34+AW34 -> 2267.3482 | BA34: =+Efficiency2!K134 -> 28.447286 | BB34: =BB33+BA34 -> 1107.3379 | BC34: =+R34/BA34 -> 1.1308284 | BD34: =+S34/BB34 -> 0.90046678
A35: =A34+1 -> 46049 | B35: Toilet | C35: 13 | D35: =+'27'!F42 -> 798.38889 | E35: =+'27'!G42 -> 606.77556 | F35: =1-(E35/D35) -> 0.24 | G35: =+P35/N35 -> 1.003692 | H35: =+P35/L35 -> 0.65149312 | I35: =+R35/P35 -> 0.95903311 | J35: =+R35/L35 -> 0.62480348 | K35: =+S35/M35 -> 0.84120883 | L35: =+Efficiency1!K140 -> 45.148596 | M35: =M34+L35 -> 1218.8769 | N35: =+Efficiency1!C140 -> 29.305803 | O35: =O34+N35 -> 1145.4049 | P35: ='27'!I38 -> 29.414 | Q35: =Q34+P35 -> 1066.675 | R35: ='27'!I40 -> 28.209 | S35: =S34+R35 -> 1025.33 | T35: =+AX35 -> 2226.685 | U35: =T35+U34 -> 125475.97 | V35: =T35/P35 -> 75.701537 | W35: =U35/Q35 -> 117.63281 | X35: =IF(AND(R35>0,T35>0),(T35/(R35*1000))*1000,0) -> 78.93527 | Y35: =IF(AND(S35>0,U35>0),U35/S35,0) -> 122.37618 | Z35: 52.1 | AA35: =Z35+AA34 -> 1399.3 | AB35: =Z35/(P35) -> 1.7712654 | AC35: =AA35/(Q35) -> 1.3118335 | AD35: =IF(AND(R35>0,Z35>0),Z35/(R35),0) -> 1.8469283 | AE35: =IF(AND(S35>0,AA35>0),AA35/(S35),0) -> 1.3647314 | AF35: ='27'!I46 -> 35303.02 | AG35: =AF35+AG34 -> 1008384.7 | AH35: =IF(AND(L35>0,AF35>0),(AF35/(P35*1000)*1000),0) -> 1200.2115 | AI35: =IF(AND(M35>0,AG35>0),(AG35/(Q35*1000)*1000),0) -> 945.35327 | AJ35: =IF(AND(R35>0,AF35>0),(AF35/(R35*1000)*1000),0) -> 1251.4807 | AK35: =IF(AND(S35>0,AG35>0),(AG35/(S35*1000)*1000),0) -> 983.47332 | AL35: 2278.6 | AM35: 561.7 | AN35: 3642.4 | AO35: =SUM(AL35:AN35) -> 6482.7 | AP35: =+[1]Jan!N31 -> 6335 | AQ35: =+AP35-AO35 -> -147.7 | AR35: =+AL35/AO35 -> 0.35148935 | AS35: =+AM35/AO35 -> 0.086645996 | AT35: =1-AR35-AS35 -> 0.56186466 | AU35: =+AR35*AQ35 -> -51.914977 | AV35: =+AS35*AQ35 -> -12.797614 | AW35: =+AT35*AQ35 -> -82.98741 | AX35: =+AL35+AU35 -> 2226.685 | AY35: =+AM35+AV35 -> 548.90239 | AZ35: =+AN35+AW35 -> 3559.4126 | BA35: =+Efficiency2!K140 -> 29.305803 | BB35: =BB34+BA35 -> 1136.6437 | BC35: =+R35/BA35 -> 0.96257386 | BD35: =+S35/BB35 -> 0.90206807
A36: =A35+1 -> 46050 | B36: Toilet | C36: 13 | D36: =+'28'!F42 -> 741.11111 | E36: =+'28'!G42 -> 563.24444 | F36: =1-(E36/D36) -> 0.24 | G36: =+P36/N36 -> 0.97256387 | H36: =+P36/L36 -> 0.58599828 | I36: =+R36/P36 -> 1.0075216 | J36: =+R36/L36 -> 0.59040595 | K36: =+S36/M36 -> 0.83225063 | L36: =+Efficiency1!K145 -> 45.148596 | M36: =M35+L36 -> 1264.0255 | N36: =+Efficiency1!C145 -> 27.203355 | O36: =O35+N36 -> 1172.6082 | P36: ='28'!I38 -> 26.457 | Q36: =Q35+P36 -> 1093.132 | R36: ='28'!I40 -> 26.656 | S36: =S35+R36 -> 1051.986 | T36: =+AX36 -> 1820.7379 | U36: =T36+U35 -> 127296.71 | V36: =T36/P36 -> 68.81876 | W36: =U36/Q36 -> 116.45136 | X36: =IF(AND(R36>0,T36>0),(T36/(R36*1000))*1000,0) -> 68.304995 | Y36: =IF(AND(S36>0,U36>0),U36/S36,0) -> 121.00609 | Z36: 48 | AA36: =Z36+AA35 -> 1447.3 | AB36: =Z36/(P36) -> 1.8142647 | AC36: =AA36/(Q36) -> 1.3239938 | AD36: =IF(AND(R36>0,Z36>0),Z36/(R36),0) -> 1.8007203 | AE36: =IF(AND(S36>0,AA36>0),AA36/(S36),0) -> 1.3757788 | AF36: ='28'!I46 -> 34063.18 | AG36: =AF36+AG35 -> 1042447.9 | AH36: =IF(AND(L36>0,AF36>0),(AF36/(P36*1000)*1000),0) -> 1287.4922 | AI36: =IF(AND(M36>0,AG36>0),(AG36/(Q36*1000)*1000),0) -> 953.63404 | AJ36: =IF(AND(R36>0,AF36>0),(AF36/(R36*1000)*1000),0) -> 1277.8804 | AK36: =IF(AND(S36>0,AG36>0),(AG36/(S36*1000)*1000),0) -> 990.93323 | AL36: 1868.9 | AM36: 771.6 | AN36: 3350.9 | AO36: =SUM(AL36:AN36) -> 5991.4 | AP36: =+[1]Jan!N32 -> 5837 | AQ36: =+AP36-AO36 -> -154.4 | AR36: =+AL36/AO36 -> 0.31193043 | AS36: =+AM36/AO36 -> 0.12878459 | AT36: =1-AR36-AS36 -> 0.55928498 | AU36: =+AR36*AQ36 -> -48.162059 | AV36: =+AS36*AQ36 -> -19.884341 | AW36: =+AT36*AQ36 -> -86.3536 | AX36: =+AL36+AU36 -> 1820.7379 | AY36: =+AM36+AV36 -> 751.71566 | AZ36: =+AN36+AW36 -> 3264.5464 | BA36: =+Efficiency2!K145 -> 27.203355 | BB36: =BB35+BA36 -> 1163.8471 | BC36: =+R36/BA36 -> 0.97987914 | BD36: =+S36/BB36 -> 0.9038868
A37: =A36+1 -> 46051 | B37: Toilet | C37: 13/12,5 | D37: =+'29'!F42 -> 759.58333 | E37: =+'29'!G42 -> 577.28333 | F37: =1-(E37/D37) -> 0.24 | G37: =+P37/N37 -> 1.0270225 | H37: =+P37/L37 -> 0.63335854 | I37: =+R37/P37 -> 1.0161319 | J37: =+R37/L37 -> 0.64357584 | K37: =+S37/M37 -> 0.8259525 | L37: =+SUM(Efficiency1!K150:K151) -> 43.651421 | M37: =M36+L37 -> 1307.6769 | N37: =+SUM(Efficiency1!C150:C151) -> 26.919565 | O37: =O36+N37 -> 1199.5278 | P37: ='29'!I38 -> 27.647 | Q37: =Q36+P37 -> 1120.779 | R37: ='29'!I40 -> 28.093 | S37: =S36+R37 -> 1080.079 | T37: =+AX37 -> 2272.2948 | U37: =T37+U36 -> 129569.01 | V37: =T37/P37 -> 82.189563 | W37: =U37/Q37 -> 115.6062 | X37: =IF(AND(R37>0,T37>0),(T37/(R37*1000))*1000,0) -> 80.884734 | Y37: =IF(AND(S37>0,U37>0),U37/S37,0) -> 119.96253 | Z37: 48.2 | AA37: =Z37+AA36 -> 1495.5 | AB37: =Z37/(P37) -> 1.743408 | AC37: =AA37/(Q37) -> 1.3343398 | AD37: =IF(AND(R37>0,Z37>0),Z37/(R37),0) -> 1.7157299 | AE37: =IF(AND(S37>0,AA37>0),AA37/(S37),0) -> 1.3846209 | AF37: ='29'!I46 -> 34150.74 | AG37: =AF37+AG36 -> 1076598.6 | AH37: =IF(AND(L37>0,AF37>0),(AF37/(P37*1000)*1000),0) -> 1235.2422 | AI37: =IF(AND(M37>0,AG37>0),(AG37/(Q37*1000)*1000),0) -> 960.58065 | AJ37: =IF(AND(R37>0,AF37>0),(AF37/(R37*1000)*1000),0) -> 1215.6317 | AK37: =IF(AND(S37>0,AG37>0),(AG37/(S37*1000)*1000),0) -> 996.77766 | AL37: 2325.4 | AM37: 758.8 | AN37: 3668 | AO37: =SUM(AL37:AN37) -> 6752.2 | AP37: =+[1]Jan!N33 -> 6598 | AQ37: =+AP37-AO37 -> -154.2 | AR37: =+AL37/AO37 -> 0.34439146 | AS37: =+AM37/AO37 -> 0.11237819 | AT37: =1-AR37-AS37 -> 0.54323035 | AU37: =+AR37*AQ37 -> -53.105163 | AV37: =+AS37*AQ37 -> -17.328717 | AW37: =+AT37*AQ37 -> -83.766121 | AX37: =+AL37+AU37 -> 2272.2948 | AY37: =+AM37+AV37 -> 741.47128 | AZ37: =+AN37+AW37 -> 3584.2339 | BA37: =+SUM(Efficiency2!K150:K151) -> 26.919565 | BB37: =BB36+BA37 -> 1190.7666 | BC37: =+R37/BA37 -> 1.0435904 | BD37: =+S37/BB37 -> 0.90704507
A38: =A37+1 -> 46052 | B38: Toilet | C38: 12,5 | D38: =+'30'!F42 -> 1005.4286 | E38: =+'30'!G42 -> 764.12571 | F38: =1-(E38/D38) -> 0.24 | G38: =+P38/N38 -> 0.99900846 | H38: =+P38/L38 -> 0.8166111 | I38: =+R38/P38 -> 0.95098931 | J38: =+R38/L38 -> 0.77658843 | K38: =+S38/M38 -> 0.82437827 | L38: =+Efficiency1!K155 -> 43.075584 | M38: =M37+L38 -> 1350.7525 | N38: =+Efficiency1!C155 -> 35.210913 | O38: =O37+N38 -> 1234.7387 | P38: ='30'!I38 -> 35.176 | Q38: =Q37+P38 -> 1155.955 | R38: ='30'!I40 -> 33.452 | S38: =S37+R38 -> 1113.531 | T38: =+AX38 -> 3435.5617 | U38: =T38+U37 -> 133004.57 | V38: =T38/P38 -> 97.667777 | W38: =U38/Q38 -> 115.06033 | X38: =IF(AND(R38>0,T38>0),(T38/(R38*1000))*1000,0) -> 102.70123 | Y38: =IF(AND(S38>0,U38>0),U38/S38,0) -> 119.44397 | Z38: 49.9 | AA38: =Z38+AA37 -> 1545.4 | AB38: =Z38/(P38) -> 1.4185809 | AC38: =AA38/(Q38) -> 1.3369033 | AD38: =IF(AND(R38>0,Z38>0),Z38/(R38),0) -> 1.4916896 | AE38: =IF(AND(S38>0,AA38>0),AA38/(S38),0) -> 1.3878374 | AF38: ='30'!I46 -> 35169.74 | AG38: =AF38+AG37 -> 1111768.4 | AH38: =IF(AND(L38>0,AF38>0),(AF38/(P38*1000)*1000),0) -> 999.82204 | AI38: =IF(AND(M38>0,AG38>0),(AG38/(Q38*1000)*1000),0) -> 961.77477 | AJ38: =IF(AND(R38>0,AF38>0),(AF38/(R38*1000)*1000),0) -> 1051.3494 | AK38: =IF(AND(S38>0,AG38>0),(AG38/(S38*1000)*1000),0) -> 998.41707 | AL38: 3558.7 | AM38: 3632.7 | AN38: 3157.7 | AO38: =SUM(AL38:AN38) -> 10349.1 | AP38: =+[1]Jan!N34 -> 9991 | AQ38: =+AP38-AO38 -> -358.1 | AR38: =+AL38/AO38 -> 0.34386565 | AS38: =+AM38/AO38 -> 0.35101603 | AT38: =1-AR38-AS38 -> 0.30511832 | AU38: =+AR38*AQ38 -> -123.13829 | AV38: =+AS38*AQ38 -> -125.69884 | AW38: =+AT38*AQ38 -> -109.26287 | AX38: =+AL38+AU38 -> 3435.5617 | AY38: =+AM38+AV38 -> 3507.0012 | AZ38: =+AN38+AW38 -> 3048.4371 | BA38: =+Efficiency2!K155 -> 35.210913 | BB38: =BB37+BA38 -> 1225.9775 | BC38: =+R38/BA38 -> 0.95004637 | BD38: =+S38/BB38 -> 0.90828009
