Workbook

Sheet Master
A1: LAPORAN PEMAKAIAN BAHAN BAKAR DI BOILER DAN STEAM
A2: Bulan : November 2025 | B2: 45748 | N2: 43160 | AE2: Juni
B4: B O I L E R 1 | F4: B O I L E R 2 | J4: B O I L E R 3 | N4: Total | O4: Fresh | P4: Total | R4: S T E A M B O I L E R 1 | V4: Effisiensi | W4: S T E A M B O I L E R 2 | AA4: Effisiensi | AB4: S T E A M B O I L E R 3 | AF4: Effisiensi | AG4: STEAM | AH4: Steam ( ton ) | AU4: Totalizer | AY4: Steam | BB4: Fresh water | BD4: Steam Sun Unit 2 (DCS) | BK4: Totalizer
A5: Tgl | B5: Total | F5: Total | J5: Total | N5: Batubara | O5: Water | P5: Bottom Ash/Fly Ash | R5: Shift | U5: Total | V5: Boiler 1 | W5: Shift | Z5: Total | AA5: Boiler 2 | AB5: Shift | AE5: Total | AF5: Boiler 3 | AG5: SINERGY | AH5: PM 11 | AI5: PM 12 | AJ5: DIP(PM12) | AK5: PM 14 | AL5: PM 15 | AM5: DIP(PM15) | AN5: PM 16 | AO5: DIP(PM16) | AP5: PM 17 | AQ5: DIP(PM17) | AT5: TOTAL | AU5: Sinergy | AX5: t/h | AY5: DIP2 | AZ5: 15 | BA5: 17 | BD5: SP | BE5: Selisih SP-PM18-PM19 | BF5: PM 18 | BG5: PM 19 | BH5: PM 20 | BI5: PM 21 | BJ5: PM 22 | BK5: Total Konsumsi | BL5: Selisih | BM5: Total | BN5: Totalizer (grup boiler)
A6: Shift | B6: Boiler 1 | C6: Shift 1 | D6: Shift 2 | E6: Shift 3 | F6: Boiler 2 | G6: Shift 1 | H6: Shift 2 | I6: Shift 3 | J6: Boiler 3 | K6: Shift 1 | L6: Shift 2 | M6: Shift 3 | N6: B. Baru | O6: B. Baru | P6: Boiler 1 | Q6: Boiler 2 | R6: I | S6: II | T6: III | W6: I | X6: II | Y6: III | AB6: I | AC6: II | AD6: III
A7: 31 | AU7: =+[1]Master!$AU$38 -> 19189 | BN7: =+[1]Master!$BN$38 -> 104425
A8: 1 | B8: =SUM(C8:E8) -> 0 | F8: =SUM(G8:I8) -> 0 | J8: =SUM(K8:M8) -> 0 | N8: =B8+F8+J8 -> 0 | U8: =SUM(R8:T8) -> 0 | V8: =B8/U8 -> #DIV/0! | Z8: =SUM(W8:Y8) -> 0 | AA8: =F8/Z8 -> #DIV/0! | AE8: =SUM(AB8:AD8) -> 0 | AF8: =J8/AE8 -> #DIV/0! | AG8: =AV8 -> 656 | AH8: =+[2]NOV!B2 -> 152.922 | AI8: =+[2]NOV!C2 -> 127.483 | AJ8: =+[2]NOV!D2 -> 12.8 | AK8: =+[2]NOV!E2 -> 25.3 | AL8: =+[2]NOV!F2 -> 62.9 | AM8: =+[2]NOV!G2 -> 7.9 | AN8: =+[2]NOV!H2 -> 137.7 | AO8: =+[2]NOV!I2 -> 0 | ... AQ8: =+[2]NOV!K2 -> 7.3 | AT8: =SUM(AH8:AS8) -> 620.605 | AU8: 19845 | AV8: =AU8-AU7 -> 656 | AW8: =AG8-AV8 -> 0 | AX8: 27.94 | BD8: =+[3]NOV!H3 -> 401.2 | BE8: =BD8-BK8 -> 56.8 | BF8: =+[3]NOV!B3 -> 145.8 | BG8: =+[3]NOV!C3 -> 71.8 | BH8: =+[3]NOV!D3 -> 0 | BI8: =+[3]NOV!E3 -> 126.8 | BK8: =SUM(BF8:BJ8) -> 344.4 | BL8: =ABS(BM8-BK8) -> 55.6 | BM8: =BN8-BN7 -> 400 | BN8: 104825
A9: =A8+1 -> 2 | B9: =SUM(C9:E9) -> 0 | F9: =SUM(G9:I9) -> 0 | J9: =SUM(K9:M9) -> 0 | N9: =B9+F9+J9 -> 0 | U9: =SUM(R9:T9) -> 0 | V9: =B9/U9 -> #DIV/0! | Z9: =SUM(W9:Y9) -> 0 | AA9: =F9/Z9 -> #DIV/0! | AE9: =SUM(AB9:AD9) -> 0 | AF9: =J9/AE9 -> #DIV/0! | AG9: =AV9 -> 653 | AH9: =+[2]NOV!B3 -> 158.395 | AI9: =+[2]NOV!C3 -> 129.185 | AJ9: =+[2]NOV!D3 -> 13.6 | AK9: =+[2]NOV!E3 -> 23.5 | AL9: =+[2]NOV!F3 -> 67.8 | AM9: =+[2]NOV!G3 -> 10.9 | AN9: =+[2]NOV!H3 -> 135.2 | AO9: =+[2]NOV!I3 -> 0 | ... AQ9: =+[2]NOV!K3 -> 8 | AT9: =SUM(AH9:AS9) -> 620.48 | AU9: 20498 | AV9: =AU9-AU8 -> 653 | AW9: =AG9-AV9 -> 0 | AX9: 23.35 | BD9: =+[3]NOV!H4 -> 404.2 | BE9: =BD9-BK9 -> 36.8 | BF9: =+[3]NOV!B4 -> 132.1 | BG9: =+[3]NOV!C4 -> 108.4 | BH9: =+[3]NOV!D4 -> 0 | BI9: =+[3]NOV!E4 -> 126.9 | BK9: =SUM(BF9:BJ9) -> 367.4 | BL9: =ABS(BM9-BK9) -> 33.6 | BM9: =BN9-BN8 -> 401 | BN9: 105226
A10: =A9+1 -> 3 | B10: =SUM(C10:E10) -> 0 | F10: =SUM(G10:I10) -> 0 | J10: =SUM(K10:M10) -> 0 | N10: =B10+F10+J10 -> 0 | U10: =SUM(R10:T10) -> 0 | V10: =B10/U10 -> #DIV/0! | Z10: =SUM(W10:Y10) -> 0 | AA10: =F10/Z10 -> #DIV/0! | AE10: =SUM(AB10:AD10) -> 0 | AF10: =J10/AE10 -> #DIV/0! | AG10: =AV10 -> 592 | AH10: =+[2]NOV!B4 -> 167.041 | AI10: =+[2]NOV!C4 -> 137.223 | AJ10: =+[2]NOV!D4 -> 11.2 | AK10: =+[2]NOV!E4 -> 23.4 | AL10: =+[2]NOV!F4 -> 69 | AM10: =+[2]NOV!G4 -> 9.9 | AN10: =+[2]NOV!H4 -> 58.3 | AO10: =+[2]NOV!I4 -> 0 | ... AQ10: =+[2]NOV!K4 -> 8.1 | AT10: =SUM(AH10:AS10) -> 572.064 | AU10: 21090 | AV10: =AU10-AU9 -> 592 | AW10: =AG10-AV10 -> 0 | AX10: 26.71 | BD10: =+[3]NOV!H5 -> 460.4 | BE10: =BD10-BK10 -> 37 | BF10: =+[3]NOV!B5 -> 144.8 | BG10: =+[3]NOV!C5 -> 147.3 | BH10: =+[3]NOV!D5 -> 5.6 | BI10: =+[3]NOV!E5 -> 125.7 | BK10: =SUM(BF10:BJ10) -> 423.4 | BL10: =ABS(BM10-BK10) -> 30.6 | BM10: =BN10-BN9 -> 454 | BN10: 105680
A11: =A10+1 -> 4 | B11: =SUM(C11:E11) -> 0 | F11: =SUM(G11:I11) -> 0 | J11: =SUM(K11:M11) -> 0 | N11: =B11+F11+J11 -> 0 | U11: =SUM(R11:T11) -> 0 | V11: =B11/U11 -> #DIV/0! | Z11: =SUM(W11:Y11) -> 0 | AA11: =F11/Z11 -> #DIV/0! | AE11: =SUM(AB11:AD11) -> 0 | AF11: =J11/AE11 -> #DIV/0! | AG11: =AV11 -> 656 | AH11: =+[2]NOV!B5 -> 147.047 | AI11: =+[2]NOV!C5 -> 138.831 | AJ11: =+[2]NOV!D5 -> 15.2 | AK11: =+[2]NOV!E5 -> 7.1 | AL11: =+[2]NOV!F5 -> 68.5 | AM11: =+[2]NOV!G5 -> 11.1 | AN11: =+[2]NOV!H5 -> 139.5 | AO11: =+[2]NOV!I5 -> 0 | ... AQ11: =+[2]NOV!K5 -> 10.5 | AT11: =SUM(AH11:AS11) -> 638.578 | AU11: 21746 | AV11: =AU11-AU10 -> 656 | AW11: =AG11-AV11 -> 0 | AX11: 26.2 | BD11: =+[3]NOV!H6 -> 518.8 | BE11: =BD11-BK11 -> 47.9 | BF11: =+[3]NOV!B6 -> 153 | BG11: =+[3]NOV!C6 -> 147.5 | BH11: =+[3]NOV!D6 -> 46.3 | BI11: =+[3]NOV!E6 -> 124.1 | BK11: =SUM(BF11:BJ11) -> 470.9 | BL11: =ABS(BM11-BK11) -> 42.1 | BM11: =BN11-BN10 -> 513 | BN11: 106193
A12: =A11+1 -> 5 | B12: =SUM(C12:E12) -> 0 | F12: =SUM(G12:I12) -> 0 | J12: =SUM(K12:M12) -> 0 | N12: =B12+F12+J12 -> 0 | U12: =SUM(R12:T12) -> 0 | V12: =B12/U12 -> #DIV/0! | Z12: =SUM(W12:Y12) -> 0 | AA12: =F12/Z12 -> #DIV/0! | AE12: =SUM(AB12:AD12) -> 0 | AF12: =J12/AE12 -> #DIV/0! | AG12: =AV12 -> 580 | AH12: =+[2]NOV!B6 -> 115.565 | AI12: =+[2]NOV!C6 -> 141.54 | AJ12: =+[2]NOV!D6 -> 15.2 | AK12: =+[2]NOV!E6 -> 3.3 | AL12: =+[2]NOV!F6 -> 45.6 | AM12: =+[2]NOV!G6 -> 6 | AN12: =+[2]NOV!H6 -> 134.6 | AO12: =+[2]NOV!I6 -> 0 | ... AQ12: =+[2]NOV!K6 -> 8.3 | AT12: =SUM(AH12:AS12) -> 555.205 | AU12: 22326 | AV12: =AU12-AU11 -> 580 | AW12: =AG12-AV12 -> 0 | AX12: 26.23 | BD12: =+[3]NOV!H7 -> 532.6 | BE12: =BD12-BK12 -> 59.7 | BF12: =+[3]NOV!B7 -> 154.2 | BG12: =+[3]NOV!C7 -> 140 | BH12: =+[3]NOV!D7 -> 112.6 | BI12: =+[3]NOV!E7 -> 66.1 | BK12: =SUM(BF12:BJ12) -> 472.9 | BL12: =ABS(BM12-BK12) -> 57.1 | BM12: =BN12-BN11 -> 530 | BN12: 106723
A13: =A12+1 -> 6 | B13: =SUM(C13:E13) -> 0 | F13: =SUM(G13:I13) -> 0 | J13: =SUM(K13:M13) -> 0 | N13: =B13+F13+J13 -> 0 | U13: =SUM(R13:T13) -> 0 | V13: =B13/U13 -> #DIV/0! | Z13: =SUM(W13:Y13) -> 0 | AA13: =F13/Z13 -> #DIV/0! | AE13: =SUM(AB13:AD13) -> 0 | AF13: =J13/AE13 -> #DIV/0! | AG13: =AV13 -> 632 | AH13: =+[2]NOV!B7 -> 116.557 | AI13: =+[2]NOV!C7 -> 144.627 | AJ13: =+[2]NOV!D7 -> 14.4 | AK13: =+[2]NOV!E7 -> 4.3 | AL13: =+[2]NOV!F7 -> 70.7 | AM13: =+[2]NOV!G7 -> 11 | AN13: =+[2]NOV!H7 -> 137 | AO13: =+[2]NOV!I7 -> 0 | ... AQ13: =+[2]NOV!K7 -> 7.9 | AT13: =SUM(AH13:AS13) -> 599.584 | AU13: 22958 | AV13: =AU13-AU12 -> 632 | AW13: =AG13-AV13 -> 0 | AX13: 26.77 | BD13: =+[3]NOV!H8 -> 560.5 | BE13: =BD13-BK13 -> 70.4 | BF13: =+[3]NOV!B8 -> 147.7 | BG13: =+[3]NOV!C8 -> 153.4 | BH13: =+[3]NOV!D8 -> 143.3 | BI13: =+[3]NOV!E8 -> 45.7 | BK13: =SUM(BF13:BJ13) -> 490.1 | BL13: =ABS(BM13-BK13) -> 53.9 | BM13: =BN13-BN12 -> 544 | BN13: 107267
A14: =A13+1 -> 7 | B14: =SUM(C14:E14) -> 0 | F14: =SUM(G14:I14) -> 0 | J14: =SUM(K14:M14) -> 0 | N14: =B14+F14+J14 -> 0 | U14: =SUM(R14:T14) -> 0 | V14: =B14/U14 -> #DIV/0! | Z14: =SUM(W14:Y14) -> 0 | AA14: =F14/Z14 -> #DIV/0! | AE14: =SUM(AB14:AD14) -> 0 | AF14: =J14/AE14 -> #DIV/0! | AG14: =AV14 -> 637 | AH14: =+[2]NOV!B8 -> 118.986 | AI14: =+[2]NOV!C8 -> 125.8 | AJ14: =+[2]NOV!D8 -> 12.8 | AK14: =+[2]NOV!E8 -> 27.7 | AL14: =+[2]NOV!F8 -> 66.1 | AM14: =+[2]NOV!G8 -> 10.8 | AN14: =+[2]NOV!H8 -> 136.4 | AO14: =+[2]NOV!I8 -> 0 | ... AQ14: =+[2]NOV!K8 -> 9 | AT14: =SUM(AH14:AS14) -> 606.486 | AU14: 23595 | AV14: =AU14-AU13 -> 637 | AW14: =AG14-AV14 -> 0 | AX14: 26.79 | BD14: =+[3]NOV!H9 -> 583.9 | BE14: =BD14-BK14 -> 20.8 | BF14: =+[3]NOV!B9 -> 157.2 | BG14: =+[3]NOV!C9 -> 157.2 | BH14: =+[3]NOV!D9 -> 136.2 | BI14: =+[3]NOV!E9 -> 112.5 | BK14: =SUM(BF14:BJ14) -> 563.1 | BL14: =ABS(BM14-BK14) -> 28.9 | BM14: =BN14-BN13 -> 592 | BN14: 107859
A15: =A14+1 -> 8 | B15: =SUM(C15:E15) -> 0 | F15: =SUM(G15:I15) -> 0 | J15: =SUM(K15:M15) -> 0 | N15: =B15+F15+J15 -> 0 | U15: =SUM(R15:T15) -> 0 | V15: =B15/U15 -> #DIV/0! | Z15: =SUM(W15:Y15) -> 0 | AA15: =F15/Z15 -> #DIV/0! | AE15: =SUM(AB15:AD15) -> 0 | AF15: =J15/AE15 -> #DIV/0! | AG15: =AV15 -> 647 | AH15: =+[2]NOV!B9 -> 113.193 | AI15: =+[2]NOV!C9 -> 131.1 | AJ15: =+[2]NOV!D9 -> 14.4 | AK15: =+[2]NOV!E9 -> 29.6 | AL15: =+[2]NOV!F9 -> 66.6 | AM15: =+[2]NOV!G9 -> 10.4 | AN15: =+[2]NOV!H9 -> 137.8 | AO15: =+[2]NOV!I9 -> 0 | ... AQ15: =+[2]NOV!K9 -> 9.4 | AT15: =SUM(AH15:AS15) -> 611.993 | AU15: 24242 | AV15: =AU15-AU14 -> 647 | AW15: =AG15-AV15 -> 0 | AX15: 27.31 | BD15: =+[3]NOV!H10 -> 627.2 | BE15: =BD15-BK15 -> 47.5 | BF15: =+[3]NOV!B10 -> 160.3 | BG15: =+[3]NOV!C10 -> 157.8 | BH15: =+[3]NOV!D10 -> 133.3 | BI15: =+[3]NOV!E10 -> 128.3 | BK15: =SUM(BF15:BJ15) -> 579.7 | BL15: =ABS(BM15-BK15) -> 38.3 | BM15: =BN15-BN14 -> 618 | BN15: 108477
A16: =A15+1 -> 9 | B16: =SUM(C16:E16) -> 0 | F16: =SUM(G16:I16) -> 0 | J16: =SUM(K16:M16) -> 0 | N16: =B16+F16+J16 -> 0 | U16: =SUM(R16:T16) -> 0 | V16: =B16/U16 -> #DIV/0! | Z16: =SUM(W16:Y16) -> 0 | AA16: =F16/Z16 -> #DIV/0! | AE16: =SUM(AB16:AD16) -> 0 | AF16: =J16/AE16 -> #DIV/0! | AG16: =AV16 -> 653 | AH16: =+[2]NOV!B10 -> 117.136 | AI16: =+[2]NOV!C10 -> 128.4 | AJ16: =+[2]NOV!D10 -> 15.2 | AK16: =+[2]NOV!E10 -> 34.8 | AL16: =+[2]NOV!F10 -> 65.8 | AM16: =+[2]NOV!G10 -> 10.8 | AN16: =+[2]NOV!H10 -> 138.5 | AO16: =+[2]NOV!I10 -> 0 | ... AQ16: =+[2]NOV!K10 -> 10.8 | AT16: =SUM(AH16:AS16) -> 622.936 | AU16: 24895 | AV16: =AU16-AU15 -> 653 | AW16: =AG16-AV16 -> 0 | AX16: 27.94 | BD16: =+[3]NOV!H11 -> 612.2 | BE16: =BD16-BK16 -> 56.6 | BF16: =+[3]NOV!B11 -> 146.1 | BG16: =+[3]NOV!C11 -> 158 | BH16: =+[3]NOV!D11 -> 126.8 | BI16: =+[3]NOV!E11 -> 124.7 | BK16: =SUM(BF16:BJ16) -> 555.6 | BL16: =ABS(BM16-BK16) -> 45.4 | BM16: =BN16-BN15 -> 601 | BN16: 109078
A17: =A16+1 -> 10 | B17: =SUM(C17:E17) -> 0 | F17: =SUM(G17:I17) -> 0 | J17: =SUM(K17:M17) -> 0 | N17: =B17+F17+J17 -> 0 | U17: =SUM(R17:T17) -> 0 | V17: =B17/U17 -> #DIV/0! | Z17: =SUM(W17:Y17) -> 0 | AA17: =F17/Z17 -> #DIV/0! | AE17: =SUM(AB17:AD17) -> 0 | AF17: =J17/AE17 -> #DIV/0! | AG17: =AV17 -> 661 | AH17: =+[2]NOV!B11 -> 119.291 | AI17: =+[2]NOV!C11 -> 130.5 | AJ17: =+[2]NOV!D11 -> 13.6 | AK17: =+[2]NOV!E11 -> 33.8 | AL17: =+[2]NOV!F11 -> 65.9 | AM17: =+[2]NOV!G11 -> 9.6 | AN17: =+[2]NOV!H11 -> 136.3 | AO17: =+[2]NOV!I11 -> 0 | ... AQ17: =+[2]NOV!K11 -> 9.3 | AT17: =SUM(AH17:AS17) -> 617.491 | AU17: 25556 | AV17: =AU17-AU16 -> 661 | AW17: =AG17-AV17 -> 0 | AX17: 27.67 | BD17: =+[3]NOV!H12 -> 535.5 | BE17: =BD17-BK17 -> 19.8 | BF17: =+[3]NOV!B12 -> 102 | BG17: =+[3]NOV!C12 -> 157.8 | BH17: =+[3]NOV!D12 -> 141.9 | BI17: =+[3]NOV!E12 -> 114 | BK17: =SUM(BF17:BJ17) -> 515.7 | BL17: =ABS(BM17-BK17) -> 35.3 | BM17: =BN17-BN16 -> 551 | BN17: 109629
A18: 11 | B18: =SUM(C18:E18) -> 0 | F18: =SUM(G18:I18) -> 0 | J18: =SUM(K18:M18) -> 0 | N18: =B18+F18+J18 -> 0 | U18: =SUM(R18:T18) -> 0 | V18: =B18/U18 -> #DIV/0! | Z18: =SUM(W18:Y18) -> 0 | AA18: =F18/Z18 -> #DIV/0! | AE18: =SUM(AB18:AD18) -> 0 | AF18: =J18/AE18 -> #DIV/0! | AG18: =AV18 -> 664 | AH18: =+[2]NOV!B12 -> 122.351 | AI18: =+[2]NOV!C12 -> 135.02 | AJ18: =+[2]NOV!D12 -> 14.4 | AK18: =+[2]NOV!E12 -> 34 | AL18: =+[2]NOV!F12 -> 69.9 | AM18: =+[2]NOV!G12 -> 9.8 | AN18: =+[2]NOV!H12 -> 128.6 | AO18: =+[2]NOV!I12 -> 0 | ... AQ18: =+[2]NOV!K12 -> 9.1 | AT18: =SUM(AH18:AS18) -> 624.271 | AU18: 26220 | AV18: =AU18-AU17 -> 664 | AW18: =AG18-AV18 -> 0 | AX18: 28.73 | BD18: =+[3]NOV!H13 -> 443.8 | BE18: =BD18-BK18 -> 33.1 | BF18: =+[3]NOV!B13 -> 4.6 | BG18: =+[3]NOV!C13 -> 155.1 | BH18: =+[3]NOV!D13 -> 134.2 | BI18: =+[3]NOV!E13 -> 116.8 | BK18: =SUM(BF18:BJ18) -> 410.7 | BL18: =ABS(BM18-BK18) -> 47.3 | BM18: =BN18-BN17 -> 458 | BN18: 110087
A19: =A18+1 -> 12 | B19: =SUM(C19:E19) -> 0 | F19: =SUM(G19:I19) -> 0 | J19: =SUM(K19:M19) -> 0 | N19: =B19+F19+J19 -> 0 | U19: =SUM(R19:T19) -> 0 | V19: =B19/U19 -> #DIV/0! | Z19: =SUM(W19:Y19) -> 0 | AA19: =F19/Z19 -> #DIV/0! | AE19: =SUM(AB19:AD19) -> 0 | AF19: =J19/AE19 -> #DIV/0! | AG19: =AV19 -> 682 | AH19: =+[2]NOV!B13 -> 122.351 | AI19: =+[2]NOV!C13 -> 137.704 | AJ19: =+[2]NOV!D13 -> 13.6 | AK19: =+[2]NOV!E13 -> 24.5 | AL19: =+[2]NOV!F13 -> 71.6 | AM19: =+[2]NOV!G13 -> 8.6 | AN19: =+[2]NOV!H13 -> 132.5 | AO19: =+[2]NOV!I13 -> 0 | ... AQ19: =+[2]NOV!K13 -> 9.4 | AT19: =SUM(AH19:AS19) -> 622.355 | AU19: 26902 | AV19: =AU19-AU18 -> 682 | AW19: =AG19-AV19 -> 0 | AX19: 29.12 | BD19: =+[3]NOV!H14 -> 466.4 | BE19: =BD19-BK19 -> 39 | BF19: =+[3]NOV!B14 -> 29.1 | BG19: =+[3]NOV!C14 -> 148.2 | BH19: =+[3]NOV!D14 -> 133.8 | BI19: =+[3]NOV!E14 -> 116.3 | BK19: =SUM(BF19:BJ19) -> 427.4 | BL19: =ABS(BM19-BK19) -> 27.6 | BM19: =BN19-BN18 -> 455 | BN19: 110542
A20: =A19+1 -> 13 | B20: =SUM(C20:E20) -> 0 | F20: =SUM(G20:I20) -> 0 | J20: =SUM(K20:M20) -> 0 | N20: =B20+F20+J20 -> 0 | U20: =SUM(R20:T20) -> 0 | V20: =B20/U20 -> #DIV/0! | Z20: =SUM(W20:Y20) -> 0 | AA20: =F20/Z20 -> #DIV/0! | AE20: =SUM(AB20:AD20) -> 0 | AF20: =J20/AE20 -> #DIV/0! | AG20: =AV20 -> 609 | AH20: =+[2]NOV!B14 -> 95.804 | AI20: =+[2]NOV!C14 -> 140.548 | AJ20: =+[2]NOV!D14 -> 14.4 | AK20: =+[2]NOV!E14 -> 13.5 | AL20: =+[2]NOV!F14 -> 61.5 | AM20: =+[2]NOV!G14 -> 8.1 | AN20: =+[2]NOV!H14 -> 131.9 | AO20: =+[2]NOV!I14 -> 0 | ... AQ20: =+[2]NOV!K14 -> 7.2 | AT20: =SUM(AH20:AS20) -> 544.952 | AU20: 27511 | AV20: =AU20-AU19 -> 609 | AW20: =AG20-AV20 -> 0 | AX20: 27.08 | BD20: =+[3]NOV!H15 -> 465.8 | BE20: =BD20-BK20 -> 48.6 | BF20: =+[3]NOV!B15 -> 0 | BG20: =+[3]NOV!C15 -> 152.5 | BH20: =+[3]NOV!D15 -> 145.4 | BI20: =+[3]NOV!E15 -> 119.3 | BK20: =SUM(BF20:BJ20) -> 417.2 | BL20: =ABS(BM20-BK20) -> 36.8 | BM20: =BN20-BN19 -> 454 | BN20: 110996
A21: =A20+1 -> 14 | B21: =SUM(C21:E21) -> 0 | F21: =SUM(G21:I21) -> 0 | J21: =SUM(K21:M21) -> 0 | N21: =B21+F21+J21 -> 0 | U21: =SUM(R21:T21) -> 0 | V21: =B21/U21 -> #DIV/0! | Z21: =SUM(W21:Y21) -> 0 | AA21: =F21/Z21 -> #DIV/0! | AE21: =SUM(AB21:AD21) -> 0 | AF21: =J21/AE21 -> #DIV/0! | AG21: =AV21 -> 658 | AH21: =+[2]NOV!B15 -> 115.551 | AI21: =+[2]NOV!C15 -> 139.785 | AJ21: =+[2]NOV!D15 -> 13.6 | AK21: =+[2]NOV!E15 -> 21.4 | AL21: =+[2]NOV!F15 -> 68.8 | AM21: =+[2]NOV!G15 -> 9.7 | AN21: =+[2]NOV!H15 -> 126.5 | AO21: =+[2]NOV!I15 -> 0 | ... AQ21: =+[2]NOV!K15 -> 10.2 | AT21: =SUM(AH21:AS21) -> 605.136 | AU21: 28169 | AV21: =AU21-AU20 -> 658 | AW21: =AG21-AV21 -> 0 | AX21: 26.78 | BD21: =+[3]NOV!H16 -> 583 | BE21: =BD21-BK21 -> 49.5 | BF21: =+[3]NOV!B16 -> 95 | BG21: =+[3]NOV!C16 -> 160.1 | BH21: =+[3]NOV!D16 -> 150.9 | BI21: =+[3]NOV!E16 -> 127.5 | BK21: =SUM(BF21:BJ21) -> 533.5 | BL21: =ABS(BM21-BK21) -> 37.5 | BM21: =BN21-BN20 -> 571 | BN21: 111567
A22: =A21+1 -> 15 | B22: =SUM(C22:E22) -> 0 | F22: =SUM(G22:I22) -> 0 | J22: =SUM(K22:M22) -> 0 | N22: =B22+F22+J22 -> 0 | U22: =SUM(R22:T22) -> 0 | V22: =B22/U22 -> #DIV/0! | Z22: =SUM(W22:Y22) -> 0 | AA22: =F22/Z22 -> #DIV/0! | AE22: =SUM(AB22:AD22) -> 0 | AF22: =J22/AE22 -> #DIV/0! | AG22: =AV22 -> 664 | AH22: =+[2]NOV!B16 -> 120.894 | AI22: =+[2]NOV!C16 -> 126.219 | AJ22: =+[2]NOV!D16 -> 17.6 | AK22: =+[2]NOV!E16 -> 19 | AL22: =+[2]NOV!F16 -> 70.8 | AM22: =+[2]NOV!G16 -> 10.8 | AN22: =+[2]NOV!H16 -> 126.9 | AO22: =+[2]NOV!I16 -> 0 | ... AQ22: =+[2]NOV!K16 -> 10.8 | AT22: =SUM(AH22:AS22) -> 604.813 | AU22: 28833 | AV22: =AU22-AU21 -> 664 | AW22: =AG22-AV22 -> 0 | AX22: 27.46 | BD22: =+[3]NOV!H17 -> 590.3 | BE22: =BD22-BK22 -> 33 | BF22: =+[3]NOV!B17 -> 128.4 | BG22: =+[3]NOV!C17 -> 150.1 | BH22: =+[3]NOV!D17 -> 152.5 | BI22: =+[3]NOV!E17 -> 126.3 | BK22: =SUM(BF22:BJ22) -> 557.3 | BL22: =ABS(BM22-BK22) -> 49.7 | BM22: =BN22-BN21 -> 607 | BN22: 112174
A23: =A22+1 -> 16 | B23: =SUM(C23:E23) -> 0 | F23: =SUM(G23:I23) -> 0 | J23: =SUM(K23:M23) -> 0 | N23: =B23+F23+J23 -> 0 | U23: =SUM(R23:T23) -> 0 | V23: =B23/U23 -> #DIV/0! | Z23: =SUM(W23:Y23) -> 0 | AA23: =F23/Z23 -> #DIV/0! | AE23: =SUM(AB23:AD23) -> 0 | AF23: =J23/AE23 -> #DIV/0! | AG23: =AV23 -> 696 | AH23: =+[2]NOV!B17 -> 124.684 | AI23: =+[2]NOV!C17 -> 135.373 | AJ23: =+[2]NOV!D17 -> 16.1 | AK23: =+[2]NOV!E17 -> 54.8 | AL23: =+[2]NOV!F17 -> 71.5 | AM23: =+[2]NOV!G17 -> 12 | AN23: =+[2]NOV!H17 -> 123.8 | AO23: =+[2]NOV!I17 -> 0 | ... AQ23: =+[2]NOV!K17 -> 9.6 | AT23: =SUM(AH23:AS23) -> 630.257 | AU23: 29529 | AV23: =AU23-AU22 -> 696 | AW23: =AG23-AV23 -> 0 | AX23: 30.41 | BD23: =+[3]NOV!H18 -> 624.1 | BE23: =BD23-BK23 -> 55 | BF23: =+[3]NOV!B18 -> 136.5 | BG23: =+[3]NOV!C18 -> 134.4 | BH23: =+[3]NOV!D18 -> 169.4 | BI23: =+[3]NOV!E18 -> 128.8 | BK23: =SUM(BF23:BJ23) -> 569.1 | BL23: =ABS(BM23-BK23) -> 43.9 | BM23: =BN23-BN22 -> 613 | BN23: 112787
A24: =A23+1 -> 17 | B24: =SUM(C24:E24) -> 0 | F24: =SUM(G24:I24) -> 0 | J24: =SUM(K24:M24) -> 0 | N24: =B24+F24+J24 -> 0 | U24: =SUM(R24:T24) -> 0 | V24: =B24/U24 -> #DIV/0! | Z24: =SUM(W24:Y24) -> 0 | AA24: =F24/Z24 -> #DIV/0! | AE24: =SUM(AB24:AD24) -> 0 | AF24: =J24/AE24 -> #DIV/0! | AG24: =AV24 -> 714 | AH24: =+[2]NOV!B18 -> 111.85 | AI24: =+[2]NOV!C18 -> 134.843 | AJ24: =+[2]NOV!D18 -> 14.8 | AK24: =+[2]NOV!E18 -> 61.1 | AL24: =+[2]NOV!F18 -> 70.4 | AM24: =+[2]NOV!G18 -> 11.6 | AN24: =+[2]NOV!H18 -> 131.7 | AO24: =+[2]NOV!I18 -> 0 | ... AQ24: =+[2]NOV!K18 -> 11.2 | AT24: =SUM(AH24:AS24) -> 648.593 | AU24: 30243 | AV24: =AU24-AU23 -> 714 | AW24: =AG24-AV24 -> 0 | AX24: 30.47 | BD24: =+[3]NOV!H19 -> 587 | BE24: =BD24-BK24 -> 54.8 | BF24: =+[3]NOV!B19 -> 132.9 | BG24: =+[3]NOV!C19 -> 152.7 | BH24: =+[3]NOV!D19 -> 131.6 | BI24: =+[3]NOV!E19 -> 115 | BK24: =SUM(BF24:BJ24) -> 532.2 | BL24: =ABS(BM24-BK24) -> 46.8 | BM24: =BN24-BN23 -> 579 | BN24: 113366
A25: =A24+1 -> 18 | B25: =SUM(C25:E25) -> 0 | F25: =SUM(G25:I25) -> 0 | J25: =SUM(K25:M25) -> 0 | N25: =B25+F25+J25 -> 0 | U25: =SUM(R25:T25) -> 0 | V25: =B25/U25 -> #DIV/0! | Z25: =SUM(W25:Y25) -> 0 | AA25: =F25/Z25 -> #DIV/0! | AE25: =SUM(AB25:AD25) -> 0 | AF25: =J25/AE25 -> #DIV/0! | AG25: =AV25 -> 717 | AH25: =+[2]NOV!B19 -> 123.029 | AI25: =+[2]NOV!C19 -> 137.159 | AJ25: =+[2]NOV!D19 -> 16 | AK25: =+[2]NOV!E19 -> 55.8 | AL25: =+[2]NOV!F19 -> 65.6 | AM25: =+[2]NOV!G19 -> 9 | AN25: =+[2]NOV!H19 -> 132 | AO25: =+[2]NOV!I19 -> 0 | ... AQ25: =+[2]NOV!K19 -> 10.1 | AT25: =SUM(AH25:AS25) -> 647.988 | AU25: 30960 | AV25: =AU25-AU24 -> 717 | AW25: =AG25-AV25 -> 0 | AX25: 29.47 | BD25: =+[3]NOV!H20 -> 576.2 | BE25: =BD25-BK25 -> 53.1 | BF25: =+[3]NOV!B20 -> 142.3 | BG25: =+[3]NOV!C20 -> 148.7 | BH25: =+[3]NOV!D20 -> 114.1 | BI25: =+[3]NOV!E20 -> 118 | BK25: =SUM(BF25:BJ25) -> 523.1 | BL25: =ABS(BM25-BK25) -> 39.9 | BM25: =BN25-BN24 -> 563 | BN25: 113929
A26: =A25+1 -> 19 | B26: =SUM(C26:E26) -> 0 | F26: =SUM(G26:I26) -> 0 | J26: =SUM(K26:M26) -> 0 | N26: =B26+F26+J26 -> 0 | U26: =SUM(R26:T26) -> 0 | V26: =B26/U26 -> #DIV/0! | Z26: =SUM(W26:Y26) -> 0 | AA26: =F26/Z26 -> #DIV/0! | AE26: =SUM(AB26:AD26) -> 0 | AF26: =J26/AE26 -> #DIV/0! | AG26: =AV26 -> 690 | AH26: =+[2]NOV!B20 -> 136.767 | AI26: =+[2]NOV!C20 -> 136.566 | AJ26: =+[2]NOV!D20 -> 16.2 | AK26: =+[2]NOV!E20 -> 29.1 | AL26: =+[2]NOV!F20 -> 69.4 | AM26: =+[2]NOV!G20 -> 10.4 | AN26: =+[2]NOV!H20 -> 130.1 | AO26: =+[2]NOV!I20 -> 0 | ... AQ26: =+[2]NOV!K20 -> 8.6 | AT26: =SUM(AH26:AS26) -> 619.033 | AU26: 31650 | AV26: =AU26-AU25 -> 690 | AW26: =AG26-AV26 -> 0 | AX26: 28.34 | BD26: =+[3]NOV!H21 -> 590.7 | BE26: =BD26-BK26 -> 54.5 | BF26: =+[3]NOV!B21 -> 129 | BG26: =+[3]NOV!C21 -> 150.5 | BH26: =+[3]NOV!D21 -> 130 | BI26: =+[3]NOV!E21 -> 126.7 | BK26: =SUM(BF26:BJ26) -> 536.2 | BL26: =ABS(BM26-BK26) -> 37.8 | BM26: =BN26-BN25 -> 574 | BN26: 114503
A27: =A26+1 -> 20 | B27: =SUM(C27:E27) -> 0 | F27: =SUM(G27:I27) -> 0 | J27: =SUM(K27:M27) -> 0 | N27: =B27+F27+J27 -> 0 | U27: =SUM(R27:T27) -> 0 | V27: =B27/U27 -> #DIV/0! | Z27: =SUM(W27:Y27) -> 0 | AA27: =F27/Z27 -> #DIV/0! | AE27: =SUM(AB27:AD27) -> 0 | AF27: =J27/AE27 -> #DIV/0! | AG27: =AV27 -> 705 | AH27: =+[2]NOV!B21 -> 134.458 | AI27: =+[2]NOV!C21 -> 134.851 | AJ27: =+[2]NOV!D21 -> 18 | AK27: =+[2]NOV!E21 -> 33.4 | AL27: =+[2]NOV!F21 -> 69.7 | AM27: =+[2]NOV!G21 -> 10 | AN27: =+[2]NOV!H21 -> 128.8 | AO27: =+[2]NOV!I21 -> 0 | ... AQ27: =+[2]NOV!K21 -> 9.4 | AT27: =SUM(AH27:AS27) -> 638.409 | AU27: 32355 | AV27: =AU27-AU26 -> 705 | AW27: =AG27-AV27 -> 0 | AX27: 29.78 | BD27: =+[3]NOV!H22 -> 603.7 | BE27: =BD27-BK27 -> 49.9 | BF27: =+[3]NOV!B22 -> 137.4 | BG27: =+[3]NOV!C22 -> 149.9 | BH27: =+[3]NOV!D22 -> 135.5 | BI27: =+[3]NOV!E22 -> 131 | BK27: =SUM(BF27:BJ27) -> 553.8 | BL27: =ABS(BM27-BK27) -> 46.2 | BM27: =BN27-BN26 -> 600 | BN27: 115103
A28: =A27+1 -> 21 | B28: =SUM(C28:E28) -> 0 | F28: =SUM(G28:I28) -> 0 | J28: =SUM(K28:M28) -> 0 | N28: =B28+F28+J28 -> 0 | U28: =SUM(R28:T28) -> 0 | V28: =B28/U28 -> #DIV/0! | Z28: =SUM(W28:Y28) -> 0 | AA28: =F28/Z28 -> #DIV/0! | AE28: =SUM(AB28:AD28) -> 0 | AF28: =J28/AE28 -> #DIV/0! | AG28: =AV28 -> 735 | AH28: =+[2]NOV!B22 -> 132.782 | AI28: =+[2]NOV!C22 -> 134.2 | AJ28: =+[2]NOV!D22 -> 17.6 | AK28: =+[2]NOV!E22 -> 55.5 | AL28: =+[2]NOV!F22 -> 70.3 | AM28: =+[2]NOV!G22 -> 9.8 | AN28: =+[2]NOV!H22 -> 128 | AO28: =+[2]NOV!I22 -> 0 | ... AQ28: =+[2]NOV!K22 -> 9.8 | AT28: =SUM(AH28:AS28) -> 658.382 | AU28: 33090 | AV28: =AU28-AU27 -> 735 | AW28: =AG28-AV28 -> 0 | AX28: 31.5 | BD28: =+[3]NOV!H23 -> 543 | BE28: =BD28-BK28 -> 45.3 | BF28: =+[3]NOV!B23 -> 88 | BG28: =+[3]NOV!C23 -> 150.2 | BH28: =+[3]NOV!D23 -> 130.3 | BI28: =+[3]NOV!E23 -> 129.2 | BK28: =SUM(BF28:BJ28) -> 497.7 | BL28: =ABS(BM28-BK28) -> 35.3 | BM28: =BN28-BN27 -> 533 | BN28: 115636
A29: =A28+1 -> 22 | B29: =SUM(C29:E29) -> 0 | F29: =SUM(G29:I29) -> 0 | J29: =SUM(K29:M29) -> 0 | N29: =B29+F29+J29 -> 0 | U29: =SUM(R29:T29) -> 0 | V29: =B29/U29 -> #DIV/0! | Z29: =SUM(W29:Y29) -> 0 | AA29: =F29/Z29 -> #DIV/0! | AE29: =SUM(AB29:AD29) -> 0 | AF29: =J29/AE29 -> #DIV/0! | AG29: =AV29 -> 722 | AH29: =+[2]NOV!B23 -> 123.971 | AI29: =+[2]NOV!C23 -> 134.357 | AJ29: =+[2]NOV!D23 -> 17 | AK29: =+[2]NOV!E23 -> 52.9 | AL29: =+[2]NOV!F23 -> 70.2 | AM29: =+[2]NOV!G23 -> 9.7 | AN29: =+[2]NOV!H23 -> 128 | AO29: =+[2]NOV!I23 -> 0 | ... AQ29: =+[2]NOV!K23 -> 10.1 | AT29: =SUM(AH29:AS29) -> 645.728 | AU29: 33812 | AV29: =AU29-AU28 -> 722 | AW29: =AG29-AV29 -> 0 | AX29: 24.35 | BD29: =+[3]NOV!H24 -> 501.6 | BE29: =BD29-BK29 -> 43.1 | BF29: =+[3]NOV!B24 -> 67.1 | BG29: =+[3]NOV!C24 -> 139.6 | BH29: =+[3]NOV!D24 -> 129.9 | BI29: =+[3]NOV!E24 -> 121.9 | BK29: =SUM(BF29:BJ29) -> 458.5 | BL29: =ABS(BM29-BK29) -> 38.5 | BM29: =BN29-BN28 -> 497 | BN29: 116133
A30: =A29+1 -> 23 | B30: =SUM(C30:E30) -> 0 | F30: =SUM(G30:I30) -> 0 | J30: =SUM(K30:M30) -> 0 | N30: =B30+F30+J30 -> 0 | U30: =SUM(R30:T30) -> 0 | V30: =B30/U30 -> #DIV/0! | Z30: =SUM(W30:Y30) -> 0 | AA30: =F30/Z30 -> #DIV/0! | AE30: =SUM(AB30:AD30) -> 0 | AF30: =J30/AE30 -> #DIV/0! | AG30: =AV30 -> 709 | AH30: =+[2]NOV!B24 -> 131.047 | AI30: =+[2]NOV!C24 -> 135.596 | AJ30: =+[2]NOV!D24 -> 17.6 | AK30: =+[2]NOV!E24 -> 55.5 | AL30: =+[2]NOV!F24 -> 69.1 | AM30: =+[2]NOV!G24 -> 10.5 | AN30: =+[2]NOV!H24 -> 128 | AO30: =+[2]NOV!I24 -> 0 | ... AQ30: =+[2]NOV!K24 -> 9.4 | AT30: =SUM(AH30:AS30) -> 643.643 | AU30: 34521 | AV30: =AU30-AU29 -> 709 | AW30: =AG30-AV30 -> 0 | AX30: 30.42 | BD30: =+[3]NOV!H25 -> 552.1 | BE30: =BD30-BK30 -> 41.5 | BF30: =+[3]NOV!B25 -> 106.7 | BG30: =+[3]NOV!C25 -> 146.8 | BH30: =+[3]NOV!D25 -> 131.4 | BI30: =+[3]NOV!E25 -> 125.7 | BK30: =SUM(BF30:BJ30) -> 510.6 | BL30: =ABS(BM30-BK30) -> 28.4 | BM30: =BN30-BN29 -> 539 | BN30: 116672
... A36: =A35+1 -> 29 | B36: =SUM(C36:E36) -> 0 | F36: =SUM(G36:I36) -> 0 | J36: =SUM(K36:M36) -> 0 | N36: =B36+F36+J36 -> 0 | U36: =SUM(R36:T36) -> 0 | V36: =B36/U36 -> #DIV/0! | Z36: =SUM(W36:Y36) -> 0 | AA36: =F36/Z36 -> #DIV/0! | AE36: =SUM(AB36:AD36) -> 0 | AF36: =J36/AE36 -> #DIV/0! | AG36: =AV36 -> 685 | AH36: =+[2]NOV!B30 -> 123.578 | AI36: =+[2]NOV!C30 -> 116.161 | AJ36: =+[2]NOV!D30 -> 20.4 | AK36: =+[2]NOV!E30 -> 50.3 | AL36: =+[2]NOV!F30 -> 66.9 | AM36: =+[2]NOV!G30 -> 10.2 | AN36: =+[2]NOV!H30 -> 120.6 | AO36: =+[2]NOV!I30 -> 0 | ... AQ36: =+[2]NOV!K30 -> 9.6 | AT36: =SUM(AH36:AS36) -> 615.039 | AU36: 38568 | AV36: =AU36-AU35 -> 685 | AW36: =AG36-AV36 -> 0 | AX36: 32.74 | BD36: =+[3]NOV!H31 -> 582 | BE36: =BD36-BK36 -> 47.2 | BF36: =+[3]NOV!B31 -> 140.4 | BG36: =+[3]NOV!C31 -> 144.1 | BH36: =+[3]NOV!D31 -> 129 | BI36: =+[3]NOV!E31 -> 121.3 | BK36: =SUM(BF36:BJ36) -> 534.8 | BL36: =ABS(BM36-BK36) -> 44.2 | BM36: =BN36-BN35 -> 579 | BN36: 120104
A37: 30 | AE37: =SUM(AB37:AD37) -> 0 | AF37: =J37/AE37 -> #DIV/0! | AG37: =AV37 -> 684 | AH37: =+[2]NOV!B31 -> 119.416 | AI37: =+[2]NOV!C31 -> 113.278 | AJ37: =+[2]NOV!D31 -> 19.2 | AK37: =+[2]NOV!E31 -> 52.1 | AL37: =+[2]NOV!F31 -> 66.7 | AM37: =+[2]NOV!G31 -> 9.8 | AN37: =+[2]NOV!H31 -> 124.4 | AO37: =+[2]NOV!I31 -> 0 | ... AQ37: =+[2]NOV!K31 -> 10 | AT37: =SUM(AH37:AS37) -> 613.294 | AU37: 39252 | AV37: =AU37-AU36 -> 684 | AW37: =AG37-AV37 -> 0 | AX37: 28.43 | BD37: =+[3]NOV!H32 -> 578 | BE37: =BD37-BK37 -> 50.1 | BF37: =+[3]NOV!B32 -> 129.8 | BG37: =+[3]NOV!C32 -> 146 | BH37: =+[3]NOV!D32 -> 127.1 | BI37: =+[3]NOV!E32 -> 125 | BK37: =SUM(BF37:BJ37) -> 527.9 | BL37: =ABS(BM37-BK37) -> 38.1 | BM37: =BN37-BN36 -> 566 | BN37: 120670
A40: Total | B40: =SUM(B8:B36) -> 0 | D40: =SUM(D8:D36) -> 0 | E40: =SUM(E8:E36) -> 0 | F40: =SUM(F8:F36) -> 0 | J40: =SUM(J8:J36) -> 0 | N40: =SUM(N8:N36) -> 0 | O40: =SUM(O8:O36) -> 0 | P40: =SUM(P8:P36) -> 0 | Q40: =SUM(Q8:Q36) -> 0 | U40: =SUMIF(U9:U36,">0") -> 0 | V40: =B40/U40 -> #DIV/0! | Z40: =SUMIF(Z8:Z36,">0") -> 0 | AA40: =F40/Z40 -> #DIV/0! | AE40: =SUMIF(AE8:AE36,">0") -> 0 | AF40: =J40/AE40 -> #DIV/0! | AG40: =SUMIF(AG8:AG38,">0") -> 20063 | AH40: =SUMIF(AH8:AH38,">0") -> 3798.933 | AI40: =SUMIF(AI8:AI38,">0") -> 3914.689 | AJ40: =SUMIF(AJ8:AJ38,">0") -> 478.9 | AK40: =SUMIF(AK8:AK38,">0") -> 1095.3 | AL40: =SUMIF(AL8:AL38,">0") -> 2015.3 | AM40: =SUMIF(AM8:AM38,">0") -> 297.3 | AN40: =SUMIF(AN8:AN38,">0") -> 3773 | AP40: =SUMIF(AP8:AP38,">0") -> 2844.5 | AQ40: =SUMIF(AQ8:AQ38,">0") -> 284.5 | AR40: =SUMIF(AR8:AR38,">0") -> 0 | AS40: =SUMIF(AS8:AS38,">0") -> 0 | AT40: =SUM(AT8:AT38) -> 18502.422 | AV40: =SUMIF(AV8:AV38,">0") -> 20063 | AY40: =SUMIF(AY8:AY36,">0") -> 0 | AZ40: =SUMIF(AZ8:AZ36,">0") -> 0 | BA40: =SUMIF(BA8:BA36,">0") -> 0
A41: Average | V41: =U40/B40 -> #DIV/0! | AA41: =Z40/F40 -> #DIV/0! | AT41: =AG40-AT40 -> 1560.578 | AV41: =AV40-AG40 -> 0
A43: RATA-RATA | B43: =SUM(B40/31) -> 0 | F43: =SUM(F40/31) -> 0 | J43: =SUM(J40/31) -> 0 | N43: =SUM(N40/31) -> 0 | P43: =SUM(P40/31) -> 0 | U43: =SUM(U40/31) -> 0 | V43: =SUM(V40/31) -> #DIV/0! | Z43: =SUM(Z40/31) -> 0 | AA43: =SUM(AA40/31) -> #DIV/0! | AE43: =SUM(AE40/31) -> 0 | AF43: =SUM(AF40/31) -> #DIV/0! | AH43: =SUM(AH40/31) -> 122.54623 | AT43: =AT40/AG40 -> 0.92221612
AT44: =AT41/AG40 -> 0.077783881
BK45: =SUM(BK13:BK38) -> 12945 | BL45: =SUM(BL8:BL38) -> 1221 | BM45: =SUM(BM13:BM38) -> 13947
B47: STD BB / Ton steam = < dr 200 | AG47: Data pemakaian steam :
AG48: Flowmeter akhir | AI48: =AU37 -> 39252
AG49: Flowmeter awal | AI49: 612232
AG50: Total pemakaian | AI50: =AI48-AI49 -> -572980
...

Sheet Steam
B2: DATA PEMAKAIAN STEAM PER HARI ( TPD )
B3: Bulan November
B4: TGL | C4: TOTAL BATUBARA | F4: STEAM | H4: KOSUMSI STEAM PM 11 | I4: KOSUMSI STEAM PM 12 | J4: KOSUMSI STEAM PM 14 | K4: KOSUMSI STEAM PM 15 | L4: KOSUMSI STEAM PM 16 | M4: KOSUMSI STEAM PM 17 | N4: KOSUMSI STEAM DIP-PM12 | O4: KOSUMSI STEAM DIP-PM15 | P4: KOSUMSI STEAM DIP-PM16 | Q4: KOSUMSI STEAM DIP-PM17 | R4: TOTAL KOSUMSI STEAM | S4: SELISIH BOILER - PM | W4: KETERANGAN | X4: Steam SIN-SUN 2 | Y4: SP | Z4: Konsumsi | AE4: Total konsumsi | AF4: Selisih | AH4: Percentage
C5: Total Boiler 1 | D5: Total Boiler 2 | E5: Total Boiler 3 | F5: BOILER 1+2+3 | G5: STEAM SINERGY | S5: TODAY | T5: % (TODAY) | U5: TODATE | V5: % (TODATE) | W5: PM STOP | Z5: PM18 | AA5: PM19 | AB5: PM20 | AC5: PM21 | AD5: PM22 | AF5: SIN-SUN2 | AG5: SP-SUN2 | AH5: SIN-SUN2 | AI5: SP-SUN2
B6: 45962 | C6: =Master!B8 -> 0 | D6: =Master!F8 -> 0 | E6: =Master!J8 -> 0 | F6: =Master!U8+Master!Z8+Master!AE8 -> 0 | G6: =Master!AG8 -> 656 | H6: =Master!AH8 -> 152.922 | I6: =Master!AI8 -> 127.483 | J6: =Master!AK8 -> 25.3 | K6: =Master!AL8 -> 62.9 | L6: =Master!AN8 -> 137.7 | M6: =Master!AP8 -> 86.3 | N6: =Master!AJ8 -> 12.8 | O6: =Master!AM8 -> 7.9 | P6: =Master!AO8 -> 0 | Q6: =Master!AQ8 -> 7.3 | R6: =SUM(H6:Q6) -> 620.605 | S6: =(F6+G6)-R6 -> 35.395 | T6: =S6/(F6+G6) -> 0.053955793 | U6: =(F6+G6)-R6 -> 35.395 | V6: =+U6/(F6+(SUM($G$6:G6))) -> 0.053955793 | W6: PM 14 1440menit | X6: =Master!BM8 -> 400 | Y6: =Master!BD8 -> 401.2 | Z6: =Master!BF8 -> 145.8 | AA6: =Master!BG8 -> 71.8 | AB6: =Master!BH8 -> 0 | AC6: =Master!BI8 -> 126.8 | AE6: =SUM(Z6:AD6) -> 344.4 | AF6: =ABS(X6-AE6) -> 55.6 | AG6: =ABS(Y6-AE6) -> 56.8 | AH6: =AF6/X6 -> 0.139 | AI6: =AG6/Y6 -> 0.14157527
B7: =1+B6 -> 45963 | C7: =Master!B9 -> 0 | D7: =Master!F9 -> 0 | E7: =Master!J9 -> 0 | F7: =Master!U9+Master!Z9+Master!AE9 -> 0 | G7: =Master!AG9 -> 653 | H7: =Master!AH9 -> 158.395 | I7: =Master!AI9 -> 129.185 | J7: =Master!AK9 -> 23.5 | K7: =Master!AL9 -> 67.8 | L7: =Master!AN9 -> 135.2 | M7: =Master!AP9 -> 73.9 | N7: =Master!AJ9 -> 13.6 | O7: =Master!AM9 -> 10.9 | P7: =Master!AO9 -> 0 | Q7: =Master!AQ9 -> 8 | R7: =SUM(H7:Q7) -> 620.48 | S7: =(F7+G7)-R7 -> 32.52 | T7: =S7/(F7+G7) -> 0.049800919 | U7: =(F7+G7)-R7+U6 -> 67.915 | V7: =+U7/(F7+(SUM($G$6:G7))) -> 0.051883117 | W7: PM 14 1440menit | X7: =Master!BM9 -> 401 | Y7: =Master!BD9 -> 404.2 | Z7: =Master!BF9 -> 132.1 | AA7: =Master!BG9 -> 108.4 | AB7: =Master!BH9 -> 0 | AC7: =Master!BI9 -> 126.9 | AE7: =SUM(Z7:AD7) -> 367.4 | AF7: =ABS(X7-AE7) -> 33.6 | AG7: =ABS(Y7-AE7) -> 36.8 | AH7: =AF7/X7 -> 0.083790524 | AI7: =AG7/Y7 -> 0.091044038
B8: =1+B7 -> 45964 | C8: =Master!B10 -> 0 | D8: =Master!F10 -> 0 | E8: =Master!J10 -> 0 | F8: =Master!U10+Master!Z10+Master!AE10 -> 0 | G8: =Master!AG10 -> 592 | H8: =Master!AH10 -> 167.041 | I8: =Master!AI10 -> 137.223 | J8: =Master!AK10 -> 23.4 | K8: =Master!AL10 -> 69 | L8: =Master!AN10 -> 58.3 | M8: =Master!AP10 -> 87.9 | N8: =Master!AJ10 -> 11.2 | O8: =Master!AM10 -> 9.9 | P8: =Master!AO10 -> 0 | Q8: =Master!AQ10 -> 8.1 | R8: =SUM(H8:Q8) -> 572.064 | S8: =(F8+G8)-R8 -> 19.936 | T8: =S8/(F8+G8) -> 0.033675676 | U8: =(F8+G8)-R8+U7 -> 87.851 | V8: =+U8/(F8+(SUM($G$6:G8))) -> 0.046213046 | W8: PM 14 1440menit, PM 16 901menit, Steam Yankee PM 12 Error | X8: =Master!BM10 -> 454 | Y8: =Master!BD10 -> 460.4 | Z8: =Master!BF10 -> 144.8 | AA8: =Master!BG10 -> 147.3 | AB8: =Master!BH10 -> 5.6 | AC8: =Master!BI10 -> 125.7 | AE8: =SUM(Z8:AD8) -> 423.4 | AF8: =ABS(X8-AE8) -> 30.6 | AG8: =ABS(Y8-AE8) -> 37 | AH8: =AF8/X8 -> 0.067400881 | AI8: =AG8/Y8 -> 0.0803649
B9: =1+B8 -> 45965 | C9: =Master!B11 -> 0 | D9: =Master!F11 -> 0 | E9: =Master!J11 -> 0 | F9: =Master!U11+Master!Z11+Master!AE11 -> 0 | G9: =Master!AG11 -> 656 | H9: =Master!AH11 -> 147.047 | I9: =Master!AI11 -> 138.831 | J9: =Master!AK11 -> 7.1 | K9: =Master!AL11 -> 68.5 | L9: =Master!AN11 -> 139.5 | M9: =Master!AP11 -> 100.8 | N9: =Master!AJ11 -> 15.2 | O9: =Master!AM11 -> 11.1 | P9: =Master!AO11 -> 0 | Q9: =Master!AQ11 -> 10.5 | R9: =SUM(H9:Q9) -> 638.578 | S9: =(F9+G9)-R9 -> 17.422 | T9: =S9/(F9+G9) -> 0.026557927 | U9: =(F9+G9)-R9+U8 -> 105.273 | V9: =+U9/(F9+(SUM($G$6:G9))) -> 0.041170512 | W9: PM 14 1440menit | X9: =Master!BM11 -> 513 | Y9: =Master!BD11 -> 518.8 | Z9: =Master!BF11 -> 153 | AA9: =Master!BG11 -> 147.5 | AB9: =Master!BH11 -> 46.3 | AC9: =Master!BI11 -> 124.1 | AE9: =SUM(Z9:AD9) -> 470.9 | AF9: =ABS(X9-AE9) -> 42.1 | AG9: =ABS(Y9-AE9) -> 47.9 | AH9: =AF9/X9 -> 0.082066277 | AI9: =AG9/Y9 -> 0.09232845
B10: =1+B9 -> 45966 | C10: =Master!B12 -> 0 | D10: =Master!F12 -> 0 | E10: =Master!J12 -> 0 | F10: =Master!U12+Master!Z12+Master!AE12 -> 0 | G10: =Master!AG12 -> 580 | H10: =Master!AH12 -> 115.565 | I10: =Master!AI12 -> 141.54 | J10: =Master!AK12 -> 3.3 | K10: =Master!AL12 -> 45.6 | L10: =Master!AN12 -> 134.6 | M10: =Master!AP12 -> 85.1 | N10: =Master!AJ12 -> 15.2 | O10: =Master!AM12 -> 6 | P10: =Master!AO12 -> 0 | Q10: =Master!AQ12 -> 8.3 | R10: =SUM(H10:Q10) -> 555.205 | S10: =(F10+G10)-R10 -> 24.795 | T10: =S10/(F10+G10) -> 0.04275 | U10: =(F10+G10)-R10+U9 -> 130.068 | V10: =+U10/(F10+(SUM($G$6:G10))) -> 0.041462544 | W10: PM 14 1440menit, PM 15 415menit | X10: =Master!BM12 -> 530 | Y10: =Master!BD12 -> 532.6 | Z10: =Master!BF12 -> 154.2 | AA10: =Master!BG12 -> 140 | AB10: =Master!BH12 -> 112.6 | AC10: =Master!BI12 -> 66.1 | AE10: =SUM(Z10:AD10) -> 472.9 | AF10: =ABS(X10-AE10) -> 57.1 | AG10: =ABS(Y10-AE10) -> 59.7 | AH10: =AF10/X10 -> 0.10773585 | AI10: =AG10/Y10 -> 0.11209163
B11: =1+B10 -> 45967 | C11: =Master!B13 -> 0 | D11: =Master!F13 -> 0 | E11: =Master!J13 -> 0 | F11: =Master!U13+Master!Z13+Master!AE13 -> 0 | G11: =Master!AG13 -> 632 | H11: =Master!AH13 -> 116.557 | I11: =Master!AI13 -> 144.627 | J11: =Master!AK13 -> 4.3 | K11: =Master!AL13 -> 70.7 | L11: =Master!AN13 -> 137 | M11: =Master!AP13 -> 93.1 | N11: =Master!AJ13 -> 14.4 | O11: =Master!AM13 -> 11 | P11: =Master!AO13 -> 0 | Q11: =Master!AQ13 -> 7.9 | R11: =SUM(H11:Q11) -> 599.584 | S11: =(F11+G11)-R11 -> 32.416 | T11: =S11/(F11+G11) -> 0.051291139 | U11: =(F11+G11)-R11+U10 -> 162.484 | V11: =+U11/(F11+(SUM($G$6:G11))) -> 0.043110639 | W11: PM 14 1440menit | X11: =Master!BM13 -> 544 | Y11: =Master!BD13 -> 560.5 | Z11: =Master!BF13 -> 147.7 | AA11: =Master!BG13 -> 153.4 | AB11: =Master!BH13 -> 143.3 | AC11: =Master!BI13 -> 45.7 | AE11: =SUM(Z11:AD11) -> 490.1 | AF11: =ABS(X11-AE11) -> 53.9 | AG11: =ABS(Y11-AE11) -> 70.4 | AH11: =AF11/X11 -> 0.099080882 | AI11: =AG11/Y11 -> 0.12560214
B12: =1+B11 -> 45968 | C12: =Master!B14 -> 0 | D12: =Master!F14 -> 0 | E12: =Master!J14 -> 0 | F12: =Master!U14+Master!Z14+Master!AE14 -> 0 | G12: =Master!AG14 -> 637 | H12: =Master!AH14 -> 118.986 | I12: =Master!AI14 -> 125.8 | J12: =Master!AK14 -> 27.7 | K12: =Master!AL14 -> 66.1 | L12: =Master!AN14 -> 136.4 | M12: =Master!AP14 -> 98.9 | N12: =Master!AJ14 -> 12.8 | O12: =Master!AM14 -> 10.8 | P12: =Master!AO14 -> 0 | Q12: =Master!AQ14 -> 9 | R12: =SUM(H12:Q12) -> 606.486 | S12: =(F12+G12)-R12 -> 30.514 | T12: =S12/(F12+G12) -> 0.047902669 | U12: =(F12+G12)-R12+U11 -> 192.998 | V12: =+U12/(F12+(SUM($G$6:G12))) -> 0.04380345 | W12: PM 14 1440menit | X12: =Master!BM14 -> 592 | Y12: =Master!BD14 -> 583.9 | Z12: =Master!BF14 -> 157.2 | AA12: =Master!BG14 -> 157.2 | AB12: =Master!BH14 -> 136.2 | AC12: =Master!BI14 -> 112.5 | AE12: =SUM(Z12:AD12) -> 563.1 | AF12: =ABS(X12-AE12) -> 28.9 | AG12: =ABS(Y12-AE12) -> 20.8 | AH12: =AF12/X12 -> 0.048817568 | AI12: =AG12/Y12 -> 0.035622538
B13: =1+B12 -> 45969 | C13: =Master!B15 -> 0 | D13: =Master!F15 -> 0 | E13: =Master!J15 -> 0 | F13: =Master!U15+Master!Z15+Master!AE15 -> 0 | G13: =Master!AG15 -> 647 | H13: =Master!AH15 -> 113.193 | I13: =Master!AI15 -> 131.1 | J13: =Master!AK15 -> 29.6 | K13: =Master!AL15 -> 66.6 | L13: =Master!AN15 -> 137.8 | M13: =Master!AP15 -> 99.5 | N13: =Master!AJ15 -> 14.4 | O13: =Master!AM15 -> 10.4 | P13: =Master!AO15 -> 0 | Q13: =Master!AQ15 -> 9.4 | R13: =SUM(H13:Q13) -> 611.993 | S13: =(F13+G13)-R13 -> 35.007 | T13: =S13/(F13+G13) -> 0.054106646 | U13: =(F13+G13)-R13+U12 -> 228.005 | V13: =+U13/(F13+(SUM($G$6:G13))) -> 0.045122699 | W13: PM 14 1440menit | X13: =Master!BM15 -> 618 | Y13: =Master!BD15 -> 627.2 | Z13: =Master!BF15 -> 160.3 | AA13: =Master!BG15 -> 157.8 | AB13: =Master!BH15 -> 133.3 | AC13: =Master!BI15 -> 128.3 | AE13: =SUM(Z13:AD13) -> 579.7 | AF13: =ABS(X13-AE13) -> 38.3 | AG13: =ABS(Y13-AE13) -> 47.5 | AH13: =AF13/X13 -> 0.06197411 | AI13: =AG13/Y13 -> 0.075733418
B14: =1+B13 -> 45970 | C14: =Master!B16 -> 0 | D14: =Master!F16 -> 0 | E14: =Master!J16 -> 0 | F14: =Master!U16+Master!Z16+Master!AE16 -> 0 | G14: =Master!AG16 -> 653 | H14: =Master!AH16 -> 117.136 | I14: =Master!AI16 -> 128.4 | J14: =Master!AK16 -> 34.8 | K14: =Master!AL16 -> 65.8 | L14: =Master!AN16 -> 138.5 | M14: =Master!AP16 -> 101.5 | N14: =Master!AJ16 -> 15.2 | O14: =Master!AM16 -> 10.8 | P14: =Master!AO16 -> 0 | Q14: =Master!AQ16 -> 10.8 | R14: =SUM(H14:Q14) -> 622.936 | S14: =(F14+G14)-R14 -> 30.064 | T14: =S14/(F14+G14) -> 0.046039816 | U14: =(F14+G14)-R14+U13 -> 258.069 | V14: =+U14/(F14+(SUM($G$6:G14))) -> 0.045227655 | W14: PM 14 1440menit | X14: =Master!BM16 -> 601 | Y14: =Master!BD16 -> 612.2 | Z14: =Master!BF16 -> 146.1 | AA14: =Master!BG16 -> 158 | AB14: =Master!BH16 -> 126.8 | AC14: =Master!BI16 -> 124.7 | AE14: =SUM(Z14:AD14) -> 555.6 | AF14: =ABS(X14-AE14) -> 45.4 | AG14: =ABS(Y14-AE14) -> 56.6 | AH14: =AF14/X14 -> 0.075540765 | AI14: =AG14/Y14 -> 0.092453447
B15: =1+B14 -> 45971 | C15: =Master!B17 -> 0 | D15: =Master!F17 -> 0 | E15: =Master!J17 -> 0 | F15: =Master!U17+Master!Z17+Master!AE17 -> 0 | G15: =Master!AG17 -> 661 | H15: =Master!AH17 -> 119.291 | I15: =Master!AI17 -> 130.5 | J15: =Master!AK17 -> 33.8 | K15: =Master!AL17 -> 65.9 | L15: =Master!AN17 -> 136.3 | M15: =Master!AP17 -> 99.2 | N15: =Master!AJ17 -> 13.6 | O15: =Master!AM17 -> 9.6 | P15: =Master!AO17 -> 0 | Q15: =Master!AQ17 -> 9.3 | R15: =SUM(H15:Q15) -> 617.491 | S15: =(F15+G15)-R15 -> 43.509 | T15: =S15/(F15+G15) -> 0.065822995 | U15: =(F15+G15)-R15+U14 -> 301.578 | V15: =+U15/(F15+(SUM($G$6:G15))) -> 0.047365792 | W15: PM 14 1440menit | X15: =Master!BM17 -> 551 | Y15: =Master!BD17 -> 535.5 | Z15: =Master!BF17 -> 102 | AA15: =Master!BG17 -> 157.8 | AB15: =Master!BH17 -> 141.9 | AC15: =Master!BI17 -> 114 | AE15: =SUM(Z15:AD15) -> 515.7 | AF15: =ABS(X15-AE15) -> 35.3 | AG15: =ABS(Y15-AE15) -> 19.8 | AH15: =AF15/X15 -> 0.064065336 | AI15: =AG15/Y15 -> 0.03697479
B16: =1+B15 -> 45972 | C16: =Master!B18 -> 0 | D16: =Master!F18 -> 0 | E16: =Master!J18 -> 0 | F16: =Master!U18+Master!Z18+Master!AE18 -> 0 | G16: =Master!AG18 -> 664 | H16: =Master!AH18 -> 122.351 | I16: =Master!AI18 -> 135.02 | J16: =Master!AK18 -> 34 | K16: =Master!AL18 -> 69.9 | L16: =Master!AN18 -> 128.6 | M16: =Master!AP18 -> 101.1 | N16: =Master!AJ18 -> 14.4 | O16: =Master!AM18 -> 9.8 | P16: =Master!AO18 -> 0 | Q16: =Master!AQ18 -> 9.1 | R16: =SUM(H16:Q16) -> 624.271 | S16: =(F16+G16)-R16 -> 39.729 | T16: =S16/(F16+G16) -> 0.059832831 | U16: =(F16+G16)-R16+U15 -> 341.307 | V16: =+U16/(F16+(SUM($G$6:G16))) -> 0.048543166 | W16: PM 14 1440menit | X16: =Master!BM18 -> 458 | Y16: =Master!BD18 -> 443.8 | Z16: =Master!BF18 -> 4.6 | AA16: =Master!BG18 -> 155.1 | AB16: =Master!BH18 -> 134.2 | AC16: =Master!BI18 -> 116.8 | AE16: =SUM(Z16:AD16) -> 410.7 | AF16: =ABS(X16-AE16) -> 47.3 | AG16: =ABS(Y16-AE16) -> 33.1 | AH16: =AF16/X16 -> 0.10327511 | AI16: =AG16/Y16 -> 0.074583146
B17: =1+B16 -> 45973 | C17: =Master!B19 -> 0 | D17: =Master!F19 -> 0 | E17: =Master!J19 -> 0 | F17: =Master!U19+Master!Z19+Master!AE19 -> 0 | G17: =Master!AG19 -> 682 | H17: =Master!AH19 -> 122.351 | I17: =Master!AI19 -> 137.704 | J17: =Master!AK19 -> 24.5 | K17: =Master!AL19 -> 71.6 | L17: =Master!AN19 -> 132.5 | M17: =Master!AP19 -> 102.1 | N17: =Master!AJ19 -> 13.6 | O17: =Master!AM19 -> 8.6 | P17: =Master!AO19 -> 0 | Q17: =Master!AQ19 -> 9.4 | R17: =SUM(H17:Q17) -> 622.355 | S17: =(F17+G17)-R17 -> 59.645 | T17: =S17/(F17+G17) -> 0.087456012 | U17: =(F17+G17)-R17+U16 -> 400.952 | V17: =+U17/(F17+(SUM($G$6:G17))) -> 0.051983923 | W17: PM 14 1440menit | X17: =Master!BM19 -> 455 | Y17: =Master!BD19 -> 466.4 | Z17: =Master!BF19 -> 29.1 | AA17: =Master!BG19 -> 148.2 | AB17: =Master!BH19 -> 133.8 | AC17: =Master!BI19 -> 116.3 | AE17: =SUM(Z17:AD17) -> 427.4 | AF17: =ABS(X17-AE17) -> 27.6 | AG17: =ABS(Y17-AE17) -> 39 | AH17: =AF17/X17 -> 0.060659341 | AI17: =AG17/Y17 -> 0.083619211
B18: =1+B17 -> 45974 | C18: =Master!B20 -> 0 | D18: =Master!F20 -> 0 | E18: =Master!J20 -> 0 | F18: =Master!U20+Master!Z20+Master!AE20 -> 0 | G18: =Master!AG20 -> 609 | H18: =Master!AH20 -> 95.804 | I18: =Master!AI20 -> 140.548 | J18: =Master!AK20 -> 13.5 | K18: =Master!AL20 -> 61.5 | L18: =Master!AN20 -> 131.9 | M18: =Master!AP20 -> 72 | N18: =Master!AJ20 -> 14.4 | O18: =Master!AM20 -> 8.1 | P18: =Master!AO20 -> 0 | Q18: =Master!AQ20 -> 7.2 | R18: =SUM(H18:Q18) -> 544.952 | S18: =(F18+G18)-R18 -> 64.048 | T18: =S18/(F18+G18) -> 0.10516913 | U18: =(F18+G18)-R18+U17 -> 465 | V18: =+U18/(F18+(SUM($G$6:G18))) -> 0.055875991 | W18: PM 14 1440menit, PM 17 460menit | X18: =Master!BM20 -> 454 | Y18: =Master!BD20 -> 465.8 | Z18: =Master!BF20 -> 0 | AA18: =Master!BG20 -> 152.5 | AB18: =Master!BH20 -> 145.4 | AC18: =Master!BI20 -> 119.3 | AE18: =SUM(Z18:AD18) -> 417.2 | AF18: =ABS(X18-AE18) -> 36.8 | AG18: =ABS(Y18-AE18) -> 48.6 | AH18: =AF18/X18 -> 0.081057269 | AI18: =AG18/Y18 -> 0.10433663
... B20: =1+B19 -> 45976 | C20: =Master!B22 -> 0 | D20: =Master!F22 -> 0 | E20: =Master!J22 -> 0 | F20: =Master!U22+Master!Z22+Master!AE22 -> 0 | G20: =Master!AG22 -> 664 | H20: =Master!AH22 -> 120.894 | I20: =Master!AI22 -> 126.219 | J20: =Master!AK22 -> 19 | K20: =Master!AL22 -> 70.8 | L20: =Master!AN22 -> 126.9 | M20: =Master!AP22 -> 101.8 | N20: =Master!AJ22 -> 17.6 | O20: =Master!AM22 -> 10.8 | P20: =Master!AO22 -> 0 | Q20: =Master!AQ22 -> 10.8 | R20: =SUM(H20:Q20) -> 604.813 | S20: =(F20+G20)-R20 -> 59.187 | T20: =S20/(F20+G20) -> 0.089137048 | U20: =(F20+G20)-R20+U19 -> 577.051 | V20: =+U20/(F20+(SUM($G$6:G20))) -> 0.059835234 | W20: PM 14 1440menit | X20: =Master!BM22 -> 607 | Y20: =Master!BD22 -> 590.3 | Z20: =Master!BF22 -> 128.4 | AA20: =Master!BG22 -> 150.1 | AB20: =Master!BH22 -> 152.5 | AC20: =Master!BI22 -> 126.3 | AE20: =SUM(Z20:AD20) -> 557.3 | AF20: =ABS(X20-AE20) -> 49.7 | AG20: =ABS(Y20-AE20) -> 33 | AH20: =AF20/X20 -> 0.081878089 | AI20: =AG20/Y20 -> 0.055903778
B21: =1+B20 -> 45977 | C21: =Master!B23 -> 0 | D21: =Master!F23 -> 0 | E21: =Master!J23 -> 0 | F21: =Master!U23+Master!Z23+Master!AE23 -> 0 | G21: =Master!AG23 -> 696 | H21: =Master!AH23 -> 124.684 | I21: =Master!AI23 -> 135.373 | J21: =Master!AK23 -> 54.8 | K21: =Master!AL23 -> 71.5 | L21: =Master!AN23 -> 123.8 | M21: =Master!AP23 -> 82.4 | N21: =Master!AJ23 -> 16.1 | O21: =Master!AM23 -> 12 | P21: =Master!AO23 -> 0 | Q21: =Master!AQ23 -> 9.6 | R21: =SUM(H21:Q21) -> 630.257 | S21: =(F21+G21)-R21 -> 65.743 | T21: =S21/(F21+G21) -> 0.094458333 | U21: =(F21+G21)-R21+U20 -> 642.794 | V21: =+U21/(F21+(SUM($G$6:G21))) -> 0.062165764 | X21: =Master!BM23 -> 613 | Y21: =Master!BD23 -> 624.1 | Z21: =Master!BF23 -> 136.5 | AA21: =Master!BG23 -> 134.4 | AB21: =Master!BH23 -> 169.4 | AC21: =Master!BI23 -> 128.8 | AE21: =SUM(Z21:AD21) -> 569.1 | AF21: =ABS(X21-AE21) -> 43.9 | AG21: =ABS(Y21-AE21) -> 55 | AH21: =AF21/X21 -> 0.071615008 | AI21: =AG21/Y21 -> 0.088126903
B22: =1+B21 -> 45978 | C22: =Master!B24 -> 0 | D22: =Master!F24 -> 0 | E22: =Master!J24 -> 0 | F22: =Master!U24+Master!Z24+Master!AE24 -> 0 | G22: =Master!AG24 -> 714 | H22: =Master!AH24 -> 111.85 | I22: =Master!AI24 -> 134.843 | J22: =Master!AK24 -> 61.1 | K22: =Master!AL24 -> 70.4 | L22: =Master!AN24 -> 131.7 | M22: =Master!AP24 -> 101.1 | N22: =Master!AJ24 -> 14.8 | O22: =Master!AM24 -> 11.6 | P22: =Master!AO24 -> 0 | Q22: =Master!AQ24 -> 11.2 | R22: =SUM(H22:Q22) -> 648.593 | S22: =(F22+G22)-R22 -> 65.407 | T22: =S22/(F22+G22) -> 0.091606443 | U22: =(F22+G22)-R22+U21 -> 708.201 | V22: =+U22/(F22+(SUM($G$6:G22))) -> 0.064067396 | X22: =Master!BM24 -> 579 | Y22: =Master!BD24 -> 587 | Z22: =Master!BF24 -> 132.9 | AA22: =Master!BG24 -> 152.7 | AB22: =Master!BH24 -> 131.6 | AC22: =Master!BI24 -> 115 | AE22: =SUM(Z22:AD22) -> 532.2 | AF22: =ABS(X22-AE22) -> 46.8 | AG22: =ABS(Y22-AE22) -> 54.8 | AH22: =AF22/X22 -> 0.080829016 | AI22: =AG22/Y22 -> 0.093356048
B23: =1+B22 -> 45979 | C23: =Master!B25 -> 0 | D23: =Master!F25 -> 0 | E23: =Master!J25 -> 0 | F23: =Master!U25+Master!Z25+Master!AE25 -> 0 | G23: =Master!AG25 -> 717 | H23: =Master!AH25 -> 123.029 | I23: =Master!AI25 -> 137.159 | J23: =Master!AK25 -> 55.8 | K23: =Master!AL25 -> 65.6 | L23: =Master!AN25 -> 132 | M23: =Master!AP25 -> 99.3 | N23: =Master!AJ25 -> 16 | O23: =Master!AM25 -> 9 | P23: =Master!AO25 -> 0 | Q23: =Master!AQ25 -> 10.1 | R23: =SUM(H23:Q23) -> 647.988 | S23: =(F23+G23)-R23 -> 69.012 | T23: =S23/(F23+G23) -> 0.096251046 | U23: =(F23+G23)-R23+U22 -> 777.213 | V23: =+U23/(F23+(SUM($G$6:G23))) -> 0.06602778 | X23: =Master!BM25 -> 563 | Y23: =Master!BD25 -> 576.2 | Z23: =Master!BF25 -> 142.3 | AA23: =Master!BG25 -> 148.7 | AB23: =Master!BH25 -> 114.1 | AC23: =Master!BI25 -> 118 | AE23: =SUM(Z23:AD23) -> 523.1 | AF23: =ABS(X23-AE23) -> 39.9 | AG23: =ABS(Y23-AE23) -> 53.1 | AH23: =AF23/X23 -> 0.070870337 | AI23: =AG23/Y23 -> 0.092155502
B24: =1+B23 -> 45980 | C24: =Master!B26 -> 0 | D24: =Master!F26 -> 0 | E24: =Master!J26 -> 0 | F24: =Master!U26+Master!Z26+Master!AE26 -> 0 | G24: =Master!AG26 -> 690 | H24: =Master!AH26 -> 136.767 | I24: =Master!AI26 -> 136.566 | J24: =Master!AK26 -> 29.1 | K24: =Master!AL26 -> 69.4 | L24: =Master!AN26 -> 130.1 | M24: =Master!AP26 -> 81.9 | N24: =Master!AJ26 -> 16.2 | O24: =Master!AM26 -> 10.4 | P24: =Master!AO26 -> 0 | Q24: =Master!AQ26 -> 8.6 | R24: =SUM(H24:Q24) -> 619.033 | S24: =(F24+G24)-R24 -> 70.967 | T24: =S24/(F24+G24) -> 0.10285072 | U24: =(F24+G24)-R24+U23 -> 848.18 | V24: =+U24/(F24+(SUM($G$6:G24))) -> 0.068066768 | W24: PM 14 653menit | X24: =Master!BM26 -> 574 | Y24: =Master!BD26 -> 590.7 | Z24: =Master!BF26 -> 129 | AA24: =Master!BG26 -> 150.5 | AB24: =Master!BH26 -> 130 | AC24: =Master!BI26 -> 126.7 | AE24: =SUM(Z24:AD24) -> 536.2 | AF24: =ABS(X24-AE24) -> 37.8 | AG24: =ABS(Y24-AE24) -> 54.5 | AH24: =AF24/X24 -> 0.065853659 | AI24: =AG24/Y24 -> 0.092263416
B25: =1+B24 -> 45981 | C25: =Master!B27 -> 0 | D25: =Master!F27 -> 0 | E25: =Master!J27 -> 0 | F25: =Master!U27+Master!Z27+Master!AE27 -> 0 | G25: =Master!AG27 -> 705 | H25: =Master!AH27 -> 134.458 | I25: =Master!AI27 -> 134.851 | J25: =Master!AK27 -> 33.4 | K25: =Master!AL27 -> 69.7 | L25: =Master!AN27 -> 128.8 | M25: =Master!AP27 -> 99.8 | N25: =Master!AJ27 -> 18 | O25: =Master!AM27 -> 10 | P25: =Master!AO27 -> 0 | Q25: =Master!AQ27 -> 9.4 | R25: =SUM(H25:Q25) -> 638.409 | S25: =(F25+G25)-R25 -> 66.591 | T25: =S25/(F25+G25) -> 0.094455319 | U25: =(F25+G25)-R25+U24 -> 914.771 | V25: =+U25/(F25+(SUM($G$6:G25))) -> 0.069479796 | W25: PM 14 723menit | X25: =Master!BM27 -> 600 | Y25: =Master!BD27 -> 603.7 | Z25: =Master!BF27 -> 137.4 | AA25: =Master!BG27 -> 149.9 | AB25: =Master!BH27 -> 135.5 | AC25: =Master!BI27 -> 131 | AE25: =SUM(Z25:AD25) -> 553.8 | AF25: =ABS(X25-AE25) -> 46.2 | AG25: =ABS(Y25-AE25) -> 49.9 | AH25: =AF25/X25 -> 0.077 | AI25: =AG25/Y25 -> 0.082656949
B26: =1+B25 -> 45982 | C26: =Master!B28 -> 0 | D26: =Master!F28 -> 0 | E26: =Master!J28 -> 0 | F26: =Master!U28+Master!Z28+Master!AE28 -> 0 | G26: =Master!AG28 -> 735 | H26: =Master!AH28 -> 132.782 | I26: =Master!AI28 -> 134.2 | J26: =Master!AK28 -> 55.5 | K26: =Master!AL28 -> 70.3 | L26: =Master!AN28 -> 128 | M26: =Master!AP28 -> 100.4 | N26: =Master!AJ28 -> 17.6 | O26: =Master!AM28 -> 9.8 | P26: =Master!AO28 -> 0 | Q26: =Master!AQ28 -> 9.8 | R26: =SUM(H26:Q26) -> 658.382 | S26: =(F26+G26)-R26 -> 76.618 | T26: =S26/(F26+G26) -> 0.10424218 | U26: =(F26+G26)-R26+U25 -> 991.389 | V26: =+U26/(F26+(SUM($G$6:G26))) -> 0.071317819 | W26: Steam PM 16 Error | X26: =Master!BM28 -> 533 | Y26: =Master!BD28 -> 543 | Z26: =Master!BF28 -> 88 | AA26: =Master!BG28 -> 150.2 | AB26: =Master!BH28 -> 130.3 | AC26: =Master!BI28 -> 129.2 | AE26: =SUM(Z26:AD26) -> 497.7 | AF26: =ABS(X26-AE26) -> 35.3 | AG26: =ABS(Y26-AE26) -> 45.3 | AH26: =AF26/X26 -> 0.066228893 | AI26: =AG26/Y26 -> 0.083425414
B27: =1+B26 -> 45983 | C27: =Master!B29 -> 0 | D27: =Master!F29 -> 0 | E27: =Master!J29 -> 0 | F27: =Master!U29+Master!Z29+Master!AE29 -> 0 | G27: =Master!AG29 -> 722 | H27: =Master!AH29 -> 123.971 | I27: =Master!AI29 -> 134.357 | J27: =Master!AK29 -> 52.9 | K27: =Master!AL29 -> 70.2 | L27: =Master!AN29 -> 128 | M27: =Master!AP29 -> 99.5 | N27: =Master!AJ29 -> 17 | O27: =Master!AM29 -> 9.7 | P27: =Master!AO29 -> 0 | Q27: =Master!AQ29 -> 10.1 | R27: =SUM(H27:Q27) -> 645.728 | S27: =(F27+G27)-R27 -> 76.272 | T27: =S27/(F27+G27) -> 0.10563989 | U27: =(F27+G27)-R27+U26 -> 1067.661 | V27: =+U27/(F27+(SUM($G$6:G27))) -> 0.073012446 | W27: Steam PM 16 Error | X27: =Master!BM29 -> 497 | Y27: =Master!BD29 -> 501.6 | Z27: =Master!BF29 -> 67.1 | AA27: =Master!BG29 -> 139.6 | AB27: =Master!BH29 -> 129.9 | AC27: =Master!BI29 -> 121.9 | AE27: =SUM(Z27:AD27) -> 458.5 | AF27: =ABS(X27-AE27) -> 38.5 | AG27: =ABS(Y27-AE27) -> 43.1 | AH27: =AF27/X27 -> 0.077464789 | AI27: =AG27/Y27 -> 0.08592504
B28: =1+B27 -> 45984 | C28: =Master!B30 -> 0 | D28: =Master!F30 -> 0 | E28: =Master!J30 -> 0 | F28: =Master!U30+Master!Z30+Master!AE30 -> 0 | G28: =Master!AG30 -> 709 | H28: =Master!AH30 -> 131.047 | I28: =Master!AI30 -> 135.596 | J28: =Master!AK30 -> 55.5 | K28: =Master!AL30 -> 69.1 | L28: =Master!AN30 -> 128 | M28: =Master!AP30 -> 86.9 | N28: =Master!AJ30 -> 17.6 | O28: =Master!AM30 -> 10.5 | P28: =Master!AO30 -> 0 | Q28: =Master!AQ30 -> 9.4 | R28: =SUM(H28:Q28) -> 643.643 | S28: =(F28+G28)-R28 -> 65.357 | T28: =S28/(F28+G28) -> 0.092181946 | U28: =(F28+G28)-R28+U27 -> 1133.018 | V28: =+U28/(F28+(SUM($G$6:G28))) -> 0.073898904 | W28: Steam PM 16 Error | X28: =Master!BM30 -> 539 | Y28: =Master!BD30 -> 552.1 | Z28: =Master!BF30 -> 106.7 | AA28: =Master!BG30 -> 146.8 | AB28: =Master!BH30 -> 131.4 | AC28: =Master!BI30 -> 125.7 | AE28: =SUM(Z28:AD28) -> 510.6 | AF28: =ABS(X28-AE28) -> 28.4 | AG28: =ABS(Y28-AE28) -> 41.5 | AH28: =AF28/X28 -> 0.052690167 | AI28: =AG28/Y28 -> 0.075167542
B29: =1+B28 -> 45985 | C29: =Master!B31 -> 0 | D29: =Master!F31 -> 0 | E29: =Master!J31 -> 0 | F29: =Master!U31+Master!Z31+Master!AE31 -> 0 | G29: =Master!AG31 -> 712 | H29: =Master!AH31 -> 128.206 | I29: =Master!AI31 -> 133.478 | J29: =Master!AK31 -> 53.5 | K29: =Master!AL31 -> 67.6 | L29: =Master!AN31 -> 128 | M29: =Master!AP31 -> 100.1 | N29: =Master!AJ31 -> 20.4 | O29: =Master!AM31 -> 10.6 | P29: =Master!AO31 -> 0 | Q29: =Master!AQ31 -> 11 | R29: =SUM(H29:Q29) -> 652.884 | S29: =(F29+G29)-R29 -> 59.116 | T29: =S29/(F29+G29) -> 0.08302809 | U29: =(F29+G29)-R29+U28 -> 1192.134 | V29: =+U29/(F29+(SUM($G$6:G29))) -> 0.074304039 | W29: Steam PM 16 Error | X29: =Master!BM31 -> 563 | Y29: =Master!BD31 -> 569.3 | Z29: =Master!BF31 -> 114.3 | AA29: =Master!BG31 -> 152.7 | AB29: =Master!BH31 -> 135 | AC29: =Master!BI31 -> 122.5 | AE29: =SUM(Z29:AD29) -> 524.5 | AF29: =ABS(X29-AE29) -> 38.5 | AG29: =ABS(Y29-AE29) -> 44.8 | AH29: =AF29/X29 -> 0.068383659 | AI29: =AG29/Y29 -> 0.078693132
B30: =1+B29 -> 45986 | C30: =Master!B32 -> 0 | D30: =Master!F32 -> 0 | E30: =Master!J32 -> 0 | F30: =Master!U32+Master!Z32+Master!AE32 -> 0 | G30: =Master!AG32 -> 611 | H30: =Master!AH32 -> 125.011 | I30: =Master!AI32 -> 91.77 | J30: =Master!AK32 -> 54.4 | K30: =Master!AL32 -> 68.9 | L30: =Master!AN32 -> 86 | M30: =Master!AP32 -> 98.7 | N30: =Master!AJ32 -> 12.8 | O30: =Master!AM32 -> 10.2 | P30: =Master!AO32 -> 0 | Q30: =Master!AQ32 -> 10.7 | R30: =SUM(H30:Q30) -> 558.481 | S30: =(F30+G30)-R30 -> 52.519 | T30: =S30/(F30+G30) -> 0.08595581 | U30: =(F30+G30)-R30+U29 -> 1244.653 | V30: =+U30/(F30+(SUM($G$6:G30))) -> 0.074731492 | W30: Steam PM 16 Error & stop 760menit, PM 12 470menit | X30: =Master!BM32 -> 580 | Y30: =Master!BD32 -> 609 | Z30: =Master!BF32 -> 131.2 | AA30: =Master!BG32 -> 151.7 | AB30: =Master!BH32 -> 133 | AC30: =Master!BI32 -> 122.2 | AE30: =SUM(Z30:AD30) -> 538.1 | AF30: =ABS(X30-AE30) -> 41.9 | AG30: =ABS(Y30-AE30) -> 70.9 | AH30: =AF30/X30 -> 0.072241379 | AI30: =AG30/Y30 -> 0.11642036
B31: =1+B30 -> 45987 | C31: =Master!B33 -> 0 | D31: =Master!F33 -> 0 | E31: =Master!J33 -> 0 | F31: =Master!U33+Master!Z33+Master!AE33 -> 0 | G31: =Master!AG33 -> 670 | H31: =Master!AH33 -> 129.503 | I31: =Master!AI33 -> 130.437 | J31: =Master!AK33 -> 54.8 | K31: =Master!AL33 -> 68.3 | L31: =Master!AN33 -> 100.5 | M31: =Master!AP33 -> 97 | N31: =Master!AJ33 -> 20.4 | O31: =Master!AM33 -> 9.6 | P31: =Master!AO33 -> 0 | Q31: =Master!AQ33 -> 9.5 | R31: =SUM(H31:Q31) -> 620.04 | S31: =(F31+G31)-R31 -> 49.96 | T31: =S31/(F31+G31) -> 0.074567164 | U31: =(F31+G31)-R31+U30 -> 1294.613 | V31: =+U31/(F31+(SUM($G$6:G31))) -> 0.074725137 | X31: =Master!BM33 -> 583 | Y31: =Master!BD33 -> 592 | Z31: =Master!BF33 -> 138.5 | AA31: =Master!BG33 -> 153.3 | AB31: =Master!BH33 -> 127.5 | AC31: =Master!BI33 -> 128.3 | AE31: =SUM(Z31:AD31) -> 547.6 | AF31: =ABS(X31-AE31) -> 35.4 | AG31: =ABS(Y31-AE31) -> 44.4 | AH31: =AF31/X31 -> 0.060720412 | AI31: =AG31/Y31 -> 0.075
B32: =1+B31 -> 45988 | C32: =Master!B34 -> 0 | D32: =Master!F34 -> 0 | E32: =Master!J34 -> 0 | F32: =Master!U34+Master!Z34+Master!AE34 -> 0 | G32: =Master!AG34 -> 684 | H32: =Master!AH34 -> 127.277 | I32: =Master!AI34 -> 117.465 | J32: =Master!AK34 -> 54.1 | K32: =Master!AL34 -> 61.9 | L32: =Master!AN34 -> 120.6 | M32: =Master!AP34 -> 98.3 | N32: =Master!AJ34 -> 20.1 | O32: =Master!AM34 -> 8.4 | P32: =Master!AO34 -> 0 | Q32: =Master!AQ34 -> 9.8 | R32: =SUM(H32:Q32) -> 617.942 | S32: =(F32+G32)-R32 -> 66.058 | T32: =S32/(F32+G32) -> 0.096576023 | U32: =(F32+G32)-R32+U31 -> 1360.671 | V32: =+U32/(F32+(SUM($G$6:G32))) -> 0.075555056 | X32: =Master!BM34 -> 564 | Y32: =Master!BD34 -> 566.4 | Z32: =Master!BF34 -> 123.7 | AA32: =Master!BG34 -> 142.4 | AB32: =Master!BH34 -> 128.6 | AC32: =Master!BI34 -> 119.8 | AE32: =SUM(Z32:AD32) -> 514.5 | AF32: =ABS(X32-AE32) -> 49.5 | AG32: =ABS(Y32-AE32) -> 51.9 | AH32: =AF32/X32 -> 0.087765957 | AI32: =AG32/Y32 -> 0.091631356
B33: =1+B32 -> 45989 | C33: =Master!B35 -> 0 | D33: =Master!F35 -> 0 | E33: =Master!J35 -> 0 | F33: =Master!U35+Master!Z35+Master!AE35 -> 0 | G33: =Master!AG35 -> 685 | H33: =Master!AH35 -> 124.27 | I33: =Master!AI35 -> 115.19 | J33: =Master!AK35 -> 52.8 | K33: =Master!AL35 -> 67.3 | L33: =Master!AN35 -> 124.8 | M33: =Master!AP35 -> 100.6 | N33: =Master!AJ35 -> 20.3 | O33: =Master!AM35 -> 10.1 | P33: =Master!AO35 -> 0 | Q33: =Master!AQ35 -> 10.4 | R33: =SUM(H33:Q33) -> 625.76 | S33: =(F33+G33)-R33 -> 59.24 | T33: =S33/(F33+G33) -> 0.086481752 | U33: =(F33+G33)-R33+U32 -> 1419.911 | V33: =+U33/(F33+(SUM($G$6:G33))) -> 0.07595544 | X33: =Master!BM35 -> 563 | Y33: =Master!BD35 -> 573 | Z33: =Master!BF35 -> 134.8 | AA33: =Master!BG35 -> 141.2 | AB33: =Master!BH35 -> 129.9 | AC33: =Master!BI35 -> 120.2 | AE33: =SUM(Z33:AD33) -> 526.1 | AF33: =ABS(X33-AE33) -> 36.9 | AG33: =ABS(Y33-AE33) -> 46.9 | AH33: =AF33/X33 -> 0.065541741 | AI33: =AG33/Y33 -> 0.081849913
B34: =1+B33 -> 45990 | C34: =Master!B36 -> 0 | D34: =Master!F36 -> 0 | E34: =Master!J36 -> 0 | F34: =Master!U36+Master!Z36+Master!AE36 -> 0 | G34: =Master!AG36 -> 685 | H34: =Master!AH36 -> 123.578 | I34: =Master!AI36 -> 116.161 | J34: =Master!AK36 -> 50.3 | K34: =Master!AL36 -> 66.9 | L34: =Master!AN36 -> 120.6 | M34: =Master!AP36 -> 97.3 | N34: =Master!AJ36 -> 20.4 | O34: =Master!AM36 -> 10.2 | P34: =Master!AO36 -> 0 | Q34: =Master!AQ36 -> 9.6 | R34: =SUM(H34:Q34) -> 615.039 | S34: =(F34+G34)-R34 -> 69.961 | T34: =S34/(F34+G34) -> 0.10213285 | U34: =(F34+G34)-R34+U33 -> 1489.872 | V34: =+U34/(F34+(SUM($G$6:G34))) -> 0.076880747 | X34: =Master!BM36 -> 579 | Y34: =Master!BD36 -> 582 | Z34: =Master!BF36 -> 140.4 | AA34: =Master!BG36 -> 144.1 | AB34: =Master!BH36 -> 129 | AC34: =Master!BI36 -> 121.3 | AE34: =SUM(Z34:AD34) -> 534.8 | AF34: =ABS(X34-AE34) -> 44.2 | AG34: =ABS(Y34-AE34) -> 47.2 | AH34: =AF34/X34 -> 0.076338515 | AI34: =AG34/Y34 -> 0.081099656
B35: =1+B34 -> 45991 | C35: =Master!B37 -> 0 | D35: =Master!F37 -> 0 | E35: =Master!J37 -> 0 | F35: =Master!U37+Master!Z37+Master!AE37 -> 0 | G35: =Master!AG37 -> 684 | H35: =Master!AH37 -> 119.416 | I35: =Master!AI37 -> 113.278 | J35: =Master!AK37 -> 52.1 | K35: =Master!AL37 -> 66.7 | L35: =Master!AN37 -> 124.4 | M35: =Master!AP37 -> 98.4 | N35: =Master!AJ37 -> 19.2 | O35: =Master!AM37 -> 9.8 | P35: =Master!AO37 -> 0 | Q35: =Master!AQ37 -> 10 | R35: =SUM(H35:Q35) -> 613.294 | S35: =(F35+G35)-R35 -> 70.706 | T35: =S35/(F35+G35) -> 0.10337135 | U35: =(F35+G35)-R35+U34 -> 1560.578 | V35: =+U35/(F35+(SUM($G$6:G35))) -> 0.077783881 | X35: =Master!BM37 -> 566 | Y35: =Master!BD37 -> 578 | Z35: =Master!BF37 -> 129.8 | AA35: =Master!BG37 -> 146 | AB35: =Master!BH37 -> 127.1 | AC35: =Master!BI37 -> 125 | AE35: =SUM(Z35:AD35) -> 527.9 | AF35: =ABS(X35-AE35) -> 38.1 | AG35: =ABS(Y35-AE35) -> 50.1 | AH35: =AF35/X35 -> 0.067314488 | AI35: =AG35/Y35 -> 0.086678201
C37: =SUMIF(C6:C34,">0") -> 0 | D37: =SUMIF(D6:D34,">0") -> 0 | E37: =SUMIF(E6:E34,">0") -> 0 | F37: =SUMIF(F6:F34,">0") -> 0 | G37: =SUMIF(G6:G36,">0") -> 20063 | H37: =SUMIF(H6:H36,">0") -> 3798.933 | I37: =SUMIF(I6:I36,">0") -> 3914.689 | J37: =SUMIF(J6:J36,">0") -> 1095.3 | K37: =SUMIF(K6:K36,">0") -> 2015.3 | L37: =SUMIF(L6:L36,">0") -> 3773 | M37: =SUMIF(M6:M36,">0") -> 2844.5 | N37: =SUMIF(N6:N36,">0") -> 478.9 | ... S37: =SUMIF(S6:S36,">0") -> 1560.578 | T37: =AVERAGEIF(T6:T36,">0") -> 0.076921265 | U37: =+U35 -> 1560.578 | V37: =+V35 -> 0.077783881 | X37: =SUM(X6:X36) -> 16245 | Y37: =SUM(Y6:Y36) -> 16433.9 | Z37: =SUM(Z6:Z36) -> 3552.9 | AA37: =SUM(AA6:AA36) -> 4369.4 | AB37: =SUM(AB6:AB36) -> 3545.1 | AC37: =SUM(AC6:AC36) -> 3556.6 | AE37: =SUM(Z37:AD37) -> 15024 | AF37: =SUM(AF6:AF23) -> 750.3 | AG37: =SUM(AG6:AG23) -> 819.4 | AH37: =AVERAGE(AH6:AH26) -> 0.078781579 | AI37: =AVERAGE(AI6:AI26) -> 0.086624918
B38: TOTAL BB | C38: =C37+D37+E37 -> 0
B39: Eff | C39: =C38/F37 -> #DIV/0!
