Workbook

Sheet Resume
A3: Bulan & PM | C3: Jumlah Hari/ Bulan | E3: Satuan | F3: Available Time | K3: Perhitungan Efisiensi PM dr Running Time | Q3: Loss Trim Rewinder dari Marketing | T3: Loss Effisiensi di Process | W3: Loss Effisiensi di EID | Z3: Loss Effisiensi di Mekanik | AC3: Loss Effisiensi di Boiler Sopa/Sun | AF3: Loss Effisiensi di Power & Steam (max 0.5%) | AI3: Schedule Shut Down | AL3: Total Loss Time & Down Time PM | AM3: Others (External & Project) | AP3: Idle Capacity
F4: Total Menit/ Bulan | G4: For Running Production | H4: Loss Capacity dr Faktor Eksternal & Project (Khusus PM16 -> % alokasi masuk ke Project Instalasi Yankee, Pulper, Rewinder) | I4: Idle Capacity (Marketing)-> % alokasi ini masuk ke COGS | J4: PHP (ton) & Eff PM dr available time | K4: Prod. Volume (teori- ton) | L4: PHP (ton) & Eff PM dr running time | M4: Loss Opportunity PHP (ton) | N4: Reject Rewinder & Broke Plant | O4: Loss Speed & Selisih Toleransi BW | P4: DT &LT Mesin | Q4: Avr Potongan Rewinder (cm) | R4: Loss Trim Rewinder | S4: Deckle PM | T4: Loss Time Process | U4: Down Time Process | V4: Total | W4: Loss Time EID | X4: Down Time EID | Y4: Total | Z4: Loss Time Mekanik | AA4: Down Time Mekanik | AB4: Total | AC4: Loss Time Boiler | AD4: Down Time Boiler | AE4: Total | AF4: Down Time PLN | AG4: Down Time Sinergy | AH4: Total | AI4: Down Time Boil Out | AJ4: Jadwal Revisi | AK4: Total | AM4: Over Down Time External Utility dari limit max 0.5% | AN4: Down Time Project & Overhaul Mesin | AO4: Total | AP4: No Order | AQ4: Down Time Cleaning Change Colour | AR4: Down Time Trial | AS4: Down Time Libur Hari Raya | AT4: Total
A5: Nov 25
A6: PM11 | C6: 30 | E6: Menit | F6: =C6*1440 -> 43200 | G6: =F6-H6-I6 -> 43200 | H6: =AO6 -> 0 | I6: =AT6 -> 0 | T6: =+'PM 11'!AF153+'PM 11'!AG153+'PM 11'!AH153+'PM 11'!AI153 -> 1766 | U6: =+'PM 11'!AN153 -> 350 | V6: =SUM(T6:U6) -> 2116 | W6: =+'PM 11'!AK153 -> 86 | X6: =+'PM 11'!AP153 -> 80 | Y6: =SUM(W6:X6) -> 166 | Z6: =+'PM 11'!AJ153 -> 77 | AA6: =+'PM 11'!AO153 -> 602 | AB6: =SUM(Z6:AA6) -> 679 | AC6: =+'PM 11'!AL153 -> 0 | AD6: =+'PM 11'!AQ153 -> 0 | AE6: =SUM(AC6:AD6) -> 0 | AF6: =+'PM 11'!AX153+'PM 11'!AY153 -> 75 | AG6: =+'PM 11'!AV153+'PM 11'!AW153 -> 0 | AH6: =SUM(AF6:AG6) -> 75 | AI6: 0 | AJ6: =+'PM 11'!AS153 -> 199 | AK6: =SUM(AI6:AJ6) -> 199 | AL6: =V6+Y6+AB6+AE6+AH6+AK6 -> 3235 | AM6: 0 | AN6: 0 | AO6: =SUM(AM6:AN6) -> 0 | AP6: 0 | AQ6: 0 | AR6: =+'PM 11'!AU165 -> 0 | AS6: 0 | AT6: =SUM(AP6:AS6) -> 0
E7: % | F7: =F6/F6 -> 1 | G7: =G6/F6 -> 1 | H7: =H6/F6 -> 0 | I7: =I6/F6 -> 0 | T7: =T6/$F$6 -> 0.04087963 | U7: =U6/$F$6 -> 0.0081018519 | V7: =V6/$F$6 -> 0.048981481 | W7: =W6/$F$6 -> 0.0019907407 | X7: =X6/$F$6 -> 0.0018518519 | Y7: =Y6/$F$6 -> 0.0038425926 | Z7: =Z6/$F$6 -> 0.0017824074 | AA7: =AA6/$F$6 -> 0.013935185 | ... AT7: =AT6/$F$6 -> 0
E8: Tonase | F8: =+[1]Efficiency1!$K$153 -> 1870.6123 | G8: =K8*G6/G6 -> 1870.6123 | H8: =K8*H6/G6 -> 0 | I8: =K8*I6/G6 -> 0 | J8: =+'PM 11'!W153 -> 1595.056 | K8: =+'PM 11'!K153 -> 1870.6123 | L8: =J8 -> 1595.056 | M8: =K8-L8 -> 275.55634 | N8: =+'PM 11'!Z153+'PM 11'!AA153 -> 34.652881 | O8: =+'PM 11'!AC153+'PM 11'!AB153 -> 95.831666 | P8: =M8-N8-O8 -> 145.07179
E9: % | F9: =F8/F8 -> 1 | G9: =G8/F8 -> 1 | H9: =H8/F8 -> 0 | I9: =I8/F8 -> 0 | J9: =J8/F8 -> 0.8526919 | K9: =K8/K8 -> 1 | L9: =L8/K8 -> 0.8526919 | M9: =M8/K8 -> 0.1473081 | N9: =N8/K8 -> 0.018524887 | O9: =O8/K8 -> 0.051230105 | P9: =P8/K8 -> 0.077553104
E10: Cm | Q10: =+'PM 11'!O153 -> 267.21724 | R10: =S10-Q10 -> 9.7827592 | S10: 277
E11: % | Q11: =Q10/S10 -> 0.96468318 | R11: =R10/S10 -> 0.03531682 | S11: =S10/S10 -> 1
A13: PM12 | C13: =+C6 -> 30 | E13: Menit | F13: =C13*1440 -> 43200 | G13: =F13-H13-I13 -> 43200 | H13: =AO13 -> 0 | I13: =+AT13 -> 0 | T13: =+'PM 12'!AF142+'PM 12'!AG142+'PM 12'!AH142+'PM 12'!AI142 -> 1273 | U13: =+'PM 12'!AN142 -> 240 | V13: =SUM(T13:U13) -> 1513 | W13: =+'PM 12'!AK142 -> 0 | X13: =+'PM 12'!AP142 -> 25 | Y13: =SUM(W13:X13) -> 25 | Z13: =+'PM 12'!AJ142 -> 0 | AA13: =+'PM 12'!AO142 -> 230 | AB13: =SUM(Z13:AA13) -> 230 | AC13: =+'PM 12'!AL142 -> 0 | AD13: =+'PM 12'!AQ142 -> 0 | AE13: =SUM(AC13:AD13) -> 0 | AF13: =+'PM 12'!AX142+'PM 12'!AY142 -> 30 | AG13: =+'PM 12'!AV142+'PM 12'!AW142 -> 0 | AH13: =SUM(AF13:AG13) -> 30 | AI13: 0 | AJ13: =+'PM 12'!AS142 -> 0 | AK13: =SUM(AI13:AJ13) -> 0 | AL13: =V13+Y13+AB13+AE13+AH13+AK13 -> 1798 | AM13: 0 | AN13: 0 | AO13: =SUM(AM13:AN13) -> 0 | AP13: 0 | AQ13: 0 | AR13: =+'PM 12'!AZ142 -> 0 | AS13: 0 | AT13: =SUM(AP13:AS13) -> 0
D14: 0 | E14: % | F14: =F13/F13 -> 1 | G14: =G13/F13 -> 1 | H14: =H13/F13 -> 0 | I14: =I13/F13 -> 0 | T14: =T13/$F$6 -> 0.029467593 | U14: =U13/$F$6 -> 0.0055555556 | V14: =V13/$F$6 -> 0.035023148 | W14: =W13/$F$6 -> 0 | X14: =X13/$F$6 -> 0.0005787037 | Y14: =Y13/$F$6 -> 0.0005787037 | Z14: =Z13/$F$6 -> 0 | AA14: =AA13/$F$6 -> 0.0053240741 | ... AT14: =AT13/$F$6 -> 0
E15: Tonase | F15: =+[2]Efficiency1!$K$142 -> 1910.4905 | G15: =K15*G13/G13 -> 1910.4905 | H15: =K15*H13/G13 -> 0 | I15: =K15*I13/G13 -> 0 | J15: =+'PM 12'!W142 -> 1727.194 | K15: =+'PM 12'!K142 -> 1910.4905 | L15: =J15 -> 1727.194 | M15: =K15-L15 -> 183.2965 | N15: =+'PM 12'!Z142+'PM 12'!AA142 -> 61.690348 | O15: =+'PM 12'!AB142+'PM 12'!AC142 -> 41.430057 | P15: =M15-N15-O15 -> 80.176091
E16: % | F16: =F15/F15 -> 1 | G16: =G15/F15 -> 1 | H16: =H15/F15 -> 0 | I16: =I15/F15 -> 0 | J16: =J15/F15 -> 0.90405789 | K16: =K15/K15 -> 1 | L16: =L15/K15 -> 0.90405789 | M16: =M15/K15 -> 0.095942113 | N16: =N15/K15 -> 0.032290319 | O16: =O15/K15 -> 0.02168556 | P16: =P15/K15 -> 0.041966234
E17: Cm | Q17: =+'PM 12'!O142 -> 324.44656 | R17: =S17-Q17 -> 11.553435 | S17: 336
E18: % | Q18: =Q17/S17 -> 0.96561478 | R18: =R17/S17 -> 0.034385223 | S18: =S17/S17 -> 1
A20: PM14 | C20: =+C13 -> 30 | E20: Menit | F20: =C20*1680 -> 50400 | G20: =F20-H20-I20 -> 27204 | H20: =AO20 -> 23196 | I20: =+AT20 -> 0 | T20: =+'PM 14'!AF168+'PM 14'!AG168+'PM 14'!AH168+'PM 14'!AI168 -> 901 | U20: =+'PM 14'!AN168 -> 107 | V20: =SUM(T20:U20) -> 1008 | W20: =+'PM 14'!AK168 -> 90 | X20: =+'PM 14'!AP168 -> 85 | Y20: =SUM(W20:X20) -> 175 | Z20: =+'PM 14'!AJ168 -> 0 | AA20: =+'PM 14'!AO168 -> 0 | AB20: =SUM(Z20:AA20) -> 0 | AC20: =+'PM 14'!AL168 -> 0 | AD20: =+'PM 14'!AQ168 -> 0 | AE20: =SUM(AC20:AD20) -> 0 | AF20: =+'PM 14'!AY168+'PM 14'!AX168 -> 0 | AG20: =+'PM 14'!AV168+'PM 14'!AW168 -> 0 | AH20: =SUM(AF20:AG20) -> 0 | AI20: 0 | AJ20: =+'PM 14'!AS168 -> 0 | AK20: =SUM(AI20:AJ20) -> 0 | AL20: =V20+Y20+AB20+AE20+AH20+AK20 -> 1183 | AM20: =+'PM 14'!AY143-Resume!AH20 -> 0 | AN20: =+'PM 14'!AZ170 -> 23196 | AO20: =SUM(AM20:AN20) -> 23196 | AP20: =+'PM 14'!AU169 -> 0 | AQ20: 0 | AR20: 0 | AS20: 0 | AT20: =SUM(AP20:AS20) -> 0
E21: % | F21: =F20/F20 -> 1 | G21: =G20/F20 -> 0.5397619 | H21: =H20/F20 -> 0.4602381 | I21: =I20/F20 -> 0 | T21: =T20/$F$6 -> 0.020856481 | U21: =U20/$F$6 -> 0.0024768519 | V21: =V20/$F$6 -> 0.023333333 | W21: =W20/$F$6 -> 0.0020833333 | X21: =X20/$F$6 -> 0.0019675926 | Y21: =Y20/$F$6 -> 0.0040509259 | Z21: =Z20/$F$6 -> 0 | AA21: =AA20/$F$6 -> 0 | ... AT21: =AT20/$F$6 -> 0
E22: Tonase | F22: =+[3]Efficiency1!$K$168 -> 1333.8946 | G22: =K22*G20/G20 -> 635.91607 | H22: =K22*H20/G20 -> 542.22574 | I22: =K22*I20/G20 -> 0 | J22: =+'PM 14'!W168 -> 500.227 | K22: =+'PM 14'!K168 -> 635.91607 | L22: =J22 -> 500.227 | M22: =K22-L22 -> 135.68907 | N22: =+'PM 14'!Y168+'PM 14'!Z168+'PM 14'!AA168 -> 42.527351 | O22: =+'PM 14'!AB168+'PM 14'!AC168 -> 55.515004 | P22: =M22-N22-O22 -> 37.646716
E23: % | F23: =F22/F22 -> 1 | G23: =G22/F22 -> 0.47673639 | H23: =H22/F22 -> 0.40649821 | I23: =I22/F22 -> 0 | J23: =J22/F22 -> 0.3750124 | K23: =K22/K22 -> 1 | L23: =L22/K22 -> 0.78662425 | M23: =M22/K22 -> 0.21337575 | N23: =N22/K22 -> 0.066875729 | O23: =O22/K22 -> 0.087299262 | P23: =P22/K22 -> 0.059200762
E24: Cm | Q24: =+'PM 14'!O168 -> 260.14017 | R24: =+S24-Q24 -> 13.859829 | S24: 274
E25: % | Q25: =Q24/S24 -> 0.94941668 | R25: =R24/S24 -> 0.050583318 | S25: =S24/S24 -> 1
A27: PM15 | C27: =+C20 -> 30 | E27: Menit | F27: =C27*1440 -> 43200 | G27: =F27-H27-I27 -> 43200 | H27: =AO27 -> 0 | I27: =+AT27 -> 0 | T27: =+'PM 15'!AF164+'PM 15'!AG164+'PM 15'!AH164+'PM 15'!AI164 -> 1398 | U27: =+'PM 15'!AN164 -> 597 | V27: =SUM(T27:U27) -> 1995 | W27: =+'PM 15'!AK164 -> 33 | X27: =+'PM 15'!AP164 -> 170 | Y27: =SUM(W27:X27) -> 203 | Z27: =+'PM 15'!AJ164 -> 0 | AA27: =+'PM 15'!AO164 -> 0 | AB27: =SUM(Z27:AA27) -> 0 | AC27: =+'PM 15'!AL164 -> 0 | AD27: =+'PM 15'!AQ164 -> 0 | AE27: =SUM(AC27:AD27) -> 0 | AF27: =+'PM 15'!AV164+'PM 15'!AW164 -> 0 | AG27: =+'PM 15'!AX164+'PM 15'!AY164 -> 0 | AH27: =SUM(AF27:AG27) -> 0 | AI27: 0 | AJ27: =+'PM 15'!AS164 -> 609 | AK27: =SUM(AI27:AJ27) -> 609 | AL27: =V27+Y27+AB27+AE27+AH27+AK27 -> 2807 | AM27: =+'PM 15'!AW196-Resume!AH27 -> 0 | AN27: =+'PM 15'!AZ158 -> 0 | AO27: =SUM(AM27:AN27) -> 0 | AP27: 0 | AQ27: =+'PM 15'!AU165 -> 0 | AR27: 0 | AS27: 0 | AT27: =SUM(AP27:AS27) -> 0
E28: % | F28: =F27/F27 -> 1 | G28: =G27/F27 -> 1 | H28: =H27/F27 -> 0 | I28: =I27/F27 -> 0 | T28: =T27/$F$6 -> 0.032361111 | U28: =U27/$F$6 -> 0.013819444 | V28: =V27/$F$6 -> 0.046180556 | W28: =W27/$F$6 -> 0.00076388889 | X28: =X27/$F$6 -> 0.0039351852 | Y28: =Y27/$F$6 -> 0.0046990741 | Z28: =Z27/$F$6 -> 0 | AA28: =AA27/$F$6 -> 0 | ... AT28: =AT27/$F$6 -> 0
E29: Tonase | F29: =+[4]Efficiency1!$K$164 -> 1637.388 | G29: =K29*G27/G27 -> 1637.388 | H29: =K29*H27/G27 -> 0 | I29: =K29*I27/G27 -> 0 | J29: =+'PM 15'!W164 -> 1468.263 | K29: =+'PM 15'!K164 -> 1637.388 | L29: =J29 -> 1468.263 | M29: =K29-L29 -> 169.12501 | N29: =+'PM 15'!Y164+'PM 15'!Z164+'PM 15'!AA164 -> 15.722141 | O29: =+'PM 15'!AB164+'PM 15'!AC164 -> 47.863354 | P29: =M29-N29-O29 -> 105.53951
E30: % | F30: =F29/F29 -> 1 | G30: =G29/F29 -> 1 | H30: =H29/F29 -> 0 | I30: =I29/F29 -> 0 | J30: =J29/F29 -> 0.89671049 | K30: =K29/K29 -> 1 | L30: =L29/K29 -> 0.89671049 | M30: =M29/K29 -> 0.10328951 | N30: =N29/K29 -> 0.0096019643 | O30: =O29/K29 -> 0.029231528 | P30: =P29/K29 -> 0.064456019
E31: Cm | Q31: =+'PM 15'!O164 -> 268.89839 | R31: =S31-Q31 -> 8.1016077 | S31: 277
E32: % | R32: =R31/S31 -> 0.029247681
A34: PM16 | C34: =+C27 -> 30 | E34: Menit | F34: =C34*1440 -> 43200 | G34: =F34-H34-I34 -> 43200 | H34: =AO34 -> 0 | I34: =+AT34 -> 0 | T34: =+'PM 16'!AF136+'PM 16'!AG136+'PM 16'!AH136+'PM 16'!AI136 -> 1007 | U34: =+'PM 16'!AN136 -> 200 | V34: =SUM(T34:U34) -> 1207 | W34: =+'PM 16'!AK136 -> 0 | X34: =+'PM 16'!AP136 -> 280 | Y34: =SUM(W34:X34) -> 280 | Z34: =+'PM 16'!AJ136 -> 0 | AA34: =+'PM 16'!AO136 -> 460 | AB34: =SUM(Z34:AA34) -> 460 | AC34: =+'PM 16'!AL136 -> 0 | AD34: =+'PM 16'!AQ136 -> 0 | AE34: =SUM(AC34:AD34) -> 0 | AF34: =+'PM 16'!AX136+'PM 16'!AY136 -> 100 | AG34: =+'PM 16'!AV136+'PM 16'!AW136 -> 0 | AH34: =SUM(AF34:AG34) -> 100 | AI34: 0 | AJ34: =+'PM 16'!AS136 -> 935 | AK34: =SUM(AI34:AJ34) -> 935 | AL34: =V34+Y34+AB34+AE34+AH34+AK34 -> 2982 | AM34: 0 | AN34: =+'PM 16'!AZ136 -> 0 | AO34: =SUM(AM34:AN34) -> 0 | AP34: =+'PM 16'!AT165+'PM 16'!AU165 -> 0 | AQ34: =+'PM 16'!AU136 -> 0 | AR34: 0 | AS34: 0 | AT34: =SUM(AP34:AS34) -> 0
E35: % | F35: =F34/F34 -> 1 | G35: =G34/F34 -> 1 | H35: =H34/F34 -> 0 | I35: =I34/F34 -> 0 | T35: =T34/$F$6 -> 0.023310185 | U35: =U34/$F$6 -> 0.0046296296 | V35: =V34/$F$6 -> 0.027939815 | W35: =W34/$F$6 -> 0 | X35: =X34/$F$6 -> 0.0064814815 | Y35: =Y34/$F$6 -> 0.0064814815 | Z35: =Z34/$F$6 -> 0 | AA35: =AA34/$F$6 -> 0.010648148 | ... AT35: =AT34/$F$6 -> 0
E36: Tonase | F36: =+[5]Efficiency1!$K$136 -> 1565.0104 | G36: =K36*G34/G34 -> 1565.0104 | H36: =K36*H34/G34 -> 0 | I36: =K36*I34/G34 -> 0 | J36: =+'PM 16'!W136 -> 1394.103 | K36: =+'PM 16'!K136 -> 1565.0104 | L36: =J36 -> 1394.103 | M36: =K36-L36 -> 170.90739 | N36: =+'PM 16'!Y136+'PM 16'!Z136+'PM 16'!AA136 -> 46.478491 | O36: =+'PM 16'!AB136+'PM 16'!AC136 -> 19.508411 | P36: =M36-N36-O36 -> 104.92049
E37: % | F37: =F36/F36 -> 1 | G37: =G36/F36 -> 1 | H37: =H36/F36 -> 0 | I37: =I36/F36 -> 0 | J37: =J36/F36 -> 0.89079473 | K37: =K36/K36 -> 1 | L37: =L36/K36 -> 0.89079473 | M37: =M36/K36 -> 0.10920527 | N37: =N36/K36 -> 0.029698519 | O37: =O36/K36 -> 0.012465355 | P37: =P36/K36 -> 0.0670414
E38: Cm | Q38: =+'PM 16'!O136 -> 275.55123 | R38: =S38-Q38 -> 8.4487651 | S38: 284
E39: % | R39: =R38/S38 -> 0.029749173
A41: PM17 | C41: =+C34 -> 30 | E41: Menit | F41: =C41*1440 -> 43200 | G41: =F41-H41-I41 -> 43200 | H41: =AO41 -> 0 | I41: =+AT41 -> 0 | T41: =+'PM 17'!AF142+'PM 17'!AG142+'PM 17'!AH142+'PM 17'!AI142 -> 609 | U41: =+'PM 17'!AN142 -> 1493 | V41: =SUM(T41:U41) -> 2102 | W41: =+'PM 17'!AK142 -> 0 | X41: =+'PM 17'!AP142 -> 637 | Y41: =SUM(W41:X41) -> 637 | Z41: =+'PM 17'!AJ142 -> 7 | AA41: =+'PM 17'!AO142 -> 420 | AB41: =SUM(Z41:AA41) -> 427 | AC41: =+'PM 17'!AL142 -> 0 | AD41: =+'PM 17'!AQ142 -> 0 | AE41: =SUM(AC41:AD41) -> 0 | AF41: =+'PM 17'!AX142+'PM 17'!AY142 -> 0 | AG41: =+'PM 17'!AV142+'PM 17'!AW142 -> 60 | AH41: =SUM(AF41:AG41) -> 60 | AI41: 0 | AJ41: =+'PM 17'!AS142 -> 0 | AK41: =SUM(AI41:AJ41) -> 0 | AL41: =V41+Y41+AB41+AE41+AH41+AK41 -> 3226 | AM41: 0 | AN41: =+'PM 17'!AZ143 -> 0 | AO41: =SUM(AM41:AN41) -> 0 | AP41: =+'PM 17'!AT182+'PM 17'!AU182 -> 0 | AQ41: =+'PM 17'!AU143 -> 0 | AR41: 0 | AS41: 0 | AT41: =SUM(AP41:AS41) -> 0
E42: % | F42: =F41/F41 -> 1 | G42: =G41/F41 -> 1 | H42: =H41/F41 -> 0 | I42: =I41/F41 -> 0 | T42: =T41/$F$6 -> 0.014097222 | U42: =U41/$F$6 -> 0.034560185 | V42: =V41/$F$6 -> 0.048657407 | W42: =W41/$F$6 -> 0 | X42: =X41/$F$6 -> 0.01474537 | Y42: =Y41/$F$6 -> 0.01474537 | Z42: =Z41/$F$6 -> 0.00016203704 | AA42: =AA41/$F$6 -> 0.0097222222 | ... AT42: =AT41/$F$6 -> 0
E43: Tonase | F43: =+[6]Efficiency1!$K$142 -> 1572.0066 | G43: =K43*G41/G41 -> 1572.0066 | H43: =K43*H41/G41 -> 0 | I43: =K43*I41/G41 -> 0 | J43: =+'PM 17'!W142 -> 1387.303 | K43: =+'PM 17'!K142 -> 1572.0066 | L43: =J43 -> 1387.303 | M43: =K43-L43 -> 184.70357 | N43: =+'PM 17'!Y142+'PM 17'!Z142+'PM 17'!AA142 -> 39.024119 | O43: =+'PM 17'!AB142+'PM 17'!AC142 -> 28.103381 | P43: =M43-N43-O43 -> 117.57607
E44: % | F44: =F43/F43 -> 1 | G44: =G43/F43 -> 1 | H44: =H43/F43 -> 0 | I44: =I43/F43 -> 0 | J44: =J43/F43 -> 0.88250458 | K44: =K43/K43 -> 1 | L44: =L43/K43 -> 0.88250458 | M44: =M43/K43 -> 0.11749542 | N44: =N43/K43 -> 0.024824399 | O44: =O43/K43 -> 0.017877394 | P44: =P43/K43 -> 0.074793625
E45: Cm | Q45: =+'PM 17'!O142 -> 256.71231 | R45: =S45-Q45 -> 7.2876881 | S45: 264
E46: % | R46: =R45/S45 -> 0.027604879

Sheet PM 11
A1: PM11 Efficiency Report
A3: Date | B3: Grade | C3: Speed real (ton) with Available Time | D3: Colour | E3: gsm | F3: Ply | G3: Standard | L3: Real Running | O3: Trim Rewinder (cm) | P3: Trim Rewinder x Running Time | Q3: Available Time (mnt) | R3: Down Time (mnt) | S3: Loss Time (mnt) | T3: Real Speed & Real Creepe Ratio with Available Time (ton) | U3: Real Speed & Real Creepe Ratio setelah dipotong DT & LT (ton) | V3: Loss tonase akibat DT + LT dari hitungan Teori with available time (ton) | W3: Accepted (ton) | X3: Real Eff dr Target Eff | Y3: Backlog | Z3: Reject Rewinder (ton) | AA3: Estimasi Reject to Broke Plant (ton) | AB3: Estimasi Faktor BW (ton) | AC3: Loss Opportunity in Speed (ton) | AD3: Downtime/ Losstime | AE3: Reason of Downtime / Losstime | AF3: Loss Time | AM3: Total Losstime | AN3: Unschedule Shut Down (mnt) | AS3: Schedule Shut Down | AT3: Marketing | AV3: EXT FACTOR | AX3: EXT FACTOR | AZ3: MANAGEMENT | BA3: Total Down Time | BB3: Freq. Sheets Break (X) | BC3: Freq. Change Blade (X) | BD3: Steam, & gangguan sinergy (X) | BE3: Freq, Trip PLN (X) | BF3: Cleaning Holes (X)
AF4: Proses | AI4: Change Grade | AJ4: Mekanik | AK4: Electric & Instrument | AL4: Boiler | AN4: Down Time Produksi | AO4: Mekanik | AP4: Electrical & Instrument | AQ4: Boiler | AR4: Total Unschedule Shut Down | AV4: LOSS | AW4: DOWN TIME | AX4: LOSS | AY4: DOWN TIME
G5: Yankee Speed (mpm) | H5: Max % Creeping | I5: Target Eff | J5: Kapasitas PM-Teori (ton) | K5: Teori (ton) with Available Time | L5: Yankee Speed (mpm) | M5: Popereel Speed (mpm) | N5: % Creeping | AF5: sheet break | AG5: change blade | AH5: change spool | AT5: Loss time | AU5: Down Time | AV5: SINERGY | AW5: SINERGY | AX5: PLN | AY5: PLN
A6: =+[1]Report1!A9 -> 45962 | B6: MG | C6: =(M6*E6*O6*Q6)/100000000 -> 59.309193 | D6: High White | E6: 12 | F6: 1 | G6: 1270 | H6: 0 | I6: 0.88 | J6: =E6*G6*(1-H6)*1440/1000000*2.77 -> 60.789312 | K6: =(IF(G6<L6,L6,G6)*(1-IF(H6<N6,H6,N6))*E6*O6*Q6)/100000000 -> 59.517504 | L6: 1290 | M6: =+L6-L6*0.0035 -> 1285.485 | N6: =1-(M6/L6) -> 0.0035 | O6: =+'[1]Trim Rwd'!H4 -> 267 | P6: =O6*(Q6-R6-S6) -> 371931 | Q6: 1440 | R6: 0 | S6: 47 | T6: =E6*M6*O6*Q6/100000000 -> 59.309193 | U6: =E6*M6*O6*(Q6-R6-S6)/100000000 -> 57.373407 | V6: =E6*G6*(1-N6)*O6/100*(R6+S6)/1000000 -> 1.905774 | W6: =+'[1]1'!K34/1000 -> 59.673 | X6: =SUM(W6:W9)/SUM(K6:K9) -> 1.0026126 | Y6: 0 | Z6: =+'[1]1'!D34/1000 -> 0.862 | AA6: =SUM(U6:U9)-SUM(W6:W9)-SUM(Z6:Z9)-SUM(Y6:Y9) -> -3.1615934 | AB6: =(SUM(K6:K9)-SUM(W6:W9)-SUM(Y6:Y9)-SUM(Z6:Z9)-SUM(AC6:AC9)-SUM(V6:V9))-AA6 -> 0.030012188 | AC6: =K6-T6 -> 0.20831126 | AD6: =+AM6+BA6 -> 20 | AE6: - Sheet Breaks (4x) | AF6: 20 | AM6: =SUM(AF6:AL6)+AT6+AV6+AX6 -> 20 | AR6: =SUM(AN6:AQ6) -> 0 | BA6: =+AR6+AS6+AU6+AW6+AY6+AZ6 -> 0 | BB6: 4
AD7: =+AM7+BA7 -> 3 | AE7: - Change Blade (2x) | AG7: 3 | AM7: =SUM(AF7:AL7)+AT7+AV7+AX7 -> 3 | AR7: =SUM(AN7:AQ7) -> 0 | BA7: =+AR7+AS7+AU7+AW7+AY7+AZ7 -> 0 | BC7: 2
AD8: =+AM8+BA8 -> 24 | AE8: - Change Spool (24x) | AH8: 24 | AM8: =SUM(AF8:AL8)+AT8+AV8+AX8 -> 24 | AR8: =SUM(AN8:AQ8) -> 0 | BA8: =+AR8+AS8+AU8+AW8+AY8+AZ8 -> 0
A10: 45963 | B10: MG | C10: =(M10*E10*O10*Q10)/100000000 -> 42.58823 | D10: High White | E10: 14 | F10: 1 | G10: 1270 | H10: 0 | I10: 0.88 | J10: =E10*G10*(1-H10)*1440/1000000*2.77 -> 70.920864 | K10: =(IF(G10<L10,L10,G10)*(1-IF(H10<N10,H10,N10))*E10*O10*Q10)/100000000 -> 42.737812 | L10: 1290 | M10: 1285.485 | N10: =1-(M10/L10) -> 0.0035 | O10: =+'[1]Trim Rwd'!H6 -> 268.91304 | P10: =O10*(Q10-R10-S10) -> 229382.83 | Q10: 880 | R10: 0 | S10: 27 | T10: =E10*M10*O10*Q10/100000000 -> 42.58823 | U10: =E10*M10*O10*(Q10-R10-S10)/100000000 -> 41.281546 | V10: =E10*G10*(1-N10)*O10/100*(R10+S10)/1000000 -> 1.2864257 | W10: =+'[1]2'!K7/1000 -> 51.575 | X10: =SUM(W10:W13)/SUM(K10:K13) -> 0.85910239 | Y10: 0 | Z10: =+'[1]2'!D34/1000 -> 0.967 | AA10: =SUM(U10:U13)-SUM(W10:W13)-SUM(Z10:Z13)-SUM(Y10:Y13) -> 5.6216186 | AB10: =(SUM(K10:K13)-SUM(W10:W13)-SUM(Y10:Y13)-SUM(Z10:Z13)-SUM(AC10:AC13)-SUM(V10:V13))-AA10 -> 0.0046736311 | AC10: =K10-T10 -> 0.14958234 | AD10: =+AM10+BA10 -> 25 | AE10: - Sheet Breaks (5x) | AF10: 25 | AM10: =SUM(AF10:AL10)+AT10+AV10+AX10 -> 25 | AR10: =SUM(AN10:AQ10) -> 0 | BA10: =+AR10+AS10+AU10+AW10+AY10+AZ10 -> 0 | BB10: 5
B11: MG | C11: =(M11*E11*O11*Q11)/100000000 -> 29.923278 | D11: High White | E11: 16.5 | F11: 1 | G11: 1210 | H11: 0 | I11: 0.88 | J11: =E11*G11*(1-H11)*1440/1000000*2.77 -> 79.636392 | K11: =(IF(G11<L11,L11,G11)*(1-IF(H11<N11,H11,N11))*E11*O11*Q11)/100000000 -> 30.298884 | L11: 1200 | M11: 1195 | N11: =1-(M11/L11) -> 0.0041666667 | O11: =+'[1]Trim Rwd'!H8 -> 271 | P11: =O11*(Q11-R11-S11) -> 142275 | Q11: 560 | R11: 0 | S11: 35 | T11: =E11*M11*O11*Q11/100000000 -> 29.923278 | U11: =E11*M11*O11*(Q11-R11-S11)/100000000 -> 28.053073 | V11: =E11*G11*(1-N11)*O11/100*(R11+S11)/1000000 -> 1.8857899 | W11: =+'[1]2'!K8/1000 -> 11.171 | AC11: =K11-T11 -> 0.375606 | AD11: =+AM11+BA11 -> 2 | AE11: - Change Blade (2x) | AG11: 2 | AM11: =SUM(AF11:AL11)+AT11+AV11+AX11 -> 2 | AR11: =SUM(AN11:AQ11) -> 0 | BA11: =+AR11+AS11+AU11+AW11+AY11+AZ11 -> 0 | BC11: 2
AD12: =+AM12+BA12 -> 25 | AE12: - Change Spool (24x) | AH12: 25 | AM12: =SUM(AF12:AL12)+AT12+AV12+AX12 -> 25 | AR12: =SUM(AN12:AQ12) -> 0 | BA12: =+AR12+AS12+AU12+AW12+AY12+AZ12 -> 0
AD13: =+AM13+BA13 -> 10 | AE13: - Change Grade | AI13: 10 | AM13: =SUM(AF13:AL13)+AT13+AV13+AX13 -> 10 | AR13: =SUM(AN13:AQ13) -> 0 | BA13: =+AR13+AS13+AU13+AW13+AY13+AZ13 -> 0
A15: 45964 | B15: MG | C15: =(M15*E15*O15*Q15)/100000000 -> 73.345843 | D15: High White | E15: 16.5 | F15: 1 | G15: 1210 | H15: 0 | I15: 0.88 | J15: =E15*G15*(1-H15)*1440/1000000*2.77 -> 79.636392 | K15: =(IF(G15<L15,L15,G15)*(1-IF(H15<N15,H15,N15))*E15*O15*Q15)/100000000 -> 75.322241 | L15: 1182.3889 | M15: 1178.2505 | N15: =1-(M15/L15) -> 0.0035 | O15: =+'[1]Trim Rwd'!H11 -> 261.99405 | P15: =O15*(Q15-R15-S15) -> 358669.85 | Q15: 1440 | R15: 0 | S15: 71 | T15: =E15*M15*O15*Q15/100000000 -> 73.345843 | U15: =E15*M15*O15*(Q15-R15-S15)/100000000 -> 69.729485 | V15: =E15*G15*(1-N15)*O15/100*(R15+S15)/1000000 -> 3.7008066 | W15: =+'[1]3'!K8/1000 -> 63.193 | X15: =SUM(W15:W18)/SUM(K15:K18) -> 0.87121678 | Y15: 0 | Z15: =+'[1]3'!D34/1000 -> 0.848 | AA15: =SUM(U15:U18)-SUM(W15:W18)-SUM(Z15:Z18)-SUM(Y15:Y18) -> 3.2594853 | AB15: =(SUM(K15:K18)-SUM(W15:W18)-SUM(Y15:Y18)-SUM(Z15:Z18)-SUM(AC15:AC18)-SUM(V15:V18))-AA15 -> -0.084449076 | AC15: =K15-T15 -> 1.9763978 | AD15: =+AM15+BA15 -> 30 | AE15: - Sheet Breaks (6x) | AF15: 30 | AM15: =SUM(AF15:AL15)+AT15+AV15+AX15 -> 30 | AR15: =SUM(AN15:AQ15) -> 0 | BA15: =+AR15+AS15+AU15+AW15+AY15+AZ15 -> 0 | BB15: 6
B16: MG | E16: 14 | W16: =+'[1]3'!K7/1000 -> 2.429 | AD16: =+AM16+BA16 -> 0 | AE16: - Change Blade (0x) | AG16: 0 | AM16: =SUM(AF16:AL16)+AT16+AV16+AX16 -> 0 | AR16: =SUM(AN16:AQ16) -> 0 | BA16: =+AR16+AS16+AU16+AW16+AY16+AZ16 -> 0 | BC16: 0
AD17: =+AM17+BA17 -> 31 | AE17: - Change Spool (25x) | AH17: 31 | AM17: =SUM(AF17:AL17)+AT17+AV17+AX17 -> 31 | AR17: =SUM(AN17:AQ17) -> 0 | BA17: =+AR17+AS17+AU17+AW17+AY17+AZ17 -> 0
AD18: =+AM18+BA18 -> 10 | AE18: - Change Grade | AI18: 10 | AM18: =SUM(AF18:AL18)+AT18+AV18+AX18 -> 10 | AR18: =SUM(AN18:AQ18) -> 0 | BA18: =+AR18+AS18+AU18+AW18+AY18+AZ18 -> 0
A20: 45965 | B20: MG | C20: =(M20*E20*O20*Q20)/100000000 -> 10.70282 | D20: High White | E20: 16.5 | F20: 1 | G20: 1210 | H20: 0 | I20: 0.88 | J20: =E20*G20*(1-H20)*1440/1000000*2.77 -> 79.636392 | K20: =(IF(G20<L20,L20,G20)*(1-IF(H20<N20,H20,N20))*E20*O20*Q20)/100000000 -> 11.20336 | L20: 1160 | M20: =+L20-L20*0.0035 -> 1155.94 | N20: =1-(M20/L20) -> 0.0035 | O20: =+'[1]Trim Rwd'!H16 -> 261 | P20: =O20*(Q20-R20-S20) -> 52200 | Q20: 215 | R20: 0 | S20: 15 | T20: =E20*M20*O20*Q20/100000000 -> 10.70282 | U20: =E20*M20*O20*(Q20-R20-S20)/100000000 -> 9.9561112 | V20: =E20*G20*(1-N20)*O20/100*(R20+S20)/1000000 -> 0.77889405 | W20: =+'[1]4'!K8/1000 -> 19.001 | X20: =SUM(W20:W25)/SUM(K20:K25) -> 0.79021127 | Y20: 0 | Z20: 0 | AA20: =SUM(U20:U25)-SUM(W20:W25)-SUM(Z20:Z25)-SUM(Y20:Y25) -> 8.3693381 | AB20: =(SUM(K20:K25)-SUM(W20:W25)-SUM(Y20:Y25)-SUM(Z20:Z25)-SUM(AC20:AC25)-SUM(V20:V25))-AA20 -> -0.018707188 | AC20: =K20-T20 -> 0.50054019 | AD20: =+AM20+BA20 -> 33 | AE20: - Sheet Breaks (7x) | AF20: 33 | AM20: =SUM(AF20:AL20)+AT20+AV20+AX20 -> 33 | AR20: =SUM(AN20:AQ20) -> 0 | BA20: =+AR20+AS20+AU20+AW20+AY20+AZ20 -> 0 | BB20: 7
B21: MG | C21: =(M21*E21*O21*Q21)/100000000 -> 6.0724219 | D21: High White | E21: 30 | F21: 1 | G21: 690 | H21: 0 | I21: 0.88 | J21: =E21*G21*(1-H21)*1440/1000000*2.77 -> 82.56816 | K21: =(IF(G21<L21,L21,G21)*(1-IF(H21<N21,H21,N21))*E21*O21*Q21)/100000000 -> 6.09375 | L21: 700 | M21: =+L21-L21*0.0035 -> 697.55 | N21: =1-(M21/L21) -> 0.0035 | O21: =+'[1]Trim Rwd'!H17 -> 232.14286 | P21: =O21*(Q21-R21-S21) -> 25535.714 | Q21: 125 | R21: 0 | S21: 15 | T21: =E21*M21*O21*Q21/100000000 -> 6.0724219 | U21: =E21*M21*O21*(Q21-R21-S21)/100000000 -> 5.3437313 | V21: =E21*G21*(1-N21)*O21/100*(R21+S21)/1000000 -> 0.71828076 | W21: =+'[1]4'!K9/1000 -> 4.193 | Z21: =+'[1]4'!D18/1000 -> 0.998 | AC21: =K21-T21 -> 0.021328125 | AD21: =+AM21+BA21 -> 0 | AE21: - Change Blade (0x) | AG21: 0 | AM21: =SUM(AF21:AL21)+AT21+AV21+AX21 -> 0 | AR21: =SUM(AN21:AQ21) -> 0 | BA21: =+AR21+AS21+AU21+AW21+AY21+AZ21 -> 0 | BC21: 0
B22: MG | C22: =(M22*E22*O22*Q22)/100000000 -> 7.4917667 | D22: High White | E22: 17 | F22: 1 | G22: 1210 | H22: 0 | I22: 0.88 | J22: =E22*G22*(1-H22)*1440/1000000*2.77 -> 82.049616 | K22: =(IF(G22<L22,L22,G22)*(1-IF(H22<N22,H22,N22))*E22*O22*Q22)/100000000 -> 7.5807307 | L22: 1200 | M22: =+L22-L22*0.0035 -> 1195.8 | N22: =1-(M22/L22) -> 0.0035 | O22: =+'[1]Trim Rwd'!H19 -> 263.2381 | P22: =O22*(Q22-R22-S22) -> 32904.762 | Q22: 140 | R22: 0 | S22: 15 | T22: =E22*M22*O22*Q22/100000000 -> 7.4917667 | U22: =E22*M22*O22*(Q22-R22-S22)/100000000 -> 6.6890774 | V22: =E22*G22*(1-N22)*O22/100*(R22+S22)/1000000 -> 0.80937837 | W22: =+'[1]4'!K10/1000 -> 18.114 | Z22: =+('[1]4'!D17/1000) -> 0.724 | AC22: =K22-T22 -> 0.088963947 | AD22: =+AM22+BA22 -> 29 | AE22: - Change Spool (25x) | AH22: 29 | AM22: =SUM(AF22:AL22)+AT22+AV22+AX22 -> 29 | AR22: =SUM(AN22:AQ22) -> 0 | BA22: =+AR22+AS22+AU22+AW22+AY22+AZ22 -> 0
B23: MG | C23: =(M23*E23*O23*Q23)/100000000 -> 30.561204 | D23: High White | E23: 18 | F23: 1 | G23: 1150 | H23: 0 | I23: 0.88 | J23: =E23*G23*(1-H23)*1440/1000000*2.77 -> 82.56816 | K23: =(IF(G23<L23,L23,G23)*(1-IF(H23<N23,H23,N23))*E23*O23*Q23)/100000000 -> 30.668544 | L23: 1160 | M23: =+L23-L23*0.0035 -> 1155.94 | N23: =1-(M23/L23) -> 0.0035 | O23: =+'[1]Trim Rwd'!H21 -> 272 | P23: =O23*(Q23-R23-S23) -> 141440 | Q23: 540 | R23: 0 | S23: 20 | T23: =E23*M23*O23*Q23/100000000 -> 30.561204 | U23: =E23*M23*O23*(Q23-R23-S23)/100000000 -> 29.429308 | V23: =E23*G23*(1-N23)*O23/100*(R23+S23)/1000000 -> 1.1221387 | W23: =+'[1]4'!K11/1000 -> 16.696 | Z23: =+('[1]4'!D19+'[1]4'!D25)/1000 -> 0.564 | AC23: =K23-T23 -> 0.1073399 | AD23: =+AM23+BA23 -> 18 | AE23: - Change Grade | AI23: 18 | AM23: =SUM(AF23:AL23)+AT23+AV23+AX23 -> 18 | AR23: =SUM(AN23:AQ23) -> 0 | BA23: =+AR23+AS23+AU23+AW23+AY23+AZ23 -> 0
B24: MG | C24: =(M24*E24*O24*Q24)/100000000 -> 19.868707 | D24: Off White | E24: 14 | F24: 1 | G24: 1270 | H24: 0 | I24: 0.88 | J24: =E24*G24*(1-H24)*1440/1000000*2.77 -> 70.920864 | K24: =(IF(G24<L24,L24,G24)*(1-IF(H24<N24,H24,N24))*E24*O24*Q24)/100000000 -> 19.938492 | L24: 1270 | M24: =+L24-L24*0.0035 -> 1265.555 | N24: =1-(M24/L24) -> 0.0035 | O24: =+'[1]Trim Rwd'!H22 -> 267 | P24: =O24*(Q24-R24-S24) -> 108135 | Q24: 420 | R24: 0 | S24: 15 | T24: =E24*M24*O24*Q24/100000000 -> 19.868707 | U24: =E24*M24*O24*(Q24-R24-S24)/100000000 -> 19.159111 | V24: =E24*G24*(1-N24)*O24/100*(R24+S24)/1000000 -> 0.70959669 | W24: =+'[1]4'!K7/1000 -> 0.658 | Z24: =+'[1]4'!D27/1000 -> 0.273 | AC24: =K24-T24 -> 0.069784722
B25: MG | E25: 21.5 | W25: =+'[1]4'!K12/1000 -> 0.987
A27: 45966 | B27: MG | C27: =(M27*E27*O27*Q27)/100000000 -> 18.900229 | D27: Off White | E27: 14 | F27: 1 | G27: 1270 | H27: 0 | I27: 0.88 | J27: =E27*G27*(1-H27)*1440/1000000*2.77 -> 70.920864 | K27: =(IF(G27<L27,L27,G27)*(1-IF(H27<N27,H27,N27))*E27*O27*Q27)/100000000 -> 20.413218 | L27: 1180 | M27: =+L27-L27*0.0035 -> 1175.87 | N27: =1-(M27/L27) -> 0.0035 | O27: =+'[1]Trim Rwd'!H25 -> 267 | P27: =O27*(Q27-R27-S27) -> 93717 | Q27: 430 | R27: 60 | S27: 19 | T27: =E27*M27*O27*Q27/100000000 -> 18.900229 | U27: =E27*M27*O27*(Q27-R27-S27)/100000000 -> 15.427861 | V27: =E27*G27*(1-N27)*O27/100*(R27+S27)/1000000 -> 3.7372092 | W27: =+'[1]5'!K7/1000 -> 29.161 | X27: =SUM(W27:W30)/SUM(K27:K30) -> 0.90111446 | Y27: 0 | Z27: =+'[1]5'!D16/1000 -> 0.444 | AA27: =SUM(U27:U30)-SUM(W27:W30)-SUM(Z27:Z30)-SUM(Y27:Y30) -> -9.9001869 | AB27: =(SUM(K27:K30)-SUM(W27:W30)-SUM(Y27:Y30)-SUM(Z27:Z30)-SUM(AC27:AC30)-SUM(V27:V30))-AA27 -> -0.8112333 | AC27: =K27-T27 -> 1.5129891 | AD27: =+AM27+BA27 -> 50 | AE27: - Sheet Breaks (10x) | AF27: 50 | AM27: =SUM(AF27:AL27)+AT27+AV27+AX27 -> 50 | AR27: =SUM(AN27:AQ27) -> 0 | BA27: =+AR27+AS27+AU27+AW27+AY27+AZ27 -> 0 | BB27: 10
B28: Facial | C28: =(M28*E28*O28*Q28)/100000000 -> 37.913124 | D28: Off White | E28: 10.3 | F28: 1 | G28: 1730 | H28: 0.16 | I28: 0.88 | J28: =E28*G28*(1-H28)*1440/1000000*2.77 -> 59.704199 | K28: =(IF(G28<L28,L28,G28)*(1-IF(H28<N28,H28,N28))*E28*O28*Q28)/100000000 -> 40.817627 | L28: 1606.8966 | M28: 1349.7931 | N28: =1-(M28/L28) -> 0.16 | O28: =+'[1]Trim Rwd'!H26 -> 270 | P28: =O28*(Q28-R28-S28) -> 221400 | Q28: 1010 | R28: 140 | S28: 50 | T28: =E28*M28*O28*Q28/100000000 -> 37.913124 | U28: =E28*M28*O28*(Q28-R28-S28)/100000000 -> 30.780952 | V28: =E28*G28*(1-N28)*O28/100*(R28+S28)/1000000 -> 7.6785635 | W28: =+'[1]5'!K13/1000 -> 17.317 | Z28: 0 | AC28: =K28-T28 -> 2.9045033 | AD28: =+AM28+BA28 -> 0 | AE28: - Change Blade (0x) | AG28: 0 | AM28: =SUM(AF28:AL28)+AT28+AV28+AX28 -> 0 | AR28: =SUM(AN28:AQ28) -> 0 | BA28: =+AR28+AS28+AU28+AW28+AY28+AZ28 -> 0 | BC28: 0
B29: MG | E29: 18 | W29: =+'[1]5'!K11/1000 -> 8.698 | Z29: =+'[1]5'!D8/1000 -> 0.489 | AD29: =+AM29+BA29 -> 19 | AE29: - Change Spool (19x) | AH29: 19 | AM29: =SUM(AF29:AL29)+AT29+AV29+AX29 -> 19 | AR29: =SUM(AN29:AQ29) -> 0 | BA29: =+AR29+AS29+AU29+AW29+AY29+AZ29 -> 0
AD30: =+AM30+BA30 -> 60 | AE30: - 11.30 Pm stop, turbo vaccum trip | AM30: =SUM(AF30:AL30)+AT30+AV30+AX30 -> 0 | AP30: 60 | AR30: =SUM(AN30:AQ30) -> 60 | BA30: =+AR30+AS30+AU30+AW30+AY30+AZ30 -> 60
AD31: =+AM31+BA31 -> 140 | AE31: - 04.00 PM Stop, Van belt vertikal screen putus tinggal 1, Med Ganti Van belt | AM31: =SUM(AF31:AL31)+AT31+AV31+AX31 -> 0 | AO31: 140 | AR31: =SUM(AN31:AQ31) -> 140 | BA31: =+AR31+AS31+AU31+AW31+AY31+AZ31 -> 140
A33: 45936 | B33: Facial | C33: =(M33*E33*O33*Q33)/100000000 -> 54.590485 | D33: Off White | E33: 12 | F33: 1 | G33: 1700 | H33: 0.24 | I33: 0.88 | J33: =E33*G33*(1-H33)*1440/1000000*2.77 -> 61.842355 | K33: =(IF(G33<L33,L33,G33)*(1-IF(H33<N33,H33,N33))*E33*O33*Q33)/100000000 -> 59.192561 | L33: 1567.8292 | M33: 1191.5502 | N33: =1-(M33/L33) -> 0.24 | O33: =+'[1]Trim Rwd'!H30 -> 267.92208 | P33: =O33*(Q33-R33-S33) -> 346423.25 | Q33: 1425 | R33: 20 | S33: =85+27 -> 112 | T33: =E33*M33*O33*Q33/100000000 -> 54.590485 | U33: =E33*M33*O33*(Q33-R33-S33)/100000000 -> 49.533682 | V33: =E33*G33*(1-N33)*O33/100*(R33+S33)/1000000 -> 5.4831003 | W33: =+'[1]6'!K14/1000 -> 43.052 | X33: =SUM(W33:W36)/SUM(K33:K36) -> 0.74072482 | Y33: 0 | Z33: 0 | AA33: =SUM(U33:U36)-SUM(W33:W36)-SUM(Z33:Z36)-SUM(Y33:Y36) -> 5.4756482 | AB33: =(SUM(K33:K36)-SUM(W33:W36)-SUM(Y33:Y36)-SUM(Z33:Z36)-SUM(AC33:AC36)-SUM(V33:V36))-AA33 -> -0.42629756 | AC33: =K33-T33 -> 4.602076 | AD33: =+AM33+BA33 -> 85 | AE33: - Sheet Breaks (27x) | AF33: 85 | AM33: =SUM(AF33:AL33)+AT33+AV33+AX33 -> 85 | AR33: =SUM(AN33:AQ33) -> 0 | BA33: =+AR33+AS33+AU33+AW33+AY33+AZ33 -> 0 | BB33: 27
B34: Facial | C34: =(M34*E34*O34*Q34)/100000000 -> 0.6449664 | D34: Off White | E34: 13 | F34: 1 | G34: 1700 | H34: 0.24 | I34: 0.88 | J34: =E34*G34*(1-H34)*1440/1000000*2.77 -> 66.995885 | K34: =(IF(G34<L34,L34,G34)*(1-IF(H34<N34,H34,N34))*E34*O34*Q34)/100000000 -> 0.6852768 | L34: 1600 | M34: 1216 | N34: =1-(M34/L34) -> 0.24 | O34: =+'[1]Trim Rwd'!H33 -> 272 | P34: =O34*(Q34-R34-S34) -> 4080 | Q34: 15 | R34: 0 | S34: 0 | T34: =E34*M34*O34*Q34/100000000 -> 0.6449664 | U34: =E34*M34*O34*(Q34-R34-S34)/100000000 -> 0.6449664 | V34: =E34*G34*(1-N34)*O34/100*(R34+S34)/1000000 -> 0 | W34: =+'[1]6'!K15/1000 -> 0 | Z34: 0 | AC34: =K34-T34 -> 0.0403104 | AD34: =+AM34+BA34 -> 0 | AE34: - Change Blade (0x) | AG34: 0 | AM34: =SUM(AF34:AL34)+AT34+AV34+AX34 -> 0 | AR34: =SUM(AN34:AQ34) -> 0 | BA34: =+AR34+AS34+AU34+AW34+AY34+AZ34 -> 0 | BC34: 0
B35: Facial | E35: 10.3 | W35: =+'[1]6'!K13/1000 -> 1.301 | Z35: =+'[1]6'!D8/1000 -> 0.35 | AD35: =+AM35+BA35 -> 27 | AE35: - Change Spool (26x) | AH35: 27 | AM35: =SUM(AF35:AL35)+AT35+AV35+AX35 -> 27 | AR35: =SUM(AN35:AQ35) -> 0 | BA35: =+AR35+AS35+AU35+AW35+AY35+AZ35 -> 0
AD36: =+AM36+BA36 -> 20 | AE36: - 12.20 pm trip stock flow alarm | AM36: =SUM(AF36:AL36)+AT36+AV36+AX36 -> 0 | AP36: 20 | AR36: =SUM(AN36:AQ36) -> 20 | BA36: =+AR36+AS36+AU36+AW36+AY36+AZ36 -> 20
A38: 45968 | B38: Facial | C38: =(M38*E38*O38*Q38)/100000000 -> 37.193062 | D38: Off White | E38: 13 | F38: 1 | G38: 1700 | H38: 0.24 | I38: 0.88 | J38: =E38*G38*(1-H38)*1440/1000000*2.77 -> 66.995885 | K38: =(IF(G38<L38,L38,G38)*(1-IF(H38<N38,H38,N38))*E38*O38*Q38)/100000000 -> 39.517629 | L38: 1600 | M38: 1216 | N38: =1-(M38/L38) -> 0.24 | O38: =+'[1]Trim Rwd'!H35 -> 272 | P38: =O38*(Q38-R38-S38) -> 210800 | Q38: 865 | R38: 0 | S38: 90 | T38: =E38*M38*O38*Q38/100000000 -> 37.193062 | U38: =E38*M38*O38*(Q38-R38-S38)/100000000 -> 33.323264 | V38: =E38*G38*(1-N38)*O38/100*(R38+S38)/1000000 -> 4.1116608 | W38: =+'[1]7'!K15/1000 -> 32.631 | X38: =SUM(W38:W41)/SUM(K38:K41) -> 0.78018144 | Y38: 0 | Z38: 0 | AA38: =SUM(U38:U41)-SUM(W38:W41)-SUM(Z38:Z41)-SUM(Y38:Y41) -> 4.4809749 | AB38: =(SUM(K38:K41)-SUM(W38:W41)-SUM(Y38:Y41)-SUM(Z38:Z41)-SUM(AC38:AC41)-SUM(V38:V41))-AA38 -> -0.3503499 | AC38: =K38-T38 -> 2.3245664 | AD38: =+AM38+BA38 -> 90 | AE38: - Sheet Breaks (18x) | AF38: 90 | AM38: =SUM(AF38:AL38)+AT38+AV38+AX38 -> 90 | AR38: =SUM(AN38:AQ38) -> 0 | BA38: =+AR38+AS38+AU38+AW38+AY38+AZ38 -> 0 | BB38: 18
B39: Facial | C39: =(M39*E39*O39*Q39)/100000000 -> 21.294 | D39: Off White | E39: 10.3 | F39: 1 | G39: 1730 | H39: 0.16 | I39: 0.88 | J39: =E39*G39*(1-H39)*1440/1000000*2.77 -> 59.704199 | K39: =(IF(G39<L39,L39,G39)*(1-IF(H39<N39,H39,N39))*E39*O39*Q39)/100000000 -> 22.893495 | L39: 1609.1304 | M39: 1351.6696 | N39: =1-(M39/L39) -> 0.16 | O39: =+'[1]Trim Rwd'!H36 -> 266 | P39: =O39*(Q39-R39-S39) -> 142576 | Q39: 575 | R39: 0 | S39: =13+26 -> 39 | T39: =E39*M39*O39*Q39/100000000 -> 21.294 | U39: =E39*M39*O39*(Q39-R39-S39)/100000000 -> 19.849711 | V39: =E39*G39*(1-N39)*O39/100*(R39+S39)/1000000 -> 1.5527762 | W39: =+'[1]7'!K13/1000 -> 11.616 | Z39: 0 | AC39: =K39-T39 -> 1.5994952 | AD39: =+AM39+BA39 -> 13 | AE39: - Change Blade (7x) | AG39: 13 | AM39: =SUM(AF39:AL39)+AT39+AV39+AX39 -> 13 | AR39: =SUM(AN39:AQ39) -> 0 | BA39: =+AR39+AS39+AU39+AW39+AY39+AZ39 -> 0 | BC39: 7
B40: Facial | E40: 12 | W40: =+'[1]7'!K14/1000 -> 4.445 | AD40: =+AM40+BA40 -> 26 | AE40: - Change Spool (25x) | AH40: 26 | AM40: =SUM(AF40:AL40)+AT40+AV40+AX40 -> 26 | AR40: =SUM(AN40:AQ40) -> 0 | BA40: =+AR40+AS40+AU40+AW40+AY40+AZ40 -> 0
A42: 45969 | B42: Facial | C42: =(M42*E42*O42*Q42)/100000000 -> 51.478431 | D42: Off White | E42: 10.3 | F42: 1 | G42: 1730 | H42: 0.16 | I42: 0.88 | J42: =E42*G42*(1-H42)*1440/1000000*2.77 -> 59.704199 | K42: =(IF(G42<L42,L42,G42)*(1-IF(H42<N42,H42,N42))*E42*O42*Q42)/100000000 -> 57.333274 | L42: 1553.3333 | M42: 1304.8 | N42: =1-(M42/L42) -> 0.16 | O42: =+'[1]Trim Rwd'!H39 -> 266 | P42: =O42*(Q42-R42-S42) -> 364686 | Q42: 1440 | R42: 0 | S42: 69 | T42: =E42*M42*O42*Q42/100000000 -> 51.478431 | U42: =E42*M42*O42*(Q42-R42-S42)/100000000 -> 49.011756 | V42: =E42*G42*(1-N42)*O42/100*(R42+S42)/1000000 -> 2.7472194 | W42: =+'[1]8'!K34/1000 -> 47.743 | X42: =SUM(W42:W45)/SUM(K42:K45) -> 0.83272761 | Y42: 0 | Z42: 0 | AA42: =SUM(U42:U45)-SUM(W42:W45)-SUM(Z42:Z45)-SUM(Y42:Y45) -> 1.2687562 | AB42: =(SUM(K42:K45)-SUM(W42:W45)-SUM(Y42:Y45)-SUM(Z42:Z45)-SUM(AC42:AC45)-SUM(V42:V45))-AA42 -> -0.28054456 | AC42: =K42-T42 -> 5.854843 | AD42: =+AM42+BA42 -> 25 | AE42: - Sheet Breaks (5x) | AF42: 25 | AM42: =SUM(AF42:AL42)+AT42+AV42+AX42 -> 25 | AR42: =SUM(AN42:AQ42) -> 0 | BA42: =+AR42+AS42+AU42+AW42+AY42+AZ42 -> 0 | BB42: 5
AD43: =+AM43+BA43 -> 18 | AE43: - Change Blade (10x) | AG43: 18 | AM43: =SUM(AF43:AL43)+AT43+AV43+AX43 -> 18 | AR43: =SUM(AN43:AQ43) -> 0 | BA43: =+AR43+AS43+AU43+AW43+AY43+AZ43 -> 0 | BC43: 10
AD44: =+AM44+BA44 -> 26 | AE44: - Change Spool (19x) | AH44: 26 | AM44: =SUM(AF44:AL44)+AT44+AV44+AX44 -> 26 | AR44: =SUM(AN44:AQ44) -> 0 | BA44: =+AR44+AS44+AU44+AW44+AY44+AZ44 -> 0
A46: 45970 | B46: Facial | C46: =(M46*E46*O46*Q46)/100000000 -> 31.490034 | D46: Off White | E46: 10.3 | F46: 1 | G46: 1730 | H46: 0.16 | I46: 0.88 | J46: =E46*G46*(1-H46)*1440/1000000*2.77 -> 59.704199 | K46: =(IF(G46<L46,L46,G46)*(1-IF(H46<N46,H46,N46))*E46*O46*Q46)/100000000 -> 34.479594 | L46: 1580 | M46: =+L46-L46*0.16 -> 1327.2 | N46: =1-(M46/L46) -> 0.16 | O46: =+'[1]Trim Rwd'!H42 -> 266 | P46: =O46*(Q46-R46-S46) -> 222642 | Q46: 866 | R46: 0 | S46: 29 | T46: =E46*M46*O46*Q46/100000000 -> 31.490034 | U46: =E46*M46*O46*(Q46-R46-S46)/100000000 -> 30.435518 | V46: =E46*G46*(1-N46)*O46/100*(R46+S46)/1000000 -> 1.1546284 | W46: =+'[1]9'!K13/1000 -> 37.961 | X46: =SUM(W46:W49)/SUM(K46:K49) -> 0.89529502 | Y46: 0 | Z46: 0 | AA46: =SUM(U46:U49)-SUM(W46:W49)-SUM(Z46:Z49)-SUM(Y46:Y49) -> -0.55747437 | AB46: =(SUM(K46:K49)-SUM(W46:W49)-SUM(Y46:Y49)-SUM(Z46:Z49)-SUM(AC46:AC49)-SUM(V46:V49))-AA46 -> -0.14288509 | AC46: =K46-T46 -> 2.9895602 | AD46: =+AM46+BA46 -> 0 | AE46: - Sheet Breaks (0x) | AF46: 0 | AM46: =SUM(AF46:AL46)+AT46+AV46+AX46 -> 0 | AR46: =SUM(AN46:AQ46) -> 0 | BA46: =+AR46+AS46+AU46+AW46+AY46+AZ46 -> 0 | BB46: 0
B47: Facial | C47: =(M47*E47*O47*Q47)/100000000 -> 23.090183 | D47: Off White | E47: 12.5 | F47: 1 | G47: 1700 | H47: 0.24 | I47: 0.88 | J47: =E47*G47*(1-H47)*1440/1000000*2.77 -> 64.41912 | K47: =(IF(G47<L47,L47,G47)*(1-IF(H47<N47,H47,N47))*E47*O47*Q47)/100000000 -> 24.843868 | L47: 1580 | M47: =+L47-L47*0.24 -> 1200.8 | N47: =1-(M47/L47) -> 0.24 | O47: =+'[1]Trim Rwd'!H43 -> 268 | P47: =O47*(Q47-R47-S47) -> 150080 | Q47: 574 | R47: 0 | S47: 14 | T47: =E47*M47*O47*Q47/100000000 -> 23.090183 | U47: =E47*M47*O47*(Q47-R47-S47)/100000000 -> 22.527008 | V47: =E47*G47*(1-N47)*O47/100*(R47+S47)/1000000 -> 0.605948 | W47: =+'[1]9'!K16/1000 -> 15.151 | Z47: =+'[1]9'!D34/1000 -> 0.408 | AC47: =K47-T47 -> 1.7536848 | AD47: =+AM47+BA47 -> 14 | AE47: - Change Blade (11x) | AG47: 14 | AM47: =SUM(AF47:AL47)+AT47+AV47+AX47 -> 14 | AR47: =SUM(AN47:AQ47) -> 0 | BA47: =+AR47+AS47+AU47+AW47+AY47+AZ47 -> 0 | BC47: 11
AD48: =+AM48+BA48 -> 29 | AE48: - Change Spool (26x) | AH48: 29 | AM48: =SUM(AF48:AL48)+AT48+AV48+AX48 -> 29 | AR48: =SUM(AN48:AQ48) -> 0 | BA48: =+AR48+AS48+AU48+AW48+AY48+AZ48 -> 0
A50: 45971 | B50: Facial | C50: =(M50*E50*O50*Q50)/100000000 -> 4.827216 | D50: Off White | E50: 12.5 | F50: 1 | G50: 1700 | H50: 0.24 | I50: 0.88 | J50: =E50*G50*(1-H50)*1440/1000000*2.77 -> 64.41912 | K50: =(IF(G50<L50,L50,G50)*(1-IF(H50<N50,H50,N50))*E50*O50*Q50)/100000000 -> 5.19384 | L50: 1580 | M50: =+L50-L50*0.24 -> 1200.8 | N50: =1-(M50/L50) -> 0.24 | O50: =+'[1]Trim Rwd'!H45 -> 268 | P50: =O50*(Q50-R50-S50) -> 28676 | Q50: 120 | R50: 0 | S50: 13 | T50: =E50*M50*O50*Q50/100000000 -> 4.827216 | U50: =E50*M50*O50*(Q50-R50-S50)/100000000 -> 4.3042676 | V50: =E50*G50*(1-N50)*O50/100*(R50+S50)/1000000 -> 0.562666 | W50: =+'[1]10'!K16/1000 -> 10.034 | X50: =SUM(W50:W53)/SUM(K50:K53) -> 0.81277099 | Y50: 0 | Z50: =+'[1]10'!D7/1000 -> 0.88 | AA50: =SUM(U50:U53)-SUM(W50:W53)-SUM(Z50:Z53)-SUM(Y50:Y53) -> 2.3899476 | AB50: =(SUM(K50:K53)-SUM(W50:W53)-SUM(Y50:Y53)-SUM(Z50:Z53)-SUM(AC50:AC53)-SUM(V50:V53))-AA50 -> -0.0397176 | AC50: =K50-T50 -> 0.366624 | AD50: =+AM50+BA50 -> 0 | AE50: - Sheet Breaks (0x) | AF50: 0 | AM50: =SUM(AF50:AL50)+AT50+AV50+AX50 -> 0 | AR50: =SUM(AN50:AQ50) -> 0 | BA50: =+AR50+AS50+AU50+AW50+AY50+AZ50 -> 0 | BB50: 0
...

Sheet PM 12
A1: PM12 Efficiency Running Report
A3: Date | B3: Grade | C3: Speed real (ton) with Available Time | D3: Colour | E3: gsm | F3: Ply | G3: Standard | L3: Real Running | O3: Trim Rewinder (cm) | P3: Trim Rewinder x Running Time | Q3: Available Time (mnt) | R3: Down Time (mnt) | S3: Loss Time (mnt) | T3: Real Speed & Real Creepe Ratio with Available Time (ton) | U3: Real Speed & Real Creepe Ratio setelah dipotong DT & LT (ton) | V3: Loss tonase akibat DT + LT dari hitungan Teori with available time (ton) | W3: Accepted (ton) | X3: Real Eff dr Target Eff | Y3: Backlog | Z3: Reject Rewinder (ton) | AA3: Estimasi Reject to Broke Plant (ton) | AB3: Estimasi Faktor BW (ton) | AC3: Loss Opportunity in Speed (ton) | AD3: Downtime/ Losstime | AE3: Reason of Downtime / Losstime | AF3: Loss Time | AM3: Total Losstime | AN3: Unschedule Shut Down (mnt) | AS3: Schedule Shut Down | AT3: Marketing | AV3: EXT FACTOR | AX3: EXT FACTOR | AZ3: MANAGEMENT | BA3: Total Down Time | BB3: Freq. Sheets Break (X) | BC3: Freq. Change Blade (X) | BD3: Steam, & gangguan sinergy (X) | BE3: Freq, Trip PLN (X) | BF3: Cleaning Holes (X)
AF4: Proses | AI4: Change Grade | AJ4: Mekanik | AK4: Electric & Instrument | AL4: Boiler | AN4: Down Time Produksi | AO4: Mekanik | AP4: Electrical & Instrument | AQ4: Boiler | AR4: Total Unschedule Shut Down | AV4: LOSS | AW4: DOWN TIME | AX4: LOSS | AY4: DOWN TIME
G5: Yankee Speed (mpm) | H5: Max % Creeping | I5: Target Eff | J5: Kapasitas PM-Teori (ton) | K5: Teori (ton) with Available Time | L5: Yankee Speed (mpm) | M5: Popereel Speed (mpm) | N5: % Creeping | AF5: sheet break | AG5: change blade | AH5: change spool | AT5: Loss time | AU5: Down Time | AV5: SINERGY | AW5: SINERGY | AX5: PLN | AY5: PLN
A6: =+[2]Report1!A9 -> 45962 | B6: Napkin | C6: =(M6*E6*O6*Q6)/100000000 -> 32.883898 | D6: RC BR | E6: 16 | F6: 1 | G6: 830 | H6: 0.14 | I6: 0.88 | J6: =E6*G6*(1-H6)*1440/1000000*3.4 -> 55.916237 | K6: =(IF(G6<L6,L6,G6)*(1-IF(H6<N6,H6,N6))*E6*O6*Q6)/100000000 -> 34.117044 | L6: 800 | M6: 688 | N6: =1-(M6/L6) -> 0.14 | O6: =+'[2]Trim Rwd'!H4 -> 321.21212 | P6: =O6*(Q6-R6-S6) -> 282666.67 | Q6: 930 | R6: 0 | S6: 50 | T6: =E6*M6*O6*Q6/100000000 -> 32.883898 | U6: =E6*M6*O6*(Q6-R6-S6)/100000000 -> 31.115947 | V6: =E6*G6*(1-N6)*O6/100*(R6+S6)/1000000 -> 1.8342497 | W6: =+'[2]1'!K7/1000 -> 31.335 | X6: =SUM(W6:W9)/SUM(K6:K9) -> 0.82240431 | Y6: 0 | Z6: =+'[2]1'!D34/1000 -> 0.66 | AA6: =SUM(U6:U9)-SUM(W6:W9)-SUM(Z6:Z9)-SUM(Y6:Y9) -> 4.235091 | AB6: =(SUM(K6:K9)-SUM(W6:W9)-SUM(Y6:Y9)-SUM(Z6:Z9)-SUM(AC6:AC9)-SUM(V6:V9))-AA6 -> -0.09497901 | AC6: =K6-T6 -> 1.2331462 | AD6: =+AM6+BA6 -> 0 | AE6: - Sheet Breaks (0x) | AF6: 0 | AM6: =SUM(AF6:AL6)+AT6+AV6+AX6 -> 0 | AR6: =SUM(AN6:AQ6) -> 0 | BA6: =+AR6+AS6+AU6+AW6+AY6+AZ6 -> 0 | BB6: 0
B7: Napkin | C7: =(M7*E7*O7*Q7)/100000000 -> 17.729966 | D7: RC BR | E7: 15.5 | F7: 1 | G7: 830 | H7: 0.14 | I7: 0.88 | J7: =E7*G7*(1-H7)*1440/1000000*3.4 -> 54.168854 | K7: =(IF(G7<L7,L7,G7)*(1-IF(H7<N7,H7,N7))*E7*O7*Q7)/100000000 -> 18.39484 | L7: 800 | M7: 688 | N7: =1-(M7/L7) -> 0.14 | O7: =+'[2]Trim Rwd'!H6 -> 326 | P7: =O7*(Q7-R7-S7) -> 159088 | Q7: 510 | R7: 0 | S7: 22 | T7: =E7*M7*O7*Q7/100000000 -> 17.729966 | U7: =E7*M7*O7*(Q7-R7-S7)/100000000 -> 16.965144 | V7: =E7*G7*(1-N7)*O7/100*(R7+S7)/1000000 -> 0.79350291 | W7: =+'[2]1'!K8/1000 -> 11.851 | Z7: 0 | AC7: =K7-T7 -> 0.66487374 | AD7: =+AM7+BA7 -> 38 | AE7: - Change Blade (8x) | AG7: 38 | AM7: =SUM(AF7:AL7)+AT7+AV7+AX7 -> 38 | AR7: =SUM(AN7:AQ7) -> 0 | BA7: =+AR7+AS7+AU7+AW7+AY7+AZ7 -> 0 | BC7: 8
AD8: =+AM8+BA8 -> 32 | AE8: - Cleaning | AH8: 32 | AM8: =SUM(AF8:AL8)+AT8+AV8+AX8 -> 32 | AR8: =SUM(AN8:AQ8) -> 0 | BA8: =+AR8+AS8+AU8+AW8+AY8+AZ8 -> 0
AD9: =+AM9+BA9 -> 2 | AE9: - Change Grade | AI9: 2 | AM9: =SUM(AF9:AL9)+AT9+AV9+AX9 -> 2 | AR9: =SUM(AN9:AQ9) -> 0 | BA9: =+AR9+AS9+AU9+AW9+AY9+AZ9 -> 0
A11: 45963 | B11: Napkin | C11: =(M11*E11*O11*Q11)/100000000 -> 50.061082 | D11: RC BR | E11: 15.5 | F11: 1 | G11: 830 | H11: 0.14 | I11: 0.88 | J11: =E11*G11*(1-H11)*1440/1000000*3.4 -> 54.168854 | K11: =(IF(G11<L11,L11,G11)*(1-IF(H11<N11,H11,N11))*E11*O11*Q11)/100000000 -> 51.938372 | L11: 800 | M11: 688 | N11: =1-(M11/L11) -> 0.14 | O11: =+'[2]Trim Rwd'!H8 -> 326 | P11: =O11*(Q11-R11-S11) -> 450858 | Q11: 1440 | R11: 0 | S11: 57 | T11: =E11*M11*O11*Q11/100000000 -> 50.061082 | U11: =E11*M11*O11*(Q11-R11-S11)/100000000 -> 48.079497 | V11: =E11*G11*(1-N11)*O11/100*(R11+S11)/1000000 -> 2.0558939 | W11: =+'[2]2'!K34/1000 -> 48.007 | X11: =SUM(W11:W14)/SUM(K11:K14) -> 0.92430698 | Y11: 0 | Z11: =+'[2]2'!D34/1000 -> 0.55 | AA11: =SUM(U11:U14)-SUM(W11:W14)-SUM(Z11:Z14)-SUM(Y11:Y14) -> -0.47750288 | AB11: =(SUM(K11:K14)-SUM(W11:W14)-SUM(Y11:Y14)-SUM(Z11:Z14)-SUM(AC11:AC14)-SUM(V11:V14))-AA11 -> -0.074309418 | AC11: =K11-T11 -> 1.8772906 | AD11: =+AM11+BA11 -> 0 | AE11: - Sheet Breaks (0x) | AF11: 0 | AM11: =SUM(AF11:AL11)+AT11+AV11+AX11 -> 0 | AR11: =SUM(AN11:AQ11) -> 0 | BA11: =+AR11+AS11+AU11+AW11+AY11+AZ11 -> 0 | BB11: 0
AD12: =+AM12+BA12 -> 43 | AE12: - Change Blade (6x) | AG12: 43 | AM12: =SUM(AF12:AL12)+AT12+AV12+AX12 -> 43 | AR12: =SUM(AN12:AQ12) -> 0 | BA12: =+AR12+AS12+AU12+AW12+AY12+AZ12 -> 0 | BC12: 6
AD13: =+AM13+BA13 -> 14 | AE13: - Cleaning | AH13: 14 | AM13: =SUM(AF13:AL13)+AT13+AV13+AX13 -> 14 | AR13: =SUM(AN13:AQ13) -> 0 | BA13: =+AR13+AS13+AU13+AW13+AY13+AZ13 -> 0
A15: 45964 | B15: Napkin | C15: =(M15*E15*O15*Q15)/100000000 -> 50.061082 | D15: RC BR | E15: 15.5 | F15: 1 | G15: 830 | H15: 0.14 | I15: 0.88 | J15: =E15*G15*(1-H15)*1440/1000000*3.4 -> 54.168854 | K15: =(IF(G15<L15,L15,G15)*(1-IF(H15<N15,H15,N15))*E15*O15*Q15)/100000000 -> 51.938372 | L15: 800 | M15: 688 | N15: =1-(M15/L15) -> 0.14 | O15: =+'[2]Trim Rwd'!H10 -> 326 | P15: =O15*(Q15-R15-S15) -> 456726 | Q15: 1440 | R15: 0 | S15: 39 | T15: =E15*M15*O15*Q15/100000000 -> 50.061082 | U15: =E15*M15*O15*(Q15-R15-S15)/100000000 -> 48.705261 | V15: =E15*G15*(1-N15)*O15/100*(R15+S15)/1000000 -> 1.4066642 | W15: =+'[2]3'!K34/1000 -> 48.51 | X15: =SUM(W15:W18)/SUM(K15:K18) -> 0.93399154 | Y15: 0 | Z15: 0 | AA15: =SUM(U15:U18)-SUM(W15:W18)-SUM(Z15:Z18)-SUM(Y15:Y18) -> 0.19526064 | AB15: =(SUM(K15:K18)-SUM(W15:W18)-SUM(Y15:Y18)-SUM(Z15:Z18)-SUM(AC15:AC18)-SUM(V15:V18))-AA15 -> -0.050843286 | AC15: =K15-T15 -> 1.8772906 | AD15: =+AM15+BA15 -> 0 | AE15: - Sheet Breaks (0x) | AF15: 0 | AM15: =SUM(AF15:AL15)+AT15+AV15+AX15 -> 0 | AR15: =SUM(AN15:AQ15) -> 0 | BA15: =+AR15+AS15+AU15+AW15+AY15+AZ15 -> 0 | BB15: 0
AD16: =+AM16+BA16 -> 23 | AE16: - Change Blade (6x) | AG16: 23 | AM16: =SUM(AF16:AL16)+AT16+AV16+AX16 -> 23 | AR16: =SUM(AN16:AQ16) -> 0 | BA16: =+AR16+AS16+AU16+AW16+AY16+AZ16 -> 0 | BC16: 6
AD17: =+AM17+BA17 -> 16 | AE17: - Cleaning | AH17: 16 | AM17: =SUM(AF17:AL17)+AT17+AV17+AX17 -> 16 | AR17: =SUM(AN17:AQ17) -> 0 | BA17: =+AR17+AS17+AU17+AW17+AY17+AZ17 -> 0
A19: 45965 | B19: Napkin | C19: =(M19*E19*O19*Q19)/100000000 -> 50.061082 | D19: RC BR | E19: 15.5 | F19: 1 | G19: 830 | H19: 0.14 | I19: 0.88 | J19: =E19*G19*(1-H19)*1440/1000000*3.4 -> 54.168854 | K19: =(IF(G19<L19,L19,G19)*(1-IF(H19<N19,H19,N19))*E19*O19*Q19)/100000000 -> 51.938372 | L19: 800 | M19: 688 | N19: =1-(M19/L19) -> 0.14 | O19: =+'[2]Trim Rwd'!H12 -> 326 | P19: =O19*(Q19-R19-S19) -> 453140 | Q19: 1440 | R19: 0 | S19: 50 | T19: =E19*M19*O19*Q19/100000000 -> 50.061082 | U19: =E19*M19*O19*(Q19-R19-S19)/100000000 -> 48.32285 | V19: =E19*G19*(1-N19)*O19/100*(R19+S19)/1000000 -> 1.8034157 | W19: =+'[2]4'!K34/1000 -> 47.162 | X19: =SUM(W19:W22)/SUM(K19:K22) -> 0.9080377 | Y19: 0 | Z19: 0 | AA19: =SUM(U19:U22)-SUM(W19:W22)-SUM(Z19:Z22)-SUM(Y19:Y22) -> 1.1608496 | AB19: =(SUM(K19:K22)-SUM(W19:W22)-SUM(Y19:Y22)-SUM(Z19:Z22)-SUM(AC19:AC22)-SUM(V19:V22))-AA19 -> -0.0651837 | AC19: =K19-T19 -> 1.8772906 | AD19: =+AM19+BA19 -> 2 | AE19: - Sheet Breaks (1x) | AF19: 2 | AM19: =SUM(AF19:AL19)+AT19+AV19+AX19 -> 2 | AR19: =SUM(AN19:AQ19) -> 0 | BA19: =+AR19+AS19+AU19+AW19+AY19+AZ19 -> 0 | BB19: 1
AD20: =+AM20+BA20 -> 29 | AE20: - Change Blade (9x) | AG20: 29 | AM20: =SUM(AF20:AL20)+AT20+AV20+AX20 -> 29 | AR20: =SUM(AN20:AQ20) -> 0 | BA20: =+AR20+AS20+AU20+AW20+AY20+AZ20 -> 0 | BC20: 9
AD21: =+AM21+BA21 -> 19 | AE21: - Cleaning | AH21: 19 | AM21: =SUM(AF21:AL21)+AT21+AV21+AX21 -> 19 | AR21: =SUM(AN21:AQ21) -> 0 | BA21: =+AR21+AS21+AU21+AW21+AY21+AZ21 -> 0
A23: 45966 | B23: Napkin | C23: =(M23*E23*O23*Q23)/100000000 -> 50.061082 | D23: RC BR | E23: 15.5 | F23: 1 | G23: 830 | H23: 0.14 | I23: 0.88 | J23: =E23*G23*(1-H23)*1440/1000000*3.4 -> 54.168854 | K23: =(IF(G23<L23,L23,G23)*(1-IF(H23<N23,H23,N23))*E23*O23*Q23)/100000000 -> 51.938372 | L23: 800 | M23: 688 | N23: =1-(M23/L23) -> 0.14 | O23: =+'[2]Trim Rwd'!H14 -> 326 | P23: =O23*(Q23-R23-S23) -> 444664 | Q23: 1440 | R23: 0 | S23: 76 | T23: =E23*M23*O23*Q23/100000000 -> 50.061082 | U23: =E23*M23*O23*(Q23-R23-S23)/100000000 -> 47.418969 | V23: =E23*G23*(1-N23)*O23/100*(R23+S23)/1000000 -> 2.7411919 | W23: =+'[2]5'!K34/1000 -> 44.61 | X23: =SUM(W23:W26)/SUM(K23:K26) -> 0.85890254 | Y23: 0 | Z23: =+'[2]5'!D34/1000 -> 2.618 | AA23: =SUM(U23:U26)-SUM(W23:W26)-SUM(Z23:Z26)-SUM(Y23:Y26) -> 0.19096896 | AB23: =(SUM(K23:K26)-SUM(W23:W26)-SUM(Y23:Y26)-SUM(Z23:Z26)-SUM(AC23:AC26)-SUM(V23:V26))-AA23 -> -0.099079224 | AC23: =K23-T23 -> 1.8772906 | AD23: =+AM23+BA23 -> 6 | AE23: - Sheet Breaks (4x) | AF23: 6 | AM23: =SUM(AF23:AL23)+AT23+AV23+AX23 -> 6 | AR23: =SUM(AN23:AQ23) -> 0 | BA23: =+AR23+AS23+AU23+AW23+AY23+AZ23 -> 0 | BB23: 4
AD24: =+AM24+BA24 -> 22 | AE24: - Change Blade (9x) | AG24: 22 | AM24: =SUM(AF24:AL24)+AT24+AV24+AX24 -> 22 | AR24: =SUM(AN24:AQ24) -> 0 | BA24: =+AR24+AS24+AU24+AW24+AY24+AZ24 -> 0 | BC24: 9
AD25: =+AM25+BA25 -> 18 | AE25: - Cleaning | AH25: 18 | AM25: =SUM(AF25:AL25)+AT25+AV25+AX25 -> 18 | AR25: =SUM(AN25:AQ25) -> 0 | BA25: =+AR25+AS25+AU25+AW25+AY25+AZ25 -> 0
AD26: =+AM26+BA26 -> 30 | AE26: - 18.00 formasi terawang, reject, adjust lips headbox | AI26: 30 | AM26: =SUM(AF26:AL26)+AT26+AV26+AX26 -> 30 | AR26: =SUM(AN26:AQ26) -> 0 | BA26: =+AR26+AS26+AU26+AW26+AY26+AZ26 -> 0
A28: 45967 | B28: Napkin | C28: =(M28*E28*O28*Q28)/100000000 -> 50.061082 | D28: RC BR | E28: 15.5 | F28: 1 | G28: 830 | H28: 0.14 | I28: 0.88 | J28: =E28*G28*(1-H28)*1440/1000000*3.4 -> 54.168854 | K28: =(IF(G28<L28,L28,G28)*(1-IF(H28<N28,H28,N28))*E28*O28*Q28)/100000000 -> 51.938372 | L28: 800 | M28: 688 | N28: =1-(M28/L28) -> 0.14 | O28: =+'[2]Trim Rwd'!H16 -> 326 | P28: =O28*(Q28-R28-S28) -> 451510 | Q28: 1440 | R28: 0 | S28: 55 | T28: =E28*M28*O28*Q28/100000000 -> 50.061082 | U28: =E28*M28*O28*(Q28-R28-S28)/100000000 -> 48.149026 | V28: =E28*G28*(1-N28)*O28/100*(R28+S28)/1000000 -> 1.9837573 | W28: =+'[2]6'!K34/1000 -> 46.864 | X28: =SUM(W28:W31)/SUM(K28:K31) -> 0.90230013 | Y28: 0 | Z28: =+'[2]6'!D34/1000 -> 0.331 | AA28: =SUM(U28:U31)-SUM(W28:W31)-SUM(Z28:Z31)-SUM(Y28:Y31) -> 0.9540264 | AB28: =(SUM(K28:K31)-SUM(W28:W31)-SUM(Y28:Y31)-SUM(Z28:Z31)-SUM(AC28:AC31)-SUM(V28:V31))-AA28 -> -0.07170207 | AC28: =K28-T28 -> 1.8772906 | AD28: =+AM28+BA28 -> 10 | AE28: - Sheet Breaks (2x) | AF28: 10 | AM28: =SUM(AF28:AL28)+AT28+AV28+AX28 -> 10 | AR28: =SUM(AN28:AQ28) -> 0 | BA28: =+AR28+AS28+AU28+AW28+AY28+AZ28 -> 0 | BB28: 2
AD29: =+AM29+BA29 -> 28 | AE29: - Change Blade (7x) | AG29: 28 | AM29: =SUM(AF29:AL29)+AT29+AV29+AX29 -> 28 | AR29: =SUM(AN29:AQ29) -> 0 | BA29: =+AR29+AS29+AU29+AW29+AY29+AZ29 -> 0 | BC29: 7
AD30: =+AM30+BA30 -> 17 | AE30: - Cleaning | AH30: 17 | AM30: =SUM(AF30:AL30)+AT30+AV30+AX30 -> 17 | AR30: =SUM(AN30:AQ30) -> 0 | BA30: =+AR30+AS30+AU30+AW30+AY30+AZ30 -> 0
A32: 45968 | B32: Napkin | C32: =(M32*E32*O32*Q32)/100000000 -> 49.997098 | D32: RC BR | E32: 15.5 | F32: 1 | G32: 830 | H32: 0.14 | I32: 0.88 | J32: =E32*G32*(1-H32)*1440/1000000*3.4 -> 54.168854 | K32: =(IF(G32<L32,L32,G32)*(1-IF(H32<N32,H32,N32))*E32*O32*Q32)/100000000 -> 51.871989 | L32: 800 | M32: 688 | N32: =1-(M32/L32) -> 0.14 | O32: =+'[2]Trim Rwd'!H18 -> 325.58333 | P32: =O32*(Q32-R32-S32) -> 455491.08 | Q32: 1440 | R32: 0 | S32: 41 | T32: =E32*M32*O32*Q32/100000000 -> 49.997098 | U32: =E32*M32*O32*(Q32-R32-S32)/100000000 -> 48.573569 | V32: =E32*G32*(1-N32)*O32/100*(R32+S32)/1000000 -> 1.4769108 | W32: =+'[2]7'!K34/1000 -> 47.042 | X32: =SUM(W32:W35)/SUM(K32:K35) -> 0.90688638 | Y32: 0 | Z32: =+'[2]7'!D34/1000 -> 0.583 | AA32: =SUM(U32:U35)-SUM(W32:W35)-SUM(Z32:Z35)-SUM(Y32:Y35) -> 0.94856913 | AB32: =(SUM(K32:K35)-SUM(W32:W35)-SUM(Y32:Y35)-SUM(Z32:Z35)-SUM(AC32:AC35)-SUM(V32:V35))-AA32 -> -0.053382318 | AC32: =K32-T32 -> 1.8748912 | AD32: =+AM32+BA32 -> 2 | AE32: - Sheet Breaks (1x) | AF32: 2 | AM32: =SUM(AF32:AL32)+AT32+AV32+AX32 -> 2 | AR32: =SUM(AN32:AQ32) -> 0 | BA32: =+AR32+AS32+AU32+AW32+AY32+AZ32 -> 0 | BB32: 1
AD33: =+AM33+BA33 -> 20 | AE33: - Change Blade (7x) | AG33: 20 | AM33: =SUM(AF33:AL33)+AT33+AV33+AX33 -> 20 | AR33: =SUM(AN33:AQ33) -> 0 | BA33: =+AR33+AS33+AU33+AW33+AY33+AZ33 -> 0 | BC33: 7
AD34: =+AM34+BA34 -> 19 | AE34: - Cleaning | AH34: 19 | AM34: =SUM(AF34:AL34)+AT34+AV34+AX34 -> 19 | AR34: =SUM(AN34:AQ34) -> 0 | BA34: =+AR34+AS34+AU34+AW34+AY34+AZ34 -> 0
A36: 45969 | B36: Napkin | C36: =(M36*E36*O36*Q36)/100000000 -> 21.132895 | D36: RC BR | E36: 15.5 | F36: 1 | G36: 830 | H36: 0.14 | I36: 0.88 | J36: =E36*G36*(1-H36)*1440/1000000*3.4 -> 54.168854 | K36: =(IF(G36<L36,L36,G36)*(1-IF(H36<N36,H36,N36))*E36*O36*Q36)/100000000 -> 21.925379 | L36: 800 | M36: 688 | N36: =1-(M36/L36) -> 0.14 | O36: =+'[2]Trim Rwd'!H21 -> 324.86957 | P36: =O36*(Q36-R36-S36) -> 189723.83 | Q36: 610 | R36: 0 | S36: =3+23 -> 26 | T36: =E36*M36*O36*Q36/100000000 -> 21.132895 | U36: =E36*M36*O36*(Q36-R36-S36)/100000000 -> 20.232149 | V36: =E36*G36*(1-N36)*O36/100*(R36+S36)/1000000 -> 0.93452434 | W36: =+'[2]8'!K8/1000 -> 22.851 | X36: =SUM(W36:W39)/SUM(K36:K39) -> 0.82066148 | Y36: 0 | Z36: =+'[2]8'!D16/1000 -> 0.7 | AA36: =SUM(U36:U39)-SUM(W36:W39)-SUM(Z36:Z39)-SUM(Y36:Y39) -> 3.6495086 | AB36: =(SUM(K36:K39)-SUM(W36:W39)-SUM(Y36:Y39)-SUM(Z36:Z39)-SUM(AC36:AC39)-SUM(V36:V39))-AA36 -> -0.063262916 | AC36: =K36-T36 -> 0.79248357 | AD36: =+AM36+BA36 -> 3 | AE36: - Sheet Breaks (1x) | AF36: 3 | AM36: =SUM(AF36:AL36)+AT36+AV36+AX36 -> 3 | AR36: =SUM(AN36:AQ36) -> 0 | BA36: =+AR36+AS36+AU36+AW36+AY36+AZ36 -> 0 | BB36: 1
B37: Napkin | C37: =(M37*E37*O37*Q37)/100000000 -> 29.663625 | D37: RC BR | E37: 16 | F37: 1 | G37: 830 | H37: 0.14 | I37: 0.88 | J37: =E37*G37*(1-H37)*1440/1000000*3.4 -> 55.916237 | K37: =(IF(G37<L37,L37,G37)*(1-IF(H37<N37,H37,N37))*E37*O37*Q37)/100000000 -> 30.77601 | L37: 800 | M37: 688 | N37: =1-(M37/L37) -> 0.14 | O37: =+'[2]Trim Rwd'!H23 -> 324.66667 | P37: =O37*(Q37-R37-S37) -> 262330.67 | Q37: 830 | R37: 0 | S37: =17+5 -> 22 | T37: =E37*M37*O37*Q37/100000000 -> 29.663625 | U37: =E37*M37*O37*(Q37-R37-S37)/100000000 -> 28.87736 | V37: =E37*G37*(1-N37)*O37/100*(R37+S37)/1000000 -> 0.81574967 | W37: =+'[2]8'!K7/1000 -> 20.399 | Z37: =+('[2]8'!D17+'[2]8'!D25)/1000 -> 1.51 | AC37: =K37-T37 -> 1.1123859 | AD37: =+AM37+BA37 -> 23 | AE37: - Change Blade (7x) | AG37: 23 | AM37: =SUM(AF37:AL37)+AT37+AV37+AX37 -> 23 | AR37: =SUM(AN37:AQ37) -> 0 | BA37: =+AR37+AS37+AU37+AW37+AY37+AZ37 -> 0 | BC37: 7
AD38: =+AM38+BA38 -> 17 | AE38: - Cleaning | AH38: 17 | AM38: =SUM(AF38:AL38)+AT38+AV38+AX38 -> 17 | AR38: =SUM(AN38:AQ38) -> 0 | BA38: =+AR38+AS38+AU38+AW38+AY38+AZ38 -> 0
AD39: =+AM39+BA39 -> 5 | AE39: - Change Grade | AI39: 5 | AM39: =SUM(AF39:AL39)+AT39+AV39+AX39 -> 5 | AR39: =SUM(AN39:AQ39) -> 0 | BA39: =+AR39+AS39+AU39+AW39+AY39+AZ39 -> 0
A41: 45970 | B41: Napkin | C41: =(M41*E41*O41*Q41)/100000000 -> 19.92276 | D41: RC BR | E41: 16.5 | F41: 1 | G41: 830 | H41: 0.14 | I41: 0.88 | J41: =E41*G41*(1-H41)*1440/1000000*3.4 -> 57.663619 | K41: =(IF(G41<L41,L41,G41)*(1-IF(H41<N41,H41,N41))*E41*O41*Q41)/100000000 -> 20.669863 | L41: 800 | M41: 688 | N41: =1-(M41/L41) -> 0.14 | O41: =+'[2]Trim Rwd'!H26 -> 325 | P41: =O41*(Q41-R41-S41) -> 162500 | Q41: 540 | R41: 0 | S41: 40 | T41: =E41*M41*O41*Q41/100000000 -> 19.92276 | U41: =E41*M41*O41*(Q41-R41-S41)/100000000 -> 18.447 | V41: =E41*G41*(1-N41)*O41/100*(R41+S41)/1000000 -> 1.531101 | W41: =+'[2]9'!K9/1000 -> 17.846 | X41: =SUM(W41:W44)/SUM(K41:K44) -> 0.77458077 | Y41: 0 | Z41: =+'[2]9'!D34/1000 -> 1.63 | AA41: =SUM(U41:U44)-SUM(W41:W44)-SUM(Z41:Z44)-SUM(Y41:Y44) -> 5.5563201 | AB41: =(SUM(K41:K44)-SUM(W41:W44)-SUM(Y41:Y44)-SUM(Z41:Z44)-SUM(AC41:AC44)-SUM(V41:V44))-AA41 -> -0.12945111 | AC41: =K41-T41 -> 0.7471035 | AD41: =+AM41+BA41 -> 20 | AE41: - Sheet Breaks (1x) | AF41: 20 | AM41: =SUM(AF41:AL41)+AT41+AV41+AX41 -> 20 | AR41: =SUM(AN41:AQ41) -> 0 | BA41: =+AR41+AS41+AU41+AW41+AY41+AZ41 -> 0 | BB41: 1
B42: Napkin | C42: =(M42*E42*O42*Q42)/100000000 -> 24.442301 | D42: RC BR | E42: 17 | F42: 1 | G42: 830 | H42: 0.14 | I42: 0.88 | J42: =E42*G42*(1-H42)*1440/1000000*3.4 -> 59.411002 | K42: =(IF(G42<L42,L42,G42)*(1-IF(H42<N42,H42,N42))*E42*O42*Q42)/100000000 -> 25.358887 | L42: 800 | M42: 688 | N42: =1-(M42/L42) -> 0.14 | O42: =+'[2]Trim Rwd'!H28 -> 324 | P42: =O42*(Q42-R42-S42) -> 195372 | Q42: 645 | R42: 0 | S42: 42 | T42: =E42*M42*O42*Q42/100000000 -> 24.442301 | U42: =E42*M42*O42*(Q42-R42-S42)/100000000 -> 22.850709 | V42: =E42*G42*(1-N42)*O42/100*(R42+S42)/1000000 -> 1.6512764 | W42: =+'[2]9'!K10/1000 -> 21.681 | AC42: =K42-T42 -> 0.91658628 | AD42: =+AM42+BA42 -> 30 | AE42: - Change Blade (9x) | AG42: 30 | AM42: =SUM(AF42:AL42)+AT42+AV42+AX42 -> 30 | AR42: =SUM(AN42:AQ42) -> 0 | BA42: =+AR42+AS42+AU42+AW42+AY42+AZ42 -> 0 | BC42: 9
B43: Napkin | C43: =(M43*E43*O43*Q43)/100000000 -> 9.809289 | D43: RC BR | E43: 17.5 | F43: 1 | G43: 830 | H43: 0.14 | I43: 0.88 | J43: =E43*G43*(1-H43)*1440/1000000*3.4 -> 61.158384 | K43: =(IF(G43<L43,L43,G43)*(1-IF(H43<N43,H43,N43))*E43*O43*Q43)/100000000 -> 10.177137 | L43: 800 | M43: 688 | N43: =1-(M43/L43) -> 0.14 | O43: =+'[2]Trim Rwd'!H29 -> 319.5 | P43: =O43*(Q43-R43-S43) -> 78277.5 | Q43: 255 | R43: 0 | S43: 10 | T43: =E43*M43*O43*Q43/100000000 -> 9.809289 | U43: =E43*M43*O43*(Q43-R43-S43)/100000000 -> 9.424611 | V43: =E43*G43*(1-N43)*O43/100*(R43+S43)/1000000 -> 0.39910343 | W43: =+'[2]9'!K11/1000 -> 4.009 | AC43: =K43-T43 -> 0.36784834 | AD43: =+AM43+BA43 -> 32 | AE43: - Cleaning | AH43: 32 | AM43: =SUM(AF43:AL43)+AT43+AV43+AX43 -> 32 | AR43: =SUM(AN43:AQ43) -> 0 | BA43: =+AR43+AS43+AU43+AW43+AY43+AZ43 -> 0
AD44: =+AM44+BA44 -> 10 | AE44: - Change Grade | AI44: 10 | AM44: =SUM(AF44:AL44)+AT44+AV44+AX44 -> 10 | AR44: =SUM(AN44:AQ44) -> 0 | BA44: =+AR44+AS44+AU44+AW44+AY44+AZ44 -> 0
A46: 45971 | B46: Napkin | C46: =(M46*E46*O46*Q46)/100000000 -> 55.393632 | D46: RC BR | E46: 17.5 | F46: 1 | G46: 830 | H46: 0.14 | I46: 0.88 | J46: =E46*G46*(1-H46)*1440/1000000*3.4 -> 61.158384 | K46: =(IF(G46<L46,L46,G46)*(1-IF(H46<N46,H46,N46))*E46*O46*Q46)/100000000 -> 57.470893 | L46: 800 | M46: 688 | N46: =1-(M46/L46) -> 0.14 | O46: =+'[2]Trim Rwd'!H31 -> 319.5 | P46: =O46*(Q46-R46-S46) -> 444105 | Q46: 1440 | R46: 0 | S46: 50 | T46: =E46*M46*O46*Q46/100000000 -> 55.393632 | U46: =E46*M46*O46*(Q46-R46-S46)/100000000 -> 53.470242 | V46: =E46*G46*(1-N46)*O46/100*(R46+S46)/1000000 -> 1.9955171 | W46: =+'[2]10'!K34/1000 -> 52.69 | X46: =SUM(W46:W49)/SUM(K46:K49) -> 0.91681192 | Y46: 0 | Z46: =+'[2]10'!D34/1000 -> 0.4 | AA46: =SUM(U46:U49)-SUM(W46:W49)-SUM(Z46:Z49)-SUM(Y46:Y49) -> 0.380242 | AB46: =(SUM(K46:K49)-SUM(W46:W49)-SUM(Y46:Y49)-SUM(Z46:Z49)-SUM(AC46:AC49)-SUM(V46:V49))-AA46 -> -0.072127125 | AC46: =K46-T46 -> 2.0772612 | AD46: =+AM46+BA46 -> 5 | AE46: - Sheet Breaks (2x) | AF46: 5 | AM46: =SUM(AF46:AL46)+AT46+AV46+AX46 -> 5 | AR46: =SUM(AN46:AQ46) -> 0 | BA46: =+AR46+AS46+AU46+AW46+AY46+AZ46 -> 0 | BB46: 2
AD47: =+AM47+BA47 -> 23 | AE47: - Change Blade (6x) | AG47: 23 | AM47: =SUM(AF47:AL47)+AT47+AV47+AX47 -> 23 | AR47: =SUM(AN47:AQ47) -> 0 | BA47: =+AR47+AS47+AU47+AW47+AY47+AZ47 -> 0 | BC47: 6
AD48: =+AM48+BA48 -> 22 | AE48: - Cleaning | AH48: 22 | AM48: =SUM(AF48:AL48)+AT48+AV48+AX48 -> 22 | AR48: =SUM(AN48:AQ48) -> 0 | BA48: =+AR48+AS48+AU48+AW48+AY48+AZ48 -> 0
A50: 45972 | B50: Napkin | C50: =(M50*E50*O50*Q50)/100000000 -> 55.393632 | D50: RC BR | E50: 17.5 | F50: 1 | G50: 830 | H50: 0.14 | I50: 0.88 | J50: =E50*G50*(1-H50)*1440/1000000*3.4 -> 61.158384 | K50: =(IF(G50<L50,L50,G50)*(1-IF(H50<N50,H50,N50))*E50*O50*Q50)/100000000 -> 57.470893 | L50: 800 | M50: 688 | N50: =1-(M50/L50) -> 0.14 | O50: =+'[2]Trim Rwd'!H33 -> 319.5 | P50: =O50*(Q50-R50-S50) -> 431325 | Q50: 1440 | R50: 30 | S50: 60 | T50: =E50*M50*O50*Q50/100000000 -> 55.393632 | U50: =E50*M50*O50*(Q50-R50-S50)/100000000 -> 51.93153 | V50: =E50*G50*(1-N50)*O50/100*(R50+S50)/1000000 -> 3.5919308 | W50: =+'[2]11'!K34/1000 -> 50.889 | X50: =SUM(W50:W53)/SUM(K50:K53) -> 0.88547432 | Y50: 0 | Z50: =+'[2]11'!D34/1000 -> 0.98 | AA50: =SUM(U50:U53)-SUM(W50:W53)-SUM(Z50:Z53)-SUM(Y50:Y53) -> 0.06253 | AB50: =(SUM(K50:K53)-SUM(W50:W53)-SUM(Y50:Y53)-SUM(Z50:Z53)-SUM(AC50:AC53)-SUM(V50:V53))-AA50 -> -0.12982883 | AC50: =K50-T50 -> 2.0772612 | AD50: =+AM50+BA50 -> 0 | AE50: - Sheet Breaks (0x) | AF50: 0 | AM50: =SUM(AF50:AL50)+AT50+AV50+AX50 -> 0 | AR50: =SUM(AN50:AQ50) -> 0 | BA50: =+AR50+AS50+AU50+AW50+AY50+AZ50 -> 0 | BB50: 0
AD51: =+AM51+BA51 -> 33 | AE51: - Change Blade (7x) | AG51: 33 | AM51: =SUM(AF51:AL51)+AT51+AV51+AX51 -> 33 | AR51: =SUM(AN51:AQ51) -> 0 | BA51: =+AR51+AS51+AU51+AW51+AY51+AZ51 -> 0 | BC51: 7
...

Sheet PM 14
A1: PM14 Efficiency Running Report
