Workbook

Sheet Jan
A1: PT SUN PAPER SOURCE
A2: LAPORAN PEMAKAIAN LISTRIK BULAN MEI 2024 | GA2: power trafo 2000 = trafo 2000 - wpl line | GP2: pulper WPL + WPL line = WPL total
A3: Tgl | B3: PLN 27.000 KVA | H3: CUBICLE INCOMING PLN | O3: PM-11 | BE3: BOILER | BH3: IPAL | BK3: UTILITTY | BQ3: 2.1 OFFICE | BU3: PM-12 | DH3: Total All Cubicle | DI3: FLOW STEAM PM12 | DQ3: Incoming Trafo Converting 1 & 2 | DS3: Incoming Trafo Converting 3 | DU3: PM 14 | EE3: PM 15 | EO3: PM 16 | FE3: PM 17 | FV3: DIP 2 | GH3: Pulper PM 16 17 | GN3: Pulper WPL | GQ3: WPL Line
O4: PM11 dari Trafo 3000 KVA | AK4: TRAFO 3000kva | AL4: Dari Trafo 4000kVA pm11 | BD4: TRAFO 4000kva | BE4: Dari Trafo 1600 KVA | BK4: 2.4 KOMPRESSOR | BM4: 2.2 SUMUR 1(BARAT) | BO4: 2.3 SUMUR 2(TIMUR) | BS4: 2.5 TIMBANGAN & | DU4: Panel no.3 | DX4: Panel no.1 | ED4: TOTAL PM 14 | EN4: TOTAL PM 15 | FK4: cubicle-mcc-drive-stock-converting3dibagi3 | FV4: bisa switch 2 power | FY4: bisa switch 2 power | GJ4: ( trafonya ikut trafo Pulper DIP2 )
B5: LWBP 1 | E5: WBP | G5: Total | H5: PLN PM11 | L5: PLN TOTAL | O5: 1. PANEL INCOMING 3200 A | S5: 1.1 PANEL VACUUM 1 | U5: 1.2 PANEL VACUUM 2 | W5: 1.3 PANEL MCC AUX 3200A | Y5: 1.3.1 GD JUMBO PM11 12 | AA5: 1.4 TURBO VACUUM | AC5: 4. WL II 1250A (Yankee,Popereel) | AG5: 5. WL II 3200A (Hood,F.Pump,FeltWire) | AL5: 2. PANEL MCC StockPrep | AP5: 3. PANEL StockPrep 2 | AT5: 3.1 SUMUR 4 | AV5: 3.2 GD SORTIR BARU | AX5: 6. PANEL REWINDER 1 (800A) | BA5: 7. PANEL REWINDER 2 (800A) | BS5: BALLPRESS | BU5: INCOMING 3,3 KV G30A | BY5: REWINDER | CC5: M. DDR 1 LF | CE5: M. DDR THICKLING | CG5: DEFLAKER | CI5: INCOMING 3200 A MCC | CM5: INCOMING 1250A HOOD | CQ5: INCOMING ABB PANEL DRIVE | CU5: INCOMING 3200A DIP PUMP | CY5: INCOMING 3200A DIP EQUIPMENT | DC5: Incoming cubicle 20 kv pm 12 | DG5: Converting | DU5: Trafo 2500(A) | DX5: Trafo 2500(B) | EA5: Trafo 3000(A) cw Pulper14 | EE5: Trafo 3000(Barat) cw Pulper15 | EH5: Trafo 3000(Timur) | EK5: Rewinder Tengah | EO5: MCC | ER5: DRIVE PANEL | EU5: AUX PANEL | EX5: STOCK | FB5: OUTGOING TRAVO PM 16 | FD5: TOTAL PM 16 | FE5: MCC | FH5: DRIVE PANEL | FK5: adjust selisih | FN5: STOCK | FQ5: CUBICLE PM 17 | FU5: TOTAL PM 17 | GC5: X | GU5: PLN-PM11-PM12-DIP1-office-boiler-Ipal-utility-convt1&2-conv1&2-convt3-PM14-PM15-DIP2-PM16-PM17-sinergy+sin
B6: Counter | D6: x 32000 | E6: Counter | F6: x 32000 | G6: LWBP+WBP | H6: KWH | I6: KVARH | J6: Daily | L6: KWH | M6: KVARH | N6: Daily | O6: KWH | P6: KVARH | Q6: Daily | R6: Cos Phi | S6: KWH | T6: Daily | U6: KWH | V6: Daily | W6: KWH | X6: Daily | Y6: KWH | Z6: Daily | AA6: KWH | AB6: Daily | AC6: KWH | AD6: KVARH | AE6: Daily KWH | AF6: Cos Phi | AG6: KWH | AH6: KVARH | AI6: Daily | AJ6: Cos Phi | AK6: DAILY | AL6: KWH | AM6: KVARH | AN6: Daily KWH | AO6: Cos Phi | AP6: KWH | AQ6: KVARH | AR6: Daily KWH | AT6: KWH | AU6: Daily KWH | AV6: KWH | AW6: Daily KWH | AX6: KWH | AY6: KVARH | AZ6: Daily KWH | BA6: KWH | BB6: KVARH | BC6: Daily KWH | BD6: DAILY | BE6: KWH | BF6: KVARH | BG6: Daily KWH | BH6: KWH | BI6: KVARH | BK6: KWH | BL6: Daily KWH | BM6: KWH | BN6: Daily KWH | BO6: KWH | BP6: Daily KWH | BQ6: KWH | BR6: Daily | BU6: KWH | BV6: KVARH | BW6: Daily | BX6: Cos Phi | BY6: KWH | BZ6: KVARH | CA6: Daily | CB6: Cos Phi | CC6: KWH | CD6: Daily | CE6: KWH | CF6: Daily | CG6: KWH | CH6: Daily | CI6: KWH | CJ6: KVARH | CK6: Daily KWH | CM6: KWH | CN6: KVARH | CO6: Daily | CQ6: KWH | CR6: KVARH | CS6: Daily KWH | CU6: KWH | CV6: KVARH | CW6: Daily KWH | CY6: KWH | CZ6: KVARH | DA6: Daily KWH | DC6: KWH | DD6: KVARH | DE6: Daily KWH | DG6: Daily KWH | DI6: FT 10 | DJ6: FT 11 | DK6: FT 12 | DL6: FT17(DIP) | DM6: Yankee | DN6: Cond. | DO6: Hood | DP6: Deinking | DQ6: KWH | DS6: KWH | DU6: KWH | DV6: KVARH | DX6: KWH | DY6: KVARH | EA6: KWH | EB6: KVARH | EE6: KWH | EF6: KVARH | EH6: KWH | EI6: KVARH | EK6: KWH | EL6: KVARH | EO6: KWH | EP6: KVARH | ER6: KWH | ES6: KVARH | EU6: KWH | EV6: KVARH | EX6: KWH | EY6: KVARH | FA6: Selisih | FB6: KWH | FE6: KWH | FF6: KVARH | FH6: KWH | FI6: KVARH | FN6: KWH | FO6: KVARH | FQ6: KWH | FR6: KVARH | FT6: Selisih | FV6: Trafo 3000 | FY6: Trafo 2000 | GB6: Trafo Pulper | GE6: Incoming Pulper | GH6: Pulper baru PM16 | GK6: Pulper PM17 | GU6: PLN selisih
A7: 1 | B7: 3149.45 | E7: 633.84 | K7: =IF(J7<=0,0,(J7/SQRT(J7^2+(I7-I6)^2))) -> 0 | L7: 8779300 | O7: 9008.1 | S7: 10911687 | U7: 1518125.2 | W7: 3032.7 | AA7: 315940 | AC7: 3248.1 | AG7: 7064.8 | AL7: 9224.2 | AP7: 6925.6 | AT7: 101794.83 | AV7: 383.12 | AX7: 433554.6 | BA7: 75411.392 | BE7: 1572.4 | BF7: 850.16 | BH7: 7577.9 | BI7: 4873.3 | BK7: 977430 | BM7: 775.01 | BO7: 563.99 | BQ7: 735.99 | BS7: 69162.24 | BU7: 1734800 | BY7: 245.79 | CC7: 404140 | CE7: 697300 | CG7: 46510 | CI7: 10271 | CM7: 2560.6 | CQ7: 2505.4 | CU7: 1678000 | CY7: 842240 | DE7: =IF((DC7-DC6)<=0,0,(DC7-DC6)) -> #VALUE! | DF7: =IF(DE7<=0,0,(DE7/SQRT(DE7^2+(DD7-DD6)^2))) -> #VALUE! | DG7: =(DE7)-DA7-CW7-CS7-CO7-CK7-BW7 -> #VALUE! | DQ7: 2233100 | DS7: 1374700 | DU7: 7367.4 | DV7: 4102 | DX7: 12231 | DY7: 8170.8 | EA7: 26979 | EB7: 19.346 | ED7: =DW7+DZ7+EC7 -> 0 | EE7: 42030 | EF7: 26.396 | EH7: 11677 | EI7: 1.5316 | EK7: 703.57 | EL7: 1012.8 | EO7: 11798 | EP7: 4106.4 | ER7: 7112.6 | ES7: 2874.4 | EU7: 2496.5 | EV7: 894.01 | EX7: 11883 | EY7: 1.2286 | FB7: 33354255 | FE7: 15841 | FF7: 5695.2 | FH7: 6548.8 | FN7: 15039 | FO7: 0.6381 | FQ7: 53165 | FR7: 12.603 | FV7: 1945200 | FW7: 633140 | FY7: 2676.8 | FZ7: 1.5058 | GB7: 719.94 | GC7: 794.88 | GE7: 8981 | GF7: 2.6102 | GH7: 1723.6 | GI7: 1449.6 | GK7: 1392.3 | GL7: 1086.2 | GN7: 150590 | GO7: 130800 | GQ7: 169800 | GR7: 171340
A8: =A7+1 -> 2 | B8: 3155.82 | C8: =IF((B8-B7)<=0,0,(B8-B7)) -> 6.37 | D8: =IF((B8-B7)*32000<=0,0,(B8-B7)*32000) -> 203840 | E8: 634.96 | F8: =IF((E8-E7)*32000<=0,0,(E8-E7)*32000) -> 35840 | G8: =D8+F8 -> 239680 | K8: =IF(J8<=0,0,(J8/SQRT(J8^2+(I8-I7)^2))) -> 0 | L8: 8803100 | N8: =IF((L8-L7)<=0,0,(L8-L7)*10) -> 238000 | O8: 9022.1 | Q8: =IF((O8-O7)<=0,0,(O8-O7))*1000 -> 14000 | R8: =IF(Q8<=0,0,(Q8/SQRT(Q8^2+(P8-P7)^2))) -> 1 | S8: 10911687 | T8: =IF((S8-S7)<=0,0,(S8-S7)) -> 0 | U8: 1518125.2 | V8: =IF((U8-U7)<=0,0,(U8-U7)) -> 0 | W8: 3039.8 | X8: =Q8-T8-V8-AB8 -> 8940 | Z8: =IF((Y8-Y7)<=0,0,(Y8-Y7)) -> 0 | AA8: 321000 | AB8: =IF((AA8-AA7)<=0,0,(AA8-AA7)) -> 5060 | AC8: 3255.8 | AE8: =IF((AC8-AC7)<=0,0,(AC8-AC7))*1000 -> 7700 | AF8: =IF(AE8<=0,0,(AE8/SQRT(AE8^2+(AD8-AD7)^2))) -> 1 | AG8: 7081.2 | AI8: =IF((AG8-AG7)<=0,0,(AG8-AG7))*1000+GX8 -> 16863.3 | AJ8: =IF(AI8<=0,0,(AI8/SQRT(AI8^2+(AH8-AH7)^2))) -> 1 | AK8: =T8+V8+X8+AE8+AI8 -> 33503.3 | AL8: 9236.4 | AN8: =IF((AL8-AL7)<=0,0,(AL8-AL7))*1000+GX8-BL8-BN8-BP8-BR8 -> 5913.3 | AO8: =IF(AN8<=0,0,(AN8/SQRT(AN8^2+(AM8-AM7)^2))) -> 1 | AP8: 6935.9 | AR8: =IF((AP8-AP7)<=0,0,(AP8-AP7))*1000 -> 10300 | AS8: =IF(AR8<=0,0,(AR8/SQRT(AR8^2+(AQ8-AQ7)^2))) -> 1 | AU8: =IF((AT8-AT7)<=0,0,(AT8-AT7)) -> 0 | AW8: =IF((AV8-AV7)<=0,0,(AV8-AV7)) -> 0 | AX8: 433969.84 | AZ8: =IF((AX8-AX7)<=0,0,(AX8-AX7)) -> 415.24 | BA8: 75957.352 | BC8: =IF((BA8-BA7)<=0,0,(BA8-BA7)) -> 545.96 | BD8: =AN8+AR8+AZ8+BC8 -> 17174.5 | BE8: 1574.5 | BF8: 851.47 | BG8: =IF((BE8-BE7)<=0,0,(BE8-BE7))*1000 -> 2100 | BH8: 7587.2 | BI8: 4879.4 | BJ8: =IF((BH8-BH7)<=0,0,(BH8-BH7))*1000 -> 9300 | BK8: 983110 | BL8: =IF((BK8-BK7)<=0,0,(BK8-BK7)) -> 5680 | BM8: 775.74 | BN8: =IF((BM8-BM7)<=0,0,BM8-BM7)*1000 -> 730 | BP8: =IF((BO8-BO7)<=0,0,(BO8-BO7))*1000 -> 0 | BQ8: 736.33 | BR8: =IF((BQ8-BQ7)<=0,0,(BQ8-BQ7))*1000 -> 340 | BS8: 69339.49 | BT8: =IF((BS8-BS7)<=0,0,(BS8-BS7)) -> 177.25 | BU8: 1744000 | BW8: =IF((BU8-BU7)<=0,0,(BU8-BU7)) -> 9200 | BX8: =IF(BW8<=0,0,(BW8/SQRT(BW8^2+(BV8-BV7)^2))) -> 1 | BY8: 246.48 | CA8: =IF((BY8-BY7)<=0,0,(BY8-BY7)*1000) -> 690 | CB8: =IF(CA8<=0,0,(CA8/SQRT(CA8^2+(BZ8-BZ7)^2))) -> 1 | CC8: 408070 | CD8: =IF((CC8-CC7)<=0,0,(CC8-CC7)) -> 3930 | CE8: 697300 | CF8: =IF((CE8-CE7)<=0,0,(CE8-CE7)) -> 0 | CG8: 46603 | CH8: =IF((CG8-CG7)<=0,0,(CG8-CG7)) -> 93 | CI8: 10289 | CK8: =IF((CI8-CI7)*1000<=0,0,(CI8-CI7)*1000)+GX8-CA8 -> 17773.3 | CL8: =IF(CK8<=0,0,(CK8/SQRT(CK8^2+(CJ8-CJ7)^2))) -> 1 | CM8: 2567.3 | CO8: =IF((CM8-CM7)<=0,0,(CM8-CM7))*1000+GX8 -> 7163.3 | CP8: =IF(CO8<=0,0,(CO8/SQRT(CO8^2+(CN8-CN7)^2))) -> 1 | CQ8: 2511.5 | CS8: =IF((CQ8-CQ7)<=0,0,(CQ8-CQ7))*1000+GX8 -> 6563.3 | CT8: =IF(CS8<=0,0,(CS8/SQRT(CS8^2+(CR8-CR7)^2))) -> 1 | CU8: 1689600 | CW8: =IF((CU8-CU7)<=0,0,(CU8-CU7)) -> 11600 | CX8: =IF(CW8<=0,0,(CW8/SQRT(CW8^2+(CV8-CV7)^2))) -> 1 | CY8: 851711 | DA8: =IF((CY8-CY7)<=0,0,(CY8-CY7)) -> 9471 | DB8: =IF(DA8<=0,0,(DA8/SQRT(DA8^2+(CZ8-CZ7)^2))) -> 1 | DE8: =IF((DC8-DC7)<=0,0,(DC8-DC7)) -> 0 | DF8: =IF(DE8<=0,0,(DE8/SQRT(DE8^2+(DD8-DD7)^2))) -> 0 | DG8: =(DE8)-DA8-CW8-CS8-CO8-CK8-BW8 -> -61770.9 | DH8: =DE8+BG8+AK8+N8 -> 273603.3 | DQ8: 2233100 | DR8: =IF((DQ8-DQ7)<=0,0,(DQ8-DQ7)) -> 0 | DS8: 1374700 | DT8: =IF((DS8-DS7)<=0,0,(DS8-DS7)) -> 0 | DU8: 7371.5 | DV8: 4104.5 | DW8: =IF((DU8-DU7)*1000<=0,0,(DU8-DU7)*1000) -> 4100 | DX8: 12238 | DY8: 8173.4 | DZ8: =IF((DX8-DX7)*1000<=0,0,(DX8-DX7)*1000)+GX8 -> 7463.3 | EA8: 27003 | EB8: 19.358 | EC8: =IF((EA8-EA7)*1000<=0,0,(EA8-EA7)*1000)+GX8+$EE$40 -> 26623.3 | ED8: =DW8+DZ8+EC8 -> 38186.6 | EE8: 42064 | EF8: 26.427 | EG8: =IF((EE8-EE7)*1000<=0,0,(EE8-EE7)*1000)+GX8+$EE$40 -> 36623.3 | EH8: 11687 | EI8: 1.5335 | EJ8: =IF((EH8-EH7)*1000<=0,0,(EH8-EH7)*1000)+GX8 -> 10463.3 | EK8: 704.3 | EL8: 1013.8 | EM8: =IF((EK8-EK7)<=0,0,(EK8-EK7))*1000 -> 730 | EN8: =EG8+EJ8+EM8 -> 47816.6 | EO8: 11807 | EP8: 4110 | EQ8: =IF((EO8-EO7)*1000<=0,0,(EO8-EO7)*1000)+GX8 -> 9463.3 | ER8: 7134.2 | ES8: 2883.5 | ET8: =IF((ER8-ER7)<=0,0,(ER8-ER7))*1000 -> 21600 | EU8: 2504.1 | EV8: 896.7 | EW8: =IF((EU8-EU7)<=0,0,(EU8-EU7))*1000+GX8 -> 8063.3 | EX8: 11895 | EY8: 1.2307 | EZ8: =IF((EX8-EX7)<=0,0,(EX8-EX7))*1000+GX8 -> 12463.3 | FA8: =FC8-EQ8-ET8-EW8-EZ8 -> -26003.9 | FB8: 33379841 | FC8: =IF((FB8-FB7)<=0,0,(FB8-FB7)) -> 25586 | FD8: =EQ8+ET8+EW8+EZ8+GJ8 -> 53289.9 | FE8: 15852 | FF8: 5698.7 | FG8: =IF((FE8-FE7)*1000<=0,0,(FE8-FE7)*1000)+FL8+GX8 -> 12063.3 | FH8: 6570 | FI8: 2.5258 | FJ8: =IF((FH8-FH7)<=0,0,(FH8-FH7))*1000+FL8+GX8 -> 22263.3 | FL8: 600 | FM8: =FT8/3 -> -463.3 | FN8: 15051 | FO8: 0.6399 | FP8: =IF((FN8-FN7)*1000<=0,0,(FN8-FN7)*1000)+FL8+GX8 -> 13063.3 | FQ8: 53211 | FR8: 12.616 | FS8: =IF((FQ8-FQ7)*1000<=0,0,(FQ8-FQ7)*1000) -> 46000 | FT8: =FS8-FG8-FJ8-FP8-DT8 -> -1389.9 | FU8: =FG8+FJ8+FP8+GM8 -> 48889.9 | FV8: 1946000 | FW8: 633650 | FX8: =IF((FV8-FV7)*1000<=0,0,(FV8-FV7)) -> 800 | FY8: 2678.4 | FZ8: 1.5061 | GA8: =IF((FY8-FY7)*1000<=0,0,((FY8-FY7)*1000)-1000) -> 600 | GB8: 720.18 | GC8: 795.29 | GD8: =IF((GB8-GB7)*1000<=0,0,(GB8-GB7)*1000) -> 240 | GE8: 8986.7 | GF8: 2.6122 | GG8: =IF((GE8-GE7)*1000<=0,0,(GE8-GE7)*1000)-GJ8-GM8 -> 2500 | GH8: 1725.3 | GI8: 1451.3 | GJ8: =IF((GH8-GH7)<=0,0,(GH8-GH7))*1000 -> 1700 | GK8: 1393.8 | GL8: 1086.8 | GM8: =IF((GK8-GK7)<=0,0,(GK8-GK7))*1000 -> 1500 | GN8: 152700 | GO8: 132870 | GP8: =IF((GN8-GN7)<=0,0,(GN8-GN7)+1000) -> 3110 | GQ8: 171320 | GR8: 173000 | GS8: =IF((GQ8-GQ7)<=0,0,(GQ8-GQ7)) -> 1520 | GU8: =DailyJan!B7-DailyJan!N7-DailyJan!V7-DailyJan!Y7-DailyJan!Z7-DailyJan!AA7-DailyJan!AB7-DailyJan!AC7-DailyJan!AD7-DailyJan!AE7-DailyJan!AK7-DailyJan!AO7-DailyJan!AS7-DailyJan!AY7-DailyJan!BD7+DailyJan!BS7-SUM(DailyJan!BM7:BQ7)-DailyJan!BR7-DailyJan!AF7-DailyJan!AG7 -> -0.052971416 | GV8: 6949.45 | GW8: =GV8/15 -> 463.29667 | GX8: 463.3 | HA8: 1968.9712 | HC8: 7640.8288 | HE8: 2660.353
A9: =A8+1 -> 3 | B9: 3162.15 | C9: =IF((B9-B8)<=0,0,(B9-B8)) -> 6.33 | D9: =IF((B9-B8)*32000<=0,0,(B9-B8)*32000) -> 202560 | E9: 636.18 | F9: =IF((E9-E8)*32000<=0,0,(E9-E8)*32000) -> 39040 | G9: =D9+F9 -> 241600 | K9: =IF(J9<=0,0,(J9/SQRT(J9^2+(I9-I8)^2))) -> 0 | L9: 8827100 | N9: =IF((L9-L8)<=0,0,(L9-L8)*10) -> 240000 | O9: 9034.8 | Q9: =IF((O9-O8)<=0,0,(O9-O8))*1000 -> 12700 | R9: =IF(Q9<=0,0,(Q9/SQRT(Q9^2+(P9-P8)^2))) -> 1 | S9: 10911687 | T9: =IF((S9-S8)<=0,0,(S9-S8)) -> 0 | U9: 1518125.2 | V9: =IF((U9-U8)<=0,0,(U9-U8)) -> 0 | W9: 3046.2 | X9: =Q9-T9-V9-AB9 -> 7820 | Z9: =IF((Y9-Y8)<=0,0,(Y9-Y8)) -> 0 | AA9: 325880 | AB9: =IF((AA9-AA8)<=0,0,(AA9-AA8)) -> 4880 | AC9: 3262.3 | AE9: =IF((AC9-AC8)<=0,0,(AC9-AC8))*1000 -> 6500 | AF9: =IF(AE9<=0,0,(AE9/SQRT(AE9^2+(AD9-AD8)^2))) -> 1 | AG9: 7096 | AI9: =IF((AG9-AG8)<=0,0,(AG9-AG8))*1000+GX9 -> 15042.7 | AJ9: =IF(AI9<=0,0,(AI9/SQRT(AI9^2+(AH9-AH8)^2))) -> 1 | AK9: =T9+V9+X9+AE9+AI9 -> 29362.7 | AL9: 9247.6 | AN9: =IF((AL9-AL8)<=0,0,(AL9-AL8))*1000+GX9-BL9-BN9-BP9-BR9 -> 4772.7 | AO9: =IF(AN9<=0,0,(AN9/SQRT(AN9^2+(AM9-AM8)^2))) -> 1 | AP9: 6944.6 | AR9: =IF((AP9-AP8)<=0,0,(AP9-AP8))*1000 -> 8700 | AS9: =IF(AR9<=0,0,(AR9/SQRT(AR9^2+(AQ9-AQ8)^2))) -> 1 | AU9: =IF((AT9-AT8)<=0,0,(AT9-AT8)) -> 0 | AW9: =IF((AV9-AV8)<=0,0,(AV9-AV8)) -> 0 | AX9: 434085.88 | AZ9: =IF((AX9-AX8)<=0,0,(AX9-AX8)) -> 116.04 | BA9: 76066.432 | BC9: =IF((BA9-BA8)<=0,0,(BA9-BA8)) -> 109.08 | BD9: =AN9+AR9+AZ9+BC9 -> 13697.82 | BE9: 1576.4 | BF9: 852.74 | BG9: =IF((BE9-BE8)<=0,0,(BE9-BE8))*1000 -> 1900 | BH9: 7596.6 | BI9: 4885.6 | BJ9: =IF((BH9-BH8)<=0,0,(BH9-BH8))*1000 -> 9400 | BK9: 988340 | BL9: =IF((BK9-BK8)<=0,0,(BK9-BK8)) -> 5230 | BM9: 776.42 | BN9: =IF((BM9-BM8)<=0,0,BM9-BM8)*1000 -> 680 | BP9: =IF((BO9-BO8)<=0,0,(BO9-BO8))*1000 -> 0 | BQ9: 737.09 | BR9: =IF((BQ9-BQ8)<=0,0,(BQ9-BQ8))*1000 -> 760 | BS9: 69513 | BT9: =IF((BS9-BS8)<=0,0,(BS9-BS8)) -> 173.51 | BU9: 1752800 | BW9: =IF((BU9-BU8)<=0,0,(BU9-BU8)) -> 8800 | BX9: =IF(BW9<=0,0,(BW9/SQRT(BW9^2+(BV9-BV8)^2))) -> 1 | BY9: 247.21 | CA9: =IF((BY9-BY8)<=0,0,(BY9-BY8)*1000) -> 730 | CB9: =IF(CA9<=0,0,(CA9/SQRT(CA9^2+(BZ9-BZ8)^2))) -> 1 | CC9: 411880 | CD9: =IF((CC9-CC8)<=0,0,(CC9-CC8)) -> 3810 | CE9: 697300 | CF9: =IF((CE9-CE8)<=0,0,(CE9-CE8)) -> 0 | CG9: 46603 | CH9: =IF((CG9-CG8)<=0,0,(CG9-CG8)) -> 0 | CI9: 10306 | CK9: =IF((CI9-CI8)*1000<=0,0,(CI9-CI8)*1000)+GX9-CA9 -> 16512.7 | CL9: =IF(CK9<=0,0,(CK9/SQRT(CK9^2+(CJ9-CJ8)^2))) -> 1 | CM9: 2573.6 | CO9: =IF((CM9-CM8)<=0,0,(CM9-CM8))*1000+GX9 -> 6542.7 | CP9: =IF(CO9<=0,0,(CO9/SQRT(CO9^2+(CN9-CN8)^2))) -> 1 | CQ9: 2517.6 | CS9: =IF((CQ9-CQ8)<=0,0,(CQ9-CQ8))*1000+GX9 -> 6342.7 | CT9: =IF(CS9<=0,0,(CS9/SQRT(CS9^2+(CR9-CR8)^2))) -> 1 | CU9: 1701600 | CW9: =IF((CU9-CU8)<=0,0,(CU9-CU8)) -> 12000 | CX9: =IF(CW9<=0,0,(CW9/SQRT(CW9^2+(CV9-CV8)^2))) -> 1 | CY9: 861880 | DA9: =IF((CY9-CY8)<=0,0,(CY9-CY8)) -> 10169 | DB9: =IF(DA9<=0,0,(DA9/SQRT(DA9^2+(CZ9-CZ8)^2))) -> 1 | DE9: =IF((DC9-DC8)<=0,0,(DC9-DC8)) -> 0 | DF9: =IF(DE9<=0,0,(DE9/SQRT(DE9^2+(DD9-DD8)^2))) -> 0 | DG9: =(DE9)-DA9-CW9-CS9-CO9-CK9-BW9 -> -60367.1 | DH9: =DE9+BG9+AK9+N9 -> 271262.7 | DQ9: 2243500 | DR9: =IF((DQ9-DQ8)<=0,0,(DQ9-DQ8)) -> 10400 | DS9: 1390400 | DT9: =IF((DS9-DS8)<=0,0,(DS9-DS8)) -> 15700 | DU9: 7375.4 | DV9: 4107 | DW9: =IF((DU9-DU8)*1000<=0,0,(DU9-DU8)*1000) -> 3900 | DX9: 12245 | DY9: 8176 | DZ9: =IF((DX9-DX8)*1000<=0,0,(DX9-DX8)*1000)+GX9 -> 7242.7 | EA9: 27026 | EB9: 19.37 | EC9: =IF((EA9-EA8)*1000<=0,0,(EA9-EA8)*1000)+GX9+$EE$40 -> 25402.7 | ED9: =DW9+DZ9+EC9 -> 36545.4 | EE9: 42098 | EF9: 26.458 | EG9: =IF((EE9-EE8)*1000<=0,0,(EE9-EE8)*1000)+GX9+$EE$40 -> 36402.7 | EH9: 11697 | EI9: 1.5355 | EJ9: =IF((EH9-EH8)*1000<=0,0,(EH9-EH8)*1000)+GX9 -> 10242.7 | EK9: 705.04 | EL9: 1014.8 | EM9: =IF((EK9-EK8)<=0,0,(EK9-EK8))*1000 -> 740 | EN9: =EG9+EJ9+EM9 -> 47385.4 | EO9: 11816 | EP9: 4113 | EQ9: =IF((EO9-EO8)*1000<=0,0,(EO9-EO8)*1000)+GX9 -> 9242.7 | ER9: 7149.2 | ES9: 2890.3 | ET9: =IF((ER9-ER8)<=0,0,(ER9-ER8))*1000 -> 15000 | EU9: 2511.8 | EV9: 899.41 | EW9: =IF((EU9-EU8)<=0,0,(EU9-EU8))*1000+GX9 -> 7942.7 | EX9: 11905 | EY9: 1.2326 | EZ9: =IF((EX9-EX8)<=0,0,(EX9-EX8))*1000+GX9 -> 10242.7 | FA9: =FC9-EQ9-ET9-EW9-EZ9 -> -21153.1 | FB9: 33401116 | FC9: =IF((FB9-FB8)<=0,0,(FB9-FB8)) -> 21275 | FD9: =EQ9+ET9+EW9+EZ9+GJ9 -> 44128.1 | FE9: 15862 | FF9: 5702.2 | FG9: =IF((FE9-FE8)*1000<=0,0,(FE9-FE8)*1000)+FL9+GX9 -> 10176.03 | FH9: 6590.5 | FI9: 2.5338 | FJ9: =IF((FH9-FH8)<=0,0,(FH9-FH8))*1000+FL9+GX9 -> 20676.03 | FL9: -66.67 | FM9: =FT9/3 -> -242.69667 | FN9: 15063 | FO9: 0.6414 | FP9: =IF((FN9-FN8)*1000<=0,0,(FN9-FN8)*1000)+FL9+GX9 -> 12176.03 | FQ9: 53269 | FR9: 12.633 | FS9: =IF((FQ9-FQ8)*1000<=0,0,(FQ9-FQ8)*1000) -> 58000 | FT9: =FS9-FG9-FJ9-FP9-DT9 -> -728.09 | FU9: =FG9+FJ9+FP9+GM9 -> 44428.09 | FV9: 1946800 | FW9: 634190 | FX9: =IF((FV9-FV8)*1000<=0,0,(FV9-FV8)) -> 800 | FY9: 2679.9 | FZ9: 1.5065 | GA9: =IF((FY9-FY8)*1000<=0,0,((FY9-FY8)*1000)-1000) -> 500 | GB9: 720.43 | GC9: 795.7 | GD9: =IF((GB9-GB8)*1000<=0,0,(GB9-GB8)*1000) -> 250 | GE9: 8991.8 | GF9: 2.6139 | GG9: =IF((GE9-GE8)*1000<=0,0,(GE9-GE8)*1000)-GJ9-GM9 -> 2000 | GH9: 1727 | GI9: 1453 | GJ9: =IF((GH9-GH8)<=0,0,(GH9-GH8))*1000 -> 1700 | GK9: 1395.2 | GL9: 1087.3 | GM9: =IF((GK9-GK8)<=0,0,(GK9-GK8))*1000 -> 1400 | GN9: 154270 | GO9: 134400 | GP9: =IF((GN9-GN8)<=0,0,(GN9-GN8)+1000) -> 2570 | GQ9: 172650 | GR9: 174590 | GS9: =IF((GQ9-GQ8)<=0,0,(GQ9-GQ8)) -> 1330 | GU9: =DailyJan!B8-DailyJan!N8-DailyJan!V8-DailyJan!Y8-DailyJan!Z8-DailyJan!AA8-DailyJan!AB8-DailyJan!AC8-DailyJan!AD8-DailyJan!AE8-DailyJan!AK8-DailyJan!AO8-DailyJan!AS8-DailyJan!AY8-DailyJan!BD8+DailyJan!BS8-SUM(DailyJan!BM8:BQ8)-DailyJan!BR8-DailyJan!AF8-DailyJan!AG8 -> 3135.037 | GV9: 3640.54 | GW9: =GV9/15 -> 242.70267 | GX9: 242.7 | HA9: 1984.744 | HC9: 4316.146 | HE9: 2660.353
A10: =A9+1 -> 4 | B10: 3167.64 | C10: =IF((B10-B9)<=0,0,(B10-B9)) -> 5.49 | D10: =IF((B10-B9)*32000<=0,0,(B10-B9)*32000) -> 175680 | E10: 637.37 | F10: =IF((E10-E9)*32000<=0,0,(E10-E9)*32000) -> 38080 | G10: =D10+F10 -> 213760 | K10: =IF(J10<=0,0,(J10/SQRT(J10^2+(I10-I9)^2))) -> 0 | L10: 8848300 | N10: =IF((L10-L9)<=0,0,(L10-L9)*10) -> 212000 | O10: 9048 | Q10: =IF((O10-O9)<=0,0,(O10-O9))*1000 -> 13200 | R10: =IF(Q10<=0,0,(Q10/SQRT(Q10^2+(P10-P9)^2))) -> 1 | S10: 10911687 | T10: =IF((S10-S9)<=0,0,(S10-S9)) -> 0 | U10: 1518125.2 | V10: =IF((U10-U9)<=0,0,(U10-U9)) -> 0 | W10: 3052.5 | X10: =Q10-T10-V10-AB10 -> 7990 | Z10: =IF((Y10-Y9)<=0,0,(Y10-Y9)) -> 0 | AA10: 331090 | AB10: =IF((AA10-AA9)<=0,0,(AA10-AA9)) -> 5210 | AC10: 3269.5 | AE10: =IF((AC10-AC9)<=0,0,(AC10-AC9))*1000 -> 7200 | AF10: =IF(AE10<=0,0,(AE10/SQRT(AE10^2+(AD10-AD9)^2))) -> 1 | AG10: 7112.1 | AI10: =IF((AG10-AG9)<=0,0,(AG10-AG9))*1000+GX10 -> 15475.81 | AJ10: =IF(AI10<=0,0,(AI10/SQRT(AI10^2+(AH10-AH9)^2))) -> 1 | AK10: =T10+V10+X10+AE10+AI10 -> 30665.81 | AL10: 9258.9 | AN10: =IF((AL10-AL9)<=0,0,(AL10-AL9))*1000+GX10-BL10-BN10-BP10-BR10 -> 4025.81 | AO10: =IF(AN10<=0,0,(AN10/SQRT(AN10^2+(AM10-AM9)^2))) -> 1 | AP10: 6954.6 | AR10: =IF((AP10-AP9)<=0,0,(AP10-AP9))*1000 -> 10000 | AS10: =IF(AR10<=0,0,(AR10/SQRT(AR10^2+(AQ10-AQ9)^2))) -> 1 | AU10: =IF((AT10-AT9)<=0,0,(AT10-AT9)) -> 0 | AW10: =IF((AV10-AV9)<=0,0,(AV10-AV9)) -> 0 | AX10: 434349.2 | AZ10: =IF((AX10-AX9)<=0,0,(AX10-AX9)) -> 263.32 | BA10: 76270.616 | BC10: =IF((BA10-BA9)<=0,0,(BA10-BA9)) -> 204.184 | BD10: =AN10+AR10+AZ10+BC10 -> 14493.314 | BE10: 1578.3 | BF10: 853.94 | BG10: =IF((BE10-BE9)<=0,0,(BE10-BE9))*1000 -> 1900 | BH10: 7605.8 | BI10: 4891.7 | BJ10: =IF((BH10-BH9)<=0,0,(BH10-BH9))*1000 -> 9200 | BK10: 993620 | BL10: =IF((BK10-BK9)<=0,0,(BK10-BK9)) -> 5280 | BM10: 777.1 | BN10: =IF((BM10-BM9)<=0,0,BM10-BM9)*1000 -> 680 | BP10: =IF((BO10-BO9)<=0,0,(BO10-BO9))*1000 -> 0 | BQ10: 737.78 | BR10: =IF((BQ10-BQ9)<=0,0,(BQ10-BQ9))*1000 -> 690 | BS10: 69705.89 | BT10: =IF((BS10-BS9)<=0,0,(BS10-BS9)) -> 192.89 | BU10: 1757200 | BW10: =IF((BU10-BU9)<=0,0,(BU10-BU9)) -> 4400 | BX10: =IF(BW10<=0,0,(BW10/SQRT(BW10^2+(BV10-BV9)^2))) -> 1 | BY10: 247.84 | CA10: =IF((BY10-BY9)<=0,0,(BY10-BY9)*1000) -> 630 | CB10: =IF(CA10<=0,0,(CA10/SQRT(CA10^2+(BZ10-BZ9)^2))) -> 1 | CC10: 412300 | CD10: =IF((CC10-CC9)<=0,0,(CC10-CC9)) -> 420 | CE10: 697300 | CF10: =IF((CE10-CE9)<=0,0,(CE10-CE9)) -> 0 | CG10: 46603 | CH10: =IF((CG10-CG9)<=0,0,(CG10-CG9)) -> 0 | CI10: 10322 | CK10: =IF((CI10-CI9)*1000<=0,0,(CI10-CI9)*1000)+GX10-CA10 -> 14745.81 | CL10: =IF(CK10<=0,0,(CK10/SQRT(CK10^2+(CJ10-CJ9)^2))) -> 1 | CM10: 2578.8 | CO10: =IF((CM10-CM9)<=0,0,(CM10-CM9))*1000+GX10 -> 4575.81 | CP10: =IF(CO10<=0,0,(CO10/SQRT(CO10^2+(CN10-CN9)^2))) -> 1 | CQ10: 2523 | CS10: =IF((CQ10-CQ9)<=0,0,(CQ10-CQ9))*1000+GX10 -> 4775.81 | CT10: =IF(CS10<=0,0,(CS10/SQRT(CS10^2+(CR10-CR9)^2))) -> 1 | CU10: 1715700 | CW10: =IF((CU10-CU9)<=0,0,(CU10-CU9)) -> 14100 | CX10: =IF(CW10<=0,0,(CW10/SQRT(CW10^2+(CV10-CV9)^2))) -> 1 | CY10: 872760 | DA10: =IF((CY10-CY9)<=0,0,(CY10-CY9)) -> 10880 | DB10: =IF(DA10<=0,0,(DA10/SQRT(DA10^2+(CZ10-CZ9)^2))) -> 1 | DE10: =IF((DC10-DC9)<=0,0,(DC10-DC9)) -> 0 | DF10: =IF(DE10<=0,0,(DE10/SQRT(DE10^2+(DD10-DD9)^2))) -> 0 | DG10: =(DE10)-DA10-CW10-CS10-CO10-CK10-BW10 -> -53477.43 | DH10: =DE10+BG10+AK10+N10 -> 244565.81 | DQ10: 2253900 | DR10: =IF((DQ10-DQ9)<=0,0,(DQ10-DQ9)) -> 10400 | DS10: 1405700 | DT10: =IF((DS10-DS9)<=0,0,(DS10-DS9)) -> 15300 | DU10: 7379.7 | DV10: 4109.7 | DW10: =IF((DU10-DU9)*1000<=0,0,(DU10-DU9)*1000) -> 4300 | DX10: 12253 | DY10: 8178.6 | DZ10: =IF((DX10-DX9)*1000<=0,0,(DX10-DX9)*1000)+GX10 -> 7375.81 | EA10: 27051 | EB10: 19.382 | EC10: =IF((EA10-EA9)*1000<=0,0,(EA10-EA9)*1000)+GX10+$EE$40 -> 26535.81 | ED10: =DW10+DZ10+EC10 -> 38211.62 | EE10: 42133 | EF10: 26.489 | EG10: =IF((EE10-EE9)*1000<=0,0,(EE10-EE9)*1000)+GX10+$EE$40 -> 36535.81 | EH10: 11707 | EI10: 1.5371 | EJ10: =IF((EH10-EH9)*1000<=0,0,(EH10-EH9)*1000)+GX10 -> 9375.81 | EK10: 705.79 | EL10: 1015.8 | EM10: =IF((EK10-EK9)<=0,0,(EK10-EK9))*1000 -> 750 | EN10: =EG10+EJ10+EM10 -> 46661.62 | EO10: 11825 | EP10: 4116.6 | EQ10: =IF((EO10-EO9)*1000<=0,0,(EO10-EO9)*1000)+GX10 -> 8375.81 | ER10: 7160.7 | ES10: 2896.1 | ET10: =IF((ER10-ER9)<=0,0,(ER10-ER9))*1000 -> 11500 | EU10: 2521.1 | EV10: 902.67 | EW10: =IF((EU10-EU9)<=0,0,(EU10-EU9))*1000+GX10 -> 8675.81 | EX10: 11916 | EY10: 1.234 | EZ10: =IF((EX10-EX9)<=0,0,(EX10-EX9))*1000+GX10 -> 10375.81 | FA10: =FC10-EQ10-ET10-EW10-EZ10 -> -17790.43 | FB10: 33422253 | FC10: =IF((FB10-FB9)<=0,0,(FB10-FB9)) -> 21137 | FD10: =EQ10+ET10+EW10+EZ10+GJ10 -> 41027.43 | FE10: 15868 | FF10: 5704.9 | FG10: =IF((FE10-FE9)*1000<=0,0,(FE10-FE9)*1000)+FL10+GX10 -> 5809.14 | FH10: 6598.9 | FI10: 2.5375 | FJ10: =IF((FH10-FH9)<=0,0,(FH10-FH9))*1000+FL10+GX10 -> 8209.14 | FL10: 433.33 | FM10: =FT10/3 -> 624.19333 | FN10: 15071 | FO10: 0.6425 | FP10: =IF((FN10-FN9)*1000<=0,0,(FN10-FN9)*1000)+FL10+GX10 -> 7809.14 | FQ10: 53308 | FR10: 12.646 | FS10: =IF((FQ10-FQ9)*1000<=0,0,(FQ10-FQ9)*1000) -> 39000 | FT10: =FS10-FG10-FJ10-FP10-DT10 -> 1872.58 | FU10: =FG10+FJ10+FP10+GM10 -> 22527.42 | FV10: 1947500 | FW10: 634720 | FX10: =IF((FV10-FV9)*1000<=0,0,(FV10-FV9)) -> 700 | FY10: 2681.5 | FZ10: 1.5069 | GA10: =IF((FY10-FY9)*1000<=0,0,((FY10-FY9)*1000)-1000) -> 600 | GB10: 720.7 | GC10: 796.14 | GD10: =IF((GB10-GB9)*1000<=0,0,(GB10-GB9)*1000) -> 270 | GE10: 8996.2 | GF10: 2.6155 | GG10: =IF((GE10-GE9)*1000<=0,0,(GE10-GE9)*1000)-GJ10-GM10 -> 1600 | GH10: 1729.1 | GI10: 1455.1 | GJ10: =IF((GH10-GH9)<=0,0,(GH10-GH9))*1000 -> 2100 | GK10: 1395.9 | GL10: 1087.6 | GM10: =IF((GK10-GK9)<=0,0,(GK10-GK9))*1000 -> 700 | GN10: 155510 | GO10: 135580 | GP10: =IF((GN10-GN9)<=0,0,(GN10-GN9)+1000) -> 2240 | GQ10: 174100 | GR10: 176340 | GS10: =IF((GQ10-GQ9)<=0,0,(GQ10-GQ9)) -> 1450 | GU10: =DailyJan!B9-DailyJan!N9-DailyJan!V9-DailyJan!Y9-DailyJan!Z9-DailyJan!AA9-DailyJan!AB9-DailyJan!AC9-DailyJan!AD9-DailyJan!AE9-DailyJan!AK9-DailyJan!AO9-DailyJan!AS9-DailyJan!AY9-DailyJan!BD9+DailyJan!BS9-SUM(DailyJan!BM9:BQ9)-DailyJan!BR9-DailyJan!AF9-DailyJan!AG9 -> 3135.003 | GV10: -9362.85 | GW10: =GV10/15 -> -624.19 | GX10: -624.19 | HA10: 1756.0384 | HC10: -8458.5284 | HE10: 2660.353
A11: =A10+1 -> 5 | B11: 3173.52 | C11: =IF((B11-B10)<=0,0,(B11-B10)) -> 5.88 | D11: =IF((B11-B10)*32000<=0,0,(B11-B10)*32000) -> 188160 | E11: 638.58 | F11: =IF((E11-E10)*32000<=0,0,(E11-E10)*32000) -> 38720 | G11: =D11+F11 -> 226880 | K11: =IF(J11<=0,0,(J11/SQRT(J11^2+(I11-I10)^2))) -> 0 | L11: 8870900 | N11: =IF((L11-L10)<=0,0,(L11-L10)*10) -> 226000 | O11: 9053.9 | Q11: =IF((O11-O10)<=0,0,(O11-O10))*1000 -> 5900 | R11: =IF(Q11<=0,0,(Q11/SQRT(Q11^2+(P11-P10)^2))) -> 1 | S11: 10911687 | T11: =IF((S11-S10)<=0,0,(S11-S10)) -> 0 | U11: 1518125.2 | V11: =IF((U11-U10)<=0,0,(U11-U10)) -> 0 | W11: 3055.7 | X11: =Q11-T11-V11-AB11 -> 3790 | Z11: =IF((Y11-Y10)<=0,0,(Y11-Y10)) -> 0 | AA11: 333200 | AB11: =IF((AA11-AA10)<=0,0,(AA11-AA10)) -> 2110 | AC11: 3272 | AE11: =IF((AC11-AC10)<=0,0,(AC11-AC10))*1000 -> 2500 | AF11: =IF(AE11<=0,0,(AE11/SQRT(AE11^2+(AD11-AD10)^2))) -> 1 | AG11: 7117.4 | AI11: =IF((AG11-AG10)<=0,0,(AG11-AG10))*1000+GX11 -> 5909.59 | AJ11: =IF(AI11<=0,0,(AI11/SQRT(AI11^2+(AH11-AH10)^2))) -> 1 | AK11: =T11+V11+X11+AE11+AI11 -> 12199.59 | AL11: 9268.1 | AN11: =IF((AL11-AL10)<=0,0,(AL11-AL10))*1000+GX11-BL11-BN11-BP11-BR11 -> 3329.59 | AO11: =IF(AN11<=0,0,(AN11/SQRT(AN11^2+(AM11-AM10)^2))) -> 1 | AP11: 6959.2 | AR11: =IF((AP11-AP10)<=0,0,(AP11-AP10))*1000 -> 4600 | AS11: =IF(AR11<=0,0,(AR11/SQRT(AR11^2+(AQ11-AQ10)^2))) -> 1 | AU11: =IF((AT11-AT10)<=0,0,(AT11-AT10)) -> 0 | AW11: =IF((AV11-AV10)<=0,0,(AV11-AV10)) -> 0 | AX11: 434532.48 | AZ11: =IF((AX11-AX10)<=0,0,(AX11-AX10)) -> 183.28 | BA11: 76498.16 | BC11: =IF((BA11-BA10)<=0,0,(BA11-BA10)) -> 227.544 | BD11: =AN11+AR11+AZ11+BC11 -> 8340.414 | BE11: 1580.2 | BF11: 855.12 | BG11: =IF((BE11-BE10)<=0,0,(BE11-BE10))*1000 -> 1900 | BH11: 7615.2 | BI11: 4897.8 | BJ11: =IF((BH11-BH10)<=0,0,(BH11-BH10))*1000 -> 9400 | BK11: 998850 | BL11: =IF((BK11-BK10)<=0,0,(BK11-BK10)) -> 5230 | BM11: 777.82 | BN11: =IF((BM11-BM10)<=0,0,BM11-BM10)*1000 -> 720 | BP11: =IF((BO11-BO10)<=0,0,(BO11-BO10))*1000 -> 0 | BQ11: 738.31 | BR11: =IF((BQ11-BQ10)<=0,0,(BQ11-BQ10))*1000 -> 530 | BS11: 69893.89 | BT11: =IF((BS11-BS10)<=0,0,(BS11-BS10)) -> 188 | BU11: 1761400 | BW11: =IF((BU11-BU10)<=0,0,(BU11-BU10)) -> 4200 | BX11: =IF(BW11<=0,0,(BW11/SQRT(BW11^2+(BV11-BV10)^2))) -> 1 | BY11: 248.53 | CA11: =IF((BY11-BY10)<=0,0,(BY11-BY10)*1000) -> 690 | CB11: =IF(CA11<=0,0,(CA11/SQRT(CA11^2+(BZ11-BZ10)^2))) -> 1 | CC11: 412300 | CD11: =IF((CC11-CC10)<=0,0,(CC11-CC10)) -> 0 | CE11: 697300 | CF11: =IF((CE11-CE10)<=0,0,(CE11-CE10)) -> 0 | CG11: 46603 | CH11: =IF((CG11-CG10)<=0,0,(CG11-CG10)) -> 0 | CI11: 10338 | CK11: =IF((CI11-CI10)*1000<=0,0,(CI11-CI10)*1000)+GX11-CA11 -> 15919.59 | CL11: =IF(CK11<=0,0,(CK11/SQRT(CK11^2+(CJ11-CJ10)^2))) -> 1 | CM11: 2584.9 | CO11: =IF((CM11-CM10)<=0,0,(CM11-CM10))*1000+GX11 -> 6709.59 | CP11: =IF(CO11<=0,0,(CO11/SQRT(CO11^2+(CN11-CN10)^2))) -> 1 | CQ11: 2528.8 | CS11: =IF((CQ11-CQ10)<=0,0,(CQ11-CQ10))*1000+GX11 -> 6409.59 | CT11: =IF(CS11<=0,0,(CS11/SQRT(CS11^2+(CR11-CR10)^2))) -> 1 | CU11: 1732100 | CW11: =IF((CU11-CU10)<=0,0,(CU11-CU10)) -> 16400 | CX11: =IF(CW11<=0,0,(CW11/SQRT(CW11^2+(CV11-CV10)^2))) -> 1 | CY11: 884650 | DA11: =IF((CY11-CY10)<=0,0,(CY11-CY10)) -> 11890 | DB11: =IF(DA11<=0,0,(DA11/SQRT(DA11^2+(CZ11-CZ10)^2))) -> 1 | DE11: =IF((DC11-DC10)<=0,0,(DC11-DC10)) -> 0 | DF11: =IF(DE11<=0,0,(DE11/SQRT(DE11^2+(DD11-DD10)^2))) -> 0 | DG11: =(DE11)-DA11-CW11-CS11-CO11-CK11-BW11 -> -61528.77 | DH11: =DE11+BG11+AK11+N11 -> 240099.59 | DQ11: 2264100 | DR11: =IF((DQ11-DQ10)<=0,0,(DQ11-DQ10)) -> 10200 | DS11: 1421700 | DT11: =IF((DS11-DS10)<=0,0,(DS11-DS10)) -> 16000 | DU11: 7384 | DV11: 4112.5 | DW11: =IF((DU11-DU10)*1000<=0,0,(DU11-DU10)*1000) -> 4300 | DX11: 12260 | DY11: 8181.1 | DZ11: =IF((DX11-DX10)*1000<=0,0,(DX11-DX10)*1000)+GX11 -> 7609.59 | EA11: 27073 | EB11: 19.393 | EC11: =IF((EA11-EA10)*1000<=0,0,(EA11-EA10)*1000)+GX11+$EE$40 -> 24769.59 | ED11: =DW11+DZ11+EC11 -> 36679.18 | EE11: 42164 | EF11: 26.519 | EG11: =IF((EE11-EE10)*1000<=0,0,(EE11-EE10)*1000)+GX11+$EE$40 -> 33769.59 | EH11: 11718 | EI11: 1.5401 | EJ11: =IF((EH11-EH10)*1000<=0,0,(EH11-EH10)*1000)+GX11 -> 11609.59 | EK11: 706.46 | EL11: 1016.7 | EM11: =IF((EK11-EK10)<=0,0,(EK11-EK10))*1000 -> 670 | EN11: =EG11+EJ11+EM11 -> 46049.18 | EO11: 11834 | EP11: 4120 | EQ11: =IF((EO11-EO10)*1000<=0,0,(EO11-EO10)*1000)+GX11 -> 9609.59 | ER11: 7178.6 | ES11: 2903.8 | ET11: =IF((ER11-ER10)<=0,0,(ER11-ER10))*1000 -> 17900 | EU11: 2529.8 | EV11: 905.63 | EW11: =IF((EU11-EU10)<=0,0,(EU11-EU10))*1000+GX11 -> 9309.59 | EX11: 11928 | EY11: 1.2361 | EZ11: =IF((EX11-EX10)<=0,0,(EX11-EX10))*1000+GX11 -> 12609.59 | FA11: =FC11-EQ11-ET11-EW11-EZ11 -> -25368.77 | FB11: 33446313 | FC11: =IF((FB11-FB10)<=0,0,(FB11-FB10)) -> 24060 | FD11: =EQ11+ET11+EW11+EZ11+GJ11 -> 51228.77 | FE11: 15875 | FF11: 5708.3 | FG11: =IF((FE11-FE10)*1000<=0,0,(FE11-FE10)*1000)+FL11+GX11 -> 7542.92 | FH11: 6615.1 | FI11: 2.5441 | FJ11: =IF((FH11-FH10)<=0,0,(FH11-FH10))*1000+FL11+GX11 -> 16742.92 | FL11: -66.67 | FM11: =FT11/3 -> -609.58667 | FN11: 15082 | FO11: 0.6436 | FP11: =IF((FN11-FN10)*1000<=0,0,(FN11-FN10)*1000)+FL11+GX11 -> 11542.92 | FQ11: 53358 | FR11: 12.662 | FS11: =IF((FQ11-FQ10)*1000<=0,0,(FQ11-FQ10)*1000) -> 50000 | FT11: =FS11-FG11-FJ11-FP11-DT11 -> -1828.76 | FU11: =FG11+FJ11+FP11+GM11 -> 37028.76 | FV11: 1955100 | FW11: 637320 | FX11: =IF((FV11-FV10)*1000<=0,0,(FV11-FV10)) -> 7600 | FY11: 2683.6 | FZ11: 1.5074 | GA11: =IF((FY11-FY10)*1000<=0,0,((FY11-FY10)*1000)-1000) -> 1100 | GB11: 721.13 | GC11: 796.74 | GD11: =IF((GB11-GB10)*1000<=0,0,(GB11-GB10)*1000) -> 430 | GE11: 9004.5 | GF11: 2.618 | GG11: =IF((GE11-GE10)*1000<=0,0,(GE11-GE10)*1000)-GJ11-GM11 -> 5300 | GH11: 1730.9 | GI11: 1456.9 | GJ11: =IF((GH11-GH10)<=0,0,(GH11-GH10))*1000 -> 1800 | GK11: 1397.1 | GL11: 1088 | GM11: =IF((GK11-GK10)<=0,0,(GK11-GK10))*1000 -> 1200 | GN11: 157490 | GO11: 137350 | GP11: =IF((GN11-GN10)<=0,0,(GN11-GN10)+1000) -> 2980 | GQ11: 175570 | GR11: 177970 | GS11: =IF((GQ11-GQ10)<=0,0,(GQ11-GQ10)) -> 1470 | GU11: =DailyJan!B10-DailyJan!N10-DailyJan!V10-DailyJan!Y10-DailyJan!Z10-DailyJan!AA10-DailyJan!AB10-DailyJan!AC10-DailyJan!AD10-DailyJan!AE10-DailyJan!AK10-DailyJan!AO10-DailyJan!AS10-DailyJan!AY10-DailyJan!BD10+DailyJan!BS10-SUM(DailyJan!BM10:BQ10)-DailyJan!BR10-DailyJan!AF10-DailyJan!AG10 -> 3134.983 | GV11: 9143.83 | GW11: =GV11/15 -> 609.58867 | GX11: 609.59 | HA11: 1863.8192 | HC11: 9940.3708 | HE11: 2660.353
A12: =A11+1 -> 6 | B12: 3180.23 | C12: =IF((B12-B11)<=0,0,(B12-B11)) -> 6.71 | D12: =IF((B12-B11)*32000<=0,0,(B12-B11)*32000) -> 214720 | E12: 639.99 | F12: =IF((E12-E11)*32000<=0,0,(E12-E11)*32000) -> 45120 | G12: =D12+F12 -> 259840 | K12: =IF(J12<=0,0,(J12/SQRT(J12^2+(I12-I11)^2))) -> 0 | L12: 8896700 | N12: =IF((L12-L11)<=0,0,(L12-L11)*10) -> 258000 | O12: 9066.9 | Q12: =IF((O12-O11)<=0,0,(O12-O11))*1000 -> 13000 | R12: =IF(Q12<=0,0,(Q12/SQRT(Q12^2+(P12-P11)^2))) -> 1 | S12: 10911687 | T12: =IF((S12-S11)<=0,0,(S12-S11)) -> 0 | U12: 1518125.2 | V12: =IF((U12-U11)<=0,0,(U12-U11)) -> 0 | W12: 3062.1 | X12: =Q12-T12-V12-AB12 -> 8000 | Z12: =IF((Y12-Y11)<=0,0,(Y12-Y11)) -> 0 | AA12: 338200 | AB12: =IF((AA12-AA11)<=0,0,(AA12-AA11)) -> 5000 | AC12: 3279.3 | AE12: =IF((AC12-AC11)<=0,0,(AC12-AC11))*1000 -> 7300 | AF12: =IF(AE12<=0,0,(AE12/SQRT(AE12^2+(AD12-AD11)^2))) -> 1 | AG12: 7131.9 | AI12: =IF((AG12-AG11)<=0,0,(AG12-AG11))*1000+GX12 -> 14547.62 | AJ12: =IF(AI12<=0,0,(AI12/SQRT(AI12^2+(AH12-AH11)^2))) -> 1 | AK12: =T12+V12+X12+AE12+AI12 -> 29847.62 | AL12: 9279.4 | AN12: =IF((AL12-AL11)<=0,0,(AL12-AL11))*1000+GX12-BL12-BN12-BP12-BR12 -> 5147.62 | AO12: =IF(AN12<=0,0,(AN12/SQRT(AN12^2+(AM12-AM11)^2))) -> 1 | AP12: 6969.3 | AR12: =IF((AP12-AP11)<=0,0,(AP12-AP11))*1000 -> 10100 | AS12: =IF(AR12<=0,0,(AR12/SQRT(AR12^2+(AQ12-AQ11)^2))) -> 1 | AU12: =IF((AT12-AT11)<=0,0,(AT12-AT11)) -> 0 | AW12: =IF((AV12-AV11)<=0,0,(AV12-AV11)) -> 0 | AX12: 434938.76 | AZ12: =IF((AX12-AX11)<=0,0,(AX12-AX11)) -> 406.28 | BA12: 77052.304 | BC12: =IF((BA12-BA11)<=0,0,(BA12-BA11)) -> 554.144 | BD12: =AN12+AR12+AZ12+BC12 -> 16208.044 | BE12: 1581.8 | BF12: 856.22 | BG12: =IF((BE12-BE11)<=0,0,(BE12-BE11))*1000 -> 1600 | BH12: 7624.6 | BI12: 4904 | BJ12: =IF((BH12-BH11)<=0,0,(BH12-BH11))*1000 -> 9400 | BK12: 1004100 | BL12: =IF((BK12-BK11)<=0,0,(BK12-BK11)) -> 5250 | BM12: 778.51 | BN12: =IF((BM12-BM11)<=0,0,BM12-BM11)*1000 -> 690 | BP12: =IF((BO12-BO11)<=0,0,(BO12-BO11))*1000 -> 0 | BQ12: 738.57 | BR12: =IF((BQ12-BQ11)<=0,0,(BQ12-BQ11))*1000 -> 260 | BS12: 70079.14 | BT12: =IF((BS12-BS11)<=0,0,(BS12-BS11)) -> 185.25 | BU12: 1767600 | BW12: =IF((BU12-BU11)<=0,0,(BU12-BU11)) -> 6200 | BX12: =IF(BW12<=0,0,(BW12/SQRT(BW12^2+(BV12-BV11)^2))) -> 1 | BY12: 249.21 | CA12: =IF((BY12-BY11)<=0,0,(BY12-BY11)*1000) -> 680 | CB12: =IF(CA12<=0,0,(CA12/SQRT(CA12^2+(BZ12-BZ11)^2))) -> 1 | CC12: 413980 | CD12: =IF((CC12-CC11)<=0,0,(CC12-CC11)) -> 1680 | CE12: 697300 | CF12: =IF((CE12-CE11)<=0,0,(CE12-CE11)) -> 0 | CG12: 46603 | CH12: =IF((CG12-CG11)<=0,0,(CG12-CG11)) -> 0 | CI12: 10355 | CK12: =IF((CI12-CI11)*1000<=0,0,(CI12-CI11)*1000)+GX12-CA12 -> 16367.62 | CL12: =IF(CK12<=0,0,(CK12/SQRT(CK12^2+(CJ12-CJ11)^2))) -> 1 | CM12: 2592.8 | CO12: =IF((CM12-CM11)<=0,0,(CM12-CM11))*1000+GX12 -> 7947.62 | CP12: =IF(CO12<=0,0,(CO12/SQRT(CO12^2+(CN12-CN11)^2))) -> 1 | CQ12: 2534.9 | CS12: =IF((CQ12-CQ11)<=0,0,(CQ12-CQ11))*1000+GX12 -> 6147.62 | CT12: =IF(CS12<=0,0,(CS12/SQRT(CS12^2+(CR12-CR11)^2))) -> 1 | CU12: 1745200 | CW12: =IF((CU12-CU11)<=0,0,(CU12-CU11)) -> 13100 | CX12: =IF(CW12<=0,0,(CW12/SQRT(CW12^2+(CV12-CV11)^2))) -> 1 | CY12: 894480 | DA12: =IF((CY12-CY11)<=0,0,(CY12-CY11)) -> 9830 | DB12: =IF(DA12<=0,0,(DA12/SQRT(DA12^2+(CZ12-CZ11)^2))) -> 1 | DE12: =IF((DC12-DC11)<=0,0,(DC12-DC11)) -> 0 | DF12: =IF(DE12<=0,0,(DE12/SQRT(DE12^2+(DD12-DD11)^2))) -> 0 | DG12: =(DE12)-DA12-CW12-CS12-CO12-CK12-BW12 -> -59592.86 | DH12: =DE12+BG12+AK12+N12 -> 289447.62 | DQ12: 2274000 | DR12: =IF((DQ12-DQ11)<=0,0,(DQ12-DQ11)) -> 9900 | DS12: 1438500 | DT12: =IF((DS12-DS11)<=0,0,(DS12-DS11)) -> 16800 | DU12: 7388 | DV12: 4114.9 | DW12: =IF((DU12-DU11)*1000<=0,0,(DU12-DU11)*1000) -> 4000 | DX12: 12267 | DY12: 8183.7 | DZ12: =IF((DX12-DX11)*1000<=0,0,(DX12-DX11)*1000)+GX12 -> 7047.62 | EA12: 27097 | EB12: 19.405 | EC12: =IF((EA12-EA11)*1000<=0,0,(EA12-EA11)*1000)+GX12+$EE$40 -> 26207.62 | ED12: =DW12+DZ12+EC12 -> 37255.24 | EE12: 42199 | EF12: 26.55 | EG12: =IF((EE12-EE11)*1000<=0,0,(EE12-EE11)*1000)+GX12+$EE$40 -> 37207.62 | EH12: 11731 | EI12: 1.5439 | EJ12: =IF((EH12-EH11)*1000<=0,0,(EH12-EH11)*1000)+GX12 -> 13047.62 | EK12: 707.12 | EL12: 1017.6 | EM12: =IF((EK12-EK11)<=0,0,(EK12-EK11))*1000 -> 660 | EN12: =EG12+EJ12+EM12 -> 50915.24 | EO12: 11843 | EP12: 4123.4 | EQ12: =IF((EO12-EO11)*1000<=0,0,(EO12-EO11)*1000)+GX12 -> 9047.62 | ER12: 7198.2 | ES12: 2912.1 | ET12: =IF((ER12-ER11)<=0,0,(ER12-ER11))*1000 -> 19600 | EU12: 2538.9 | EV12: 908.75 | EW12: =IF((EU12-EU11)<=0,0,(EU12-EU11))*1000+GX12 -> 9147.62 | EX12: 11941 | EY12: 1.2386 | EZ12: =IF((EX12-EX11)<=0,0,(EX12-EX11))*1000+GX12 -> 13047.62 | FA12: =FC12-EQ12-ET12-EW12-EZ12 -> -25076.86 | FB12: 33472079 | FC12: =IF((FB12-FB11)<=0,0,(FB12-FB11)) -> 25766 | FD12: =EQ12+ET12+EW12+EZ12+GJ12 -> 52542.86 | FE12: 15882 | FF12: 5711.6 | FG12: =IF((FE12-FE11)*1000<=0,0,(FE12-FE11)*1000)+FL12+GX12 -> 7280.95 | FH12: 6634.6 | FI12: 2.5518 | FJ12: =IF((FH12-FH11)<=0,0,(FH12-FH11))*1000+FL12+GX12 -> 19780.95 | FL12: 233.33 | FM12: =FT12/3 -> -47.616667 | FN12: 15094 | FO12: 0.6451 | FP12: =IF((FN12-FN11)*1000<=0,0,(FN12-FN11)*1000)+FL12+GX12 -> 12280.95 | FQ12: 53414 | FR12: 12.679 | FS12: =IF((FQ12-FQ11)*1000<=0,0,(FQ12-FQ11)*1000) -> 56000 | FT12: =FS12-FG12-FJ12-FP12-DT12 -> -142.85 | FU12: =FG12+FJ12+FP12+GM12 -> 40542.85 | FV12: 1964000 | FW12: 640170 | FX12: =IF((FV12-FV11)*1000<=0,0,(FV12-FV11)) -> 8900 | FY12: 2685.9 | FZ12: 1.5078 | GA12: =IF((FY12-FY11)*1000<=0,0,((FY12-FY11)*1000)-GS12) -> 930 | GB12: 721.58 | GC12: 797.36 | GD12: =IF((GB12-GB11)*1000<=0,0,(GB12-GB11)*1000) -> 450 | GE12: 9012 | GF12: 2.6203 | GG12: =IF((GE12-GE11)*1000<=0,0,(GE12-GE11)*1000)-GJ12-GM12 -> 4600 | GH12: 1732.6 | GI12: 1458.5 | GJ12: =IF((GH12-GH11)<=0,0,(GH12-GH11))*1000 -> 1700 | GK12: 1398.3 | GL12: 1088.5 | GM12: =IF((GK12-GK11)<=0,0,(GK12-GK11))*1000 -> 1200 | GN12: 158770 | GO12: 138490 | GP12: =IF((GN12-GN11)<=0,0,(GN12-GN11)) -> 1280 | GQ12: 176940 | GR12: 179590 | GS12: =IF((GQ12-GQ11)<=0,0,(GQ12-GQ11)) -> 1370 | GU12: =DailyJan!B11-DailyJan!N11-DailyJan!V11-DailyJan!Y11-DailyJan!Z11-DailyJan!AA11-DailyJan!AB11-DailyJan!AC11-DailyJan!AD11-DailyJan!AE11-DailyJan!AK11-DailyJan!AO11-DailyJan!AS11-DailyJan!AY11-DailyJan!BD11+DailyJan!BS11-SUM(DailyJan!BM11:BQ11)-DailyJan!BR11-DailyJan!AF11-DailyJan!AG11 -> 3134.933 | GV12: 714.23 | GW12: =GV12/15 -> 47.615333 | GX12: 47.62 | HA12: 2134.5856 | HC12: 1240.0044 | HE12: 2660.353
A13: =A12+1 -> 7 | B13: 3187.22 | C13: =IF((B13-B12)<=0,0,(B13-B12)) -> 6.99 | D13: =IF((B13-B12)*32000<=0,0,(B13-B12)*32000) -> 223680 | E13: 641.43 | F13: =IF((E13-E12)*32000<=0,0,(E13-E12)*32000) -> 46080 | G13: =D13+F13 -> 269760 | K13: =IF(J13<=0,0,(J13/SQRT(J13^2+(I13-I12)^2))) -> 0 | L13: 8923500 | N13: =IF((L13-L12)<=0,0,(L13-L12)*10) -> 268000 | O13: 9079.6 | Q13: =IF((O13-O12)<=0,0,(O13-O12))*1000 -> 12700 | R13: =IF(Q13<=0,0,(Q13/SQRT(Q13^2+(P13-P12)^2))) -> 1 | S13: 10911687 | T13: =IF((S13-S12)<=0,0,(S13-S12)) -> 0 | U13: 1518125.2 | V13: =IF((U13-U12)<=0,0,(U13-U12)) -> 0 | W13: 3068.5 | X13: =Q13-T13-V13-AB13 -> 8020 | Z13: =IF((Y13-Y12)<=0,0,(Y13-Y12)) -> 0 | AA13: 342880 | AB13: =IF((AA13-AA12)<=0,0,(AA13-AA12)) -> 4680 | AC13: 3284.7 | AE13: =IF((AC13-AC12)<=0,0,(AC13-AC12))*1000 -> 5400 | AF13: =IF(AE13<=0,0,(AE13/SQRT(AE13^2+(AD13-AD12)^2))) -> 1 | AG13: 7144.9 | AI13: =IF((AG13-AG12)<=0,0,(AG13-AG12))*1000+GX13 -> 13436.37 | AJ13: =IF(AI13<=0,0,(AI13/SQRT(AI13^2+(AH13-AH12)^2))) -> 1 | AK13: =T13+V13+X13+AE13+AI13 -> 26856.37 | AL13: 9292.6 | AN13: =IF((AL13-AL12)<=0,0,(AL13-AL12))*1000+GX13-BL13-BN13-BP13-BR13 -> 6956.37 | AO13: =IF(AN13<=0,0,(AN13/SQRT(AN13^2+(AM13-AM12)^2))) -> 1 | AP13: 6982.7 | AR13: =IF((AP13-AP12)<=0,0,(AP13-AP12))*1000 -> 13400 | AS13: =IF(AR13<=0,0,(AR13/SQRT(AR13^2+(AQ13-AQ12)^2))) -> 1 | AU13: =IF((AT13-AT12)<=0,0,(AT13-AT12)) -> 0 | AW13: =IF((AV13-AV12)<=0,0,(AV13-AV12)) -> 0 | AX13: 435334.8 | AZ13: =IF((AX13-AX12)<=0,0,(AX13-AX12)) -> 396.04 | BA13: 77755.424 | BC13: =IF((BA13-BA12)<=0,0,(BA13-BA12)) -> 703.12 | BD13: =AN13+AR13+AZ13+BC13 -> 21455.53 | BE13: 1583.7 | BF13: 857.37 | BG13: =IF((BE13-BE12)<=0,0,(BE13-BE12))*1000 -> 1900 | BH13: 7633.9 | BI13: 4910.7 | BJ13: =IF((BH13-BH12)<=0,0,(BH13-BH12))*1000 -> 9300 | BK13: 1009300 | BL13: =IF((BK13-BK12)<=0,0,(BK13-BK12)) -> 5200 | BM13: 779.23 | BN13: =IF((BM13-BM12)<=0,0,BM13-BM12)*1000 -> 720 | BP13: =IF((BO13-BO12)<=0,0,(BO13-BO12))*1000 -> 0 | BQ13: 739.33 | BR13: =IF((BQ13-BQ12)<=0,0,(BQ13-BQ12))*1000 -> 760 | BS13: 70260.77 | BT13: =IF((BS13-BS12)<=0,0,(BS13-BS12)) -> 181.63 | BU13: 1771900 | BW13: =IF((BU13-BU12)<=0,0,(BU13-BU12)) -> 4300 | BX13: =IF(BW13<=0,0,(BW13/SQRT(BW13^2+(BV13-BV12)^2))) -> 1 | BY13: 249.93 | CA13: =IF((BY13-BY12)<=0,0,(BY13-BY12)*1000) -> 720 | CB13: =IF(CA13<=0,0,(CA13/SQRT(CA13^2+(BZ13-BZ12)^2))) -> 1 | CC13: 414370 | CD13: =IF((CC13-CC12)<=0,0,(CC13-CC12)) -> 390 | CE13: 697300 | CF13: =IF((CE13-CE12)<=0,0,(CE13-CE12)) -> 0 | CG13: 46603 | CH13: =IF((CG13-CG12)<=0,0,(CG13-CG12)) -> 0 | CI13: 10370 | CK13: =IF((CI13-CI12)*1000<=0,0,(CI13-CI12)*1000)+GX13-CA13 -> 14716.37 | CL13: =IF(CK13<=0,0,(CK13/SQRT(CK13^2+(CJ13-CJ12)^2))) -> 1 | CM13: 2600.2 | CO13: =IF((CM13-CM12)<=0,0,(CM13-CM12))*1000+GX13 -> 7836.37 | CP13: =IF(CO13<=0,0,(CO13/SQRT(CO13^2+(CN13-CN12)^2))) -> 1 | CQ13: 2540.4 | CS13: =IF((CQ13-CQ12)<=0,0,(CQ13-CQ12))*1000+GX13 -> 5936.37 | CT13: =IF(CS13<=0,0,(CS13/SQRT(CS13^2+(CR13-CR12)^2))) -> 1 | CU13: 1762700 | CW13: =IF((CU13-CU12)<=0,0,(CU13-CU12)) -> 17500 | CX13: =IF(CW13<=0,0,(CW13/SQRT(CW13^2+(CV13-CV12)^2))) -> 1 | CY13: 905570 | DA13: =IF((CY13-CY12)<=0,0,(CY13-CY12)) -> 11090 | DB13: =IF(DA13<=0,0,(DA13/SQRT(DA13^2+(CZ13-CZ12)^2))) -> 1 | DE13: =IF((DC13-DC12)<=0,0,(DC13-DC12)) -> 0 | DF13: =IF(DE13<=0,0,(DE13/SQRT(DE13^2+(DD13-DD12)^2))) -> 0 | DG13: =(DE13)-DA13-CW13-CS13-CO13-CK13-BW13 -> -61379.11 | DH13: =DE13+BG13+AK13+N13 -> 296756.37 | DQ13: 2285600 | DR13: =IF((DQ13-DQ12)<=0,0,(DQ13-DQ12)) -> 11600 | DS13: 1454900 | DT13: =IF((DS13-DS12)<=0,0,(DS13-DS12)) -> 16400 | DU13: 7392.2 | DV13: 4117.5 | DW13: =IF((DU13-DU12)*1000<=0,0,(DU13-DU12)*1000) -> 4200 | DX13: 12274 | DY13: 8186.3 | DZ13: =IF((DX13-DX12)*1000<=0,0,(DX13-DX12)*1000)+GX13 -> 7436.37 | EA13: 27120 | EB13: 19.416 | EC13: =IF((EA13-EA12)*1000<=0,0,(EA13-EA12)*1000)+GX13+$EE$40 -> 25596.37 | ED13: =DW13+DZ13+EC13 -> 37232.74 | EE13: 42231 | EF13: 26.58 | EG13: =IF((EE13-EE12)*1000<=0,0,(EE13-EE12)*1000)+GX13+$EE$40 -> 34596.37 | EH13: 11743 | EI13: 1.5473 | EJ13: =IF((EH13-EH12)*1000<=0,0,(EH13-EH12)*1000)+GX13 -> 12436.37 | EK13: 707.78 | EL13: 1018.5 | EM13: =IF((EK13-EK12)<=0,0,(EK13-EK12))*1000 -> 660 | EN13: =EG13+EJ13+EM13 -> 47692.74 | EO13: 11851 | EP13: 4126.8 | EQ13: =IF((EO13-EO12)*1000<=0,0,(EO13-EO12)*1000)+GX13 -> 8436.37 | ER13: 7215 | ES13: 2919.6 | ET13: =IF((ER13-ER12)<=0,0,(ER13-ER12))*1000 -> 16800 | EU13: 2548.3 | EV13: 911.97 | EW13: =IF((EU13-EU12)<=0,0,(EU13-EU12))*1000+GX13 -> 9836.37 | EX13: 11953 | EY13: 1.2407 | EZ13: =IF((EX13-EX12)<=0,0,(EX13-EX12))*1000+GX13 -> 12436.37 | FA13: =FC13-EQ13-ET13-EW13-EZ13 -> -23396.11 | FB13: 33496192 | FC13: =IF((FB13-FB12)<=0,0,(FB13-FB12)) -> 24113 | FD13: =EQ13+ET13+EW13+EZ13+GJ13 -> 48909.11 | FE13: 15890 | FF13: 5714 | FG13: =IF((FE13-FE12)*1000<=0,0,(FE13-FE12)*1000)+FL13+GX13 -> 8103.04 | FH13: 6654.2 | FI13: 2.5594 | FJ13: =IF((FH13-FH12)<=0,0,(FH13-FH12))*1000+FL13+GX13 -> 19703.04 | FL13: -333.33 | FM13: =FT13/3 -> -436.37333 | FN13: 15106 | FO13: 0.646 | FP13: =IF((FN13-FN12)*1000<=0,0,(FN13-FN12)*1000)+FL13+GX13 -> 12103.04 | FQ13: 53469 | FR13: 12.696 | FS13: =IF((FQ13-FQ12)*1000<=0,0,(FQ13-FQ12)*1000) -> 55000 | FT13: =FS13-FG13-FJ13-FP13-DT13 -> -1309.12 | FU13: =FG13+FJ13+FP13+GM13 -> 40109.12 | FV13: 1981200 | FW13: 645490 | FX13: =IF((FV13-FV12)*1000<=0,0,(FV13-FV12)) -> 17200 | FY13: 2688.7 | FZ13: 1.5083 | GA13: =IF((FY13-FY12)*1000<=0,0,((FY13-FY12)*1000)-GS13) -> 1570 | GB13: 722.59 | GC13: 798.7 | GD13: =IF((GB13-GB12)*1000<=0,0,(GB13-GB12)*1000) -> 1010 | GE13: 9020.5 | GF13: 2.6228 | GG13: =IF((GE13-GE12)*1000<=0,0,(GE13-GE12)*1000)-GJ13-GM13 -> 6900 | GH13: 1734 | GI13: 1459.9 | GJ13: =IF((GH13-GH12)<=0,0,(GH13-GH12))*1000 -> 1400 | GK13: 1398.5 | GL13: 1088.6 | GM13: =IF((GK13-GK12)<=0,0,(GK13-GK12))*1000 -> 200 | GN13: 158830 | GO13: 138550 | GP13: =IF((GN13-GN12)<=0,0,(GN13-GN12)) -> 60 | GQ13: 178170 | GR13: 180860 | GS13: =IF((GQ13-GQ12)<=0,0,(GQ13-GQ12)) -> 1230 | GU13: =DailyJan!B12-DailyJan!N12-DailyJan!V12-DailyJan!Y12-DailyJan!Z12-DailyJan!AA12-DailyJan!AB12-DailyJan!AC12-DailyJan!AD12-DailyJan!AE12-DailyJan!AK12-DailyJan!AO12-DailyJan!AS12-DailyJan!AY12-DailyJan!BD12+DailyJan!BS12-SUM(DailyJan!BM12:BQ12)-DailyJan!BR12-DailyJan!AF12-DailyJan!AG12 -> 3134.927 | GV13: 6545.48 | GW13: =GV13/15 -> 436.36533 | GX13: 436.37 | HA13: 2216.0784 | HC13: 6989.7516 | HE13: 2660.353
A14: =A13+1 -> 8 | B14: 3194.4 | C14: =IF((B14-B13)<=0,0,(B14-B13)) -> 7.18 | D14: =IF((B14-B13)*32000<=0,0,(B14-B13)*32000) -> 229760 | E14: 642.98 | F14: =IF((E14-E13)*32000<=0,0,(E14-E13)*32000) -> 49600 | G14: =D14+F14 -> 279360 | K14: =IF(J14<=0,0,(J14/SQRT(J14^2+(I14-I13)^2))) -> 0 | L14: 8951200 | N14: =IF((L14-L13)<=0,0,(L14-L13)*10) -> 277000 | O14: 9092.8 | Q14: =IF((O14-O13)<=0,0,(O14-O13))*1000 -> 13200 | R14: =IF(Q14<=0,0,(Q14/SQRT(Q14^2+(P14-P13)^2))) -> 1 | S14: 10911687 | T14: =IF((S14-S13)<=0,0,(S14-S13)) -> 0 | U14: 1518125.2 | V14: =IF((U14-U13)<=0,0,(U14-U13)) -> 0 | W14: 3075.2 | X14: =Q14-T14-V14-AB14 -> 8370 | Z14: =IF((Y14-Y13)<=0,0,(Y14-Y13)) -> 0 | AA14: 347710 | AB14: =IF((AA14-AA13)<=0,0,(AA14-AA13)) -> 4830 | AC14: 3289.6 | AE14: =IF((AC14-AC13)<=0,0,(AC14-AC13))*1000 -> 4900 | AF14: =IF(AE14<=0,0,(AE14/SQRT(AE14^2+(AD14-AD13)^2))) -> 1 | AG14: 7157 | AI14: =IF((AG14-AG13)<=0,0,(AG14-AG13))*1000+GX14 -> 11872.57 | AJ14: =IF(AI14<=0,0,(AI14/SQRT(AI14^2+(AH14-AH13)^2))) -> 1 | AK14: =T14+V14+X14+AE14+AI14 -> 25142.57 | AL14: 9306.3 | AN14: =IF((AL14-AL13)<=0,0,(AL14-AL13))*1000+GX14-BL14-BN14-BP14-BR14 -> 6912.57 | AO14: =IF(AN14<=0,0,(AN14/SQRT(AN14^2+(AM14-AM13)^2))) -> 1 | AP14: 6997.3 | AR14: =IF((AP14-AP13)<=0,0,(AP14-AP13))*1000 -> 14600 | AS14: =IF(AR14<=0,0,(AR14/SQRT(AR14^2+(AQ14-AQ13)^2))) -> 1 | AU14: =IF((AT14-AT13)<=0,0,(AT14-AT13)) -> 0 | AW14: =IF((AV14-AV13)<=0,0,(AV14-AV13)) -> 0 | AX14: 435832.08 | AZ14: =IF((AX14-AX13)<=0,0,(AX14-AX13)) -> 497.28 | BA14: 78446.296 | BC14: =IF((BA14-BA13)<=0,0,(BA14-BA13)) -> 690.872 | BD14: =AN14+AR14+AZ14+BC14 -> 22700.722 | BE14: 1585.6 | BF14: 858.54 | BG14: =IF((BE14-BE13)<=0,0,(BE14-BE13))*1000 -> 1900 | BH14: 7643.1 | BI14: 4916.2 | BJ14: =IF((BH14-BH13)<=0,0,(BH14-BH13))*1000 -> 9200 | BK14: 1014500 | BL14: =IF((BK14-BK13)<=0,0,(BK14-BK13)) -> 5200 | BM14: 779.91 | BN14: =IF((BM14-BM13)<=0,0,BM14-BM13)*1000 -> 680 | BP14: =IF((BO14-BO13)<=0,0,(BO14-BO13))*1000 -> 0 | BQ14: 740.01 | BR14: =IF((BQ14-BQ13)<=0,0,(BQ14-BQ13))*1000 -> 680 | BS14: 70445.07 | BT14: =IF((BS14-BS13)<=0,0,(BS14-BS13)) -> 184.3 | BU14: 1776000 | BW14: =IF((BU14-BU13)<=0,0,(BU14-BU13)) -> 4100 | BX14: =IF(BW14<=0,0,(BW14/SQRT(BW14^2+(BV14-BV13)^2))) -> 1 | BY14: 250.84 | CA14: =IF((BY14-BY13)<=0,0,(BY14-BY13)*1000) -> 910 | CB14: =IF(CA14<=0,0,(CA14/SQRT(CA14^2+(BZ14-BZ13)^2))) -> 1 | CC14: 414370 | CD14: =IF((CC14-CC13)<=0,0,(CC14-CC13)) -> 0 | CE14: 697300 | CF14: =IF((CE14-CE13)<=0,0,(CE14-CE13)) -> 0 | CG14: 46631 | CH14: =IF((CG14-CG13)<=0,0,(CG14-CG13)) -> 28 | CI14: 10386 | CK14: =IF((CI14-CI13)*1000<=0,0,(CI14-CI13)*1000)+GX14-CA14 -> 14862.57 | CL14: =IF(CK14<=0,0,(CK14/SQRT(CK14^2+(CJ14-CJ13)^2))) -> 1 | CM14: 2608.3 | CO14: =IF((CM14-CM13)<=0,0,(CM14-CM13))*1000+GX14 -> 7872.57 | CP14: =IF(CO14<=0,0,(CO14/SQRT(CO14^2+(CN14-CN13)^2))) -> 1 | CQ14: 2546.6 | CS14: =IF((CQ14-CQ13)<=0,0,(CQ14-CQ13))*1000+GX14 -> 5972.57 | CT14: =IF(CS14<=0,0,(CS14/SQRT(CS14^2+(CR14-CR13)^2))) -> 1 | CU14: 1782400 | CW14: =IF((CU14-CU13)<=0,0,(CU14-CU13)) -> 19700 | CX14: =IF(CW14<=0,0,(CW14/SQRT(CW14^2+(CV14-CV13)^2))) -> 1 | CY14: 917800 | DA14: =IF((CY14-CY13)<=0,0,(CY14-CY13)) -> 12230 | DB14: =IF(DA14<=0,0,(DA14/SQRT(DA14^2+(CZ14-CZ13)^2))) -> 1 | DE14: =IF((DC14-DC13)<=0,0,(DC14-DC13)) -> 0 | DF14: =IF(DE14<=0,0,(DE14/SQRT(DE14^2+(DD14-DD13)^2))) -> 0 | DG14: =(DE14)-DA14-CW14-CS14-CO14-CK14-BW14 -> -64737.71 | DH14: =DE14+BG14+AK14+N14 -> 304042.57 | DQ14: 2298100 | DR14: =IF((DQ14-DQ13)<=0,0,(DQ14-DQ13)) -> 12500 | DS14: 1469500 | DT14: =IF((DS14-DS13)<=0,0,(DS14-DS13)) -> 14600 | DU14: 7396.4 | DV14: 4120 | DW14: =IF((DU14-DU13)*1000<=0,0,(DU14-DU13)*1000) -> 4200 | DX14: 12281 | DY14: 8188.9 | DZ14: =IF((DX14-DX13)*1000<=0,0,(DX14-DX13)*1000)+GX14 -> 6772.57 | EA14: 27143 | EB14: 19.428 | EC14: =IF((EA14-EA13)*1000<=0,0,(EA14-EA13)*1000)+GX14+$EE$40 -> 24932.57 | ED14: =DW14+DZ14+EC14 -> 35905.14 | EE14: 42261 | EF14: 26.608 | EG14: =IF((EE14-EE13)*1000<=0,0,(EE14-EE13)*1000)+GX14+$EE$40 -> 31932.57 | EH14: 11755 | EI14: 1.5505 | EJ14: =IF((EH14-EH13)*1000<=0,0,(EH14-EH13)*1000)+GX14 -> 11772.57 | EK14: 708.39 | EL14: 1019.3 | EM14: =IF((EK14-EK13)<=0,0,(EK14-EK13))*1000 -> 610 | EN14: =EG14+EJ14+EM14 -> 44315.14 | EO14: 11860 | EP14: 4129.9 | EQ14: =IF((EO14-EO13)*1000<=0,0,(EO14-EO13)*1000)+GX14 -> 8772.57 | ER14: 7233.1 | ES14: 2927.3 | ET14: =IF((ER14-ER13)<=0,0,(ER14-ER13))*1000 -> 18100 | EU14: 2557.8 | EV14: 915.28 | EW14: =IF((EU14-EU13)<=0,0,(EU14-EU13))*1000+GX14 -> 9272.57 | EX14: 11966 | EY14: 1.2427 | EZ14: =IF((EX14-EX13)<=0,0,(EX14-EX13))*1000+GX14 -> 12772.57 | FA14: =FC14-EQ14-ET14-EW14-EZ14 -> -24200.71 | FB14: 33520909 | FC14: =IF((FB14-FB13)<=0,0,(FB14-FB13)) -> 24717 | FD14: =EQ14+ET14+EW14+EZ14+GJ14 -> 50517.71 | FE14: 15898 | FF14: 5712 | FG14: =IF((FE14-FE13)*1000<=0,0,(FE14-FE13)*1000)+FL14+GX14 -> 8539.24 | FH14: 6674.3 | FI14: 2.5671 | FJ14: =IF((FH14-FH13)<=0,0,(FH14-FH13))*1000+FL14+GX14 -> 20639.24 | FL14: 766.67 | FM14: =FT14/3 -> 227.42667 | FN14: 15119 | FO14: 0.6485 | FP14: =IF((FN14-FN13)*1000<=0,0,(FN14-FN13)*1000)+FL14+GX14 -> 13539.24 | FQ14: 53527 | FR14: 12.712 | FS14: =IF((FQ14-FQ13)*1000<=0,0,(FQ14-FQ13)*1000) -> 58000 | FT14: =FS14-FG14-FJ14-FP14-DT14 -> 682.28 | FU14: =FG14+FJ14+FP14+GM14 -> 42717.72 | FV14: 1999600 | FW14: 651240 | FX14: =IF((FV14-FV13)*1000<=0,0,(FV14-FV13)) -> 18400 | FY14: 2691.3 | FZ14: 1.5089 | GA14: =IF((FY14-FY13)*1000<=0,0,((FY14-FY13)*1000)-GS14) -> 1530 | GB14: 724.07 | GC14: 800.67 | GD14: =IF((GB14-GB13)*1000<=0,0,(GB14-GB13)*1000) -> 1480 | GE14: 9031.2 | GF14: 2.626 | GG14: =IF((GE14-GE13)*1000<=0,0,(GE14-GE13)*1000)-GJ14-GM14 -> 9100 | GH14: 1735.6 | GI14: 1461.5 | GJ14: =IF((GH14-GH13)<=0,0,(GH14-GH13))*1000 -> 1600 | GK14: 1398.5 | GL14: 1088.6 | GM14: =IF((GK14-GK13)<=0,0,(GK14-GK13))*1000 -> 0 | GN14: 158830 | GO14: 138560 | GP14: =IF((GN14-GN13)<=0,0,(GN14-GN13)) -> 0 | GQ14: 179240 | GR14: 181920 | GS14: =IF((GQ14-GQ13)<=0,0,(GQ14-GQ13)) -> 1070 | GU14: =DailyJan!B13-DailyJan!N13-DailyJan!V13-DailyJan!Y13-DailyJan!Z13-DailyJan!AA13-DailyJan!AB13-DailyJan!AC13-DailyJan!AD13-DailyJan!AE13-DailyJan!AK13-DailyJan!AO13-DailyJan!AS13-DailyJan!AY13-DailyJan!BD13+DailyJan!BS13-SUM(DailyJan!BM13:BQ13)-DailyJan!BR13-DailyJan!AF13-DailyJan!AG13 -> 3134.935 | GV14: -3411.51 | GW14: =GV14/15 -> -227.434 | GX14: -227.43 | HA14: 2294.9424 | HC14: -3046.1024 | HE14: 2660.353
A15: =A14+1 -> 9 | B15: 3201.8 | C15: =IF((B15-B14)<=0,0,(B15-B14)) -> 7.4 | D15: =IF((B15-B14)*32000<=0,0,(B15-B14)*32000) -> 236800 | E15: 644.36 | F15: =IF((E15-E14)*32000<=0,0,(E15-E14)*32000) -> 44160 | G15: =D15+F15 -> 280960 | K15: =IF(J15<=0,0,(J15/SQRT(J15^2+(I15-I14)^2))) -> 0 | L15: 8979100 | N15: =IF((L15-L14)<=0,0,(L15-L14)*10) -> 279000 | O15: 9106.1 | Q15: =IF((O15-O14)<=0,0,(O15-O14))*1000 -> 13300 | R15: =IF(Q15<=0,0,(Q15/SQRT(Q15^2+(P15-P14)^2))) -> 1 | S15: 10911687 | T15: =IF((S15-S14)<=0,0,(S15-S14)) -> 0 | U15: 1518125.2 | V15: =IF((U15-U14)<=0,0,(U15-U14)) -> 0 | W15: 3082.1 | X15: =Q15-T15-V15-AB15 -> 8400 | Z15: =IF((Y15-Y14)<=0,0,(Y15-Y14)) -> 0 | AA15: 352610 | AB15: =IF((AA15-AA14)<=0,0,(AA15-AA14)) -> 4900 | AC15: 3294.3 | AE15: =IF((AC15-AC14)<=0,0,(AC15-AC14))*1000 -> 4700 | AF15: =IF(AE15<=0,0,(AE15/SQRT(AE15^2+(AD15-AD14)^2))) -> 1 | AG15: 7168.5 | AI15: =IF((AG15-AG14)<=0,0,(AG15-AG14))*1000+GX15 -> 11653.87 | AJ15: =IF(AI15<=0,0,(AI15/SQRT(AI15^2+(AH15-AH14)^2))) -> 1 | AK15: =T15+V15+X15+AE15+AI15 -> 24753.87 | AL15: 9320.6 | AN15: =IF((AL15-AL14)<=0,0,(AL15-AL14))*1000+GX15-BL15-BN15-BP15-BR15 -> 7623.87 | AO15: =IF(AN15<=0,0,(AN15/SQRT(AN15^2+(AM15-AM14)^2))) -> 1 | AP15: 7012.5 | AR15: =IF((AP15-AP14)<=0,0,(AP15-AP14))*1000 -> 15200 | AS15: =IF(AR15<=0,0,(AR15/SQRT(AR15^2+(AQ15-AQ14)^2))) -> 1 | AU15: =IF((AT15-AT14)<=0,0,(AT15-AT14)) -> 0 | AW15: =IF((AV15-AV14)<=0,0,(AV15-AV14)) -> 0 | AX15: 436360.8 | AZ15: =IF((AX15-AX14)<=0,0,(AX15-AX14)) -> 528.72 | BA15: 79162.696 | BC15: =IF((BA15-BA14)<=0,0,(BA15-BA14)) -> 716.4 | BD15: =AN15+AR15+AZ15+BC15 -> 24068.99 | BE15: 1587.8 | BF15: 859.86 | BG15: =IF((BE15-BE14)<=0,0,(BE15-BE14))*1000 -> 2200 | BH15: 7652.7 | BI15: 4922.6 | BJ15: =IF((BH15-BH14)<=0,0,(BH15-BH14))*1000 -> 9600 | BK15: 1019900 | BL15: =IF((BK15-BK14)<=0,0,(BK15-BK14)) -> 5400 | BM15: 780.62 | BN15: =IF((BM15-BM14)<=0,0,BM15-BM14)*1000 -> 710 | BP15: =IF((BO15-BO14)<=0,0,(BO15-BO14))*1000 -> 0 | BQ15: 740.73 | BR15: =IF((BQ15-BQ14)<=0,0,(BQ15-BQ14))*1000 -> 720 | BS15: 70614.21 | BT15: =IF((BS15-BS14)<=0,0,(BS15-BS14)) -> 169.14 | BU15: 1780500 | BW15: =IF((BU15-BU14)<=0,0,(BU15-BU14)) -> 4500 | BX15: =IF(BW15<=0,0,(BW15/SQRT(BW15^2+(BV15-BV14)^2))) -> 1 | BY15: 251.79 | CA15: =IF((BY15-BY14)<=0,0,(BY15-BY14)*1000) -> 950 | CB15: =IF(CA15<=0,0,(CA15/SQRT(CA15^2+(BZ15-BZ14)^2))) -> 1 | CC15: 414370 | CD15: =IF((CC15-CC14)<=0,0,(CC15-CC14)) -> 0 | CE15: 697300 | CF15: =IF((CE15-CE14)<=0,0,(CE15-CE14)) -> 0 | CG15: 47059 | CH15: =IF((CG15-CG14)<=0,0,(CG15-CG14)) -> 428 | CI15: 10403 | CK15: =IF((CI15-CI14)*1000<=0,0,(CI15-CI14)*1000)+GX15-CA15 -> 16203.87 | CL15: =IF(CK15<=0,0,(CK15/SQRT(CK15^2+(CJ15-CJ14)^2))) -> 1 | CM15: 2617.1 | CO15: =IF((CM15-CM14)<=0,0,(CM15-CM14))*1000+GX15 -> 8953.87 | CP15: =IF(CO15<=0,0,(CO15/SQRT(CO15^2+(CN15-CN14)^2))) -> 1 | CQ15: 2553 | CS15: =IF((CQ15-CQ14)<=0,0,(CQ15-CQ14))*1000+GX15 -> 6553.87 | CT15: =IF(CS15<=0,0,(CS15/SQRT(CS15^2+(CR15-CR14)^2))) -> 1 | CU15: 1800000 | CW15: =IF((CU15-CU14)<=0,0,(CU15-CU14)) -> 17600 | CX15: =IF(CW15<=0,0,(CW15/SQRT(CW15^2+(CV15-CV14)^2))) -> 1 | CY15: 927810 | DA15: =IF((CY15-CY14)<=0,0,(CY15-CY14)) -> 10010 | DB15: =IF(DA15<=0,0,(DA15/SQRT(DA15^2+(CZ15-CZ14)^2))) -> 1 | DE15: =IF((DC15-DC14)<=0,0,(DC15-DC14)) -> 0 | DF15: =IF(DE15<=0,0,(DE15/SQRT(DE15^2+(DD15-DD14)^2))) -> 0 | DG15: =(DE15)-DA15-CW15-CS15-CO15-CK15-BW15 -> -63821.61 | DH15: =DE15+BG15+AK15+N15 -> 305953.87 | DQ15: 2310600 | DR15: =IF((DQ15-DQ14)<=0,0,(DQ15-DQ14)) -> 12500 | DS15: 1482900 | DT15: =IF((DS15-DS14)<=0,0,(DS15-DS14)) -> 13400 | DU15: 7399.7 | DV15: 4122 | DW15: =IF((DU15-DU14)*1000<=0,0,(DU15-DU14)*1000) -> 3300 | DX15: 12284 | DY15: 8191 | DZ15: =IF((DX15-DX14)*1000<=0,0,(DX15-DX14)*1000)+GX15 -> 3153.87 | EA15: 27155 | EB15: 19.434 | EC15: =IF((EA15-EA14)*1000<=0,0,(EA15-EA14)*1000)+GX15+$EE$40 -> 14313.87 | ED15: =DW15+DZ15+EC15 -> 20767.74 | EE15: 42292 | EF15: 26.638 | EG15: =IF((EE15-EE14)*1000<=0,0,(EE15-EE14)*1000)+GX15+$EE$40 -> 33313.87 | EH15: 11768 | EI15: 1.5542 | EJ15: =IF((EH15-EH14)*1000<=0,0,(EH15-EH14)*1000)+GX15 -> 13153.87 | EK15: 709.02 | EL15: 1020.2 | EM15: =IF((EK15-EK14)<=0,0,(EK15-EK14))*1000 -> 630 | EN15: =EG15+EJ15+EM15 -> 47097.74 | EO15: 11868 | EP15: 4133.1 | EQ15: =IF((EO15-EO14)*1000<=0,0,(EO15-EO14)*1000)+GX15 -> 8153.87 | ER15: 7251.2 | ES15: 2935.2 | ET15: =IF((ER15-ER14)<=0,0,(ER15-ER14))*1000 -> 18100 | EU15: 2567.3 | EV15: 918.51 | EW15: =IF((EU15-EU14)<=0,0,(EU15-EU14))*1000+GX15 -> 9653.87 | EX15: 11977 | EY15: 1.2442 | EZ15: =IF((EX15-EX14)<=0,0,(EX15-EX14))*1000+GX15 -> 11153.87 | FA15: =FC15-EQ15-ET15-EW15-EZ15 -> -22787.61 | FB15: 33545183 | FC15: =IF((FB15-FB14)<=0,0,(FB15-FB14)) -> 24274 | FD15: =EQ15+ET15+EW15+EZ15+GJ15 -> 48661.61 | FE15: 15906 | FF15: 5718.5 | FG15: =IF((FE15-FE14)*1000<=0,0,(FE15-FE14)*1000)+FL15+GX15 -> 8420.54 | FH15: 6694.1 | FI15: 2.5748 | FJ15: =IF((FH15-FH14)<=0,0,(FH15-FH14))*1000+FL15+GX15 -> 20220.54 | FL15: 266.67 | FM15: =FT15/3 -> -153.87333 | FN15: 15132 | FO15: 0.6504 | FP15: =IF((FN15-FN14)*1000<=0,0,(FN15-FN14)*1000)+FL15+GX15 -> 13420.54 | FQ15: 53582 | FR15: 12.728 | FS15: =IF((FQ15-FQ14)*1000<=0,0,(FQ15-FQ14)*1000) -> 55000 | FT15: =FS15-FG15-FJ15-FP15-DT15 -> -461.62 | FU15: =FG15+FJ15+FP15+GM15 -> 42061.62 | FV15: 2019200 | FW15: 657580 | FX15: =IF((FV15-FV14)*1000<=0,0,(FV15-FV14)) -> 19600 | FY15: 2694 | FZ15: 1.5094 | GA15: =IF((FY15-FY14)*1000<=0,0,((FY15-FY14)*1000)-GS15) -> 1670 | GB15: 725.44 | GC15: 802.43 | GD15: =IF((GB15-GB14)*1000<=0,0,(GB15-GB14)*1000) -> 1370 | GE15: 9040.7 | GF15: 2.6333 | GG15: =IF((GE15-GE14)*1000<=0,0,(GE15-GE14)*1000)-GJ15-GM15 -> 7900 | GH15: 1737.2 | GI15: 1463 | GJ15: =IF((GH15-GH14)<=0,0,(GH15-GH14))*1000 -> 1600 | GK15: 1398.5 | GL15: 1088.6 | GM15: =IF((GK15-GK14)<=0,0,(GK15-GK14))*1000 -> 0 | GN15: 158850 | GO15: 138560 | GP15: =IF((GN15-GN14)<=0,0,(GN15-GN14)) -> 20 | GQ15: 180270 | GR15: 182880 | GS15: =IF((GQ15-GQ14)<=0,0,(GQ15-GQ14)) -> 1030 | GU15: =DailyJan!B14-DailyJan!N14-DailyJan!V14-DailyJan!Y14-DailyJan!Z14-DailyJan!AA14-DailyJan!AB14-DailyJan!AC14-DailyJan!AD14-DailyJan!AE14-DailyJan!AK14-DailyJan!AO14-DailyJan!AS14-DailyJan!AY14-DailyJan!BD14+DailyJan!BS14-SUM(DailyJan!BM14:BQ14)-DailyJan!BR14-DailyJan!AF14-DailyJan!AG14 -> 3135.0364 | GV15: 2308.09 | GW15: =GV15/15 -> 153.87267 | GX15: 153.87 | HA15: 2308.0864 | HC15: 8063.7836 | HE15: 8063.7836
