Workbook

Sheet Report1
A3: PAPER MACHINE 12 DAILY REPORT 1
A6: DATE | B6: GRADE | C6: GSM | D6: Speed yankee (mpm) | E6: Speed reel (mpm) | F6: Creep ( % ) | G6: Real Eff PM ( % ) | H6: Real Eff PM vs Target (%) | I6: Real Eff FG vs Real Eff PM (%) | J6: Eff FG vs Target (%) | L6: Kapasitas Target (ton) | N6: Kapasitas Teori Real (ton) | P6: PM PROD Timbangan (TON) | R6: FINSHED GOODS (TON) | T6: NET GROSS (Timbangan) (%) | V6: NET GROSS ( Scanner) (%) | X6: FRESH WATER | AB6: GAS HOOD | AH6: STEAM (TON) | AN6: STEAM (TON) DEINKING | AT6: POWER (kWh) | AZ6: POWER (kWh) DEINKING | BF6: Report | BH6: Kapasitas Running (ton) | BJ6: Eff FG vs Target Running(%)
X7: CONSUMPTION | Z7: /TON FG. | AB7: CONSUMPTION | AD7: /TON PM. | AF7: /TON FG. | AH7: CONSUMPTION | AJ7: /TON PM. | AL7: /TON FG. | AN7: CONSUMPTION | AP7: /TON PM. | AR7: /TON FG. | AT7: CONSUMPTION | AV7: /TON PM | AX7: /TON FG | AZ7: CONSUMPTION | BB7: /TON PM | BD7: /TON FG | BF7: Hood | BG7: Yankee
J8: TODAY | K8: TODATE | L8: TODAY | M8: TODATE | N8: TODAY | O8: TODATE | P8: TODAY | Q8: TODATE | R8: TODAY | S8: TODATE | T8: TODAY | U8: TODATE | V8: TODAY | W8: TODATE | X8: TODAY | Y8: TODATE | Z8: TODAY | AA8: TODATE | AB8: TODAY | AC8: TODATE | AD8: TODAY | AE8: TODATE | AF8: TODAY | AG8: TODATE | AH8: TODAY | AI8: TODATE | AJ8: TODAY | AK8: TODATE | AL8: TODAY | AM8: TODATE | AN8: TODAY | AO8: TODATE | AP8: TODAY | AQ8: TODATE | AR8: TODAY | AS8: TODATE | AT8: TODAY | AU8: TODATE | AV8: TODAY | AW8: TODATE | AX8: TODAY | AY8: TODATE | AZ8: TODAY | BA8: TODATE | BB8: TODAY | BC8: TODATE | BD8: TODAY | BE8: TODATE | BH8: TODAY | BI8: TODATE | BJ8: TODAY | BK8: TODATE
A9: 45901 | B9: Towel/KTW | C9: 35,5/34/17 | D9: =+'1'!F42 -> 545.41667 | E9: =+'1'!G42 -> 479.96667 | F9: =1-(E9/D9) -> 0.12 | G9: =+P9/N9 -> 0.98199703 | H9: =+P9/L9 -> 0.98199703 | I9: =+R9/P9 -> 1.0012564 | J9: =+R9/L9 -> 0.98323083 | K9: =+S9/M9 -> 0.98323083 | L9: =+SUM(Efficiency1!K6:K8) -> 74.566417 | M9: =L9 -> 74.566417 | N9: =+SUM(Efficiency1!C6:C8) -> 74.566417 | O9: =N9 -> 74.566417 | P9: ='1'!I38 -> 73.224 | Q9: =P9 -> 73.224 | R9: ='1'!I40 -> 73.316 | S9: =R9 -> 73.316 | T9: =R9/P9 -> 1.0012564 | U9: =S9/Q9 -> 1.0012564 | V9: =R9/L9 -> 0.98323083 | W9: =S9/M9 -> 0.98323083 | AB9: 0 | AC9: =AB9 -> 0 | AD9: =AB9/P9 -> 0 | AE9: =AC9/Q9 -> 0 | AF9: =IF(AND(R9>0,AB9>0),(AB9/(R9*1000))*1000,0) -> 0 | AG9: =IF(AND(S9>0,AC9>0),AC9/S9,0) -> 0 | AH9: =+BF9+BG9 -> 136.698 | AI9: =AH9 -> 136.698 | AJ9: =AH9/(P9) -> 1.8668469 | AK9: =AI9/(Q9) -> 1.8668469 | AL9: =IF(AND(R9>0,AH9>0),AH9/(R9),0) -> 1.8645043 | AM9: =IF(AND(S9>0,AI9>0),AI9/(S9),0) -> 1.8645043 | AN9: 18 | AO9: =AN9 -> 18 | AP9: =AN9/(P9) -> 0.24582104 | AQ9: =AO9/(Q9) -> 0.24582104 | AR9: =IF(AND(R9>0,AN9>0),AN9/(R9),0) -> 0.24551258 | AS9: =IF(AND(S9>0,AO9>0),AO9/(S9),0) -> 0.24551258 | AT9: ='1'!I46 -> 31655 | AU9: =AT9 -> 31655 | AV9: =IF(AND(L9>0,AT9>0),(AT9/(P9*1000)*1000),0) -> 432.30362 | AW9: =IF(AND(M9>0,AU9>0),(AU9/(Q9*1000)*1000),0) -> 432.30362 | AX9: =IF(AND(R9>0,AT9>0),(AT9/(R9*1000)*1000),0) -> 431.76114 | AY9: =IF(AND(S9>0,AU9>0),(AU9/(S9*1000)*1000),0) -> 431.76114 | AZ9: =+Listrik!AH8 -> 31993 | BA9: =AZ9 -> 31993 | BB9: =IF(AND(L9>0,AZ9>0),(AZ9/(P9*1000)*1000),0) -> 436.91959 | BC9: =IF(AND(M9>0,BA9>0),(BA9/(Q9*1000)*1000),0) -> 436.91959 | BD9: =IF(AND(R9>0,AZ9>0),(AZ9/(R9*1000)*1000),0) -> 436.37132 | BE9: =IF(AND(S9>0,BA9>0),(BA9/(S9*1000)*1000),0) -> 436.37132 | BF9: =30.349 -> 30.349 | BG9: 106.349 | BH9: =+SUM(Efficiency2!K6:K8) -> 74.566417 | BI9: =BH9 -> 74.566417 | BJ9: =+R9/BH9 -> 0.98323083 | BK9: =+S9/BI9 -> 0.98323083
A10: =A9+1 -> 45902 | B10: KTW/Towel | C10: 17/31,5 | D10: =+'2'!F42 -> 694.375 | E10: =+'2'!G42 -> 611.05 | F10: =1-(E10/D10) -> 0.12 | G10: =+P10/N10 -> 0.96094104 | H10: =+P10/L10 -> 0.96094104 | I10: =+R10/P10 -> 0.99610287 | J10: =+R10/L10 -> 0.95719613 | K10: =+S10/M10 -> 0.97141642 | L10: =+SUM(Efficiency1!K11:K12) -> 61.950731 | M10: =M9+L10 -> 136.51715 | N10: =+SUM(Efficiency1!C11:C12) -> 61.950731 | O10: =O9+N10 -> 136.51715 | P10: ='2'!I38 -> 59.531 | Q10: =Q9+P10 -> 132.755 | R10: ='2'!I40 -> 59.299 | S10: =S9+R10 -> 132.615 | T10: =R10/P10 -> 0.99610287 | U10: =S10/Q10 -> 0.99894543 | V10: =R10/L10 -> 0.95719613 | W10: =S10/M10 -> 0.97141642 | AB10: 0 | AC10: =AB10+AC9 -> 0 | AD10: =AB10/P10 -> 0 | AE10: =AC10/Q10 -> 0 | AF10: =IF(AND(R10>0,AB10>0),(AB10/(R10*1000))*1000,0) -> 0 | AG10: =IF(AND(S10>0,AC10>0),AC10/S10,0) -> 0 | AH10: =+BF10+BG10 -> 106.594 | AI10: =AH10+AI9 -> 243.292 | AJ10: =AH10/(P10) -> 1.7905629 | AK10: =AI10/(Q10) -> 1.8326391 | AL10: =IF(AND(R10>0,AH10>0),AH10/(R10),0) -> 1.7975683 | AM10: =IF(AND(S10>0,AI10>0),AI10/(S10),0) -> 1.8345738 | AN10: 13.6 | AO10: =AN10+AO9 -> 31.6 | AP10: =AN10/(P10) -> 0.2284524 | AQ10: =AO10/(Q10) -> 0.23803247 | AR10: =IF(AND(R10>0,AN10>0),AN10/(R10),0) -> 0.22934619 | AS10: =IF(AND(S10>0,AO10>0),AO10/(S10),0) -> 0.23828375 | AT10: ='2'!I46 -> 36503.15 | AU10: =AT10+AU9 -> 68158.15 | AV10: =IF(AND(L10>0,AT10>0),(AT10/(P10*1000)*1000),0) -> 613.17885 | AW10: =IF(AND(M10>0,AU10>0),(AU10/(Q10*1000)*1000),0) -> 513.41305 | AX10: =IF(AND(R10>0,AT10>0),(AT10/(R10*1000)*1000),0) -> 615.57783 | AY10: =IF(AND(S10>0,AU10>0),(AU10/(S10*1000)*1000),0) -> 513.95506 | AZ10: =+Listrik!AH9 -> 23403 | BA10: =AZ10+BA9 -> 55396 | BB10: =IF(AND(L10>0,AZ10>0),(AZ10/(P10*1000)*1000),0) -> 393.12291 | BC10: =IF(AND(M10>0,BA10>0),(BA10/(Q10*1000)*1000),0) -> 417.27995 | BD10: =IF(AND(R10>0,AZ10>0),(AZ10/(R10*1000)*1000),0) -> 394.66096 | BE10: =IF(AND(S10>0,BA10>0),(BA10/(S10*1000)*1000),0) -> 417.72047 | BF10: =6.213 -> 6.213 | BG10: 100.381 | BH10: =+SUM(Efficiency2!K11:K12) -> 61.950731 | BI10: =BI9+BH10 -> 136.51715 | BJ10: =+R10/BH10 -> 0.95719613 | BK10: =+S10/BI10 -> 0.97141642
A11: =A10+1 -> 45903 | B11: Towel/Napkin | C11: 31,5/18/15,5 | D11: =+'3'!F42 -> 805.24306 | E11: =+'3'!G42 -> 693.33958 | F11: =1-(E11/D11) -> 0.13896857 | G11: =+P11/N11 -> 0.88341752 | H11: =+P11/L11 -> 0.88341752 | I11: =+R11/P11 -> 0.81543365 | J11: =+R11/L11 -> 0.72036837 | K11: =+S11/M11 -> 0.8973071 | L11: =+SUM(Efficiency1!K16:K18) -> 57.179079 | M11: =M10+L11 -> 193.69623 | N11: =+SUM(Efficiency1!C16:C18) -> 57.179079 | O11: =O10+N11 -> 193.69623 | P11: ='3'!I38 -> 50.513 | Q11: =Q10+P11 -> 183.268 | R11: ='3'!I40 -> 41.19 | S11: =S10+R11 -> 173.805 | T11: =R11/P11 -> 0.81543365 | U11: =S11/Q11 -> 0.94836524 | V11: =R11/L11 -> 0.72036837 | W11: =S11/M11 -> 0.8973071 | AB11: 0 | AC11: =AB11+AC10 -> 0 | AD11: =AB11/P11 -> 0 | AE11: =AC11/Q11 -> 0 | AF11: =IF(AND(R11>0,AB11>0),(AB11/(R11*1000))*1000,0) -> 0 | AG11: =IF(AND(S11>0,AC11>0),AC11/S11,0) -> 0 | AH11: =+BF11+BG11 -> 111.037 | AI11: =AH11+AI10 -> 354.329 | AJ11: =AH11/(P11) -> 2.1981866 | AK11: =AI11/(Q11) -> 1.9333926 | AL11: =IF(AND(R11>0,AH11>0),AH11/(R11),0) -> 2.6957271 | AM11: =IF(AND(S11>0,AI11>0),AI11/(S11),0) -> 2.0386583 | AN11: 16 | AO11: =AN11+AO10 -> 47.6 | AP11: =AN11/(P11) -> 0.31675014 | AQ11: =AO11/(Q11) -> 0.25972892 | AR11: =IF(AND(R11>0,AN11>0),AN11/(R11),0) -> 0.3884438 | AS11: =IF(AND(S11>0,AO11>0),AO11/(S11),0) -> 0.27387014 | AT11: ='3'!I46 -> 31786.35 | AU11: =AT11+AU10 -> 99944.5 | AV11: =IF(AND(L11>0,AT11>0),(AT11/(P11*1000)*1000),0) -> 629.27068 | AW11: =IF(AND(M11>0,AU11>0),(AU11/(Q11*1000)*1000),0) -> 545.34616 | AX11: =IF(AND(R11>0,AT11>0),(AT11/(R11*1000)*1000),0) -> 771.70066 | AY11: =IF(AND(S11>0,AU11>0),(AU11/(S11*1000)*1000),0) -> 575.03812 | AZ11: =+Listrik!AH10 -> 27173 | BA11: =AZ11+BA10 -> 82569 | BB11: =IF(AND(L11>0,AZ11>0),(AZ11/(P11*1000)*1000),0) -> 537.94073 | BC11: =IF(AND(M11>0,BA11>0),(BA11/(Q11*1000)*1000),0) -> 450.53692 | BD11: =IF(AND(R11>0,AZ11>0),(AZ11/(R11*1000)*1000),0) -> 659.69896 | BE11: =IF(AND(S11>0,BA11>0),(BA11/(S11*1000)*1000),0) -> 475.06689 | BF11: =9.29 -> 9.29 | BG11: 101.747 | BH11: =+SUM(Efficiency2!K16:K18) -> 48.487136 | BI11: =BI10+BH11 -> 185.00428 | BJ11: =+R11/BH11 -> 0.84950367 | BK11: =+S11/BI11 -> 0.93946473
A12: =A11+1 -> 45904 | B12: Napkin | C12: 15,5 | D12: =+'4'!F42 -> 830 | E12: =+'4'!G42 -> 713.8 | F12: =1-(E12/D12) -> 0.14 | G12: =+P12/N12 -> 0.91937615 | H12: =+P12/L12 -> 0.91937615 | I12: =+R12/P12 -> 0.98740592 | J12: =+R12/L12 -> 0.90779745 | K12: =+S12/M12 -> 0.89950372 | L12: =+Efficiency1!K22 -> 51.301092 | M12: =M11+L12 -> 244.99732 | N12: =+Efficiency1!C22 -> 51.301092 | O12: =O11+N12 -> 244.99732 | P12: ='4'!I38 -> 47.165 | Q12: =Q11+P12 -> 230.433 | R12: ='4'!I40 -> 46.571 | S12: =S11+R12 -> 220.376 | T12: =R12/P12 -> 0.98740592 | U12: =S12/Q12 -> 0.95635608 | V12: =R12/L12 -> 0.90779745 | W12: =S12/M12 -> 0.89950372 | AB12: 0 | AC12: =AB12+AC11 -> 0 | AD12: =AB12/P12 -> 0 | AE12: =AC12/Q12 -> 0 | AF12: =IF(AND(R12>0,AB12>0),(AB12/(R12*1000))*1000,0) -> 0 | AG12: =IF(AND(S12>0,AC12>0),AC12/S12,0) -> 0 | AH12: =+BF12+BG12 -> 110.163 | AI12: =AH12+AI11 -> 464.492 | AJ12: =AH12/(P12) -> 2.3356938 | AK12: =AI12/(Q12) -> 2.0157356 | AL12: =IF(AND(R12>0,AH12>0),AH12/(R12),0) -> 2.365485 | AM12: =IF(AND(S12>0,AI12>0),AI12/(S12),0) -> 2.107725 | AN12: 16.6 | AO12: =AN12+AO11 -> 64.2 | AP12: =AN12/(P12) -> 0.3519559 | AQ12: =AO12/(Q12) -> 0.27860593 | AR12: =IF(AND(R12>0,AN12>0),AN12/(R12),0) -> 0.356445 | AS12: =IF(AND(S12>0,AO12>0),AO12/(S12),0) -> 0.29132029 | AT12: ='4'!I46 -> 42990.48 | AU12: =AT12+AU11 -> 142934.98 | AV12: =IF(AND(L12>0,AT12>0),(AT12/(P12*1000)*1000),0) -> 911.49115 | AW12: =IF(AND(M12>0,AU12>0),(AU12/(Q12*1000)*1000),0) -> 620.28867 | AX12: =IF(AND(R12>0,AT12>0),(AT12/(R12*1000)*1000),0) -> 923.11696 | AY12: =IF(AND(S12>0,AU12>0),(AU12/(S12*1000)*1000),0) -> 648.59595 | AZ12: =+Listrik!AH11 -> 24030 | BA12: =AZ12+BA11 -> 106599 | BB12: =IF(AND(L12>0,AZ12>0),(AZ12/(P12*1000)*1000),0) -> 509.48797 | BC12: =IF(AND(M12>0,BA12>0),(BA12/(Q12*1000)*1000),0) -> 462.60301 | BD12: =IF(AND(R12>0,AZ12>0),(AZ12/(R12*1000)*1000),0) -> 515.98634 | BE12: =IF(AND(S12>0,BA12>0),(BA12/(S12*1000)*1000),0) -> 483.7142 | BF12: =2.204 -> 2.204 | BG12: 107.959 | BH12: =+Efficiency2!K22 -> 51.301092 | BI12: =BI11+BH12 -> 236.30538 | BJ12: =+R12/BH12 -> 0.90779745 | BK12: =+S12/BI12 -> 0.93258987
A13: =A12+1 -> 45905 | B13: Napkin | C13: 15,5 | D13: =+'5'!F42 -> 830 | E13: =+'5'!G42 -> 713.8 | F13: =1-(E13/D13) -> 0.14 | G13: =+P13/N13 -> 0.95001877 | H13: =+P13/L13 -> 0.95001877 | I13: =+R13/P13 -> 0.97747092 | J13: =+R13/L13 -> 0.92861572 | K13: =+S13/M13 -> 0.90454417 | L13: =+Efficiency1!K26 -> 51.301092 | M13: =M12+L13 -> 296.29841 | N13: =+Efficiency1!C26 -> 51.301092 | O13: =O12+N13 -> 296.29841 | P13: ='5'!I38 -> 48.737 | Q13: =Q12+P13 -> 279.17 | R13: ='5'!I40 -> 47.639 | S13: =S12+R13 -> 268.015 | T13: =R13/P13 -> 0.97747092 | U13: =S13/Q13 -> 0.96004227 | V13: =R13/L13 -> 0.92861572 | W13: =S13/M13 -> 0.90454417 | AB13: 0 | AC13: =AB13+AC12 -> 0 | AD13: =AB13/P13 -> 0 | AE13: =AC13/Q13 -> 0 | AF13: =IF(AND(R13>0,AB13>0),(AB13/(R13*1000))*1000,0) -> 0 | AG13: =IF(AND(S13>0,AC13>0),AC13/S13,0) -> 0 | AH13: =+BF13+BG13 -> 109.321 | AI13: =AH13+AI12 -> 573.813 | AJ13: =AH13/(P13) -> 2.2430802 | AK13: =AI13/(Q13) -> 2.055425 | AL13: =IF(AND(R13>0,AH13>0),AH13/(R13),0) -> 2.2947795 | AM13: =IF(AND(S13>0,AI13>0),AI13/(S13),0) -> 2.1409735 | AN13: 14.5 | AO13: =AN13+AO12 -> 78.7 | AP13: =AN13/(P13) -> 0.29751523 | AQ13: =AO13/(Q13) -> 0.28190708 | AR13: =IF(AND(R13>0,AN13>0),AN13/(R13),0) -> 0.30437247 | AS13: =IF(AND(S13>0,AO13>0),AO13/(S13),0) -> 0.29364028 | AT13: ='5'!I46 -> 37099.29 | AU13: =AT13+AU12 -> 180034.27 | AV13: =IF(AND(L13>0,AT13>0),(AT13/(P13*1000)*1000),0) -> 761.21407 | AW13: =IF(AND(M13>0,AU13>0),(AU13/(Q13*1000)*1000),0) -> 644.89118 | AX13: =IF(AND(R13>0,AT13>0),(AT13/(R13*1000)*1000),0) -> 778.75879 | AY13: =IF(AND(S13>0,AU13>0),(AU13/(S13*1000)*1000),0) -> 671.73207 | AZ13: =+Listrik!AH12 -> 21581 | BA13: =AZ13+BA12 -> 128180 | BB13: =IF(AND(L13>0,AZ13>0),(AZ13/(P13*1000)*1000),0) -> 442.80526 | BC13: =IF(AND(M13>0,BA13>0),(BA13/(Q13*1000)*1000),0) -> 459.14676 | BD13: =IF(AND(R13>0,AZ13>0),(AZ13/(R13*1000)*1000),0) -> 453.01119 | BE13: =IF(AND(S13>0,BA13>0),(BA13/(S13*1000)*1000),0) -> 478.25681 | BF13: =2.376 -> 2.376 | BG13: 106.945 | BH13: =+Efficiency2!K26 -> 51.301092 | BI13: =BI12+BH13 -> 287.60647 | BJ13: =+R13/BH13 -> 0.92861572 | BK13: =+S13/BI13 -> 0.93188099
A14: =A13+1 -> 45906 | B14: Napkin | C14: 15,5 | D14: =+'6'!F42 -> 830 | E14: =+'6'!G42 -> 713.8 | F14: =1-(E14/D14) -> 0.14 | G14: =+P14/N14 -> 0.93581558 | H14: =+P14/L14 -> 0.93581558 | I14: =+R14/P14 -> 0.99091531 | J14: =+R14/L14 -> 0.92731399 | K14: =+S14/M14 -> 0.9079169 | L14: =+Efficiency1!K30 -> 51.519766 | M14: =M13+L14 -> 347.81818 | N14: =+Efficiency1!C30 -> 51.519766 | O14: =O13+N14 -> 347.81818 | P14: ='6'!I38 -> 48.213 | Q14: =Q13+P14 -> 327.383 | R14: ='6'!I40 -> 47.775 | S14: =S13+R14 -> 315.79 | T14: =R14/P14 -> 0.99091531 | U14: =S14/Q14 -> 0.96458888 | V14: =R14/L14 -> 0.92731399 | W14: =S14/M14 -> 0.9079169 | AB14: 0 | AC14: =AB14+AC13 -> 0 | AD14: =AB14/P14 -> 0 | AE14: =AC14/Q14 -> 0 | AF14: =IF(AND(R14>0,AB14>0),(AB14/(R14*1000))*1000,0) -> 0 | AG14: =IF(AND(S14>0,AC14>0),AC14/S14,0) -> 0 | AH14: =+BF14+BG14 -> 109.851 | AI14: =AH14+AI13 -> 683.664 | AJ14: =AH14/(P14) -> 2.2784519 | AK14: =AI14/(Q14) -> 2.0882697 | AL14: =IF(AND(R14>0,AH14>0),AH14/(R14),0) -> 2.2993407 | AM14: =IF(AND(S14>0,AI14>0),AI14/(S14),0) -> 2.1649324 | AN14: 12.3 | AO14: =AN14+AO13 -> 91 | AP14: =AN14/(P14) -> 0.25511791 | AQ14: =AO14/(Q14) -> 0.2779619 | AR14: =IF(AND(R14>0,AN14>0),AN14/(R14),0) -> 0.25745683 | AS14: =IF(AND(S14>0,AO14>0),AO14/(S14),0) -> 0.28816619 | AT14: ='6'!I46 -> 34913.8 | AU14: =AT14+AU13 -> 214948.07 | AV14: =IF(AND(L14>0,AT14>0),(AT14/(P14*1000)*1000),0) -> 724.15738 | AW14: =IF(AND(M14>0,AU14>0),(AU14/(Q14*1000)*1000),0) -> 656.56454 | AX14: =IF(AND(R14>0,AT14>0),(AT14/(R14*1000)*1000),0) -> 730.79644 | AY14: =IF(AND(S14>0,AU14>0),(AU14/(S14*1000)*1000),0) -> 680.66775 | AZ14: =+Listrik!AH13 -> 18507 | BA14: =AZ14+BA13 -> 146687 | BB14: =IF(AND(L14>0,AZ14>0),(AZ14/(P14*1000)*1000),0) -> 383.85913 | BC14: =IF(AND(M14>0,BA14>0),(BA14/(Q14*1000)*1000),0) -> 448.05931 | BD14: =IF(AND(R14>0,AZ14>0),(AZ14/(R14*1000)*1000),0) -> 387.37834 | BE14: =IF(AND(S14>0,BA14>0),(BA14/(S14*1000)*1000),0) -> 464.50806 | BF14: =2.1 -> 2.1 | BG14: 107.751 | BH14: =+Efficiency2!K30 -> 51.519766 | BI14: =BI13+BH14 -> 339.12623 | BJ14: =+R14/BH14 -> 0.92731399 | BK14: =+S14/BI14 -> 0.93118718
A15: =A14+1 -> 45907 | B15: Napkin | C15: 16/16,5/17 | D15: =+'7'!F42 -> 830 | E15: =+'7'!G42 -> 713.8 | F15: =1-(E15/D15) -> 0.14 | G15: =+P15/N15 -> 0.89802477 | H15: =+P15/L15 -> 0.89802477 | I15: =+R15/P15 -> 0.82150335 | J15: =+R15/L15 -> 0.73773035 | K15: =+S15/M15 -> 0.88495401 | L15: =+SUM(Efficiency1!K35:K37) -> 54.250174 | M15: =M14+L15 -> 402.06835 | N15: =+SUM(Efficiency1!C35:C37) -> 54.250174 | O15: =O14+N15 -> 402.06835 | P15: ='7'!I38 -> 48.718 | Q15: =Q14+P15 -> 376.101 | R15: ='7'!I40 -> 40.022 | S15: =S14+R15 -> 355.812 | T15: =R15/P15 -> 0.82150335 | U15: =S15/Q15 -> 0.94605438 | V15: =R15/L15 -> 0.73773035 | W15: =S15/M15 -> 0.88495401 | AB15: 0 | AC15: =AB15+AC14 -> 0 | AD15: =AB15/P15 -> 0 | AE15: =AC15/Q15 -> 0 | AF15: =IF(AND(R15>0,AB15>0),(AB15/(R15*1000))*1000,0) -> 0 | AG15: =IF(AND(S15>0,AC15>0),AC15/S15,0) -> 0 | AH15: =+BF15+BG15 -> 110.38 | AI15: =AH15+AI14 -> 794.044 | AJ15: =AH15/(P15) -> 2.2656924 | AK15: =AI15/(Q15) -> 2.111252 | AL15: =IF(AND(R15>0,AH15>0),AH15/(R15),0) -> 2.7579831 | AM15: =IF(AND(S15>0,AI15>0),AI15/(S15),0) -> 2.2316392 | AN15: 15.3 | AO15: =AN15+AO14 -> 106.3 | AP15: =AN15/(P15) -> 0.3140523 | AQ15: =AO15/(Q15) -> 0.28263684 | AR15: =IF(AND(R15>0,AN15>0),AN15/(R15),0) -> 0.38228974 | AS15: =IF(AND(S15>0,AO15>0),AO15/(S15),0) -> 0.29875327 | AT15: ='7'!I46 -> 39123.47 | AU15: =AT15+AU14 -> 254071.54 | AV15: =IF(AND(L15>0,AT15>0),(AT15/(P15*1000)*1000),0) -> 803.05985 | AW15: =IF(AND(M15>0,AU15>0),(AU15/(Q15*1000)*1000),0) -> 675.54072 | AX15: =IF(AND(R15>0,AT15>0),(AT15/(R15*1000)*1000),0) -> 977.5491 | AY15: =IF(AND(S15>0,AU15>0),(AU15/(S15*1000)*1000),0) -> 714.06119 | AZ15: =+Listrik!AH14 -> 22128 | BA15: =AZ15+BA14 -> 168815 | BB15: =IF(AND(L15>0,AZ15>0),(AZ15/(P15*1000)*1000),0) -> 454.20584 | BC15: =IF(AND(M15>0,BA15>0),(BA15/(Q15*1000)*1000),0) -> 448.85549 | BD15: =IF(AND(R15>0,AZ15>0),(AZ15/(R15*1000)*1000),0) -> 552.89591 | BE15: =IF(AND(S15>0,BA15>0),(BA15/(S15*1000)*1000),0) -> 474.44999 | BF15: =2.264 -> 2.264 | BG15: 108.116 | BH15: =+SUM(Efficiency2!K35:K37) -> 54.250174 | BI15: =BI14+BH15 -> 393.37641 | BJ15: =+R15/BH15 -> 0.73773035 | BK15: =+S15/BI15 -> 0.90450773
A16: =A15+1 -> 45908 | B16: Napkin | C16: 17/19 | D16: =+'8'!F42 -> 830 | E16: =+'8'!G42 -> 713.8 | F16: =1-(E16/D16) -> 0.14 | G16: =+P16/N16 -> 0.91174907 | H16: =+P16/L16 -> 0.91174907 | I16: =+R16/P16 -> 1.0414222 | J16: =+R16/L16 -> 0.94951569 | K16: =+S16/M16 -> 0.89299409 | L16: =+SUM(Efficiency1!K40:K41) -> 57.193368 | M16: =M15+L16 -> 459.26172 | N16: =+SUM(Efficiency1!C40:C41) -> 57.193368 | O16: =O15+N16 -> 459.26172 | P16: ='8'!I38 -> 52.146 | Q16: =Q15+P16 -> 428.247 | R16: ='8'!I40 -> 54.306 | S16: =S15+R16 -> 410.118 | T16: =R16/P16 -> 1.0414222 | U16: =S16/Q16 -> 0.95766695 | V16: =R16/L16 -> 0.94951569 | W16: =S16/M16 -> 0.89299409 | AB16: 0 | AC16: =AB16+AC15 -> 0 | AD16: =AB16/P16 -> 0 | AE16: =AC16/Q16 -> 0 | AF16: =IF(AND(R16>0,AB16>0),(AB16/(R16*1000))*1000,0) -> 0 | AG16: =IF(AND(S16>0,AC16>0),AC16/S16,0) -> 0 | AH16: =+BF16+BG16 -> 116.023 | AI16: =AH16+AI15 -> 910.067 | AJ16: =AH16/(P16) -> 2.2249645 | AK16: =AI16/(Q16) -> 2.1250984 | AL16: =IF(AND(R16>0,AH16>0),AH16/(R16),0) -> 2.1364674 | AM16: =IF(AND(S16>0,AI16>0),AI16/(S16),0) -> 2.219037 | AN16: 13.6 | AO16: =AN16+AO15 -> 119.9 | AP16: =AN16/(P16) -> 0.2608062 | AQ16: =AO16/(Q16) -> 0.27997861 | AR16: =IF(AND(R16>0,AN16>0),AN16/(R16),0) -> 0.25043273 | AS16: =IF(AND(S16>0,AO16>0),AO16/(S16),0) -> 0.29235488 | AT16: ='8'!I46 -> 36533.85 | AU16: =AT16+AU15 -> 290605.39 | AV16: =IF(AND(L16>0,AT16>0),(AT16/(P16*1000)*1000),0) -> 700.60695 | AW16: =IF(AND(M16>0,AU16>0),(AU16/(Q16*1000)*1000),0) -> 678.59294 | AX16: =IF(AND(R16>0,AT16>0),(AT16/(R16*1000)*1000),0) -> 672.74058 | AY16: =IF(AND(S16>0,AU16>0),(AU16/(S16*1000)*1000),0) -> 708.5897 | AZ16: =+Listrik!AH15 -> 22105 | BA16: =AZ16+BA15 -> 190920 | BB16: =IF(AND(L16>0,AZ16>0),(AZ16/(P16*1000)*1000),0) -> 423.90596 | BC16: =IF(AND(M16>0,BA16>0),(BA16/(Q16*1000)*1000),0) -> 445.81748 | BD16: =IF(AND(R16>0,AZ16>0),(AZ16/(R16*1000)*1000),0) -> 407.04526 | BE16: =IF(AND(S16>0,BA16>0),(BA16/(S16*1000)*1000),0) -> 465.52456 | BF16: =2.857 -> 2.857 | BG16: 113.166 | BH16: =+SUM(Efficiency2!K40:K41) -> 57.193368 | BI16: =BI15+BH16 -> 450.56978 | BJ16: =+R16/BH16 -> 0.94951569 | BK16: =+S16/BI16 -> 0.91022084
A17: =A16+1 -> 45909 | B17: Napkin | C17: 19 | D17: =+'9'!F42 -> 830 | E17: =+'9'!G42 -> 713.8 | F17: =1-(E17/D17) -> 0.14 | G17: =+P17/N17 -> 0.93955571 | H17: =+P17/L17 -> 0.93955571 | I17: =+R17/P17 -> 0.95484998 | J17: =+R17/L17 -> 0.89713475 | K17: =+S17/M17 -> 0.89349628 | L17: =+Efficiency1!K45 -> 63.388471 | M17: =M16+L17 -> 522.65019 | N17: =+Efficiency1!C45 -> 63.388471 | O17: =O16+N17 -> 522.65019 | P17: ='9'!I38 -> 59.557 | Q17: =Q16+P17 -> 487.804 | R17: ='9'!I40 -> 56.868 | S17: =S16+R17 -> 466.986 | T17: =R17/P17 -> 0.95484998 | U17: =S17/Q17 -> 0.95732302 | V17: =R17/L17 -> 0.89713475 | W17: =S17/M17 -> 0.89349628 | AB17: 0 | AC17: =AB17+AC16 -> 0 | AD17: =AB17/P17 -> 0 | AE17: =AC17/Q17 -> 0 | AF17: =IF(AND(R17>0,AB17>0),(AB17/(R17*1000))*1000,0) -> 0 | AG17: =IF(AND(S17>0,AC17>0),AC17/S17,0) -> 0 | AH17: =+BF17+BG17 -> 122.304 | AI17: =AH17+AI16 -> 1032.371 | AJ17: =AH17/(P17) -> 2.0535621 | AK17: =AI17/(Q17) -> 2.1163644 | AL17: =IF(AND(R17>0,AH17>0),AH17/(R17),0) -> 2.1506647 | AM17: =IF(AND(S17>0,AI17>0),AI17/(S17),0) -> 2.2107108 | AN17: 14.5 | AO17: =AN17+AO16 -> 134.4 | AP17: =AN17/(P17) -> 0.24346424 | AQ17: =AO17/(Q17) -> 0.2755205 | AR17: =IF(AND(R17>0,AN17>0),AN17/(R17),0) -> 0.25497644 | AS17: =IF(AND(S17>0,AO17>0),AO17/(S17),0) -> 0.28780306 | AT17: ='9'!I46 -> 41643.23 | AU17: =AT17+AU16 -> 332248.62 | AV17: =IF(AND(L17>0,AT17>0),(AT17/(P17*1000)*1000),0) -> 699.21638 | AW17: =IF(AND(M17>0,AU17>0),(AU17/(Q17*1000)*1000),0) -> 681.1109 | AX17: =IF(AND(R17>0,AT17>0),(AT17/(R17*1000)*1000),0) -> 732.27879 | AY17: =IF(AND(S17>0,AU17>0),(AU17/(S17*1000)*1000),0) -> 711.47448 | AZ17: =+Listrik!AH16 -> 23014 | BA17: =AZ17+BA16 -> 213934 | BB17: =IF(AND(L17>0,AZ17>0),(AZ17/(P17*1000)*1000),0) -> 386.41973 | BC17: =IF(AND(M17>0,BA17>0),(BA17/(Q17*1000)*1000),0) -> 438.56549 | BD17: =IF(AND(R17>0,AZ17>0),(AZ17/(R17*1000)*1000),0) -> 404.69157 | BE17: =IF(AND(S17>0,BA17>0),(BA17/(S17*1000)*1000),0) -> 458.11652 | BF17: =6.248 -> 6.248 | BG17: 116.056 | BH17: =+Efficiency2!K45 -> 63.388471 | BI17: =BI16+BH17 -> 513.95825 | BJ17: =+R17/BH17 -> 0.89713475 | BK17: =+S17/BI17 -> 0.90860688
A18: =A17+1 -> 45910 | B18: Napkin | C18: 19/20 | D18: =+'10'!F42 -> 809.72222 | E18: =+'10'!G42 -> 696.36111 | F18: =1-(E18/D18) -> 0.14 | G18: =+P18/N18 -> 0.94793842 | H18: =+P18/L18 -> 0.9244268 | I18: =+R18/P18 -> 0.96312877 | J18: =+R18/L18 -> 0.89034205 | K18: =+S18/M18 -> 0.89314508 | L18: =+SUM(Efficiency1!K50:K51) -> 65.483822 | M18: =M17+L18 -> 588.13401 | N18: =+SUM(Efficiency1!C50:C51) -> 63.859633 | O18: =O17+N18 -> 586.50982 | P18: ='10'!I38 -> 60.535 | Q18: =Q17+P18 -> 548.339 | R18: ='10'!I40 -> 58.303 | S18: =S17+R18 -> 525.289 | T18: =R18/P18 -> 0.96312877 | U18: =S18/Q18 -> 0.95796396 | V18: =R18/L18 -> 0.89034205 | W18: =S18/M18 -> 0.89314508 | AB18: 0 | AC18: =AB18+AC17 -> 0 | AD18: =AB18/P18 -> 0 | AE18: =AC18/Q18 -> 0 | AF18: =IF(AND(R18>0,AB18>0),(AB18/(R18*1000))*1000,0) -> 0 | AG18: =IF(AND(S18>0,AC18>0),AC18/S18,0) -> 0 | AH18: =+BF18+BG18 -> 123.912 | AI18: =AH18+AI17 -> 1156.283 | AJ18: =AH18/(P18) -> 2.046948 | AK18: =AI18/(Q18) -> 2.108701 | AL18: =IF(AND(R18>0,AH18>0),AH18/(R18),0) -> 2.1253109 | AM18: =IF(AND(S18>0,AI18>0),AI18/(S18),0) -> 2.2012321 | AN18: 19.5 | AO18: =AN18+AO17 -> 153.9 | AP18: =AN18/(P18) -> 0.32212769 | AQ18: =AO18/(Q18) -> 0.28066579 | AR18: =IF(AND(R18>0,AN18>0),AN18/(R18),0) -> 0.33445963 | AS18: =IF(AND(S18>0,AO18>0),AO18/(S18),0) -> 0.29298158 | AT18: ='10'!I46 -> 28268.21 | AU18: =AT18+AU17 -> 360516.83 | AV18: =IF(AND(L18>0,AT18>0),(AT18/(P18*1000)*1000),0) -> 466.97299 | AW18: =IF(AND(M18>0,AU18>0),(AU18/(Q18*1000)*1000),0) -> 657.47071 | AX18: =IF(AND(R18>0,AT18>0),(AT18/(R18*1000)*1000),0) -> 484.85001 | AY18: =IF(AND(S18>0,AU18>0),(AU18/(S18*1000)*1000),0) -> 686.32092 | AZ18: =+Listrik!AH17 -> 29093 | BA18: =AZ18+BA17 -> 243027 | BB18: =IF(AND(L18>0,AZ18>0),(AZ18/(P18*1000)*1000),0) -> 480.598 | BC18: =IF(AND(M18>0,BA18>0),(BA18/(Q18*1000)*1000),0) -> 443.20575 | BD18: =IF(AND(R18>0,AZ18>0),(AZ18/(R18*1000)*1000),0) -> 498.99662 | BE18: =IF(AND(S18>0,BA18>0),(BA18/(S18*1000)*1000),0) -> 462.65389 | BF18: =6.298 -> 6.298 | BG18: 117.614 | BH18: =+SUM(Efficiency2!K50:K51) -> 65.483822 | BI18: =BI17+BH18 -> 579.44207 | BJ18: =+R18/BH18 -> 0.89034205 | BK18: =+S18/BI18 -> 0.90654274
A19: =A18+1 -> 45911 | B19: Napkin | C19: 20/15,5 | D19: =+'11'!F42 -> 825.83333 | E19: =+'11'!G42 -> 710.21667 | F19: =1-(E19/D19) -> 0.14 | G19: =+P19/N19 -> 0.87151571 | H19: =+P19/L19 -> 0.87151571 | I19: =+R19/P19 -> 0.98298858 | J19: =+R19/L19 -> 0.85668999 | K19: =+S19/M19 -> 0.89002894 | L19: =+SUM(Efficiency1!K54:K55) -> 54.972044 | M19: =M18+L19 -> 643.10605 | N19: =+SUM(Efficiency1!C54:C55) -> 54.972044 | O19: =O18+N19 -> 641.48187 | P19: ='11'!I38 -> 47.909 | Q19: =Q18+P19 -> 596.248 | R19: ='11'!I40 -> 47.094 | S19: =S18+R19 -> 572.383 | T19: =R19/P19 -> 0.98298858 | U19: =S19/Q19 -> 0.95997471 | V19: =R19/L19 -> 0.85668999 | W19: =S19/M19 -> 0.89002894 | AB19: 0 | AC19: =AB19+AC18 -> 0 | AD19: =AB19/P19 -> 0 | AE19: =AC19/Q19 -> 0 | AF19: =IF(AND(R19>0,AB19>0),(AB19/(R19*1000))*1000,0) -> 0 | AG19: =IF(AND(S19>0,AC19>0),AC19/S19,0) -> 0 | AH19: =+BF19+BG19 -> 112.045 | AI19: =AH19+AI18 -> 1268.328 | AJ19: =AH19/(P19) -> 2.3387046 | AK19: =AI19/(Q19) -> 2.127182 | AL19: =IF(AND(R19>0,AH19>0),AH19/(R19),0) -> 2.3791778 | AM19: =IF(AND(S19>0,AI19>0),AI19/(S19),0) -> 2.2158729 | AN19: 17 | AO19: =AN19+AO18 -> 170.9 | AP19: =AN19/(P19) -> 0.35483938 | AQ19: =AO19/(Q19) -> 0.2866257 | AR19: =IF(AND(R19>0,AN19>0),AN19/(R19),0) -> 0.36098017 | AS19: =IF(AND(S19>0,AO19>0),AO19/(S19),0) -> 0.2985763 | AT19: ='11'!I46 -> 38436.24 | AU19: =AT19+AU18 -> 398953.07 | AV19: =IF(AND(L19>0,AT19>0),(AT19/(P19*1000)*1000),0) -> 802.27598 | AW19: =IF(AND(M19>0,AU19>0),(AU19/(Q19*1000)*1000),0) -> 669.10593 | AX19: =IF(AND(R19>0,AT19>0),(AT19/(R19*1000)*1000),0) -> 816.16002 | AY19: =IF(AND(S19>0,AU19>0),(AU19/(S19*1000)*1000),0) -> 697.0037 | AZ19: =+Listrik!AH18 -> 25940 | BA19: =AZ19+BA18 -> 268967 | BB19: =IF(AND(L19>0,AZ19>0),(AZ19/(P19*1000)*1000),0) -> 541.44315 | BC19: =IF(AND(M19>0,BA19>0),(BA19/(Q19*1000)*1000),0) -> 451.09921 | BD19: =IF(AND(R19>0,AZ19>0),(AZ19/(R19*1000)*1000),0) -> 550.81327 | BE19: =IF(AND(S19>0,BA19>0),(BA19/(S19*1000)*1000),0) -> 469.90739 | BF19: =3.535 -> 3.535 | BG19: 108.51 | BH19: =+SUM(Efficiency2!K54:K55) -> 54.972044 | BI19: =BI18+BH19 -> 634.41411 | BJ19: =+R19/BH19 -> 0.85668999 | BK19: =+S19/BI19 -> 0.90222299
A20: =A19+1 -> 45912 | B20: Napkin | C20: 15,5 | D20: =+'12'!F42 -> 830 | E20: =+'12'!G42 -> 713.8 | F20: =1-(E20/D20) -> 0.14 | G20: =+P20/N20 -> 0.93010992 | H20: =+P20/L20 -> 0.93010992 | I20: =+R20/P20 -> 0.94912866 | J20: =+R20/L20 -> 0.88279398 | K20: =+S20/M20 -> 0.88948881 | L20: =+Efficiency1!K59 -> 51.885265 | M20: =M19+L20 -> 694.99132 | N20: =+Efficiency1!C59 -> 51.885265 | O20: =O19+N20 -> 693.36713 | P20: ='12'!I38 -> 48.259 | Q20: =Q19+P20 -> 644.507 | R20: ='12'!I40 -> 45.804 | S20: =S19+R20 -> 618.187 | T20: =R20/P20 -> 0.94912866 | U20: =S20/Q20 -> 0.95916258 | V20: =R20/L20 -> 0.88279398 | W20: =S20/M20 -> 0.88948881 | AB20: 0 | AC20: =AB20+AC19 -> 0 | AD20: =AB20/P20 -> 0 | AE20: =AC20/Q20 -> 0 | AF20: =IF(AND(R20>0,AB20>0),(AB20/(R20*1000))*1000,0) -> 0 | AG20: =IF(AND(S20>0,AC20>0),AC20/S20,0) -> 0 | AH20: =+BF20+BG20 -> 113.462 | AI20: =AH20+AI19 -> 1381.79 | AJ20: =AH20/(P20) -> 2.3511055 | AK20: =AI20/(Q20) -> 2.1439488 | AL20: =IF(AND(R20>0,AH20>0),AH20/(R20),0) -> 2.4771199 | AM20: =IF(AND(S20>0,AI20>0),AI20/(S20),0) -> 2.2352298 | AN20: 13.6 | AO20: =AN20+AO19 -> 184.5 | AP20: =AN20/(P20) -> 0.28181272 | AQ20: =AO20/(Q20) -> 0.28626532 | AR20: =IF(AND(R20>0,AN20>0),AN20/(R20),0) -> 0.2969173 | AS20: =IF(AND(S20>0,AO20>0),AO20/(S20),0) -> 0.29845338 | AT20: ='12'!I46 -> 36955.4 | AU20: =AT20+AU19 -> 435908.47 | AV20: =IF(AND(L20>0,AT20>0),(AT20/(P20*1000)*1000),0) -> 765.77219 | AW20: =IF(AND(M20>0,AU20>0),(AU20/(Q20*1000)*1000),0) -> 676.34404 | AX20: =IF(AND(R20>0,AT20>0),(AT20/(R20*1000)*1000),0) -> 806.816 | AY20: =IF(AND(S20>0,AU20>0),(AU20/(S20*1000)*1000),0) -> 705.14014 | AZ20: =+Listrik!AH19 -> 23541 | BA20: =AZ20+BA19 -> 292508 | BB20: =IF(AND(L20>0,AZ20>0),(AZ20/(P20*1000)*1000),0) -> 487.80538 | BC20: =IF(AND(M20>0,BA20>0),(BA20/(Q20*1000)*1000),0) -> 453.84767 | BD20: =IF(AND(R20>0,AZ20>0),(AZ20/(R20*1000)*1000),0) -> 513.95075 | BE20: =IF(AND(S20>0,BA20>0),(BA20/(S20*1000)*1000),0) -> 473.17074 | BF20: =3.526 -> 3.526 | BG20: 109.936 | BH20: =+Efficiency2!K59 -> 51.885265 | BI20: =BI19+BH20 -> 686.29938 | BJ20: =+R20/BH20 -> 0.88279398 | BK20: =+S20/BI20 -> 0.90075413
A21: =A20+1 -> 45913 | B21: Napkin | C21: 15,5/17 | D21: =+'13'!F42 -> 830 | E21: =+'13'!G42 -> 713.8 | F21: =1-(E21/D21) -> 0.14 | G21: =+P21/N21 -> 0.96911797 | H21: =+P21/L21 -> 0.96911797 | I21: =+R21/P21 -> 1.023667 | J21: =+R21/L21 -> 0.99205408 | K21: =+S21/M21 -> 0.89709599 | L21: =+SUM(Efficiency1!K63:K64) -> 55.6764 | M21: =M20+L21 -> 750.66772 | N21: =+SUM(Efficiency1!C63:C64) -> 55.6764 | O21: =O20+N21 -> 749.04353 | P21: ='13'!I38 -> 53.957 | Q21: =Q20+P21 -> 698.464 | R21: ='13'!I40 -> 55.234 | S21: =S20+R21 -> 673.421 | T21: =R21/P21 -> 1.023667 | U21: =S21/Q21 -> 0.96414561 | V21: =R21/L21 -> 0.99205408 | W21: =S21/M21 -> 0.89709599 | AB21: 0 | AC21: =AB21+AC20 -> 0 | AD21: =AB21/P21 -> 0 | AE21: =AC21/Q21 -> 0 | AF21: =IF(AND(R21>0,AB21>0),(AB21/(R21*1000))*1000,0) -> 0 | AG21: =IF(AND(S21>0,AC21>0),AC21/S21,0) -> 0 | AH21: =+BF21+BG21 -> 114.811 | AI21: =AH21+AI20 -> 1496.601 | AJ21: =AH21/(P21) -> 2.127824 | AK21: =AI21/(Q21) -> 2.1427031 | AL21: =IF(AND(R21>0,AH21>0),AH21/(R21),0) -> 2.0786291 | AM21: =IF(AND(S21>0,AI21>0),AI21/(S21),0) -> 2.2223854 | AN21: 16.2 | AO21: =AN21+AO20 -> 200.7 | AP21: =AN21/(P21) -> 0.30023908 | AQ21: =AO21/(Q21) -> 0.2873448 | AR21: =IF(AND(R21>0,AN21>0),AN21/(R21),0) -> 0.29329761 | AS21: =IF(AND(S21>0,AO21>0),AO21/(S21),0) -> 0.2980305 | AT21: ='13'!I46 -> 41823.79 | AU21: =AT21+AU20 -> 477732.26 | AV21: =IF(AND(L21>0,AT21>0),(AT21/(P21*1000)*1000),0) -> 775.13186 | AW21: =IF(AND(M21>0,AU21>0),(AU21/(Q21*1000)*1000),0) -> 683.97549 | AX21: =IF(AND(R21>0,AT21>0),(AT21/(R21*1000)*1000),0) -> 757.21096 | AY21: =IF(AND(S21>0,AU21>0),(AU21/(S21*1000)*1000),0) -> 709.41099 | AZ21: =+Listrik!AH20 -> 24561 | BA21: =AZ21+BA20 -> 317069 | BB21: =IF(AND(L21>0,AZ21>0),(AZ21/(P21*1000)*1000),0) -> 455.1958 | BC21: =IF(AND(M21>0,BA21>0),(BA21/(Q21*1000)*1000),0) -> 453.95181 | BD21: =IF(AND(R21>0,AZ21>0),(AZ21/(R21*1000)*1000),0) -> 444.67176 | BE21: =IF(AND(S21>0,BA21>0),(BA21/(S21*1000)*1000),0) -> 470.83325 | BF21: =2.694 -> 2.694 | BG21: 112.117 | BH21: =+SUM(Efficiency2!K63:K64) -> 55.6764 | BI21: =BI20+BH21 -> 741.97578 | BJ21: =+R21/BH21 -> 0.99205408 | BK21: =+S21/BI21 -> 0.9076051
A22: =A21+1 -> 45914 | B22: Napkin | C22: 17 | D22: =+'14'!F42 -> 830 | E22: =+'14'!G42 -> 713.8 | F22: =1-(E22/D22) -> 0.14 | G22: =+P22/N22 -> 0.90443657 | H22: =+P22/L22 -> 0.90443657 | I22: =+R22/P22 -> 0.99867752 | J22: =+R22/L22 -> 0.90324047 | K22: =+S22/M22 -> 0.89754626 | L22: =+Efficiency1!K67 -> 59.359608 | M22: =M21+L22 -> 810.02733 | N22: =+Efficiency1!C67 -> 59.359608 | O22: =O21+N22 -> 808.40314 | P22: ='14'!I38 -> 53.687 | Q22: =Q21+P22 -> 752.151 | R22: ='14'!I40 -> 53.616 | S22: =S21+R22 -> 727.037 | T22: =R22/P22 -> 0.99867752 | U22: =S22/Q22 -> 0.96661043 | V22: =R22/L22 -> 0.90324047 | W22: =S22/M22 -> 0.89754626 | AB22: 0 | AC22: =AB22+AC21 -> 0 | AD22: =AB22/P22 -> 0 | AE22: =AC22/Q22 -> 0 | AF22: =IF(AND(R22>0,AB22>0),(AB22/(R22*1000))*1000,0) -> 0 | AG22: =IF(AND(S22>0,AC22>0),AC22/S22,0) -> 0 | AH22: =+BF22+BG22 -> 117.177 | AI22: =AH22+AI21 -> 1613.778 | AJ22: =AH22/(P22) -> 2.1825954 | AK22: =AI22/(Q22) -> 2.1455506 | AL22: =IF(AND(R22>0,AH22>0),AH22/(R22),0) -> 2.1854857 | AM22: =IF(AND(S22>0,AI22>0),AI22/(S22),0) -> 2.2196642 | AN22: 13.6 | AO22: =AN22+AO21 -> 214.3 | AP22: =AN22/(P22) -> 0.25332017 | AQ22: =AO22/(Q22) -> 0.28491619 | AR22: =IF(AND(R22>0,AN22>0),AN22/(R22),0) -> 0.25365563 | AS22: =IF(AND(S22>0,AO22>0),AO22/(S22),0) -> 0.29475804 | AT22: ='14'!I46 -> 36466.51 | AU22: =AT22+AU21 -> 514198.77 | AV22: =IF(AND(L22>0,AT22>0),(AT22/(P22*1000)*1000),0) -> 679.24283 | AW22: =IF(AND(M22>0,AU22>0),(AU22/(Q22*1000)*1000),0) -> 683.63769 | AX22: =IF(AND(R22>0,AT22>0),(AT22/(R22*1000)*1000),0) -> 680.14231 | AY22: =IF(AND(S22>0,AU22>0),(AU22/(S22*1000)*1000),0) -> 707.25255 | AZ22: =+Listrik!AH21 -> 22273 | BA22: =AZ22+BA21 -> 339342 | BB22: =IF(AND(L22>0,AZ22>0),(AZ22/(P22*1000)*1000),0) -> 414.86766 | BC22: =IF(AND(M22>0,BA22>0),(BA22/(Q22*1000)*1000),0) -> 451.16207 | BD22: =IF(AND(R22>0,AZ22>0),(AZ22/(R22*1000)*1000),0) -> 415.41704 | BE22: =IF(AND(S22>0,BA22>0),(BA22/(S22*1000)*1000),0) -> 466.74653 | BF22: =2.686 -> 2.686 | BG22: 114.491 | BH22: =+Efficiency2!K67 -> 59.359608 | BI22: =BI21+BH22 -> 801.33539 | BJ22: =+R22/BH22 -> 0.90324047 | BK22: =+S22/BI22 -> 0.90728179
A23: =A22+1 -> 45915 | B23: Napkin | C23: 17/19 | D23: =+'15'!F42 -> 830 | E23: =+'15'!G42 -> 713.8 | F23: =1-(E23/D23) -> 0.14 | G23: =+P23/N23 -> 0.90825088 | H23: =+P23/L23 -> 0.90825088 | I23: =+R23/P23 -> 0.92150009 | J23: =+R23/L23 -> 0.83695326 | K23: =+S23/M23 -> 0.89319426 | L23: =+SUM(Efficiency1!K71:K72) -> 62.680919 | M23: =M22+L23 -> 872.70825 | N23: =+SUM(Efficiency1!C71:C72) -> 62.680919 | O23: =O22+N23 -> 871.08406 | P23: ='15'!I38 -> 56.93 | Q23: =Q22+P23 -> 809.081 | R23: ='15'!I40 -> 52.461 | S23: =S22+R23 -> 779.498 | T23: =R23/P23 -> 0.92150009 | U23: =S23/Q23 -> 0.96343629 | V23: =R23/L23 -> 0.83695326 | W23: =S23/M23 -> 0.89319426 | AB23: 0 | AC23: =AB23+AC22 -> 0 | AD23: =AB23/P23 -> 0 | AE23: =AC23/Q23 -> 0 | AF23: =IF(AND(R23>0,AB23>0),(AB23/(R23*1000))*1000,0) -> 0 | AG23: =IF(AND(S23>0,AC23>0),AC23/S23,0) -> 0 | AH23: =+BF23+BG23 -> 123.947 | AI23: =AH23+AI22 -> 1737.725 | AJ23: =AH23/(P23) -> 2.1771825 | AK23: =AI23/(Q23) -> 2.1477763 | AL23: =IF(AND(R23>0,AH23>0),AH23/(R23),0) -> 2.3626503 | AM23: =IF(AND(S23>0,AI23>0),AI23/(S23),0) -> 2.2292873 | AN23: 20.4 | AO23: =AN23+AO22 -> 234.7 | AP23: =AN23/(P23) -> 0.3583348 | AQ23: =AO23/(Q23) -> 0.2900822 | AR23: =IF(AND(R23>0,AN23>0),AN23/(R23),0) -> 0.3888603 | AS23: =IF(AND(S23>0,AO23>0),AO23/(S23),0) -> 0.30109122 | AT23: ='15'!I46 -> 35837.69 | AU23: =AT23+AU22 -> 550036.46 | AV23: =IF(AND(L23>0,AT23>0),(AT23/(P23*1000)*1000),0) -> 629.50448 | AW23: =IF(AND(M23>0,AU23>0),(AU23/(Q23*1000)*1000),0) -> 679.82867 | AX23: =IF(AND(R23>0,AT23>0),(AT23/(R23*1000)*1000),0) -> 683.13013 | AY23: =IF(AND(S23>0,AU23>0),(AU23/(S23*1000)*1000),0) -> 705.62908 | AZ23: =+Listrik!AH22 -> 32172 | BA23: =AZ23+BA22 -> 371514 | BB23: =IF(AND(L23>0,AZ23>0),(AZ23/(P23*1000)*1000),0) -> 565.11505 | BC23: =IF(AND(M23>0,BA23>0),(BA23/(Q23*1000)*1000),0) -> 459.18023 | BD23: =IF(AND(R23>0,AZ23>0),(AZ23/(R23*1000)*1000),0) -> 613.25556 | BE23: =IF(AND(S23>0,BA23>0),(BA23/(S23*1000)*1000),0) -> 476.60674 | BF23: =7.403 -> 7.403 | BG23: 116.544 | BH23: =+SUM(Efficiency2!K71:K72) -> 62.680919 | BI23: =BI22+BH23 -> 864.01631 | BJ23: =+R23/BH23 -> 0.83695326 | BK23: =+S23/BI23 -> 0.90217973
A24: =A23+1 -> 45916 | B24: Napkin/Towel | C24: 19/19 | D24: =+'16'!F42 -> 830 | E24: =+'16'!G42 -> 713.8 | F24: =1-(E24/D24) -> 0.14 | G24: =+P24/N24 -> 0.93640452 | H24: =+P24/L24 -> 0.93640452 | I24: =+R24/P24 -> 1.0170343 | J24: =+R24/L24 -> 0.95235547 | K24: =+S24/M24 -> 0.89726274 | L24: =+SUM(Efficiency1!K77:K78) -> 64.447574 | M24: =M23+L24 -> 937.15582 | N24: =+SUM(Efficiency1!C77:C78) -> 64.447574 | O24: =O23+N24 -> 935.53163 | P24: ='16'!I38 -> 60.349 | Q24: =Q23+P24 -> 869.43 | R24: ='16'!I40 -> 61.377 | S24: =S23+R24 -> 840.875 | T24: =R24/P24 -> 1.0170343 | U24: =S24/Q24 -> 0.96715664 | V24: =R24/L24 -> 0.95235547 | W24: =S24/M24 -> 0.89726274 | AB24: 0 | AC24: =AB24+AC23 -> 0 | AD24: =AB24/P24 -> 0 | AE24: =AC24/Q24 -> 0 | AF24: =IF(AND(R24>0,AB24>0),(AB24/(R24*1000))*1000,0) -> 0 | AG24: =IF(AND(S24>0,AC24>0),AC24/S24,0) -> 0 | AH24: =+BF24+BG24 -> 123.711 | AI24: =AH24+AI23 -> 1861.436 | AJ24: =AH24/(P24) -> 2.0499263 | AK24: =AI24/(Q24) -> 2.1409843 | AL24: =IF(AND(R24>0,AH24>0),AH24/(R24),0) -> 2.0155922 | AM24: =IF(AND(S24>0,AI24>0),AI24/(S24),0) -> 2.2136893 | AN24: 20.4 | AO24: =AN24+AO23 -> 255.1 | AP24: =AN24/(P24) -> 0.33803377 | AQ24: =AO24/(Q24) -> 0.29341063 | AR24: =IF(AND(R24>0,AN24>0),AN24/(R24),0) -> 0.33237206 | AS24: =IF(AND(S24>0,AO24>0),AO24/(S24),0) -> 0.30337446 | AT24: ='16'!I46 -> 36230.23 | AU24: =AT24+AU23 -> 586266.69 | AV24: =IF(AND(L24>0,AT24>0),(AT24/(P24*1000)*1000),0) -> 600.34516 | AW24: =IF(AND(M24>0,AU24>0),(AU24/(Q24*1000)*1000),0) -> 674.31155 | AX24: =IF(AND(R24>0,AT24>0),(AT24/(R24*1000)*1000),0) -> 590.29001 | AY24: =IF(AND(S24>0,AU24>0),(AU24/(S24*1000)*1000),0) -> 697.21028 | AZ24: =+Listrik!AH23 -> 29325 | BA24: =AZ24+BA23 -> 400839 | BB24: =IF(AND(L24>0,AZ24>0),(AZ24/(P24*1000)*1000),0) -> 485.92354 | BC24: =IF(AND(M24>0,BA24>0),(BA24/(Q24*1000)*1000),0) -> 461.03654 | BD24: =IF(AND(R24>0,AZ24>0),(AZ24/(R24*1000)*1000),0) -> 477.78484 | BE24: =IF(AND(S24>0,BA24>0),(BA24/(S24*1000)*1000),0) -> 476.69273 | BF24: =8.994 -> 8.994 | BG24: 114.717 | BH24: =+SUM(Efficiency2!K77:K78) -> 64.447574 | BI24: =BI23+BH24 -> 928.46388 | BJ24: =+R24/BH24 -> 0.95235547 | BK24: =+S24/BI24 -> 0.90566259
A25: =A24+1 -> 45917 | B25: Towel/Napkin | C25: 19/21/25 | D25: =+'17'!F42 -> 713.15972 | E25: =+'17'!G42 -> 613.31736 | F25: =1-(E25/D25) -> 0.14 | G25: =+P25/N25 -> 0.9942044 | H25: =+P25/L25 -> 0.99176047 | I25: =+R25/P25 -> 0.98519296 | J25: =+R25/L25 -> 0.97707543 | K25: =+S25/M25 -> 0.90260877 | L25: =+SUM(Efficiency1!K82:K84) -> 67.27935 | M25: =M24+L25 -> 1004.4352 | N25: =+SUM(Efficiency1!C82:C84) -> 67.113966 | O25: =O24+N25 -> 1002.6456 | P25: ='17'!I38 -> 66.725 | Q25: =Q24+P25 -> 936.155 | R25: ='17'!I40 -> 65.737 | S25: =S24+R25 -> 906.612 | T25: =R25/P25 -> 0.98519296 | U25: =S25/Q25 -> 0.96844219 | V25: =R25/L25 -> 0.97707543 | W25: =S25/M25 -> 0.90260877 | AB25: 0 | AC25: =AB25+AC24 -> 0 | AD25: =AB25/P25 -> 0 | AE25: =AC25/Q25 -> 0 | AF25: =IF(AND(R25>0,AB25>0),(AB25/(R25*1000))*1000,0) -> 0 | AG25: =IF(AND(S25>0,AC25>0),AC25/S25,0) -> 0 | AH25: =+BF25+BG25 -> 122.557 | AI25: =AH25+AI24 -> 1983.993 | AJ25: =AH25/(P25) -> 1.8367478 | AK25: =AI25/(Q25) -> 2.1192997 | AL25: =IF(AND(R25>0,AH25>0),AH25/(R25),0) -> 1.8643534 | AM25: =IF(AND(S25>0,AI25>0),AI25/(S25),0) -> 2.1883595 | AN25: 20.4 | AO25: =AN25+AO24 -> 275.5 | AP25: =AN25/(P25) -> 0.30573248 | AQ25: =AO25/(Q25) -> 0.29428887 | AR25: =IF(AND(R25>0,AN25>0),AN25/(R25),0) -> 0.31032752 | AS25: =IF(AND(S25>0,AO25>0),AO25/(S25),0) -> 0.30387862 | AT25: ='17'!I46 -> 34377.08 | AU25: =AT25+AU24 -> 620643.77 | AV25: =IF(AND(L25>0,AT25>0),(AT25/(P25*1000)*1000),0) -> 515.2054 | AW25: =IF(AND(M25>0,AU25>0),(AU25/(Q25*1000)*1000),0) -> 662.97116 | AX25: =IF(AND(R25>0,AT25>0),(AT25/(R25*1000)*1000),0) -> 522.94872 | AY25: =IF(AND(S25>0,AU25>0),(AU25/(S25*1000)*1000),0) -> 684.57485 | AZ25: =+Listrik!AH24 -> 30704 | BA25: =AZ25+BA24 -> 431543 | BB25: =IF(AND(L25>0,AZ25>0),(AZ25/(P25*1000)*1000),0) -> 460.15736 | BC25: =IF(AND(M25>0,BA25>0),(BA25/(Q25*1000)*1000),0) -> 460.97388 | BD25: =IF(AND(R25>0,AZ25>0),(AZ25/(R25*1000)*1000),0) -> 467.07334 | BE25: =IF(AND(S25>0,BA25>0),(BA25/(S25*1000)*1000),0) -> 475.99524 | BF25: =9.263 -> 9.263 | BG25: 113.294 | BH25: =+SUM(Efficiency2!K82:K84) -> 67.610235 | BI25: =BI24+BH25 -> 996.07411 | BJ25: =+R25/BH25 -> 0.97229362 | BK25: =+S25/BI25 -> 0.91018528
A26: =A25+1 -> 45918 | B26: Napkin/Towel | C26: 25/36 | D26: =+'18'!F42 -> 431.85039 | E26: =+'18'!G42 -> 379.97559 | F26: =1-(E26/D26) -> 0.12012216 | G26: =+P26/N26 -> 0.86121293 | H26: =+P26/L26 -> 0.86121293 | I26: =+R26/P26 -> 0.97836795 | J26: =+R26/L26 -> 0.84258313 | K26: =+S26/M26 -> 0.8988332 | L26: =+SUM(Efficiency1!K87:K88) -> 67.418867 | M26: =M25+L26 -> 1071.854 | N26: =+SUM(Efficiency1!C87:C88) -> 67.418867 | O26: =O25+N26 -> 1070.0645 | P26: ='18'!I38 -> 58.062 | Q26: =Q25+P26 -> 994.217 | R26: ='18'!I40 -> 56.806 | S26: =S25+R26 -> 963.418 | T26: =R26/P26 -> 0.97836795 | U26: =S26/Q26 -> 0.96902185 | V26: =R26/L26 -> 0.84258313 | W26: =S26/M26 -> 0.8988332 | AB26: 0 | AC26: =AB26+AC25 -> 0 | AD26: =AB26/P26 -> 0 | AE26: =AC26/Q26 -> 0 | AF26: =IF(AND(R26>0,AB26>0),(AB26/(R26*1000))*1000,0) -> 0 | AG26: =IF(AND(S26>0,AC26>0),AC26/S26,0) -> 0 | AH26: =+BF26+BG26 -> 103.283 | AI26: =AH26+AI25 -> 2087.276 | AJ26: =AH26/(P26) -> 1.7788399 | AK26: =AI26/(Q26) -> 2.0994169 | AL26: =IF(AND(R26>0,AH26>0),AH26/(R26),0) -> 1.8181706 | AM26: =IF(AND(S26>0,AI26>0),AI26/(S26),0) -> 2.1665321 | AN26: 19.2 | AO26: =AN26+AO25 -> 294.7 | AP26: =AN26/(P26) -> 0.330681 | AQ26: =AO26/(Q26) -> 0.29641416 | AR26: =IF(AND(R26>0,AN26>0),AN26/(R26),0) -> 0.33799247 | AS26: =IF(AND(S26>0,AO26>0),AO26/(S26),0) -> 0.30589007 | AT26: ='18'!I46 -> 27286.69 | AU26: =AT26+AU25 -> 647930.46 | AV26: =IF(AND(L26>0,AT26>0),(AT26/(P26*1000)*1000),0) -> 469.9578 | AW26: =IF(AND(M26>0,AU26>0),(AU26/(Q26*1000)*1000),0) -> 651.69924 | AX26: =IF(AND(R26>0,AT26>0),(AT26/(R26*1000)*1000),0) -> 480.34873 | AY26: =IF(AND(S26>0,AU26>0),(AU26/(S26*1000)*1000),0) -> 672.53306 | AZ26: =+Listrik!AH25 -> 30984 | BA26: =AZ26+BA25 -> 462527 | BB26: =IF(AND(L26>0,AZ26>0),(AZ26/(P26*1000)*1000),0) -> 533.63646 | BC26: =IF(AND(M26>0,BA26>0),(BA26/(Q26*1000)*1000),0) -> 465.21735 | BD26: =IF(AND(R26>0,AZ26>0),(AZ26/(R26*1000)*1000),0) -> 545.43534 | BE26: =IF(AND(S26>0,BA26>0),(BA26/(S26*1000)*1000),0) -> 480.08964 | BF26: =13.891 -> 13.891 | BG26: 89.392 | BH26: =+SUM(Efficiency2!K87:K88) -> 67.418867 | BI26: =BI25+BH26 -> 1063.493 | BJ26: =+R26/BH26 -> 0.84258313 | BK26: =+S26/BI26 -> 0.90589973
A27: =A26+1 -> 45919 | B27: Towel | C27: 36/37,5 | D27: =+'19'!F42 -> 432.98611 | E27: =+'19'!G42 -> 381.02778 | F27: =1-(E27/D27) -> 0.12 | G27: =+P27/N27 -> 1.0069411 | H27: =+P27/L27 -> 0.97214946 | I27: =+R27/P27 -> 0.97395603 | J27: =+R27/L27 -> 0.94683083 | K27: =+S27/M27 -> 0.90167364 | L27: =+SUM(Efficiency1!K93:K94) -> 67.420703 | M27: =M26+L27 -> 1139.2747 | N27: =+SUM(Efficiency1!C93:C94) -> 65.091193 | O27: =O26+N27 -> 1135.1557 | P27: ='19'!I38 -> 65.543 | Q27: =Q26+P27 -> 1059.76 | R27: ='19'!I40 -> 63.836 | S27: =S26+R27 -> 1027.254 | T27: =R27/P27 -> 0.97395603 | U27: =S27/Q27 -> 0.96932702 | V27: =R27/L27 -> 0.94683083 | W27: =S27/M27 -> 0.90167364 | AB27: 0 | AC27: =AB27+AC26 -> 0 | AD27: =AB27/P27 -> 0 | AE27: =AC27/Q27 -> 0 | AF27: =IF(AND(R27>0,AB27>0),(AB27/(R27*1000))*1000,0) -> 0 | AG27: =IF(AND(S27>0,AC27>0),AC27/S27,0) -> 0 | AH27: =+BF27+BG27 -> 103.564 | AI27: =AH27+AI26 -> 2190.84 | AJ27: =AH27/(P27) -> 1.5800925 | AK27: =AI27/(Q27) -> 2.0672983 | AL27: =IF(AND(R27>0,AH27>0),AH27/(R27),0) -> 1.6223448 | AM27: =IF(AND(S27>0,AI27>0),AI27/(S27),0) -> 2.132715 | AN27: 19.2 | AO27: =AN27+AO26 -> 313.9 | AP27: =AN27/(P27) -> 0.29293746 | AQ27: =AO27/(Q27) -> 0.29619914 | AR27: =IF(AND(R27>0,AN27>0),AN27/(R27),0) -> 0.30077072 | AS27: =IF(AND(S27>0,AO27>0),AO27/(S27),0) -> 0.30557194 | AT27: ='19'!I46 -> 30474.55 | AU27: =AT27+AU26 -> 678405.01 | AV27: =IF(AND(L27>0,AT27>0),(AT27/(P27*1000)*1000),0) -> 464.95507 | AW27: =IF(AND(M27>0,AU27>0),(AU27/(Q27*1000)*1000),0) -> 640.14967 | AX27: =IF(AND(R27>0,AT27>0),(AT27/(R27*1000)*1000),0) -> 477.38815 | AY27: =IF(AND(S27>0,AU27>0),(AU27/(S27*1000)*1000),0) -> 660.4063 | AZ27: =+Listrik!AH26 -> 30624 | BA27: =AZ27+BA26 -> 493151 | BB27: =IF(AND(L27>0,AZ27>0),(AZ27/(P27*1000)*1000),0) -> 467.23525 | BC27: =IF(AND(M27>0,BA27>0),(BA27/(Q27*1000)*1000),0) -> 465.34215 | BD27: =IF(AND(R27>0,AZ27>0),(AZ27/(R27*1000)*1000),0) -> 479.72931 | BE27: =IF(AND(S27>0,BA27>0),(BA27/(S27*1000)*1000),0) -> 480.06725 | BF27: =8.625 -> 8.625 | BG27: 94.939 | BH27: =+SUM(Efficiency2!K93:K94) -> 67.420703 | BI27: =BI26+BH27 -> 1130.9137 | BJ27: =+R27/BH27 -> 0.94683083 | BK27: =+S27/BI27 -> 0.90833988
A28: =A27+1 -> 45920 | B28: Towel | C28: 37,5/38 | D28: =+'20'!F42 -> 423.57639 | E28: =+'20'!G42 -> 372.74722 | F28: =1-(E28/D28) -> 0.12 | G28: =+P28/N28 -> 1.0185433 | H28: =+P28/L28 -> 0.99532336 | I28: =+R28/P28 -> 0.99634908 | J28: =+R28/L28 -> 0.99168952 | K28: =+S28/M28 -> 0.90658664 | L28: =+SUM(Efficiency1!K97:K98) -> 65.770585 | M28: =M27+L28 -> 1205.0453 | N28: =+SUM(Efficiency1!C97:C98) -> 64.271203 | O28: =O27+N28 -> 1199.4269 | P28: ='20'!I38 -> 65.463 | Q28: =Q27+P28 -> 1125.223 | R28: ='20'!I40 -> 65.224 | S28: =S27+R28 -> 1092.478 | T28: =R28/P28 -> 0.99634908 | U28: =S28/Q28 -> 0.9708991 | V28: =R28/L28 -> 0.99168952 | W28: =S28/M28 -> 0.90658664 | AB28: 0 | AC28: =AB28+AC27 -> 0 | AD28: =AB28/P28 -> 0 | AE28: =AC28/Q28 -> 0 | AF28: =IF(AND(R28>0,AB28>0),(AB28/(R28*1000))*1000,0) -> 0 | AG28: =IF(AND(S28>0,AC28>0),AC28/S28,0) -> 0 | AH28: =+BF28+BG28 -> 106.863 | AI28: =AH28+AI27 -> 2297.703 | AJ28: =AH28/(P28) -> 1.6324183 | AK28: =AI28/(Q28) -> 2.0419979 | AL28: =IF(AND(R28>0,AH28>0),AH28/(R28),0) -> 1.6384 | AM28: =IF(AND(S28>0,AI28>0),AI28/(S28),0) -> 2.103203 | AN28: 19.2 | AO28: =AN28+AO27 -> 333.1 | AP28: =AN28/(P28) -> 0.29329545 | AQ28: =AO28/(Q28) -> 0.29603021 | AR28: =IF(AND(R28>0,AN28>0),AN28/(R28),0) -> 0.29437017 | AS28: =IF(AND(S28>0,AO28>0),AO28/(S28),0) -> 0.30490317 | AT28: ='20'!I46 -> 31571.82 | AU28: =AT28+AU27 -> 709976.83 | AV28: =IF(AND(L28>0,AT28>0),(AT28/(P28*1000)*1000),0) -> 482.28495 | AW28: =IF(AND(M28>0,AU28>0),(AU28/(Q28*1000)*1000),0) -> 630.96544 | AX28: =IF(AND(R28>0,AT28>0),(AT28/(R28*1000)*1000),0) -> 484.05219 | AY28: =IF(AND(S28>0,AU28>0),(AU28/(S28*1000)*1000),0) -> 649.87746 | AZ28: =+Listrik!AH27 -> 31607 | BA28: =AZ28+BA27 -> 524758 | BB28: =IF(AND(L28>0,AZ28>0),(AZ28/(P28*1000)*1000),0) -> 482.82236 | BC28: =IF(AND(M28>0,BA28>0),(BA28/(Q28*1000)*1000),0) -> 466.35911 | BD28: =IF(AND(R28>0,AZ28>0),(AZ28/(R28*1000)*1000),0) -> 484.59156 | BE28: =IF(AND(S28>0,BA28>0),(BA28/(S28*1000)*1000),0) -> 480.33736 | BF28: =9.321 -> 9.321 | BG28: 97.542 | BH28: =+SUM(Efficiency2!K97:K98) -> 65.770585 | BI28: =BI27+BH28 -> 1196.6843 | BJ28: =+R28/BH28 -> 0.99168952 | BK28: =+S28/BI28 -> 0.91292083
A29: =A28+1 -> 45921 | B29: Towel | C29: 37,5/38/35 | D29: =+'21'!F42 -> 428 | E29: =+'21'!G42 -> 376.64 | F29: =1-(E29/D29) -> 0.12 | G29: =+P29/N29 -> 1.0301224 | H29: =+P29/L29 -> 1.0012504 | I29: =+R29/P29 -> 0.98512323 | J29: =+R29/L29 -> 0.986355 | K29: =+S29/M29 -> 0.91078019 | L29: =+SUM(Efficiency1!K101:K103) -> 66.866392 | M29: =M28+L29 -> 1271.9117 | N29: =+SUM(Efficiency1!C101:C103) -> 64.992277 | O29: =O28+N29 -> 1264.4191 | P29: ='21'!I38 -> 66.95 | Q29: =Q28+P29 -> 1192.173 | R29: ='21'!I40 -> 65.954 | S29: =S28+R29 -> 1158.432 | T29: =R29/P29 -> 0.98512323 | U29: =S29/Q29 -> 0.9716979 | V29: =R29/L29 -> 0.986355 | W29: =S29/M29 -> 0.91078019 | AB29: 0 | AC29: =AB29+AC28 -> 0 | AD29: =AB29/P29 -> 0 | AE29: =AC29/Q29 -> 0 | AF29: =IF(AND(R29>0,AB29>0),(AB29/(R29*1000))*1000,0) -> 0 | AG29: =IF(AND(S29>0,AC29>0),AC29/S29,0) -> 0 | AH29: =+BF29+BG29 -> 103.867 | AI29: =AH29+AI28 -> 2401.57 | AJ29: =AH29/(P29) -> 1.5514115 | AK29: =AI29/(Q29) -> 2.0144476 | AL29: =IF(AND(R29>0,AH29>0),AH29/(R29),0) -> 1.57484 | AM29: =IF(AND(S29>0,AI29>0),AI29/(S29),0) -> 2.0731213 | AN29: 19 | AO29: =AN29+AO28 -> 352.1 | AP29: =AN29/(P29) -> 0.28379388 | AQ29: =AO29/(Q29) -> 0.29534304 | AR29: =IF(AND(R29>0,AN29>0),AN29/(R29),0) -> 0.28807957 | AS29: =IF(AND(S29>0,AO29>0),AO29/(S29),0) -> 0.30394533 | AT29: ='21'!I46 -> 32204.82 | AU29: =AT29+AU28 -> 742181.65 | AV29: =IF(AND(L29>0,AT29>0),(AT29/(P29*1000)*1000),0) -> 481.02793 | AW29: =IF(AND(M29>0,AU29>0),(AU29/(Q29*1000)*1000),0) -> 622.54526 | AX29: =IF(AND(R29>0,AT29>0),(AT29/(R29*1000)*1000),0) -> 488.29214 | AY29: =IF(AND(S29>0,AU29>0),(AU29/(S29*1000)*1000),0) -> 640.67779 | AZ29: =+Listrik!AH28 -> 30826 | BA29: =AZ29+BA28 -> 555584 | BB29: =IF(AND(L29>0,AZ29>0),(AZ29/(P29*1000)*1000),0) -> 460.43316 | BC29: =IF(AND(M29>0,BA29>0),(BA29/(Q29*1000)*1000),0) -> 466.02632 | BD29: =IF(AND(R29>0,AZ29>0),(AZ29/(R29*1000)*1000),0) -> 467.38636 | BE29: =IF(AND(S29>0,BA29>0),(BA29/(S29*1000)*1000),0) -> 479.60001 | BF29: =8.747 -> 8.747 | BG29: 95.12 | BH29: =+SUM(Efficiency2!K101:K103) -> 66.866392 | BI29: =BI28+BH29 -> 1263.5507 | BJ29: =+R29/BH29 -> 0.986355 | BK29: =+S29/BI29 -> 0.91680693
A30: =A29+1 -> 45922 | B30: Towel | C30: 35/34 | D30: =+'22'!F42 -> 462.5 | E30: =+'22'!G42 -> 407 | F30: =1-(E30/D30) -> 0.12 | G30: =+P30/N30 -> 0.90397573 | H30: =+P30/L30 -> 0.89430301 | I30: =+R30/P30 -> 0.98115409 | J30: =+R30/L30 -> 0.87744905 | K30: =+S30/M30 -> 0.90908735 | L30: =+SUM(Efficiency1!K106:K107) -> 68.055233 | M30: =M29+L30 -> 1339.967 | N30: =+SUM(Efficiency1!C106:C107) -> 67.327029 | O30: =O29+N30 -> 1331.7462 | P30: ='22'!I38 -> 60.862 | Q30: =Q29+P30 -> 1253.035 | R30: ='22'!I40 -> 59.715 | S30: =S29+R30 -> 1218.147 | T30: =R30/P30 -> 0.98115409 | U30: =S30/Q30 -> 0.9721572 | V30: =R30/L30 -> 0.87744905 | W30: =S30/M30 -> 0.90908735 | AB30: 0 | AC30: =AB30+AC29 -> 0 | AD30: =AB30/P30 -> 0 | AE30: =AC30/Q30 -> 0 | AF30: =IF(AND(R30>0,AB30>0),(AB30/(R30*1000))*1000,0) -> 0 | AG30: =IF(AND(S30>0,AC30>0),AC30/S30,0) -> 0 | AH30: =+BF30+BG30 -> 110.496 | AI30: =AH30+AI29 -> 2512.066 | AJ30: =AH30/(P30) -> 1.8155171 | AK30: =AI30/(Q30) -> 2.0047852 | AL30: =IF(AND(R30>0,AH30>0),AH30/(R30),0) -> 1.8503893 | AM30: =IF(AND(S30>0,AI30>0),AI30/(S30),0) -> 2.0622027 | AN30: 19.2 | AO30: =AN30+AO29 -> 371.3 | AP30: =AN30/(P30) -> 0.31546778 | AQ30: =AO30/(Q30) -> 0.29632053 | AR30: =IF(AND(R30>0,AN30>0),AN30/(R30),0) -> 0.32152725 | AS30: =IF(AND(S30>0,AO30>0),AO30/(S30),0) -> 0.30480722 | AT30: ='22'!I46 -> 29536.63 | AU30: =AT30+AU29 -> 771718.28 | AV30: =IF(AND(L30>0,AT30>0),(AT30/(P30*1000)*1000),0) -> 485.30495 | AW30: =IF(AND(M30>0,AU30>0),(AU30/(Q30*1000)*1000),0) -> 615.87927 | AX30: =IF(AND(R30>0,AT30>0),(AT30/(R30*1000)*1000),0) -> 494.62664 | AY30: =IF(AND(S30>0,AU30>0),(AU30/(S30*1000)*1000),0) -> 633.51819 | AZ30: =+Listrik!AH29 -> 32511 | BA30: =AZ30+BA29 -> 588095 | BB30: =IF(AND(L30>0,AZ30>0),(AZ30/(P30*1000)*1000),0) -> 534.17568 | BC30: =IF(AND(M30>0,BA30>0),(BA30/(Q30*1000)*1000),0) -> 469.33645 | BD30: =IF(AND(R30>0,AZ30>0),(AZ30/(R30*1000)*1000),0) -> 544.43607 | BE30: =IF(AND(S30>0,BA30>0),(BA30/(S30*1000)*1000),0) -> 482.77835 | BF30: =11.785 -> 11.785 | BG30: 98.711 | BH30: =+SUM(Efficiency2!K106:K107) -> 68.055233 | BI30: =BI29+BH30 -> 1331.6059 | BJ30: =+R30/BH30 -> 0.87744905 | BK30: =+S30/BI30 -> 0.91479544
A31: =A30+1 -> 45923 | B31: Towel | C31: 34/33,5 | D31: =+'23'!F42 -> 475.48611 | E31: =+'23'!G42 -> 418.42778 | F31: =1-(E31/D31) -> 0.12 | G31: =+P31/N31 -> 1.0195275 | H31: =+P31/L31 -> 1.0094367 | I31: =+R31/P31 -> 0.95424309 | J31: =+R31/L31 -> 0.96324801 | K31: =+S31/M31 -> 0.91163977 | L31: =+SUM(Efficiency1!K112:K113) -> 66.271614 | M31: =M30+L31 -> 1406.2386 | N31: =+SUM(Efficiency1!C112:C113) -> 65.615688 | O31: =O30+N31 -> 1397.3619 | P31: ='23'!I38 -> 66.897 | Q31: =Q30+P31 -> 1319.932 | R31: ='23'!I40 -> 63.836 | S31: =S30+R31 -> 1281.983 | T31: =R31/P31 -> 0.95424309 | U31: =S31/Q31 -> 0.97124928 | V31: =R31/L31 -> 0.96324801 | W31: =S31/M31 -> 0.91163977 | AB31: 0 | AC31: =AB31+AC30 -> 0 | AD31: =AB31/P31 -> 0 | AE31: =AC31/Q31 -> 0 | AF31: =IF(AND(R31>0,AB31>0),(AB31/(R31*1000))*1000,0) -> 0 | AG31: =IF(AND(S31>0,AC31>0),AC31/S31,0) -> 0 | AH31: =+BF31+BG31 -> 139.111 | AI31: =AH31+AI30 -> 2651.177 | AJ31: =AH31/(P31) -> 2.0794804 | AK31: =AI31/(Q31) -> 2.0085709 | AL31: =IF(AND(R31>0,AH31>0),AH31/(R31),0) -> 2.1791936 | AM31: =IF(AND(S31>0,AI31>0),AI31/(S31),0) -> 2.0680282 | AN31: 19.5 | AO31: =AN31+AO30 -> 390.8 | AP31: =AN31/(P31) -> 0.29149289 | AQ31: =AO31/(Q31) -> 0.29607586 | AR31: =IF(AND(R31>0,AN31>0),AN31/(R31),0) -> 0.30547027 | AS31: =IF(AND(S31>0,AO31>0),AO31/(S31),0) -> 0.30484024 | AT31: ='23'!I46 -> 32669.65 | AU31: =AT31+AU30 -> 804387.93 | AV31: =IF(AND(L31>0,AT31>0),(AT31/(P31*1000)*1000),0) -> 488.35747 | AW31: =IF(AND(M31>0,AU31>0),(AU31/(Q31*1000)*1000),0) -> 609.41619 | AX31: =IF(AND(R31>0,AT31>0),(AT31/(R31*1000)*1000),0) -> 511.7747 | AY31: =IF(AND(S31>0,AU31>0),(AU31/(S31*1000)*1000),0) -> 627.456 | AZ31: =+Listrik!AH30 -> 30551 | BA31: =AZ31+BA30 -> 618646 | BB31: =IF(AND(L31>0,AZ31>0),(AZ31/(P31*1000)*1000),0) -> 456.68715 | BC31: =IF(AND(M31>0,BA31>0),(BA31/(Q31*1000)*1000),0) -> 468.69536 | BD31: =IF(AND(R31>0,AZ31>0),(AZ31/(R31*1000)*1000),0) -> 478.58575 | BE31: =IF(AND(S31>0,BA31>0),(BA31/(S31*1000)*1000),0) -> 482.56958 | BF31: =32.183 -> 32.183 | BG31: 106.928 | BH31: =+SUM(Efficiency2!K112:K113) -> 66.271614 | BI31: =BI30+BH31 -> 1397.8775 | BJ31: =+R31/BH31 -> 0.96324801 | BK31: =+S31/BI31 -> 0.91709251
A32: =A31+1 -> 45924 | B32: Towel | C32: 33,5/31,5 | D32: =+'24'!F42 -> 497.3125 | E32: =+'24'!G42 -> 437.635 | F32: =1-(E32/D32) -> 0.12 | G32: =+P32/N32 -> 0.90225012 | H32: =+P32/L32 -> 0.89966714 | I32: =+R32/P32 -> 0.97197028 | J32: =+R32/L32 -> 0.87444972 | K32: =+S32/M32 -> 0.90992988 | L32: =+SUM(Efficiency1!K117:K118) -> 67.77062 | M32: =M31+L32 -> 1474.0092 | N32: =+SUM(Efficiency1!C117:C118) -> 67.576605 | O32: =O31+N32 -> 1464.9385 | P32: ='24'!I38 -> 60.971 | Q32: =Q31+P32 -> 1380.903 | R32: ='24'!I40 -> 59.262 | S32: =S31+R32 -> 1341.245 | T32: =R32/P32 -> 0.97197028 | U32: =S32/Q32 -> 0.97128111 | V32: =R32/L32 -> 0.87444972 | W32: =S32/M32 -> 0.90992988 | AB32: 0 | AC32: =AB32+AC31 -> 0 | AD32: =AB32/P32 -> 0 | AE32: =AC32/Q32 -> 0 | AF32: =IF(AND(R32>0,AB32>0),(AB32/(R32*1000))*1000,0) -> 0 | AG32: =IF(AND(S32>0,AC32>0),AC32/S32,0) -> 0 | AH32: =+BF32+BG32 -> 133.193 | AI32: =AH32+AI31 -> 2784.37 | AJ32: =AH32/(P32) -> 2.1845304 | AK32: =AI32/(Q32) -> 2.01634 | AL32: =IF(AND(R32>0,AH32>0),AH32/(R32),0) -> 2.2475279 | AM32: =IF(AND(S32>0,AI32>0),AI32/(S32),0) -> 2.0759593 | AN32: 16.8 | AO32: =AN32+AO31 -> 407.6 | AP32: =AN32/(P32) -> 0.27554083 | AQ32: =AO32/(Q32) -> 0.29516918 | AR32: =IF(AND(R32>0,AN32>0),AN32/(R32),0) -> 0.28348689 | AS32: =IF(AND(S32>0,AO32>0),AO32/(S32),0) -> 0.30389675 | AT32: =+'24'!I46 -> 30165.65 | AU32: =AT32+AU31 -> 834553.58 | AV32: =IF(AND(L32>0,AT32>0),(AT32/(P32*1000)*1000),0) -> 494.75406 | AW32: =IF(AND(M32>0,AU32>0),(AU32/(Q32*1000)*1000),0) -> 604.35351 | AX32: =IF(AND(R32>0,AT32>0),(AT32/(R32*1000)*1000),0) -> 509.0218 | AY32: =IF(AND(S32>0,AU32>0),(AU32/(S32*1000)*1000),0) -> 622.22307 | AZ32: =+Listrik!AH31 -> 21761 | BA32: =AZ32+BA31 -> 640407 | BB32: =IF(AND(L32>0,AZ32>0),(AZ32/(P32*1000)*1000),0) -> 356.90738 | BC32: =IF(AND(M32>0,BA32>0),(BA32/(Q32*1000)*1000),0) -> 463.75958 | BD32: =IF(AND(R32>0,AZ32>0),(AZ32/(R32*1000)*1000),0) -> 367.19989 | BE32: =IF(AND(S32>0,BA32>0),(BA32/(S32*1000)*1000),0) -> 477.47205 | BF32: =30.74 -> 30.74 | BG32: 102.453 | BH32: =+SUM(Efficiency2!K117:K118) -> 67.77062 | BI32: =BI31+BH32 -> 1465.6481 | BJ32: =+R32/BH32 -> 0.87444972 | BK32: =+S32/BI32 -> 0.91512074
A33: =A32+1 -> 45925 | B33: Towel | C33: 31,5 | D33: =+'25'!F42 -> 505.13889 | E33: =+'25'!G42 -> 444.52222 | F33: =1-(E33/D33) -> 0.12 | G33: =+P33/N33 -> 0.9765565 | H33: =+P33/L33 -> 0.94864743 | I33: =+R33/P33 -> 0.92477806 | J33: =+R33/L33 -> 0.87728833 | K33: =+S33/M33 -> 0.9085161 | L33: =+Efficiency1!K123 -> 66.732906 | M33: =M32+L33 -> 1540.7421 | N33: =+Efficiency1!C123 -> 64.825743 | O33: =O32+N33 -> 1529.7642 | P33: ='25'!I38 -> 63.306 | Q33: =Q32+P33 -> 1444.209 | R33: ='25'!I40 -> 58.544 | S33: =S32+R33 -> 1399.789 | T33: =R33/P33 -> 0.92477806 | U33: =S33/Q33 -> 0.96924268 | V33: =R33/L33 -> 0.87728833 | W33: =S33/M33 -> 0.9085161 | AB33: 0 | AC33: =AB33+AC32 -> 0 | AD33: =AB33/P33 -> 0 | AE33: =AC33/Q33 -> 0 | AF33: =IF(AND(R33>0,AB33>0),(AB33/(R33*1000))*1000,0) -> 0 | AG33: =IF(AND(S33>0,AC33>0),AC33/S33,0) -> 0 | AH33: =+BF33+BG33 -> 152.683 | AI33: =AH33+AI32 -> 2937.053 | AJ33: =AH33/(P33) -> 2.4118251 | AK33: =AI33/(Q33) -> 2.0336759 | AL33: =IF(AND(R33>0,AH33>0),AH33/(R33),0) -> 2.6080042 | AM33: =IF(AND(S33>0,AI33>0),AI33/(S33),0) -> 2.0982112 | AN33: 14.4 | AO33: =AN33+AO32 -> 422 | AP33: =AN33/(P33) -> 0.22746659 | AQ33: =AO33/(Q33) -> 0.29220147 | AR33: =IF(AND(R33>0,AN33>0),AN33/(R33),0) -> 0.24596884 | AS33: =IF(AND(S33>0,AO33>0),AO33/(S33),0) -> 0.30147401 | AT33: =+'25'!I46 -> 34987.03 | AU33: =AT33+AU32 -> 869540.61 | AV33: =IF(AND(L33>0,AT33>0),(AT33/(P33*1000)*1000),0) -> 552.66531 | AW33: =IF(AND(M33>0,AU33>0),(AU33/(Q33*1000)*1000),0) -> 602.08779 | AX33: =IF(AND(R33>0,AT33>0),(AT33/(R33*1000)*1000),0) -> 597.6194 | AY33: =IF(AND(S33>0,AU33>0),(AU33/(S33*1000)*1000),0) -> 621.19406 | AZ33: =+Listrik!AH32 -> 28158 | BA33: =AZ33+BA32 -> 668565 | BB33: =IF(AND(L33>0,AZ33>0),(AZ33/(P33*1000)*1000),0) -> 444.79196 | BC33: =IF(AND(M33>0,BA33>0),(BA33/(Q33*1000)*1000),0) -> 462.92815 | BD33: =IF(AND(R33>0,AZ33>0),(AZ33/(R33*1000)*1000),0) -> 480.97158 | BE33: =IF(AND(S33>0,BA33>0),(BA33/(S33*1000)*1000),0) -> 477.61841 | BF33: =35.215 -> 35.215 | BG33: 117.468 | BH33: =+Efficiency2!K123 -> 66.732906 | BI33: =BI32+BH33 -> 1532.381 | BJ33: =+R33/BH33 -> 0.87728833 | BK33: =+S33/BI33 -> 0.91347319
A34: =A33+1 -> 45926 | B34: Towel | C34: 31,5/30,5 | D34: =+'26'!F42 -> 529.13194 | E34: =+'26'!G42 -> 465.63611 | F34: =1-(E34/D34) -> 0.12 | G34: =+P34/N34 -> 0.93434591 | H34: =+P34/L34 -> 0.93434591 | I34: =+R34/P34 -> 1.0114634 | J34: =+R34/L34 -> 0.94505665 | K34: =+S34/M34 -> 0.91005387 | L34: =+SUM(Efficiency1!K128:K129) -> 67.689064 | M34: =M33+L34 -> 1608.4312 | N34: =+SUM(Efficiency1!C128:C129) -> 67.689064 | O34: =O33+N34 -> 1597.4533 | P34: ='26'!I38 -> 63.245 | Q34: =Q33+P34 -> 1507.454 | R34: ='26'!I40 -> 63.97 | S34: =S33+R34 -> 1463.759 | T34: =R34/P34 -> 1.0114634 | U34: =S34/Q34 -> 0.97101404 | V34: =R34/L34 -> 0.94505665 | W34: =S34/M34 -> 0.91005387 | AB34: 0 | AC34: =AB34+AC33 -> 0 | AD34: =AB34/P34 -> 0 | AE34: =AC34/Q34 -> 0 | AF34: =IF(AND(R34>0,AB34>0),(AB34/(R34*1000))*1000,0) -> 0 | AG34: =IF(AND(S34>0,AC34>0),AC34/S34,0) -> 0 | AH34: =+BF34+BG34 -> 138.879 | AI34: =AH34+AI33 -> 3075.932 | AJ34: =AH34/(P34) -> 2.195889 | AK34: =AI34/(Q34) -> 2.0404815 | AL34: =IF(AND(R34>0,AH34>0),AH34/(R34),0) -> 2.171002 | AM34: =IF(AND(S34>0,AI34>0),AI34/(S34),0) -> 2.1013924 | AN34: 16 | AO34: =AN34+AO33 -> 438 | AP34: =AN34/(P34) -> 0.25298443 | AQ34: =AO34/(Q34) -> 0.29055613 | AR34: =IF(AND(R34>0,AN34>0),AN34/(R34),0) -> 0.25011724 | AS34: =IF(AND(S34>0,AO34>0),AO34/(S34),0) -> 0.29922959 | AT34: ='26'!I46 -> 32269.03 | AU34: =AT34+AU33 -> 901809.64 | AV34: =IF(AND(L34>0,AT34>0),(AT34/(P34*1000)*1000),0) -> 510.22263 | AW34: =IF(AND(M34>0,AU34>0),(AU34/(Q34*1000)*1000),0) -> 598.2336 | AX34: =IF(AND(R34>0,AT34>0),(AT34/(R34*1000)*1000),0) -> 504.44005 | AY34: =IF(AND(S34>0,AU34>0),(AU34/(S34*1000)*1000),0) -> 616.09161 | AZ34: =+Listrik!AH33 -> 25716 | BA34: =AZ34+BA33 -> 694281 | BB34: =IF(AND(L34>0,AZ34>0),(AZ34/(P34*1000)*1000),0) -> 406.60922 | BC34: =IF(AND(M34>0,BA34>0),(BA34/(Q34*1000)*1000),0) -> 460.5653 | BD34: =IF(AND(R34>0,AZ34>0),(AZ34/(R34*1000)*1000),0) -> 402.00094 | BE34: =IF(AND(S34>0,BA34>0),(BA34/(S34*1000)*1000),0) -> 474.31374 | BF34: =28.715 -> 28.715 | BG34: 110.164 | BH34: =+SUM(Efficiency2!K128:K129) -> 67.689064 | BI34: =BI33+BH34 -> 1600.0701 | BJ34: =+R34/BH34 -> 0.94505665 | BK34: =+S34/BI34 -> 0.9148093
