Workbook

Sheet Report1
A3: PAPER MACHINE 12 DAILY REPORT 1
A6: DATE | B6: GRADE | C6: GSM | D6: Speed yankee (mpm) | E6: Speed reel (mpm) | F6: Creep ( % ) | G6: Real Eff PM ( % ) | H6: Real Eff PM vs Target (%) | I6: Real Eff FG vs Real Eff PM (%) | J6: Eff FG vs Target (%) | L6: Kapasitas Target (ton) | N6: Kapasitas Teori Real (ton) | P6: PM PROD Timbangan (TON) | R6: FINSHED GOODS (TON) | T6: NET GROSS (Timbangan) (%) | V6: NET GROSS ( Scanner) (%) | X6: FRESH WATER | AB6: GAS HOOD | AH6: STEAM (TON) | AN6: STEAM (TON) DEINKING | AT6: POWER (kWh) | AZ6: POWER (kWh) DEINKING | BF6: Report | BH6: Kapasitas Running (ton) | BJ6: Eff FG vs Target Running(%)
X7: CONSUMPTION | Z7: /TON FG. | AB7: CONSUMPTION | AD7: /TON PM. | AF7: /TON FG. | AH7: CONSUMPTION | AJ7: /TON PM. | AL7: /TON FG. | AN7: CONSUMPTION | AP7: /TON PM. | AR7: /TON FG. | AT7: CONSUMPTION | AV7: /TON PM | AX7: /TON FG | AZ7: CONSUMPTION | BB7: /TON PM | BD7: /TON FG | BF7: Hood | BG7: Yankee
J8: TODAY | K8: TODATE | L8: TODAY | M8: TODATE | N8: TODAY | O8: TODATE | P8: TODAY | Q8: TODATE | R8: TODAY | S8: TODATE | T8: TODAY | U8: TODATE | V8: TODAY | W8: TODATE | X8: TODAY | Y8: TODATE | Z8: TODAY | AA8: TODATE | AB8: TODAY | AC8: TODATE | AD8: TODAY | AE8: TODATE | AF8: TODAY | AG8: TODATE | AH8: TODAY | AI8: TODATE | AJ8: TODAY | AK8: TODATE | AL8: TODAY | AM8: TODATE | AN8: TODAY | AO8: TODATE | AP8: TODAY | AQ8: TODATE | AR8: TODAY | AS8: TODATE | AT8: TODAY | AU8: TODATE | AV8: TODAY | AW8: TODATE | AX8: TODAY | AY8: TODATE | AZ8: TODAY | BA8: TODATE | BB8: TODAY | BC8: TODATE | BD8: TODAY | BE8: TODATE | BH8: TODAY | BI8: TODATE | BJ8: TODAY | BK8: TODATE
A9: 45870 | B9: Towel | C9: 38/36 | D9: =+'1'!F42 -> 481.5625 | E9: =+'1'!G42 -> 423.775 | F9: =1-(E9/D9) -> 0.12 | G9: =+P9/N9 -> 1.0910447 | H9: =+P9/L9 -> 1.0910447 | I9: =+R9/P9 -> 0.98406717 | J9: =+R9/L9 -> 1.0736613 | K9: =+S9/M9 -> 1.0736613 | L9: =+SUM(Efficiency1!K6:K7) -> 74.6688 | M9: =L9 -> 74.6688 | N9: =+SUM(Efficiency1!C6:C7) -> 74.6688 | O9: =N9 -> 74.6688 | P9: ='1'!I38 -> 81.467 | Q9: =P9 -> 81.467 | R9: ='1'!I40 -> 80.169 | S9: =R9 -> 80.169 | T9: =R9/P9 -> 0.98406717 | U9: =S9/Q9 -> 0.98406717 | V9: =R9/L9 -> 1.0736613 | W9: =S9/M9 -> 1.0736613 | AB9: 0 | AC9: =AB9 -> 0 | AD9: =AB9/P9 -> 0 | AE9: =AC9/Q9 -> 0 | AF9: =IF(AND(R9>0,AB9>0),(AB9/(R9*1000))*1000,0) -> 0 | AG9: =IF(AND(S9>0,AC9>0),AC9/S9,0) -> 0 | AH9: =+BF9+BG9 -> 184.398 | AI9: =AH9 -> 184.398 | AJ9: =AH9/(P9) -> 2.2634686 | AK9: =AI9/(Q9) -> 2.2634686 | AL9: =IF(AND(R9>0,AH9>0),AH9/(R9),0) -> 2.300116 | AM9: =IF(AND(S9>0,AI9>0),AI9/(S9),0) -> 2.300116 | AN9: 19.2 | AO9: =AN9 -> 19.2 | AP9: =AN9/(P9) -> 0.23567825 | AQ9: =AO9/(Q9) -> 0.23567825 | AR9: =IF(AND(R9>0,AN9>0),AN9/(R9),0) -> 0.23949407 | AS9: =IF(AND(S9>0,AO9>0),AO9/(S9),0) -> 0.23949407 | AT9: ='1'!I46 -> 34391.93 | AU9: =AT9 -> 34391.93 | AV9: =IF(AND(L9>0,AT9>0),(AT9/(P9*1000)*1000),0) -> 422.15781 | AW9: =IF(AND(M9>0,AU9>0),(AU9/(Q9*1000)*1000),0) -> 422.15781 | AX9: =IF(AND(R9>0,AT9>0),(AT9/(R9*1000)*1000),0) -> 428.99288 | AY9: =IF(AND(S9>0,AU9>0),(AU9/(S9*1000)*1000),0) -> 428.99288 | AZ9: =+Listrik!AH8 -> 31567 | BA9: =AZ9 -> 31567 | BB9: =IF(AND(L9>0,AZ9>0),(AZ9/(P9*1000)*1000),0) -> 387.48205 | BC9: =IF(AND(M9>0,BA9>0),(BA9/(Q9*1000)*1000),0) -> 387.48205 | BD9: =IF(AND(R9>0,AZ9>0),(AZ9/(R9*1000)*1000),0) -> 393.75569 | BE9: =IF(AND(S9>0,BA9>0),(BA9/(S9*1000)*1000),0) -> 393.75569 | BF9: 32.547 | BG9: 151.851 | BH9: =+SUM(Efficiency2!K6:K7) -> 74.6688 | BI9: =BH9 -> 74.6688 | BJ9: =+R9/BH9 -> 1.0736613 | BK9: =+S9/BI9 -> 1.0736613
A10: =A9+1 -> 45871 | B10: Towel/Napkin | C10: 36/34/30/20/20 | D10: =+'2'!F42 -> 632.22662 | E10: =+'2'!G42 -> 549.06158 | F10: =1-(E10/D10) -> 0.13154308 | G10: =+P10/N10 -> 1.0675109 | H10: =+P10/L10 -> 1.0491653 | I10: =+R10/P10 -> 0.96114571 | J10: =+R10/L10 -> 1.0084007 | K10: =+S10/M10 -> 1.04268 | L10: =+SUM(Efficiency1!K10:K14) -> 67.485079 | M10: =M9+L10 -> 142.15388 | N10: =+SUM(Efficiency1!C10:C14) -> 66.325317 | O10: =O9+N10 -> 140.99412 | P10: ='2'!I38 -> 70.803 | Q10: =Q9+P10 -> 152.27 | R10: ='2'!I40 -> 68.052 | S10: =S9+R10 -> 148.221 | T10: =R10/P10 -> 0.96114571 | U10: =S10/Q10 -> 0.97340908 | V10: =R10/L10 -> 1.0084007 | W10: =S10/M10 -> 1.04268 | AB10: 0 | AC10: =AB10+AC9 -> 0 | AD10: =AB10/P10 -> 0 | AE10: =AC10/Q10 -> 0 | AF10: =IF(AND(R10>0,AB10>0),(AB10/(R10*1000))*1000,0) -> 0 | AG10: =IF(AND(S10>0,AC10>0),AC10/S10,0) -> 0 | AH10: =+BF10+BG10 -> 182.523 | AI10: =AH10+AI9 -> 366.921 | AJ10: =AH10/(P10) -> 2.5778992 | AK10: =AI10/(Q10) -> 2.4096736 | AL10: =IF(AND(R10>0,AH10>0),AH10/(R10),0) -> 2.6821107 | AM10: =IF(AND(S10>0,AI10>0),AI10/(S10),0) -> 2.4754994 | AN10: 17.9 | AO10: =AN10+AO9 -> 37.1 | AP10: =AN10/(P10) -> 0.25281415 | AQ10: =AO10/(Q10) -> 0.24364615 | AR10: =IF(AND(R10>0,AN10>0),AN10/(R10),0) -> 0.26303415 | AS10: =IF(AND(S10>0,AO10>0),AO10/(S10),0) -> 0.25030191 | AT10: ='2'!I46 -> 36137.49 | AU10: =AT10+AU9 -> 70529.42 | AV10: =IF(AND(L10>0,AT10>0),(AT10/(P10*1000)*1000),0) -> 510.3949 | AW10: =IF(AND(M10>0,AU10>0),(AU10/(Q10*1000)*1000),0) -> 463.18658 | AX10: =IF(AND(R10>0,AT10>0),(AT10/(R10*1000)*1000),0) -> 531.0276 | AY10: =IF(AND(S10>0,AU10>0),(AU10/(S10*1000)*1000),0) -> 475.83959 | AZ10: =+Listrik!AH9 -> 31411 | BA10: =AZ10+BA9 -> 62978 | BB10: =IF(AND(L10>0,AZ10>0),(AZ10/(P10*1000)*1000),0) -> 443.63939 | BC10: =IF(AND(M10>0,BA10>0),(BA10/(Q10*1000)*1000),0) -> 413.59427 | BD10: =IF(AND(R10>0,AZ10>0),(AZ10/(R10*1000)*1000),0) -> 461.5735 | BE10: =IF(AND(S10>0,BA10>0),(BA10/(S10*1000)*1000),0) -> 424.89256 | BF10: 31.046 | BG10: 151.477 | BH10: =+SUM(Efficiency2!K10:K14) -> 67.485079 | BI10: =BI9+BH10 -> 142.15388 | BJ10: =+R10/BH10 -> 1.0084007 | BK10: =+S10/BI10 -> 1.04268
A11: =A10+1 -> 45872 | B11: Napkin | C11: 20/17,5 | D11: =+'3'!F42 -> 800 | E11: =+'3'!G42 -> 688 | F11: =1-(E11/D11) -> 0.14 | G11: =+P11/N11 -> 0.96439363 | H11: =+P11/L11 -> 0.92953603 | I11: =+R11/P11 -> 0.98017008 | J11: =+R11/L11 -> 0.9111034 | K11: =+S11/M11 -> 1.0044027 | L11: =+SUM(Efficiency1!K16:K17) -> 58.320494 | M11: =M10+L11 -> 200.47437 | N11: =+SUM(Efficiency1!C16:C17) -> 56.212524 | O11: =O10+N11 -> 197.20664 | P11: ='3'!I38 -> 54.211 | Q11: =Q10+P11 -> 206.481 | R11: ='3'!I40 -> 53.136 | S11: =S10+R11 -> 201.357 | T11: =R11/P11 -> 0.98017008 | U11: =S11/Q11 -> 0.97518416 | V11: =R11/L11 -> 0.9111034 | W11: =S11/M11 -> 1.0044027 | AB11: 0 | AC11: =AB11+AC10 -> 0 | AD11: =AB11/P11 -> 0 | AE11: =AC11/Q11 -> 0 | AF11: =IF(AND(R11>0,AB11>0),(AB11/(R11*1000))*1000,0) -> 0 | AG11: =IF(AND(S11>0,AC11>0),AC11/S11,0) -> 0 | AH11: =+BF11+BG11 -> 153.787 | AI11: =AH11+AI10 -> 520.708 | AJ11: =AH11/(P11) -> 2.8368228 | AK11: =AI11/(Q11) -> 2.5218204 | AL11: =IF(AND(R11>0,AH11>0),AH11/(R11),0) -> 2.8942148 | AM11: =IF(AND(S11>0,AI11>0),AI11/(S11),0) -> 2.585994 | AN11: 15.2 | AO11: =AN11+AO10 -> 52.3 | AP11: =AN11/(P11) -> 0.2803859 | AQ11: =AO11/(Q11) -> 0.25329207 | AR11: =IF(AND(R11>0,AN11>0),AN11/(R11),0) -> 0.28605842 | AS11: =IF(AND(S11>0,AO11>0),AO11/(S11),0) -> 0.25973768 | AT11: ='3'!I46 -> 36005.95 | AU11: =AT11+AU10 -> 106535.37 | AV11: =IF(AND(L11>0,AT11>0),(AT11/(P11*1000)*1000),0) -> 664.18162 | AW11: =IF(AND(M11>0,AU11>0),(AU11/(Q11*1000)*1000),0) -> 515.95726 | AX11: =IF(AND(R11>0,AT11>0),(AT11/(R11*1000)*1000),0) -> 677.61875 | AY11: =IF(AND(S11>0,AU11>0),(AU11/(S11*1000)*1000),0) -> 529.08699 | AZ11: =+Listrik!AH10 -> 25392 | BA11: =AZ11+BA10 -> 88370 | BB11: =IF(AND(L11>0,AZ11>0),(AZ11/(P11*1000)*1000),0) -> 468.39202 | BC11: =IF(AND(M11>0,BA11>0),(BA11/(Q11*1000)*1000),0) -> 427.98127 | BD11: =IF(AND(R11>0,AZ11>0),(AZ11/(R11*1000)*1000),0) -> 477.86811 | BE11: =IF(AND(S11>0,BA11>0),(BA11/(S11*1000)*1000),0) -> 438.87225 | BF11: 12.443 | BG11: 141.344 | BH11: =+SUM(Efficiency2!K16:K17) -> 58.320494 | BI11: =BI10+BH11 -> 200.47437 | BJ11: =+R11/BH11 -> 0.9111034 | BK11: =+S11/BI11 -> 1.0044027
A12: =A11+1 -> 45873 | B12: Napkin | C12: 17,5/16/15,5 | D12: =+'4'!F42 -> 800 | E12: =+'4'!G42 -> 688 | F12: =1-(E12/D12) -> 0.14 | G12: =+P12/N12 -> 0.9360689 | H12: =+P12/L12 -> 0.90223509 | I12: =+R12/P12 -> 0.88727018 | J12: =+R12/L12 -> 0.80052628 | K12: =+S12/M12 -> 0.96132157 | L12: =+SUM(Efficiency1!K20:K22) -> 53.712165 | M12: =M11+L12 -> 254.18654 | N12: =+SUM(Efficiency1!C20:C22) -> 51.770762 | O12: =O11+N12 -> 248.9774 | P12: ='4'!I38 -> 48.461 | Q12: =Q11+P12 -> 254.942 | R12: ='4'!I40 -> 42.998 | S12: =S11+R12 -> 244.355 | T12: =R12/P12 -> 0.88727018 | U12: =S12/Q12 -> 0.95847291 | V12: =R12/L12 -> 0.80052628 | W12: =S12/M12 -> 0.96132157 | AB12: 0 | AC12: =AB12+AC11 -> 0 | AD12: =AB12/P12 -> 0 | AE12: =AC12/Q12 -> 0 | AF12: =IF(AND(R12>0,AB12>0),(AB12/(R12*1000))*1000,0) -> 0 | AG12: =IF(AND(S12>0,AC12>0),AC12/S12,0) -> 0 | AH12: =+BF12+BG12 -> 147.404 | AI12: =AH12+AI11 -> 668.112 | AJ12: =AH12/(P12) -> 3.0417036 | AK12: =AI12/(Q12) -> 2.6206431 | AL12: =IF(AND(R12>0,AH12>0),AH12/(R12),0) -> 3.4281594 | AM12: =IF(AND(S12>0,AI12>0),AI12/(S12),0) -> 2.7341859 | AN12: 10.2 | AO12: =AN12+AO11 -> 62.5 | AP12: =AN12/(P12) -> 0.21047853 | AQ12: =AO12/(Q12) -> 0.2451538 | AR12: =IF(AND(R12>0,AN12>0),AN12/(R12),0) -> 0.23722034 | AS12: =IF(AND(S12>0,AO12>0),AO12/(S12),0) -> 0.25577541 | AT12: ='4'!I46 -> 37811.29 | AU12: =AT12+AU11 -> 144346.66 | AV12: =IF(AND(L12>0,AT12>0),(AT12/(P12*1000)*1000),0) -> 780.24164 | AW12: =IF(AND(M12>0,AU12>0),(AU12/(Q12*1000)*1000),0) -> 566.19411 | AX12: =IF(AND(R12>0,AT12>0),(AT12/(R12*1000)*1000),0) -> 879.37323 | AY12: =IF(AND(S12>0,AU12>0),(AU12/(S12*1000)*1000),0) -> 590.72522 | AZ12: =+Listrik!AH11 -> 16754 | BA12: =AZ12+BA11 -> 105124 | BB12: =IF(AND(L12>0,AZ12>0),(AZ12/(P12*1000)*1000),0) -> 345.7213 | BC12: =IF(AND(M12>0,BA12>0),(BA12/(Q12*1000)*1000),0) -> 412.34477 | BD12: =IF(AND(R12>0,AZ12>0),(AZ12/(R12*1000)*1000),0) -> 389.64603 | BE12: =IF(AND(S12>0,BA12>0),(BA12/(S12*1000)*1000),0) -> 430.21015 | BF12: 8.093 | BG12: 139.311 | BH12: =+SUM(Efficiency2!K20:K22) -> 53.712165 | BI12: =BI11+BH12 -> 254.18654 | BJ12: =+R12/BH12 -> 0.80052628 | BK12: =+S12/BI12 -> 0.96132157
A13: =A12+1 -> 45874 | B13: Napkin | C13: 16/17 | D13: =+'5'!F42 -> 765.21739 | E13: =+'5'!G42 -> 658.08696 | F13: =1-(E13/D13) -> 0.14 | G13: =+P13/N13 -> 0.035520165 | H13: =+P13/L13 -> 0.034028706 | I13: =+R13/P13 -> 1.3367117 | J13: =+R13/L13 -> 0.04548657 | K13: =+S13/M13 -> 0.80530974 | L13: =+SUM(Efficiency1!K25:K26) -> 52.191229 | M13: =M12+L13 -> 306.37777 | N13: =+SUM(Efficiency1!C25:C26) -> 49.999767 | O13: =O12+N13 -> 298.97717 | P13: ='5'!I38 -> 1.776 | Q13: =Q12+P13 -> 256.718 | R13: ='5'!I40 -> 2.374 | S13: =S12+R13 -> 246.729 | T13: =R13/P13 -> 1.3367117 | U13: =S13/Q13 -> 0.9610896 | V13: =R13/L13 -> 0.04548657 | W13: =S13/M13 -> 0.80530974 | AB13: 0 | AC13: =AB13+AC12 -> 0 | AD13: =AB13/P13 -> 0 | AE13: =AC13/Q13 -> 0 | AF13: =IF(AND(R13>0,AB13>0),(AB13/(R13*1000))*1000,0) -> 0 | AG13: =IF(AND(S13>0,AC13>0),AC13/S13,0) -> 0 | AH13: =+BF13+BG13 -> 46.217 | AI13: =AH13+AI12 -> 714.329 | AJ13: =AH13/(P13) -> 26.023086 | AK13: =AI13/(Q13) -> 2.7825435 | AL13: =IF(AND(R13>0,AH13>0),AH13/(R13),0) -> 19.467987 | AM13: =IF(AND(S13>0,AI13>0),AI13/(S13),0) -> 2.8951968 | AN13: 0 | AO13: =AN13+AO12 -> 62.5 | AP13: =AN13/(P13) -> 0 | AQ13: =AO13/(Q13) -> 0.2434578 | AR13: =IF(AND(R13>0,AN13>0),AN13/(R13),0) -> 0 | AS13: =IF(AND(S13>0,AO13>0),AO13/(S13),0) -> 0.25331437 | AT13: ='5'!I46 -> 10057.15 | AU13: =AT13+AU12 -> 154403.81 | AV13: =IF(AND(L13>0,AT13>0),(AT13/(P13*1000)*1000),0) -> 5662.8097 | AW13: =IF(AND(M13>0,AU13>0),(AU13/(Q13*1000)*1000),0) -> 601.453 | AX13: =IF(AND(R13>0,AT13>0),(AT13/(R13*1000)*1000),0) -> 4236.3732 | AY13: =IF(AND(S13>0,AU13>0),(AU13/(S13*1000)*1000),0) -> 625.80325 | AZ13: =+Listrik!AH12 -> 627 | BA13: =AZ13+BA12 -> 105751 | BB13: =IF(AND(L13>0,AZ13>0),(AZ13/(P13*1000)*1000),0) -> 353.04054 | BC13: =IF(AND(M13>0,BA13>0),(BA13/(Q13*1000)*1000),0) -> 411.9345 | BD13: =IF(AND(R13>0,AZ13>0),(AZ13/(R13*1000)*1000),0) -> 264.1112 | BE13: =IF(AND(S13>0,BA13>0),(BA13/(S13*1000)*1000),0) -> 428.61196 | BF13: 2.692 | BG13: 43.525 | BH13: =+SUM(Efficiency2!K25:K26) -> 6.8625303 | BI13: =BI12+BH13 -> 261.04907 | BJ13: =+R13/BH13 -> 0.34593654 | BK13: =+S13/BI13 -> 0.94514415
A14: =A13+1 -> 45875 | B14: Napkin | C14: 17/16 | D14: =+'6'!F42 -> 749.58333 | E14: =+'6'!G42 -> 640.0625 | F14: =1-(E14/D14) -> 0.14610895 | G14: =+P14/N14 -> 0.87113491 | H14: =+P14/L14 -> 0.78522824 | I14: =+R14/P14 -> 0.76422821 | J14: =+R14/L14 -> 0.60009357 | K14: =+S14/M14 -> 0.77405446 | L14: =+SUM(Efficiency1!K30:K31) -> 55.046416 | M14: =M13+L14 -> 361.42418 | N14: =+SUM(Efficiency1!C30:C31) -> 49.618032 | O14: =O13+N14 -> 348.5952 | P14: ='6'!I38 -> 43.224 | Q14: =Q13+P14 -> 299.942 | R14: ='6'!I40 -> 33.033 | S14: =S13+R14 -> 279.762 | T14: =R14/P14 -> 0.76422821 | U14: =S14/Q14 -> 0.93272033 | V14: =R14/L14 -> 0.60009357 | W14: =S14/M14 -> 0.77405446 | AB14: 0 | AC14: =AB14+AC13 -> 0 | AD14: =AB14/P14 -> 0 | AE14: =AC14/Q14 -> 0 | AF14: =IF(AND(R14>0,AB14>0),(AB14/(R14*1000))*1000,0) -> 0 | AG14: =IF(AND(S14>0,AC14>0),AC14/S14,0) -> 0 | AH14: =+BF14+BG14 -> 132.045 | AI14: =AH14+AI13 -> 846.374 | AJ14: =AH14/(P14) -> 3.0549001 | AK14: =AI14/(Q14) -> 2.8217922 | AL14: =IF(AND(R14>0,AH14>0),AH14/(R14),0) -> 3.9973663 | AM14: =IF(AND(S14>0,AI14>0),AI14/(S14),0) -> 3.0253358 | AN14: 0 | AO14: =AN14+AO13 -> 62.5 | AP14: =AN14/(P14) -> 0 | AQ14: =AO14/(Q14) -> 0.20837362 | AR14: =IF(AND(R14>0,AN14>0),AN14/(R14),0) -> 0 | AS14: =IF(AND(S14>0,AO14>0),AO14/(S14),0) -> 0.22340418 | AT14: ='6'!I46 -> 45279.07 | AU14: =AT14+AU13 -> 199682.88 | AV14: =IF(AND(L14>0,AT14>0),(AT14/(P14*1000)*1000),0) -> 1047.5447 | AW14: =IF(AND(M14>0,AU14>0),(AU14/(Q14*1000)*1000),0) -> 665.73831 | AX14: =IF(AND(R14>0,AT14>0),(AT14/(R14*1000)*1000),0) -> 1370.7223 | AY14: =IF(AND(S14>0,AU14>0),(AU14/(S14*1000)*1000),0) -> 713.75984 | AZ14: =+Listrik!AH13 -> 613 | BA14: =AZ14+BA13 -> 106364 | BB14: =IF(AND(L14>0,AZ14>0),(AZ14/(P14*1000)*1000),0) -> 14.181936 | BC14: =IF(AND(M14>0,BA14>0),(BA14/(Q14*1000)*1000),0) -> 354.61523 | BD14: =IF(AND(R14>0,AZ14>0),(AZ14/(R14*1000)*1000),0) -> 18.5572 | BE14: =IF(AND(S14>0,BA14>0),(BA14/(S14*1000)*1000),0) -> 380.19459 | BF14: 33.814 | BG14: 98.231 | BH14: =+SUM(Efficiency2!K30:K31) -> 49.107396 | BI14: =BI13+BH14 -> 310.15646 | BJ14: =+R14/BH14 -> 0.67266853 | BK14: =+S14/BI14 -> 0.90200281
A15: =A14+1 -> 45876 | B15: Napkin | C15: 16/19 | D15: =+'7'!F42 -> 826.625 | E15: =+'7'!G42 -> 710.8975 | F15: =1-(E15/D15) -> 0.14 | G15: =+P15/N15 -> 0.61550264 | H15: =+P15/L15 -> 0.6120839 | I15: =+R15/P15 -> 0.90913817 | J15: =+R15/L15 -> 0.55646884 | K15: =+S15/M15 -> 0.74460828 | L15: =+SUM(Efficiency1!K37:K38) -> 56.567408 | M15: =M14+L15 -> 417.99159 | N15: =+SUM(Efficiency1!C37:C38) -> 56.253211 | O15: =O14+N15 -> 404.84841 | P15: ='7'!I38 -> 34.624 | Q15: =Q14+P15 -> 334.566 | R15: ='7'!I40 -> 31.478 | S15: =S14+R15 -> 311.24 | T15: =R15/P15 -> 0.90913817 | U15: =S15/Q15 -> 0.93027983 | V15: =R15/L15 -> 0.55646884 | W15: =S15/M15 -> 0.74460828 | AB15: 0 | AC15: =AB15+AC14 -> 0 | AD15: =AB15/P15 -> 0 | AE15: =AC15/Q15 -> 0 | AF15: =IF(AND(R15>0,AB15>0),(AB15/(R15*1000))*1000,0) -> 0 | AG15: =IF(AND(S15>0,AC15>0),AC15/S15,0) -> 0 | AH15: =+BF15+BG15 -> 108.702 | AI15: =AH15+AI14 -> 955.076 | AJ15: =AH15/(P15) -> 3.1394986 | AK15: =AI15/(Q15) -> 2.8546714 | AL15: =IF(AND(R15>0,AH15>0),AH15/(R15),0) -> 3.4532689 | AM15: =IF(AND(S15>0,AI15>0),AI15/(S15),0) -> 3.0686159 | AN15: 0 | AO15: =AN15+AO14 -> 62.5 | AP15: =AN15/(P15) -> 0 | AQ15: =AO15/(Q15) -> 0.18680918 | AR15: =IF(AND(R15>0,AN15>0),AN15/(R15),0) -> 0 | AS15: =IF(AND(S15>0,AO15>0),AO15/(S15),0) -> 0.20080966 | AT15: ='7'!I46 -> 35046.91 | AU15: =AT15+AU14 -> 234729.79 | AV15: =IF(AND(L15>0,AT15>0),(AT15/(P15*1000)*1000),0) -> 1012.2144 | AW15: =IF(AND(M15>0,AU15>0),(AU15/(Q15*1000)*1000),0) -> 701.59487 | AX15: =IF(AND(R15>0,AT15>0),(AT15/(R15*1000)*1000),0) -> 1113.3779 | AY15: =IF(AND(S15>0,AU15>0),(AU15/(S15*1000)*1000),0) -> 754.17617 | AZ15: =+Listrik!AH14 -> 474 | BA15: =AZ15+BA14 -> 106838 | BB15: =IF(AND(L15>0,AZ15>0),(AZ15/(P15*1000)*1000),0) -> 13.689926 | BC15: =IF(AND(M15>0,BA15>0),(BA15/(Q15*1000)*1000),0) -> 319.33311 | BD15: =IF(AND(R15>0,AZ15>0),(AZ15/(R15*1000)*1000),0) -> 15.058136 | BE15: =IF(AND(S15>0,BA15>0),(BA15/(S15*1000)*1000),0) -> 343.26565 | BF15: 15.377 | BG15: 93.325 | BH15: =+SUM(Efficiency2!K37:K38) -> 56.567408 | BI15: =BI14+BH15 -> 366.72387 | BJ15: =+R15/BH15 -> 0.55646884 | BK15: =+S15/BI15 -> 0.84870395
A16: =A15+1 -> 45877 | B16: Napkin | C16: 19/25 | D16: =+'8'!F42 -> 791.66667 | E16: =+'8'!G42 -> 680.83333 | F16: =1-(E16/D16) -> 0.14 | G16: =+P16/N16 -> 0.91226458 | H16: =+P16/L16 -> 0.86837635 | I16: =+R16/P16 -> 0.99082225 | J16: =+R16/L16 -> 0.86040661 | K16: =+S16/M16 -> 0.76319655 | L16: =+SUM(Efficiency1!K42:K43) -> 79.927327 | M16: =M15+L16 -> 497.91892 | N16: =+SUM(Efficiency1!C42:C43) -> 76.082095 | O16: =O15+N16 -> 480.93051 | P16: ='8'!I38 -> 69.407 | Q16: =Q15+P16 -> 403.973 | R16: ='8'!I40 -> 68.77 | S16: =S15+R16 -> 380.01 | T16: =R16/P16 -> 0.99082225 | U16: =S16/Q16 -> 0.94068168 | V16: =R16/L16 -> 0.86040661 | W16: =S16/M16 -> 0.76319655 | AB16: 0 | AC16: =AB16+AC15 -> 0 | AD16: =AB16/P16 -> 0 | AE16: =AC16/Q16 -> 0 | AF16: =IF(AND(R16>0,AB16>0),(AB16/(R16*1000))*1000,0) -> 0 | AG16: =IF(AND(S16>0,AC16>0),AC16/S16,0) -> 0 | AH16: =+BF16+BG16 -> 146.912 | AI16: =AH16+AI15 -> 1101.988 | AJ16: =AH16/(P16) -> 2.1166741 | AK16: =AI16/(Q16) -> 2.7278754 | AL16: =IF(AND(R16>0,AH16>0),AH16/(R16),0) -> 2.1362804 | AM16: =IF(AND(S16>0,AI16>0),AI16/(S16),0) -> 2.8998921 | AN16: 0 | AO16: =AN16+AO15 -> 62.5 | AP16: =AN16/(P16) -> 0 | AQ16: =AO16/(Q16) -> 0.15471331 | AR16: =IF(AND(R16>0,AN16>0),AN16/(R16),0) -> 0 | AS16: =IF(AND(S16>0,AO16>0),AO16/(S16),0) -> 0.16446936 | AT16: ='8'!I46 -> 43791.81 | AU16: =AT16+AU15 -> 278521.6 | AV16: =IF(AND(L16>0,AT16>0),(AT16/(P16*1000)*1000),0) -> 630.94227 | AW16: =IF(AND(M16>0,AU16>0),(AU16/(Q16*1000)*1000),0) -> 689.45598 | AX16: =IF(AND(R16>0,AT16>0),(AT16/(R16*1000)*1000),0) -> 636.78653 | AY16: =IF(AND(S16>0,AU16>0),(AU16/(S16*1000)*1000),0) -> 732.93229 | AZ16: =+Listrik!AH15 -> 519 | BA16: =AZ16+BA15 -> 107357 | BB16: =IF(AND(L16>0,AZ16>0),(AZ16/(P16*1000)*1000),0) -> 7.4776319 | BC16: =IF(AND(M16>0,BA16>0),(BA16/(Q16*1000)*1000),0) -> 265.75291 | BD16: =IF(AND(R16>0,AZ16>0),(AZ16/(R16*1000)*1000),0) -> 7.5468954 | BE16: =IF(AND(S16>0,BA16>0),(BA16/(S16*1000)*1000),0) -> 282.51099 | BF16: 24.583 | BG16: 122.329 | BH16: =+SUM(Efficiency2!K42:K43) -> 79.927327 | BI16: =BI15+BH16 -> 446.6512 | BJ16: =+R16/BH16 -> 0.86040661 | BK16: =+S16/BI16 -> 0.85079812
A17: =A16+1 -> 45878 | B17: Napkin | C17: 25/23 | D17: =+'9'!F42 -> 825.27076 | E17: =+'9'!G42 -> 709.73285 | F17: =1-(E17/D17) -> 0.14 | G17: =+P17/N17 -> 0.86613137 | H17: =+P17/L17 -> 0.86103263 | I17: =+R17/P17 -> 0.96419895 | J17: =+R17/L17 -> 0.83020676 | K17: =+S17/M17 -> 0.77264687 | L17: =+SUM(Efficiency1!K46:K47) -> 81.749515 | M17: =M16+L17 -> 579.66843 | N17: =+SUM(Efficiency1!C46:C47) -> 81.268272 | O17: =O16+N17 -> 562.19878 | P17: ='9'!I38 -> 70.389 | Q17: =Q16+P17 -> 474.362 | R17: ='9'!I40 -> 67.869 | S17: =S16+R17 -> 447.879 | T17: =R17/P17 -> 0.96419895 | U17: =S17/Q17 -> 0.94417133 | V17: =R17/L17 -> 0.83020676 | W17: =S17/M17 -> 0.77264687 | AB17: 0 | AC17: =AB17+AC16 -> 0 | AD17: =AB17/P17 -> 0 | AE17: =AC17/Q17 -> 0 | AF17: =IF(AND(R17>0,AB17>0),(AB17/(R17*1000))*1000,0) -> 0 | AG17: =IF(AND(S17>0,AC17>0),AC17/S17,0) -> 0 | AH17: =+BF17+BG17 -> 158.437 | AI17: =AH17+AI16 -> 1260.425 | AJ17: =AH17/(P17) -> 2.2508773 | AK17: =AI17/(Q17) -> 2.6570952 | AL17: =IF(AND(R17>0,AH17>0),AH17/(R17),0) -> 2.3344531 | AM17: =IF(AND(S17>0,AI17>0),AI17/(S17),0) -> 2.8142087 | AN17: 0 | AO17: =AN17+AO16 -> 62.5 | AP17: =AN17/(P17) -> 0 | AQ17: =AO17/(Q17) -> 0.13175592 | AR17: =IF(AND(R17>0,AN17>0),AN17/(R17),0) -> 0 | AS17: =IF(AND(S17>0,AO17>0),AO17/(S17),0) -> 0.13954662 | AT17: ='9'!I46 -> 45323.43 | AU17: =AT17+AU16 -> 323845.03 | AV17: =IF(AND(L17>0,AT17>0),(AT17/(P17*1000)*1000),0) -> 643.89933 | AW17: =IF(AND(M17>0,AU17>0),(AU17/(Q17*1000)*1000),0) -> 682.69598 | AX17: =IF(AND(R17>0,AT17>0),(AT17/(R17*1000)*1000),0) -> 667.80754 | AY17: =IF(AND(S17>0,AU17>0),(AU17/(S17*1000)*1000),0) -> 723.06366 | AZ17: =+Listrik!AH16 -> 451 | BA17: =AZ17+BA16 -> 107808 | BB17: =IF(AND(L17>0,AZ17>0),(AZ17/(P17*1000)*1000),0) -> 6.4072511 | BC17: =IF(AND(M17>0,BA17>0),(BA17/(Q17*1000)*1000),0) -> 227.26947 | BD17: =IF(AND(R17>0,AZ17>0),(AZ17/(R17*1000)*1000),0) -> 6.6451546 | BE17: =IF(AND(S17>0,BA17>0),(BA17/(S17*1000)*1000),0) -> 240.70787 | BF17: 29.199 | BG17: 129.238 | BH17: =+SUM(Efficiency2!K46:K47) -> 81.749515 | BI17: =BI16+BH17 -> 528.40071 | BJ17: =+R17/BH17 -> 0.83020676 | BK17: =+S17/BI17 -> 0.84761241
A18: =A17+1 -> 45879 | B18: Napkin/Towel | C18: 23/23/17 | D18: =+'10'!F42 -> 830 | E18: =+'10'!G42 -> 713.8 | F18: =1-(E18/D18) -> 0.14 | G18: =+P18/N18 -> 0.95879678 | H18: =+P18/L18 -> 0.95879678 | I18: =+R18/P18 -> 1.0138024 | J18: =+R18/L18 -> 0.97203049 | K18: =+S18/M18 -> 0.79608713 | L18: =+SUM(Efficiency1!K52:K55) -> 77.227001 | M18: =M17+L18 -> 656.89543 | N18: =+SUM(Efficiency1!C52:C55) -> 77.227001 | O18: =O17+N18 -> 639.42578 | P18: ='10'!I38 -> 74.045 | Q18: =Q17+P18 -> 548.407 | R18: ='10'!I40 -> 75.067 | S18: =S17+R18 -> 522.946 | T18: =R18/P18 -> 1.0138024 | U18: =S18/Q18 -> 0.9535728 | V18: =R18/L18 -> 0.97203049 | W18: =S18/M18 -> 0.79608713 | AB18: 0 | AC18: =AB18+AC17 -> 0 | AD18: =AB18/P18 -> 0 | AE18: =AC18/Q18 -> 0 | AF18: =IF(AND(R18>0,AB18>0),(AB18/(R18*1000))*1000,0) -> 0 | AG18: =IF(AND(S18>0,AC18>0),AC18/S18,0) -> 0 | AH18: =+BF18+BG18 -> 157.118 | AI18: =AH18+AI17 -> 1417.543 | AJ18: =AH18/(P18) -> 2.1219259 | AK18: =AI18/(Q18) -> 2.5848375 | AL18: =IF(AND(R18>0,AH18>0),AH18/(R18),0) -> 2.0930369 | AM18: =IF(AND(S18>0,AI18>0),AI18/(S18),0) -> 2.7106871 | AN18: 0 | AO18: =AN18+AO17 -> 62.5 | AP18: =AN18/(P18) -> 0 | AQ18: =AO18/(Q18) -> 0.11396645 | AR18: =IF(AND(R18>0,AN18>0),AN18/(R18),0) -> 0 | AS18: =IF(AND(S18>0,AO18>0),AO18/(S18),0) -> 0.11951521 | AT18: ='10'!I46 -> 45373.81 | AU18: =AT18+AU17 -> 369218.84 | AV18: =IF(AND(L18>0,AT18>0),(AT18/(P18*1000)*1000),0) -> 612.78695 | AW18: =IF(AND(M18>0,AU18>0),(AU18/(Q18*1000)*1000),0) -> 673.25698 | AX18: =IF(AND(R18>0,AT18>0),(AT18/(R18*1000)*1000),0) -> 604.44416 | AY18: =IF(AND(S18>0,AU18>0),(AU18/(S18*1000)*1000),0) -> 706.03626 | AZ18: =+Listrik!AH17 -> 455 | BA18: =AZ18+BA17 -> 108263 | BB18: =IF(AND(L18>0,AZ18>0),(AZ18/(P18*1000)*1000),0) -> 6.1449119 | BC18: =IF(AND(M18>0,BA18>0),(BA18/(Q18*1000)*1000),0) -> 197.4136 | BD18: =IF(AND(R18>0,AZ18>0),(AZ18/(R18*1000)*1000),0) -> 6.0612519 | BE18: =IF(AND(S18>0,BA18>0),(BA18/(S18*1000)*1000),0) -> 207.0252 | BF18: 29.489 | BG18: 127.629 | BH18: =+SUM(Efficiency2!K52:K54) -> 77.227001 | BI18: =BI17+BH18 -> 605.62771 | BJ18: =+R18/BH18 -> 0.97203049 | BK18: =+S18/BI18 -> 0.86347766
A19: =A18+1 -> 45880 | B19: Napkin | C19: 17 | D19: =+'11'!F42 -> 830 | E19: =+'11'!G42 -> 680.6 | F19: =1-(E19/D19) -> 0.18 | G19: =+P19/N19 -> 0.90900745 | H19: =+P19/L19 -> 0.90900745 | I19: =+R19/P19 -> 0.94749427 | J19: =+R19/L19 -> 0.86127935 | K19: =+S19/M19 -> 0.80110245 | L19: =+Efficiency1!K57 -> 54.747626 | M19: =M18+L19 -> 711.64306 | N19: =+Efficiency1!C57 -> 54.747626 | O19: =O18+N19 -> 694.17341 | P19: ='11'!I38 -> 49.766 | Q19: =Q18+P19 -> 598.173 | R19: ='11'!I40 -> 47.153 | S19: =S18+R19 -> 570.099 | T19: =R19/P19 -> 0.94749427 | U19: =S19/Q19 -> 0.95306709 | V19: =R19/L19 -> 0.86127935 | W19: =S19/M19 -> 0.80110245 | AB19: 0 | AC19: =AB19+AC18 -> 0 | AD19: =AB19/P19 -> 0 | AE19: =AC19/Q19 -> 0 | AF19: =IF(AND(R19>0,AB19>0),(AB19/(R19*1000))*1000,0) -> 0 | AG19: =IF(AND(S19>0,AC19>0),AC19/S19,0) -> 0 | AH19: =+BF19+BG19 -> 133.884 | AI19: =AH19+AI18 -> 1551.427 | AJ19: =AH19/(P19) -> 2.6902705 | AK19: =AI19/(Q19) -> 2.5936092 | AL19: =IF(AND(R19>0,AH19>0),AH19/(R19),0) -> 2.8393527 | AM19: =IF(AND(S19>0,AI19>0),AI19/(S19),0) -> 2.7213291 | AN19: 0 | AO19: =AN19+AO18 -> 62.5 | AP19: =AN19/(P19) -> 0 | AQ19: =AO19/(Q19) -> 0.10448482 | AR19: =IF(AND(R19>0,AN19>0),AN19/(R19),0) -> 0 | AS19: =IF(AND(S19>0,AO19>0),AO19/(S19),0) -> 0.10963008 | AT19: ='11'!I46 -> 45530.73 | AU19: =AT19+AU18 -> 414749.57 | AV19: =IF(AND(L19>0,AT19>0),(AT19/(P19*1000)*1000),0) -> 914.89631 | AW19: =IF(AND(M19>0,AU19>0),(AU19/(Q19*1000)*1000),0) -> 693.36057 | AX19: =IF(AND(R19>0,AT19>0),(AT19/(R19*1000)*1000),0) -> 965.59561 | AY19: =IF(AND(S19>0,AU19>0),(AU19/(S19*1000)*1000),0) -> 727.50447 | AZ19: =+Listrik!AH18 -> 459 | BA19: =AZ19+BA18 -> 108722 | BB19: =IF(AND(L19>0,AZ19>0),(AZ19/(P19*1000)*1000),0) -> 9.2231644 | BC19: =IF(AND(M19>0,BA19>0),(BA19/(Q19*1000)*1000),0) -> 181.75678 | BD19: =IF(AND(R19>0,AZ19>0),(AZ19/(R19*1000)*1000),0) -> 9.7342693 | BE19: =IF(AND(S19>0,BA19>0),(BA19/(S19*1000)*1000),0) -> 190.70723 | BF19: 24.868 | BG19: 109.016 | BH19: =+Efficiency2!K57 -> 54.747626 | BI19: =BI18+BH19 -> 660.37534 | BJ19: =+R19/BH19 -> 0.86127935 | BK19: =+S19/BI19 -> 0.86329541
A20: =A19+1 -> 45881 | B20: Napkin | C20: 17 | D20: =+'12'!F42 -> 830 | E20: =+'12'!G42 -> 680.6 | F20: =1-(E20/D20) -> 0.18 | G20: =+P20/N20 -> 0.93771824 | H20: =+P20/L20 -> 0.93771824 | I20: =+R20/P20 -> 0.97067733 | J20: =+R20/L20 -> 0.91022184 | K20: =+S20/M20 -> 0.80878019 | L20: =+SUM(Efficiency1!K61:K62) -> 53.861595 | M20: =M19+L20 -> 765.50465 | N20: =+SUM(Efficiency1!C61:C62) -> 53.861595 | O20: =O19+N20 -> 748.035 | P20: ='12'!I38 -> 50.507 | Q20: =Q19+P20 -> 648.68 | R20: ='12'!I40 -> 49.026 | S20: =S19+R20 -> 619.125 | T20: =R20/P20 -> 0.97067733 | U20: =S20/Q20 -> 0.95443824 | V20: =R20/L20 -> 0.91022184 | W20: =S20/M20 -> 0.80878019 | AB20: 0 | AC20: =AB20+AC19 -> 0 | AD20: =AB20/P20 -> 0 | AE20: =AC20/Q20 -> 0 | AF20: =IF(AND(R20>0,AB20>0),(AB20/(R20*1000))*1000,0) -> 0 | AG20: =IF(AND(S20>0,AC20>0),AC20/S20,0) -> 0 | AH20: =+BF20+BG20 -> 116.591 | AI20: =AH20+AI19 -> 1668.018 | AJ20: =AH20/(P20) -> 2.3084127 | AK20: =AI20/(Q20) -> 2.5714035 | AL20: =IF(AND(R20>0,AH20>0),AH20/(R20),0) -> 2.3781463 | AM20: =IF(AND(S20>0,AI20>0),AI20/(S20),0) -> 2.6941538 | AN20: 0 | AO20: =AN20+AO19 -> 62.5 | AP20: =AN20/(P20) -> 0 | AQ20: =AO20/(Q20) -> 0.09634951 | AR20: =IF(AND(R20>0,AN20>0),AN20/(R20),0) -> 0 | AS20: =IF(AND(S20>0,AO20>0),AO20/(S20),0) -> 0.10094892 | AT20: ='12'!I46 -> 46234.88 | AU20: =AT20+AU19 -> 460984.45 | AV20: =IF(AND(L20>0,AT20>0),(AT20/(P20*1000)*1000),0) -> 915.41529 | AW20: =IF(AND(M20>0,AU20>0),(AU20/(Q20*1000)*1000),0) -> 710.65001 | AX20: =IF(AND(R20>0,AT20>0),(AT20/(R20*1000)*1000),0) -> 943.06858 | AY20: =IF(AND(S20>0,AU20>0),(AU20/(S20*1000)*1000),0) -> 744.57412 | AZ20: =+Listrik!AH19 -> 456 | BA20: =AZ20+BA19 -> 109178 | BB20: =IF(AND(L20>0,AZ20>0),(AZ20/(P20*1000)*1000),0) -> 9.0284515 | BC20: =IF(AND(M20>0,BA20>0),(BA20/(Q20*1000)*1000),0) -> 168.30795 | BD20: =IF(AND(R20>0,AZ20>0),(AZ20/(R20*1000)*1000),0) -> 9.3011871 | BE20: =IF(AND(S20>0,BA20>0),(BA20/(S20*1000)*1000),0) -> 176.34242 | BF20: 9.368 | BG20: 107.223 | BH20: =+SUM(Efficiency2!K61:K62) -> 53.861595 | BI20: =BI19+BH20 -> 714.23694 | BJ20: =+R20/BH20 -> 0.91022184 | BK20: =+S20/BI20 -> 0.8668342
A21: =A20+1 -> 45882 | B21: Napkin | C21: 17/16 | D21: =+'13'!F42 -> 830 | E21: =+'13'!G42 -> 685.7875 | F21: =1-(E21/D21) -> 0.17375 | G21: =+P21/N21 -> 0.88931062 | H21: =+P21/L21 -> 0.88931062 | I21: =+R21/P21 -> 0.91013151 | J21: =+R21/L21 -> 0.80938962 | K21: =+S21/M21 -> 0.80881996 | L21: =+SUM(Efficiency1!K65:K66) -> 53.44027 | M21: =M20+L21 -> 818.94492 | N21: =+SUM(Efficiency1!C65:C66) -> 53.44027 | O21: =O20+N21 -> 801.47527 | P21: ='13'!I38 -> 47.525 | Q21: =Q20+P21 -> 696.205 | R21: ='13'!I40 -> 43.254 | S21: =S20+R21 -> 662.379 | T21: =R21/P21 -> 0.91013151 | U21: =S21/Q21 -> 0.95141374 | V21: =R21/L21 -> 0.80938962 | W21: =S21/M21 -> 0.80881996 | AB21: 0 | AC21: =AB21+AC20 -> 0 | AD21: =AB21/P21 -> 0 | AE21: =AC21/Q21 -> 0 | AF21: =IF(AND(R21>0,AB21>0),(AB21/(R21*1000))*1000,0) -> 0 | AG21: =IF(AND(S21>0,AC21>0),AC21/S21,0) -> 0 | AH21: =+BF21+BG21 -> 116.601 | AI21: =AH21+AI20 -> 1784.619 | AJ21: =AH21/(P21) -> 2.4534666 | AK21: =AI21/(Q21) -> 2.5633527 | AL21: =IF(AND(R21>0,AH21>0),AH21/(R21),0) -> 2.6957276 | AM21: =IF(AND(S21>0,AI21>0),AI21/(S21),0) -> 2.6942566 | AN21: 0 | AO21: =AN21+AO20 -> 62.5 | AP21: =AN21/(P21) -> 0 | AQ21: =AO21/(Q21) -> 0.089772409 | AR21: =IF(AND(R21>0,AN21>0),AN21/(R21),0) -> 0 | AS21: =IF(AND(S21>0,AO21>0),AO21/(S21),0) -> 0.094356856 | AT21: ='13'!I46 -> 45494.83 | AU21: =AT21+AU20 -> 506479.28 | AV21: =IF(AND(L21>0,AT21>0),(AT21/(P21*1000)*1000),0) -> 957.28206 | AW21: =IF(AND(M21>0,AU21>0),(AU21/(Q21*1000)*1000),0) -> 727.48584 | AX21: =IF(AND(R21>0,AT21>0),(AT21/(R21*1000)*1000),0) -> 1051.8063 | AY21: =IF(AND(S21>0,AU21>0),(AU21/(S21*1000)*1000),0) -> 764.63668 | AZ21: =+Listrik!AH20 -> 531 | BA21: =AZ21+BA20 -> 109709 | BB21: =IF(AND(L21>0,AZ21>0),(AZ21/(P21*1000)*1000),0) -> 11.173067 | BC21: =IF(AND(M21>0,BA21>0),(BA21/(Q21*1000)*1000),0) -> 157.58146 | BD21: =IF(AND(R21>0,AZ21>0),(AZ21/(R21*1000)*1000),0) -> 12.276321 | BE21: =IF(AND(S21>0,BA21>0),(BA21/(S21*1000)*1000),0) -> 165.62874 | BF21: 9.407 | BG21: 107.194 | BH21: =+SUM(Efficiency2!K65:K66) -> 53.44027 | BI21: =BI20+BH21 -> 767.67721 | BJ21: =+R21/BH21 -> 0.80938962 | BK21: =+S21/BI21 -> 0.86283531
A22: =A21+1 -> 45883 | B22: Napkin | C22: 16 | D22: =+'14'!F42 -> 830 | E22: =+'14'!G42 -> 705.5 | F22: =1-(E22/D22) -> 0.15 | G22: =+P22/N22 -> 0.92427 | H22: =+P22/L22 -> 0.92427 | I22: =+R22/P22 -> 0.94157168 | J22: =+R22/L22 -> 0.87026645 | K22: =+S22/M22 -> 0.81248964 | L22: =+Efficiency1!K70 -> 52.015104 | M22: =M21+L22 -> 870.96003 | N22: =+Efficiency1!C70 -> 52.015104 | O22: =O21+N22 -> 853.49038 | P22: ='14'!I38 -> 48.076 | Q22: =Q21+P22 -> 744.281 | R22: ='14'!I40 -> 45.267 | S22: =S21+R22 -> 707.646 | T22: =R22/P22 -> 0.94157168 | U22: =S22/Q22 -> 0.950778 | V22: =R22/L22 -> 0.87026645 | W22: =S22/M22 -> 0.81248964 | AB22: 0 | AC22: =AB22+AC21 -> 0 | AD22: =AB22/P22 -> 0 | AE22: =AC22/Q22 -> 0 | AF22: =IF(AND(R22>0,AB22>0),(AB22/(R22*1000))*1000,0) -> 0 | AG22: =IF(AND(S22>0,AC22>0),AC22/S22,0) -> 0 | AH22: =+BF22+BG22 -> 115.741 | AI22: =AH22+AI21 -> 1900.36 | AJ22: =AH22/(P22) -> 2.407459 | AK22: =AI22/(Q22) -> 2.553283 | AL22: =IF(AND(R22>0,AH22>0),AH22/(R22),0) -> 2.5568516 | AM22: =IF(AND(S22>0,AI22>0),AI22/(S22),0) -> 2.685467 | AN22: 0 | AO22: =AN22+AO21 -> 62.5 | AP22: =AN22/(P22) -> 0 | AQ22: =AO22/(Q22) -> 0.08397366 | AR22: =IF(AND(R22>0,AN22>0),AN22/(R22),0) -> 0 | AS22: =IF(AND(S22>0,AO22>0),AO22/(S22),0) -> 0.088320997 | AT22: ='14'!I46 -> 41466.24 | AU22: =AT22+AU21 -> 547945.52 | AV22: =IF(AND(L22>0,AT22>0),(AT22/(P22*1000)*1000),0) -> 862.51435 | AW22: =IF(AND(M22>0,AU22>0),(AU22/(Q22*1000)*1000),0) -> 736.20786 | AX22: =IF(AND(R22>0,AT22>0),(AT22/(R22*1000)*1000),0) -> 916.03685 | AY22: =IF(AND(S22>0,AU22>0),(AU22/(S22*1000)*1000),0) -> 774.32151 | AZ22: =+Listrik!AH21 -> 363 | BA22: =AZ22+BA21 -> 110072 | BB22: =IF(AND(L22>0,AZ22>0),(AZ22/(P22*1000)*1000),0) -> 7.550545 | BC22: =IF(AND(M22>0,BA22>0),(BA22/(Q22*1000)*1000),0) -> 147.89038 | BD22: =IF(AND(R22>0,AZ22>0),(AZ22/(R22*1000)*1000),0) -> 8.0190868 | BE22: =IF(AND(S22>0,BA22>0),(BA22/(S22*1000)*1000),0) -> 155.5467 | BF22: 10.371 | BG22: 105.37 | BH22: =+Efficiency2!K70 -> 52.015104 | BI22: =BI21+BH22 -> 819.69231 | BJ22: =+R22/BH22 -> 0.87026645 | BK22: =+S22/BI22 -> 0.86330687
A23: =A22+1 -> 45884 | B23: Napkin | C23: 16 | D23: =+'15'!F42 -> 830 | E23: =+'15'!G42 -> 705.5 | F23: =1-(E23/D23) -> 0.15 | G23: =+P23/N23 -> 0.94151499 | H23: =+P23/L23 -> 0.94151499 | I23: =+R23/P23 -> 0.98868764 | J23: =+R23/L23 -> 0.93086424 | K23: =+S23/M23 -> 0.81916075 | L23: =+Efficiency1!K74 -> 52.015104 | M23: =M22+L23 -> 922.97513 | N23: =+Efficiency1!C74 -> 52.015104 | O23: =O22+N23 -> 905.50548 | P23: ='15'!I38 -> 48.973 | Q23: =Q22+P23 -> 793.254 | R23: ='15'!I40 -> 48.419 | S23: =S22+R23 -> 756.065 | T23: =R23/P23 -> 0.98868764 | U23: =S23/Q23 -> 0.95311842 | V23: =R23/L23 -> 0.93086424 | W23: =S23/M23 -> 0.81916075 | AB23: 0 | AC23: =AB23+AC22 -> 0 | AD23: =AB23/P23 -> 0 | AE23: =AC23/Q23 -> 0 | AF23: =IF(AND(R23>0,AB23>0),(AB23/(R23*1000))*1000,0) -> 0 | AG23: =IF(AND(S23>0,AC23>0),AC23/S23,0) -> 0 | AH23: =+BF23+BG23 -> 117.891 | AI23: =AH23+AI22 -> 2018.251 | AJ23: =AH23/(P23) -> 2.4072652 | AK23: =AI23/(Q23) -> 2.5442683 | AL23: =IF(AND(R23>0,AH23>0),AH23/(R23),0) -> 2.4348086 | AM23: =IF(AND(S23>0,AI23>0),AI23/(S23),0) -> 2.6694147 | AN23: 0 | AO23: =AN23+AO22 -> 62.5 | AP23: =AN23/(P23) -> 0 | AQ23: =AO23/(Q23) -> 0.078789392 | AR23: =IF(AND(R23>0,AN23>0),AN23/(R23),0) -> 0 | AS23: =IF(AND(S23>0,AO23>0),AO23/(S23),0) -> 0.08266485 | AT23: ='15'!I46 -> 45444.29 | AU23: =AT23+AU22 -> 593389.81 | AV23: =IF(AND(L23>0,AT23>0),(AT23/(P23*1000)*1000),0) -> 927.94581 | AW23: =IF(AND(M23>0,AU23>0),(AU23/(Q23*1000)*1000),0) -> 748.04515 | AX23: =IF(AND(R23>0,AT23>0),(AT23/(R23*1000)*1000),0) -> 938.56317 | AY23: =IF(AND(S23>0,AU23>0),(AU23/(S23*1000)*1000),0) -> 784.83968 | AZ23: =+Listrik!AH22 -> 444 | BA23: =AZ23+BA22 -> 110516 | BB23: =IF(AND(L23>0,AZ23>0),(AZ23/(P23*1000)*1000),0) -> 9.0662202 | BC23: =IF(AND(M23>0,BA23>0),(BA23/(Q23*1000)*1000),0) -> 139.31981 | BD23: =IF(AND(R23>0,AZ23>0),(AZ23/(R23*1000)*1000),0) -> 9.1699539 | BE23: =IF(AND(S23>0,BA23>0),(BA23/(S23*1000)*1000),0) -> 146.17262 | BF23: 11.933 | BG23: 105.958 | BH23: =+Efficiency2!K74 -> 52.015104 | BI23: =BI22+BH23 -> 871.70741 | BJ23: =+R23/BH23 -> 0.93086424 | BK23: =+S23/BI23 -> 0.86733804
A24: =A23+1 -> 45885 | B24: Napkin | C24: 16 | D24: =+'16'!F42 -> 830 | E24: =+'16'!G42 -> 705.5 | F24: =1-(E24/D24) -> 0.15 | G24: =+P24/N24 -> 0.93905416 | H24: =+P24/L24 -> 0.93905416 | I24: =+R24/P24 -> 1.0013922 | J24: =+R24/L24 -> 0.94036148 | K24: =+S24/M24 -> 0.82562673 | L24: =+Efficiency1!K78 -> 52.015104 | M24: =M23+L24 -> 974.99024 | N24: =+Efficiency1!C78 -> 52.015104 | O24: =O23+N24 -> 957.52058 | P24: ='16'!I38 -> 48.845 | Q24: =Q23+P24 -> 842.099 | R24: ='16'!I40 -> 48.913 | S24: =S23+R24 -> 804.978 | T24: =R24/P24 -> 1.0013922 | U24: =S24/Q24 -> 0.95591848 | V24: =R24/L24 -> 0.94036148 | W24: =S24/M24 -> 0.82562673 | AB24: 0 | AC24: =AB24+AC23 -> 0 | AD24: =AB24/P24 -> 0 | AE24: =AC24/Q24 -> 0 | AF24: =IF(AND(R24>0,AB24>0),(AB24/(R24*1000))*1000,0) -> 0 | AG24: =IF(AND(S24>0,AC24>0),AC24/S24,0) -> 0 | AH24: =+BF24+BG24 -> 115.43 | AI24: =AH24+AI23 -> 2133.681 | AJ24: =AH24/(P24) -> 2.3631897 | AK24: =AI24/(Q24) -> 2.533765 | AL24: =IF(AND(R24>0,AH24>0),AH24/(R24),0) -> 2.3599043 | AM24: =IF(AND(S24>0,AI24>0),AI24/(S24),0) -> 2.6506078 | AN24: 0 | AO24: =AN24+AO23 -> 62.5 | AP24: =AN24/(P24) -> 0 | AQ24: =AO24/(Q24) -> 0.074219302 | AR24: =IF(AND(R24>0,AN24>0),AN24/(R24),0) -> 0 | AS24: =IF(AND(S24>0,AO24>0),AO24/(S24),0) -> 0.077641873 | AT24: ='16'!I46 -> 45451.2 | AU24: =AT24+AU23 -> 638841.01 | AV24: =IF(AND(L24>0,AT24>0),(AT24/(P24*1000)*1000),0) -> 930.51899 | AW24: =IF(AND(M24>0,AU24>0),(AU24/(Q24*1000)*1000),0) -> 758.62934 | AX24: =IF(AND(R24>0,AT24>0),(AT24/(R24*1000)*1000),0) -> 929.22536 | AY24: =IF(AND(S24>0,AU24>0),(AU24/(S24*1000)*1000),0) -> 793.61301 | AZ24: =+Listrik!AH23 -> 438 | BA24: =AZ24+BA23 -> 110954 | BB24: =IF(AND(L24>0,AZ24>0),(AZ24/(P24*1000)*1000),0) -> 8.967141 | BC24: =IF(AND(M24>0,BA24>0),(BA24/(Q24*1000)*1000),0) -> 131.75885 | BD24: =IF(AND(R24>0,AZ24>0),(AZ24/(R24*1000)*1000),0) -> 8.9546746 | BE24: =IF(AND(S24>0,BA24>0),(BA24/(S24*1000)*1000),0) -> 137.83482 | BF24: 10.511 | BG24: 104.919 | BH24: =+Efficiency2!K78 -> 52.015104 | BI24: =BI23+BH24 -> 923.72252 | BJ24: =+R24/BH24 -> 0.94036148 | BK24: =+S24/BI24 -> 0.87145001
A25: =A24+1 -> 45886 | B25: Napkin | C25: 16 | D25: =+'17'!F42 -> 830 | E25: =+'17'!G42 -> 705.5 | F25: =1-(E25/D25) -> 0.15 | G25: =+P25/N25 -> 0.93313281 | H25: =+P25/L25 -> 0.93313281 | I25: =+R25/P25 -> 1.014731 | J25: =+R25/L25 -> 0.94687881 | K25: =+S25/M25 -> 0.83176783 | L25: =+Efficiency1!K82 -> 52.015104 | M25: =M24+L25 -> 1027.0053 | N25: =+Efficiency1!C82 -> 52.015104 | O25: =O24+N25 -> 1009.5357 | P25: ='17'!I38 -> 48.537 | Q25: =Q24+P25 -> 890.636 | R25: ='17'!I40 -> 49.252 | S25: =S24+R25 -> 854.23 | T25: =R25/P25 -> 1.014731 | U25: =S25/Q25 -> 0.95912359 | V25: =R25/L25 -> 0.94687881 | W25: =S25/M25 -> 0.83176783 | AB25: 0 | AC25: =AB25+AC24 -> 0 | AD25: =AB25/P25 -> 0 | AE25: =AC25/Q25 -> 0 | AF25: =IF(AND(R25>0,AB25>0),(AB25/(R25*1000))*1000,0) -> 0 | AG25: =IF(AND(S25>0,AC25>0),AC25/S25,0) -> 0 | AH25: =+BF25+BG25 -> 113.325 | AI25: =AH25+AI24 -> 2247.006 | AJ25: =AH25/(P25) -> 2.3348167 | AK25: =AI25/(Q25) -> 2.5229229 | AL25: =IF(AND(R25>0,AH25>0),AH25/(R25),0) -> 2.3009218 | AM25: =IF(AND(S25>0,AI25>0),AI25/(S25),0) -> 2.6304461 | AN25: 0 | AO25: =AN25+AO24 -> 62.5 | AP25: =AN25/(P25) -> 0 | AQ25: =AO25/(Q25) -> 0.070174572 | AR25: =IF(AND(R25>0,AN25>0),AN25/(R25),0) -> 0 | AS25: =IF(AND(S25>0,AO25>0),AO25/(S25),0) -> 0.073165307 | AT25: ='17'!I46 -> 43184.71 | AU25: =AT25+AU24 -> 682025.72 | AV25: =IF(AND(L25>0,AT25>0),(AT25/(P25*1000)*1000),0) -> 889.72763 | AW25: =IF(AND(M25>0,AU25>0),(AU25/(Q25*1000)*1000),0) -> 765.77381 | AX25: =IF(AND(R25>0,AT25>0),(AT25/(R25*1000)*1000),0) -> 876.8113 | AY25: =IF(AND(S25>0,AU25>0),(AU25/(S25*1000)*1000),0) -> 798.40994 | AZ25: =+Listrik!AH24 -> 422 | BA25: =AZ25+BA24 -> 111376 | BB25: =IF(AND(L25>0,AZ25>0),(AZ25/(P25*1000)*1000),0) -> 8.6943981 | BC25: =IF(AND(M25>0,BA25>0),(BA25/(Q25*1000)*1000),0) -> 125.05221 | BD25: =IF(AND(R25>0,AZ25>0),(AZ25/(R25*1000)*1000),0) -> 8.56818 | BE25: =IF(AND(S25>0,BA25>0),(BA25/(S25*1000)*1000),0) -> 130.38175 | BF25: 9.749 | BG25: 103.576 | BH25: =+Efficiency2!K82 -> 52.015104 | BI25: =BI24+BH25 -> 975.73762 | BJ25: =+R25/BH25 -> 0.94687881 | BK25: =+S25/BI25 -> 0.87547101
A26: =A25+1 -> 45887 | B26: Napkin/Towel | C26: 16/23 | D26: =+'18'!F42 -> 830 | E26: =+'18'!G42 -> 718.9875 | F26: =1-(E26/D26) -> 0.13375 | G26: =+P26/N26 -> 0.94948021 | H26: =+P26/L26 -> 0.94948021 | I26: =+R26/P26 -> 0.98086657 | J26: =+R26/L26 -> 0.93131339 | K26: =+S26/M26 -> 0.83788225 | L26: =+SUM(Efficiency1!K87:K88) -> 67.210458 | M26: =M25+L26 -> 1094.2158 | N26: =+SUM(Efficiency1!C87:C88) -> 67.210458 | O26: =O25+N26 -> 1076.7461 | P26: ='18'!I38 -> 63.815 | Q26: =Q25+P26 -> 954.451 | R26: ='18'!I40 -> 62.594 | S26: =S25+R26 -> 916.824 | T26: =R26/P26 -> 0.98086657 | U26: =S26/Q26 -> 0.96057734 | V26: =R26/L26 -> 0.93131339 | W26: =S26/M26 -> 0.83788225 | AB26: 0 | AC26: =AB26+AC25 -> 0 | AD26: =AB26/P26 -> 0 | AE26: =AC26/Q26 -> 0 | AF26: =IF(AND(R26>0,AB26>0),(AB26/(R26*1000))*1000,0) -> 0 | AG26: =IF(AND(S26>0,AC26>0),AC26/S26,0) -> 0 | AH26: =+BF26+BG26 -> 135.752 | AI26: =AH26+AI25 -> 2382.758 | AJ26: =AH26/(P26) -> 2.1272742 | AK26: =AI26/(Q26) -> 2.4964697 | AL26: =IF(AND(R26>0,AH26>0),AH26/(R26),0) -> 2.1687702 | AM26: =IF(AND(S26>0,AI26>0),AI26/(S26),0) -> 2.5989263 | AN26: 0 | AO26: =AN26+AO25 -> 62.5 | AP26: =AN26/(P26) -> 0 | AQ26: =AO26/(Q26) -> 0.06548267 | AR26: =IF(AND(R26>0,AN26>0),AN26/(R26),0) -> 0 | AS26: =IF(AND(S26>0,AO26>0),AO26/(S26),0) -> 0.068170118 | AT26: ='18'!I46 -> 46342.47 | AU26: =AT26+AU25 -> 728368.19 | AV26: =IF(AND(L26>0,AT26>0),(AT26/(P26*1000)*1000),0) -> 726.20027 | AW26: =IF(AND(M26>0,AU26>0),(AU26/(Q26*1000)*1000),0) -> 763.1279 | AX26: =IF(AND(R26>0,AT26>0),(AT26/(R26*1000)*1000),0) -> 740.36601 | AY26: =IF(AND(S26>0,AU26>0),(AU26/(S26*1000)*1000),0) -> 794.44712 | AZ26: =+Listrik!AH25 -> 451 | BA26: =AZ26+BA25 -> 111827 | BB26: =IF(AND(L26>0,AZ26>0),(AZ26/(P26*1000)*1000),0) -> 7.0673039 | BC26: =IF(AND(M26>0,BA26>0),(BA26/(Q26*1000)*1000),0) -> 117.16369 | BD26: =IF(AND(R26>0,AZ26>0),(AZ26/(R26*1000)*1000),0) -> 7.2051634 | BE26: =IF(AND(S26>0,BA26>0),(BA26/(S26*1000)*1000),0) -> 121.97216 | BF26: 20.451 | BG26: 115.301 | BH26: =+SUM(Efficiency2!K87:K88) -> 67.210458 | BI26: =BI25+BH26 -> 1042.9481 | BJ26: =+R26/BH26 -> 0.93131339 | BK26: =+S26/BI26 -> 0.87906965
A27: =A26+1 -> 45888 | B27: Towel | C27: 23/17 | D27: =+'19'!F42 -> 830 | E27: =+'19'!G42 -> 709.65 | F27: =1-(E27/D27) -> 0.145 | G27: =+P27/N27 -> 0.95443971 | H27: =+P27/L27 -> 0.95443971 | I27: =+R27/P27 -> 0.94104074 | J27: =+R27/L27 -> 0.89816665 | K27: =+S27/M27 -> 0.84145923 | L27: =+SUM(Efficiency1!K92:K93) -> 69.020599 | M27: =M26+L27 -> 1163.2364 | N27: =+SUM(Efficiency1!C92:C93) -> 69.020599 | O27: =O26+N27 -> 1145.7667 | P27: ='19'!I38 -> 65.876 | Q27: =Q26+P27 -> 1020.327 | R27: ='19'!I40 -> 61.992 | S27: =S26+R27 -> 978.816 | T27: =R27/P27 -> 0.94104074 | U27: =S27/Q27 -> 0.95931598 | V27: =R27/L27 -> 0.89816665 | W27: =S27/M27 -> 0.84145923 | AB27: 0 | AC27: =AB27+AC26 -> 0 | AD27: =AB27/P27 -> 0 | AE27: =AC27/Q27 -> 0 | AF27: =IF(AND(R27>0,AB27>0),(AB27/(R27*1000))*1000,0) -> 0 | AG27: =IF(AND(S27>0,AC27>0),AC27/S27,0) -> 0 | AH27: =+BF27+BG27 -> 138.817 | AI27: =AH27+AI26 -> 2521.575 | AJ27: =AH27/(P27) -> 2.1072469 | AK27: =AI27/(Q27) -> 2.4713401 | AL27: =IF(AND(R27>0,AH27>0),AH27/(R27),0) -> 2.2392728 | AM27: =IF(AND(S27>0,AI27>0),AI27/(S27),0) -> 2.5761481 | AN27: 0 | AO27: =AN27+AO26 -> 62.5 | AP27: =AN27/(P27) -> 0 | AQ27: =AO27/(Q27) -> 0.061254872 | AR27: =IF(AND(R27>0,AN27>0),AN27/(R27),0) -> 0 | AS27: =IF(AND(S27>0,AO27>0),AO27/(S27),0) -> 0.063852655 | AT27: ='19'!I46 -> 48109.29 | AU27: =AT27+AU26 -> 776477.48 | AV27: =IF(AND(L27>0,AT27>0),(AT27/(P27*1000)*1000),0) -> 730.30072 | AW27: =IF(AND(M27>0,AU27>0),(AU27/(Q27*1000)*1000),0) -> 761.00846 | AX27: =IF(AND(R27>0,AT27>0),(AT27/(R27*1000)*1000),0) -> 776.05643 | AY27: =IF(AND(S27>0,AU27>0),(AU27/(S27*1000)*1000),0) -> 793.28237 | AZ27: =+Listrik!AH26 -> 448 | BA27: =AZ27+BA26 -> 112275 | BB27: =IF(AND(L27>0,AZ27>0),(AZ27/(P27*1000)*1000),0) -> 6.8006558 | BC27: =IF(AND(M27>0,BA27>0),(BA27/(Q27*1000)*1000),0) -> 110.03825 | BD27: =IF(AND(R27>0,AZ27>0),(AZ27/(R27*1000)*1000),0) -> 7.2267389 | BE27: =IF(AND(S27>0,BA27>0),(BA27/(S27*1000)*1000),0) -> 114.70491 | BF27: 22.284 | BG27: 116.533 | BH27: =+SUM(Efficiency2!K92:K93) -> 69.020599 | BI27: =BI26+BH27 -> 1111.9687 | BJ27: =+R27/BH27 -> 0.89816665 | BK27: =+S27/BI27 -> 0.88025501
A28: =A27+1 -> 45889 | B28: Towel | C28: 17 | D28: =+'20'!F42 -> 830 | E28: =+'20'!G42 -> 680.6 | F28: =1-(E28/D28) -> 0.18 | G28: =+P28/N28 -> 0.94227825 | H28: =+P28/L28 -> 0.94227825 | I28: =+R28/P28 -> 0.98982429 | J28: =+R28/L28 -> 0.9326899 | K28: =+S28/M28 -> 0.84549324 | L28: =+Efficiency1!K97 -> 53.815314 | M28: =M27+L28 -> 1217.0517 | N28: =+Efficiency1!C97 -> 53.815314 | O28: =O27+N28 -> 1199.5821 | P28: ='20'!I38 -> 50.709 | Q28: =Q27+P28 -> 1071.036 | R28: ='20'!I40 -> 50.193 | S28: =S27+R28 -> 1029.009 | T28: =R28/P28 -> 0.98982429 | U28: =S28/Q28 -> 0.96076042 | V28: =R28/L28 -> 0.9326899 | W28: =S28/M28 -> 0.84549324 | AB28: 0 | AC28: =AB28+AC27 -> 0 | AD28: =AB28/P28 -> 0 | AE28: =AC28/Q28 -> 0 | AF28: =IF(AND(R28>0,AB28>0),(AB28/(R28*1000))*1000,0) -> 0 | AG28: =IF(AND(S28>0,AC28>0),AC28/S28,0) -> 0 | AH28: =+BF28+BG28 -> 123.075 | AI28: =AH28+AI27 -> 2644.65 | AJ28: =AH28/(P28) -> 2.4270839 | AK28: =AI28/(Q28) -> 2.4692447 | AL28: =IF(AND(R28>0,AH28>0),AH28/(R28),0) -> 2.4520351 | AM28: =IF(AND(S28>0,AI28>0),AI28/(S28),0) -> 2.5700941 | AN28: 0 | AO28: =AN28+AO27 -> 62.5 | AP28: =AN28/(P28) -> 0 | AQ28: =AO28/(Q28) -> 0.058354715 | AR28: =IF(AND(R28>0,AN28>0),AN28/(R28),0) -> 0 | AS28: =IF(AND(S28>0,AO28>0),AO28/(S28),0) -> 0.06073805 | AT28: ='20'!I46 -> 48289.2 | AU28: =AT28+AU27 -> 824766.68 | AV28: =IF(AND(L28>0,AT28>0),(AT28/(P28*1000)*1000),0) -> 952.28066 | AW28: =IF(AND(M28>0,AU28>0),(AU28/(Q28*1000)*1000),0) -> 770.06439 | AX28: =IF(AND(R28>0,AT28>0),(AT28/(R28*1000)*1000),0) -> 962.07041 | AY28: =IF(AND(S28>0,AU28>0),(AU28/(S28*1000)*1000),0) -> 801.51552 | AZ28: =+Listrik!AH27 -> 448 | BA28: =AZ28+BA27 -> 112723 | BB28: =IF(AND(L28>0,AZ28>0),(AZ28/(P28*1000)*1000),0) -> 8.8347236 | BC28: =IF(AND(M28>0,BA28>0),(BA28/(Q28*1000)*1000),0) -> 105.2467 | BD28: =IF(AND(R28>0,AZ28>0),(AZ28/(R28*1000)*1000),0) -> 8.9255474 | BE28: =IF(AND(S28>0,BA28>0),(BA28/(S28*1000)*1000),0) -> 109.5452 | BF28: 23.2 | BG28: 99.875 | BH28: =+Efficiency2!K97 -> 53.815314 | BI28: =BI27+BH28 -> 1165.784 | BJ28: =+R28/BH28 -> 0.9326899 | BK28: =+S28/BI28 -> 0.88267553
A29: =A28+1 -> 45890 | B29: Towel | C29: 17 | D29: =+'21'!F42 -> 830 | E29: =+'21'!G42 -> 680.6 | F29: =1-(E29/D29) -> 0.18 | G29: =+P29/N29 -> 0.9428601 | H29: =+P29/L29 -> 0.9428601 | I29: =+R29/P29 -> 0.98284208 | J29: =+R29/L29 -> 0.92668258 | K29: =+S29/M29 -> 0.84893654 | L29: =+Efficiency1!K101 -> 53.901952 | M29: =M28+L29 -> 1270.9537 | N29: =+Efficiency1!C101 -> 53.901952 | O29: =O28+N29 -> 1253.484 | P29: ='21'!I38 -> 50.822 | Q29: =Q28+P29 -> 1121.858 | R29: ='21'!I40 -> 49.95 | S29: =S28+R29 -> 1078.959 | T29: =R29/P29 -> 0.98284208 | U29: =S29/Q29 -> 0.96176076 | V29: =R29/L29 -> 0.92668258 | W29: =S29/M29 -> 0.84893654 | AB29: 0 | AC29: =AB29+AC28 -> 0 | AD29: =AB29/P29 -> 0 | AE29: =AC29/Q29 -> 0 | AF29: =IF(AND(R29>0,AB29>0),(AB29/(R29*1000))*1000,0) -> 0 | AG29: =IF(AND(S29>0,AC29>0),AC29/S29,0) -> 0 | AH29: =+BF29+BG29 -> 108.176 | AI29: =AH29+AI28 -> 2752.826 | AJ29: =AH29/(P29) -> 2.128527 | AK29: =AI29/(Q29) -> 2.4538097 | AL29: =IF(AND(R29>0,AH29>0),AH29/(R29),0) -> 2.1656857 | AM29: =IF(AND(S29>0,AI29>0),AI29/(S29),0) -> 2.5513722 | AN29: 0 | AO29: =AN29+AO28 -> 62.5 | AP29: =AN29/(P29) -> 0 | AQ29: =AO29/(Q29) -> 0.055711151 | AR29: =IF(AND(R29>0,AN29>0),AN29/(R29),0) -> 0 | AS29: =IF(AND(S29>0,AO29>0),AO29/(S29),0) -> 0.057926205 | AT29: ='21'!I46 -> 42917.65 | AU29: =AT29+AU28 -> 867684.33 | AV29: =IF(AND(L29>0,AT29>0),(AT29/(P29*1000)*1000),0) -> 844.46991 | AW29: =IF(AND(M29>0,AU29>0),(AU29/(Q29*1000)*1000),0) -> 773.43508 | AX29: =IF(AND(R29>0,AT29>0),(AT29/(R29*1000)*1000),0) -> 859.21221 | AY29: =IF(AND(S29>0,AU29>0),(AU29/(S29*1000)*1000),0) -> 804.18656 | AZ29: =+Listrik!AH28 -> 426 | BA29: =AZ29+BA28 -> 113149 | BB29: =IF(AND(L29>0,AZ29>0),(AZ29/(P29*1000)*1000),0) -> 8.3821967 | BC29: =IF(AND(M29>0,BA29>0),(BA29/(Q29*1000)*1000),0) -> 100.85858 | BD29: =IF(AND(R29>0,AZ29>0),(AZ29/(R29*1000)*1000),0) -> 8.5285285 | BE29: =IF(AND(S29>0,BA29>0),(BA29/(S29*1000)*1000),0) -> 104.86867 | BF29: 7.726 | BG29: 100.45 | BH29: =+Efficiency2!K101 -> 53.901952 | BI29: =BI28+BH29 -> 1219.6859 | BJ29: =+R29/BH29 -> 0.92668258 | BK29: =+S29/BI29 -> 0.88462034
A30: =A29+1 -> 45891 | B30: Towel | C30: 17/16 | D30: =+'22'!F42 -> 830 | E30: =+'22'!G42 -> 680.6 | F30: =1-(E30/D30) -> 0.18 | G30: =+P30/N30 -> 0.94815375 | H30: =+P30/L30 -> 0.94815375 | I30: =+R30/P30 -> 0.99561797 | J30: =+R30/L30 -> 0.94399891 | K30: =+S30/M30 -> 0.85273861 | L30: =+SUM(Efficiency1!K105:K106) -> 52.950273 | M30: =M29+L30 -> 1323.9039 | N30: =+SUM(Efficiency1!C105:C106) -> 52.950273 | O30: =O29+N30 -> 1306.4343 | P30: ='22'!I38 -> 50.205 | Q30: =Q29+P30 -> 1172.063 | R30: ='22'!I40 -> 49.985 | S30: =S29+R30 -> 1128.944 | T30: =R30/P30 -> 0.99561797 | U30: =S30/Q30 -> 0.96321102 | V30: =R30/L30 -> 0.94399891 | W30: =S30/M30 -> 0.85273861 | AB30: 0 | AC30: =AB30+AC29 -> 0 | AD30: =AB30/P30 -> 0 | AE30: =AC30/Q30 -> 0 | AF30: =IF(AND(R30>0,AB30>0),(AB30/(R30*1000))*1000,0) -> 0 | AG30: =IF(AND(S30>0,AC30>0),AC30/S30,0) -> 0 | AH30: =+BF30+BG30 -> 105.152 | AI30: =AH30+AI29 -> 2857.978 | AJ30: =AH30/(P30) -> 2.0944527 | AK30: =AI30/(Q30) -> 2.4384167 | AL30: =IF(AND(R30>0,AH30>0),AH30/(R30),0) -> 2.1036711 | AM30: =IF(AND(S30>0,AI30>0),AI30/(S30),0) -> 2.5315498 | AN30: 0 | AO30: =AN30+AO29 -> 62.5 | AP30: =AN30/(P30) -> 0 | AQ30: =AO30/(Q30) -> 0.053324779 | AR30: =IF(AND(R30>0,AN30>0),AN30/(R30),0) -> 0 | AS30: =IF(AND(S30>0,AO30>0),AO30/(S30),0) -> 0.055361471 | AT30: ='22'!I46 -> 43762.28 | AU30: =AT30+AU29 -> 911446.61 | AV30: =IF(AND(L30>0,AT30>0),(AT30/(P30*1000)*1000),0) -> 871.67175 | AW30: =IF(AND(M30>0,AU30>0),(AU30/(Q30*1000)*1000),0) -> 777.64302 | AX30: =IF(AND(R30>0,AT30>0),(AT30/(R30*1000)*1000),0) -> 875.50825 | AY30: =IF(AND(S30>0,AU30>0),(AU30/(S30*1000)*1000),0) -> 807.34439 | AZ30: =+Listrik!AH29 -> 442 | BA30: =AZ30+BA29 -> 113591 | BB30: =IF(AND(L30>0,AZ30>0),(AZ30/(P30*1000)*1000),0) -> 8.803904 | BC30: =IF(AND(M30>0,BA30>0),(BA30/(Q30*1000)*1000),0) -> 96.915439 | BD30: =IF(AND(R30>0,AZ30>0),(AZ30/(R30*1000)*1000),0) -> 8.8426528 | BE30: =IF(AND(S30>0,BA30>0),(BA30/(S30*1000)*1000),0) -> 100.61704 | BF30: 6.286 | BG30: 98.866 | BH30: =+SUM(Efficiency2!K105:K106) -> 52.950273 | BI30: =BI29+BH30 -> 1272.6362 | BJ30: =+R30/BH30 -> 0.94399891 | BK30: =+S30/BI30 -> 0.88709089
A31: =A30+1 -> 45892 | B31: Towel | C31: 16 | D31: =+'23'!F42 -> 830 | E31: =+'23'!G42 -> 680.6 | F31: =1-(E31/D31) -> 0.18 | G31: =+P31/N31 -> 0.95912494 | H31: =+P31/L31 -> 0.95912494 | I31: =+R31/P31 -> 1.021553 | J31: =+R31/L31 -> 0.97979699 | K31: =+S31/M31 -> 0.85747629 | L31: =+Efficiency1!K110 -> 51.276948 | M31: =M30+L31 -> 1375.1809 | N31: =+Efficiency1!C110 -> 51.276948 | O31: =O30+N31 -> 1357.7112 | P31: ='23'!I38 -> 49.181 | Q31: =Q30+P31 -> 1221.244 | R31: ='23'!I40 -> 50.241 | S31: =S30+R31 -> 1179.185 | T31: =R31/P31 -> 1.021553 | U31: =S31/Q31 -> 0.96556053 | V31: =R31/L31 -> 0.97979699 | W31: =S31/M31 -> 0.85747629 | AB31: 0 | AC31: =AB31+AC30 -> 0 | AD31: =AB31/P31 -> 0 | AE31: =AC31/Q31 -> 0 | AF31: =IF(AND(R31>0,AB31>0),(AB31/(R31*1000))*1000,0) -> 0 | AG31: =IF(AND(S31>0,AC31>0),AC31/S31,0) -> 0 | AH31: =+BF31+BG31 -> 105.311 | AI31: =AH31+AI30 -> 2963.289 | AJ31: =AH31/(P31) -> 2.1412944 | AK31: =AI31/(Q31) -> 2.4264512 | AL31: =IF(AND(R31>0,AH31>0),AH31/(R31),0) -> 2.0961167 | AM31: =IF(AND(S31>0,AI31>0),AI31/(S31),0) -> 2.5129975 | AN31: 0 | AO31: =AN31+AO30 -> 62.5 | AP31: =AN31/(P31) -> 0 | AQ31: =AO31/(Q31) -> 0.051177324 | AR31: =IF(AND(R31>0,AN31>0),AN31/(R31),0) -> 0 | AS31: =IF(AND(S31>0,AO31>0),AO31/(S31),0) -> 0.053002709 | AT31: ='23'!I46 -> 43551.41 | AU31: =AT31+AU30 -> 954998.02 | AV31: =IF(AND(L31>0,AT31>0),(AT31/(P31*1000)*1000),0) -> 885.53323 | AW31: =IF(AND(M31>0,AU31>0),(AU31/(Q31*1000)*1000),0) -> 781.98789 | AX31: =IF(AND(R31>0,AT31>0),(AT31/(R31*1000)*1000),0) -> 866.84998 | AY31: =IF(AND(S31>0,AU31>0),(AU31/(S31*1000)*1000),0) -> 809.87972 | AZ31: =+Listrik!AH30 -> 269 | BA31: =AZ31+BA30 -> 113860 | BB31: =IF(AND(L31>0,AZ31>0),(AZ31/(P31*1000)*1000),0) -> 5.4695919 | BC31: =IF(AND(M31>0,BA31>0),(BA31/(Q31*1000)*1000),0) -> 93.232802 | BD31: =IF(AND(R31>0,AZ31>0),(AZ31/(R31*1000)*1000),0) -> 5.3541928 | BE31: =IF(AND(S31>0,BA31>0),(BA31/(S31*1000)*1000),0) -> 96.558216 | BF31: 6.385 | BG31: 98.926 | BH31: =+Efficiency2!K110 -> 51.276948 | BI31: =BI30+BH31 -> 1323.9132 | BJ31: =+R31/BH31 -> 0.97979699 | BK31: =+S31/BI31 -> 0.89068153
A32: =A31+1 -> 45893 | B32: Towel | C32: 16 | D32: =+'24'!F42 -> 830 | E32: =+'24'!G42 -> 680.6 | F32: =1-(E32/D32) -> 0.18 | G32: =+P32/N32 -> 0.98511638 | H32: =+P32/L32 -> 0.98511638 | I32: =+R32/P32 -> 1.0126109 | J32: =+R32/L32 -> 0.99753962 | K32: =+S32/M32 -> 0.86251857 | L32: =+Efficiency1!K114 -> 51.355354 | M32: =M31+L32 -> 1426.5362 | N32: =+Efficiency1!C114 -> 51.355354 | O32: =O31+N32 -> 1409.0666 | P32: ='24'!I38 -> 50.591 | Q32: =Q31+P32 -> 1271.835 | R32: ='24'!I40 -> 51.229 | S32: =S31+R32 -> 1230.414 | T32: =R32/P32 -> 1.0126109 | U32: =S32/Q32 -> 0.9674321 | V32: =R32/L32 -> 0.99753962 | W32: =S32/M32 -> 0.86251857 | AB32: 0 | AC32: =AB32+AC31 -> 0 | AD32: =AB32/P32 -> 0 | AE32: =AC32/Q32 -> 0 | AF32: =IF(AND(R32>0,AB32>0),(AB32/(R32*1000))*1000,0) -> 0 | AG32: =IF(AND(S32>0,AC32>0),AC32/S32,0) -> 0 | AH32: =+BF32+BG32 -> 105.106 | AI32: =AH32+AI31 -> 3068.395 | AJ32: =AH32/(P32) -> 2.0775632 | AK32: =AI32/(Q32) -> 2.4125732 | AL32: =IF(AND(R32>0,AH32>0),AH32/(R32),0) -> 2.0516895 | AM32: =IF(AND(S32>0,AI32>0),AI32/(S32),0) -> 2.4937907 | AN32: 0 | AO32: =AN32+AO31 -> 62.5 | AP32: =AN32/(P32) -> 0 | AQ32: =AO32/(Q32) -> 0.049141595 | AR32: =IF(AND(R32>0,AN32>0),AN32/(R32),0) -> 0 | AS32: =IF(AND(S32>0,AO32>0),AO32/(S32),0) -> 0.050795911 | AT32: =+'24'!I46 -> 43127.88 | AU32: =AT32+AU31 -> 998125.9 | AV32: =IF(AND(L32>0,AT32>0),(AT32/(P32*1000)*1000),0) -> 852.48127 | AW32: =IF(AND(M32>0,AU32>0),(AU32/(Q32*1000)*1000),0) -> 784.79197 | AX32: =IF(AND(R32>0,AT32>0),(AT32/(R32*1000)*1000),0) -> 841.86457 | AY32: =IF(AND(S32>0,AU32>0),(AU32/(S32*1000)*1000),0) -> 811.21143 | AZ32: =+Listrik!AH31 -> 736 | BA32: =AZ32+BA31 -> 114596 | BB32: =IF(AND(L32>0,AZ32>0),(AZ32/(P32*1000)*1000),0) -> 14.548042 | BC32: =IF(AND(M32>0,BA32>0),(BA32/(Q32*1000)*1000),0) -> 90.102883 | BD32: =IF(AND(R32>0,AZ32>0),(AZ32/(R32*1000)*1000),0) -> 14.366863 | BE32: =IF(AND(S32>0,BA32>0),(BA32/(S32*1000)*1000),0) -> 93.136131 | BF32: 6.468 | BG32: 98.638 | BH32: =+Efficiency2!K114 -> 51.355354 | BI32: =BI31+BH32 -> 1375.2685 | BJ32: =+R32/BH32 -> 0.99753962 | BK32: =+S32/BI32 -> 0.89467183
A33: =A32+1 -> 45894 | B33: Towel/Napkin | C33: 16/18 | D33: =+'25'!F42 -> 830 | E33: =+'25'!G42 -> 704.11667 | F33: =1-(E33/D33) -> 0.15166667 | G33: =+P33/N33 -> 0.95970529 | H33: =+P33/L33 -> 0.95970529 | I33: =+R33/P33 -> 0.99061355 | J33: =+R33/L33 -> 0.95069706 | K33: =+S33/M33 -> 0.86594796 | L33: =+SUM(Efficiency1!K118:K119) -> 57.725013 | M33: =M32+L33 -> 1484.2613 | N33: =+SUM(Efficiency1!C118:C119) -> 57.725013 | O33: =O32+N33 -> 1466.7916 | P33: ='25'!I38 -> 55.399 | Q33: =Q32+P33 -> 1327.234 | R33: ='25'!I40 -> 54.879 | S33: =S32+R33 -> 1285.293 | T33: =R33/P33 -> 0.99061355 | U33: =S33/Q33 -> 0.96839969 | V33: =R33/L33 -> 0.95069706 | W33: =S33/M33 -> 0.86594796 | AB33: 0 | AC33: =AB33+AC32 -> 0 | AD33: =AB33/P33 -> 0 | AE33: =AC33/Q33 -> 0 | AF33: =IF(AND(R33>0,AB33>0),(AB33/(R33*1000))*1000,0) -> 0 | AG33: =IF(AND(S33>0,AC33>0),AC33/S33,0) -> 0 | AH33: =+BF33+BG33 -> 109.325 | AI33: =AH33+AI32 -> 3177.72 | AJ33: =AH33/(P33) -> 1.9734111 | AK33: =AI33/(Q33) -> 2.3942425 | AL33: =IF(AND(R33>0,AH33>0),AH33/(R33),0) -> 1.9921099 | AM33: =IF(AND(S33>0,AI33>0),AI33/(S33),0) -> 2.4723701 | AN33: 0 | AO33: =AN33+AO32 -> 62.5 | AP33: =AN33/(P33) -> 0 | AQ33: =AO33/(Q33) -> 0.047090415 | AR33: =IF(AND(R33>0,AN33>0),AN33/(R33),0) -> 0 | AS33: =IF(AND(S33>0,AO33>0),AO33/(S33),0) -> 0.048627045 | AT33: =+'25'!I46 -> 43253.17 | AU33: =AT33+AU32 -> 1041379.1 | AV33: =IF(AND(L33>0,AT33>0),(AT33/(P33*1000)*1000),0) -> 780.75723 | AW33: =IF(AND(M33>0,AU33>0),(AU33/(Q33*1000)*1000),0) -> 784.62356 | AX33: =IF(AND(R33>0,AT33>0),(AT33/(R33*1000)*1000),0) -> 788.15521 | AY33: =IF(AND(S33>0,AU33>0),(AU33/(S33*1000)*1000),0) -> 810.22698 | AZ33: =+Listrik!AH32 -> 436 | BA33: =AZ33+BA32 -> 115032 | BB33: =IF(AND(L33>0,AZ33>0),(AZ33/(P33*1000)*1000),0) -> 7.8701782 | BC33: =IF(AND(M33>0,BA33>0),(BA33/(Q33*1000)*1000),0) -> 86.670474 | BD33: =IF(AND(R33>0,AZ33>0),(AZ33/(R33*1000)*1000),0) -> 7.9447512 | BE33: =IF(AND(S33>0,BA33>0),(BA33/(S33*1000)*1000),0) -> 89.498659 | BF33: =6.979 -> 6.979 | BG33: 102.346 | BH33: =+SUM(Efficiency2!K118:K119) -> 57.725013 | BI33: =BI32+BH33 -> 1432.9935 | BJ33: =+R33/BH33 -> 0.95069706 | BK33: =+S33/BI33 -> 0.89692868
A34: =A33+1 -> 45895 | B34: Napkin | C34: 18 | D34: =+'26'!F42 -> 830 | E34: =+'26'!G42 -> 713.8 | F34: =1-(E34/D34) -> 0.14 | G34: =+P34/N34 -> 0.95867517 | H34: =+P34/L34 -> 0.95867517 | I34: =+R34/P34 -> 0.99156045 | J34: =+R34/L34 -> 0.95058438 | K34: =+S34/M34 -> 0.869253 | L34: =+Efficiency1!K123 -> 60.315529 | M34: =M33+L34 -> 1544.5768 | N34: =+Efficiency1!C123 -> 60.315529 | O34: =O33+N34 -> 1527.1071 | P34: ='26'!I38 -> 57.823 | Q34: =Q33+P34 -> 1385.057 | R34: ='26'!I40 -> 57.335 | S34: =S33+R34 -> 1342.628 | T34: =R34/P34 -> 0.99156045 | U34: =S34/Q34 -> 0.9693666 | V34: =R34/L34 -> 0.95058438 | W34: =S34/M34 -> 0.869253 | AB34: 0 | AC34: =AB34+AC33 -> 0 | AD34: =AB34/P34 -> 0 | AE34: =AC34/Q34 -> 0 | AF34: =IF(AND(R34>0,AB34>0),(AB34/(R34*1000))*1000,0) -> 0 | AG34: =IF(AND(S34>0,AC34>0),AC34/S34,0) -> 0 | AH34: =+BF34+BG34 -> 122.668 | AI34: =AH34+AI33 -> 3300.388 | AJ34: =AH34/(P34) -> 2.1214396 | AK34: =AI34/(Q34) -> 2.3828536 | AL34: =IF(AND(R34>0,AH34>0),AH34/(R34),0) -> 2.1394959 | AM34: =IF(AND(S34>0,AI34>0),AI34/(S34),0) -> 2.4581552 | AN34: 0 | AO34: =AN34+AO33 -> 62.5 | AP34: =AN34/(P34) -> 0 | AQ34: =AO34/(Q34) -> 0.045124497 | AR34: =IF(AND(R34>0,AN34>0),AN34/(R34),0) -> 0 | AS34: =IF(AND(S34>0,AO34>0),AO34/(S34),0) -> 0.046550496 | AT34: ='26'!I46 -> 45688.99 | AU34: =AT34+AU33 -> 1087068.1 | AV34: =IF(AND(L34>0,AT34>0),(AT34/(P34*1000)*1000),0) -> 790.15253 | AW34: =IF(AND(M34>0,AU34>0),(AU34/(Q34*1000)*1000),0) -> 784.85439 | AX34: =IF(AND(R34>0,AT34>0),(AT34/(R34*1000)*1000),0) -> 796.87782 | AY34: =IF(AND(S34>0,AU34>0),(AU34/(S34*1000)*1000),0) -> 809.65693 | AZ34: =+Listrik!AH33 -> 451 | BA34: =AZ34+BA33 -> 115483 | BB34: =IF(AND(L34>0,AZ34>0),(AZ34/(P34*1000)*1000),0) -> 7.7996645 | BC34: =IF(AND(M34>0,BA34>0),(BA34/(Q34*1000)*1000),0) -> 83.377796 | BD34: =IF(AND(R34>0,AZ34>0),(AZ34/(R34*1000)*1000),0) -> 7.8660504 | BE34: =IF(AND(S34>0,BA34>0),(BA34/(S34*1000)*1000),0) -> 86.012656 | BF34: =18.756 -> 18.756 | BG34: 103.912 | BH34: =+Efficiency2!K123 -> 60.315529 | BI34: =BI33+BH34 -> 1493.3091 | BJ34: =+R34/BH34 -> 0.95058438 | BK34: =+S34/BI34 -> 0.89909586
A35: =A34+1 -> 45896 | B35: Napkin | C35: 18/20 | D35: =+'27'!F42 -> 830 | E35: =+'27'!G42 -> 713.8 | F35: =1-(E35/D35) -> 0.14 | G35: =+P35/N35 -> 0.97707782 | H35: =+P35/L35 -> 0.97707782 | I35: =+R35/P35 -> 0.96034195 | J35: =+R35/L35 -> 0.93832882 | K35: =+S35/M35 -> 0.872097 | L35: =+SUM(Efficiency1!K127:K128) -> 66.324297 | M35: =M34+L35 -> 1610.9011 | N35: =+SUM(Efficiency1!C127:C128) -> 66.324297 | O35: =O34+N35 -> 1593.4314 | P35: ='27'!I38 -> 64.804 | Q35: =Q34+P35 -> 1449.861 | R35: ='27'!I40 -> 62.234 | S35: =S34+R35 -> 1404.862 | T35: =R35/P35 -> 0.96034195 | U35: =S35/Q35 -> 0.96896323 | V35: =R35/L35 -> 0.93832882 | W35: =S35/M35 -> 0.872097 | AB35: 0 | AC35: =AB35+AC34 -> 0 | AD35: =AB35/P35 -> 0 | AE35: =AC35/Q35 -> 0 | AF35: =IF(AND(R35>0,AB35>0),(AB35/(R35*1000))*1000,0) -> 0 | AG35: =IF(AND(S35>0,AC35>0),AC35/S35,0) -> 0 | AH35: =+BF35+BG35 -> 129.308 | AI35: =AH35+AI34 -> 3429.696 | AJ35: =AH35/(P35) -> 1.9953707 | AK35: =AI35/(Q35) -> 2.3655344 | AL35: =IF(AND(R35>0,AH35>0),AH35/(R35),0) -> 2.077771 | AM35: =IF(AND(S35>0,AI35>0),AI35/(S35),0) -> 2.4413046 | AN35: 9.2 | AO35: =AN35+AO34 -> 71.7 | AP35: =AN35/(P35) -> 0.14196655 | AQ35: =AO35/(Q35) -> 0.049453017 | AR35: =IF(AND(R35>0,AN35>0),AN35/(R35),0) -> 0.14782916 | AS35: =IF(AND(S35>0,AO35>0),AO35/(S35),0) -> 0.051037041 | AT35: ='27'!I46 -> 37805.63 | AU35: =AT35+AU34 -> 1124873.7 | AV35: =IF(AND(L35>0,AT35>0),(AT35/(P35*1000)*1000),0) -> 583.3842 | AW35: =IF(AND(M35>0,AU35>0),(AU35/(Q35*1000)*1000),0) -> 775.84933 | AX35: =IF(AND(R35>0,AT35>0),(AT35/(R35*1000)*1000),0) -> 607.4755 | AY35: =IF(AND(S35>0,AU35>0),(AU35/(S35*1000)*1000),0) -> 800.70049 | AZ35: =+Listrik!AH34 -> 28797.24 | BA35: =AZ35+BA34 -> 144280.24 | BB35: =IF(AND(L35>0,AZ35>0),(AZ35/(P35*1000)*1000),0) -> 444.37442 | BC35: =IF(AND(M35>0,BA35>0),(BA35/(Q35*1000)*1000),0) -> 99.513153 | BD35: =IF(AND(R35>0,AZ35>0),(AZ35/(R35*1000)*1000),0) -> 462.7252 | BE35: =IF(AND(S35>0,BA35>0),(BA35/(S35*1000)*1000),0) -> 102.70065 | BF35: =21.847 -> 21.847 | BG35: 107.461 | BH35: =+SUM(Efficiency2!K127:K128) -> 66.324297 | BI35: =BI34+BH35 -> 1559.6334 | BJ35: =+R35/BH35 -> 0.93832882 | BK35: =+S35/BI35 -> 0.90076427
