Workbook

Sheet Report1
A3: PAPER MACHINE 12 DAILY REPORT 1
A6: DATE | B6: GRADE | C6: GSM | D6: Speed yankee (mpm) | E6: Speed reel (mpm) | F6: Creep ( % ) | G6: Real Eff PM ( % ) | H6: Real Eff PM vs Target (%) | I6: Real Eff FG vs Real Eff PM (%) | J6: Eff FG vs Target (%) | L6: Kapasitas Target (ton) | N6: Kapasitas Teori Real (ton) | P6: PM PROD Timbangan (TON) | R6: FINSHED GOODS (TON) | T6: NET GROSS (Timbangan) (%) | V6: NET GROSS ( Scanner) (%) | X6: FRESH WATER | AB6: GAS HOOD | AH6: STEAM (TON) | AN6: STEAM (TON) DEINKING | AT6: POWER (kWh) | AZ6: POWER (kWh) DEINKING | BF6: Report | BH6: Kapasitas Running (ton) | BJ6: Eff FG vs Target Running(%)
X7: CONSUMPTION | Z7: /TON FG. | AB7: CONSUMPTION | AD7: /TON PM. | AF7: /TON FG. | AH7: CONSUMPTION | AJ7: /TON PM. | AL7: /TON FG. | AN7: CONSUMPTION | AP7: /TON PM. | AR7: /TON FG. | AT7: CONSUMPTION | AV7: /TON PM | AX7: /TON FG | AZ7: CONSUMPTION | BB7: /TON PM | BD7: /TON FG | BF7: Hood | BG7: Yankee
J8: TODAY | K8: TODATE | L8: TODAY | M8: TODATE | N8: TODAY | O8: TODATE | P8: TODAY | Q8: TODATE | R8: TODAY | S8: TODATE | T8: TODAY | U8: TODATE | V8: TODAY | W8: TODATE | X8: TODAY | Y8: TODATE | Z8: TODAY | AA8: TODATE | AB8: TODAY | AC8: TODATE | AD8: TODAY | AE8: TODATE | AF8: TODAY | AG8: TODATE | AH8: TODAY | AI8: TODATE | AJ8: TODAY | AK8: TODATE | AL8: TODAY | AM8: TODATE | AN8: TODAY | AO8: TODATE | AP8: TODAY | AQ8: TODATE | AR8: TODAY | AS8: TODATE | AT8: TODAY | AU8: TODATE | AV8: TODAY | AW8: TODATE | AX8: TODAY | AY8: TODATE | AZ8: TODAY | BA8: TODATE | BB8: TODAY | BC8: TODATE | BD8: TODAY | BE8: TODATE | BH8: TODAY | BI8: TODATE | BJ8: TODAY | BK8: TODATE
A9: 45992 | B9: Towel | C9: 38 | D9: =+'1'!F42 -> 383.81944 | E9: =+'1'!G42 -> 337.76111 | F9: =1-(E9/D9) -> 0.12 | G9: =+P9/N9 -> 1.025141 | H9: =+P9/L9 -> 0.91504432 | I9: =+R9/P9 -> 0.99257336 | J9: =+R9/L9 -> 0.90824861 | K9: =+S9/M9 -> 0.90824861 | L9: =+Efficiency1!K6 -> 66.071117 | M9: =L9 -> 66.071117 | N9: =+Efficiency1!C6 -> 58.975301 | O9: =N9 -> 58.975301 | P9: ='1'!I38 -> 60.458 | Q9: =P9 -> 60.458 | R9: ='1'!I40 -> 60.009 | S9: =R9 -> 60.009 | T9: =R9/P9 -> 0.99257336 | U9: =S9/Q9 -> 0.99257336 | V9: =R9/L9 -> 0.90824861 | W9: =S9/M9 -> 0.90824861 | AB9: 0 | AC9: =AB9 -> 0 | AD9: =AB9/P9 -> 0 | AE9: =AC9/Q9 -> 0 | AF9: =IF(AND(R9>0,AB9>0),(AB9/(R9*1000))*1000,0) -> 0 | AG9: =IF(AND(S9>0,AC9>0),AC9/S9,0) -> 0 | AH9: =+BF9+BG9 -> 100.193 | AI9: =AH9 -> 100.193 | AJ9: =AH9/(P9) -> 1.6572331 | AK9: =AI9/(Q9) -> 1.6572331 | AL9: =IF(AND(R9>0,AH9>0),AH9/(R9),0) -> 1.6696329 | AM9: =IF(AND(S9>0,AI9>0),AI9/(S9),0) -> 1.6696329 | AN9: 19.2 | AO9: =AN9 -> 19.2 | AP9: =AN9/(P9) -> 0.31757584 | AQ9: =AO9/(Q9) -> 0.31757584 | AR9: =IF(AND(R9>0,AN9>0),AN9/(R9),0) -> 0.31995201 | AS9: =IF(AND(S9>0,AO9>0),AO9/(S9),0) -> 0.31995201 | AT9: ='1'!I46 -> 33143.09 | AU9: =AT9 -> 33143.09 | AV9: =IF(AND(L9>0,AT9>0),(AT9/(P9*1000)*1000),0) -> 548.20024 | AW9: =IF(AND(M9>0,AU9>0),(AU9/(Q9*1000)*1000),0) -> 548.20024 | AX9: =IF(AND(R9>0,AT9>0),(AT9/(R9*1000)*1000),0) -> 552.30199 | AY9: =IF(AND(S9>0,AU9>0),(AU9/(S9*1000)*1000),0) -> 552.30199 | AZ9: =+Listrik!AH8 -> 29647 | BA9: =AZ9 -> 29647 | BB9: =IF(AND(L9>0,AZ9>0),(AZ9/(P9*1000)*1000),0) -> 490.37348 | BC9: =IF(AND(M9>0,BA9>0),(BA9/(Q9*1000)*1000),0) -> 490.37348 | BD9: =IF(AND(R9>0,AZ9>0),(AZ9/(R9*1000)*1000),0) -> 494.04256 | BE9: =IF(AND(S9>0,BA9>0),(BA9/(S9*1000)*1000),0) -> 494.04256 | BF9: 2.764 | BG9: 97.429 | BH9: =+Efficiency2!K6 -> 66.071117 | BI9: =BH9 -> 66.071117 | BJ9: =+R9/BH9 -> 0.90824861 | BK9: =+S9/BI9 -> 0.90824861
A10: =A9+1 -> 45993 | B10: Towel/Napkin | C10: 38/36/20 | D10: =+'2'!F42 -> 602.92135 | E10: =+'2'!G42 -> 520.81798 | F10: =1-(E10/D10) -> 0.13617592 | G10: =+P10/N10 -> 0.89735141 | H10: =+P10/L10 -> 0.76500578 | I10: =+R10/P10 -> 0.8619298 | J10: =+R10/L10 -> 0.65938128 | K10: =+S10/M10 -> 0.78260306 | L10: =+SUM(Efficiency1!K10:K12) -> 67.370733 | M10: =M9+L10 -> 133.44185 | N10: =+SUM(Efficiency1!C10:C12) -> 57.434579 | O10: =O9+N10 -> 116.40988 | P10: ='2'!I38 -> 51.539 | Q10: =Q9+P10 -> 111.997 | R10: ='2'!I40 -> 44.423 | S10: =S9+R10 -> 104.432 | T10: =R10/P10 -> 0.8619298 | U10: =S10/Q10 -> 0.93245355 | V10: =R10/L10 -> 0.65938128 | W10: =S10/M10 -> 0.78260306 | AB10: 0 | AC10: =AB10+AC9 -> 0 | AD10: =AB10/P10 -> 0 | AE10: =AC10/Q10 -> 0 | AF10: =IF(AND(R10>0,AB10>0),(AB10/(R10*1000))*1000,0) -> 0 | AG10: =IF(AND(S10>0,AC10>0),AC10/S10,0) -> 0 | AH10: =+BF10+BG10 -> 122.515 | AI10: =AH10+AI9 -> 222.708 | AJ10: =AH10/(P10) -> 2.3771319 | AK10: =AI10/(Q10) -> 1.9885175 | AL10: =IF(AND(R10>0,AH10>0),AH10/(R10),0) -> 2.7579182 | AM10: =IF(AND(S10>0,AI10>0),AI10/(S10),0) -> 2.1325647 | AN10: 16.8 | AO10: =AN10+AO9 -> 36 | AP10: =AN10/(P10) -> 0.32596674 | AQ10: =AO10/(Q10) -> 0.32143718 | AR10: =IF(AND(R10>0,AN10>0),AN10/(R10),0) -> 0.37818247 | AS10: =IF(AND(S10>0,AO10>0),AO10/(S10),0) -> 0.34472192 | AT10: ='2'!I46 -> 30787.85 | AU10: =AT10+AU9 -> 63930.94 | AV10: =IF(AND(L10>0,AT10>0),(AT10/(P10*1000)*1000),0) -> 597.36995 | AW10: =IF(AND(M10>0,AU10>0),(AU10/(Q10*1000)*1000),0) -> 570.82725 | AX10: =IF(AND(R10>0,AT10>0),(AT10/(R10*1000)*1000),0) -> 693.06103 | AY10: =IF(AND(S10>0,AU10>0),(AU10/(S10*1000)*1000),0) -> 612.17769 | AZ10: =+Listrik!AH9 -> 18058 | BA10: =AZ10+BA9 -> 47705 | BB10: =IF(AND(L10>0,AZ10>0),(AZ10/(P10*1000)*1000),0) -> 350.37544 | BC10: =IF(AND(M10>0,BA10>0),(BA10/(Q10*1000)*1000),0) -> 425.94891 | BD10: =IF(AND(R10>0,AZ10>0),(AZ10/(R10*1000)*1000),0) -> 406.50114 | BE10: =IF(AND(S10>0,BA10>0),(BA10/(S10*1000)*1000),0) -> 456.80443 | BF10: =2.112 -> 2.112 | BG10: 120.403 | BH10: =+SUM(Efficiency2!K10:K12) -> 67.370733 | BI10: =BI9+BH10 -> 133.44185 | BJ10: =+R10/BH10 -> 0.65938128 | BK10: =+S10/BI10 -> 0.78260306
A11: =A10+1 -> 45994 | B11: Napkin | C11: 20 | D11: =+'3'!F42 -> 700 | E11: =+'3'!G42 -> 602 | F11: =1-(E11/D11) -> 0.14 | G11: =+P11/N11 -> 0.82248985 | H11: =+P11/L11 -> 0.69366614 | I11: =+R11/P11 -> 1.0585873 | J11: =+R11/L11 -> 0.73430615 | K11: =+S11/M11 -> 0.76632515 | L11: =+Efficiency1!K15 -> 67.839552 | M11: =M10+L11 -> 201.2814 | N11: =+Efficiency1!C15 -> 57.21408 | O11: =O10+N11 -> 173.62396 | P11: ='3'!I38 -> 47.058 | Q11: =Q10+P11 -> 159.055 | R11: ='3'!I40 -> 49.815 | S11: =S10+R11 -> 154.247 | T11: =R11/P11 -> 1.0585873 | U11: =S11/Q11 -> 0.96977146 | V11: =R11/L11 -> 0.73430615 | W11: =S11/M11 -> 0.76632515 | AB11: 0 | AC11: =AB11+AC10 -> 0 | AD11: =AB11/P11 -> 0 | AE11: =AC11/Q11 -> 0 | AF11: =IF(AND(R11>0,AB11>0),(AB11/(R11*1000))*1000,0) -> 0 | AG11: =IF(AND(S11>0,AC11>0),AC11/S11,0) -> 0 | AH11: =+BF11+BG11 -> 108.375 | AI11: =AH11+AI10 -> 331.083 | AJ11: =AH11/(P11) -> 2.3030091 | AK11: =AI11/(Q11) -> 2.081563 | AL11: =IF(AND(R11>0,AH11>0),AH11/(R11),0) -> 2.1755495 | AM11: =IF(AND(S11>0,AI11>0),AI11/(S11),0) -> 2.1464469 | AN11: 9.8 | AO11: =AN11+AO10 -> 45.8 | AP11: =AN11/(P11) -> 0.20825364 | AQ11: =AO11/(Q11) -> 0.28795071 | AR11: =IF(AND(R11>0,AN11>0),AN11/(R11),0) -> 0.19672789 | AS11: =IF(AND(S11>0,AO11>0),AO11/(S11),0) -> 0.29692636 | AT11: ='3'!I46 -> 9621.46 | AU11: =AT11+AU10 -> 73552.4 | AV11: =IF(AND(L11>0,AT11>0),(AT11/(P11*1000)*1000),0) -> 204.4596 | AW11: =IF(AND(M11>0,AU11>0),(AU11/(Q11*1000)*1000),0) -> 462.43375 | AX11: =IF(AND(R11>0,AT11>0),(AT11/(R11*1000)*1000),0) -> 193.14383 | AY11: =IF(AND(S11>0,AU11>0),(AU11/(S11*1000)*1000),0) -> 476.84817 | AZ11: =+Listrik!AH10 -> 509 | BA11: =AZ11+BA10 -> 48214 | BB11: =IF(AND(L11>0,AZ11>0),(AZ11/(P11*1000)*1000),0) -> 10.816439 | BC11: =IF(AND(M11>0,BA11>0),(BA11/(Q11*1000)*1000),0) -> 303.12785 | BD11: =IF(AND(R11>0,AZ11>0),(AZ11/(R11*1000)*1000),0) -> 10.217806 | BE11: =IF(AND(S11>0,BA11>0),(BA11/(S11*1000)*1000),0) -> 312.57658 | BF11: =1.131 -> 1.131 | BG11: 107.244 | BH11: =+Efficiency2!K15 -> 55.590744 | BI11: =BI10+BH11 -> 189.03259 | BJ11: =+R11/BH11 -> 0.89610242 | BK11: =+S11/BI11 -> 0.81598097
A12: =A11+1 -> 45995 | B12: Napkin | C12: STOP | D12: =+'4'!F42 -> 0 | E12: =+'4'!G42 -> 0 | F12: =1-(E12/D12) -> #DIV/0! | G12: =+P12/N12 -> 0 | H12: =+P12/L12 -> 0 | I12: =+R12/P12 -> #DIV/0! | J12: =+R12/L12 -> 0 | K12: =+S12/M12 -> 0.57315121 | L12: =+Efficiency1!K20 -> 67.839552 | M12: =M11+L12 -> 269.12095 | N12: =+Efficiency1!C20 -> 57.21408 | O12: =O11+N12 -> 230.83804 | P12: ='4'!I38 -> 0 | Q12: =Q11+P12 -> 159.055 | R12: ='4'!I40 -> 0 | S12: =S11+R12 -> 154.247 | T12: =R12/P12 -> #DIV/0! | U12: =S12/Q12 -> 0.96977146 | V12: =R12/L12 -> 0 | W12: =S12/M12 -> 0.57315121 | AB12: 0 | AC12: =AB12+AC11 -> 0 | AD12: =AB12/P12 -> #DIV/0! | AE12: =AC12/Q12 -> 0 | AF12: =IF(AND(R12>0,AB12>0),(AB12/(R12*1000))*1000,0) -> 0 | AG12: =IF(AND(S12>0,AC12>0),AC12/S12,0) -> 0 | AH12: =+BF12+BG12 -> 6.184 | AI12: =AH12+AI11 -> 337.267 | AJ12: =AH12/(P12) -> #DIV/0! | AK12: =AI12/(Q12) -> 2.1204426 | AL12: =IF(AND(R12>0,AH12>0),AH12/(R12),0) -> 0 | AM12: =IF(AND(S12>0,AI12>0),AI12/(S12),0) -> 2.1865385 | AN12: 0 | AO12: =AN12+AO11 -> 45.8 | AP12: =AN12/(P12) -> #DIV/0! | AQ12: =AO12/(Q12) -> 0.28795071 | AR12: =IF(AND(R12>0,AN12>0),AN12/(R12),0) -> 0 | AS12: =IF(AND(S12>0,AO12>0),AO12/(S12),0) -> 0.29692636 | AT12: ='4'!I46 -> 23567.18 | AU12: =AT12+AU11 -> 97119.58 | AV12: =IF(AND(L12>0,AT12>0),(AT12/(P12*1000)*1000),0) -> #DIV/0! | AW12: =IF(AND(M12>0,AU12>0),(AU12/(Q12*1000)*1000),0) -> 610.60375 | AX12: =IF(AND(R12>0,AT12>0),(AT12/(R12*1000)*1000),0) -> 0 | AY12: =IF(AND(S12>0,AU12>0),(AU12/(S12*1000)*1000),0) -> 629.63675 | AZ12: =+Listrik!AH11 -> 1070 | BA12: =AZ12+BA11 -> 49284 | BB12: =IF(AND(L12>0,AZ12>0),(AZ12/(P12*1000)*1000),0) -> #DIV/0! | BC12: =IF(AND(M12>0,BA12>0),(BA12/(Q12*1000)*1000),0) -> 309.85508 | BD12: =IF(AND(R12>0,AZ12>0),(AZ12/(R12*1000)*1000),0) -> 0 | BE12: =IF(AND(S12>0,BA12>0),(BA12/(S12*1000)*1000),0) -> 319.51351 | BF12: 0.501 | BG12: 5.683 | BH12: =+Efficiency2!K20 -> 12.248808 | BI12: =BI11+BH12 -> 201.2814 | BJ12: =+R12/BH12 -> 0 | BK12: =+S12/BI12 -> 0.76632515
A13: =A12+1 -> 45996 | B13: Towel | C13: 17 | D13: =+'5'!F42 -> 794.83983 | E13: =+'5'!G42 -> 683.56225 | F13: =1-(E13/D13) -> 0.14 | G13: =+P13/N13 -> 0.74109904 | H13: =+P13/L13 -> 0.70970486 | I13: =+R13/P13 -> 0.8454965 | J13: =+R13/L13 -> 0.60005298 | K13: =+S13/M13 -> 0.57775515 | L13: =+Efficiency1!K26 -> 55.56676 | M13: =M12+L13 -> 324.68771 | N13: =+Efficiency1!C26 -> 53.21286 | O13: =O12+N13 -> 284.0509 | P13: ='5'!I38 -> 39.436 | Q13: =Q12+P13 -> 198.491 | R13: ='5'!I40 -> 33.343 | S13: =S12+R13 -> 187.59 | T13: =R13/P13 -> 0.8454965 | U13: =S13/Q13 -> 0.94508063 | V13: =R13/L13 -> 0.60005298 | W13: =S13/M13 -> 0.57775515 | AB13: 0 | AC13: =AB13+AC12 -> 0 | AD13: =AB13/P13 -> 0 | AE13: =AC13/Q13 -> 0 | AF13: =IF(AND(R13>0,AB13>0),(AB13/(R13*1000))*1000,0) -> 0 | AG13: =IF(AND(S13>0,AC13>0),AC13/S13,0) -> 0 | AH13: =+BF13+BG13 -> 109.386 | AI13: =AH13+AI12 -> 446.653 | AJ13: =AH13/(P13) -> 2.77376 | AK13: =AI13/(Q13) -> 2.2502431 | AL13: =IF(AND(R13>0,AH13>0),AH13/(R13),0) -> 3.2806286 | AM13: =IF(AND(S13>0,AI13>0),AI13/(S13),0) -> 2.3810065 | AN13: 7.5 | AO13: =AN13+AO12 -> 53.3 | AP13: =AN13/(P13) -> 0.19018156 | AQ13: =AO13/(Q13) -> 0.26852603 | AR13: =IF(AND(R13>0,AN13>0),AN13/(R13),0) -> 0.22493477 | AS13: =IF(AND(S13>0,AO13>0),AO13/(S13),0) -> 0.28413028 | AT13: ='5'!I46 -> 31737.23 | AU13: =AT13+AU12 -> 128856.81 | AV13: =IF(AND(L13>0,AT13>0),(AT13/(P13*1000)*1000),0) -> 804.77812 | AW13: =IF(AND(M13>0,AU13>0),(AU13/(Q13*1000)*1000),0) -> 649.18213 | AX13: =IF(AND(R13>0,AT13>0),(AT13/(R13*1000)*1000),0) -> 951.84087 | AY13: =IF(AND(S13>0,AU13>0),(AU13/(S13*1000)*1000),0) -> 686.9066 | AZ13: =+Listrik!AH12 -> 21381.5 | BA13: =AZ13+BA12 -> 70665.5 | BB13: =IF(AND(L13>0,AZ13>0),(AZ13/(P13*1000)*1000),0) -> 542.18227 | BC13: =IF(AND(M13>0,BA13>0),(BA13/(Q13*1000)*1000),0) -> 356.01362 | BD13: =IF(AND(R13>0,AZ13>0),(AZ13/(R13*1000)*1000),0) -> 641.25903 | BE13: =IF(AND(S13>0,BA13>0),(BA13/(S13*1000)*1000),0) -> 376.70185 | BF13: =0.024 -> 0.024 | BG13: 109.362 | BH13: =+Efficiency2!K26 -> 55.56676 | BI13: =BI12+BH13 -> 256.84816 | BJ13: =+R13/BH13 -> 0.60005298 | BK13: =+S13/BI13 -> 0.73035368
A14: =A13+1 -> 45997 | B14: Towel/Napkin | C14: 17/15,5 | D14: =+'6'!F42 -> 829.30982 | E14: =+'6'!G42 -> 713.20644 | F14: =1-(E14/D14) -> 0.14 | G14: =+P14/N14 -> 0.81473424 | H14: =+P14/L14 -> 0.81407819 | I14: =+R14/P14 -> 0.90842041 | J14: =+R14/L14 -> 0.73952524 | K14: =+S14/M14 -> 0.60007309 | L14: =+SUM(Efficiency1!K31:K32) -> 51.963068 | M14: =M13+L14 -> 376.65078 | N14: =+SUM(Efficiency1!C31:C32) -> 51.921225 | O14: =O13+N14 -> 335.97213 | P14: ='6'!I38 -> 42.302 | Q14: =Q13+P14 -> 240.793 | R14: ='6'!I40 -> 38.428 | S14: =S13+R14 -> 226.018 | T14: =R14/P14 -> 0.90842041 | U14: =S14/Q14 -> 0.93864024 | V14: =R14/L14 -> 0.73952524 | W14: =S14/M14 -> 0.60007309 | AB14: 0 | AC14: =AB14+AC13 -> 0 | AD14: =AB14/P14 -> 0 | AE14: =AC14/Q14 -> 0 | AF14: =IF(AND(R14>0,AB14>0),(AB14/(R14*1000))*1000,0) -> 0 | AG14: =IF(AND(S14>0,AC14>0),AC14/S14,0) -> 0 | AH14: =+BF14+BG14 -> 124.375 | AI14: =AH14+AI13 -> 571.028 | AJ14: =AH14/(P14) -> 2.9401683 | AK14: =AI14/(Q14) -> 2.3714477 | AL14: =IF(AND(R14>0,AH14>0),AH14/(R14),0) -> 3.2365723 | AM14: =IF(AND(S14>0,AI14>0),AI14/(S14),0) -> 2.5264713 | AN14: 8.9 | AO14: =AN14+AO13 -> 62.2 | AP14: =AN14/(P14) -> 0.21039194 | AQ14: =AO14/(Q14) -> 0.25831316 | AR14: =IF(AND(R14>0,AN14>0),AN14/(R14),0) -> 0.23160196 | AS14: =IF(AND(S14>0,AO14>0),AO14/(S14),0) -> 0.27519932 | AT14: ='6'!I46 -> 36470.97 | AU14: =AT14+AU13 -> 165327.78 | AV14: =IF(AND(L14>0,AT14>0),(AT14/(P14*1000)*1000),0) -> 862.15711 | AW14: =IF(AND(M14>0,AU14>0),(AU14/(Q14*1000)*1000),0) -> 686.59712 | AX14: =IF(AND(R14>0,AT14>0),(AT14/(R14*1000)*1000),0) -> 949.07281 | AY14: =IF(AND(S14>0,AU14>0),(AU14/(S14*1000)*1000),0) -> 731.48059 | AZ14: =+Listrik!AH13 -> 19565 | BA14: =AZ14+BA13 -> 90230.5 | BB14: =IF(AND(L14>0,AZ14>0),(AZ14/(P14*1000)*1000),0) -> 462.50768 | BC14: =IF(AND(M14>0,BA14>0),(BA14/(Q14*1000)*1000),0) -> 374.72227 | BD14: =IF(AND(R14>0,AZ14>0),(AZ14/(R14*1000)*1000),0) -> 509.13396 | BE14: =IF(AND(S14>0,BA14>0),(BA14/(S14*1000)*1000),0) -> 399.2182 | BF14: =0.208 -> 0.208 | BG14: 124.167 | BH14: =+SUM(Efficiency2!K31:K32) -> 51.963068 | BI14: =BI13+BH14 -> 308.81123 | BJ14: =+R14/BH14 -> 0.73952524 | BK14: =+S14/BI14 -> 0.73189696
A15: =A14+1 -> 45998 | B15: Napkin | C15: 15,5 | D15: =+'7'!F42 -> 830 | E15: =+'7'!G42 -> 713.8 | F15: =1-(E15/D15) -> 0.14 | G15: =+P15/N15 -> 0.95447036 | H15: =+P15/L15 -> 0.95447036 | I15: =+R15/P15 -> 0.98243621 | J15: =+R15/L15 -> 0.93770625 | K15: =+S15/M15 -> 0.64079475 | L15: =+Efficiency1!K38 -> 51.657969 | M15: =M14+L15 -> 428.30875 | N15: =+Efficiency1!C38 -> 51.657969 | O15: =O14+N15 -> 387.63009 | P15: ='7'!I38 -> 49.306 | Q15: =Q14+P15 -> 290.099 | R15: ='7'!I40 -> 48.44 | S15: =S14+R15 -> 274.458 | T15: =R15/P15 -> 0.98243621 | U15: =S15/Q15 -> 0.94608392 | V15: =R15/L15 -> 0.93770625 | W15: =S15/M15 -> 0.64079475 | AB15: 0 | AC15: =AB15+AC14 -> 0 | AD15: =AB15/P15 -> 0 | AE15: =AC15/Q15 -> 0 | AF15: =IF(AND(R15>0,AB15>0),(AB15/(R15*1000))*1000,0) -> 0 | AG15: =IF(AND(S15>0,AC15>0),AC15/S15,0) -> 0 | AH15: =+BF15+BG15 -> 124.127 | AI15: =AH15+AI14 -> 695.155 | AJ15: =AH15/(P15) -> 2.5174827 | AK15: =AI15/(Q15) -> 2.3962682 | AL15: =IF(AND(R15>0,AH15>0),AH15/(R15),0) -> 2.5624897 | AM15: =IF(AND(S15>0,AI15>0),AI15/(S15),0) -> 2.5328283 | AN15: 8.8 | AO15: =AN15+AO14 -> 71 | AP15: =AN15/(P15) -> 0.17847726 | AQ15: =AO15/(Q15) -> 0.24474404 | AR15: =IF(AND(R15>0,AN15>0),AN15/(R15),0) -> 0.18166804 | AS15: =IF(AND(S15>0,AO15>0),AO15/(S15),0) -> 0.25869168 | AT15: ='7'!I46 -> 35692.67 | AU15: =AT15+AU14 -> 201020.45 | AV15: =IF(AND(L15>0,AT15>0),(AT15/(P15*1000)*1000),0) -> 723.90115 | AW15: =IF(AND(M15>0,AU15>0),(AU15/(Q15*1000)*1000),0) -> 692.93741 | AX15: =IF(AND(R15>0,AT15>0),(AT15/(R15*1000)*1000),0) -> 736.8429 | AY15: =IF(AND(S15>0,AU15>0),(AU15/(S15*1000)*1000),0) -> 732.427 | AZ15: =+Listrik!AH14 -> 23299 | BA15: =AZ15+BA14 -> 113529.5 | BB15: =IF(AND(L15>0,AZ15>0),(AZ15/(P15*1000)*1000),0) -> 472.53884 | BC15: =IF(AND(M15>0,BA15>0),(BA15/(Q15*1000)*1000),0) -> 391.34744 | BD15: =IF(AND(R15>0,AZ15>0),(AZ15/(R15*1000)*1000),0) -> 480.98679 | BE15: =IF(AND(S15>0,BA15>0),(BA15/(S15*1000)*1000),0) -> 413.64981 | BF15: =0.004 -> 0.004 | BG15: 124.123 | BH15: =+Efficiency2!K38 -> 51.657969 | BI15: =BI14+BH15 -> 360.4692 | BJ15: =+R15/BH15 -> 0.93770625 | BK15: =+S15/BI15 -> 0.76139099
A16: =A15+1 -> 45999 | B16: Napkin | C16: 15,5 | D16: =+'8'!F42 -> 830 | E16: =+'8'!G42 -> 713.8 | F16: =1-(E16/D16) -> 0.14 | G16: =+P16/N16 -> 0.91606018 | H16: =+P16/L16 -> 0.91606018 | I16: =+R16/P16 -> 0.97029599 | J16: =+R16/L16 -> 0.88884951 | K16: =+S16/M16 -> 0.66753231 | L16: =+Efficiency1!K42 -> 51.744417 | M16: =M15+L16 -> 480.05317 | N16: =+Efficiency1!C42 -> 51.744417 | O16: =O15+N16 -> 439.37451 | P16: ='8'!I38 -> 47.401 | Q16: =Q15+P16 -> 337.5 | R16: ='8'!I40 -> 45.993 | S16: =S15+R16 -> 320.451 | T16: =R16/P16 -> 0.97029599 | U16: =S16/Q16 -> 0.94948444 | V16: =R16/L16 -> 0.88884951 | W16: =S16/M16 -> 0.66753231 | AB16: 0 | AC16: =AB16+AC15 -> 0 | AD16: =AB16/P16 -> 0 | AE16: =AC16/Q16 -> 0 | AF16: =IF(AND(R16>0,AB16>0),(AB16/(R16*1000))*1000,0) -> 0 | AG16: =IF(AND(S16>0,AC16>0),AC16/S16,0) -> 0 | AH16: =+BF16+BG16 -> 118.254 | AI16: =AH16+AI15 -> 813.409 | AJ16: =AH16/(P16) -> 2.4947575 | AK16: =AI16/(Q16) -> 2.4101007 | AL16: =IF(AND(R16>0,AH16>0),AH16/(R16),0) -> 2.5711304 | AM16: =IF(AND(S16>0,AI16>0),AI16/(S16),0) -> 2.5383257 | AN16: 7.9 | AO16: =AN16+AO15 -> 78.9 | AP16: =AN16/(P16) -> 0.16666315 | AQ16: =AO16/(Q16) -> 0.23377778 | AR16: =IF(AND(R16>0,AN16>0),AN16/(R16),0) -> 0.17176527 | AS16: =IF(AND(S16>0,AO16>0),AO16/(S16),0) -> 0.24621549 | AT16: ='8'!I46 -> 34343.67 | AU16: =AT16+AU15 -> 235364.12 | AV16: =IF(AND(L16>0,AT16>0),(AT16/(P16*1000)*1000),0) -> 724.53471 | AW16: =IF(AND(M16>0,AU16>0),(AU16/(Q16*1000)*1000),0) -> 697.37517 | AX16: =IF(AND(R16>0,AT16>0),(AT16/(R16*1000)*1000),0) -> 746.71515 | AY16: =IF(AND(S16>0,AU16>0),(AU16/(S16*1000)*1000),0) -> 734.47772 | AZ16: =+Listrik!AH15 -> 21403.6 | BA16: =AZ16+BA15 -> 134933.1 | BB16: =IF(AND(L16>0,AZ16>0),(AZ16/(P16*1000)*1000),0) -> 451.54322 | BC16: =IF(AND(M16>0,BA16>0),(BA16/(Q16*1000)*1000),0) -> 399.80178 | BD16: =IF(AND(R16>0,AZ16>0),(AZ16/(R16*1000)*1000),0) -> 465.36647 | BE16: =IF(AND(S16>0,BA16>0),(BA16/(S16*1000)*1000),0) -> 421.07249 | BF16: =4.051 -> 4.051 | BG16: 114.203 | BH16: =+Efficiency2!K42 -> 51.744417 | BI16: =BI15+BH16 -> 412.21362 | BJ16: =+R16/BH16 -> 0.88884951 | BK16: =+S16/BI16 -> 0.77739062
A17: =A16+1 -> 46000 | B17: Napkin | C17: 15,5/17/16,5/20 | D17: =+'9'!F42 -> 830 | E17: =+'9'!G42 -> 713.8 | F17: =1-(E17/D17) -> 0.14 | G17: =+P17/N17 -> 0.95940623 | H17: =+P17/L17 -> 0.95940623 | I17: =+R17/P17 -> 0.944384 | J17: =+R17/L17 -> 0.90604789 | K17: =+S17/M17 -> 0.69265777 | L17: =+SUM(Efficiency1!K47:K50) -> 56.523502 | M17: =M16+L17 -> 536.57667 | N17: =+SUM(Efficiency1!C47:C50) -> 56.523502 | O17: =O16+N17 -> 495.89801 | P17: ='9'!I38 -> 54.229 | Q17: =Q16+P17 -> 391.729 | R17: ='9'!I40 -> 51.213 | S17: =S16+R17 -> 371.664 | T17: =R17/P17 -> 0.944384 | U17: =S17/Q17 -> 0.94877836 | V17: =R17/L17 -> 0.90604789 | W17: =S17/M17 -> 0.69265777 | AB17: 0 | AC17: =AB17+AC16 -> 0 | AD17: =AB17/P17 -> 0 | AE17: =AC17/Q17 -> 0 | AF17: =IF(AND(R17>0,AB17>0),(AB17/(R17*1000))*1000,0) -> 0 | AG17: =IF(AND(S17>0,AC17>0),AC17/S17,0) -> 0 | AH17: =+BF17+BG17 -> 135.581 | AI17: =AH17+AI16 -> 948.99 | AJ17: =AH17/(P17) -> 2.5001567 | AK17: =AI17/(Q17) -> 2.4225676 | AL17: =IF(AND(R17>0,AH17>0),AH17/(R17),0) -> 2.6473942 | AM17: =IF(AND(S17>0,AI17>0),AI17/(S17),0) -> 2.5533546 | AN17: 9.4 | AO17: =AN17+AO16 -> 88.3 | AP17: =AN17/(P17) -> 0.17333899 | AQ17: =AO17/(Q17) -> 0.22541093 | AR17: =IF(AND(R17>0,AN17>0),AN17/(R17),0) -> 0.18354715 | AS17: =IF(AND(S17>0,AO17>0),AO17/(S17),0) -> 0.23758018 | AT17: ='9'!I46 -> 34596.58 | AU17: =AT17+AU16 -> 269960.7 | AV17: =IF(AND(L17>0,AT17>0),(AT17/(P17*1000)*1000),0) -> 637.97193 | AW17: =IF(AND(M17>0,AU17>0),(AU17/(Q17*1000)*1000),0) -> 689.15168 | AX17: =IF(AND(R17>0,AT17>0),(AT17/(R17*1000)*1000),0) -> 675.54293 | AY17: =IF(AND(S17>0,AU17>0),(AU17/(S17*1000)*1000),0) -> 726.35687 | AZ17: =+Listrik!AH16 -> 28955.4 | BA17: =AZ17+BA16 -> 163888.5 | BB17: =IF(AND(L17>0,AZ17>0),(AZ17/(P17*1000)*1000),0) -> 533.94678 | BC17: =IF(AND(M17>0,BA17>0),(BA17/(Q17*1000)*1000),0) -> 418.37214 | BD17: =IF(AND(R17>0,AZ17>0),(AZ17/(R17*1000)*1000),0) -> 565.3916 | BE17: =IF(AND(S17>0,BA17>0),(BA17/(S17*1000)*1000),0) -> 440.95877 | BF17: =17.335 -> 17.335 | BG17: 118.246 | BH17: =+SUM(Efficiency2!K47:K50) -> 56.523502 | BI17: =BI16+BH17 -> 468.73712 | BJ17: =+R17/BH17 -> 0.90604789 | BK17: =+S17/BI17 -> 0.79290499
A18: =A17+1 -> 46001 | B18: Napkin | C18: 20 | D18: =+'10'!F42 -> 830 | E18: =+'10'!G42 -> 713.8 | F18: =1-(E18/D18) -> 0.14 | G18: =+P18/N18 -> 0.86294792 | H18: =+P18/L18 -> 0.86294792 | I18: =+R18/P18 -> 0.97120016 | J18: =+R18/L18 -> 0.83809516 | K18: =+S18/M18 -> 0.70898163 | L18: =+Efficiency1!K52 -> 67.839552 | M18: =M17+L18 -> 604.41622 | N18: =+Efficiency1!C52 -> 67.839552 | O18: =O17+N18 -> 563.73757 | P18: ='10'!I38 -> 58.542 | Q18: =Q17+P18 -> 450.271 | R18: ='10'!I40 -> 56.856 | S18: =S17+R18 -> 428.52 | T18: =R18/P18 -> 0.97120016 | U18: =S18/Q18 -> 0.95169354 | V18: =R18/L18 -> 0.83809516 | W18: =S18/M18 -> 0.70898163 | AB18: 0 | AC18: =AB18+AC17 -> 0 | AD18: =AB18/P18 -> 0 | AE18: =AC18/Q18 -> 0 | AF18: =IF(AND(R18>0,AB18>0),(AB18/(R18*1000))*1000,0) -> 0 | AG18: =IF(AND(S18>0,AC18>0),AC18/S18,0) -> 0 | AH18: =+BF18+BG18 -> 127.567 | AI18: =AH18+AI17 -> 1076.557 | AJ18: =AH18/(P18) -> 2.179068 | AK18: =AI18/(Q18) -> 2.390909 | AL18: =IF(AND(R18>0,AH18>0),AH18/(R18),0) -> 2.2436858 | AM18: =IF(AND(S18>0,AI18>0),AI18/(S18),0) -> 2.5122678 | AN18: 11.2 | AO18: =AN18+AO17 -> 99.5 | AP18: =AN18/(P18) -> 0.19131564 | AQ18: =AO18/(Q18) -> 0.22097803 | AR18: =IF(AND(R18>0,AN18>0),AN18/(R18),0) -> 0.19698888 | AS18: =IF(AND(S18>0,AO18>0),AO18/(S18),0) -> 0.23219453 | AT18: ='10'!I46 -> 22539 | AU18: =AT18+AU17 -> 292499.7 | AV18: =IF(AND(L18>0,AT18>0),(AT18/(P18*1000)*1000),0) -> 385.00564 | AW18: =IF(AND(M18>0,AU18>0),(AU18/(Q18*1000)*1000),0) -> 649.60812 | AX18: =IF(AND(R18>0,AT18>0),(AT18/(R18*1000)*1000),0) -> 396.42254 | AY18: =IF(AND(S18>0,AU18>0),(AU18/(S18*1000)*1000),0) -> 682.58121 | AZ18: =+Listrik!AH17 -> 33847.08 | BA18: =AZ18+BA17 -> 197735.58 | BB18: =IF(AND(L18>0,AZ18>0),(AZ18/(P18*1000)*1000),0) -> 578.16747 | BC18: =IF(AND(M18>0,BA18>0),(BA18/(Q18*1000)*1000),0) -> 439.14794 | BD18: =IF(AND(R18>0,AZ18>0),(AZ18/(R18*1000)*1000),0) -> 595.31237 | BE18: =IF(AND(S18>0,BA18>0),(BA18/(S18*1000)*1000),0) -> 461.43839 | BF18: =9.15 -> 9.15 | BG18: 118.417 | BH18: =+Efficiency2!K52 -> 67.839552 | BI18: =BI17+BH18 -> 536.57667 | BJ18: =+R18/BH18 -> 0.83809516 | BK18: =+S18/BI18 -> 0.7986184
A19: =A18+1 -> 46002 | B19: Napkin | C19: 20 | D19: =+'11'!F42 -> 830 | E19: =+'11'!G42 -> 713.8 | F19: =1-(E19/D19) -> 0.14 | G19: =+P19/N19 -> 0.73063572 | H19: =+P19/L19 -> 0.73063572 | I19: =+R19/P19 -> 0.94863414 | J19: =+R19/L19 -> 0.69310599 | K19: =+S19/M19 -> 0.70737957 | L19: =+Efficiency1!K57 -> 67.839552 | M19: =M18+L19 -> 672.25577 | N19: =+Efficiency1!C57 -> 67.839552 | O19: =O18+N19 -> 631.57712 | P19: ='11'!I38 -> 49.566 | Q19: =Q18+P19 -> 499.837 | R19: ='11'!I40 -> 47.02 | S19: =S18+R19 -> 475.54 | T19: =R19/P19 -> 0.94863414 | U19: =S19/Q19 -> 0.95139015 | V19: =R19/L19 -> 0.69310599 | W19: =S19/M19 -> 0.70737957 | AB19: 0 | AC19: =AB19+AC18 -> 0 | AD19: =AB19/P19 -> 0 | AE19: =AC19/Q19 -> 0 | AF19: =IF(AND(R19>0,AB19>0),(AB19/(R19*1000))*1000,0) -> 0 | AG19: =IF(AND(S19>0,AC19>0),AC19/S19,0) -> 0 | AH19: =+BF19+BG19 -> 97.398 | AI19: =AH19+AI18 -> 1173.955 | AJ19: =AH19/(P19) -> 1.9650163 | AK19: =AI19/(Q19) -> 2.3486757 | AL19: =IF(AND(R19>0,AH19>0),AH19/(R19),0) -> 2.0714164 | AM19: =IF(AND(S19>0,AI19>0),AI19/(S19),0) -> 2.4686777 | AN19: 10.7 | AO19: =AN19+AO18 -> 110.2 | AP19: =AN19/(P19) -> 0.21587378 | AQ19: =AO19/(Q19) -> 0.22047187 | AR19: =IF(AND(R19>0,AN19>0),AN19/(R19),0) -> 0.22756274 | AS19: =IF(AND(S19>0,AO19>0),AO19/(S19),0) -> 0.23173655 | AT19: ='11'!I46 -> 35062.46 | AU19: =AT19+AU18 -> 327562.16 | AV19: =IF(AND(L19>0,AT19>0),(AT19/(P19*1000)*1000),0) -> 707.38934 | AW19: =IF(AND(M19>0,AU19>0),(AU19/(Q19*1000)*1000),0) -> 655.33796 | AX19: =IF(AND(R19>0,AT19>0),(AT19/(R19*1000)*1000),0) -> 745.69247 | AY19: =IF(AND(S19>0,AU19>0),(AU19/(S19*1000)*1000),0) -> 688.82147 | AZ19: =+Listrik!AH18 -> 29465.28 | BA19: =AZ19+BA18 -> 227200.86 | BB19: =IF(AND(L19>0,AZ19>0),(AZ19/(P19*1000)*1000),0) -> 594.46556 | BC19: =IF(AND(M19>0,BA19>0),(BA19/(Q19*1000)*1000),0) -> 454.5499 | BD19: =IF(AND(R19>0,AZ19>0),(AZ19/(R19*1000)*1000),0) -> 626.65419 | BE19: =IF(AND(S19>0,BA19>0),(BA19/(S19*1000)*1000),0) -> 477.77445 | BF19: 0.316 | BG19: 97.082 | BH19: =+Efficiency2!K57 -> 67.839552 | BI19: =BI18+BH19 -> 604.41622 | BJ19: =+R19/BH19 -> 0.69310599 | BK19: =+S19/BI19 -> 0.78677571
A20: =A19+1 -> 46003 | B20: Napkin | C20: 20 | D20: =+'12'!F42 -> 830 | E20: =+'12'!G42 -> 713.8 | F20: =1-(E20/D20) -> 0.14 | G20: =+P20/N20 -> 0.94862144 | H20: =+P20/L20 -> 0.94862144 | I20: =+R20/P20 -> 0.93456046 | J20: =+R20/L20 -> 0.88654408 | K20: =+S20/M20 -> 0.72360625 | L20: =+Efficiency1!K62 -> 66.94873 | M20: =M19+L20 -> 739.2045 | N20: =+Efficiency1!C62 -> 66.94873 | O20: =O19+N20 -> 698.52585 | P20: ='12'!I38 -> 63.509 | Q20: =Q19+P20 -> 563.346 | R20: ='12'!I40 -> 59.353 | S20: =S19+R20 -> 534.893 | T20: =R20/P20 -> 0.93456046 | U20: =S20/Q20 -> 0.94949285 | V20: =R20/L20 -> 0.88654408 | W20: =S20/M20 -> 0.72360625 | AB20: 0 | AC20: =AB20+AC19 -> 0 | AD20: =AB20/P20 -> 0 | AE20: =AC20/Q20 -> 0 | AF20: =IF(AND(R20>0,AB20>0),(AB20/(R20*1000))*1000,0) -> 0 | AG20: =IF(AND(S20>0,AC20>0),AC20/S20,0) -> 0 | AH20: =+BF20+BG20 -> 128.033 | AI20: =AH20+AI19 -> 1301.988 | AJ20: =AH20/(P20) -> 2.015982 | AK20: =AI20/(Q20) -> 2.3111693 | AL20: =IF(AND(R20>0,AH20>0),AH20/(R20),0) -> 2.1571445 | AM20: =IF(AND(S20>0,AI20>0),AI20/(S20),0) -> 2.4341093 | AN20: 12.8 | AO20: =AN20+AO19 -> 123 | AP20: =AN20/(P20) -> 0.20154624 | AQ20: =AO20/(Q20) -> 0.21833829 | AR20: =IF(AND(R20>0,AN20>0),AN20/(R20),0) -> 0.21565885 | AS20: =IF(AND(S20>0,AO20>0),AO20/(S20),0) -> 0.22995253 | AT20: ='12'!I46 -> 42222.02 | AU20: =AT20+AU19 -> 369784.18 | AV20: =IF(AND(L20>0,AT20>0),(AT20/(P20*1000)*1000),0) -> 664.81947 | AW20: =IF(AND(M20>0,AU20>0),(AU20/(Q20*1000)*1000),0) -> 656.40686 | AX20: =IF(AND(R20>0,AT20>0),(AT20/(R20*1000)*1000),0) -> 711.37129 | AY20: =IF(AND(S20>0,AU20>0),(AU20/(S20*1000)*1000),0) -> 691.32365 | AZ20: =+Listrik!AH19 -> 28493.8 | BA20: =AZ20+BA19 -> 255694.66 | BB20: =IF(AND(L20>0,AZ20>0),(AZ20/(P20*1000)*1000),0) -> 448.65767 | BC20: =IF(AND(M20>0,BA20>0),(BA20/(Q20*1000)*1000),0) -> 453.88564 | BD20: =IF(AND(R20>0,AZ20>0),(AZ20/(R20*1000)*1000),0) -> 480.07346 | BE20: =IF(AND(S20>0,BA20>0),(BA20/(S20*1000)*1000),0) -> 478.02955 | BF20: =0.088 -> 0.088 | BG20: 127.945 | BH20: =+Efficiency2!K62 -> 66.94873 | BI20: =BI19+BH20 -> 671.36495 | BJ20: =+R20/BH20 -> 0.88654408 | BK20: =+S20/BI20 -> 0.79672464
A21: =A20+1 -> 46004 | B21: Napkin | C21: 20 | D21: =+'13'!F42 -> 830 | E21: =+'13'!G42 -> 747 | F21: =1-(E21/D21) -> 0.1 | G21: =+P21/N21 -> 0.88130006 | H21: =+P21/L21 -> 0.88130006 | I21: =+R21/P21 -> 0.95056819 | J21: =+R21/L21 -> 0.8377358 | K21: =+S21/M21 -> 0.73324632 | L21: =+Efficiency1!K67 -> 68.198112 | M21: =M20+L21 -> 807.40262 | N21: =+Efficiency1!C67 -> 68.198112 | O21: =O20+N21 -> 766.72396 | P21: ='13'!I38 -> 60.103 | Q21: =Q20+P21 -> 623.449 | R21: ='13'!I40 -> 57.132 | S21: =S20+R21 -> 592.025 | T21: =R21/P21 -> 0.95056819 | U21: =S21/Q21 -> 0.94959652 | V21: =R21/L21 -> 0.8377358 | W21: =S21/M21 -> 0.73324632 | AB21: 0 | AC21: =AB21+AC20 -> 0 | AD21: =AB21/P21 -> 0 | AE21: =AC21/Q21 -> 0 | AF21: =IF(AND(R21>0,AB21>0),(AB21/(R21*1000))*1000,0) -> 0 | AG21: =IF(AND(S21>0,AC21>0),AC21/S21,0) -> 0 | AH21: =+BF21+BG21 -> 133.353 | AI21: =AH21+AI20 -> 1435.341 | AJ21: =AH21/(P21) -> 2.2187412 | AK21: =AI21/(Q21) -> 2.3022589 | AL21: =IF(AND(R21>0,AH21>0),AH21/(R21),0) -> 2.334121 | AM21: =IF(AND(S21>0,AI21>0),AI21/(S21),0) -> 2.4244601 | AN21: 10.3 | AO21: =AN21+AO20 -> 133.3 | AP21: =AN21/(P21) -> 0.17137248 | AQ21: =AO21/(Q21) -> 0.21381059 | AR21: =IF(AND(R21>0,AN21>0),AN21/(R21),0) -> 0.18028425 | AS21: =IF(AND(S21>0,AO21>0),AO21/(S21),0) -> 0.22515941 | AT21: ='13'!I46 -> 40782.93 | AU21: =AT21+AU20 -> 410567.11 | AV21: =IF(AND(L21>0,AT21>0),(AT21/(P21*1000)*1000),0) -> 678.55065 | AW21: =IF(AND(M21>0,AU21>0),(AU21/(Q21*1000)*1000),0) -> 658.54161 | AX21: =IF(AND(R21>0,AT21>0),(AT21/(R21*1000)*1000),0) -> 713.8369 | AY21: =IF(AND(S21>0,AU21>0),(AU21/(S21*1000)*1000),0) -> 693.49624 | AZ21: =+Listrik!AH20 -> 24431.2 | BA21: =AZ21+BA20 -> 280125.86 | BB21: =IF(AND(L21>0,AZ21>0),(AZ21/(P21*1000)*1000),0) -> 406.48886 | BC21: =IF(AND(M21>0,BA21>0),(BA21/(Q21*1000)*1000),0) -> 449.3164 | BD21: =IF(AND(R21>0,AZ21>0),(AZ21/(R21*1000)*1000),0) -> 427.62725 | BE21: =IF(AND(S21>0,BA21>0),(BA21/(S21*1000)*1000),0) -> 473.16559 | BF21: =0.009 -> 0.009 | BG21: 133.344 | BH21: =+Efficiency2!K67 -> 68.198112 | BI21: =BI20+BH21 -> 739.56306 | BJ21: =+R21/BH21 -> 0.8377358 | BK21: =+S21/BI21 -> 0.80050645
A22: =A21+1 -> 46005 | B22: Napkin | C22: 20 | D22: =+'14'!F42 -> 830 | E22: =+'14'!G42 -> 747 | F22: =1-(E22/D22) -> 0.1 | G22: =+P22/N22 -> 0.97883328 | H22: =+P22/L22 -> 0.97883328 | I22: =+R22/P22 -> 0.99122702 | J22: =+R22/L22 -> 0.970246 | K22: =+S22/M22 -> 0.75180329 | L22: =+Efficiency1!K73 -> 68.589822 | M22: =M21+L22 -> 875.99244 | N22: =+Efficiency1!C73 -> 68.589822 | O22: =O21+N22 -> 835.31378 | P22: ='14'!I38 -> 67.138 | Q22: =Q21+P22 -> 690.587 | R22: ='14'!I40 -> 66.549 | S22: =S21+R22 -> 658.574 | T22: =R22/P22 -> 0.99122702 | U22: =S22/Q22 -> 0.95364378 | V22: =R22/L22 -> 0.970246 | W22: =S22/M22 -> 0.75180329 | AB22: 0 | AC22: =AB22+AC21 -> 0 | AD22: =AB22/P22 -> 0 | AE22: =AC22/Q22 -> 0 | AF22: =IF(AND(R22>0,AB22>0),(AB22/(R22*1000))*1000,0) -> 0 | AG22: =IF(AND(S22>0,AC22>0),AC22/S22,0) -> 0 | AH22: =+BF22+BG22 -> 132.521 | AI22: =AH22+AI21 -> 1567.862 | AJ22: =AH22/(P22) -> 1.9738598 | AK22: =AI22/(Q22) -> 2.2703323 | AL22: =IF(AND(R22>0,AH22>0),AH22/(R22),0) -> 1.9913297 | AM22: =IF(AND(S22>0,AI22>0),AI22/(S22),0) -> 2.3806922 | AN22: 11.3 | AO22: =AN22+AO21 -> 144.6 | AP22: =AN22/(P22) -> 0.16831005 | AQ22: =AO22/(Q22) -> 0.20938709 | AR22: =IF(AND(R22>0,AN22>0),AN22/(R22),0) -> 0.1697997 | AS22: =IF(AND(S22>0,AO22>0),AO22/(S22),0) -> 0.2195653 | AT22: ='14'!I46 -> 37906.03 | AU22: =AT22+AU21 -> 448473.14 | AV22: =IF(AND(L22>0,AT22>0),(AT22/(P22*1000)*1000),0) -> 564.59874 | AW22: =IF(AND(M22>0,AU22>0),(AU22/(Q22*1000)*1000),0) -> 649.4086 | AX22: =IF(AND(R22>0,AT22>0),(AT22/(R22*1000)*1000),0) -> 569.59579 | AY22: =IF(AND(S22>0,AU22>0),(AU22/(S22*1000)*1000),0) -> 680.97608 | AZ22: =+Listrik!AH21 -> 35388.9 | BA22: =AZ22+BA21 -> 315514.76 | BB22: =IF(AND(L22>0,AZ22>0),(AZ22/(P22*1000)*1000),0) -> 527.10685 | BC22: =IF(AND(M22>0,BA22>0),(BA22/(Q22*1000)*1000),0) -> 456.87909 | BD22: =IF(AND(R22>0,AZ22>0),(AZ22/(R22*1000)*1000),0) -> 531.77208 | BE22: =IF(AND(S22>0,BA22>0),(BA22/(S22*1000)*1000),0) -> 479.08779 | BF22: =0.002 -> 0.002 | BG22: 132.519 | BH22: =+Efficiency2!K73 -> 68.589822 | BI22: =BI21+BH22 -> 808.15289 | BJ22: =+R22/BH22 -> 0.970246 | BK22: =+S22/BI22 -> 0.81491264
A23: =A22+1 -> 46006 | B23: Napkin | C23: 20 | D23: =+'15'!F42 -> 830 | E23: =+'15'!G42 -> 747 | F23: =1-(E23/D23) -> 0.1 | G23: =+P23/N23 -> 0.94431095 | H23: =+P23/L23 -> 0.94431095 | I23: =+R23/P23 -> 1.0248104 | J23: =+R23/L23 -> 0.96773972 | K23: =+S23/M23 -> 0.76762819 | L23: =+Efficiency1!K77 -> 69.273792 | M23: =M22+L23 -> 945.26623 | N23: =+Efficiency1!C77 -> 69.273792 | O23: =O22+N23 -> 904.58757 | P23: ='15'!I38 -> 65.416 | Q23: =Q22+P23 -> 756.003 | R23: ='15'!I40 -> 67.039 | S23: =S22+R23 -> 725.613 | T23: =R23/P23 -> 1.0248104 | U23: =S23/Q23 -> 0.95980175 | V23: =R23/L23 -> 0.96773972 | W23: =S23/M23 -> 0.76762819 | AB23: 0 | AC23: =AB23+AC22 -> 0 | AD23: =AB23/P23 -> 0 | AE23: =AC23/Q23 -> 0 | AF23: =IF(AND(R23>0,AB23>0),(AB23/(R23*1000))*1000,0) -> 0 | AG23: =IF(AND(S23>0,AC23>0),AC23/S23,0) -> 0 | AH23: =+BF23+BG23 -> 133.916 | AI23: =AH23+AI22 -> 1701.778 | AJ23: =AH23/(P23) -> 2.0471444 | AK23: =AI23/(Q23) -> 2.2510202 | AL23: =IF(AND(R23>0,AH23>0),AH23/(R23),0) -> 1.9975835 | AM23: =IF(AND(S23>0,AI23>0),AI23/(S23),0) -> 2.345297 | AN23: 13.7 | AO23: =AN23+AO22 -> 158.3 | AP23: =AN23/(P23) -> 0.20942889 | AQ23: =AO23/(Q23) -> 0.2093907 | AR23: =IF(AND(R23>0,AN23>0),AN23/(R23),0) -> 0.20435866 | AS23: =IF(AND(S23>0,AO23>0),AO23/(S23),0) -> 0.21816037 | AT23: ='15'!I46 -> 41264.75 | AU23: =AT23+AU22 -> 489737.89 | AV23: =IF(AND(L23>0,AT23>0),(AT23/(P23*1000)*1000),0) -> 630.80515 | AW23: =IF(AND(M23>0,AU23>0),(AU23/(Q23*1000)*1000),0) -> 647.79887 | AX23: =IF(AND(R23>0,AT23>0),(AT23/(R23*1000)*1000),0) -> 615.5335 | AY23: =IF(AND(S23>0,AU23>0),(AU23/(S23*1000)*1000),0) -> 674.92987 | AZ23: =+Listrik!AH22 -> 30529.6 | BA23: =AZ23+BA22 -> 346044.36 | BB23: =IF(AND(L23>0,AZ23>0),(AZ23/(P23*1000)*1000),0) -> 466.69928 | BC23: =IF(AND(M23>0,BA23>0),(BA23/(Q23*1000)*1000),0) -> 457.72882 | BD23: =IF(AND(R23>0,AZ23>0),(AZ23/(R23*1000)*1000),0) -> 455.40059 | BE23: =IF(AND(S23>0,BA23>0),(BA23/(S23*1000)*1000),0) -> 476.89934 | BF23: =0.293 -> 0.293 | BG23: 133.623 | BH23: =+Efficiency2!K77 -> 69.273792 | BI23: =BI22+BH23 -> 877.42668 | BJ23: =+R23/BH23 -> 0.96773972 | BK23: =+S23/BI23 -> 0.8269785
A24: =A23+1 -> 46007 | B24: Napkin | C24: 20/18 | D24: =+'16'!F42 -> 830 | E24: =+'16'!G42 -> 747 | F24: =1-(E24/D24) -> 0.1 | G24: =+P24/N24 -> 0.97260579 | H24: =+P24/L24 -> 0.97260579 | I24: =+R24/P24 -> 1.0085245 | J24: =+R24/L24 -> 0.98089678 | K24: =+S24/M24 -> 0.78116106 | L24: =+SUM(Efficiency1!K81:K82) -> 64.045475 | M24: =M23+L24 -> 1009.3117 | N24: =+SUM(Efficiency1!C81:C82) -> 64.045475 | O24: =O23+N24 -> 968.63305 | P24: ='16'!I38 -> 62.291 | Q24: =Q23+P24 -> 818.294 | R24: ='16'!I40 -> 62.822 | S24: =S23+R24 -> 788.435 | T24: =R24/P24 -> 1.0085245 | U24: =S24/Q24 -> 0.96351067 | V24: =R24/L24 -> 0.98089678 | W24: =S24/M24 -> 0.78116106 | AB24: 0 | AC24: =AB24+AC23 -> 0 | AD24: =AB24/P24 -> 0 | AE24: =AC24/Q24 -> 0 | AF24: =IF(AND(R24>0,AB24>0),(AB24/(R24*1000))*1000,0) -> 0 | AG24: =IF(AND(S24>0,AC24>0),AC24/S24,0) -> 0 | AH24: =+BF24+BG24 -> 124.453 | AI24: =AH24+AI23 -> 1826.231 | AJ24: =AH24/(P24) -> 1.9979291 | AK24: =AI24/(Q24) -> 2.2317541 | AL24: =IF(AND(R24>0,AH24>0),AH24/(R24),0) -> 1.9810417 | AM24: =IF(AND(S24>0,AI24>0),AI24/(S24),0) -> 2.3162734 | AN24: 11.8 | AO24: =AN24+AO23 -> 170.1 | AP24: =AN24/(P24) -> 0.18943347 | AQ24: =AO24/(Q24) -> 0.2078715 | AR24: =IF(AND(R24>0,AN24>0),AN24/(R24),0) -> 0.18783229 | AS24: =IF(AND(S24>0,AO24>0),AO24/(S24),0) -> 0.21574385 | AT24: ='16'!I46 -> 35921.71 | AU24: =AT24+AU23 -> 525659.6 | AV24: =IF(AND(L24>0,AT24>0),(AT24/(P24*1000)*1000),0) -> 576.67576 | AW24: =IF(AND(M24>0,AU24>0),(AU24/(Q24*1000)*1000),0) -> 642.38477 | AX24: =IF(AND(R24>0,AT24>0),(AT24/(R24*1000)*1000),0) -> 571.80144 | AY24: =IF(AND(S24>0,AU24>0),(AU24/(S24*1000)*1000),0) -> 666.71266 | AZ24: =+Listrik!AH23 -> 30832 | BA24: =AZ24+BA23 -> 376876.36 | BB24: =IF(AND(L24>0,AZ24>0),(AZ24/(P24*1000)*1000),0) -> 494.96717 | BC24: =IF(AND(M24>0,BA24>0),(BA24/(Q24*1000)*1000),0) -> 460.56351 | BD24: =IF(AND(R24>0,AZ24>0),(AZ24/(R24*1000)*1000),0) -> 490.78348 | BE24: =IF(AND(S24>0,BA24>0),(BA24/(S24*1000)*1000),0) -> 478.00562 | BF24: 0.264 | BG24: 124.189 | BH24: =+SUM(Efficiency2!K81:K82) -> 64.045475 | BI24: =BI23+BH24 -> 941.47215 | BJ24: =+R24/BH24 -> 0.98089678 | BK24: =+S24/BI24 -> 0.83744909
A25: =A24+1 -> 46008 | B25: Napkin/Towel | C25: 18/17 | D25: =+'17'!F42 -> 830 | E25: =+'17'!G42 -> 713.8 | F25: =1-(E25/D25) -> 0.14 | G25: =+P25/N25 -> 0.98465696 | H25: =+P25/L25 -> 0.98465696 | I25: =+R25/P25 -> 0.98976932 | J25: =+R25/L25 -> 0.97458325 | K25: =+S25/M25 -> 0.79148002 | L25: =+SUM(Efficiency1!K86:K87) -> 56.880723 | M25: =M24+L25 -> 1066.1924 | N25: =+SUM(Efficiency1!C86:C87) -> 56.880723 | O25: =O24+N25 -> 1025.5138 | P25: ='17'!I38 -> 56.008 | Q25: =Q24+P25 -> 874.302 | R25: ='17'!I40 -> 55.435 | S25: =S24+R25 -> 843.87 | T25: =R25/P25 -> 0.98976932 | U25: =S25/Q25 -> 0.96519281 | V25: =R25/L25 -> 0.97458325 | W25: =S25/M25 -> 0.79148002 | AB25: 0 | AC25: =AB25+AC24 -> 0 | AD25: =AB25/P25 -> 0 | AE25: =AC25/Q25 -> 0 | AF25: =IF(AND(R25>0,AB25>0),(AB25/(R25*1000))*1000,0) -> 0 | AG25: =IF(AND(S25>0,AC25>0),AC25/S25,0) -> 0 | AH25: =+BF25+BG25 -> 116.296 | AI25: =AH25+AI24 -> 1942.527 | AJ25: =AH25/(P25) -> 2.0764177 | AK25: =AI25/(Q25) -> 2.2218032 | AL25: =IF(AND(R25>0,AH25>0),AH25/(R25),0) -> 2.0978804 | AM25: =IF(AND(S25>0,AI25>0),AI25/(S25),0) -> 2.3019268 | AN25: 11 | AO25: =AN25+AO24 -> 181.1 | AP25: =AN25/(P25) -> 0.19640051 | AQ25: =AO25/(Q25) -> 0.20713666 | AR25: =IF(AND(R25>0,AN25>0),AN25/(R25),0) -> 0.19843059 | AS25: =IF(AND(S25>0,AO25>0),AO25/(S25),0) -> 0.21460652 | AT25: ='17'!I46 -> 36390.38 | AU25: =AT25+AU24 -> 562049.98 | AV25: =IF(AND(L25>0,AT25>0),(AT25/(P25*1000)*1000),0) -> 649.73539 | AW25: =IF(AND(M25>0,AU25>0),(AU25/(Q25*1000)*1000),0) -> 642.85565 | AX25: =IF(AND(R25>0,AT25>0),(AT25/(R25*1000)*1000),0) -> 656.45134 | AY25: =IF(AND(S25>0,AU25>0),(AU25/(S25*1000)*1000),0) -> 666.03858 | AZ25: =+Listrik!AH24 -> 30072.5 | BA25: =AZ25+BA24 -> 406948.86 | BB25: =IF(AND(L25>0,AZ25>0),(AZ25/(P25*1000)*1000),0) -> 536.93222 | BC25: =IF(AND(M25>0,BA25>0),(BA25/(Q25*1000)*1000),0) -> 465.45571 | BD25: =IF(AND(R25>0,AZ25>0),(AZ25/(R25*1000)*1000),0) -> 542.48219 | BE25: =IF(AND(S25>0,BA25>0),(BA25/(S25*1000)*1000),0) -> 482.24117 | BF25: =0.369 -> 0.369 | BG25: 115.927 | BH25: =+SUM(Efficiency2!K86:K87) -> 56.880723 | BI25: =BI24+BH25 -> 998.35288 | BJ25: =+R25/BH25 -> 0.97458325 | BK25: =+S25/BI25 -> 0.84526225
A26: =A25+1 -> 46009 | B26: Towel/Napkin | C26: 17/15,5/17,5 | D26: =+'18'!F42 -> 830 | E26: =+'18'!G42 -> 713.8 | F26: =1-(E26/D26) -> 0.14 | G26: =+P26/N26 -> 0.91023291 | H26: =+P26/L26 -> 0.91023291 | I26: =+R26/P26 -> 0.91900299 | J26: =+R26/L26 -> 0.83650677 | K26: =+S26/M26 -> 0.79367899 | L26: =+SUM(Efficiency1!K90:K92) -> 54.743131 | M26: =M25+L26 -> 1120.9356 | N26: =+SUM(Efficiency1!C90:C92) -> 54.743131 | O26: =O25+N26 -> 1080.2569 | P26: ='18'!I38 -> 49.829 | Q26: =Q25+P26 -> 924.131 | R26: ='18'!I40 -> 45.793 | S26: =S25+R26 -> 889.663 | T26: =R26/P26 -> 0.91900299 | U26: =S26/Q26 -> 0.96270226 | V26: =R26/L26 -> 0.83650677 | W26: =S26/M26 -> 0.79367899 | AB26: 0 | AC26: =AB26+AC25 -> 0 | AD26: =AB26/P26 -> 0 | AE26: =AC26/Q26 -> 0 | AF26: =IF(AND(R26>0,AB26>0),(AB26/(R26*1000))*1000,0) -> 0 | AG26: =IF(AND(S26>0,AC26>0),AC26/S26,0) -> 0 | AH26: =+BF26+BG26 -> 111.286 | AI26: =AH26+AI25 -> 2053.813 | AJ26: =AH26/(P26) -> 2.2333581 | AK26: =AI26/(Q26) -> 2.2224263 | AL26: =IF(AND(R26>0,AH26>0),AH26/(R26),0) -> 2.4301968 | AM26: =IF(AND(S26>0,AI26>0),AI26/(S26),0) -> 2.3085292 | AN26: 11 | AO26: =AN26+AO25 -> 192.1 | AP26: =AN26/(P26) -> 0.22075498 | AQ26: =AO26/(Q26) -> 0.20787096 | AR26: =IF(AND(R26>0,AN26>0),AN26/(R26),0) -> 0.24021139 | AS26: =IF(AND(S26>0,AO26>0),AO26/(S26),0) -> 0.21592446 | AT26: ='18'!I46 -> 39231.1 | AU26: =AT26+AU25 -> 601281.08 | AV26: =IF(AND(L26>0,AT26>0),(AT26/(P26*1000)*1000),0) -> 787.31462 | AW26: =IF(AND(M26>0,AU26>0),(AU26/(Q26*1000)*1000),0) -> 650.64485 | AX26: =IF(AND(R26>0,AT26>0),(AT26/(R26*1000)*1000),0) -> 856.70517 | AY26: =IF(AND(S26>0,AU26>0),(AU26/(S26*1000)*1000),0) -> 675.85263 | AZ26: =+Listrik!AH25 -> 28928.8 | BA26: =AZ26+BA25 -> 435877.66 | BB26: =IF(AND(L26>0,AZ26>0),(AZ26/(P26*1000)*1000),0) -> 580.56152 | BC26: =IF(AND(M26>0,BA26>0),(BA26/(Q26*1000)*1000),0) -> 471.6622 | BD26: =IF(AND(R26>0,AZ26>0),(AZ26/(R26*1000)*1000),0) -> 631.72974 | BE26: =IF(AND(S26>0,BA26>0),(BA26/(S26*1000)*1000),0) -> 489.93569 | BF26: =0.73 -> 0.73 | BG26: 110.556 | BH26: =+SUM(Efficiency2!K90:K92) -> 54.467615 | BI26: =BI25+BH26 -> 1052.8205 | BJ26: =+R26/BH26 -> 0.84073811 | BK26: =+S26/BI26 -> 0.8450282
A27: =A26+1 -> 46010 | B27: Towel | C27: 17,5/22 | D27: =+'19'!F42 -> 807.8125 | E27: =+'19'!G42 -> 694.71875 | F27: =1-(E27/D27) -> 0.14 | G27: =+P27/N27 -> 0.96823217 | H27: =+P27/L27 -> 0.96823217 | I27: =+R27/P27 -> 1.0039482 | J27: =+R27/L27 -> 0.97205498 | K27: =+S27/M27 -> 0.80414143 | L27: =+SUM(Efficiency1!K96:K97) -> 69.843786 | M27: =M26+L27 -> 1190.7793 | N27: =+SUM(Efficiency1!C96:C97) -> 69.843786 | O27: =O26+N27 -> 1150.1007 | P27: ='19'!I38 -> 67.625 | Q27: =Q26+P27 -> 991.756 | R27: ='19'!I40 -> 67.892 | S27: =S26+R27 -> 957.555 | T27: =R27/P27 -> 1.0039482 | U27: =S27/Q27 -> 0.9655147 | V27: =R27/L27 -> 0.97205498 | W27: =S27/M27 -> 0.80414143 | AB27: 0 | AC27: =AB27+AC26 -> 0 | AD27: =AB27/P27 -> 0 | AE27: =AC27/Q27 -> 0 | AF27: =IF(AND(R27>0,AB27>0),(AB27/(R27*1000))*1000,0) -> 0 | AG27: =IF(AND(S27>0,AC27>0),AC27/S27,0) -> 0 | AH27: =+BF27+BG27 -> 132.33 | AI27: =AH27+AI26 -> 2186.143 | AJ27: =AH27/(P27) -> 1.9568207 | AK27: =AI27/(Q27) -> 2.2043154 | AL27: =IF(AND(R27>0,AH27>0),AH27/(R27),0) -> 1.9491251 | AM27: =IF(AND(S27>0,AI27>0),AI27/(S27),0) -> 2.2830469 | AN27: 11.9 | AO27: =AN27+AO26 -> 204 | AP27: =AN27/(P27) -> 0.17597043 | AQ27: =AO27/(Q27) -> 0.20569576 | AR27: =IF(AND(R27>0,AN27>0),AN27/(R27),0) -> 0.17527838 | AS27: =IF(AND(S27>0,AO27>0),AO27/(S27),0) -> 0.21304259 | AT27: ='19'!I46 -> 38946.09 | AU27: =AT27+AU26 -> 640227.17 | AV27: =IF(AND(L27>0,AT27>0),(AT27/(P27*1000)*1000),0) -> 575.91261 | AW27: =IF(AND(M27>0,AU27>0),(AU27/(Q27*1000)*1000),0) -> 645.54908 | AX27: =IF(AND(R27>0,AT27>0),(AT27/(R27*1000)*1000),0) -> 573.64771 | AY27: =IF(AND(S27>0,AU27>0),(AU27/(S27*1000)*1000),0) -> 668.60616 | AZ27: =+Listrik!AH26 -> 35268.5 | BA27: =AZ27+BA26 -> 471146.16 | BB27: =IF(AND(L27>0,AZ27>0),(AZ27/(P27*1000)*1000),0) -> 521.5305 | BC27: =IF(AND(M27>0,BA27>0),(BA27/(Q27*1000)*1000),0) -> 475.06258 | BD27: =IF(AND(R27>0,AZ27>0),(AZ27/(R27*1000)*1000),0) -> 519.47947 | BE27: =IF(AND(S27>0,BA27>0),(BA27/(S27*1000)*1000),0) -> 492.03039 | BF27: =0.905 -> 0.905 | BG27: 131.425 | BH27: =+SUM(Efficiency2!K96:K97) -> 71.766077 | BI27: =BI26+BH27 -> 1124.5866 | BJ27: =+R27/BH27 -> 0.946018 | BK27: =+S27/BI27 -> 0.85147291
A28: =A27+1 -> 46011 | B28: Towel | C28: 22/31,5 | D28: =+'20'!F42 -> 672.77778 | E28: =+'20'!G42 -> 584.39444 | F28: =1-(E28/D28) -> 0.13137077 | G28: =+P28/N28 -> 0.9879247 | H28: =+P28/L28 -> 0.9879247 | I28: =+R28/P28 -> 0.98060809 | J28: =+R28/L28 -> 0.96876695 | K28: =+S28/M28 -> 0.81322985 | L28: =+SUM(Efficiency1!K101:K102) -> 69.580202 | M28: =M27+L28 -> 1260.3595 | N28: =+SUM(Efficiency1!C101:C102) -> 69.580202 | O28: =O27+N28 -> 1219.6809 | P28: ='20'!I38 -> 68.74 | Q28: =Q27+P28 -> 1060.496 | R28: ='20'!I40 -> 67.407 | S28: =S27+R28 -> 1024.962 | T28: =R28/P28 -> 0.98060809 | U28: =S28/Q28 -> 0.96649304 | V28: =R28/L28 -> 0.96876695 | W28: =S28/M28 -> 0.81322985 | AB28: 0 | AC28: =AB28+AC27 -> 0 | AD28: =AB28/P28 -> 0 | AE28: =AC28/Q28 -> 0 | AF28: =IF(AND(R28>0,AB28>0),(AB28/(R28*1000))*1000,0) -> 0 | AG28: =IF(AND(S28>0,AC28>0),AC28/S28,0) -> 0 | AH28: =+BF28+BG28 -> 127.609 | AI28: =AH28+AI27 -> 2313.752 | AJ28: =AH28/(P28) -> 1.8564009 | AK28: =AI28/(Q28) -> 2.181764 | AL28: =IF(AND(R28>0,AH28>0),AH28/(R28),0) -> 1.893112 | AM28: =IF(AND(S28>0,AI28>0),AI28/(S28),0) -> 2.2574027 | AN28: 12.5 | AO28: =AN28+AO27 -> 216.5 | AP28: =AN28/(P28) -> 0.18184463 | AQ28: =AO28/(Q28) -> 0.20414976 | AR28: =IF(AND(R28>0,AN28>0),AN28/(R28),0) -> 0.18544068 | AS28: =IF(AND(S28>0,AO28>0),AO28/(S28),0) -> 0.21122734 | AT28: ='20'!I46 -> 34356.28 | AU28: =AT28+AU27 -> 674583.45 | AV28: =IF(AND(L28>0,AT28>0),(AT28/(P28*1000)*1000),0) -> 499.80041 | AW28: =IF(AND(M28>0,AU28>0),(AU28/(Q28*1000)*1000),0) -> 636.10183 | AX28: =IF(AND(R28>0,AT28>0),(AT28/(R28*1000)*1000),0) -> 509.68416 | AY28: =IF(AND(S28>0,AU28>0),(AU28/(S28*1000)*1000),0) -> 658.15459 | AZ28: =+Listrik!AH27 -> 30456.4 | BA28: =AZ28+BA27 -> 501602.56 | BB28: =IF(AND(L28>0,AZ28>0),(AZ28/(P28*1000)*1000),0) -> 443.06663 | BC28: =IF(AND(M28>0,BA28>0),(BA28/(Q28*1000)*1000),0) -> 472.98864 | BD28: =IF(AND(R28>0,AZ28>0),(AZ28/(R28*1000)*1000),0) -> 451.82845 | BE28: =IF(AND(S28>0,BA28>0),(BA28/(S28*1000)*1000),0) -> 489.38649 | BF28: 0.678 | BG28: 126.931 | BH28: =+SUM(Efficiency2!K101:K102) -> 69.580202 | BI28: =BI27+BH28 -> 1194.1668 | BJ28: =+R28/BH28 -> 0.96876695 | BK28: =+S28/BI28 -> 0.85830725
A29: =A28+1 -> 46012 | B29: Towel | C29: 31,5 | D29: =+'21'!F42 -> 550 | E29: =+'21'!G42 -> 484 | F29: =1-(E29/D29) -> 0.12 | G29: =+P29/N29 -> 0.95823313 | H29: =+P29/L29 -> 0.95823313 | I29: =+R29/P29 -> 0.99103816 | J29: =+R29/L29 -> 0.9496456 | K29: =+S29/M29 -> 0.82051927 | L29: =+Efficiency1!K106 -> 71.1497 | M29: =M28+L29 -> 1331.5092 | N29: =+Efficiency1!C106 -> 71.1497 | O29: =O28+N29 -> 1290.8306 | P29: ='21'!I38 -> 68.178 | Q29: =Q28+P29 -> 1128.674 | R29: ='21'!I40 -> 67.567 | S29: =S28+R29 -> 1092.529 | T29: =R29/P29 -> 0.99103816 | U29: =S29/Q29 -> 0.9679757 | V29: =R29/L29 -> 0.9496456 | W29: =S29/M29 -> 0.82051927 | AB29: 0 | AC29: =AB29+AC28 -> 0 | AD29: =AB29/P29 -> 0 | AE29: =AC29/Q29 -> 0 | AF29: =IF(AND(R29>0,AB29>0),(AB29/(R29*1000))*1000,0) -> 0 | AG29: =IF(AND(S29>0,AC29>0),AC29/S29,0) -> 0 | AH29: =+BF29+BG29 -> 124.239 | AI29: =AH29+AI28 -> 2437.991 | AJ29: =AH29/(P29) -> 1.822274 | AK29: =AI29/(Q29) -> 2.1600489 | AL29: =IF(AND(R29>0,AH29>0),AH29/(R29),0) -> 1.8387526 | AM29: =IF(AND(S29>0,AI29>0),AI29/(S29),0) -> 2.2315115 | AN29: 12 | AO29: =AN29+AO28 -> 228.5 | AP29: =AN29/(P29) -> 0.17600986 | AQ29: =AO29/(Q29) -> 0.20244995 | AR29: =IF(AND(R29>0,AN29>0),AN29/(R29),0) -> 0.17760149 | AS29: =IF(AND(S29>0,AO29>0),AO29/(S29),0) -> 0.20914777 | AT29: ='21'!I46 -> 35244.77 | AU29: =AT29+AU28 -> 709828.22 | AV29: =IF(AND(L29>0,AT29>0),(AT29/(P29*1000)*1000),0) -> 516.95224 | AW29: =IF(AND(M29>0,AU29>0),(AU29/(Q29*1000)*1000),0) -> 628.90456 | AX29: =IF(AND(R29>0,AT29>0),(AT29/(R29*1000)*1000),0) -> 521.62698 | AY29: =IF(AND(S29>0,AU29>0),(AU29/(S29*1000)*1000),0) -> 649.7111 | AZ29: =+Listrik!AH28 -> 35140.08 | BA29: =AZ29+BA28 -> 536742.64 | BB29: =IF(AND(L29>0,AZ29>0),(AZ29/(P29*1000)*1000),0) -> 515.4167 | BC29: =IF(AND(M29>0,BA29>0),(BA29/(Q29*1000)*1000),0) -> 475.55152 | BD29: =IF(AND(R29>0,AZ29>0),(AZ29/(R29*1000)*1000),0) -> 520.07755 | BE29: =IF(AND(S29>0,BA29>0),(BA29/(S29*1000)*1000),0) -> 491.28457 | BF29: 1.133 | BG29: 123.106 | BH29: =+Efficiency2!K106 -> 71.1497 | BI29: =BI28+BH29 -> 1265.3165 | BJ29: =+R29/BH29 -> 0.9496456 | BK29: =+S29/BI29 -> 0.86344328
A30: =A29+1 -> 46013 | B30: Towel | C30: 31,5/32/33,5/34 | D30: =+'22'!F42 -> 550 | E30: =+'22'!G42 -> 484 | F30: =1-(E30/D30) -> 0.12 | G30: =+P30/N30 -> 0.97358522 | H30: =+P30/L30 -> 0.97358522 | I30: =+R30/P30 -> 0.98761997 | J30: =+R30/L30 -> 0.96153221 | K30: =+S30/M30 -> 0.82810173 | L30: =+SUM(Efficiency1!K110:K113) -> 75.665692 | M30: =M29+L30 -> 1407.1749 | N30: =+SUM(Efficiency1!C110:C113) -> 75.665692 | O30: =O29+N30 -> 1366.4963 | P30: ='22'!I38 -> 73.667 | Q30: =Q29+P30 -> 1202.341 | R30: ='22'!I40 -> 72.755 | S30: =S29+R30 -> 1165.284 | T30: =R30/P30 -> 0.98761997 | U30: =S30/Q30 -> 0.96917929 | V30: =R30/L30 -> 0.96153221 | W30: =S30/M30 -> 0.82810173 | AB30: 0 | AC30: =AB30+AC29 -> 0 | AD30: =AB30/P30 -> 0 | AE30: =AC30/Q30 -> 0 | AF30: =IF(AND(R30>0,AB30>0),(AB30/(R30*1000))*1000,0) -> 0 | AG30: =IF(AND(S30>0,AC30>0),AC30/S30,0) -> 0 | AH30: =+BF30+BG30 -> 126.074 | AI30: =AH30+AI29 -> 2564.065 | AJ30: =AH30/(P30) -> 1.711404 | AK30: =AI30/(Q30) -> 2.1325606 | AL30: =IF(AND(R30>0,AH30>0),AH30/(R30),0) -> 1.7328568 | AM30: =IF(AND(S30>0,AI30>0),AI30/(S30),0) -> 2.2003778 | AN30: 13.1 | AO30: =AN30+AO29 -> 241.6 | AP30: =AN30/(P30) -> 0.17782725 | AQ30: =AO30/(Q30) -> 0.20094133 | AR30: =IF(AND(R30>0,AN30>0),AN30/(R30),0) -> 0.18005635 | AS30: =IF(AND(S30>0,AO30>0),AO30/(S30),0) -> 0.20733143 | AT30: ='22'!I46 -> 31401.67 | AU30: =AT30+AU29 -> 741229.89 | AV30: =IF(AND(L30>0,AT30>0),(AT30/(P30*1000)*1000),0) -> 426.26508 | AW30: =IF(AND(M30>0,AU30>0),(AU30/(Q30*1000)*1000),0) -> 616.48891 | AX30: =IF(AND(R30>0,AT30>0),(AT30/(R30*1000)*1000),0) -> 431.60841 | AY30: =IF(AND(S30>0,AU30>0),(AU30/(S30*1000)*1000),0) -> 636.09377 | AZ30: =+Listrik!AH29 -> 36036.877 | BA30: =AZ30+BA29 -> 572779.52 | BB30: =IF(AND(L30>0,AZ30>0),(AZ30/(P30*1000)*1000),0) -> 489.18616 | BC30: =IF(AND(M30>0,BA30>0),(BA30/(Q30*1000)*1000),0) -> 476.38691 | BD30: =IF(AND(R30>0,AZ30>0),(AZ30/(R30*1000)*1000),0) -> 495.31822 | BE30: =IF(AND(S30>0,BA30>0),(BA30/(S30*1000)*1000),0) -> 491.53641 | BF30: =1.923 -> 1.923 | BG30: 124.151 | BH30: =+SUM(Efficiency2!K110:K113) -> 75.665692 | BI30: =BI29+BH30 -> 1340.9822 | BJ30: =+R30/BH30 -> 0.96153221 | BK30: =+S30/BI30 -> 0.868978
A31: =A30+1 -> 46014 | B31: Towel | C31: 34 | D31: =+'23'!F42 -> 550 | E31: =+'23'!G42 -> 484 | F31: =1-(E31/D31) -> 0.12 | G31: =+P31/N31 -> 0.97882386 | H31: =+P31/L31 -> 0.97882386 | I31: =+R31/P31 -> 0.99068843 | J31: =+R31/L31 -> 0.96970947 | K31: =+S31/M31 -> 0.83554952 | L31: =+Efficiency1!K115 -> 78.118243 | M31: =M30+L31 -> 1485.2932 | N31: =+Efficiency1!C115 -> 78.118243 | O31: =O30+N31 -> 1444.6145 | P31: ='23'!I38 -> 76.464 | Q31: =Q30+P31 -> 1278.805 | R31: ='23'!I40 -> 75.752 | S31: =S30+R31 -> 1241.036 | T31: =R31/P31 -> 0.99068843 | U31: =S31/Q31 -> 0.9704654 | V31: =R31/L31 -> 0.96970947 | W31: =S31/M31 -> 0.83554952 | AB31: 0 | AC31: =AB31+AC30 -> 0 | AD31: =AB31/P31 -> 0 | AE31: =AC31/Q31 -> 0 | AF31: =IF(AND(R31>0,AB31>0),(AB31/(R31*1000))*1000,0) -> 0 | AG31: =IF(AND(S31>0,AC31>0),AC31/S31,0) -> 0 | AH31: =+BF31+BG31 -> 116.667 | AI31: =AH31+AI30 -> 2680.732 | AJ31: =AH31/(P31) -> 1.5257768 | AK31: =AI31/(Q31) -> 2.0962789 | AL31: =IF(AND(R31>0,AH31>0),AH31/(R31),0) -> 1.5401178 | AM31: =IF(AND(S31>0,AI31>0),AI31/(S31),0) -> 2.1600759 | AN31: 13.56569 | AO31: =AN31+AO30 -> 255.16569 | AP31: =AN31/(P31) -> 0.17741277 | AQ31: =AO31/(Q31) -> 0.19953448 | AR31: =IF(AND(R31>0,AN31>0),AN31/(R31),0) -> 0.17908029 | AS31: =IF(AND(S31>0,AO31>0),AO31/(S31),0) -> 0.205607 | AT31: ='23'!I46 -> 33466.8 | AU31: =AT31+AU30 -> 774696.69 | AV31: =IF(AND(L31>0,AT31>0),(AT31/(P31*1000)*1000),0) -> 437.68048 | AW31: =IF(AND(M31>0,AU31>0),(AU31/(Q31*1000)*1000),0) -> 605.79736 | AX31: =IF(AND(R31>0,AT31>0),(AT31/(R31*1000)*1000),0) -> 441.79428 | AY31: =IF(AND(S31>0,AU31>0),(AU31/(S31*1000)*1000),0) -> 624.23386 | AZ31: =+Listrik!AH30 -> 36508.568 | BA31: =AZ31+BA30 -> 609288.09 | BB31: =IF(AND(L31>0,AZ31>0),(AZ31/(P31*1000)*1000),0) -> 477.46087 | BC31: =IF(AND(M31>0,BA31>0),(BA31/(Q31*1000)*1000),0) -> 476.45113 | BD31: =IF(AND(R31>0,AZ31>0),(AZ31/(R31*1000)*1000),0) -> 481.94857 | BE31: =IF(AND(S31>0,BA31>0),(BA31/(S31*1000)*1000),0) -> 490.95118 | BF31: 0.292 | BG31: 116.375 | BH31: =+Efficiency2!K115 -> 78.118243 | BI31: =BI30+BH31 -> 1419.1004 | BJ31: =+R31/BH31 -> 0.96970947 | BK31: =+S31/BI31 -> 0.87452304
A32: =A31+1 -> 46015 | B32: Towel | C32: 34/35,5 | D32: =+'24'!F42 -> 538.33333 | E32: =+'24'!G42 -> 473.73333 | F32: =1-(E32/D32) -> 0.12 | G32: =+P32/N32 -> 0.97837806 | H32: =+P32/L32 -> 0.97837806 | I32: =+R32/P32 -> 1.011617 | J32: =+R32/L32 -> 0.98974383 | K32: =+S32/M32 -> 0.84304872 | L32: =+SUM(Efficiency1!K119:K120) -> 75.929748 | M32: =M31+L32 -> 1561.2229 | N32: =+SUM(Efficiency1!C119:C120) -> 75.929748 | O32: =O31+N32 -> 1520.5443 | P32: ='24'!I38 -> 74.288 | Q32: =Q31+P32 -> 1353.093 | R32: ='24'!I40 -> 75.151 | S32: =S31+R32 -> 1316.187 | T32: =R32/P32 -> 1.011617 | U32: =S32/Q32 -> 0.97272471 | V32: =R32/L32 -> 0.98974383 | W32: =S32/M32 -> 0.84304872 | AB32: 0 | AC32: =AB32+AC31 -> 0 | AD32: =AB32/P32 -> 0 | AE32: =AC32/Q32 -> 0 | AF32: =IF(AND(R32>0,AB32>0),(AB32/(R32*1000))*1000,0) -> 0 | AG32: =IF(AND(S32>0,AC32>0),AC32/S32,0) -> 0 | AH32: =+BF32+BG32 -> 114.794 | AI32: =AH32+AI31 -> 2795.526 | AJ32: =AH32/(P32) -> 1.5452563 | AK32: =AI32/(Q32) -> 2.0660265 | AL32: =IF(AND(R32>0,AH32>0),AH32/(R32),0) -> 1.5275113 | AM32: =IF(AND(S32>0,AI32>0),AI32/(S32),0) -> 2.1239581 | AN32: 5.9877988 | AO32: =AN32+AO31 -> 261.15349 | AP32: =AN32/(P32) -> 0.080602504 | AQ32: =AO32/(Q32) -> 0.19300483 | AR32: =IF(AND(R32>0,AN32>0),AN32/(R32),0) -> 0.079676901 | AS32: =IF(AND(S32>0,AO32>0),AO32/(S32),0) -> 0.19841671 | AT32: =+'24'!I46 -> 31476.17 | AU32: =AT32+AU31 -> 806172.86 | AV32: =IF(AND(L32>0,AT32>0),(AT32/(P32*1000)*1000),0) -> 423.70464 | AW32: =IF(AND(M32>0,AU32>0),(AU32/(Q32*1000)*1000),0) -> 595.80004 | AX32: =IF(AND(R32>0,AT32>0),(AT32/(R32*1000)*1000),0) -> 418.839 | AY32: =IF(AND(S32>0,AU32>0),(AU32/(S32*1000)*1000),0) -> 612.50632 | AZ32: =+Listrik!AH31 -> 36246.134 | BA32: =AZ32+BA31 -> 645534.22 | BB32: =IF(AND(L32>0,AZ32>0),(AZ32/(P32*1000)*1000),0) -> 487.91371 | BC32: =IF(AND(M32>0,BA32>0),(BA32/(Q32*1000)*1000),0) -> 477.08045 | BD32: =IF(AND(R32>0,AZ32>0),(AZ32/(R32*1000)*1000),0) -> 482.31073 | BE32: =IF(AND(S32>0,BA32>0),(BA32/(S32*1000)*1000),0) -> 490.45783 | BF32: 0.431 | BG32: 114.363 | BH32: =+SUM(Efficiency2!K119:K120) -> 75.929748 | BI32: =BI31+BH32 -> 1495.0302 | BJ32: =+R32/BH32 -> 0.98974383 | BK32: =+S32/BI32 -> 0.88037489
A33: =A32+1 -> 46016 | B33: Towel | C33: 35,5/36 | D33: =+'25'!F42 -> 530 | E33: =+'25'!G42 -> 466.4 | F33: =1-(E33/D33) -> 0.12 | G33: =+P33/N33 -> 0.96095709 | H33: =+P33/L33 -> 0.96095709 | I33: =+R33/P33 -> 0.9929134 | J33: =+R33/L33 -> 0.95414717 | K33: =+S33/M33 -> 0.84823866 | L33: =+SUM(Efficiency1!K124:K125) -> 76.506017 | M33: =M32+L33 -> 1637.7289 | N33: =+SUM(Efficiency1!C124:C125) -> 76.506017 | O33: =O32+N33 -> 1597.0503 | P33: ='25'!I38 -> 73.519 | Q33: =Q32+P33 -> 1426.612 | R33: ='25'!I40 -> 72.998 | S33: =S32+R33 -> 1389.185 | T33: =R33/P33 -> 0.9929134 | U33: =S33/Q33 -> 0.97376512 | V33: =R33/L33 -> 0.95414717 | W33: =S33/M33 -> 0.84823866 | AB33: 0 | AC33: =AB33+AC32 -> 0 | AD33: =AB33/P33 -> 0 | AE33: =AC33/Q33 -> 0 | AF33: =IF(AND(R33>0,AB33>0),(AB33/(R33*1000))*1000,0) -> 0 | AG33: =IF(AND(S33>0,AC33>0),AC33/S33,0) -> 0 | AH33: =+BF33+BG33 -> 115.069 | AI33: =AH33+AI32 -> 2910.595 | AJ33: =AH33/(P33) -> 1.56516 | AK33: =AI33/(Q33) -> 2.0402149 | AL33: =IF(AND(R33>0,AH33>0),AH33/(R33),0) -> 1.5763309 | AM33: =IF(AND(S33>0,AI33>0),AI33/(S33),0) -> 2.0951817 | AN33: 6.4382628 | AO33: =AN33+AO32 -> 267.59175 | AP33: =AN33/(P33) -> 0.087572775 | AQ33: =AO33/(Q33) -> 0.1875715 | AR33: =IF(AND(R33>0,AN33>0),AN33/(R33),0) -> 0.088197797 | AS33: =IF(AND(S33>0,AO33>0),AO33/(S33),0) -> 0.19262499 | AT33: =+'25'!I46 -> 30103.19 | AU33: =AT33+AU32 -> 836276.05 | AV33: =IF(AND(L33>0,AT33>0),(AT33/(P33*1000)*1000),0) -> 409.46136 | AW33: =IF(AND(M33>0,AU33>0),(AU33/(Q33*1000)*1000),0) -> 586.19726 | AX33: =IF(AND(R33>0,AT33>0),(AT33/(R33*1000)*1000),0) -> 412.38376 | AY33: =IF(AND(S33>0,AU33>0),(AU33/(S33*1000)*1000),0) -> 601.99041 | AZ33: =+Listrik!AH32 -> 40418.34 | BA33: =AZ33+BA32 -> 685952.56 | BB33: =IF(AND(L33>0,AZ33>0),(AZ33/(P33*1000)*1000),0) -> 549.76727 | BC33: =IF(AND(M33>0,BA33>0),(BA33/(Q33*1000)*1000),0) -> 480.82629 | BD33: =IF(AND(R33>0,AZ33>0),(AZ33/(R33*1000)*1000),0) -> 553.69106 | BE33: =IF(AND(S33>0,BA33>0),(BA33/(S33*1000)*1000),0) -> 493.78057 | BF33: 0.173 | BG33: 114.896 | BH33: =+SUM(Efficiency2!K124:K125) -> 76.506017 | BI33: =BI32+BH33 -> 1571.5362 | BJ33: =+R33/BH33 -> 0.95414717 | BK33: =+S33/BI33 -> 0.88396629
A34: =A33+1 -> 46017 | B34: Towel | C34: 36/38 | D34: =+'26'!F42 -> 530 | E34: =+'26'!G42 -> 466.4 | F34: =1-(E34/D34) -> 0.12 | G34: =+P34/N34 -> 0.98930199 | H34: =+P34/L34 -> 0.98930199 | I34: =+R34/P34 -> 0.98920999 | J34: =+R34/L34 -> 0.97862741 | K34: =+S34/M34 -> 0.85433861 | L34: =+SUM(Efficiency1!K128:K129) -> 80.377884 | M34: =M33+L34 -> 1718.1068 | N34: =+SUM(Efficiency1!C128:C129) -> 80.377884 | O34: =O33+N34 -> 1677.4282 | P34: ='26'!I38 -> 79.518 | Q34: =Q33+P34 -> 1506.13 | R34: ='26'!I40 -> 78.66 | S34: =S33+R34 -> 1467.845 | T34: =R34/P34 -> 0.98920999 | U34: =S34/Q34 -> 0.97458055 | V34: =R34/L34 -> 0.97862741 | W34: =S34/M34 -> 0.85433861 | AB34: 0 | AC34: =AB34+AC33 -> 0 | AD34: =AB34/P34 -> 0 | AE34: =AC34/Q34 -> 0 | AF34: =IF(AND(R34>0,AB34>0),(AB34/(R34*1000))*1000,0) -> 0 | AG34: =IF(AND(S34>0,AC34>0),AC34/S34,0) -> 0 | AH34: =+BF34+BG34 -> 118.446 | AI34: =AH34+AI33 -> 3029.041 | AJ34: =AH34/(P34) -> 1.4895495 | AK34: =AI34/(Q34) -> 2.0111418 | AL34: =IF(AND(R34>0,AH34>0),AH34/(R34),0) -> 1.5057971 | AM34: =IF(AND(S34>0,AI34>0),AI34/(S34),0) -> 2.0635973 | AN34: 6.9 | AO34: =AN34+AO33 -> 274.49175 | AP34: =AN34/(P34) -> 0.086772806 | AQ34: =AO34/(Q34) -> 0.18224971 | AR34: =IF(AND(R34>0,AN34>0),AN34/(R34),0) -> 0.087719298 | AS34: =IF(AND(S34>0,AO34>0),AO34/(S34),0) -> 0.18700323 | AT34: ='26'!I46 -> 34188.04 | AU34: =AT34+AU33 -> 870464.09 | AV34: =IF(AND(L34>0,AT34>0),(AT34/(P34*1000)*1000),0) -> 429.94089 | AW34: =IF(AND(M34>0,AU34>0),(AU34/(Q34*1000)*1000),0) -> 577.94751 | AX34: =IF(AND(R34>0,AT34>0),(AT34/(R34*1000)*1000),0) -> 434.63056 | AY34: =IF(AND(S34>0,AU34>0),(AU34/(S34*1000)*1000),0) -> 593.0218 | AZ34: =+Listrik!AH33 -> 37588.4 | BA34: =AZ34+BA33 -> 723540.96 | BB34: =IF(AND(L34>0,AZ34>0),(AZ34/(P34*1000)*1000),0) -> 472.70304 | BC34: =IF(AND(M34>0,BA34>0),(BA34/(Q34*1000)*1000),0) -> 480.39742 | BD34: =IF(AND(R34>0,AZ34>0),(AZ34/(R34*1000)*1000),0) -> 477.85914 | BE34: =IF(AND(S34>0,BA34>0),(BA34/(S34*1000)*1000),0) -> 492.92736 | BF34: =0.642 -> 0.642 | BG34: 117.804 | BH34: =+SUM(Efficiency2!K128:K129) -> 80.377884 | BI34: =BI33+BH34 -> 1651.9141 | BJ34: =+R34/BH34 -> 0.97862741 | BK34: =+S34/BI34 -> 0.88857226
A35: =A34+1 -> 46018 | B35: Towel | C35: 38 | D35: =+'27'!F42 -> 530 | E35: =+'27'!G42 -> 466.4 | F35: =1-(E35/D35) -> 0.12 | G35: =+P35/N35 -> 0.96483311 | H35: =+P35/L35 -> 0.96483311 | I35: =+R35/P35 -> 0.96578719 | J35: =+R35/L35 -> 0.93182345 | K35: =+S35/M35 -> 0.85783366 | L35: =+Efficiency1!K132 -> 81.158077 | M35: =M34+L35 -> 1799.2649 | N35: =+Efficiency1!C132 -> 81.158077 | O35: =O34+N35 -> 1758.5863 | P35: ='27'!I38 -> 78.304 | Q35: =Q34+P35 -> 1584.434 | R35: ='27'!I40 -> 75.625 | S35: =S34+R35 -> 1543.47 | T35: =R35/P35 -> 0.96578719 | U35: =S35/Q35 -> 0.97414597 | V35: =R35/L35 -> 0.93182345 | W35: =S35/M35 -> 0.85783366 | AB35: 0 | AC35: =AB35+AC34 -> 0 | AD35: =AB35/P35 -> 0 | AE35: =AC35/Q35 -> 0 | AF35: =IF(AND(R35>0,AB35>0),(AB35/(R35*1000))*1000,0) -> 0 | AG35: =IF(AND(S35>0,AC35>0),AC35/S35,0) -> 0 | AH35: =+BF35+BG35 -> 121.955 | AI35: =AH35+AI34 -> 3150.996 | AJ35: =AH35/(P35) -> 1.5574556 | AK35: =AI35/(Q35) -> 1.9887203 | AL35: =IF(AND(R35>0,AH35>0),AH35/(R35),0) -> 1.6126281 | AM35: =IF(AND(S35>0,AI35>0),AI35/(S35),0) -> 2.0415013 | AN35: 6.4 | AO35: =AN35+AO34 -> 280.89175 | AP35: =AN35/(P35) -> 0.081732734 | AQ35: =AO35/(Q35) -> 0.17728208 | AR35: =IF(AND(R35>0,AN35>0),AN35/(R35),0) -> 0.084628099 | AS35: =IF(AND(S35>0,AO35>0),AO35/(S35),0) -> 0.18198718 | AT35: ='27'!I46 -> 31921.49 | AU35: =AT35+AU34 -> 902385.58 | AV35: =IF(AND(L35>0,AT35>0),(AT35/(P35*1000)*1000),0) -> 407.66104 | AW35: =IF(AND(M35>0,AU35>0),(AU35/(Q35*1000)*1000),0) -> 569.53182 | AX35: =IF(AND(R35>0,AT35>0),(AT35/(R35*1000)*1000),0) -> 422.10235 | AY35: =IF(AND(S35>0,AU35>0),(AU35/(S35*1000)*1000),0) -> 584.64731 | AZ35: =+Listrik!AH34 -> 40256.7 | BA35: =AZ35+BA34 -> 763797.66 | BB35: =IF(AND(L35>0,AZ35>0),(AZ35/(P35*1000)*1000),0) -> 514.10784 | BC35: =IF(AND(M35>0,BA35>0),(BA35/(Q35*1000)*1000),0) -> 482.06341 | BD35: =IF(AND(R35>0,AZ35>0),(AZ35/(R35*1000)*1000),0) -> 532.32 | BE35: =IF(AND(S35>0,BA35>0),(BA35/(S35*1000)*1000),0) -> 494.85747 | BF35: =0.909 -> 0.909 | BG35: 121.046 | BH35: =+Efficiency2!K132 -> 81.158077 | BI35: =BI34+BH35 -> 1733.0721 | BJ35: =+R35/BH35 -> 0.93182345 | BK35: =+S35/BI35 -> 0.89059767
