Workbook

Sheet Report1
A3: PAPER MACHINE 12 DAILY REPORT 1
A6: DATE | B6: GRADE | C6: GSM | D6: Speed yankee (mpm) | E6: Speed reel (mpm) | F6: Creep ( % ) | G6: Real Eff PM ( % ) | H6: Real Eff PM vs Target (%) | I6: Real Eff FG vs Real Eff PM (%) | J6: Eff FG vs Target (%) | L6: Kapasitas Target (ton) | N6: Kapasitas Teori Real (ton) | P6: PM PROD Timbangan (TON) | R6: FINSHED GOODS (TON) | T6: NET GROSS (Timbangan) (%) | V6: NET GROSS ( Scanner) (%) | X6: FRESH WATER | AB6: GAS HOOD | AH6: STEAM (TON) | AN6: STEAM (TON) DEINKING | AT6: POWER (kWh) | AZ6: POWER (kWh) DEINKING | BF6: Report | BH6: Kapasitas Running (ton) | BJ6: Eff FG vs Target Running(%)
X7: CONSUMPTION | Z7: /TON FG. | AB7: CONSUMPTION | AD7: /TON PM. | AF7: /TON FG. | AH7: CONSUMPTION | AJ7: /TON PM. | AL7: /TON FG. | AN7: CONSUMPTION | AP7: /TON PM. | AR7: /TON FG. | AT7: CONSUMPTION | AV7: /TON PM | AX7: /TON FG | AZ7: CONSUMPTION | BB7: /TON PM | BD7: /TON FG | BF7: Hood | BG7: Yankee
J8: TODAY | K8: TODATE | L8: TODAY | M8: TODATE | N8: TODAY | O8: TODATE | P8: TODAY | Q8: TODATE | R8: TODAY | S8: TODATE | T8: TODAY | U8: TODATE | V8: TODAY | W8: TODATE | X8: TODAY | Y8: TODATE | Z8: TODAY | AA8: TODATE | AB8: TODAY | AC8: TODATE | AD8: TODAY | AE8: TODATE | AF8: TODAY | AG8: TODATE | AH8: TODAY | AI8: TODATE | AJ8: TODAY | AK8: TODATE | AL8: TODAY | AM8: TODATE | AN8: TODAY | AO8: TODATE | AP8: TODAY | AQ8: TODATE | AR8: TODAY | AS8: TODATE | AT8: TODAY | AU8: TODATE | AV8: TODAY | AW8: TODATE | AX8: TODAY | AY8: TODATE | AZ8: TODAY | BA8: TODATE | BB8: TODAY | BC8: TODATE | BD8: TODAY | BE8: TODATE | BH8: TODAY | BI8: TODATE | BJ8: TODAY | BK8: TODATE
A9: 45931 | B9: Towel | C9: 34 | D9: =+'1'!F42 -> 0 | E9: =+'1'!G42 -> 0 | F9: =1-(E9/D9) -> #DIV/0! | G9: =+P9/N9 -> 0 | H9: =+P9/L9 -> 0 | I9: =+R9/P9 -> #DIV/0! | J9: =+R9/L9 -> 0 | K9: =+S9/M9 -> 0 | L9: =+SUM(Efficiency1!K6:K8) -> 69.693972 | M9: =L9 -> 69.693972 | N9: =+SUM(Efficiency1!C6:C8) -> 69.693972 | O9: =N9 -> 69.693972 | P9: ='1'!I38 -> 0 | Q9: =P9 -> 0 | R9: ='1'!I40 -> 0 | S9: =R9 -> 0 | T9: =R9/P9 -> #DIV/0! | U9: =S9/Q9 -> #DIV/0! | V9: =R9/L9 -> 0 | W9: =S9/M9 -> 0 | AB9: 0 | AC9: =AB9 -> 0 | AD9: =AB9/P9 -> #DIV/0! | AE9: =AC9/Q9 -> #DIV/0! | AF9: =IF(AND(R9>0,AB9>0),(AB9/(R9*1000))*1000,0) -> 0 | AG9: =IF(AND(S9>0,AC9>0),AC9/S9,0) -> 0 | AH9: =+BF9+BG9 -> 2.169 | AI9: =AH9 -> 2.169 | AJ9: =AH9/(P9) -> #DIV/0! | AK9: =AI9/(Q9) -> #DIV/0! | AL9: =IF(AND(R9>0,AH9>0),AH9/(R9),0) -> 0 | AM9: =IF(AND(S9>0,AI9>0),AI9/(S9),0) -> 0 | AN9: 0 | AO9: =AN9 -> 0 | AP9: =AN9/(P9) -> #DIV/0! | AQ9: =AO9/(Q9) -> #DIV/0! | AR9: =IF(AND(R9>0,AN9>0),AN9/(R9),0) -> 0 | AS9: =IF(AND(S9>0,AO9>0),AO9/(S9),0) -> 0 | AT9: ='1'!I46 -> 9364.25 | AU9: =AT9 -> 9364.25 | AV9: =IF(AND(L9>0,AT9>0),(AT9/(P9*1000)*1000),0) -> #DIV/0! | AW9: =IF(AND(M9>0,AU9>0),(AU9/(Q9*1000)*1000),0) -> #DIV/0! | AX9: =IF(AND(R9>0,AT9>0),(AT9/(R9*1000)*1000),0) -> 0 | AY9: =IF(AND(S9>0,AU9>0),(AU9/(S9*1000)*1000),0) -> 0 | AZ9: =+Listrik!AH8 -> 8610 | BA9: =AZ9 -> 8610 | BB9: =IF(AND(L9>0,AZ9>0),(AZ9/(P9*1000)*1000),0) -> #DIV/0! | BC9: =IF(AND(M9>0,BA9>0),(BA9/(Q9*1000)*1000),0) -> #DIV/0! | BD9: =IF(AND(R9>0,AZ9>0),(AZ9/(R9*1000)*1000),0) -> 0 | BE9: =IF(AND(S9>0,BA9>0),(BA9/(S9*1000)*1000),0) -> 0 | BF9: =0.023 -> 0.023 | BG9: 2.146 | BH9: =+SUM(Efficiency2!K6:K8) -> 0 | BI9: =BH9 -> 0 | BJ9: =+R9/BH9 -> #DIV/0! | BK9: =+S9/BI9 -> #DIV/0!
A10: =A9+1 -> 45932 | B10: Towel | C10: 17 | D10: =+'2'!F42 -> 812.2906 | E10: =+'2'!G42 -> 698.56991 | F10: =1-(E10/D10) -> 0.14 | G10: =+P10/N10 -> 0.78061971 | H10: =+P10/L10 -> 0.76396392 | I10: =+R10/P10 -> 0.83387906 | J10: =+R10/L10 -> 0.63705352 | K10: =+S10/M10 -> 0.28260253 | L10: =+Efficiency1!K11 -> 55.56676 | M10: =M9+L10 -> 125.26073 | N10: =+Efficiency1!C11 -> 54.381153 | O10: =O9+N10 -> 124.07513 | P10: ='2'!I38 -> 42.451 | Q10: =Q9+P10 -> 42.451 | R10: ='2'!I40 -> 35.399 | S10: =S9+R10 -> 35.399 | T10: =R10/P10 -> 0.83387906 | U10: =S10/Q10 -> 0.83387906 | V10: =R10/L10 -> 0.63705352 | W10: =S10/M10 -> 0.28260253 | AB10: 0 | AC10: =AB10+AC9 -> 0 | AD10: =AB10/P10 -> 0 | AE10: =AC10/Q10 -> 0 | AF10: =IF(AND(R10>0,AB10>0),(AB10/(R10*1000))*1000,0) -> 0 | AG10: =IF(AND(S10>0,AC10>0),AC10/S10,0) -> 0 | AH10: =+BF10+BG10 -> 146.954 | AI10: =AH10+AI9 -> 149.123 | AJ10: =AH10/(P10) -> 3.4617324 | AK10: =AI10/(Q10) -> 3.5128266 | AL10: =IF(AND(R10>0,AH10>0),AH10/(R10),0) -> 4.1513602 | AM10: =IF(AND(S10>0,AI10>0),AI10/(S10),0) -> 4.2126331 | AN10: 15.2 | AO10: =AN10+AO9 -> 15.2 | AP10: =AN10/(P10) -> 0.35805988 | AQ10: =AO10/(Q10) -> 0.35805988 | AR10: =IF(AND(R10>0,AN10>0),AN10/(R10),0) -> 0.42939066 | AS10: =IF(AND(S10>0,AO10>0),AO10/(S10),0) -> 0.42939066 | AT10: ='2'!I46 -> 33377.97 | AU10: =AT10+AU9 -> 42742.22 | AV10: =IF(AND(L10>0,AT10>0),(AT10/(P10*1000)*1000),0) -> 786.27052 | AW10: =IF(AND(M10>0,AU10>0),(AU10/(Q10*1000)*1000),0) -> 1006.8601 | AX10: =IF(AND(R10>0,AT10>0),(AT10/(R10*1000)*1000),0) -> 942.90714 | AY10: =IF(AND(S10>0,AU10>0),(AU10/(S10*1000)*1000),0) -> 1207.4415 | AZ10: =+Listrik!AH9 -> 34737 | BA10: =AZ10+BA9 -> 43347 | BB10: =IF(AND(L10>0,AZ10>0),(AZ10/(P10*1000)*1000),0) -> 818.28461 | BC10: =IF(AND(M10>0,BA10>0),(BA10/(Q10*1000)*1000),0) -> 1021.1067 | BD10: =IF(AND(R10>0,AZ10>0),(AZ10/(R10*1000)*1000),0) -> 981.29891 | BE10: =IF(AND(S10>0,BA10>0),(BA10/(S10*1000)*1000),0) -> 1224.5261 | BF10: =3.409 -> 3.409 | BG10: 143.545 | BH10: =+Efficiency2!K11 -> 46.305634 | BI10: =BI9+BH10 -> 46.305634 | BJ10: =+R10/BH10 -> 0.76446422 | BK10: =+S10/BI10 -> 0.76446422
A11: =A10+1 -> 45933 | B11: Towel | C11: 17/18 | D11: =+'3'!F42 -> 830 | E11: =+'3'!G42 -> 713.8 | F11: =1-(E11/D11) -> 0.14 | G11: =+P11/N11 -> 0.94700659 | H11: =+P11/L11 -> 0.94700659 | I11: =+R11/P11 -> 0.94632789 | J11: =+R11/L11 -> 0.89617874 | K11: =+S11/M11 -> 0.4794761 | L11: =+SUM(Efficiency1!K16:K17) -> 59.180159 | M11: =M10+L11 -> 184.44089 | N11: =+SUM(Efficiency1!C16:C17) -> 59.180159 | O11: =O10+N11 -> 183.25528 | P11: ='3'!I38 -> 56.044 | Q11: =Q10+P11 -> 98.495 | R11: ='3'!I40 -> 53.036 | S11: =S10+R11 -> 88.435 | T11: =R11/P11 -> 0.94632789 | U11: =S11/Q11 -> 0.89786284 | V11: =R11/L11 -> 0.89617874 | W11: =S11/M11 -> 0.4794761 | AB11: 0 | AC11: =AB11+AC10 -> 0 | AD11: =AB11/P11 -> 0 | AE11: =AC11/Q11 -> 0 | AF11: =IF(AND(R11>0,AB11>0),(AB11/(R11*1000))*1000,0) -> 0 | AG11: =IF(AND(S11>0,AC11>0),AC11/S11,0) -> 0 | AH11: =+BF11+BG11 -> 135.528 | AI11: =AH11+AI10 -> 284.651 | AJ11: =AH11/(P11) -> 2.4182428 | AK11: =AI11/(Q11) -> 2.8900046 | AL11: =IF(AND(R11>0,AH11>0),AH11/(R11),0) -> 2.5553963 | AM11: =IF(AND(S11>0,AI11>0),AI11/(S11),0) -> 3.2187595 | AN11: 10.1 | AO11: =AN11+AO10 -> 25.3 | AP11: =AN11/(P11) -> 0.18021554 | AQ11: =AO11/(Q11) -> 0.25686583 | AR11: =IF(AND(R11>0,AN11>0),AN11/(R11),0) -> 0.19043668 | AS11: =IF(AND(S11>0,AO11>0),AO11/(S11),0) -> 0.28608583 | AT11: ='3'!I46 -> 36074.73 | AU11: =AT11+AU10 -> 78816.95 | AV11: =IF(AND(L11>0,AT11>0),(AT11/(P11*1000)*1000),0) -> 643.68585 | AW11: =IF(AND(M11>0,AU11>0),(AU11/(Q11*1000)*1000),0) -> 800.2127 | AX11: =IF(AND(R11>0,AT11>0),(AT11/(R11*1000)*1000),0) -> 680.19326 | AY11: =IF(AND(S11>0,AU11>0),(AU11/(S11*1000)*1000),0) -> 891.24159 | AZ11: =+Listrik!AH10 -> 27237.2 | BA11: =AZ11+BA10 -> 70584.2 | BB11: =IF(AND(L11>0,AZ11>0),(AZ11/(P11*1000)*1000),0) -> 485.99672 | BC11: =IF(AND(M11>0,BA11>0),(BA11/(Q11*1000)*1000),0) -> 716.62724 | BD11: =IF(AND(R11>0,AZ11>0),(AZ11/(R11*1000)*1000),0) -> 513.5606 | BE11: =IF(AND(S11>0,BA11>0),(BA11/(S11*1000)*1000),0) -> 798.14779 | BF11: =1.849 -> 1.849 | BG11: 133.679 | BH11: =+SUM(Efficiency2!K16:K17) -> 59.180159 | BI11: =BI10+BH11 -> 105.48579 | BJ11: =+R11/BH11 -> 0.89617874 | BK11: =+S11/BI11 -> 0.83835935
A12: =A11+1 -> 45934 | B12: Towel | C12: 18 | D12: =+'4'!F42 -> 830 | E12: =+'4'!G42 -> 713.8 | F12: =1-(E12/D12) -> 0.14 | G12: =+P12/N12 -> 0.70148974 | H12: =+P12/L12 -> 0.70148974 | I12: =+R12/P12 -> 0.78664644 | J12: =+R12/L12 -> 0.55182441 | K12: =+S12/M12 -> 0.49705656 | L12: =+Efficiency1!K21 -> 59.205427 | M12: =M11+L12 -> 243.64632 | N12: =+Efficiency1!C21 -> 59.205427 | O12: =O11+N12 -> 242.46071 | P12: ='4'!I38 -> 41.532 | Q12: =Q11+P12 -> 140.027 | R12: ='4'!I40 -> 32.671 | S12: =S11+R12 -> 121.106 | T12: =R12/P12 -> 0.78664644 | U12: =S12/Q12 -> 0.86487606 | V12: =R12/L12 -> 0.55182441 | W12: =S12/M12 -> 0.49705656 | AB12: 0 | AC12: =AB12+AC11 -> 0 | AD12: =AB12/P12 -> 0 | AE12: =AC12/Q12 -> 0 | AF12: =IF(AND(R12>0,AB12>0),(AB12/(R12*1000))*1000,0) -> 0 | AG12: =IF(AND(S12>0,AC12>0),AC12/S12,0) -> 0 | AH12: =+BF12+BG12 -> 123.195 | AI12: =AH12+AI11 -> 407.846 | AJ12: =AH12/(P12) -> 2.966267 | AK12: =AI12/(Q12) -> 2.912624 | AL12: =IF(AND(R12>0,AH12>0),AH12/(R12),0) -> 3.7707753 | AM12: =IF(AND(S12>0,AI12>0),AI12/(S12),0) -> 3.3676779 | AN12: 8.4 | AO12: =AN12+AO11 -> 33.7 | AP12: =AN12/(P12) -> 0.20225368 | AQ12: =AO12/(Q12) -> 0.24066787 | AR12: =IF(AND(R12>0,AN12>0),AN12/(R12),0) -> 0.25710875 | AS12: =IF(AND(S12>0,AO12>0),AO12/(S12),0) -> 0.27826862 | AT12: ='4'!I46 -> 29622.36 | AU12: =AT12+AU11 -> 108439.31 | AV12: =IF(AND(L12>0,AT12>0),(AT12/(P12*1000)*1000),0) -> 713.24184 | AW12: =IF(AND(M12>0,AU12>0),(AU12/(Q12*1000)*1000),0) -> 774.41715 | AX12: =IF(AND(R12>0,AT12>0),(AT12/(R12*1000)*1000),0) -> 906.68666 | AY12: =IF(AND(S12>0,AU12>0),(AU12/(S12*1000)*1000),0) -> 895.40824 | AZ12: =+Listrik!AH11 -> 22490.5 | BA12: =AZ12+BA11 -> 93074.7 | BB12: =IF(AND(L12>0,AZ12>0),(AZ12/(P12*1000)*1000),0) -> 541.5222 | BC12: =IF(AND(M12>0,BA12>0),(BA12/(Q12*1000)*1000),0) -> 664.6911 | BD12: =IF(AND(R12>0,AZ12>0),(AZ12/(R12*1000)*1000),0) -> 688.39338 | BE12: =IF(AND(S12>0,BA12>0),(BA12/(S12*1000)*1000),0) -> 768.53913 | BF12: =2.854 -> 2.854 | BG12: 120.341 | BH12: =+Efficiency2!K21 -> 59.205427 | BI12: =BI11+BH12 -> 164.69122 | BJ12: =+R12/BH12 -> 0.55182441 | BK12: =+S12/BI12 -> 0.73535189
A13: =A12+1 -> 45935 | B13: Towel | C13: 18/20 | D13: =+'5'!F42 -> 830 | E13: =+'5'!G42 -> 713.8 | F13: =1-(E13/D13) -> 0.14 | G13: =+P13/N13 -> 0.7943066 | H13: =+P13/L13 -> 0.7943066 | I13: =+R13/P13 -> 0.90507276 | J13: =+R13/L13 -> 0.71890526 | K13: =+S13/M13 -> 0.54222786 | L13: =+SUM(Efficiency1!K26:K27) -> 62.293326 | M13: =M12+L13 -> 305.93964 | N13: =+SUM(Efficiency1!C26:C27) -> 62.293326 | O13: =O12+N13 -> 304.75404 | P13: ='5'!I38 -> 49.48 | Q13: =Q12+P13 -> 189.507 | R13: ='5'!I40 -> 44.783 | S13: =S12+R13 -> 165.889 | T13: =R13/P13 -> 0.90507276 | U13: =S13/Q13 -> 0.87537136 | V13: =R13/L13 -> 0.71890526 | W13: =S13/M13 -> 0.54222786 | AB13: 0 | AC13: =AB13+AC12 -> 0 | AD13: =AB13/P13 -> 0 | AE13: =AC13/Q13 -> 0 | AF13: =IF(AND(R13>0,AB13>0),(AB13/(R13*1000))*1000,0) -> 0 | AG13: =IF(AND(S13>0,AC13>0),AC13/S13,0) -> 0 | AH13: =+BF13+BG13 -> 125.263 | AI13: =AH13+AI12 -> 533.109 | AJ13: =AH13/(P13) -> 2.5315885 | AK13: =AI13/(Q13) -> 2.8131362 | AL13: =IF(AND(R13>0,AH13>0),AH13/(R13),0) -> 2.7971105 | AM13: =IF(AND(S13>0,AI13>0),AI13/(S13),0) -> 3.2136489 | AN13: 10.6 | AO13: =AN13+AO12 -> 44.3 | AP13: =AN13/(P13) -> 0.21422797 | AQ13: =AO13/(Q13) -> 0.23376445 | AR13: =IF(AND(R13>0,AN13>0),AN13/(R13),0) -> 0.23669696 | AS13: =IF(AND(S13>0,AO13>0),AO13/(S13),0) -> 0.26704604 | AT13: ='5'!I46 -> 31409.12 | AU13: =AT13+AU12 -> 139848.43 | AV13: =IF(AND(L13>0,AT13>0),(AT13/(P13*1000)*1000),0) -> 634.78416 | AW13: =IF(AND(M13>0,AU13>0),(AU13/(Q13*1000)*1000),0) -> 737.95918 | AX13: =IF(AND(R13>0,AT13>0),(AT13/(R13*1000)*1000),0) -> 701.36257 | AY13: =IF(AND(S13>0,AU13>0),(AU13/(S13*1000)*1000),0) -> 843.02413 | AZ13: =+Listrik!AH12 -> 25890.64 | BA13: =AZ13+BA12 -> 118965.34 | BB13: =IF(AND(L13>0,AZ13>0),(AZ13/(P13*1000)*1000),0) -> 523.25465 | BC13: =IF(AND(M13>0,BA13>0),(BA13/(Q13*1000)*1000),0) -> 627.76225 | BD13: =IF(AND(R13>0,AZ13>0),(AZ13/(R13*1000)*1000),0) -> 578.13545 | BE13: =IF(AND(S13>0,BA13>0),(BA13/(S13*1000)*1000),0) -> 717.13821 | BF13: =1.709 -> 1.709 | BG13: 123.554 | BH13: =+SUM(Efficiency2!K26:K27) -> 62.293326 | BI13: =BI12+BH13 -> 226.98455 | BJ13: =+R13/BH13 -> 0.71890526 | BK13: =+S13/BI13 -> 0.7308383
A14: =A13+1 -> 45936 | B14: Towel | C14: 20/17/18/18,5 | D14: =+'6'!F42 -> 830 | E14: =+'6'!G42 -> 713.8 | F14: =1-(E14/D14) -> 0.14 | G14: =+P14/N14 -> 0.94593443 | H14: =+P14/L14 -> 0.94593443 | I14: =+R14/P14 -> 0.97516556 | J14: =+R14/L14 -> 0.92244268 | K14: =+S14/M14 -> 0.60950089 | L14: =+SUM(Efficiency1!K32:K35) -> 65.767772 | M14: =M13+L14 -> 371.70742 | N14: =+SUM(Efficiency1!C32:C35) -> 65.767772 | O14: =O13+N14 -> 370.52181 | P14: ='6'!I38 -> 62.212 | Q14: =Q13+P14 -> 251.719 | R14: ='6'!I40 -> 60.667 | S14: =S13+R14 -> 226.556 | T14: =R14/P14 -> 0.97516556 | U14: =S14/Q14 -> 0.90003536 | V14: =R14/L14 -> 0.92244268 | W14: =S14/M14 -> 0.60950089 | AB14: 0 | AC14: =AB14+AC13 -> 0 | AD14: =AB14/P14 -> 0 | AE14: =AC14/Q14 -> 0 | AF14: =IF(AND(R14>0,AB14>0),(AB14/(R14*1000))*1000,0) -> 0 | AG14: =IF(AND(S14>0,AC14>0),AC14/S14,0) -> 0 | AH14: =+BF14+BG14 -> 136.004 | AI14: =AH14+AI13 -> 669.113 | AJ14: =AH14/(P14) -> 2.1861377 | AK14: =AI14/(Q14) -> 2.6581744 | AL14: =IF(AND(R14>0,AH14>0),AH14/(R14),0) -> 2.2418119 | AM14: =IF(AND(S14>0,AI14>0),AI14/(S14),0) -> 2.9534111 | AN14: 10.3 | AO14: =AN14+AO13 -> 54.6 | AP14: =AN14/(P14) -> 0.16556291 | AQ14: =AO14/(Q14) -> 0.21690854 | AR14: =IF(AND(R14>0,AN14>0),AN14/(R14),0) -> 0.16977929 | AS14: =IF(AND(S14>0,AO14>0),AO14/(S14),0) -> 0.24100002 | AT14: ='6'!I46 -> 36077.61 | AU14: =AT14+AU13 -> 175926.04 | AV14: =IF(AND(L14>0,AT14>0),(AT14/(P14*1000)*1000),0) -> 579.914 | AW14: =IF(AND(M14>0,AU14>0),(AU14/(Q14*1000)*1000),0) -> 698.89853 | AX14: =IF(AND(R14>0,AT14>0),(AT14/(R14*1000)*1000),0) -> 594.68261 | AY14: =IF(AND(S14>0,AU14>0),(AU14/(S14*1000)*1000),0) -> 776.52342 | AZ14: =+Listrik!AH13 -> 26265.4 | BA14: =AZ14+BA13 -> 145230.74 | BB14: =IF(AND(L14>0,AZ14>0),(AZ14/(P14*1000)*1000),0) -> 422.19186 | BC14: =IF(AND(M14>0,BA14>0),(BA14/(Q14*1000)*1000),0) -> 576.95581 | BD14: =IF(AND(R14>0,AZ14>0),(AZ14/(R14*1000)*1000),0) -> 432.94378 | BE14: =IF(AND(S14>0,BA14>0),(BA14/(S14*1000)*1000),0) -> 641.03683 | BF14: =2.099 -> 2.099 | BG14: 133.905 | BH14: =+SUM(Efficiency2!K32:K35) -> 65.767772 | BI14: =BI13+BH14 -> 292.75232 | BJ14: =+R14/BH14 -> 0.92244268 | BK14: =+S14/BI14 -> 0.77388286
A15: =A14+1 -> 45937 | B15: Towel | C15: 18,5/32 | D15: =+'7'!F42 -> 538.88889 | E15: =+'7'!G42 -> 472.72361 | F15: =1-(E15/D15) -> 0.12278093 | G15: =+P15/N15 -> 1.0569362 | H15: =+P15/L15 -> 1.0383609 | I15: =+R15/P15 -> 1.0085612 | J15: =+R15/L15 -> 1.0472504 | K15: =+S15/M15 -> 0.67572565 | L15: =+SUM(Efficiency1!K37:K38) -> 66.257313 | M15: =M14+L15 -> 437.96473 | N15: =+SUM(Efficiency1!C37:C38) -> 65.092859 | O15: =O14+N15 -> 435.61467 | P15: ='7'!I38 -> 68.799 | Q15: =Q14+P15 -> 320.518 | R15: ='7'!I40 -> 69.388 | S15: =S14+R15 -> 295.944 | T15: =R15/P15 -> 1.0085612 | U15: =S15/Q15 -> 0.92333036 | V15: =R15/L15 -> 1.0472504 | W15: =S15/M15 -> 0.67572565 | AB15: 0 | AC15: =AB15+AC14 -> 0 | AD15: =AB15/P15 -> 0 | AE15: =AC15/Q15 -> 0 | AF15: =IF(AND(R15>0,AB15>0),(AB15/(R15*1000))*1000,0) -> 0 | AG15: =IF(AND(S15>0,AC15>0),AC15/S15,0) -> 0 | AH15: =+BF15+BG15 -> 121.743 | AI15: =AH15+AI14 -> 790.856 | AJ15: =AH15/(P15) -> 1.7695461 | AK15: =AI15/(Q15) -> 2.4674308 | AL15: =IF(AND(R15>0,AH15>0),AH15/(R15),0) -> 1.7545253 | AM15: =IF(AND(S15>0,AI15>0),AI15/(S15),0) -> 2.6723164 | AN15: 13.1 | AO15: =AN15+AO14 -> 67.7 | AP15: =AN15/(P15) -> 0.19040974 | AQ15: =AO15/(Q15) -> 0.21122059 | AR15: =IF(AND(R15>0,AN15>0),AN15/(R15),0) -> 0.18879345 | AS15: =IF(AND(S15>0,AO15>0),AO15/(S15),0) -> 0.2287595 | AT15: ='7'!I46 -> 35992.25 | AU15: =AT15+AU14 -> 211918.29 | AV15: =IF(AND(L15>0,AT15>0),(AT15/(P15*1000)*1000),0) -> 523.15077 | AW15: =IF(AND(M15>0,AU15>0),(AU15/(Q15*1000)*1000),0) -> 661.17438 | AX15: =IF(AND(R15>0,AT15>0),(AT15/(R15*1000)*1000),0) -> 518.71001 | AY15: =IF(AND(S15>0,AU15>0),(AU15/(S15*1000)*1000),0) -> 716.07564 | AZ15: =+Listrik!AH14 -> 34858.6 | BA15: =AZ15+BA14 -> 180089.34 | BB15: =IF(AND(L15>0,AZ15>0),(AZ15/(P15*1000)*1000),0) -> 506.67306 | BC15: =IF(AND(M15>0,BA15>0),(BA15/(Q15*1000)*1000),0) -> 561.86966 | BD15: =IF(AND(R15>0,AZ15>0),(AZ15/(R15*1000)*1000),0) -> 502.37217 | BE15: =IF(AND(S15>0,BA15>0),(BA15/(S15*1000)*1000),0) -> 608.52506 | BF15: =2.261 -> 2.261 | BG15: 119.482 | BH15: =+SUM(Efficiency2!K37:K38) -> 66.257313 | BI15: =BI14+BH15 -> 359.00963 | BJ15: =+R15/BH15 -> 1.0472504 | BK15: =+S15/BI15 -> 0.82433443
A16: =A15+1 -> 45938 | B16: Towel | C16: 32/34/36/38 | D16: =+'8'!F42 -> 473.52083 | E16: =+'8'!G42 -> 416.69833 | F16: =1-(E16/D16) -> 0.12 | G16: =+P16/N16 -> 0.96361311 | H16: =+P16/L16 -> 0.95854409 | I16: =+R16/P16 -> 0.98539637 | J16: =+R16/L16 -> 0.94454587 | K16: =+S16/M16 -> 0.71156213 | L16: =+SUM(Efficiency1!K42:K45) -> 67.365707 | M16: =M15+L16 -> 505.33044 | N16: =+SUM(Efficiency1!C42:C45) -> 67.011334 | O16: =O15+N16 -> 502.626 | P16: ='8'!I38 -> 64.573 | Q16: =Q15+P16 -> 385.091 | R16: ='8'!I40 -> 63.63 | S16: =S15+R16 -> 359.574 | T16: =R16/P16 -> 0.98539637 | U16: =S16/Q16 -> 0.93373774 | V16: =R16/L16 -> 0.94454587 | W16: =S16/M16 -> 0.71156213 | AB16: 0 | AC16: =AB16+AC15 -> 0 | AD16: =AB16/P16 -> 0 | AE16: =AC16/Q16 -> 0 | AF16: =IF(AND(R16>0,AB16>0),(AB16/(R16*1000))*1000,0) -> 0 | AG16: =IF(AND(S16>0,AC16>0),AC16/S16,0) -> 0 | AH16: =+BF16+BG16 -> 121.563 | AI16: =AH16+AI15 -> 912.419 | AJ16: =AH16/(P16) -> 1.882567 | AK16: =AI16/(Q16) -> 2.3693595 | AL16: =IF(AND(R16>0,AH16>0),AH16/(R16),0) -> 1.9104668 | AM16: =IF(AND(S16>0,AI16>0),AI16/(S16),0) -> 2.5374999 | AN16: 10.6 | AO16: =AN16+AO15 -> 78.3 | AP16: =AN16/(P16) -> 0.1641553 | AQ16: =AO16/(Q16) -> 0.20332856 | AR16: =IF(AND(R16>0,AN16>0),AN16/(R16),0) -> 0.16658809 | AS16: =IF(AND(S16>0,AO16>0),AO16/(S16),0) -> 0.21775768 | AT16: ='8'!I46 -> 32501.39 | AU16: =AT16+AU15 -> 244419.68 | AV16: =IF(AND(L16>0,AT16>0),(AT16/(P16*1000)*1000),0) -> 503.32786 | AW16: =IF(AND(M16>0,AU16>0),(AU16/(Q16*1000)*1000),0) -> 634.70629 | AX16: =IF(AND(R16>0,AT16>0),(AT16/(R16*1000)*1000),0) -> 510.78721 | AY16: =IF(AND(S16>0,AU16>0),(AU16/(S16*1000)*1000),0) -> 679.74792 | AZ16: =+Listrik!AH15 -> 26943.4 | BA16: =AZ16+BA15 -> 207032.74 | BB16: =IF(AND(L16>0,AZ16>0),(AZ16/(P16*1000)*1000),0) -> 417.25489 | BC16: =IF(AND(M16>0,BA16>0),(BA16/(Q16*1000)*1000),0) -> 537.6203 | BD16: =IF(AND(R16>0,AZ16>0),(AZ16/(R16*1000)*1000),0) -> 423.43863 | BE16: =IF(AND(S16>0,BA16>0),(BA16/(S16*1000)*1000),0) -> 575.77227 | BF16: =2.285 -> 2.285 | BG16: 119.278 | BH16: =+SUM(Efficiency2!K42:K45) -> 67.365707 | BI16: =BI15+BH16 -> 426.37534 | BJ16: =+R16/BH16 -> 0.94454587 | BK16: =+S16/BI16 -> 0.84332739
A17: =A16+1 -> 45939 | B17: Towel | C17: 38/36/30 | D17: =+'9'!F42 -> 475.48611 | E17: =+'9'!G42 -> 418.42778 | F17: =1-(E17/D17) -> 0.12 | G17: =+P17/N17 -> 0.99152521 | H17: =+P17/L17 -> 0.99152521 | I17: =+R17/P17 -> 0.98867919 | J17: =+R17/L17 -> 0.98030034 | K17: =+S17/M17 -> 0.74353555 | L17: =+SUM(Efficiency1!K47:K49) -> 68.241331 | M17: =M16+L17 -> 573.57177 | N17: =+SUM(Efficiency1!C47:C49) -> 68.241331 | O17: =O16+N17 -> 570.86733 | P17: ='9'!I38 -> 67.663 | Q17: =Q16+P17 -> 452.754 | R17: ='9'!I40 -> 66.897 | S17: =S16+R17 -> 426.471 | T17: =R17/P17 -> 0.98867919 | U17: =S17/Q17 -> 0.94194861 | V17: =R17/L17 -> 0.98030034 | W17: =S17/M17 -> 0.74353555 | AB17: 0 | AC17: =AB17+AC16 -> 0 | AD17: =AB17/P17 -> 0 | AE17: =AC17/Q17 -> 0 | AF17: =IF(AND(R17>0,AB17>0),(AB17/(R17*1000))*1000,0) -> 0 | AG17: =IF(AND(S17>0,AC17>0),AC17/S17,0) -> 0 | AH17: =+BF17+BG17 -> 125.213 | AI17: =AH17+AI16 -> 1037.632 | AJ17: =AH17/(P17) -> 1.8505387 | AK17: =AI17/(Q17) -> 2.2918229 | AL17: =IF(AND(R17>0,AH17>0),AH17/(R17),0) -> 1.8717282 | AM17: =IF(AND(S17>0,AI17>0),AI17/(S17),0) -> 2.4330658 | AN17: 14.1 | AO17: =AN17+AO16 -> 92.4 | AP17: =AN17/(P17) -> 0.20838568 | AQ17: =AO17/(Q17) -> 0.20408434 | AR17: =IF(AND(R17>0,AN17>0),AN17/(R17),0) -> 0.21077178 | AS17: =IF(AND(S17>0,AO17>0),AO17/(S17),0) -> 0.21666186 | AT17: ='9'!I46 -> 30853.79 | AU17: =AT17+AU16 -> 275273.47 | AV17: =IF(AND(L17>0,AT17>0),(AT17/(P17*1000)*1000),0) -> 455.99205 | AW17: =IF(AND(M17>0,AU17>0),(AU17/(Q17*1000)*1000),0) -> 607.99788 | AX17: =IF(AND(R17>0,AT17>0),(AT17/(R17*1000)*1000),0) -> 461.21336 | AY17: =IF(AND(S17>0,AU17>0),(AU17/(S17*1000)*1000),0) -> 645.4682 | AZ17: =+Listrik!AH16 -> 36937.2 | BA17: =AZ17+BA16 -> 243969.94 | BB17: =IF(AND(L17>0,AZ17>0),(AZ17/(P17*1000)*1000),0) -> 545.89953 | BC17: =IF(AND(M17>0,BA17>0),(BA17/(Q17*1000)*1000),0) -> 538.85761 | BD17: =IF(AND(R17>0,AZ17>0),(AZ17/(R17*1000)*1000),0) -> 552.15032 | BE17: =IF(AND(S17>0,BA17>0),(BA17/(S17*1000)*1000),0) -> 572.06689 | BF17: =2.54 -> 2.54 | BG17: 122.673 | BH17: =+SUM(Efficiency2!K47:K49) -> 68.241331 | BI17: =BI16+BH17 -> 494.61667 | BJ17: =+R17/BH17 -> 0.98030034 | BK17: =+S17/BI17 -> 0.86222529
A18: =A17+1 -> 45940 | B18: Towel | C18: 30/28 | D18: =+'10'!F42 -> 589.09722 | E18: =+'10'!G42 -> 518.40556 | F18: =1-(E18/D18) -> 0.12 | G18: =+P18/N18 -> 0.98000011 | H18: =+P18/L18 -> 0.98000011 | I18: =+R18/P18 -> 0.9801886 | J18: =+R18/L18 -> 0.96058493 | K18: =+S18/M18 -> 0.76704967 | L18: =+SUM(Efficiency1!K52:K53) -> 69.687747 | M18: =M17+L18 -> 643.25951 | N18: =+SUM(Efficiency1!C52:C53) -> 69.687747 | O18: =O17+N18 -> 640.55508 | P18: ='10'!I38 -> 68.294 | Q18: =Q17+P18 -> 521.048 | R18: ='10'!I40 -> 66.941 | S18: =S17+R18 -> 493.412 | T18: =R18/P18 -> 0.9801886 | U18: =S18/Q18 -> 0.94696074 | V18: =R18/L18 -> 0.96058493 | W18: =S18/M18 -> 0.76704967 | AB18: 0 | AC18: =AB18+AC17 -> 0 | AD18: =AB18/P18 -> 0 | AE18: =AC18/Q18 -> 0 | AF18: =IF(AND(R18>0,AB18>0),(AB18/(R18*1000))*1000,0) -> 0 | AG18: =IF(AND(S18>0,AC18>0),AC18/S18,0) -> 0 | AH18: =+BF18+BG18 -> 136.842 | AI18: =AH18+AI17 -> 1174.474 | AJ18: =AH18/(P18) -> 2.0037192 | AK18: =AI18/(Q18) -> 2.254061 | AL18: =IF(AND(R18>0,AH18>0),AH18/(R18),0) -> 2.044218 | AM18: =IF(AND(S18>0,AI18>0),AI18/(S18),0) -> 2.380311 | AN18: 12.2 | AO18: =AN18+AO17 -> 104.6 | AP18: =AN18/(P18) -> 0.17863941 | AQ18: =AO18/(Q18) -> 0.20074926 | AR18: =IF(AND(R18>0,AN18>0),AN18/(R18),0) -> 0.18225004 | AS18: =IF(AND(S18>0,AO18>0),AO18/(S18),0) -> 0.21199322 | AT18: ='10'!I46 -> 32327.01 | AU18: =AT18+AU17 -> 307600.48 | AV18: =IF(AND(L18>0,AT18>0),(AT18/(P18*1000)*1000),0) -> 473.35066 | AW18: =IF(AND(M18>0,AU18>0),(AU18/(Q18*1000)*1000),0) -> 590.3496 | AX18: =IF(AND(R18>0,AT18>0),(AT18/(R18*1000)*1000),0) -> 482.91794 | AY18: =IF(AND(S18>0,AU18>0),(AU18/(S18*1000)*1000),0) -> 623.41508 | AZ18: =+Listrik!AH17 -> 31230.8 | BA18: =AZ18+BA17 -> 275200.74 | BB18: =IF(AND(L18>0,AZ18>0),(AZ18/(P18*1000)*1000),0) -> 457.29932 | BC18: =IF(AND(M18>0,BA18>0),(BA18/(Q18*1000)*1000),0) -> 528.16773 | BD18: =IF(AND(R18>0,AZ18>0),(AZ18/(R18*1000)*1000),0) -> 466.54218 | BE18: =IF(AND(S18>0,BA18>0),(BA18/(S18*1000)*1000),0) -> 557.7504 | BF18: =2.767 -> 2.767 | BG18: 134.075 | BH18: =+SUM(Efficiency2!K52:K53) -> 69.687747 | BI18: =BI17+BH18 -> 564.30442 | BJ18: =+R18/BH18 -> 0.96058493 | BK18: =+S18/BI18 -> 0.87437203
A19: =A18+1 -> 45941 | B19: Towel | C19: 28/20,5 | D19: =+'11'!F42 -> 794.58333 | E19: =+'11'!G42 -> 684.39167 | F19: =1-(E19/D19) -> 0.13867855 | G19: =+P19/N19 -> 0.97195726 | H19: =+P19/L19 -> 0.95001115 | I19: =+R19/P19 -> 0.95021019 | J19: =+R19/L19 -> 0.90271028 | K19: =+S19/M19 -> 0.77990833 | L19: =+SUM(Efficiency1!K57:K58) -> 67.356051 | M19: =M18+L19 -> 710.61557 | N19: =+SUM(Efficiency1!C57:C58) -> 65.835199 | O19: =O18+N19 -> 706.39028 | P19: ='11'!I38 -> 63.989 | Q19: =Q18+P19 -> 585.037 | R19: ='11'!I40 -> 60.803 | S19: =S18+R19 -> 554.215 | T19: =R19/P19 -> 0.95021019 | U19: =S19/Q19 -> 0.94731615 | V19: =R19/L19 -> 0.90271028 | W19: =S19/M19 -> 0.77990833 | AB19: 0 | AC19: =AB19+AC18 -> 0 | AD19: =AB19/P19 -> 0 | AE19: =AC19/Q19 -> 0 | AF19: =IF(AND(R19>0,AB19>0),(AB19/(R19*1000))*1000,0) -> 0 | AG19: =IF(AND(S19>0,AC19>0),AC19/S19,0) -> 0 | AH19: =+BF19+BG19 -> 139.471 | AI19: =AH19+AI18 -> 1313.945 | AJ19: =AH19/(P19) -> 2.179609 | AK19: =AI19/(Q19) -> 2.2459178 | AL19: =IF(AND(R19>0,AH19>0),AH19/(R19),0) -> 2.2938177 | AM19: =IF(AND(S19>0,AI19>0),AI19/(S19),0) -> 2.3708218 | AN19: 11.5 | AO19: =AN19+AO18 -> 116.1 | AP19: =AN19/(P19) -> 0.17971839 | AQ19: =AO19/(Q19) -> 0.19844899 | AR19: =IF(AND(R19>0,AN19>0),AN19/(R19),0) -> 0.1891354 | AS19: =IF(AND(S19>0,AO19>0),AO19/(S19),0) -> 0.20948549 | AT19: ='11'!I46 -> 35496.17 | AU19: =AT19+AU18 -> 343096.65 | AV19: =IF(AND(L19>0,AT19>0),(AT19/(P19*1000)*1000),0) -> 554.723 | AW19: =IF(AND(M19>0,AU19>0),(AU19/(Q19*1000)*1000),0) -> 586.45291 | AX19: =IF(AND(R19>0,AT19>0),(AT19/(R19*1000)*1000),0) -> 583.78978 | AY19: =IF(AND(S19>0,AU19>0),(AU19/(S19*1000)*1000),0) -> 619.06778 | AZ19: =+Listrik!AH18 -> 28711.446 | BA19: =AZ19+BA18 -> 303912.19 | BB19: =IF(AND(L19>0,AZ19>0),(AZ19/(P19*1000)*1000),0) -> 448.69346 | BC19: =IF(AND(M19>0,BA19>0),(BA19/(Q19*1000)*1000),0) -> 519.47515 | BD19: =IF(AND(R19>0,AZ19>0),(AZ19/(R19*1000)*1000),0) -> 472.20443 | BE19: =IF(AND(S19>0,BA19>0),(BA19/(S19*1000)*1000),0) -> 548.36514 | BF19: =2.447 -> 2.447 | BG19: 137.024 | BH19: =+SUM(Efficiency2!K57:K58) -> 67.356051 | BI19: =BI18+BH19 -> 631.66047 | BJ19: =+R19/BH19 -> 0.90271028 | BK19: =+S19/BI19 -> 0.87739384
A20: =A19+1 -> 45942 | B20: Napkin | C20: 20,5 | D20: =+'12'!F42 -> 803.23482 | E20: =+'12'!G42 -> 690.78195 | F20: =1-(E20/D20) -> 0.14 | G20: =+P20/N20 -> 0.79756488 | H20: =+P20/L20 -> 0.77184564 | I20: =+R20/P20 -> 0.98396936 | J20: =+R20/L20 -> 0.75947247 | K20: =+S20/M20 -> 0.7781398 | L20: =+Efficiency1!K62 -> 67.323046 | M20: =M19+L20 -> 777.93861 | N20: =+Efficiency1!C62 -> 65.152067 | O20: =O19+N20 -> 771.54235 | P20: ='12'!I38 -> 51.963 | Q20: =Q19+P20 -> 637 | R20: ='12'!I40 -> 51.13 | S20: =S19+R20 -> 605.345 | T20: =R20/P20 -> 0.98396936 | U20: =S20/Q20 -> 0.95030612 | V20: =R20/L20 -> 0.75947247 | W20: =S20/M20 -> 0.7781398 | AB20: 0 | AC20: =AB20+AC19 -> 0 | AD20: =AB20/P20 -> 0 | AE20: =AC20/Q20 -> 0 | AF20: =IF(AND(R20>0,AB20>0),(AB20/(R20*1000))*1000,0) -> 0 | AG20: =IF(AND(S20>0,AC20>0),AC20/S20,0) -> 0 | AH20: =+BF20+BG20 -> 125.794 | AI20: =AH20+AI19 -> 1439.739 | AJ20: =AH20/(P20) -> 2.4208379 | AK20: =AI20/(Q20) -> 2.2601868 | AL20: =IF(AND(R20>0,AH20>0),AH20/(R20),0) -> 2.4602777 | AM20: =IF(AND(S20>0,AI20>0),AI20/(S20),0) -> 2.3783776 | AN20: 10.2 | AO20: =AN20+AO19 -> 126.3 | AP20: =AN20/(P20) -> 0.19629352 | AQ20: =AO20/(Q20) -> 0.19827316 | AR20: =IF(AND(R20>0,AN20>0),AN20/(R20),0) -> 0.19949149 | AS20: =IF(AND(S20>0,AO20>0),AO20/(S20),0) -> 0.20864135 | AT20: ='12'!I46 -> 33687.62 | AU20: =AT20+AU19 -> 376784.27 | AV20: =IF(AND(L20>0,AT20>0),(AT20/(P20*1000)*1000),0) -> 648.30014 | AW20: =IF(AND(M20>0,AU20>0),(AU20/(Q20*1000)*1000),0) -> 591.49807 | AX20: =IF(AND(R20>0,AT20>0),(AT20/(R20*1000)*1000),0) -> 658.86212 | AY20: =IF(AND(S20>0,AU20>0),(AU20/(S20*1000)*1000),0) -> 622.42898 | AZ20: =+Listrik!AH19 -> 28421.702 | BA20: =AZ20+BA19 -> 332333.89 | BB20: =IF(AND(L20>0,AZ20>0),(AZ20/(P20*1000)*1000),0) -> 546.96038 | BC20: =IF(AND(M20>0,BA20>0),(BA20/(Q20*1000)*1000),0) -> 521.71725 | BD20: =IF(AND(R20>0,AZ20>0),(AZ20/(R20*1000)*1000),0) -> 555.87135 | BE20: =IF(AND(S20>0,BA20>0),(BA20/(S20*1000)*1000),0) -> 548.99915 | BF20: =2.482 -> 2.482 | BG20: 123.312 | BH20: =+Efficiency2!K62 -> 67.323046 | BI20: =BI19+BH20 -> 698.98351 | BJ20: =+R20/BH20 -> 0.75947247 | BK20: =+S20/BI20 -> 0.86603616
A21: =A20+1 -> 45943 | B21: Napkin | C21: 20,5 | D21: =+'13'!F42 -> 830 | E21: =+'13'!G42 -> 713.8 | F21: =1-(E21/D21) -> 0.14 | G21: =+P21/N21 -> 0.86636008 | H21: =+P21/L21 -> 0.86636008 | I21: =+R21/P21 -> 0.93690635 | J21: =+R21/L21 -> 0.81169827 | K21: =+S21/M21 -> 0.78081266 | L21: =+Efficiency1!K68 -> 67.323046 | M21: =M20+L21 -> 845.26166 | N21: =+Efficiency1!C68 -> 67.323046 | O21: =O20+N21 -> 838.86539 | P21: ='13'!I38 -> 58.326 | Q21: =Q20+P21 -> 695.326 | R21: ='13'!I40 -> 54.646 | S21: =S20+R21 -> 659.991 | T21: =R21/P21 -> 0.93690635 | U21: =S21/Q21 -> 0.94918211 | V21: =R21/L21 -> 0.81169827 | W21: =S21/M21 -> 0.78081266 | AB21: 0 | AC21: =AB21+AC20 -> 0 | AD21: =AB21/P21 -> 0 | AE21: =AC21/Q21 -> 0 | AF21: =IF(AND(R21>0,AB21>0),(AB21/(R21*1000))*1000,0) -> 0 | AG21: =IF(AND(S21>0,AC21>0),AC21/S21,0) -> 0 | AH21: =+BF21+BG21 -> 135.662 | AI21: =AH21+AI20 -> 1575.401 | AJ21: =AH21/(P21) -> 2.3259267 | AK21: =AI21/(Q21) -> 2.2657013 | AL21: =IF(AND(R21>0,AH21>0),AH21/(R21),0) -> 2.4825605 | AM21: =IF(AND(S21>0,AI21>0),AI21/(S21),0) -> 2.3870038 | AN21: 10.2 | AO21: =AN21+AO20 -> 136.5 | AP21: =AN21/(P21) -> 0.17487913 | AQ21: =AO21/(Q21) -> 0.1963108 | AR21: =IF(AND(R21>0,AN21>0),AN21/(R21),0) -> 0.18665593 | AS21: =IF(AND(S21>0,AO21>0),AO21/(S21),0) -> 0.206821 | AT21: ='13'!I46 -> 32518.41 | AU21: =AT21+AU20 -> 409302.68 | AV21: =IF(AND(L21>0,AT21>0),(AT21/(P21*1000)*1000),0) -> 557.52855 | AW21: =IF(AND(M21>0,AU21>0),(AU21/(Q21*1000)*1000),0) -> 588.64861 | AX21: =IF(AND(R21>0,AT21>0),(AT21/(R21*1000)*1000),0) -> 595.07393 | AY21: =IF(AND(S21>0,AU21>0),(AU21/(S21*1000)*1000),0) -> 620.16403 | AZ21: =+Listrik!AH20 -> 26345.3 | BA21: =AZ21+BA20 -> 358679.19 | BB21: =IF(AND(L21>0,AZ21>0),(AZ21/(P21*1000)*1000),0) -> 451.6905 | BC21: =IF(AND(M21>0,BA21>0),(BA21/(Q21*1000)*1000),0) -> 515.8432 | BD21: =IF(AND(R21>0,AZ21>0),(AZ21/(R21*1000)*1000),0) -> 482.10848 | BE21: =IF(AND(S21>0,BA21>0),(BA21/(S21*1000)*1000),0) -> 543.46073 | BF21: =2.315 -> 2.315 | BG21: 133.347 | BH21: =+Efficiency2!K68 -> 67.323046 | BI21: =BI20+BH21 -> 766.30656 | BJ21: =+R21/BH21 -> 0.81169827 | BK21: =+S21/BI21 -> 0.86126237
A22: =A21+1 -> 45944 | B22: Napkin/Towel | C22: 20,5/30 | D22: =+'14'!F42 -> 636.52778 | E22: =+'14'!G42 -> 555.01458 | F22: =1-(E22/D22) -> 0.12805913 | G22: =+P22/N22 -> 0.9970745 | H22: =+P22/L22 -> 0.9970745 | I22: =+R22/P22 -> 1.0587114 | J22: =+R22/L22 -> 1.0556142 | K22: =+S22/M22 -> 0.80080352 | L22: =+SUM(Efficiency1!K74:K75) -> 66.314001 | M22: =M21+L22 -> 911.57566 | N22: =+SUM(Efficiency1!C74:C75) -> 66.314001 | O22: =O21+N22 -> 905.17939 | P22: ='14'!I38 -> 66.12 | Q22: =Q21+P22 -> 761.446 | R22: ='14'!I40 -> 70.002 | S22: =S21+R22 -> 729.993 | T22: =R22/P22 -> 1.0587114 | U22: =S22/Q22 -> 0.95869307 | V22: =R22/L22 -> 1.0556142 | W22: =S22/M22 -> 0.80080352 | AB22: 0 | AC22: =AB22+AC21 -> 0 | AD22: =AB22/P22 -> 0 | AE22: =AC22/Q22 -> 0 | AF22: =IF(AND(R22>0,AB22>0),(AB22/(R22*1000))*1000,0) -> 0 | AG22: =IF(AND(S22>0,AC22>0),AC22/S22,0) -> 0 | AH22: =+BF22+BG22 -> 142.463 | AI22: =AH22+AI21 -> 1717.864 | AJ22: =AH22/(P22) -> 2.1546128 | AK22: =AI22/(Q22) -> 2.2560549 | AL22: =IF(AND(R22>0,AH22>0),AH22/(R22),0) -> 2.0351276 | AM22: =IF(AND(S22>0,AI22>0),AI22/(S22),0) -> 2.3532609 | AN22: 16.6 | AO22: =AN22+AO21 -> 153.1 | AP22: =AN22/(P22) -> 0.25105868 | AQ22: =AO22/(Q22) -> 0.20106482 | AR22: =IF(AND(R22>0,AN22>0),AN22/(R22),0) -> 0.23713608 | AS22: =IF(AND(S22>0,AO22>0),AO22/(S22),0) -> 0.20972804 | AT22: ='14'!I46 -> 33745.6 | AU22: =AT22+AU21 -> 443048.28 | AV22: =IF(AND(L22>0,AT22>0),(AT22/(P22*1000)*1000),0) -> 510.36903 | AW22: =IF(AND(M22>0,AU22>0),(AU22/(Q22*1000)*1000),0) -> 581.85121 | AX22: =IF(AND(R22>0,AT22>0),(AT22/(R22*1000)*1000),0) -> 482.06623 | AY22: =IF(AND(S22>0,AU22>0),(AU22/(S22*1000)*1000),0) -> 606.92127 | AZ22: =+Listrik!AH21 -> 38320.4 | BA22: =AZ22+BA21 -> 396999.59 | BB22: =IF(AND(L22>0,AZ22>0),(AZ22/(P22*1000)*1000),0) -> 579.55838 | BC22: =IF(AND(M22>0,BA22>0),(BA22/(Q22*1000)*1000),0) -> 521.37589 | BD22: =IF(AND(R22>0,AZ22>0),(AZ22/(R22*1000)*1000),0) -> 547.41865 | BE22: =IF(AND(S22>0,BA22>0),(BA22/(S22*1000)*1000),0) -> 543.84027 | BF22: =5.471 -> 5.471 | BG22: 136.992 | BH22: =+SUM(Efficiency2!K74:K75) -> 66.314001 | BI22: =BI21+BH22 -> 832.62056 | BJ22: =+R22/BH22 -> 1.0556142 | BK22: =+S22/BI22 -> 0.8767415
A23: =A22+1 -> 45945 | B23: Towel/Napkin | C23: 30/17/16 | D23: =+'15'!F42 -> 818.33333 | E23: =+'15'!G42 -> 704.225 | F23: =1-(E23/D23) -> 0.13943992 | G23: =+P23/N23 -> 0.96293527 | H23: =+P23/L23 -> 0.96293527 | I23: =+R23/P23 -> 0.92461296 | J23: =+R23/L23 -> 0.89034243 | K23: =+S23/M23 -> 0.80598669 | L23: =+SUM(Efficiency1!K79:K81) -> 56.011034 | M23: =M22+L23 -> 967.58669 | N23: =+SUM(Efficiency1!C79:C81) -> 56.011034 | O23: =O22+N23 -> 961.19043 | P23: ='15'!I38 -> 53.935 | Q23: =Q22+P23 -> 815.381 | R23: ='15'!I40 -> 49.869 | S23: =S22+R23 -> 779.862 | T23: =R23/P23 -> 0.92461296 | U23: =S23/Q23 -> 0.95643877 | V23: =R23/L23 -> 0.89034243 | W23: =S23/M23 -> 0.80598669 | AB23: 0 | AC23: =AB23+AC22 -> 0 | AD23: =AB23/P23 -> 0 | AE23: =AC23/Q23 -> 0 | AF23: =IF(AND(R23>0,AB23>0),(AB23/(R23*1000))*1000,0) -> 0 | AG23: =IF(AND(S23>0,AC23>0),AC23/S23,0) -> 0 | AH23: =+BF23+BG23 -> 125.113 | AI23: =AH23+AI22 -> 1842.977 | AJ23: =AH23/(P23) -> 2.3196996 | AK23: =AI23/(Q23) -> 2.2602648 | AL23: =IF(AND(R23>0,AH23>0),AH23/(R23),0) -> 2.5088331 | AM23: =IF(AND(S23>0,AI23>0),AI23/(S23),0) -> 2.3632091 | AN23: 16.8 | AO23: =AN23+AO22 -> 169.9 | AP23: =AN23/(P23) -> 0.31148605 | AQ23: =AO23/(Q23) -> 0.20836885 | AR23: =IF(AND(R23>0,AN23>0),AN23/(R23),0) -> 0.33688263 | AS23: =IF(AND(S23>0,AO23>0),AO23/(S23),0) -> 0.21785906 | AT23: ='15'!I46 -> 35638.8 | AU23: =AT23+AU22 -> 478687.08 | AV23: =IF(AND(L23>0,AT23>0),(AT23/(P23*1000)*1000),0) -> 660.77315 | AW23: =IF(AND(M23>0,AU23>0),(AU23/(Q23*1000)*1000),0) -> 587.07166 | AX23: =IF(AND(R23>0,AT23>0),(AT23/(R23*1000)*1000),0) -> 714.64838 | AY23: =IF(AND(S23>0,AU23>0),(AU23/(S23*1000)*1000),0) -> 613.80998 | AZ23: =+Listrik!AH22 -> 25872 | BA23: =AZ23+BA22 -> 422871.59 | BB23: =IF(AND(L23>0,AZ23>0),(AZ23/(P23*1000)*1000),0) -> 479.68851 | BC23: =IF(AND(M23>0,BA23>0),(BA23/(Q23*1000)*1000),0) -> 518.6184 | BD23: =IF(AND(R23>0,AZ23>0),(AZ23/(R23*1000)*1000),0) -> 518.79925 | BE23: =IF(AND(S23>0,BA23>0),(BA23/(S23*1000)*1000),0) -> 542.239 | BF23: =5.063 -> 5.063 | BG23: 120.05 | BH23: =+SUM(Efficiency2!K79:K81) -> 56.011034 | BI23: =BI22+BH23 -> 888.63159 | BJ23: =+R23/BH23 -> 0.89034243 | BK23: =+S23/BI23 -> 0.87759878
A24: =A23+1 -> 45946 | B24: Napkin | C24: 16 | D24: =+'16'!F42 -> 830 | E24: =+'16'!G42 -> 713.8 | F24: =1-(E24/D24) -> 0.14 | G24: =+P24/N24 -> 0.96589685 | H24: =+P24/L24 -> 0.96589685 | I24: =+R24/P24 -> 0.47945259 | J24: =+R24/L24 -> 0.46310174 | K24: =+S24/M24 -> 0.78819439 | L24: =+SUM(Efficiency1!K84:K85) -> 52.955965 | M24: =M23+L24 -> 1020.5427 | N24: =+SUM(Efficiency1!C84:C85) -> 52.955965 | O24: =O23+N24 -> 1014.1464 | P24: ='16'!I38 -> 51.15 | Q24: =Q23+P24 -> 866.531 | R24: ='16'!I40 -> 24.524 | S24: =S23+R24 -> 804.386 | T24: =R24/P24 -> 0.47945259 | U24: =S24/Q24 -> 0.928283 | V24: =R24/L24 -> 0.46310174 | W24: =S24/M24 -> 0.78819439 | AB24: 0 | AC24: =AB24+AC23 -> 0 | AD24: =AB24/P24 -> 0 | AE24: =AC24/Q24 -> 0 | AF24: =IF(AND(R24>0,AB24>0),(AB24/(R24*1000))*1000,0) -> 0 | AG24: =IF(AND(S24>0,AC24>0),AC24/S24,0) -> 0 | AH24: =+BF24+BG24 -> 129.235 | AI24: =AH24+AI23 -> 1972.212 | AJ24: =AH24/(P24) -> 2.5265885 | AK24: =AI24/(Q24) -> 2.2759855 | AL24: =IF(AND(R24>0,AH24>0),AH24/(R24),0) -> 5.2697358 | AM24: =IF(AND(S24>0,AI24>0),AI24/(S24),0) -> 2.4518229 | AN24: 13.6 | AO24: =AN24+AO23 -> 183.5 | AP24: =AN24/(P24) -> 0.26588465 | AQ24: =AO24/(Q24) -> 0.21176392 | AR24: =IF(AND(R24>0,AN24>0),AN24/(R24),0) -> 0.5545588 | AS24: =IF(AND(S24>0,AO24>0),AO24/(S24),0) -> 0.22812431 | AT24: ='16'!I46 -> 30895.6 | AU24: =AT24+AU23 -> 509582.68 | AV24: =IF(AND(L24>0,AT24>0),(AT24/(P24*1000)*1000),0) -> 604.01955 | AW24: =IF(AND(M24>0,AU24>0),(AU24/(Q24*1000)*1000),0) -> 588.07207 | AX24: =IF(AND(R24>0,AT24>0),(AT24/(R24*1000)*1000),0) -> 1259.8108 | AY24: =IF(AND(S24>0,AU24>0),(AU24/(S24*1000)*1000),0) -> 633.50516 | AZ24: =+Listrik!AH23 -> 24647 | BA24: =AZ24+BA23 -> 447518.59 | BB24: =IF(AND(L24>0,AZ24>0),(AZ24/(P24*1000)*1000),0) -> 481.85728 | BC24: =IF(AND(M24>0,BA24>0),(BA24/(Q24*1000)*1000),0) -> 516.44845 | BD24: =IF(AND(R24>0,AZ24>0),(AZ24/(R24*1000)*1000),0) -> 1005.0155 | BE24: =IF(AND(S24>0,BA24>0),(BA24/(S24*1000)*1000),0) -> 556.34806 | BF24: =1.916 -> 1.916 | BG24: 127.319 | BH24: =+SUM(Efficiency2!K84:K85) -> 52.955965 | BI24: =BI23+BH24 -> 941.58756 | BJ24: =+R24/BH24 -> 0.46310174 | BK24: =+S24/BI24 -> 0.85428699
A25: =A24+1 -> 45947 | B25: Napkin | C25: 16/15,5 | D25: =+'17'!F42 -> 800 | E25: =+'17'!G42 -> 688 | F25: =1-(E25/D25) -> 0.14 | G25: =+P25/N25 -> 0.7978859 | H25: =+P25/L25 -> 0.76904665 | I25: =+R25/P25 -> 1.0637745 | J25: =+R25/L25 -> 0.81809222 | K25: =+S25/M25 -> 0.78965832 | L25: =+SUM(Efficiency1!K89:K90) -> 52.542976 | M25: =M24+L25 -> 1073.0856 | N25: =+SUM(Efficiency1!C89:C90) -> 50.643832 | O25: =O24+N25 -> 1064.7902 | P25: ='17'!I38 -> 40.408 | Q25: =Q24+P25 -> 906.939 | R25: ='17'!I40 -> 42.985 | S25: =S24+R25 -> 847.371 | T25: =R25/P25 -> 1.0637745 | U25: =S25/Q25 -> 0.93431973 | V25: =R25/L25 -> 0.81809222 | W25: =S25/M25 -> 0.78965832 | AB25: 0 | AC25: =AB25+AC24 -> 0 | AD25: =AB25/P25 -> 0 | AE25: =AC25/Q25 -> 0 | AF25: =IF(AND(R25>0,AB25>0),(AB25/(R25*1000))*1000,0) -> 0 | AG25: =IF(AND(S25>0,AC25>0),AC25/S25,0) -> 0 | AH25: =+BF25+BG25 -> 105.137 | AI25: =AH25+AI24 -> 2077.349 | AJ25: =AH25/(P25) -> 2.6018858 | AK25: =AI25/(Q25) -> 2.2905058 | AL25: =IF(AND(R25>0,AH25>0),AH25/(R25),0) -> 2.4458997 | AM25: =IF(AND(S25>0,AI25>0),AI25/(S25),0) -> 2.4515224 | AN25: 8.5 | AO25: =AN25+AO24 -> 192 | AP25: =AN25/(P25) -> 0.21035439 | AQ25: =AO25/(Q25) -> 0.21170112 | AR25: =IF(AND(R25>0,AN25>0),AN25/(R25),0) -> 0.1977434 | AS25: =IF(AND(S25>0,AO25>0),AO25/(S25),0) -> 0.22658316 | AT25: ='17'!I46 -> 33547.44 | AU25: =AT25+AU24 -> 543130.12 | AV25: =IF(AND(L25>0,AT25>0),(AT25/(P25*1000)*1000),0) -> 830.21778 | AW25: =IF(AND(M25>0,AU25>0),(AU25/(Q25*1000)*1000),0) -> 598.8607 | AX25: =IF(AND(R25>0,AT25>0),(AT25/(R25*1000)*1000),0) -> 780.44527 | AY25: =IF(AND(S25>0,AU25>0),(AU25/(S25*1000)*1000),0) -> 640.95906 | AZ25: =+Listrik!AH24 -> 17331 | BA25: =AZ25+BA24 -> 464849.59 | BB25: =IF(AND(L25>0,AZ25>0),(AZ25/(P25*1000)*1000),0) -> 428.90022 | BC25: =IF(AND(M25>0,BA25>0),(BA25/(Q25*1000)*1000),0) -> 512.5478 | BD25: =IF(AND(R25>0,AZ25>0),(AZ25/(R25*1000)*1000),0) -> 403.18716 | BE25: =IF(AND(S25>0,BA25>0),(BA25/(S25*1000)*1000),0) -> 548.57859 | BF25: =1.377 -> 1.377 | BG25: 103.76 | BH25: =+SUM(Efficiency2!K89:K90) -> 52.542976 | BI25: =BI24+BH25 -> 994.13054 | BJ25: =+R25/BH25 -> 0.81809222 | BK25: =+S25/BI25 -> 0.85237398
A26: =A25+1 -> 45948 | B26: Napkin | C26: 15,5 | D26: =+'18'!F42 -> 830 | E26: =+'18'!G42 -> 713.8 | F26: =1-(E26/D26) -> 0.14 | G26: =+P26/N26 -> 0.49518917 | H26: =+P26/L26 -> 0.49518917 | I26: =+R26/P26 -> 0.94822006 | J26: =+R26/L26 -> 0.4695483 | K26: =+S26/M26 -> 0.77475031 | L26: =+Efficiency1!K95 -> 52.416333 | M26: =M25+L26 -> 1125.502 | N26: =+Efficiency1!C95 -> 52.416333 | O26: =O25+N26 -> 1117.2066 | P26: ='18'!I38 -> 25.956 | Q26: =Q25+P26 -> 932.895 | R26: ='18'!I40 -> 24.612 | S26: =S25+R26 -> 871.983 | T26: =R26/P26 -> 0.94822006 | U26: =S26/Q26 -> 0.93470648 | V26: =R26/L26 -> 0.4695483 | W26: =S26/M26 -> 0.77475031 | AB26: 0 | AC26: =AB26+AC25 -> 0 | AD26: =AB26/P26 -> 0 | AE26: =AC26/Q26 -> 0 | AF26: =IF(AND(R26>0,AB26>0),(AB26/(R26*1000))*1000,0) -> 0 | AG26: =IF(AND(S26>0,AC26>0),AC26/S26,0) -> 0 | AH26: =+BF26+BG26 -> 80.039 | AI26: =AH26+AI25 -> 2157.388 | AJ26: =AH26/(P26) -> 3.0836415 | AK26: =AI26/(Q26) -> 2.3125732 | AL26: =IF(AND(R26>0,AH26>0),AH26/(R26),0) -> 3.2520315 | AM26: =IF(AND(S26>0,AI26>0),AI26/(S26),0) -> 2.474117 | AN26: 11.1 | AO26: =AN26+AO25 -> 203.1 | AP26: =AN26/(P26) -> 0.42764679 | AQ26: =AO26/(Q26) -> 0.21770939 | AR26: =IF(AND(R26>0,AN26>0),AN26/(R26),0) -> 0.45099951 | AS26: =IF(AND(S26>0,AO26>0),AO26/(S26),0) -> 0.23291738 | AT26: ='18'!I46 -> 21046.07 | AU26: =AT26+AU25 -> 564176.19 | AV26: =IF(AND(L26>0,AT26>0),(AT26/(P26*1000)*1000),0) -> 810.83642 | AW26: =IF(AND(M26>0,AU26>0),(AU26/(Q26*1000)*1000),0) -> 604.75851 | AX26: =IF(AND(R26>0,AT26>0),(AT26/(R26*1000)*1000),0) -> 855.11417 | AY26: =IF(AND(S26>0,AU26>0),(AU26/(S26*1000)*1000),0) -> 647.00366 | AZ26: =+Listrik!AH25 -> 17305 | BA26: =AZ26+BA25 -> 482154.59 | BB26: =IF(AND(L26>0,AZ26>0),(AZ26/(P26*1000)*1000),0) -> 666.70519 | BC26: =IF(AND(M26>0,BA26>0),(BA26/(Q26*1000)*1000),0) -> 516.83693 | BD26: =IF(AND(R26>0,AZ26>0),(AZ26/(R26*1000)*1000),0) -> 703.1123 | BE26: =IF(AND(S26>0,BA26>0),(BA26/(S26*1000)*1000),0) -> 552.94035 | BF26: =0.643 -> 0.643 | BG26: 79.396 | BH26: =+Efficiency2!K95 -> 52.416333 | BI26: =BI25+BH26 -> 1046.5469 | BJ26: =+R26/BH26 -> 0.4695483 | BK26: =+S26/BI26 -> 0.83320014
A27: =A26+1 -> 45949 | B27: Napkin | C27: 15,5 | D27: =+'19'!F42 -> 830 | E27: =+'19'!G42 -> 713.8 | F27: =1-(E27/D27) -> 0.14 | G27: =+P27/N27 -> 0.96702683 | H27: =+P27/L27 -> 0.96702683 | I27: =+R27/P27 -> 0.96760574 | J27: =+R27/L27 -> 0.93570072 | K27: =+S27/M27 -> 0.78191246 | L27: =+Efficiency1!K100 -> 52.416333 | M27: =M26+L27 -> 1177.9183 | N27: =+Efficiency1!C100 -> 52.416333 | O27: =O26+N27 -> 1169.6229 | P27: ='19'!I38 -> 50.688 | Q27: =Q26+P27 -> 983.583 | R27: ='19'!I40 -> 49.046 | S27: =S26+R27 -> 921.029 | T27: =R27/P27 -> 0.96760574 | U27: =S27/Q27 -> 0.93640191 | V27: =R27/L27 -> 0.93570072 | W27: =S27/M27 -> 0.78191246 | AB27: 0 | AC27: =AB27+AC26 -> 0 | AD27: =AB27/P27 -> 0 | AE27: =AC27/Q27 -> 0 | AF27: =IF(AND(R27>0,AB27>0),(AB27/(R27*1000))*1000,0) -> 0 | AG27: =IF(AND(S27>0,AC27>0),AC27/S27,0) -> 0 | AH27: =+BF27+BG27 -> 121.2 | AI27: =AH27+AI26 -> 2278.588 | AJ27: =AH27/(P27) -> 2.3910985 | AK27: =AI27/(Q27) -> 2.3166199 | AL27: =IF(AND(R27>0,AH27>0),AH27/(R27),0) -> 2.4711495 | AM27: =IF(AND(S27>0,AI27>0),AI27/(S27),0) -> 2.473959 | AN27: 12 | AO27: =AN27+AO26 -> 215.1 | AP27: =AN27/(P27) -> 0.23674242 | AQ27: =AO27/(Q27) -> 0.21869024 | AR27: =IF(AND(R27>0,AN27>0),AN27/(R27),0) -> 0.24466827 | AS27: =IF(AND(S27>0,AO27>0),AO27/(S27),0) -> 0.23354313 | AT27: ='19'!I46 -> 37504.57 | AU27: =AT27+AU26 -> 601680.76 | AV27: =IF(AND(L27>0,AT27>0),(AT27/(P27*1000)*1000),0) -> 739.91024 | AW27: =IF(AND(M27>0,AU27>0),(AU27/(Q27*1000)*1000),0) -> 611.72342 | AX27: =IF(AND(R27>0,AT27>0),(AT27/(R27*1000)*1000),0) -> 764.68152 | AY27: =IF(AND(S27>0,AU27>0),(AU27/(S27*1000)*1000),0) -> 653.27016 | AZ27: =+Listrik!AH26 -> 19293 | BA27: =AZ27+BA26 -> 501447.59 | BB27: =IF(AND(L27>0,AZ27>0),(AZ27/(P27*1000)*1000),0) -> 380.62263 | BC27: =IF(AND(M27>0,BA27>0),(BA27/(Q27*1000)*1000),0) -> 509.81726 | BD27: =IF(AND(R27>0,AZ27>0),(AZ27/(R27*1000)*1000),0) -> 393.36541 | BE27: =IF(AND(S27>0,BA27>0),(BA27/(S27*1000)*1000),0) -> 544.44278 | BF27: =1.149 -> 1.149 | BG27: 120.051 | BH27: =+Efficiency2!K100 -> 52.416333 | BI27: =BI26+BH27 -> 1098.9632 | BJ27: =+R27/BH27 -> 0.93570072 | BK27: =+S27/BI27 -> 0.83808903
A28: =A27+1 -> 45950 | B28: Napkin | C28: 15,5 | D28: =+'20'!F42 -> 830 | E28: =+'20'!G42 -> 713.8 | F28: =1-(E28/D28) -> 0.14 | G28: =+P28/N28 -> 0.94172937 | H28: =+P28/L28 -> 0.94172937 | I28: =+R28/P28 -> 1.0053685 | J28: =+R28/L28 -> 0.94678505 | K28: =+S28/M28 -> 0.78893658 | L28: =+Efficiency1!K104 -> 52.416333 | M28: =M27+L28 -> 1230.3346 | N28: =+Efficiency1!C104 -> 52.416333 | O28: =O27+N28 -> 1222.0392 | P28: ='20'!I38 -> 49.362 | Q28: =Q27+P28 -> 1032.945 | R28: ='20'!I40 -> 49.627 | S28: =S27+R28 -> 970.656 | T28: =R28/P28 -> 1.0053685 | U28: =S28/Q28 -> 0.93969766 | V28: =R28/L28 -> 0.94678505 | W28: =S28/M28 -> 0.78893658 | AB28: 0 | AC28: =AB28+AC27 -> 0 | AD28: =AB28/P28 -> 0 | AE28: =AC28/Q28 -> 0 | AF28: =IF(AND(R28>0,AB28>0),(AB28/(R28*1000))*1000,0) -> 0 | AG28: =IF(AND(S28>0,AC28>0),AC28/S28,0) -> 0 | AH28: =+BF28+BG28 -> 120.823 | AI28: =AH28+AI27 -> 2399.411 | AJ28: =AH28/(P28) -> 2.4476926 | AK28: =AI28/(Q28) -> 2.3228836 | AL28: =IF(AND(R28>0,AH28>0),AH28/(R28),0) -> 2.4346223 | AM28: =IF(AND(S28>0,AI28>0),AI28/(S28),0) -> 2.4719478 | AN28: 14.4 | AO28: =AN28+AO27 -> 229.5 | AP28: =AN28/(P28) -> 0.29172238 | AQ28: =AO28/(Q28) -> 0.22218027 | AR28: =IF(AND(R28>0,AN28>0),AN28/(R28),0) -> 0.29016463 | AS28: =IF(AND(S28>0,AO28>0),AO28/(S28),0) -> 0.23643804 | AT28: ='20'!I46 -> 35243.73 | AU28: =AT28+AU27 -> 636924.49 | AV28: =IF(AND(L28>0,AT28>0),(AT28/(P28*1000)*1000),0) -> 713.98505 | AW28: =IF(AND(M28>0,AU28>0),(AU28/(Q28*1000)*1000),0) -> 616.61026 | AX28: =IF(AND(R28>0,AT28>0),(AT28/(R28*1000)*1000),0) -> 710.17249 | AY28: =IF(AND(S28>0,AU28>0),(AU28/(S28*1000)*1000),0) -> 656.17942 | AZ28: =+Listrik!AH27 -> 22897 | BA28: =AZ28+BA27 -> 524344.59 | BB28: =IF(AND(L28>0,AZ28>0),(AZ28/(P28*1000)*1000),0) -> 463.85884 | BC28: =IF(AND(M28>0,BA28>0),(BA28/(Q28*1000)*1000),0) -> 507.62101 | BD28: =IF(AND(R28>0,AZ28>0),(AZ28/(R28*1000)*1000),0) -> 461.38191 | BE28: =IF(AND(S28>0,BA28>0),(BA28/(S28*1000)*1000),0) -> 540.1961 | BF28: =2.103 -> 2.103 | BG28: 118.72 | BH28: =+Efficiency2!K104 -> 52.416333 | BI28: =BI27+BH28 -> 1151.3795 | BJ28: =+R28/BH28 -> 0.94678505 | BK28: =+S28/BI28 -> 0.84303739
A29: =A28+1 -> 45951 | B29: Napkin | C29: 15,5/17/16 | D29: =+'21'!F42 -> 830 | E29: =+'21'!G42 -> 713.8 | F29: =1-(E29/D29) -> 0.14 | G29: =+P29/N29 -> 0.94766473 | H29: =+P29/L29 -> 0.94766473 | I29: =+R29/P29 -> 0.94631689 | J29: =+R29/L29 -> 0.89679114 | K29: =+S29/M29 -> 0.79359268 | L29: =+SUM(Efficiency1!K108:K110) -> 55.510138 | M29: =M28+L29 -> 1285.8448 | N29: =+SUM(Efficiency1!C108:C110) -> 55.510138 | O29: =O28+N29 -> 1277.5494 | P29: ='21'!I38 -> 52.605 | Q29: =Q28+P29 -> 1085.55 | R29: ='21'!I40 -> 49.781 | S29: =S28+R29 -> 1020.437 | T29: =R29/P29 -> 0.94631689 | U29: =S29/Q29 -> 0.94001842 | V29: =R29/L29 -> 0.89679114 | W29: =S29/M29 -> 0.79359268 | AB29: 0 | AC29: =AB29+AC28 -> 0 | AD29: =AB29/P29 -> 0 | AE29: =AC29/Q29 -> 0 | AF29: =IF(AND(R29>0,AB29>0),(AB29/(R29*1000))*1000,0) -> 0 | AG29: =IF(AND(S29>0,AC29>0),AC29/S29,0) -> 0 | AH29: =+BF29+BG29 -> 128.018 | AI29: =AH29+AI28 -> 2527.429 | AJ29: =AH29/(P29) -> 2.433571 | AK29: =AI29/(Q29) -> 2.3282474 | AL29: =IF(AND(R29>0,AH29>0),AH29/(R29),0) -> 2.5716237 | AM29: =IF(AND(S29>0,AI29>0),AI29/(S29),0) -> 2.4768104 | AN29: 12.1 | AO29: =AN29+AO28 -> 241.6 | AP29: =AN29/(P29) -> 0.23001616 | AQ29: =AO29/(Q29) -> 0.22255999 | AR29: =IF(AND(R29>0,AN29>0),AN29/(R29),0) -> 0.24306462 | AS29: =IF(AND(S29>0,AO29>0),AO29/(S29),0) -> 0.23676131 | AT29: ='21'!I46 -> 37000.89 | AU29: =AT29+AU28 -> 673925.38 | AV29: =IF(AND(L29>0,AT29>0),(AT29/(P29*1000)*1000),0) -> 703.37211 | AW29: =IF(AND(M29>0,AU29>0),(AU29/(Q29*1000)*1000),0) -> 620.81468 | AX29: =IF(AND(R29>0,AT29>0),(AT29/(R29*1000)*1000),0) -> 743.27334 | AY29: =IF(AND(S29>0,AU29>0),(AU29/(S29*1000)*1000),0) -> 660.42821 | AZ29: =+Listrik!AH28 -> 19372 | BA29: =AZ29+BA28 -> 543716.59 | BB29: =IF(AND(L29>0,AZ29>0),(AZ29/(P29*1000)*1000),0) -> 368.25397 | BC29: =IF(AND(M29>0,BA29>0),(BA29/(Q29*1000)*1000),0) -> 500.86738 | BD29: =IF(AND(R29>0,AZ29>0),(AZ29/(R29*1000)*1000),0) -> 389.14445 | BE29: =IF(AND(S29>0,BA29>0),(BA29/(S29*1000)*1000),0) -> 532.8272 | BF29: =1.037 -> 1.037 | BG29: 126.981 | BH29: =+SUM(Efficiency2!K108:K110) -> 55.510138 | BI29: =BI28+BH29 -> 1206.8897 | BJ29: =+R29/BH29 -> 0.89679114 | BK29: =+S29/BI29 -> 0.84550976
A30: =A29+1 -> 45952 | B30: Napkin/Towel | C30: 16/19/30,5 | D30: =+'22'!F42 -> 697.08333 | E30: =+'22'!G42 -> 608.47639 | F30: =1-(E30/D30) -> 0.12711098 | G30: =+P30/N30 -> 0.94982551 | H30: =+P30/L30 -> 0.94982551 | I30: =+R30/P30 -> 0.85691648 | J30: =+R30/L30 -> 0.81392114 | K30: =+S30/M30 -> 0.79454385 | L30: =+SUM(Efficiency1!K113:K115) -> 63.117909 | M30: =M29+L30 -> 1348.9627 | N30: =+SUM(Efficiency1!C113:C115) -> 63.117909 | O30: =O29+N30 -> 1340.6673 | P30: ='22'!I38 -> 59.951 | Q30: =Q29+P30 -> 1145.501 | R30: ='22'!I40 -> 51.373 | S30: =S29+R30 -> 1071.81 | T30: =R30/P30 -> 0.85691648 | U30: =S30/Q30 -> 0.9356692 | V30: =R30/L30 -> 0.81392114 | W30: =S30/M30 -> 0.79454385 | AB30: 0 | AC30: =AB30+AC29 -> 0 | AD30: =AB30/P30 -> 0 | AE30: =AC30/Q30 -> 0 | AF30: =IF(AND(R30>0,AB30>0),(AB30/(R30*1000))*1000,0) -> 0 | AG30: =IF(AND(S30>0,AC30>0),AC30/S30,0) -> 0 | AH30: =+BF30+BG30 -> 133.476 | AI30: =AH30+AI29 -> 2660.905 | AJ30: =AH30/(P30) -> 2.2264182 | AK30: =AI30/(Q30) -> 2.3229181 | AL30: =IF(AND(R30>0,AH30>0),AH30/(R30),0) -> 2.5981741 | AM30: =IF(AND(S30>0,AI30>0),AI30/(S30),0) -> 2.4826275 | AN30: 17.6 | AO30: =AN30+AO29 -> 259.2 | AP30: =AN30/(P30) -> 0.29357308 | AQ30: =AO30/(Q30) -> 0.22627654 | AR30: =IF(AND(R30>0,AN30>0),AN30/(R30),0) -> 0.34259241 | AS30: =IF(AND(S30>0,AO30>0),AO30/(S30),0) -> 0.24183391 | AT30: ='22'!I46 -> 36649.12 | AU30: =AT30+AU29 -> 710574.5 | AV30: =IF(AND(L30>0,AT30>0),(AT30/(P30*1000)*1000),0) -> 611.31791 | AW30: =IF(AND(M30>0,AU30>0),(AU30/(Q30*1000)*1000),0) -> 620.31766 | AX30: =IF(AND(R30>0,AT30>0),(AT30/(R30*1000)*1000),0) -> 713.39264 | AY30: =IF(AND(S30>0,AU30>0),(AU30/(S30*1000)*1000),0) -> 662.96685 | AZ30: =+Listrik!AH29 -> 27589 | BA30: =AZ30+BA29 -> 571305.59 | BB30: =IF(AND(L30>0,AZ30>0),(AZ30/(P30*1000)*1000),0) -> 460.19249 | BC30: =IF(AND(M30>0,BA30>0),(BA30/(Q30*1000)*1000),0) -> 498.73862 | BD30: =IF(AND(R30>0,AZ30>0),(AZ30/(R30*1000)*1000),0) -> 537.03307 | BE30: =IF(AND(S30>0,BA30>0),(BA30/(S30*1000)*1000),0) -> 533.02879 | BF30: =1.02 -> 1.02 | BG30: 132.456 | BH30: =+SUM(Efficiency2!K113:K115) -> 63.117909 | BI30: =BI29+BH30 -> 1270.0076 | BJ30: =+R30/BH30 -> 0.81392114 | BK30: =+S30/BI30 -> 0.84393984
A31: =A30+1 -> 45953 | B31: Towel | C31: 30,5 | D31: =+'23'!F42 -> 540 | E31: =+'23'!G42 -> 475.2 | F31: =1-(E31/D31) -> 0.12 | G31: =+P31/N31 -> 0.99139474 | H31: =+P31/L31 -> 0.99139474 | I31: =+R31/P31 -> 1.0339043 | J31: =+R31/L31 -> 1.0250073 | K31: =+S31/M31 -> 0.80570668 | L31: =+Efficiency1!K118 -> 68.664879 | M31: =M30+L31 -> 1417.6276 | N31: =+Efficiency1!C118 -> 68.664879 | O31: =O30+N31 -> 1409.3322 | P31: ='23'!I38 -> 68.074 | Q31: =Q30+P31 -> 1213.575 | R31: ='23'!I40 -> 70.382 | S31: =S30+R31 -> 1142.192 | T31: =R31/P31 -> 1.0339043 | U31: =S31/Q31 -> 0.94117957 | V31: =R31/L31 -> 1.0250073 | W31: =S31/M31 -> 0.80570668 | AB31: 0 | AC31: =AB31+AC30 -> 0 | AD31: =AB31/P31 -> 0 | AE31: =AC31/Q31 -> 0 | AF31: =IF(AND(R31>0,AB31>0),(AB31/(R31*1000))*1000,0) -> 0 | AG31: =IF(AND(S31>0,AC31>0),AC31/S31,0) -> 0 | AH31: =+BF31+BG31 -> 140.747 | AI31: =AH31+AI30 -> 2801.652 | AJ31: =AH31/(P31) -> 2.0675588 | AK31: =AI31/(Q31) -> 2.308594 | AL31: =IF(AND(R31>0,AH31>0),AH31/(R31),0) -> 1.9997585 | AM31: =IF(AND(S31>0,AI31>0),AI31/(S31),0) -> 2.4528731 | AN31: 16.8 | AO31: =AN31+AO30 -> 276 | AP31: =AN31/(P31) -> 0.24679026 | AQ31: =AO31/(Q31) -> 0.22742723 | AR31: =IF(AND(R31>0,AN31>0),AN31/(R31),0) -> 0.23869739 | AS31: =IF(AND(S31>0,AO31>0),AO31/(S31),0) -> 0.24164063 | AT31: ='23'!I46 -> 36655.41 | AU31: =AT31+AU30 -> 747229.91 | AV31: =IF(AND(L31>0,AT31>0),(AT31/(P31*1000)*1000),0) -> 538.46417 | AW31: =IF(AND(M31>0,AU31>0),(AU31/(Q31*1000)*1000),0) -> 615.72619 | AX31: =IF(AND(R31>0,AT31>0),(AT31/(R31*1000)*1000),0) -> 520.8066 | AY31: =IF(AND(S31>0,AU31>0),(AU31/(S31*1000)*1000),0) -> 654.20692 | AZ31: =+Listrik!AH30 -> 26268 | BA31: =AZ31+BA30 -> 597573.59 | BB31: =IF(AND(L31>0,AZ31>0),(AZ31/(P31*1000)*1000),0) -> 385.8742 | BC31: =IF(AND(M31>0,BA31>0),(BA31/(Q31*1000)*1000),0) -> 492.40763 | BD31: =IF(AND(R31>0,AZ31>0),(AZ31/(R31*1000)*1000),0) -> 373.22043 | BE31: =IF(AND(S31>0,BA31>0),(BA31/(S31*1000)*1000),0) -> 523.18138 | BF31: =2.512 -> 2.512 | BG31: 138.235 | BH31: =+Efficiency2!K118 -> 68.664879 | BI31: =BI30+BH31 -> 1338.6725 | BJ31: =+R31/BH31 -> 1.0250073 | BK31: =+S31/BI31 -> 0.85322738
A32: =A31+1 -> 45954 | B32: Towel | C32: 30,5/34 | D32: =+'24'!F42 -> 501.52778 | E32: =+'24'!G42 -> 441.34444 | F32: =1-(E32/D32) -> 0.12 | G32: =+P32/N32 -> 0.99596315 | H32: =+P32/L32 -> 0.99596315 | I32: =+R32/P32 -> 0.98853306 | J32: =+R32/L32 -> 0.98454249 | K32: =+S32/M32 -> 0.81418748 | L32: =+SUM(Efficiency1!K122:K123) -> 70.573896 | M32: =M31+L32 -> 1488.2015 | N32: =+SUM(Efficiency1!C122:C123) -> 70.573896 | O32: =O31+N32 -> 1479.906 | P32: ='24'!I38 -> 70.289 | Q32: =Q31+P32 -> 1283.864 | R32: ='24'!I40 -> 69.483 | S32: =S31+R32 -> 1211.675 | T32: =R32/P32 -> 0.98853306 | U32: =S32/Q32 -> 0.94377208 | V32: =R32/L32 -> 0.98454249 | W32: =S32/M32 -> 0.81418748 | AB32: 0 | AC32: =AB32+AC31 -> 0 | AD32: =AB32/P32 -> 0 | AE32: =AC32/Q32 -> 0 | AF32: =IF(AND(R32>0,AB32>0),(AB32/(R32*1000))*1000,0) -> 0 | AG32: =IF(AND(S32>0,AC32>0),AC32/S32,0) -> 0 | AH32: =+BF32+BG32 -> 128.811 | AI32: =AH32+AI31 -> 2930.463 | AJ32: =AH32/(P32) -> 1.8325912 | AK32: =AI32/(Q32) -> 2.2825338 | AL32: =IF(AND(R32>0,AH32>0),AH32/(R32),0) -> 1.8538491 | AM32: =IF(AND(S32>0,AI32>0),AI32/(S32),0) -> 2.4185223 | AN32: 18.4 | AO32: =AN32+AO31 -> 294.4 | AP32: =AN32/(P32) -> 0.26177638 | AQ32: =AO32/(Q32) -> 0.22930778 | AR32: =IF(AND(R32>0,AN32>0),AN32/(R32),0) -> 0.26481298 | AS32: =IF(AND(S32>0,AO32>0),AO32/(S32),0) -> 0.24296944 | AT32: =+'24'!I46 -> 32248.19 | AU32: =AT32+AU31 -> 779478.1 | AV32: =IF(AND(L32>0,AT32>0),(AT32/(P32*1000)*1000),0) -> 458.79426 | AW32: =IF(AND(M32>0,AU32>0),(AU32/(Q32*1000)*1000),0) -> 607.13448 | AX32: =IF(AND(R32>0,AT32>0),(AT32/(R32*1000)*1000),0) -> 464.11626 | AY32: =IF(AND(S32>0,AU32>0),(AU32/(S32*1000)*1000),0) -> 643.30625 | AZ32: =+Listrik!AH31 -> 28009 | BA32: =AZ32+BA31 -> 625582.59 | BB32: =IF(AND(L32>0,AZ32>0),(AZ32/(P32*1000)*1000),0) -> 398.4834 | BC32: =IF(AND(M32>0,BA32>0),(BA32/(Q32*1000)*1000),0) -> 487.26546 | BD32: =IF(AND(R32>0,AZ32>0),(AZ32/(R32*1000)*1000),0) -> 403.1058 | BE32: =IF(AND(S32>0,BA32>0),(BA32/(S32*1000)*1000),0) -> 516.2957 | BF32: =2.442 -> 2.442 | BG32: 126.369 | BH32: =+SUM(Efficiency2!K122:K123) -> 70.573896 | BI32: =BI31+BH32 -> 1409.2464 | BJ32: =+R32/BH32 -> 0.98454249 | BK32: =+S32/BI32 -> 0.85980354
A33: =A32+1 -> 45955 | B33: Towel | C33: 34 | D33: =+'25'!F42 -> 490 | E33: =+'25'!G42 -> 431.2 | F33: =1-(E33/D33) -> 0.12 | G33: =+P33/N33 -> 0.97537631 | H33: =+P33/L33 -> 0.97537631 | I33: =+R33/P33 -> 0.99975676 | J33: =+R33/L33 -> 0.97513906 | K33: =+S33/M33 -> 0.8211651 | L33: =+Efficiency1!K127 -> 67.440637 | M33: =M32+L33 -> 1555.6421 | N33: =+Efficiency1!C127 -> 67.440637 | O33: =O32+N33 -> 1547.3467 | P33: ='25'!I38 -> 65.78 | Q33: =Q32+P33 -> 1349.644 | R33: ='25'!I40 -> 65.764 | S33: =S32+R33 -> 1277.439 | T33: =R33/P33 -> 0.99975676 | U33: =S33/Q33 -> 0.94650071 | V33: =R33/L33 -> 0.97513906 | W33: =S33/M33 -> 0.8211651 | AB33: 0 | AC33: =AB33+AC32 -> 0 | AD33: =AB33/P33 -> 0 | AE33: =AC33/Q33 -> 0 | AF33: =IF(AND(R33>0,AB33>0),(AB33/(R33*1000))*1000,0) -> 0 | AG33: =IF(AND(S33>0,AC33>0),AC33/S33,0) -> 0 | AH33: =+BF33+BG33 -> 124.761 | AI33: =AH33+AI32 -> 3055.224 | AJ33: =AH33/(P33) -> 1.8966403 | AK33: =AI33/(Q33) -> 2.2637258 | AL33: =IF(AND(R33>0,AH33>0),AH33/(R33),0) -> 1.8971018 | AM33: =IF(AND(S33>0,AI33>0),AI33/(S33),0) -> 2.391679 | AN33: 19.2 | AO33: =AN33+AO32 -> 313.6 | AP33: =AN33/(P33) -> 0.29188203 | AQ33: =AO33/(Q33) -> 0.23235757 | AR33: =IF(AND(R33>0,AN33>0),AN33/(R33),0) -> 0.29195304 | AS33: =IF(AND(S33>0,AO33>0),AO33/(S33),0) -> 0.24549117 | AT33: =+'25'!I46 -> 30996.16 | AU33: =AT33+AU32 -> 810474.26 | AV33: =IF(AND(L33>0,AT33>0),(AT33/(P33*1000)*1000),0) -> 471.20949 | AW33: =IF(AND(M33>0,AU33>0),(AU33/(Q33*1000)*1000),0) -> 600.50966 | AX33: =IF(AND(R33>0,AT33>0),(AT33/(R33*1000)*1000),0) -> 471.32413 | AY33: =IF(AND(S33>0,AU33>0),(AU33/(S33*1000)*1000),0) -> 634.45242 | AZ33: =+Listrik!AH32 -> 29470 | BA33: =AZ33+BA32 -> 655052.59 | BB33: =IF(AND(L33>0,AZ33>0),(AZ33/(P33*1000)*1000),0) -> 448.00851 | BC33: =IF(AND(M33>0,BA33>0),(BA33/(Q33*1000)*1000),0) -> 485.35213 | BD33: =IF(AND(R33>0,AZ33>0),(AZ33/(R33*1000)*1000),0) -> 448.11751 | BE33: =IF(AND(S33>0,BA33>0),(BA33/(S33*1000)*1000),0) -> 512.78581 | BF33: =2.56 -> 2.56 | BG33: 122.201 | BH33: =+Efficiency2!K127 -> 67.440637 | BI33: =BI32+BH33 -> 1476.687 | BJ33: =+R33/BH33 -> 0.97513906 | BK33: =+S33/BI33 -> 0.86507094
A34: =A33+1 -> 45956 | B34: Towel | C34: 34/36 | D34: =+'26'!F42 -> 479.27083 | E34: =+'26'!G42 -> 421.75833 | F34: =1-(E34/D34) -> 0.12 | G34: =+P34/N34 -> 0.97829542 | H34: =+P34/L34 -> 0.97829542 | I34: =+R34/P34 -> 1.0015442 | J34: =+R34/L34 -> 0.97980613 | K34: =+S34/M34 -> 0.82770201 | L34: =+SUM(Efficiency1!K131:K132) -> 66.856083 | M34: =M33+L34 -> 1622.4982 | N34: =+SUM(Efficiency1!C131:C132) -> 66.856083 | O34: =O33+N34 -> 1614.2028 | P34: ='26'!I38 -> 65.405 | Q34: =Q33+P34 -> 1415.049 | R34: ='26'!I40 -> 65.506 | S34: =S33+R34 -> 1342.945 | T34: =R34/P34 -> 1.0015442 | U34: =S34/Q34 -> 0.94904487 | V34: =R34/L34 -> 0.97980613 | W34: =S34/M34 -> 0.82770201 | AB34: 0 | AC34: =AB34+AC33 -> 0 | AD34: =AB34/P34 -> 0 | AE34: =AC34/Q34 -> 0 | AF34: =IF(AND(R34>0,AB34>0),(AB34/(R34*1000))*1000,0) -> 0 | AG34: =IF(AND(S34>0,AC34>0),AC34/S34,0) -> 0 | AH34: =+BF34+BG34 -> 124.25 | AI34: =AH34+AI33 -> 3179.474 | AJ34: =AH34/(P34) -> 1.8997019 | AK34: =AI34/(Q34) -> 2.2469003 | AL34: =IF(AND(R34>0,AH34>0),AH34/(R34),0) -> 1.8967728 | AM34: =IF(AND(S34>0,AI34>0),AI34/(S34),0) -> 2.3675385 | AN34: 12.8 | AO34: =AN34+AO33 -> 326.4 | AP34: =AN34/(P34) -> 0.19570369 | AQ34: =AO34/(Q34) -> 0.23066339 | AR34: =IF(AND(R34>0,AN34>0),AN34/(R34),0) -> 0.19540195 | AS34: =IF(AND(S34>0,AO34>0),AO34/(S34),0) -> 0.24304793 | AT34: ='26'!I46 -> 32689.73 | AU34: =AT34+AU33 -> 843163.99 | AV34: =IF(AND(L34>0,AT34>0),(AT34/(P34*1000)*1000),0) -> 499.80475 | AW34: =IF(AND(M34>0,AU34>0),(AU34/(Q34*1000)*1000),0) -> 595.85498 | AX34: =IF(AND(R34>0,AT34>0),(AT34/(R34*1000)*1000),0) -> 499.03413 | AY34: =IF(AND(S34>0,AU34>0),(AU34/(S34*1000)*1000),0) -> 627.847 | AZ34: =+Listrik!AH33 -> 20119 | BA34: =AZ34+BA33 -> 675171.59 | BB34: =IF(AND(L34>0,AZ34>0),(AZ34/(P34*1000)*1000),0) -> 307.60645 | BC34: =IF(AND(M34>0,BA34>0),(BA34/(Q34*1000)*1000),0) -> 477.13654 | BD34: =IF(AND(R34>0,AZ34>0),(AZ34/(R34*1000)*1000),0) -> 307.13217 | BE34: =IF(AND(S34>0,BA34>0),(BA34/(S34*1000)*1000),0) -> 502.75446 | BF34: =1.676 -> 1.676 | BG34: 122.574 | BH34: =+SUM(Efficiency2!K131:K132) -> 67.513665 | BI34: =BI33+BH34 -> 1544.2007 | BJ34: =+R34/BH34 -> 0.97026284 | BK34: =+S34/BI34 -> 0.86967001
A35: =A34+1 -> 45957 | B35: Towel | C35: 36 | D35: =+'27'!F42 -> 450 | E35: =+'27'!G42 -> 396 | F35: =1-(E35/D35) -> 0.12 | G35: =+P35/N35 -> 0.91540652 | H35: =+P35/L35 -> 0.90534711 | I35: =+R35/P35 -> 1.0030626 | J35: =+R35/L35 -> 0.90811978 | K35: =+S35/M35 -> 0.83081241 | L35: =+Efficiency1!K136 -> 65.279935 | M35: =M34+L35 -> 1687.7781 | N35: =+Efficiency1!C136 -> 64.562573 | O35: =O34+N35 -> 1678.7653 | P35: ='27'!I38 -> 59.101 | Q35: =Q34+P35 -> 1474.15 | R35: ='27'!I40 -> 59.282 | S35: =S34+R35 -> 1402.227 | T35: =R35/P35 -> 1.0030626 | U35: =S35/Q35 -> 0.95121053 | V35: =R35/L35 -> 0.90811978 | W35: =S35/M35 -> 0.83081241 | AB35: 0 | AC35: =AB35+AC34 -> 0 | AD35: =AB35/P35 -> 0 | AE35: =AC35/Q35 -> 0 | AF35: =IF(AND(R35>0,AB35>0),(AB35/(R35*1000))*1000,0) -> 0 | AG35: =IF(AND(S35>0,AC35>0),AC35/S35,0) -> 0 | AH35: =+BF35+BG35 -> 113.839 | AI35: =AH35+AI34 -> 3293.313 | AJ35: =AH35/(P35) -> 1.9261772 | AK35: =AI35/(Q35) -> 2.234042 | AL35: =IF(AND(R35>0,AH35>0),AH35/(R35),0) -> 1.9202962 | AM35: =IF(AND(S35>0,AI35>0),AI35/(S35),0) -> 2.3486304 | AN35: 19.2 | AO35: =AN35+AO34 -> 345.6 | AP35: =AN35/(P35) -> 0.3248676 | AQ35: =AO35/(Q35) -> 0.23444019 | AR35: =IF(AND(R35>0,AN35>0),AN35/(R35),0) -> 0.32387571 | AS35: =IF(AND(S35>0,AO35>0),AO35/(S35),0) -> 0.24646509 | AT35: ='27'!I46 -> 29322.03 | AU35: =AT35+AU34 -> 872486.02 | AV35: =IF(AND(L35>0,AT35>0),(AT35/(P35*1000)*1000),0) -> 496.13424 | AW35: =IF(AND(M35>0,AU35>0),(AU35/(Q35*1000)*1000),0) -> 591.85702 | AX35: =IF(AND(R35>0,AT35>0),(AT35/(R35*1000)*1000),0) -> 494.61945 | AY35: =IF(AND(S35>0,AU35>0),(AU35/(S35*1000)*1000),0) -> 622.21453 | AZ35: =+Listrik!AH34 -> 28867 | BA35: =AZ35+BA34 -> 704038.59 | BB35: =IF(AND(L35>0,AZ35>0),(AZ35/(P35*1000)*1000),0) -> 488.43505 | BC35: =IF(AND(M35>0,BA35>0),(BA35/(Q35*1000)*1000),0) -> 477.58952 | BD35: =IF(AND(R35>0,AZ35>0),(AZ35/(R35*1000)*1000),0) -> 486.94376 | BE35: =IF(AND(S35>0,BA35>0),(BA35/(S35*1000)*1000),0) -> 502.08603 | BF35: =2.107 -> 2.107 | BG35: 111.732 | BH35: =+Efficiency2!K136 -> 65.279935 | BI35: =BI34+BH35 -> 1609.4806 | BJ35: =+R35/BH35 -> 0.90811978 | BK35: =+S35/BI35 -> 0.87122952
