Workbook

Sheet Report1
A3: PAPER MACHINE 15 DAILY REPORT 1
A6: DATE | B6: GRADE | C6: GSM | D6: Speed yankee (mpm) | E6: Speed reel (mpm) | F6: Creep ( % ) | G6: Real Eff PM ( % ) | H6: Real Eff PM vs Target (%) | I6: Real Eff FG vs Real Eff PM (%) | J6: Eff FG vs Target (%) | L6: Kapasitas Target (ton) | N6: Kapasitas Teori Real (ton) | P6: PM PROD Timbangan (TON) | R6: FINSHED GOODS (TON) | T6: NET GROSS (Timbangan) (%) | V6: NET GROSS ( Scanner) (%) | X6: FRESH WATER | AB6: GAS HOOD | AH6: STEAM (TON) | AN6: STEAM (TON) DEINKING | AT6: POWER (kWh) | AZ6: POWER (kWh) DEINKING | BF6: POWER WPL (kWh) | BL6: Kapasitas Running (ton) | BN6: Eff FG vs Target Running(%)
X7: CONSUMPTION | Z7: /TON FG. | AB7: CONSUMPTION | AD7: /TON PM. | AF7: /TON FG. | AH7: CONSUMPTION | AJ7: /TON PM. | AL7: /TON FG. | AN7: CONSUMPTION | AP7: /TON PM. | AR7: /TON FG. | AT7: CONSUMPTION | AV7: /TON PM | AX7: /TON FG | AZ7: CONSUMPTION | BB7: /TON PM | BD7: /TON FG | BF7: CONSUMPTION | BH7: /TON PM | BJ7: /TON FG
J8: TODAY | K8: TODATE | L8: TODAY | M8: TODATE | N8: TODAY | O8: TODATE | P8: TODAY | Q8: TODATE | R8: TODAY | S8: TODATE | T8: TODAY | U8: TODATE | V8: TODAY | W8: TODATE | X8: TODAY | Y8: TODATE | Z8: TODAY | AA8: TODATE | AB8: TODAY | AC8: TODATE | AD8: TODAY | AE8: TODATE | AF8: TODAY | AG8: TODATE | AH8: TODAY | AI8: TODATE | AJ8: TODAY | AK8: TODATE | AL8: TODAY | AM8: TODATE | AN8: TODAY | AO8: TODATE | AP8: TODAY | AQ8: TODATE | AR8: TODAY | AS8: TODATE | AT8: TODAY | AU8: TODATE | AV8: TODAY | AW8: TODATE | AX8: TODAY | AY8: TODATE | AZ8: TODAY | BA8: TODATE | BB8: TODAY | BC8: TODATE | BD8: TODAY | BE8: TODATE | BF8: TODAY | BG8: TODATE | BH8: TODAY | BI8: TODATE | BJ8: TODAY | BK8: TODATE | BL8: TODAY | BM8: TODATE | BN8: TODAY | BO8: TODATE
A9: 46023 | B9: Toilet | C9: 13,5 | D9: =+'1'!F42 -> 1226.3498 | E9: =+'1'!G42 -> 963.19392 | F9: =1-(E9/D9) -> 0.21458469 | G9: =+P9/N9 -> 0.86663364 | H9: =+P9/L9 -> 0.81129466 | I9: =+R9/P9 -> 0.99110364 | J9: =+R9/L9 -> 0.80407709 | K9: =+S9/M9 -> 0.80407709 | L9: =+Efficiency1!K6 -> 55.004676 | M9: =L9 -> 55.004676 | N9: =+Efficiency1!C6 -> 51.492347 | O9: =N9 -> 51.492347 | P9: ='1'!I38 -> 44.625 | Q9: =P9 -> 44.625 | R9: ='1'!I40 -> 44.228 | S9: =R9 -> 44.228 | T9: =R9/P9 -> 0.99110364 | U9: =S9/Q9 -> 0.99110364 | V9: =R9/L9 -> 0.80407709 | W9: =S9/M9 -> 0.80407709 | AB9: =+[1]Report1!AY9 -> 4609.7934 | AC9: =AB9 -> 4609.7934 | AD9: =AB9/P9 -> 103.30069 | AE9: =AC9/Q9 -> 103.30069 | AF9: =IF(AND(R9>0,AB9>0),(AB9/(R9*1000))*1000,0) -> 104.22794 | AG9: =IF(AND(S9>0,AC9>0),AC9/S9,0) -> 104.22794 | AH9: 62.5 | AI9: =AH9 -> 62.5 | AJ9: =AH9/(P9) -> 1.4005602 | AK9: =AI9/(Q9) -> 1.4005602 | AL9: =IF(AND(R9>0,AH9>0),AH9/(R9),0) -> 1.413132 | AM9: =IF(AND(S9>0,AI9>0),AI9/(S9),0) -> 1.413132 | AN9: 4.9 | AO9: =AN9 -> 4.9 | AP9: =AN9/(P9) -> 0.10980392 | AQ9: =AO9/(Q9) -> 0.10980392 | AR9: =IF(AND(R9>0,AN9>0),AN9/(R9),0) -> 0.11078955 | AS9: =IF(AND(S9>0,AO9>0),AO9/(S9),0) -> 0.11078955 | AT9: ='1'!I46 -> 38371.28 | AU9: =AT9 -> 38371.28 | AV9: =IF(AND(L9>0,AT9>0),(AT9/(P9*1000)*1000),0) -> 859.86062 | AW9: =IF(AND(M9>0,AU9>0),(AU9/(Q9*1000)*1000),0) -> 859.86062 | AX9: =IF(AND(R9>0,AT9>0),(AT9/(R9*1000)*1000),0) -> 867.57891 | AY9: =IF(AND(S9>0,AU9>0),(AU9/(S9*1000)*1000),0) -> 867.57891 | AZ9: =+Listrik!S8 -> 25320 | BA9: =AZ9 -> 25320 | BB9: =IF(AND(L9>0,AZ9>0),(AZ9/(P9*1000)*1000),0) -> 567.39496 | BC9: =IF(AND(M9>0,BA9>0),(BA9/(Q9*1000)*1000),0) -> 567.39496 | BD9: =IF(AND(R9>0,AZ9>0),(AZ9/(R9*1000)*1000),0) -> 572.48802 | BE9: =IF(AND(S9>0,BA9>0),(BA9/(S9*1000)*1000),0) -> 572.48802 | BF9: =+Listrik!V8 -> 139.8 | BG9: =BF9 -> 139.8 | BH9: =IF(AND(L9>0,BF9>0),(BF9/(P9*1000)*1000),0) -> 3.1327731 | BI9: =IF(AND(M9>0,BG9>0),(BG9/(Q9*1000)*1000),0) -> 3.1327731 | BJ9: =IF(AND(R9>0,BF9>0),(BF9/(R9*1000)*1000),0) -> 3.1608936 | BK9: =IF(AND(S9>0,BG9>0),(BG9/(S9*1000)*1000),0) -> 3.1608936 | BL9: =+Efficiency2!K6 -> 55.004676 | BM9: =BL9 -> 55.004676 | BN9: =+R9/BL9 -> 0.80407709 | BO9: =+S9/BM9 -> 0.80407709
A10: =A9+1 -> 46024 | B10: Toilet | C10: 13,5 | D10: =+'2'!F42 -> 1250 | E10: =+'2'!G42 -> 975 | F10: =1-(E10/D10) -> 0.22 | G10: =+P10/N10 -> 0.95373488 | H10: =+P10/L10 -> 0.90315803 | I10: =+R10/P10 -> 0.93325555 | J10: =+R10/L10 -> 0.84287725 | K10: =+S10/M10 -> 0.82348382 | L10: =+Efficiency1!K12 -> 55.042416 | M10: =M9+L10 -> 110.04709 | N10: =+Efficiency1!C12 -> 52.1235 | O10: =O9+N10 -> 103.61585 | P10: ='2'!I38 -> 49.712 | Q10: =Q9+P10 -> 94.337 | R10: ='2'!I40 -> 46.394 | S10: =S9+R10 -> 90.622 | T10: =R10/P10 -> 0.93325555 | U10: =S10/Q10 -> 0.96061991 | V10: =R10/L10 -> 0.84287725 | W10: =S10/M10 -> 0.82348382 | AB10: =+[1]Report1!AY10 -> 5215.6722 | AC10: =AB10+AC9 -> 9825.4656 | AD10: =AB10/P10 -> 104.91777 | AE10: =AC10/Q10 -> 104.15283 | AF10: =IF(AND(R10>0,AB10>0),(AB10/(R10*1000))*1000,0) -> 112.42127 | AG10: =IF(AND(S10>0,AC10>0),AC10/S10,0) -> 108.42252 | AH10: 65.4 | AI10: =AH10+AI9 -> 127.9 | AJ10: =AH10/(P10) -> 1.3155777 | AK10: =AI10/(Q10) -> 1.3557777 | AL10: =IF(AND(R10>0,AH10>0),AH10/(R10),0) -> 1.409665 | AM10: =IF(AND(S10>0,AI10>0),AI10/(S10),0) -> 1.4113571 | AN10: 4.1 | AO10: =AN10+AO9 -> 9 | AP10: =AN10/(P10) -> 0.082475056 | AQ10: =AO10/(Q10) -> 0.095402652 | AR10: =IF(AND(R10>0,AN10>0),AN10/(R10),0) -> 0.088373497 | AS10: =IF(AND(S10>0,AO10>0),AO10/(S10),0) -> 0.099313632 | AT10: ='2'!I46 -> 43610.8 | AU10: =AT10+AU9 -> 81982.08 | AV10: =IF(AND(L10>0,AT10>0),(AT10/(P10*1000)*1000),0) -> 877.26907 | AW10: =IF(AND(M10>0,AU10>0),(AU10/(Q10*1000)*1000),0) -> 869.03421 | AX10: =IF(AND(R10>0,AT10>0),(AT10/(R10*1000)*1000),0) -> 940.00948 | AY10: =IF(AND(S10>0,AU10>0),(AU10/(S10*1000)*1000),0) -> 904.6598 | AZ10: =+Listrik!S9 -> 26780 | BA10: =AZ10+BA9 -> 52100 | BB10: =IF(AND(L10>0,AZ10>0),(AZ10/(P10*1000)*1000),0) -> 538.70293 | BC10: =IF(AND(M10>0,BA10>0),(BA10/(Q10*1000)*1000),0) -> 552.27535 | BD10: =IF(AND(R10>0,AZ10>0),(AZ10/(R10*1000)*1000),0) -> 577.22981 | BE10: =IF(AND(S10>0,BA10>0),(BA10/(S10*1000)*1000),0) -> 574.91558 | BF10: =+Listrik!V9 -> 1120.1 | BG10: =BF10+BG9 -> 1259.9 | BH10: =IF(AND(L10>0,BF10>0),(BF10/(P10*1000)*1000),0) -> 22.531783 | BI10: =IF(AND(M10>0,BG10>0),(BG10/(Q10*1000)*1000),0) -> 13.355311 | BJ10: =IF(AND(R10>0,BF10>0),(BF10/(R10*1000)*1000),0) -> 24.143208 | BK10: =IF(AND(S10>0,BG10>0),(BG10/(S10*1000)*1000),0) -> 13.902805 | BL10: =+Efficiency2!K12 -> 55.042416 | BM10: =BM9+BL10 -> 110.04709 | BN10: =+R10/BL10 -> 0.84287725 | BO10: =+S10/BM10 -> 0.82348382
A11: =A10+1 -> 46025 | B11: Toilet | C11: 13,5 | D11: =+'3'!F42 -> 1260 | E11: =+'3'!G42 -> 982.8 | F11: =1-(E11/D11) -> 0.22 | G11: =+P11/N11 -> 0.81649413 | H11: =+P11/L11 -> 0.77938076 | I11: =+R11/P11 -> 1.0028206 | J11: =+R11/L11 -> 0.78157906 | K11: =+S11/M11 -> 0.80951238 | L11: =+Efficiency1!K17 -> 55.042416 | M11: =M10+L11 -> 165.08951 | N11: =+Efficiency1!C17 -> 52.540488 | O11: =O10+N11 -> 156.15633 | P11: ='3'!I38 -> 42.899 | Q11: =Q10+P11 -> 137.236 | R11: ='3'!I40 -> 43.02 | S11: =S10+R11 -> 133.642 | T11: =R11/P11 -> 1.0028206 | U11: =S11/Q11 -> 0.97381154 | V11: =R11/L11 -> 0.78157906 | W11: =S11/M11 -> 0.80951238 | AB11: =+[1]Report1!AY11 -> 4809.878 | AC11: =AB11+AC10 -> 14635.344 | AD11: =AB11/P11 -> 112.12098 | AE11: =AC11/Q11 -> 106.64362 | AF11: =IF(AND(R11>0,AB11>0),(AB11/(R11*1000))*1000,0) -> 111.80563 | AG11: =IF(AND(S11>0,AC11>0),AC11/S11,0) -> 109.51156 | AH11: 62.2 | AI11: =AH11+AI10 -> 190.1 | AJ11: =AH11/(P11) -> 1.4499172 | AK11: =AI11/(Q11) -> 1.385205 | AL11: =IF(AND(R11>0,AH11>0),AH11/(R11),0) -> 1.4458391 | AM11: =IF(AND(S11>0,AI11>0),AI11/(S11),0) -> 1.422457 | AN11: 0 | AO11: =AN11+AO10 -> 9 | AP11: =AN11/(P11) -> 0 | AQ11: =AO11/(Q11) -> 0.06558046 | AR11: =IF(AND(R11>0,AN11>0),AN11/(R11),0) -> 0 | AS11: =IF(AND(S11>0,AO11>0),AO11/(S11),0) -> 0.067344098 | AT11: ='3'!I46 -> 39396.56 | AU11: =AT11+AU10 -> 121378.64 | AV11: =IF(AND(L11>0,AT11>0),(AT11/(P11*1000)*1000),0) -> 918.35614 | AW11: =IF(AND(M11>0,AU11>0),(AU11/(Q11*1000)*1000),0) -> 884.45189 | AX11: =IF(AND(R11>0,AT11>0),(AT11/(R11*1000)*1000),0) -> 915.77313 | AY11: =IF(AND(S11>0,AU11>0),(AU11/(S11*1000)*1000),0) -> 908.23723 | AZ11: =+Listrik!S10 -> 25570 | BA11: =AZ11+BA10 -> 77670 | BB11: =IF(AND(L11>0,AZ11>0),(AZ11/(P11*1000)*1000),0) -> 596.05119 | BC11: =IF(AND(M11>0,BA11>0),(BA11/(Q11*1000)*1000),0) -> 565.95937 | BD11: =IF(AND(R11>0,AZ11>0),(AZ11/(R11*1000)*1000),0) -> 594.37471 | BE11: =IF(AND(S11>0,BA11>0),(BA11/(S11*1000)*1000),0) -> 581.17957 | BF11: =+Listrik!V10 -> 1200.1 | BG11: =BF11+BG10 -> 2460 | BH11: =IF(AND(L11>0,BF11>0),(BF11/(P11*1000)*1000),0) -> 27.975011 | BI11: =IF(AND(M11>0,BG11>0),(BG11/(Q11*1000)*1000),0) -> 17.925326 | BJ11: =IF(AND(R11>0,BF11>0),(BF11/(R11*1000)*1000),0) -> 27.896327 | BK11: =IF(AND(S11>0,BG11>0),(BG11/(S11*1000)*1000),0) -> 18.407387 | BL11: =+Efficiency2!K17 -> 55.042416 | BM11: =BM10+BL11 -> 165.08951 | BN11: =+R11/BL11 -> 0.78157906 | BO11: =+S11/BM11 -> 0.80951238
A12: =A11+1 -> 46026 | B12: Toilet | C12: 13,5/14,5 | D12: =+'4'!F42 -> 1225.1153 | E12: =+'4'!G42 -> 964.61585 | F12: =1-(E12/D12) -> 0.21263258 | G12: =+P12/N12 -> 0.90082657 | H12: =+P12/L12 -> 0.85521164 | I12: =+R12/P12 -> 1.0254029 | J12: =+R12/L12 -> 0.87693647 | K12: =+S12/M12 -> 0.82627821 | L12: =+SUM(Efficiency1!K23:K24) -> 54.637938 | M12: =M11+L12 -> 219.72745 | N12: =+SUM(Efficiency1!C23:C24) -> 51.87125 | O12: =O11+N12 -> 208.02758 | P12: ='4'!I38 -> 46.727 | Q12: =Q11+P12 -> 183.963 | R12: ='4'!I40 -> 47.914 | S12: =S11+R12 -> 181.556 | T12: =R12/P12 -> 1.0254029 | U12: =S12/Q12 -> 0.98691585 | V12: =R12/L12 -> 0.87693647 | W12: =S12/M12 -> 0.82627821 | AB12: =+[1]Report1!AY12 -> 4954.3705 | AC12: =AB12+AC11 -> 19589.714 | AD12: =AB12/P12 -> 106.028 | AE12: =AC12/Q12 -> 106.48725 | AF12: =IF(AND(R12>0,AB12>0),(AB12/(R12*1000))*1000,0) -> 103.40131 | AG12: =IF(AND(S12>0,AC12>0),AC12/S12,0) -> 107.89902 | AH12: 66.5 | AI12: =AH12+AI11 -> 256.6 | AJ12: =AH12/(P12) -> 1.4231601 | AK12: =AI12/(Q12) -> 1.3948457 | AL12: =IF(AND(R12>0,AH12>0),AH12/(R12),0) -> 1.3879033 | AM12: =IF(AND(S12>0,AI12>0),AI12/(S12),0) -> 1.413338 | AN12: 0 | AO12: =AN12+AO11 -> 9 | AP12: =AN12/(P12) -> 0 | AQ12: =AO12/(Q12) -> 0.048922881 | AR12: =IF(AND(R12>0,AN12>0),AN12/(R12),0) -> 0 | AS12: =IF(AND(S12>0,AO12>0),AO12/(S12),0) -> 0.049571482 | AT12: ='4'!I46 -> 42217 | AU12: =AT12+AU11 -> 163595.64 | AV12: =IF(AND(L12>0,AT12>0),(AT12/(P12*1000)*1000),0) -> 903.48193 | AW12: =IF(AND(M12>0,AU12>0),(AU12/(Q12*1000)*1000),0) -> 889.28556 | AX12: =IF(AND(R12>0,AT12>0),(AT12/(R12*1000)*1000),0) -> 881.09947 | AY12: =IF(AND(S12>0,AU12>0),(AU12/(S12*1000)*1000),0) -> 901.07537 | AZ12: =+Listrik!S11 -> 25340 | BA12: =AZ12+BA11 -> 103010 | BB12: =IF(AND(L12>0,AZ12>0),(AZ12/(P12*1000)*1000),0) -> 542.29889 | BC12: =IF(AND(M12>0,BA12>0),(BA12/(Q12*1000)*1000),0) -> 559.94956 | BD12: =IF(AND(R12>0,AZ12>0),(AZ12/(R12*1000)*1000),0) -> 528.86422 | BE12: =IF(AND(S12>0,BA12>0),(BA12/(S12*1000)*1000),0) -> 567.37315 | BF12: =+Listrik!V11 -> 1259.8 | BG12: =BF12+BG11 -> 3719.8 | BH12: =IF(AND(L12>0,BF12>0),(BF12/(P12*1000)*1000),0) -> 26.960858 | BI12: =IF(AND(M12>0,BG12>0),(BG12/(Q12*1000)*1000),0) -> 20.22037 | BJ12: =IF(AND(R12>0,BF12>0),(BF12/(R12*1000)*1000),0) -> 26.292942 | BK12: =IF(AND(S12>0,BG12>0),(BG12/(S12*1000)*1000),0) -> 20.488444 | BL12: =+SUM(Efficiency2!K23:K24) -> 54.637938 | BM12: =BM11+BL12 -> 219.72745 | BN12: =+R12/BL12 -> 0.87693647 | BO12: =+S12/BM12 -> 0.82627821
A13: =A12+1 -> 46027 | B13: Toilet | C13: 14,5 | D13: =+'5'!F42 -> 1136.6667 | E13: =+'5'!G42 -> 932.06667 | F13: =1-(E13/D13) -> 0.18 | G13: =+P13/N13 -> 0.99313921 | H13: =+P13/L13 -> 0.96484464 | I13: =+R13/P13 -> 0.95039784 | J13: =+R13/L13 -> 0.91698626 | K13: =+S13/M13 -> 0.84387502 | L13: =+Efficiency1!K29 -> 52.885198 | M13: =M12+L13 -> 272.61264 | N13: =+Efficiency1!C29 -> 51.378497 | O13: =O12+N13 -> 259.40608 | P13: ='5'!I38 -> 51.026 | Q13: =Q12+P13 -> 234.989 | R13: ='5'!I40 -> 48.495 | S13: =S12+R13 -> 230.051 | T13: =R13/P13 -> 0.95039784 | U13: =S13/Q13 -> 0.97898625 | V13: =R13/L13 -> 0.91698626 | W13: =S13/M13 -> 0.84387502 | AB13: =+[1]Report1!AY13 -> 5248.7084 | AC13: =AB13+AC12 -> 24838.423 | AD13: =AB13/P13 -> 102.86341 | AE13: =AC13/Q13 -> 105.70036 | AF13: =IF(AND(R13>0,AB13>0),(AB13/(R13*1000))*1000,0) -> 108.23195 | AG13: =IF(AND(S13>0,AC13>0),AC13/S13,0) -> 107.9692 | AH13: 68.2 | AI13: =AH13+AI12 -> 324.8 | AJ13: =AH13/(P13) -> 1.3365735 | AK13: =AI13/(Q13) -> 1.3821924 | AL13: =IF(AND(R13>0,AH13>0),AH13/(R13),0) -> 1.4063305 | AM13: =IF(AND(S13>0,AI13>0),AI13/(S13),0) -> 1.4118608 | AN13: 0 | AO13: =AN13+AO12 -> 9 | AP13: =AN13/(P13) -> 0 | AQ13: =AO13/(Q13) -> 0.038299665 | AR13: =IF(AND(R13>0,AN13>0),AN13/(R13),0) -> 0 | AS13: =IF(AND(S13>0,AO13>0),AO13/(S13),0) -> 0.03912176 | AT13: ='5'!I46 -> 41777.78 | AU13: =AT13+AU12 -> 205373.42 | AV13: =IF(AND(L13>0,AT13>0),(AT13/(P13*1000)*1000),0) -> 818.75475 | AW13: =IF(AND(M13>0,AU13>0),(AU13/(Q13*1000)*1000),0) -> 873.97036 | AX13: =IF(AND(R13>0,AT13>0),(AT13/(R13*1000)*1000),0) -> 861.48634 | AY13: =IF(AND(S13>0,AU13>0),(AU13/(S13*1000)*1000),0) -> 892.72996 | AZ13: =+Listrik!S12 -> 28130 | BA13: =AZ13+BA12 -> 131140 | BB13: =IF(AND(L13>0,AZ13>0),(AZ13/(P13*1000)*1000),0) -> 551.28758 | BC13: =IF(AND(M13>0,BA13>0),(BA13/(Q13*1000)*1000),0) -> 558.06868 | BD13: =IF(AND(R13>0,AZ13>0),(AZ13/(R13*1000)*1000),0) -> 580.0598 | BE13: =IF(AND(S13>0,BA13>0),(BA13/(S13*1000)*1000),0) -> 570.04751 | BF13: =+Listrik!V12 -> 1210.1 | BG13: =BF13+BG12 -> 4929.9 | BH13: =IF(AND(L13>0,BF13>0),(BF13/(P13*1000)*1000),0) -> 23.715361 | BI13: =IF(AND(M13>0,BG13>0),(BG13/(Q13*1000)*1000),0) -> 20.97928 | BJ13: =IF(AND(R13>0,BF13>0),(BF13/(R13*1000)*1000),0) -> 24.953088 | BK13: =IF(AND(S13>0,BG13>0),(BG13/(S13*1000)*1000),0) -> 21.429596 | BL13: =+Efficiency2!K29 -> 52.885198 | BM13: =BM12+BL13 -> 272.61264 | BN13: =+R13/BL13 -> 0.91698626 | BO13: =+S13/BM13 -> 0.84387502
A14: =A13+1 -> 46028 | B14: Toilet/Towel | C14: 14,5/29/17 | D14: =+'6'!F42 -> 782.19081 | E14: =+'6'!G42 -> 644.07314 | F14: =1-(E14/D14) -> 0.17657797 | G14: =+P14/N14 -> 0.33172946 | H14: =+P14/L14 -> 0.28524303 | I14: =+R14/P14 -> 0.94892253 | J14: =+R14/L14 -> 0.27067354 | K14: =+S14/M14 -> 0.75293166 | L14: =+SUM(Efficiency1!K35:K37) -> 51.408793 | M14: =M13+L14 -> 324.02144 | N14: =+SUM(Efficiency1!C35:C37) -> 44.204696 | O14: =O13+N14 -> 303.61078 | P14: ='6'!I38 -> 14.664 | Q14: =Q13+P14 -> 249.653 | R14: ='6'!I40 -> 13.915 | S14: =S13+R14 -> 243.966 | T14: =R14/P14 -> 0.94892253 | U14: =S14/Q14 -> 0.97722038 | V14: =R14/L14 -> 0.27067354 | W14: =S14/M14 -> 0.75293166 | AB14: =+[1]Report1!AY14 -> 2262.5317 | AC14: =AB14+AC13 -> 27100.954 | AD14: =AB14/P14 -> 154.29158 | AE14: =AC14/Q14 -> 108.55449 | AF14: =IF(AND(R14>0,AB14>0),(AB14/(R14*1000))*1000,0) -> 162.5966 | AG14: =IF(AND(S14>0,AC14>0),AC14/S14,0) -> 111.08496 | AH14: 31 | AI14: =AH14+AI13 -> 355.8 | AJ14: =AH14/(P14) -> 2.1140207 | AK14: =AI14/(Q14) -> 1.4251781 | AL14: =IF(AND(R14>0,AH14>0),AH14/(R14),0) -> 2.2278117 | AM14: =IF(AND(S14>0,AI14>0),AI14/(S14),0) -> 1.4583999 | AN14: 0 | AO14: =AN14+AO13 -> 9 | AP14: =AN14/(P14) -> 0 | AQ14: =AO14/(Q14) -> 0.036050037 | AR14: =IF(AND(R14>0,AN14>0),AN14/(R14),0) -> 0 | AS14: =IF(AND(S14>0,AO14>0),AO14/(S14),0) -> 0.036890386 | AT14: ='6'!I46 -> 22668.38 | AU14: =AT14+AU13 -> 228041.8 | AV14: =IF(AND(L14>0,AT14>0),(AT14/(P14*1000)*1000),0) -> 1545.8524 | AW14: =IF(AND(M14>0,AU14>0),(AU14/(Q14*1000)*1000),0) -> 913.43505 | AX14: =IF(AND(R14>0,AT14>0),(AT14/(R14*1000)*1000),0) -> 1629.0607 | AY14: =IF(AND(S14>0,AU14>0),(AU14/(S14*1000)*1000),0) -> 934.72779 | AZ14: =+Listrik!S13 -> 16920 | BA14: =AZ14+BA13 -> 148060 | BB14: =IF(AND(L14>0,AZ14>0),(AZ14/(P14*1000)*1000),0) -> 1153.8462 | BC14: =IF(AND(M14>0,BA14>0),(BA14/(Q14*1000)*1000),0) -> 593.06317 | BD14: =IF(AND(R14>0,AZ14>0),(AZ14/(R14*1000)*1000),0) -> 1215.954 | BE14: =IF(AND(S14>0,BA14>0),(BA14/(S14*1000)*1000),0) -> 606.88785 | BF14: =+Listrik!V13 -> 1130.1 | BG14: =BF14+BG13 -> 6060 | BH14: =IF(AND(L14>0,BF14>0),(BF14/(P14*1000)*1000),0) -> 77.066285 | BI14: =IF(AND(M14>0,BG14>0),(BG14/(Q14*1000)*1000),0) -> 24.273692 | BJ14: =IF(AND(R14>0,BF14>0),(BF14/(R14*1000)*1000),0) -> 81.214517 | BK14: =IF(AND(S14>0,BG14>0),(BG14/(S14*1000)*1000),0) -> 24.839527 | BL14: =+SUM(Efficiency2!K35:K37) -> 34.261563 | BM14: =BM13+BL14 -> 306.87421 | BN14: =+R14/BL14 -> 0.40614026 | BO14: =+S14/BM14 -> 0.79500328
A15: =A14+1 -> 46029 | B15: Towel | C15: 17/35,5/22/14 | D15: =+'7'!F42 -> 791.73611 | E15: =+'7'!G42 -> 652.42285 | F15: =1-(E15/D15) -> 0.17595921 | G15: =+P15/N15 -> 0.99741491 | H15: =+P15/L15 -> 0.88858553 | I15: =+R15/P15 -> 0.83896642 | J15: =+R15/L15 -> 0.74549342 | K15: =+S15/M15 -> 0.75190968 | L15: =+SUM(Efficiency1!K42:K45) -> 51.610113 | M15: =M14+L15 -> 375.63155 | N15: =+SUM(Efficiency1!C42:C45) -> 45.97886 | O15: =O14+N15 -> 349.58964 | P15: ='7'!I38 -> 45.86 | Q15: =Q14+P15 -> 295.513 | R15: ='7'!I40 -> 38.475 | S15: =S14+R15 -> 282.441 | T15: =R15/P15 -> 0.83896642 | U15: =S15/Q15 -> 0.95576506 | V15: =R15/L15 -> 0.74549342 | W15: =S15/M15 -> 0.75190968 | AB15: =+[1]Report1!AY15 -> 4833.6882 | AC15: =AB15+AC14 -> 31934.643 | AD15: =AB15/P15 -> 105.40096 | AE15: =AC15/Q15 -> 108.0651 | AF15: =IF(AND(R15>0,AB15>0),(AB15/(R15*1000))*1000,0) -> 125.63192 | AG15: =IF(AND(S15>0,AC15>0),AC15/S15,0) -> 113.0666 | AH15: 59.5 | AI15: =AH15+AI14 -> 415.3 | AJ15: =AH15/(P15) -> 1.297427 | AK15: =AI15/(Q15) -> 1.4053527 | AL15: =IF(AND(R15>0,AH15>0),AH15/(R15),0) -> 1.5464587 | AM15: =IF(AND(S15>0,AI15>0),AI15/(S15),0) -> 1.4703956 | AN15: 0 | AO15: =AN15+AO14 -> 9 | AP15: =AN15/(P15) -> 0 | AQ15: =AO15/(Q15) -> 0.030455513 | AR15: =IF(AND(R15>0,AN15>0),AN15/(R15),0) -> 0 | AS15: =IF(AND(S15>0,AO15>0),AO15/(S15),0) -> 0.031865062 | AT15: ='7'!I46 -> 37977.44 | AU15: =AT15+AU14 -> 266019.24 | AV15: =IF(AND(L15>0,AT15>0),(AT15/(P15*1000)*1000),0) -> 828.11688 | AW15: =IF(AND(M15>0,AU15>0),(AU15/(Q15*1000)*1000),0) -> 900.19471 | AX15: =IF(AND(R15>0,AT15>0),(AT15/(R15*1000)*1000),0) -> 987.06797 | AY15: =IF(AND(S15>0,AU15>0),(AU15/(S15*1000)*1000),0) -> 941.85773 | AZ15: =+Listrik!S14 -> 24940 | BA15: =AZ15+BA14 -> 173000 | BB15: =IF(AND(L15>0,AZ15>0),(AZ15/(P15*1000)*1000),0) -> 543.82904 | BC15: =IF(AND(M15>0,BA15>0),(BA15/(Q15*1000)*1000),0) -> 585.42264 | BD15: =IF(AND(R15>0,AZ15>0),(AZ15/(R15*1000)*1000),0) -> 648.21313 | BE15: =IF(AND(S15>0,BA15>0),(BA15/(S15*1000)*1000),0) -> 612.5173 | BF15: =+Listrik!V14 -> 1230.1 | BG15: =BF15+BG14 -> 7290.1 | BH15: =IF(AND(L15>0,BF15>0),(BF15/(P15*1000)*1000),0) -> 26.822939 | BI15: =IF(AND(M15>0,BG15>0),(BG15/(Q15*1000)*1000),0) -> 24.669304 | BJ15: =IF(AND(R15>0,BF15>0),(BF15/(R15*1000)*1000),0) -> 31.97141 | BK15: =IF(AND(S15>0,BG15>0),(BG15/(S15*1000)*1000),0) -> 25.811054 | BL15: =+SUM(Efficiency2!K42:K45) -> 51.610113 | BM15: =BM14+BL15 -> 358.48432 | BN15: =+R15/BL15 -> 0.74549342 | BO15: =+S15/BM15 -> 0.78787546
A16: =A15+1 -> 46030 | B16: Towel/Napkin | C16: 14/35,5/29/15,5 | D16: =+'8'!F42 -> 795.625 | E16: =+'8'!G42 -> 683.36236 | F16: =1-(E16/D16) -> 0.14109994 | G16: =+P16/N16 -> 0.96692511 | H16: =+P16/L16 -> 0.92428198 | I16: =+R16/P16 -> 0.8665366 | J16: =+R16/L16 -> 0.80092416 | K16: =+S16/M16 -> 0.75810475 | L16: =+SUM(Efficiency1!K47:K50) -> 54.345969 | M16: =M15+L16 -> 429.97752 | N16: =+SUM(Efficiency1!C47:C50) -> 51.949214 | O16: =O15+N16 -> 401.53885 | P16: ='8'!I38 -> 50.231 | Q16: =Q15+P16 -> 345.744 | R16: ='8'!I40 -> 43.527 | S16: =S15+R16 -> 325.968 | T16: =R16/P16 -> 0.8665366 | U16: =S16/Q16 -> 0.94280161 | V16: =R16/L16 -> 0.80092416 | W16: =S16/M16 -> 0.75810475 | AB16: =+[1]Report1!AY16 -> 5031.5806 | AC16: =AB16+AC15 -> 36966.223 | AD16: =AB16/P16 -> 100.16883 | AE16: =AC16/Q16 -> 106.9179 | AF16: =IF(AND(R16>0,AB16>0),(AB16/(R16*1000))*1000,0) -> 115.59677 | AG16: =IF(AND(S16>0,AC16>0),AC16/S16,0) -> 113.40445 | AH16: 62.8 | AI16: =AH16+AI15 -> 478.1 | AJ16: =AH16/(P16) -> 1.250224 | AK16: =AI16/(Q16) -> 1.382815 | AL16: =IF(AND(R16>0,AH16>0),AH16/(R16),0) -> 1.4427826 | AM16: =IF(AND(S16>0,AI16>0),AI16/(S16),0) -> 1.4667084 | AN16: 0 | AO16: =AN16+AO15 -> 9 | AP16: =AN16/(P16) -> 0 | AQ16: =AO16/(Q16) -> 0.02603082 | AR16: =IF(AND(R16>0,AN16>0),AN16/(R16),0) -> 0 | AS16: =IF(AND(S16>0,AO16>0),AO16/(S16),0) -> 0.027610072 | AT16: ='8'!I46 -> 36439.14 | AU16: =AT16+AU15 -> 302458.38 | AV16: =IF(AND(L16>0,AT16>0),(AT16/(P16*1000)*1000),0) -> 725.43131 | AW16: =IF(AND(M16>0,AU16>0),(AU16/(Q16*1000)*1000),0) -> 874.80442 | AX16: =IF(AND(R16>0,AT16>0),(AT16/(R16*1000)*1000),0) -> 837.16176 | AY16: =IF(AND(S16>0,AU16>0),(AU16/(S16*1000)*1000),0) -> 927.87752 | AZ16: =+Listrik!S15 -> 25470 | BA16: =AZ16+BA15 -> 198470 | BB16: =IF(AND(L16>0,AZ16>0),(AZ16/(P16*1000)*1000),0) -> 507.05739 | BC16: =IF(AND(M16>0,BA16>0),(BA16/(Q16*1000)*1000),0) -> 574.03744 | BD16: =IF(AND(R16>0,AZ16>0),(AZ16/(R16*1000)*1000),0) -> 585.15404 | BE16: =IF(AND(S16>0,BA16>0),(BA16/(S16*1000)*1000),0) -> 608.86345 | BF16: =+Listrik!V15 -> 1210.1 | BG16: =BF16+BG15 -> 8500.2 | BH16: =IF(AND(L16>0,BF16>0),(BF16/(P16*1000)*1000),0) -> 24.090701 | BI16: =IF(AND(M16>0,BG16>0),(BG16/(Q16*1000)*1000),0) -> 24.585242 | BJ16: =IF(AND(R16>0,BF16>0),(BF16/(R16*1000)*1000),0) -> 27.801135 | BK16: =IF(AND(S16>0,BG16>0),(BG16/(S16*1000)*1000),0) -> 26.076793 | BL16: =+SUM(Efficiency2!K47:K50) -> 54.345969 | BM16: =BM15+BL16 -> 412.83029 | BN16: =+R16/BL16 -> 0.80092416 | BO16: =+S16/BM16 -> 0.78959323
A17: =A16+1 -> 46031 | B17: Napkin/Facial/Toilet | C17: 15,5/14/13,5 | D17: =+'9'!F42 -> 955.11806 | E17: =+'9'!G42 -> 814.25812 | F17: =1-(E17/D17) -> 0.14747908 | G17: =+P17/N17 -> 1.0030259 | H17: =+P17/L17 -> 0.86094225 | I17: =+R17/P17 -> 1.0893908 | J17: =+R17/L17 -> 0.93790256 | K17: =+S17/M17 -> 0.77806339 | L17: =+SUM(Efficiency1!K52:K54) -> 53.690012 | M17: =M16+L17 -> 483.66753 | N17: =+SUM(Efficiency1!C52:C54) -> 46.084554 | O17: =O16+N17 -> 447.62341 | P17: ='9'!I38 -> 46.224 | Q17: =Q16+P17 -> 391.968 | R17: ='9'!I40 -> 50.356 | S17: =S16+R17 -> 376.324 | T17: =R17/P17 -> 1.0893908 | U17: =S17/Q17 -> 0.96008858 | V17: =R17/L17 -> 0.93790256 | W17: =S17/M17 -> 0.77806339 | AB17: =+[1]Report1!AY17 -> 3875.86 | AC17: =AB17+AC16 -> 40842.083 | AD17: =AB17/P17 -> 83.849515 | AE17: =AC17/Q17 -> 104.19749 | AF17: =IF(AND(R17>0,AB17>0),(AB17/(R17*1000))*1000,0) -> 76.969179 | AG17: =IF(AND(S17>0,AC17>0),AC17/S17,0) -> 108.52904 | AH17: 68 | AI17: =AH17+AI16 -> 546.1 | AJ17: =AH17/(P17) -> 1.4710973 | AK17: =AI17/(Q17) -> 1.393226 | AL17: =IF(AND(R17>0,AH17>0),AH17/(R17),0) -> 1.3503853 | AM17: =IF(AND(S17>0,AI17>0),AI17/(S17),0) -> 1.4511432 | AN17: 0 | AO17: =AN17+AO16 -> 9 | AP17: =AN17/(P17) -> 0 | AQ17: =AO17/(Q17) -> 0.022961058 | AR17: =IF(AND(R17>0,AN17>0),AN17/(R17),0) -> 0 | AS17: =IF(AND(S17>0,AO17>0),AO17/(S17),0) -> 0.023915562 | AT17: ='9'!I46 -> 39302.36 | AU17: =AT17+AU16 -> 341760.74 | AV17: =IF(AND(L17>0,AT17>0),(AT17/(P17*1000)*1000),0) -> 850.25874 | AW17: =IF(AND(M17>0,AU17>0),(AU17/(Q17*1000)*1000),0) -> 871.9098 | AX17: =IF(AND(R17>0,AT17>0),(AT17/(R17*1000)*1000),0) -> 780.49011 | AY17: =IF(AND(S17>0,AU17>0),(AU17/(S17*1000)*1000),0) -> 908.15558 | AZ17: =+Listrik!S16 -> 24740 | BA17: =AZ17+BA16 -> 223210 | BB17: =IF(AND(L17>0,AZ17>0),(AZ17/(P17*1000)*1000),0) -> 535.2198 | BC17: =IF(AND(M17>0,BA17>0),(BA17/(Q17*1000)*1000),0) -> 569.45975 | BD17: =IF(AND(R17>0,AZ17>0),(AZ17/(R17*1000)*1000),0) -> 491.30193 | BE17: =IF(AND(S17>0,BA17>0),(BA17/(S17*1000)*1000),0) -> 593.13251 | BF17: =+Listrik!V16 -> 1299.6 | BG17: =BF17+BG16 -> 9799.8 | BH17: =IF(AND(L17>0,BF17>0),(BF17/(P17*1000)*1000),0) -> 28.115265 | BI17: =IF(AND(M17>0,BG17>0),(BG17/(Q17*1000)*1000),0) -> 25.001531 | BJ17: =IF(AND(R17>0,BF17>0),(BF17/(R17*1000)*1000),0) -> 25.808245 | BK17: =IF(AND(S17>0,BG17>0),(BG17/(S17*1000)*1000),0) -> 26.040858 | BL17: =+SUM(Efficiency2!K52:K54) -> 46.084554 | BM17: =BM16+BL17 -> 458.91484 | BN17: =+R17/BL17 -> 1.0926872 | BO17: =+S17/BM17 -> 0.82003013
A18: =A17+1 -> 46032 | B18: Toilet | C18: 13,5/15 | D18: =+'10'!F42 -> 1097.4453 | E18: =+'10'!G42 -> 917.35669 | F18: =1-(E18/D18) -> 0.16409799 | G18: =+P18/N18 -> 0.79890827 | H18: =+P18/L18 -> 0.71555745 | I18: =+R18/P18 -> 0.96532027 | J18: =+R18/L18 -> 0.69074211 | K18: =+S18/M18 -> 0.76964245 | L18: =+SUM(Efficiency1!K58:K59) -> 51.621292 | M18: =M17+L18 -> 535.28882 | N18: =+SUM(Efficiency1!C58:C59) -> 46.235596 | O18: =O17+N18 -> 493.859 | P18: ='10'!I38 -> 36.938 | Q18: =Q17+P18 -> 428.906 | R18: ='10'!I40 -> 35.657 | S18: =S17+R18 -> 411.981 | T18: =R18/P18 -> 0.96532027 | U18: =S18/Q18 -> 0.96053914 | V18: =R18/L18 -> 0.69074211 | W18: =S18/M18 -> 0.76964245 | AB18: =+[1]Report1!AY18 -> 4629.317 | AC18: =AB18+AC17 -> 45471.4 | AD18: =AB18/P18 -> 125.32668 | AE18: =AC18/Q18 -> 106.01717 | AF18: =IF(AND(R18>0,AB18>0),(AB18/(R18*1000))*1000,0) -> 129.82912 | AG18: =IF(AND(S18>0,AC18>0),AC18/S18,0) -> 110.37257 | AH18: 61.2 | AI18: =AH18+AI17 -> 607.3 | AJ18: =AH18/(P18) -> 1.6568304 | AK18: =AI18/(Q18) -> 1.415928 | AL18: =IF(AND(R18>0,AH18>0),AH18/(R18),0) -> 1.716353 | AM18: =IF(AND(S18>0,AI18>0),AI18/(S18),0) -> 1.4740971 | AN18: 0 | AO18: =AN18+AO17 -> 9 | AP18: =AN18/(P18) -> 0 | AQ18: =AO18/(Q18) -> 0.020983619 | AR18: =IF(AND(R18>0,AN18>0),AN18/(R18),0) -> 0 | AS18: =IF(AND(S18>0,AO18>0),AO18/(S18),0) -> 0.021845668 | AT18: ='10'!I46 -> 38098.46 | AU18: =AT18+AU17 -> 379859.2 | AV18: =IF(AND(L18>0,AT18>0),(AT18/(P18*1000)*1000),0) -> 1031.4164 | AW18: =IF(AND(M18>0,AU18>0),(AU18/(Q18*1000)*1000),0) -> 885.64674 | AX18: =IF(AND(R18>0,AT18>0),(AT18/(R18*1000)*1000),0) -> 1068.4707 | AY18: =IF(AND(S18>0,AU18>0),(AU18/(S18*1000)*1000),0) -> 922.03087 | AZ18: =+Listrik!S17 -> 22580 | BA18: =AZ18+BA17 -> 245790 | BB18: =IF(AND(L18>0,AZ18>0),(AZ18/(P18*1000)*1000),0) -> 611.2946 | BC18: =IF(AND(M18>0,BA18>0),(BA18/(Q18*1000)*1000),0) -> 573.06263 | BD18: =IF(AND(R18>0,AZ18>0),(AZ18/(R18*1000)*1000),0) -> 633.25574 | BE18: =IF(AND(S18>0,BA18>0),(BA18/(S18*1000)*1000),0) -> 596.60518 | BF18: =+Listrik!V17 -> 1250.1 | BG18: =BF18+BG17 -> 11049.9 | BH18: =IF(AND(L18>0,BF18>0),(BF18/(P18*1000)*1000),0) -> 33.843197 | BI18: =IF(AND(M18>0,BG18>0),(BG18/(Q18*1000)*1000),0) -> 25.762988 | BJ18: =IF(AND(R18>0,BF18>0),(BF18/(R18*1000)*1000),0) -> 35.059035 | BK18: =IF(AND(S18>0,BG18>0),(BG18/(S18*1000)*1000),0) -> 26.821383 | BL18: =+SUM(Efficiency2!K58:K59) -> 43.47462 | BM18: =BM17+BL18 -> 502.38946 | BN18: =+R18/BL18 -> 0.82017967 | BO18: =+S18/BM18 -> 0.82004307
A19: =A18+1 -> 46033 | B19: Toilet | C19: 15 | D19: =+'11'!F42 -> 1166.6667 | E19: =+'11'!G42 -> 933.33333 | F19: =1-(E19/D19) -> 0.2 | G19: =+P19/N19 -> 1.0119048 | H19: =+P19/L19 -> 1.0119048 | I19: =+R19/P19 -> 0.94985057 | J19: =+R19/L19 -> 0.96115832 | K19: =+S19/M19 -> 0.78726016 | L19: =+Efficiency1!K66 -> 54.2304 | M19: =M18+L19 -> 589.51922 | N19: =+Efficiency1!C66 -> 54.2304 | O19: =O18+N19 -> 548.0894 | P19: ='11'!I38 -> 54.876 | Q19: =Q18+P19 -> 483.782 | R19: ='11'!I40 -> 52.124 | S19: =S18+R19 -> 464.105 | T19: =R19/P19 -> 0.94985057 | U19: =S19/Q19 -> 0.95932672 | V19: =R19/L19 -> 0.96115832 | W19: =S19/M19 -> 0.78726016 | AB19: =+[1]Report1!AY19 -> 5245.5838 | AC19: =AB19+AC18 -> 50716.984 | AD19: =AB19/P19 -> 95.589762 | AE19: =AC19/Q19 -> 104.83438 | AF19: =IF(AND(R19>0,AB19>0),(AB19/(R19*1000))*1000,0) -> 100.63663 | AG19: =IF(AND(S19>0,AC19>0),AC19/S19,0) -> 109.27912 | AH19: 67.8 | AI19: =AH19+AI18 -> 675.1 | AJ19: =AH19/(P19) -> 1.2355128 | AK19: =AI19/(Q19) -> 1.3954632 | AL19: =IF(AND(R19>0,AH19>0),AH19/(R19),0) -> 1.3007444 | AM19: =IF(AND(S19>0,AI19>0),AI19/(S19),0) -> 1.4546277 | AN19: 0 | AO19: =AN19+AO18 -> 9 | AP19: =AN19/(P19) -> 0 | AQ19: =AO19/(Q19) -> 0.018603421 | AR19: =IF(AND(R19>0,AN19>0),AN19/(R19),0) -> 0 | AS19: =IF(AND(S19>0,AO19>0),AO19/(S19),0) -> 0.019392163 | AT19: ='11'!I46 -> 43694.34 | AU19: =AT19+AU18 -> 423553.54 | AV19: =IF(AND(L19>0,AT19>0),(AT19/(P19*1000)*1000),0) -> 796.2377 | AW19: =IF(AND(M19>0,AU19>0),(AU19/(Q19*1000)*1000),0) -> 875.50496 | AX19: =IF(AND(R19>0,AT19>0),(AT19/(R19*1000)*1000),0) -> 838.2768 | AY19: =IF(AND(S19>0,AU19>0),(AU19/(S19*1000)*1000),0) -> 912.62438 | AZ19: =+Listrik!S18 -> 28170 | BA19: =AZ19+BA18 -> 273960 | BB19: =IF(AND(L19>0,AZ19>0),(AZ19/(P19*1000)*1000),0) -> 513.33916 | BC19: =IF(AND(M19>0,BA19>0),(BA19/(Q19*1000)*1000),0) -> 566.28812 | BD19: =IF(AND(R19>0,AZ19>0),(AZ19/(R19*1000)*1000),0) -> 540.44202 | BE19: =IF(AND(S19>0,BA19>0),(BA19/(S19*1000)*1000),0) -> 590.29745 | BF19: =+Listrik!V18 -> 1260.1 | BG19: =BF19+BG18 -> 12310 | BH19: =IF(AND(L19>0,BF19>0),(BF19/(P19*1000)*1000),0) -> 22.962679 | BI19: =IF(AND(M19>0,BG19>0),(BG19/(Q19*1000)*1000),0) -> 25.445345 | BJ19: =IF(AND(R19>0,BF19>0),(BF19/(R19*1000)*1000),0) -> 24.175044 | BK19: =IF(AND(S19>0,BG19>0),(BG19/(S19*1000)*1000),0) -> 26.52417 | BL19: =+Efficiency2!K66 -> 54.2304 | BM19: =BM18+BL19 -> 556.61986 | BN19: =+R19/BL19 -> 0.96115832 | BO19: =+S19/BM19 -> 0.83379166
A20: =A19+1 -> 46034 | B20: Toilet | C20: 15/14 | D20: =+'12'!F42 -> 1223.625 | E20: =+'12'!G42 -> 959.51375 | F20: =1-(E20/D20) -> 0.21584329 | G20: =+P20/N20 -> 0.97188393 | H20: =+P20/L20 -> 0.95012431 | I20: =+R20/P20 -> 1.0235116 | J20: =+R20/L20 -> 0.97246329 | K20: =+S20/M20 -> 0.80289199 | L20: =+SUM(Efficiency1!K71:K72) -> 54.344468 | M20: =M19+L20 -> 643.86369 | N20: =+SUM(Efficiency1!C71:C72) -> 53.127743 | O20: =O19+N20 -> 601.21715 | P20: ='12'!I38 -> 51.634 | Q20: =Q19+P20 -> 535.416 | R20: ='12'!I40 -> 52.848 | S20: =S19+R20 -> 516.953 | T20: =R20/P20 -> 1.0235116 | U20: =S20/Q20 -> 0.96551653 | V20: =R20/L20 -> 0.97246329 | W20: =S20/M20 -> 0.80289199 | AB20: =+[1]Report1!AY20 -> 5839.2934 | AC20: =AB20+AC19 -> 56556.277 | AD20: =AB20/P20 -> 113.09008 | AE20: =AC20/Q20 -> 105.63053 | AF20: =IF(AND(R20>0,AB20>0),(AB20/(R20*1000))*1000,0) -> 110.49223 | AG20: =IF(AND(S20>0,AC20>0),AC20/S20,0) -> 109.40313 | AH20: 64.8 | AI20: =AH20+AI19 -> 739.9 | AJ20: =AH20/(P20) -> 1.254987 | AK20: =AI20/(Q20) -> 1.3819161 | AL20: =IF(AND(R20>0,AH20>0),AH20/(R20),0) -> 1.226158 | AM20: =IF(AND(S20>0,AI20>0),AI20/(S20),0) -> 1.4312713 | AN20: 0 | AO20: =AN20+AO19 -> 9 | AP20: =AN20/(P20) -> 0 | AQ20: =AO20/(Q20) -> 0.016809359 | AR20: =IF(AND(R20>0,AN20>0),AN20/(R20),0) -> 0 | AS20: =IF(AND(S20>0,AO20>0),AO20/(S20),0) -> 0.017409706 | AT20: ='12'!I46 -> 42672.88 | AU20: =AT20+AU19 -> 466226.42 | AV20: =IF(AND(L20>0,AT20>0),(AT20/(P20*1000)*1000),0) -> 826.44924 | AW20: =IF(AND(M20>0,AU20>0),(AU20/(Q20*1000)*1000),0) -> 870.77416 | AX20: =IF(AND(R20>0,AT20>0),(AT20/(R20*1000)*1000),0) -> 807.46443 | AY20: =IF(AND(S20>0,AU20>0),(AU20/(S20*1000)*1000),0) -> 901.8739 | AZ20: =+Listrik!S19 -> 25953.2 | BA20: =AZ20+BA19 -> 299913.2 | BB20: =IF(AND(L20>0,AZ20>0),(AZ20/(P20*1000)*1000),0) -> 502.6378 | BC20: =IF(AND(M20>0,BA20>0),(BA20/(Q20*1000)*1000),0) -> 560.14986 | BD20: =IF(AND(R20>0,AZ20>0),(AZ20/(R20*1000)*1000),0) -> 491.09143 | BE20: =IF(AND(S20>0,BA20>0),(BA20/(S20*1000)*1000),0) -> 580.15564 | BF20: =+Listrik!V19 -> 1419.8 | BG20: =BF20+BG19 -> 13729.8 | BH20: =IF(AND(L20>0,BF20>0),(BF20/(P20*1000)*1000),0) -> 27.497385 | BI20: =IF(AND(M20>0,BG20>0),(BG20/(Q20*1000)*1000),0) -> 25.643238 | BJ20: =IF(AND(R20>0,BF20>0),(BF20/(R20*1000)*1000),0) -> 26.865728 | BK20: =IF(AND(S20>0,BG20>0),(BG20/(S20*1000)*1000),0) -> 26.559088 | BL20: =+SUM(Efficiency2!K71:K72) -> 54.344468 | BM20: =BM19+BL20 -> 610.96433 | BN20: =+R20/BL20 -> 0.97246329 | BO20: =+S20/BM20 -> 0.84612632
A21: =A20+1 -> 46035 | B21: Toilet | C21: 14/15 | D21: =+'13'!F42 -> 1181.0547 | E21: =+'13'!G42 -> 921.22266 | F21: =1-(E21/D21) -> 0.22 | G21: =+P21/N21 -> 0.82478893 | H21: =+P21/L21 -> 0.80925281 | I21: =+R21/P21 -> 0.97342109 | J21: =+R21/L21 -> 0.78774375 | K21: =+S21/M21 -> 0.80172215 | L21: =+SUM(Efficiency1!K76:K77) -> 53.884274 | M21: =M20+L21 -> 697.74797 | N21: =+SUM(Efficiency1!C76:C77) -> 52.869284 | O21: =O20+N21 -> 654.08643 | P21: ='13'!I38 -> 43.606 | Q21: =Q20+P21 -> 579.022 | R21: ='13'!I40 -> 42.447 | S21: =S20+R21 -> 559.4 | T21: =R21/P21 -> 0.97342109 | U21: =S21/Q21 -> 0.96611182 | V21: =R21/L21 -> 0.78774375 | W21: =S21/M21 -> 0.80172215 | AB21: =+[1]Report1!AY21 -> 5336.2658 | AC21: =AB21+AC20 -> 61892.543 | AD21: =AB21/P21 -> 122.37458 | AE21: =AC21/Q21 -> 106.89152 | AF21: =IF(AND(R21>0,AB21>0),(AB21/(R21*1000))*1000,0) -> 125.71597 | AG21: =IF(AND(S21>0,AC21>0),AC21/S21,0) -> 110.64094 | AH21: 62 | AI21: =AH21+AI20 -> 801.9 | AJ21: =AH21/(P21) -> 1.4218227 | AK21: =AI21/(Q21) -> 1.3849215 | AL21: =IF(AND(R21>0,AH21>0),AH21/(R21),0) -> 1.460645 | AM21: =IF(AND(S21>0,AI21>0),AI21/(S21),0) -> 1.4335002 | AN21: 0 | AO21: =AN21+AO20 -> 9 | AP21: =AN21/(P21) -> 0 | AQ21: =AO21/(Q21) -> 0.015543451 | AR21: =IF(AND(R21>0,AN21>0),AN21/(R21),0) -> 0 | AS21: =IF(AND(S21>0,AO21>0),AO21/(S21),0) -> 0.016088666 | AT21: ='13'!I46 -> 41288.86 | AU21: =AT21+AU20 -> 507515.28 | AV21: =IF(AND(L21>0,AT21>0),(AT21/(P21*1000)*1000),0) -> 946.8619 | AW21: =IF(AND(M21>0,AU21>0),(AU21/(Q21*1000)*1000),0) -> 876.50431 | AX21: =IF(AND(R21>0,AT21>0),(AT21/(R21*1000)*1000),0) -> 972.71562 | AY21: =IF(AND(S21>0,AU21>0),(AU21/(S21*1000)*1000),0) -> 907.24934 | AZ21: =+Listrik!S20 -> 22009.5 | BA21: =AZ21+BA20 -> 321922.7 | BB21: =IF(AND(L21>0,AZ21>0),(AZ21/(P21*1000)*1000),0) -> 504.73559 | BC21: =IF(AND(M21>0,BA21>0),(BA21/(Q21*1000)*1000),0) -> 555.97663 | BD21: =IF(AND(R21>0,AZ21>0),(AZ21/(R21*1000)*1000),0) -> 518.51721 | BE21: =IF(AND(S21>0,BA21>0),(BA21/(S21*1000)*1000),0) -> 575.47855 | BF21: =+Listrik!V20 -> 1430.1 | BG21: =BF21+BG20 -> 15159.9 | BH21: =IF(AND(L21>0,BF21>0),(BF21/(P21*1000)*1000),0) -> 32.795946 | BI21: =IF(AND(M21>0,BG21>0),(BG21/(Q21*1000)*1000),0) -> 26.181907 | BJ21: =IF(AND(R21>0,BF21>0),(BF21/(R21*1000)*1000),0) -> 33.691427 | BK21: =IF(AND(S21>0,BG21>0),(BG21/(S21*1000)*1000),0) -> 27.100286 | BL21: =+SUM(Efficiency2!K76:K77) -> 53.884274 | BM21: =BM20+BL21 -> 664.84861 | BN21: =+R21/BL21 -> 0.78774375 | BO21: =+S21/BM21 -> 0.84139456
A22: =A21+1 -> 46036 | B22: Toilet | C22: 15 | D22: =+'14'!F42 -> 1163.3333 | E22: =+'14'!G42 -> 907.4 | F22: =1-(E22/D22) -> 0.22 | G22: =+P22/N22 -> 1.0054628 | H22: =+P22/L22 -> 1.0054628 | I22: =+R22/P22 -> 0.94071299 | J22: =+R22/L22 -> 0.94585188 | K22: =+S22/M22 -> 0.81205749 | L22: =+Efficiency1!K82 -> 53.89956 | M22: =M21+L22 -> 751.64753 | N22: =+Efficiency1!C82 -> 53.89956 | O22: =O21+N22 -> 707.98599 | P22: ='14'!I38 -> 54.194 | Q22: =Q21+P22 -> 633.216 | R22: ='14'!I40 -> 50.981 | S22: =S21+R22 -> 610.381 | T22: =R22/P22 -> 0.94071299 | U22: =S22/Q22 -> 0.96393806 | V22: =R22/L22 -> 0.94585188 | W22: =S22/M22 -> 0.81205749 | AB22: =+[1]Report1!AY22 -> 5765.3371 | AC22: =AB22+AC21 -> 67657.88 | AD22: =AB22/P22 -> 106.38331 | AE22: =AC22/Q22 -> 106.84803 | AF22: =IF(AND(R22>0,AB22>0),(AB22/(R22*1000))*1000,0) -> 113.08796 | AG22: =IF(AND(S22>0,AC22>0),AC22/S22,0) -> 110.84532 | AH22: 67.7 | AI22: =AH22+AI21 -> 869.6 | AJ22: =AH22/(P22) -> 1.2492158 | AK22: =AI22/(Q22) -> 1.3733071 | AL22: =IF(AND(R22>0,AH22>0),AH22/(R22),0) -> 1.3279457 | AM22: =IF(AND(S22>0,AI22>0),AI22/(S22),0) -> 1.4246839 | AN22: 0 | AO22: =AN22+AO21 -> 9 | AP22: =AN22/(P22) -> 0 | AQ22: =AO22/(Q22) -> 0.014213159 | AR22: =IF(AND(R22>0,AN22>0),AN22/(R22),0) -> 0 | AS22: =IF(AND(S22>0,AO22>0),AO22/(S22),0) -> 0.014744889 | AT22: ='14'!I46 -> 42590.38 | AU22: =AT22+AU21 -> 550105.66 | AV22: =IF(AND(L22>0,AT22>0),(AT22/(P22*1000)*1000),0) -> 785.88737 | AW22: =IF(AND(M22>0,AU22>0),(AU22/(Q22*1000)*1000),0) -> 868.74883 | AX22: =IF(AND(R22>0,AT22>0),(AT22/(R22*1000)*1000),0) -> 835.41672 | AY22: =IF(AND(S22>0,AU22>0),(AU22/(S22*1000)*1000),0) -> 901.24965 | AZ22: =+Listrik!S21 -> 25272.3 | BA22: =AZ22+BA21 -> 347195 | BB22: =IF(AND(L22>0,AZ22>0),(AZ22/(P22*1000)*1000),0) -> 466.33022 | BC22: =IF(AND(M22>0,BA22>0),(BA22/(Q22*1000)*1000),0) -> 548.30421 | BD22: =IF(AND(R22>0,AZ22>0),(AZ22/(R22*1000)*1000),0) -> 495.71997 | BE22: =IF(AND(S22>0,BA22>0),(BA22/(S22*1000)*1000),0) -> 568.81685 | BF22: =+Listrik!V21 -> 1416.6 | BG22: =BF22+BG21 -> 16576.5 | BH22: =IF(AND(L22>0,BF22>0),(BF22/(P22*1000)*1000),0) -> 26.139425 | BI22: =IF(AND(M22>0,BG22>0),(BG22/(Q22*1000)*1000),0) -> 26.178271 | BJ22: =IF(AND(R22>0,BF22>0),(BF22/(R22*1000)*1000),0) -> 27.786823 | BK22: =IF(AND(S22>0,BG22>0),(BG22/(S22*1000)*1000),0) -> 27.157628 | BL22: =+Efficiency2!K82 -> 53.89956 | BM22: =BM21+BL22 -> 718.74817 | BN22: =+R22/BL22 -> 0.94585188 | BO22: =+S22/BM22 -> 0.84922791
A23: =A22+1 -> 46037 | B23: Toilet | C23: 15 | D23: =+'15'!F42 -> 1170 | E23: =+'15'!G42 -> 936 | F23: =1-(E23/D23) -> 0.2 | G23: =+P23/N23 -> 0.97139846 | H23: =+P23/L23 -> 0.97139846 | I23: =+R23/P23 -> 0.99660136 | J23: =+R23/L23 -> 0.96809702 | K23: =+S23/M23 -> 0.82277434 | L23: =+Efficiency1!K87 -> 55.430395 | M23: =M22+L23 -> 807.07792 | N23: =+Efficiency1!C87 -> 55.430395 | O23: =O22+N23 -> 763.41638 | P23: ='15'!I38 -> 53.845 | Q23: =Q22+P23 -> 687.061 | R23: ='15'!I40 -> 53.662 | S23: =S22+R23 -> 664.043 | T23: =R23/P23 -> 0.99660136 | U23: =S23/Q23 -> 0.96649788 | V23: =R23/L23 -> 0.96809702 | W23: =S23/M23 -> 0.82277434 | AB23: =+[1]Report1!AY23 -> 5606.3908 | AC23: =AB23+AC22 -> 73264.271 | AD23: =AB23/P23 -> 104.12092 | AE23: =AC23/Q23 -> 106.6343 | AF23: =IF(AND(R23>0,AB23>0),(AB23/(R23*1000))*1000,0) -> 104.47599 | AG23: =IF(AND(S23>0,AC23>0),AC23/S23,0) -> 110.33061 | AH23: 67.7 | AI23: =AH23+AI22 -> 937.3 | AJ23: =AH23/(P23) -> 1.2573127 | AK23: =AI23/(Q23) -> 1.3642166 | AL23: =IF(AND(R23>0,AH23>0),AH23/(R23),0) -> 1.2616004 | AM23: =IF(AND(S23>0,AI23>0),AI23/(S23),0) -> 1.411505 | AN23: 0 | AO23: =AN23+AO22 -> 9 | AP23: =AN23/(P23) -> 0 | AQ23: =AO23/(Q23) -> 0.013099274 | AR23: =IF(AND(R23>0,AN23>0),AN23/(R23),0) -> 0 | AS23: =IF(AND(S23>0,AO23>0),AO23/(S23),0) -> 0.013553339 | AT23: ='15'!I46 -> 44053.52 | AU23: =AT23+AU22 -> 594159.18 | AV23: =IF(AND(L23>0,AT23>0),(AT23/(P23*1000)*1000),0) -> 818.15433 | AW23: =IF(AND(M23>0,AU23>0),(AU23/(Q23*1000)*1000),0) -> 864.78374 | AX23: =IF(AND(R23>0,AT23>0),(AT23/(R23*1000)*1000),0) -> 820.94443 | AY23: =IF(AND(S23>0,AU23>0),(AU23/(S23*1000)*1000),0) -> 894.7601 | AZ23: =+Listrik!S22 -> 24513.95 | BA23: =AZ23+BA22 -> 371708.95 | BB23: =IF(AND(L23>0,AZ23>0),(AZ23/(P23*1000)*1000),0) -> 455.26883 | BC23: =IF(AND(M23>0,BA23>0),(BA23/(Q23*1000)*1000),0) -> 541.01303 | BD23: =IF(AND(R23>0,AZ23>0),(AZ23/(R23*1000)*1000),0) -> 456.8214 | BE23: =IF(AND(S23>0,BA23>0),(BA23/(S23*1000)*1000),0) -> 559.76639 | BF23: =+Listrik!V22 -> 1436.8 | BG23: =BF23+BG22 -> 18013.3 | BH23: =IF(AND(L23>0,BF23>0),(BF23/(P23*1000)*1000),0) -> 26.684 | BI23: =IF(AND(M23>0,BG23>0),(BG23/(Q23*1000)*1000),0) -> 26.217905 | BJ23: =IF(AND(R23>0,BF23>0),(BF23/(R23*1000)*1000),0) -> 26.774999 | BK23: =IF(AND(S23>0,BG23>0),(BG23/(S23*1000)*1000),0) -> 27.126707 | BL23: =+Efficiency2!K87 -> 55.430395 | BM23: =BM22+BL23 -> 774.17856 | BN23: =+R23/BL23 -> 0.96809702 | BO23: =+S23/BM23 -> 0.85773881
A24: =A23+1 -> 46038 | B24: Toilet | C24: 15 | D24: =+'16'!F42 -> 1170 | E24: =+'16'!G42 -> 936 | F24: =1-(E24/D24) -> 0.2 | G24: =+P24/N24 -> 0.98252184 | H24: =+P24/L24 -> 0.98252184 | I24: =+R24/P24 -> 0.91394135 | J24: =+R24/L24 -> 0.89796734 | K24: =+S24/M24 -> 0.82760394 | L24: =+Efficiency1!K92 -> 55.396224 | M24: =M23+L24 -> 862.47414 | N24: =+Efficiency1!C92 -> 55.396224 | O24: =O23+N24 -> 818.81261 | P24: ='16'!I38 -> 54.428 | Q24: =Q23+P24 -> 741.489 | R24: ='16'!I40 -> 49.744 | S24: =S23+R24 -> 713.787 | T24: =R24/P24 -> 0.91394135 | U24: =S24/Q24 -> 0.96264004 | V24: =R24/L24 -> 0.89796734 | W24: =S24/M24 -> 0.82760394 | AB24: =+[1]Report1!AY24 -> 5828.234 | AC24: =AB24+AC23 -> 79092.505 | AD24: =AB24/P24 -> 107.08154 | AE24: =AC24/Q24 -> 106.66713 | AF24: =IF(AND(R24>0,AB24>0),(AB24/(R24*1000))*1000,0) -> 117.16456 | AG24: =IF(AND(S24>0,AC24>0),AC24/S24,0) -> 110.80687 | AH24: 69 | AI24: =AH24+AI23 -> 1006.3 | AJ24: =AH24/(P24) -> 1.2677298 | AK24: =AI24/(Q24) -> 1.3571341 | AL24: =IF(AND(R24>0,AH24>0),AH24/(R24),0) -> 1.387102 | AM24: =IF(AND(S24>0,AI24>0),AI24/(S24),0) -> 1.4098043 | AN24: 0 | AO24: =AN24+AO23 -> 9 | AP24: =AN24/(P24) -> 0 | AQ24: =AO24/(Q24) -> 0.012137739 | AR24: =IF(AND(R24>0,AN24>0),AN24/(R24),0) -> 0 | AS24: =IF(AND(S24>0,AO24>0),AO24/(S24),0) -> 0.012608803 | AT24: ='16'!I46 -> 43291.78 | AU24: =AT24+AU23 -> 637450.96 | AV24: =IF(AND(L24>0,AT24>0),(AT24/(P24*1000)*1000),0) -> 795.39538 | AW24: =IF(AND(M24>0,AU24>0),(AU24/(Q24*1000)*1000),0) -> 859.69038 | AX24: =IF(AND(R24>0,AT24>0),(AT24/(R24*1000)*1000),0) -> 870.29149 | AY24: =IF(AND(S24>0,AU24>0),(AU24/(S24*1000)*1000),0) -> 893.05487 | AZ24: =+Listrik!S23 -> 24911.256 | BA24: =AZ24+BA23 -> 396620.21 | BB24: =IF(AND(L24>0,AZ24>0),(AZ24/(P24*1000)*1000),0) -> 457.69192 | BC24: =IF(AND(M24>0,BA24>0),(BA24/(Q24*1000)*1000),0) -> 534.89695 | BD24: =IF(AND(R24>0,AZ24>0),(AZ24/(R24*1000)*1000),0) -> 500.78916 | BE24: =IF(AND(S24>0,BA24>0),(BA24/(S24*1000)*1000),0) -> 555.65625 | BF24: =+Listrik!V23 -> 1424 | BG24: =BF24+BG23 -> 19437.3 | BH24: =IF(AND(L24>0,BF24>0),(BF24/(P24*1000)*1000),0) -> 26.163004 | BI24: =IF(AND(M24>0,BG24>0),(BG24/(Q24*1000)*1000),0) -> 26.213875 | BJ24: =IF(AND(R24>0,BF24>0),(BF24/(R24*1000)*1000),0) -> 28.626568 | BK24: =IF(AND(S24>0,BG24>0),(BG24/(S24*1000)*1000),0) -> 27.231233 | BL24: =+Efficiency2!K92 -> 55.396224 | BM24: =BM23+BL24 -> 829.57478 | BN24: =+R24/BL24 -> 0.89796734 | BO24: =+S24/BM24 -> 0.86042514
A25: =A24+1 -> 46039 | B25: Toilet | C25: 15/18/16 | D25: =+'17'!F42 -> 1069.0412 | E25: =+'17'!G42 -> 880.42734 | F25: =1-(E25/D25) -> 0.17643274 | G25: =+P25/N25 -> 0.86758856 | H25: =+P25/L25 -> 0.86758856 | I25: =+R25/P25 -> 1.0719426 | J25: =+R25/L25 -> 0.93000513 | K25: =+S25/M25 -> 0.83376964 | L25: =+SUM(Efficiency1!K97:K99) -> 55.257759 | M25: =M24+L25 -> 917.7319 | N25: =+SUM(Efficiency1!C97:C99) -> 55.257759 | O25: =O24+N25 -> 874.07037 | P25: ='17'!I38 -> 47.941 | Q25: =Q24+P25 -> 789.43 | R25: ='17'!I40 -> 51.39 | S25: =S24+R25 -> 765.177 | T25: =R25/P25 -> 1.0719426 | U25: =S25/Q25 -> 0.96927783 | V25: =R25/L25 -> 0.93000513 | W25: =S25/M25 -> 0.83376964 | AB25: =+[1]Report1!AY25 -> 5210.2065 | AC25: =AB25+AC24 -> 84302.711 | AD25: =AB25/P25 -> 108.67955 | AE25: =AC25/Q25 -> 106.78934 | AF25: =IF(AND(R25>0,AB25>0),(AB25/(R25*1000))*1000,0) -> 101.38561 | AG25: =IF(AND(S25>0,AC25>0),AC25/S25,0) -> 110.17413 | AH25: 63.8 | AI25: =AH25+AI24 -> 1070.1 | AJ25: =AH25/(P25) -> 1.3308024 | AK25: =AI25/(Q25) -> 1.355535 | AL25: =IF(AND(R25>0,AH25>0),AH25/(R25),0) -> 1.2414867 | AM25: =IF(AND(S25>0,AI25>0),AI25/(S25),0) -> 1.3985 | AN25: 0 | AO25: =AN25+AO24 -> 9 | AP25: =AN25/(P25) -> 0 | AQ25: =AO25/(Q25) -> 0.011400631 | AR25: =IF(AND(R25>0,AN25>0),AN25/(R25),0) -> 0 | AS25: =IF(AND(S25>0,AO25>0),AO25/(S25),0) -> 0.011761984 | AT25: ='17'!I46 -> 37880.24 | AU25: =AT25+AU24 -> 675331.2 | AV25: =IF(AND(L25>0,AT25>0),(AT25/(P25*1000)*1000),0) -> 790.14288 | AW25: =IF(AND(M25>0,AU25>0),(AU25/(Q25*1000)*1000),0) -> 855.46686 | AX25: =IF(AND(R25>0,AT25>0),(AT25/(R25*1000)*1000),0) -> 737.11306 | AY25: =IF(AND(S25>0,AU25>0),(AU25/(S25*1000)*1000),0) -> 882.58168 | AZ25: =+Listrik!S24 -> 25366.652 | BA25: =AZ25+BA24 -> 421986.86 | BB25: =IF(AND(L25>0,AZ25>0),(AZ25/(P25*1000)*1000),0) -> 529.1223 | BC25: =IF(AND(M25>0,BA25>0),(BA25/(Q25*1000)*1000),0) -> 534.54627 | BD25: =IF(AND(R25>0,AZ25>0),(AZ25/(R25*1000)*1000),0) -> 493.61066 | BE25: =IF(AND(S25>0,BA25>0),(BA25/(S25*1000)*1000),0) -> 551.48921 | BF25: =+Listrik!V24 -> 1452.4 | BG25: =BF25+BG24 -> 20889.7 | BH25: =IF(AND(L25>0,BF25>0),(BF25/(P25*1000)*1000),0) -> 30.295572 | BI25: =IF(AND(M25>0,BG25>0),(BG25/(Q25*1000)*1000),0) -> 26.461751 | BJ25: =IF(AND(R25>0,BF25>0),(BF25/(R25*1000)*1000),0) -> 28.262308 | BK25: =IF(AND(S25>0,BG25>0),(BG25/(S25*1000)*1000),0) -> 27.300481 | BL25: =+SUM(Efficiency2!K97:K99) -> 55.257759 | BM25: =BM24+BL25 -> 884.83254 | BN25: =+R25/BL25 -> 0.93000513 | BO25: =+S25/BM25 -> 0.86477041
A26: =A25+1 -> 46040 | B26: Toilet | C26: 16/20/14 | D26: =+'18'!F42 -> 1081.6111 | E26: =+'18'!G42 -> 882.54056 | F26: =1-(E26/D26) -> 0.18405003 | G26: =+P26/N26 -> 0.97419746 | H26: =+P26/L26 -> 0.97419746 | I26: =+R26/P26 -> 0.95610988 | J26: =+R26/L26 -> 0.93143981 | K26: =+S26/M26 -> 0.83920411 | L26: =+SUM(Efficiency1!K103:K105) -> 54.0722 | M26: =M25+L26 -> 971.8041 | N26: =+SUM(Efficiency1!C103:C105) -> 54.0722 | O26: =O25+N26 -> 928.14257 | P26: ='18'!I38 -> 52.677 | Q26: =Q25+P26 -> 842.107 | R26: ='18'!I40 -> 50.365 | S26: =S25+R26 -> 815.542 | T26: =R26/P26 -> 0.95610988 | U26: =S26/Q26 -> 0.96845413 | V26: =R26/L26 -> 0.93143981 | W26: =S26/M26 -> 0.83920411 | AB26: =+[1]Report1!AY26 -> 5381.9623 | AC26: =AB26+AC25 -> 89684.674 | AD26: =AB26/P26 -> 102.16911 | AE26: =AC26/Q26 -> 106.50033 | AF26: =IF(AND(R26>0,AB26>0),(AB26/(R26*1000))*1000,0) -> 106.85917 | AG26: =IF(AND(S26>0,AC26>0),AC26/S26,0) -> 109.96941 | AH26: 65.7 | AI26: =AH26+AI25 -> 1135.8 | AJ26: =AH26/(P26) -> 1.2472236 | AK26: =AI26/(Q26) -> 1.3487597 | AL26: =IF(AND(R26>0,AH26>0),AH26/(R26),0) -> 1.3044773 | AM26: =IF(AND(S26>0,AI26>0),AI26/(S26),0) -> 1.3926934 | AN26: 0 | AO26: =AN26+AO25 -> 9 | AP26: =AN26/(P26) -> 0 | AQ26: =AO26/(Q26) -> 0.010687478 | AR26: =IF(AND(R26>0,AN26>0),AN26/(R26),0) -> 0 | AS26: =IF(AND(S26>0,AO26>0),AO26/(S26),0) -> 0.011035606 | AT26: ='18'!I46 -> 41512.02 | AU26: =AT26+AU25 -> 716843.22 | AV26: =IF(AND(L26>0,AT26>0),(AT26/(P26*1000)*1000),0) -> 788.04829 | AW26: =IF(AND(M26>0,AU26>0),(AU26/(Q26*1000)*1000),0) -> 851.24957 | AX26: =IF(AND(R26>0,AT26>0),(AT26/(R26*1000)*1000),0) -> 824.22357 | AY26: =IF(AND(S26>0,AU26>0),(AU26/(S26*1000)*1000),0) -> 878.97769 | AZ26: =+Listrik!S25 -> 24979.086 | BA26: =AZ26+BA25 -> 446965.94 | BB26: =IF(AND(L26>0,AZ26>0),(AZ26/(P26*1000)*1000),0) -> 474.19341 | BC26: =IF(AND(M26>0,BA26>0),(BA26/(Q26*1000)*1000),0) -> 530.77096 | BD26: =IF(AND(R26>0,AZ26>0),(AZ26/(R26*1000)*1000),0) -> 495.9612 | BE26: =IF(AND(S26>0,BA26>0),(BA26/(S26*1000)*1000),0) -> 548.05999 | BF26: =+Listrik!V25 -> 1359.8 | BG26: =BF26+BG25 -> 22249.5 | BH26: =IF(AND(L26>0,BF26>0),(BF26/(P26*1000)*1000),0) -> 25.813923 | BI26: =IF(AND(M26>0,BG26>0),(BG26/(Q26*1000)*1000),0) -> 26.421227 | BJ26: =IF(AND(R26>0,BF26>0),(BF26/(R26*1000)*1000),0) -> 26.998908 | BK26: =IF(AND(S26>0,BG26>0),(BG26/(S26*1000)*1000),0) -> 27.281857 | BL26: =+SUM(Efficiency2!K103:K105) -> 54.0722 | BM26: =BM25+BL26 -> 938.90474 | BN26: =+R26/BL26 -> 0.93143981 | BO26: =+S26/BM26 -> 0.86860995
A27: =A26+1 -> 46041 | B27: Toilet | C27: 14/15 | D27: =+'19'!F42 -> 1185.1528 | E27: =+'19'!G42 -> 948.12222 | F27: =1-(E27/D27) -> 0.2 | G27: =+P27/N27 -> 0.96722319 | H27: =+P27/L27 -> 0.96722319 | I27: =+R27/P27 -> 0.98712262 | J27: =+R27/L27 -> 0.95476788 | K27: =+S27/M27 -> 0.84517104 | L27: =+SUM(Efficiency1!K108:K109) -> 52.909195 | M27: =M26+L27 -> 1024.7133 | N27: =+SUM(Efficiency1!C108:C109) -> 52.909195 | O27: =O26+N27 -> 981.05176 | P27: ='19'!I38 -> 51.175 | Q27: =Q26+P27 -> 893.282 | R27: ='19'!I40 -> 50.516 | S27: =S26+R27 -> 866.058 | T27: =R27/P27 -> 0.98712262 | U27: =S27/Q27 -> 0.96952362 | V27: =R27/L27 -> 0.95476788 | W27: =S27/M27 -> 0.84517104 | AB27: =+[1]Report1!AY27 -> 5813.3923 | AC27: =AB27+AC26 -> 95498.066 | AD27: =AB27/P27 -> 113.59829 | AE27: =AC27/Q27 -> 106.90696 | AF27: =IF(AND(R27>0,AB27>0),(AB27/(R27*1000))*1000,0) -> 115.08022 | AG27: =IF(AND(S27>0,AC27>0),AC27/S27,0) -> 110.26752 | AH27: 65.1 | AI27: =AH27+AI26 -> 1200.9 | AJ27: =AH27/(P27) -> 1.2721055 | AK27: =AI27/(Q27) -> 1.3443683 | AL27: =IF(AND(R27>0,AH27>0),AH27/(R27),0) -> 1.2887006 | AM27: =IF(AND(S27>0,AI27>0),AI27/(S27),0) -> 1.3866277 | AN27: 0 | AO27: =AN27+AO26 -> 9 | AP27: =AN27/(P27) -> 0 | AQ27: =AO27/(Q27) -> 0.010075206 | AR27: =IF(AND(R27>0,AN27>0),AN27/(R27),0) -> 0 | AS27: =IF(AND(S27>0,AO27>0),AO27/(S27),0) -> 0.010391914 | AT27: ='19'!I46 -> 42202.98 | AU27: =AT27+AU26 -> 759046.2 | AV27: =IF(AND(L27>0,AT27>0),(AT27/(P27*1000)*1000),0) -> 824.67963 | AW27: =IF(AND(M27>0,AU27>0),(AU27/(Q27*1000)*1000),0) -> 849.72741 | AX27: =IF(AND(R27>0,AT27>0),(AT27/(R27*1000)*1000),0) -> 835.43788 | AY27: =IF(AND(S27>0,AU27>0),(AU27/(S27*1000)*1000),0) -> 876.43807 | AZ27: =+Listrik!S26 -> 24339.091 | BA27: =AZ27+BA26 -> 471305.04 | BB27: =IF(AND(L27>0,AZ27>0),(AZ27/(P27*1000)*1000),0) -> 475.6051 | BC27: =IF(AND(M27>0,BA27>0),(BA27/(Q27*1000)*1000),0) -> 527.61058 | BD27: =IF(AND(R27>0,AZ27>0),(AZ27/(R27*1000)*1000),0) -> 481.80955 | BE27: =IF(AND(S27>0,BA27>0),(BA27/(S27*1000)*1000),0) -> 544.19569 | BF27: =+Listrik!V26 -> 1436.4 | BG27: =BF27+BG26 -> 23685.9 | BH27: =IF(AND(L27>0,BF27>0),(BF27/(P27*1000)*1000),0) -> 28.068393 | BI27: =IF(AND(M27>0,BG27>0),(BG27/(Q27*1000)*1000),0) -> 26.515591 | BJ27: =IF(AND(R27>0,BF27>0),(BF27/(R27*1000)*1000),0) -> 28.434555 | BK27: =IF(AND(S27>0,BG27>0),(BG27/(S27*1000)*1000),0) -> 27.349092 | BL27: =+SUM(Efficiency2!K108:K109) -> 52.909195 | BM27: =BM26+BL27 -> 991.81394 | BN27: =+R27/BL27 -> 0.95476788 | BO27: =+S27/BM27 -> 0.87320612
A28: =A27+1 -> 46042 | B28: Toilet | C28: 15 | D28: =+'20'!F42 -> 1183.3333 | E28: =+'20'!G42 -> 934.83333 | F28: =1-(E28/D28) -> 0.21 | G28: =+P28/N28 -> 0.99636388 | H28: =+P28/L28 -> 0.99636388 | I28: =+R28/P28 -> 0.99156478 | J28: =+R28/L28 -> 0.98795933 | K28: =+S28/M28 -> 0.85248564 | L28: =+Efficiency1!K113 -> 55.327176 | M28: =M27+L28 -> 1080.0405 | N28: =+Efficiency1!C113 -> 55.327176 | O28: =O27+N28 -> 1036.3789 | P28: ='20'!I38 -> 55.126 | Q28: =Q27+P28 -> 948.408 | R28: ='20'!I40 -> 54.661 | S28: =S27+R28 -> 920.719 | T28: =R28/P28 -> 0.99156478 | U28: =S28/Q28 -> 0.97080476 | V28: =R28/L28 -> 0.98795933 | W28: =S28/M28 -> 0.85248564 | AB28: =+[1]Report1!AY28 -> 5792.7104 | AC28: =AB28+AC27 -> 101290.78 | AD28: =AB28/P28 -> 105.08128 | AE28: =AC28/Q28 -> 106.80085 | AF28: =IF(AND(R28>0,AB28>0),(AB28/(R28*1000))*1000,0) -> 105.9752 | AG28: =IF(AND(S28>0,AC28>0),AC28/S28,0) -> 110.01269 | AH28: 67.1 | AI28: =AH28+AI27 -> 1268 | AJ28: =AH28/(P28) -> 1.2172115 | AK28: =AI28/(Q28) -> 1.3369773 | AL28: =IF(AND(R28>0,AH28>0),AH28/(R28),0) -> 1.2275663 | AM28: =IF(AND(S28>0,AI28>0),AI28/(S28),0) -> 1.3771846 | AN28: 0 | AO28: =AN28+AO27 -> 9 | AP28: =AN28/(P28) -> 0 | AQ28: =AO28/(Q28) -> 0.0094895868 | AR28: =IF(AND(R28>0,AN28>0),AN28/(R28),0) -> 0 | AS28: =IF(AND(S28>0,AO28>0),AO28/(S28),0) -> 0.0097749693 | AT28: ='20'!I46 -> 44065.32 | AU28: =AT28+AU27 -> 803111.52 | AV28: =IF(AND(L28>0,AT28>0),(AT28/(P28*1000)*1000),0) -> 799.35638 | AW28: =IF(AND(M28>0,AU28>0),(AU28/(Q28*1000)*1000),0) -> 846.79961 | AX28: =IF(AND(R28>0,AT28>0),(AT28/(R28*1000)*1000),0) -> 806.15649 | AY28: =IF(AND(S28>0,AU28>0),(AU28/(S28*1000)*1000),0) -> 872.26561 | AZ28: =+Listrik!S27 -> 22682.858 | BA28: =AZ28+BA27 -> 493987.89 | BB28: =IF(AND(L28>0,AZ28>0),(AZ28/(P28*1000)*1000),0) -> 411.47295 | BC28: =IF(AND(M28>0,BA28>0),(BA28/(Q28*1000)*1000),0) -> 520.86011 | BD28: =IF(AND(R28>0,AZ28>0),(AZ28/(R28*1000)*1000),0) -> 414.97334 | BE28: =IF(AND(S28>0,BA28>0),(BA28/(S28*1000)*1000),0) -> 536.52406 | BF28: =+Listrik!V27 -> 1374.1 | BG28: =BF28+BG27 -> 25060 | BH28: =IF(AND(L28>0,BF28>0),(BF28/(P28*1000)*1000),0) -> 24.926532 | BI28: =IF(AND(M28>0,BG28>0),(BG28/(Q28*1000)*1000),0) -> 26.423227 | BJ28: =IF(AND(R28>0,BF28>0),(BF28/(R28*1000)*1000),0) -> 25.138581 | BK28: =IF(AND(S28>0,BG28>0),(BG28/(S28*1000)*1000),0) -> 27.217859 | BL28: =+Efficiency2!K113 -> 55.327176 | BM28: =BM27+BL28 -> 1047.1411 | BN28: =+R28/BL28 -> 0.98795933 | BO28: =+S28/BM28 -> 0.87926927
A29: =A28+1 -> 46043 | B29: Toilet | C29: 15/13,5/13 | D29: =+'21'!F42 -> 1189.0278 | E29: =+'21'!G42 -> 939.33194 | F29: =1-(E29/D29) -> 0.21 | G29: =+P29/N29 -> 0.98267087 | H29: =+P29/L29 -> 0.96623524 | I29: =+R29/P29 -> 0.96810086 | J29: =+R29/L29 -> 0.93541317 | K29: =+S29/M29 -> 0.85646969 | L29: =+SUM(Efficiency1!K118:K120) -> 54.506395 | M29: =M28+L29 -> 1134.5469 | N29: =+SUM(Efficiency1!C118:C120) -> 53.59475 | O29: =O28+N29 -> 1089.9737 | P29: ='21'!I38 -> 52.666 | Q29: =Q28+P29 -> 1001.074 | R29: ='21'!I40 -> 50.986 | S29: =S28+R29 -> 971.705 | T29: =R29/P29 -> 0.96810086 | U29: =S29/Q29 -> 0.97066251 | V29: =R29/L29 -> 0.93541317 | W29: =S29/M29 -> 0.85646969 | AB29: =+[1]Report1!AY29 -> 5439.9798 | AC29: =AB29+AC28 -> 106730.76 | AD29: =AB29/P29 -> 103.29206 | AE29: =AC29/Q29 -> 106.61625 | AF29: =IF(AND(R29>0,AB29>0),(AB29/(R29*1000))*1000,0) -> 106.69556 | AG29: =IF(AND(S29>0,AC29>0),AC29/S29,0) -> 109.83864 | AH29: 67.8 | AI29: =AH29+AI28 -> 1335.8 | AJ29: =AH29/(P29) -> 1.2873581 | AK29: =AI29/(Q29) -> 1.3343669 | AL29: =IF(AND(R29>0,AH29>0),AH29/(R29),0) -> 1.3297768 | AM29: =IF(AND(S29>0,AI29>0),AI29/(S29),0) -> 1.3746971 | AN29: 0 | AO29: =AN29+AO28 -> 9 | AP29: =AN29/(P29) -> 0 | AQ29: =AO29/(Q29) -> 0.0089903444 | AR29: =IF(AND(R29>0,AN29>0),AN29/(R29),0) -> 0 | AS29: =IF(AND(S29>0,AO29>0),AO29/(S29),0) -> 0.0092620703 | AT29: ='21'!I46 -> 42495.38 | AU29: =AT29+AU28 -> 845606.9 | AV29: =IF(AND(L29>0,AT29>0),(AT29/(P29*1000)*1000),0) -> 806.88452 | AW29: =IF(AND(M29>0,AU29>0),(AU29/(Q29*1000)*1000),0) -> 844.69969 | AX29: =IF(AND(R29>0,AT29>0),(AT29/(R29*1000)*1000),0) -> 833.47154 | AY29: =IF(AND(S29>0,AU29>0),(AU29/(S29*1000)*1000),0) -> 870.23006 | AZ29: =+Listrik!S28 -> 26164.9 | BA29: =AZ29+BA28 -> 520152.79 | BB29: =IF(AND(L29>0,AZ29>0),(AZ29/(P29*1000)*1000),0) -> 496.80819 | BC29: =IF(AND(M29>0,BA29>0),(BA29/(Q29*1000)*1000),0) -> 519.59475 | BD29: =IF(AND(R29>0,AZ29>0),(AZ29/(R29*1000)*1000),0) -> 513.17813 | BE29: =IF(AND(S29>0,BA29>0),(BA29/(S29*1000)*1000),0) -> 535.29908 | BF29: =+Listrik!V28 -> 1419.8 | BG29: =BF29+BG28 -> 26479.8 | BH29: =IF(AND(L29>0,BF29>0),(BF29/(P29*1000)*1000),0) -> 26.958569 | BI29: =IF(AND(M29>0,BG29>0),(BG29/(Q29*1000)*1000),0) -> 26.451391 | BJ29: =IF(AND(R29>0,BF29>0),(BF29/(R29*1000)*1000),0) -> 27.84686 | BK29: =IF(AND(S29>0,BG29>0),(BG29/(S29*1000)*1000),0) -> 27.250863 | BL29: =+SUM(Efficiency2!K118:K120) -> 54.506395 | BM29: =BM28+BL29 -> 1101.6475 | BN29: =+R29/BL29 -> 0.93541317 | BO29: =+S29/BM29 -> 0.88204711
A30: =A29+1 -> 46044 | B30: Toilet | C30: 13 | D30: =+'22'!F42 -> 1276.6667 | E30: =+'22'!G42 -> 1008.5667 | F30: =1-(E30/D30) -> 0.21 | G30: =+P30/N30 -> 0.95839514 | H30: =+P30/L30 -> 0.95839514 | I30: =+R30/P30 -> 0.98677313 | J30: =+R30/L30 -> 0.94571857 | K30: =+S30/M30 -> 0.86033454 | L30: =+Efficiency1!K123 -> 51.354601 | M30: =M29+L30 -> 1185.9015 | N30: =+Efficiency1!C123 -> 51.354601 | O30: =O29+N30 -> 1141.3283 | P30: ='22'!I38 -> 49.218 | Q30: =Q29+P30 -> 1050.292 | R30: ='22'!I40 -> 48.567 | S30: =S29+R30 -> 1020.272 | T30: =R30/P30 -> 0.98677313 | U30: =S30/Q30 -> 0.97141747 | V30: =R30/L30 -> 0.94571857 | W30: =S30/M30 -> 0.86033454 | AB30: =+[1]Report1!AY30 -> 5708.1953 | AC30: =AB30+AC29 -> 112438.95 | AD30: =AB30/P30 -> 115.9778 | AE30: =AC30/Q30 -> 107.05494 | AF30: =IF(AND(R30>0,AB30>0),(AB30/(R30*1000))*1000,0) -> 117.53238 | AG30: =IF(AND(S30>0,AC30>0),AC30/S30,0) -> 110.20488 | AH30: 66.8 | AI30: =AH30+AI29 -> 1402.6 | AJ30: =AH30/(P30) -> 1.357227 | AK30: =AI30/(Q30) -> 1.3354381 | AL30: =IF(AND(R30>0,AH30>0),AH30/(R30),0) -> 1.3754195 | AM30: =IF(AND(S30>0,AI30>0),AI30/(S30),0) -> 1.3747314 | AN30: 0 | AO30: =AN30+AO29 -> 9 | AP30: =AN30/(P30) -> 0 | AQ30: =AO30/(Q30) -> 0.0085690456 | AR30: =IF(AND(R30>0,AN30>0),AN30/(R30),0) -> 0 | AS30: =IF(AND(S30>0,AO30>0),AO30/(S30),0) -> 0.0088211771 | AT30: ='22'!I46 -> 47332.34 | AU30: =AT30+AU29 -> 892939.24 | AV30: =IF(AND(L30>0,AT30>0),(AT30/(P30*1000)*1000),0) -> 961.68759 | AW30: =IF(AND(M30>0,AU30>0),(AU30/(Q30*1000)*1000),0) -> 850.18189 | AX30: =IF(AND(R30>0,AT30>0),(AT30/(R30*1000)*1000),0) -> 974.57821 | AY30: =IF(AND(S30>0,AU30>0),(AU30/(S30*1000)*1000),0) -> 875.19724 | AZ30: =+Listrik!S29 -> 20304 | BA30: =AZ30+BA29 -> 540456.79 | BB30: =IF(AND(L30>0,AZ30>0),(AZ30/(P30*1000)*1000),0) -> 412.532 | BC30: =IF(AND(M30>0,BA30>0),(BA30/(Q30*1000)*1000),0) -> 514.57765 | BD30: =IF(AND(R30>0,AZ30>0),(AZ30/(R30*1000)*1000),0) -> 418.06165 | BE30: =IF(AND(S30>0,BA30>0),(BA30/(S30*1000)*1000),0) -> 529.71834 | BF30: =+Listrik!V29 -> 1410.1 | BG30: =BF30+BG29 -> 27889.9 | BH30: =IF(AND(L30>0,BF30>0),(BF30/(P30*1000)*1000),0) -> 28.650087 | BI30: =IF(AND(M30>0,BG30>0),(BG30/(Q30*1000)*1000),0) -> 26.554425 | BJ30: =IF(AND(R30>0,BF30>0),(BF30/(R30*1000)*1000),0) -> 29.034118 | BK30: =IF(AND(S30>0,BG30>0),(BG30/(S30*1000)*1000),0) -> 27.33575 | BL30: =+Efficiency2!K123 -> 51.354601 | BM30: =BM29+BL30 -> 1153.0021 | BN30: =+R30/BL30 -> 0.94571857 | BO30: =+S30/BM30 -> 0.88488303
A31: =A30+1 -> 46045 | B31: Toilet | C31: 13/13,5 | D31: =+'23'!F42 -> 1162.3472 | E31: =+'23'!G42 -> 918.25431 | F31: =1-(E31/D31) -> 0.21 | G31: =+P31/N31 -> 0.98417311 | H31: =+P31/L31 -> 0.90091921 | I31: =+R31/P31 -> 1.0043947 | J31: =+R31/L31 -> 0.90487852 | K31: =+S31/M31 -> 0.86215439 | L31: =+SUM(Efficiency1!K128:K129) -> 50.513963 | M31: =M30+L31 -> 1236.4154 | N31: =+SUM(Efficiency1!C128:C129) -> 46.240849 | O31: =O30+N31 -> 1187.5691 | P31: ='23'!I38 -> 45.509 | Q31: =Q30+P31 -> 1095.801 | R31: ='23'!I40 -> 45.709 | S31: =S30+R31 -> 1065.981 | T31: =R31/P31 -> 1.0043947 | U31: =S31/Q31 -> 0.97278703 | V31: =R31/L31 -> 0.90487852 | W31: =S31/M31 -> 0.86215439 | AB31: =+[1]Report1!AY31 -> 4071.2316 | AC31: =AB31+AC30 -> 116510.18 | AD31: =AB31/P31 -> 89.459922 | AE31: =AC31/Q31 -> 106.32422 | AF31: =IF(AND(R31>0,AB31>0),(AB31/(R31*1000))*1000,0) -> 89.06849 | AG31: =IF(AND(S31>0,AC31>0),AC31/S31,0) -> 109.29856 | AH31: 70.5 | AI31: =AH31+AI30 -> 1473.1 | AJ31: =AH31/(P31) -> 1.5491441 | AK31: =AI31/(Q31) -> 1.3443134 | AL31: =IF(AND(R31>0,AH31>0),AH31/(R31),0) -> 1.5423658 | AM31: =IF(AND(S31>0,AI31>0),AI31/(S31),0) -> 1.3819196 | AN31: 0 | AO31: =AN31+AO30 -> 9 | AP31: =AN31/(P31) -> 0 | AQ31: =AO31/(Q31) -> 0.0082131701 | AR31: =IF(AND(R31>0,AN31>0),AN31/(R31),0) -> 0 | AS31: =IF(AND(S31>0,AO31>0),AO31/(S31),0) -> 0.0084429272 | AT31: ='23'!I46 -> 43269.68 | AU31: =AT31+AU30 -> 936208.92 | AV31: =IF(AND(L31>0,AT31>0),(AT31/(P31*1000)*1000),0) -> 950.79391 | AW31: =IF(AND(M31>0,AU31>0),(AU31/(Q31*1000)*1000),0) -> 854.36034 | AX31: =IF(AND(R31>0,AT31>0),(AT31/(R31*1000)*1000),0) -> 946.6337 | AY31: =IF(AND(S31>0,AU31>0),(AU31/(S31*1000)*1000),0) -> 878.26042 | AZ31: =+Listrik!S30 -> 20655 | BA31: =AZ31+BA30 -> 561111.79 | BB31: =IF(AND(L31>0,AZ31>0),(AZ31/(P31*1000)*1000),0) -> 453.86627 | BC31: =IF(AND(M31>0,BA31>0),(BA31/(Q31*1000)*1000),0) -> 512.05629 | BD31: =IF(AND(R31>0,AZ31>0),(AZ31/(R31*1000)*1000),0) -> 451.88037 | BE31: =IF(AND(S31>0,BA31>0),(BA31/(S31*1000)*1000),0) -> 526.38067 | BF31: =+Listrik!V30 -> 1400.1 | BG31: =BF31+BG30 -> 29290 | BH31: =IF(AND(L31>0,BF31>0),(BF31/(P31*1000)*1000),0) -> 30.765343 | BI31: =IF(AND(M31>0,BG31>0),(BG31/(Q31*1000)*1000),0) -> 26.729306 | BJ31: =IF(AND(R31>0,BF31>0),(BF31/(R31*1000)*1000),0) -> 30.630729 | BK31: =IF(AND(S31>0,BG31>0),(BG31/(S31*1000)*1000),0) -> 27.477038 | BL31: =+SUM(Efficiency2!K128:K129) -> 46.240849 | BM31: =BM30+BL31 -> 1199.243 | BN31: =+R31/BL31 -> 0.98849829 | BO31: =+S31/BM31 -> 0.88887826
