Workbook

Sheet eff all value

Sheet eff all value (2)

Sheet Report1
A3: PAPER MACHINE 15 DAILY REPORT 1
A6: DATE | B6: GRADE | C6: GSM | D6: Speed yankee (mpm) | E6: Speed reel (mpm) | F6: Creep ( % ) | G6: Real Eff PM ( % ) | H6: Real Eff PM vs Target (%) | I6: Real Eff FG vs Real Eff PM (%) | J6: Eff FG vs Target (%) | L6: Kapasitas Target (ton) | N6: Kapasitas Teori Real (ton) | P6: PM PROD Timbangan (TON) | R6: FINSHED GOODS (TON) | T6: NET GROSS (Timbangan) (%) | V6: NET GROSS ( Scanner) (%) | X6: FRESH WATER | AB6: GAS HOOD | AH6: STEAM (TON) | AN6: STEAM (TON) DEINKING | AT6: POWER (kWh) | AZ6: POWER (kWh) DEINKING | BF6: POWER WPL (kWh) | BL6: Kapasitas Running (ton) | BN6: Eff FG vs Target Running(%)
X7: CONSUMPTION | Z7: /TON FG. | AB7: CONSUMPTION | AD7: /TON PM. | AF7: /TON FG. | AH7: CONSUMPTION | AJ7: /TON PM. | AL7: /TON FG. | AN7: CONSUMPTION | AP7: /TON PM. | AR7: /TON FG. | AT7: CONSUMPTION | AV7: /TON PM | AX7: /TON FG | AZ7: CONSUMPTION | BB7: /TON PM | BD7: /TON FG | BF7: CONSUMPTION | BH7: /TON PM | BJ7: /TON FG
J8: TODAY | K8: TODATE | L8: TODAY | M8: TODATE | N8: TODAY | O8: TODATE | P8: TODAY | Q8: TODATE | R8: TODAY | S8: TODATE | T8: TODAY | U8: TODATE | V8: TODAY | W8: TODATE | X8: TODAY | Y8: TODATE | Z8: TODAY | AA8: TODATE | AB8: TODAY | AC8: TODATE | AD8: TODAY | AE8: TODATE | AF8: TODAY | AG8: TODATE | AH8: TODAY | AI8: TODATE | AJ8: TODAY | AK8: TODATE | AL8: TODAY | AM8: TODATE | AN8: TODAY | AO8: TODATE | AP8: TODAY | AQ8: TODATE | AR8: TODAY | AS8: TODATE | AT8: TODAY | AU8: TODATE | AV8: TODAY | AW8: TODATE | AX8: TODAY | AY8: TODATE | AZ8: TODAY | BA8: TODATE | BB8: TODAY | BC8: TODATE | BD8: TODAY | BE8: TODATE | BF8: TODAY | BG8: TODATE | BH8: TODAY | BI8: TODATE | BJ8: TODAY | BK8: TODATE | BL8: TODAY | BM8: TODATE | BN8: TODAY | BO8: TODATE
A9: 46082 | B9: Toilet | C9: 14/15,5 | D9: =+'1'!F42 -> 1048.6682 | E9: =+'1'!G42 -> 796.9878 | F9: =1-(E9/D9) -> 0.24 | G9: =+P9/N9 -> 0.84390104 | H9: =+P9/L9 -> 0.7325231 | I9: =+R9/P9 -> 0.89894465 | J9: =+R9/L9 -> 0.65849772 | K9: =+S9/M9 -> 0.65849772 | L9: =+SUM(Efficiency1!K6:K7) -> 53.940961 | M9: =L9 -> 53.940961 | N9: =+SUM(Efficiency1!C6:C7) -> 46.821841 | O9: =N9 -> 46.821841 | P9: ='1'!I38 -> 39.513 | Q9: =P9 -> 39.513 | R9: ='1'!I40 -> 35.52 | S9: =R9 -> 35.52 | T9: =R9/P9 -> 0.89894465 | U9: =S9/Q9 -> 0.89894465 | V9: =R9/L9 -> 0.65849772 | W9: =S9/M9 -> 0.65849772 | AB9: =+[1]Report1!AY9 -> 4216.8386 | AC9: =AB9 -> 4216.8386 | AD9: =AB9/P9 -> 106.72028 | AE9: =AC9/Q9 -> 106.72028 | AF9: =IF(AND(R9>0,AB9>0),(AB9/(R9*1000))*1000,0) -> 118.7173 | AG9: =IF(AND(S9>0,AC9>0),AC9/S9,0) -> 118.7173 | AH9: 59 | AI9: =AH9 -> 59 | AJ9: =AH9/(P9) -> 1.4931795 | AK9: =AI9/(Q9) -> 1.4931795 | AL9: =IF(AND(R9>0,AH9>0),AH9/(R9),0) -> 1.661036 | AM9: =IF(AND(S9>0,AI9>0),AI9/(S9),0) -> 1.661036 | AN9: 0 | AO9: =AN9 -> 0 | AP9: =AN9/(P9) -> 0 | AQ9: =AO9/(Q9) -> 0 | AR9: =IF(AND(R9>0,AN9>0),AN9/(R9),0) -> 0 | AS9: =IF(AND(S9>0,AO9>0),AO9/(S9),0) -> 0 | AT9: ='1'!I46 -> 36680.9 | AU9: =AT9 -> 36680.9 | AV9: =IF(AND(L9>0,AT9>0),(AT9/(P9*1000)*1000),0) -> 928.32486 | AW9: =IF(AND(M9>0,AU9>0),(AU9/(Q9*1000)*1000),0) -> 928.32486 | AX9: =IF(AND(R9>0,AT9>0),(AT9/(R9*1000)*1000),0) -> 1032.683 | AY9: =IF(AND(S9>0,AU9>0),(AU9/(S9*1000)*1000),0) -> 1032.683 | AZ9: =+Listrik!S8 -> 15252.6 | BA9: =AZ9 -> 15252.6 | BB9: =IF(AND(L9>0,AZ9>0),(AZ9/(P9*1000)*1000),0) -> 386.01473 | BC9: =IF(AND(M9>0,BA9>0),(BA9/(Q9*1000)*1000),0) -> 386.01473 | BD9: =IF(AND(R9>0,AZ9>0),(AZ9/(R9*1000)*1000),0) -> 429.40878 | BE9: =IF(AND(S9>0,BA9>0),(BA9/(S9*1000)*1000),0) -> 429.40878 | BG9: =BF9 -> 0 | BH9: =IF(AND(L9>0,BF9>0),(BF9/(P9*1000)*1000),0) -> 0 | BI9: =IF(AND(U9>0,BG9>0),(BG9/(Q9*1000)*1000),0) -> 0 | BJ9: =IF(AND(L9>0,BF9>0),(BF9/(R9*1000)*1000),0) -> 0 | BK9: =IF(AND(AA9>0,BG9>0),(BG9/(S9*1000)*1000),0) -> 0 | BL9: =+SUM(Efficiency2!K6:K7) -> 53.940961 | BM9: =BL9 -> 53.940961 | BN9: =+R9/BL9 -> 0.65849772 | BO9: =+S9/BM9 -> 0.65849772
A10: =A9+1 -> 46083 | B10: Toilet | C10: 15,5 | D10: =+'2'!F42 -> 1000 | E10: =+'2'!G42 -> 760 | F10: =1-(E10/D10) -> 0.24 | G10: =+P10/N10 -> 0.54426012 | H10: =+P10/L10 -> 0.46113455 | I10: =+R10/P10 -> 1.141741 | J10: =+R10/L10 -> 0.52649622 | K10: =+S10/M10 -> 0.59248734 | L10: =+Efficiency1!K12 -> 53.956703 | M10: =M9+L10 -> 107.89766 | N10: =+Efficiency1!C12 -> 45.715824 | O10: =O9+N10 -> 92.537665 | P10: ='2'!I38 -> 24.8813 | Q10: =Q9+P10 -> 64.3943 | R10: ='2'!I40 -> 28.408 | S10: =S9+R10 -> 63.928 | T10: =R10/P10 -> 1.141741 | U10: =S10/Q10 -> 0.99275868 | V10: =R10/L10 -> 0.52649622 | W10: =S10/M10 -> 0.59248734 | AB10: =+[1]Report1!AY10 -> 3311.0567 | AC10: =AB10+AC9 -> 7527.8953 | AD10: =AB10/P10 -> 133.0741 | AE10: =AC10/Q10 -> 116.90313 | AF10: =IF(AND(R10>0,AB10>0),(AB10/(R10*1000))*1000,0) -> 116.55367 | AG10: =IF(AND(S10>0,AC10>0),AC10/S10,0) -> 117.75584 | AH10: 50.5 | AI10: =AH10+AI9 -> 109.5 | AJ10: =AH10/(P10) -> 2.0296367 | AK10: =AI10/(Q10) -> 1.7004611 | AL10: =IF(AND(R10>0,AH10>0),AH10/(R10),0) -> 1.7776683 | AM10: =IF(AND(S10>0,AI10>0),AI10/(S10),0) -> 1.7128645 | AN10: 0 | AO10: =AN10+AO9 -> 0 | AP10: =AN10/(P10) -> 0 | AQ10: =AO10/(Q10) -> 0 | AR10: =IF(AND(R10>0,AN10>0),AN10/(R10),0) -> 0 | AS10: =IF(AND(S10>0,AO10>0),AO10/(S10),0) -> 0 | AT10: ='2'!I46 -> 28571.7 | AU10: =AT10+AU9 -> 65252.6 | AV10: =IF(AND(L10>0,AT10>0),(AT10/(P10*1000)*1000),0) -> 1148.3202 | AW10: =IF(AND(M10>0,AU10>0),(AU10/(Q10*1000)*1000),0) -> 1013.3288 | AX10: =IF(AND(R10>0,AT10>0),(AT10/(R10*1000)*1000),0) -> 1005.7625 | AY10: =IF(AND(S10>0,AU10>0),(AU10/(S10*1000)*1000),0) -> 1020.7202 | AZ10: =+Listrik!S9 -> 16604 | BA10: =AZ10+BA9 -> 31856.6 | BB10: =IF(AND(L10>0,AZ10>0),(AZ10/(P10*1000)*1000),0) -> 667.32848 | BC10: =IF(AND(M10>0,BA10>0),(BA10/(Q10*1000)*1000),0) -> 494.71149 | BD10: =IF(AND(R10>0,AZ10>0),(AZ10/(R10*1000)*1000),0) -> 584.48324 | BE10: =IF(AND(S10>0,BA10>0),(BA10/(S10*1000)*1000),0) -> 498.31998 | BG10: =BF10+BG9 -> 0 | BH10: =IF(AND(L10>0,BF10>0),(BF10/(P10*1000)*1000),0) -> 0 | BI10: =IF(AND(U10>0,BG10>0),(BG10/(Q10*1000)*1000),0) -> 0 | BJ10: =IF(AND(L10>0,BF10>0),(BF10/(R10*1000)*1000),0) -> 0 | BK10: =IF(AND(AA10>0,BG10>0),(BG10/(S10*1000)*1000),0) -> 0 | BL10: =+Efficiency2!K12 -> 53.956703 | BM10: =BM9+BL10 -> 107.89766 | BN10: =+R10/BL10 -> 0.52649622 | BO10: =+S10/BM10 -> 0.59248734
A11: =A10+1 -> 46084 | B11: Toilet | C11: 15,5/14 | D11: =+'3'!F42 -> 1001.0417 | E11: =+'3'!G42 -> 770.80208 | F11: =1-(E11/D11) -> 0.23 | G11: =+P11/N11 -> 0.99541287 | H11: =+P11/L11 -> 0.80440441 | I11: =+R11/P11 -> 0.9286137 | J11: =+R11/L11 -> 0.74698095 | K11: =+S11/M11 -> 0.64440541 | L11: =+SUM(Efficiency1!K19:K20) -> 54.611834 | M11: =M10+L11 -> 162.5095 | N11: =+SUM(Efficiency1!C19:C20) -> 44.132441 | O11: =O10+N11 -> 136.67011 | P11: ='3'!I38 -> 43.93 | Q11: =Q10+P11 -> 108.3243 | R11: ='3'!I40 -> 40.794 | S11: =S10+R11 -> 104.722 | T11: =R11/P11 -> 0.9286137 | U11: =S11/Q11 -> 0.96674523 | V11: =R11/L11 -> 0.74698095 | W11: =S11/M11 -> 0.64440541 | AB11: =+[1]Report1!AY11 -> 4290.7663 | AC11: =AB11+AC10 -> 11818.662 | AD11: =AB11/P11 -> 97.672805 | AE11: =AC11/Q11 -> 109.10444 | AF11: =IF(AND(R11>0,AB11>0),(AB11/(R11*1000))*1000,0) -> 105.18131 | AG11: =IF(AND(S11>0,AC11>0),AC11/S11,0) -> 112.85749 | AH11: 62 | AI11: =AH11+AI10 -> 171.5 | AJ11: =AH11/(P11) -> 1.4113362 | AK11: =AI11/(Q11) -> 1.5832089 | AL11: =IF(AND(R11>0,AH11>0),AH11/(R11),0) -> 1.5198313 | AM11: =IF(AND(S11>0,AI11>0),AI11/(S11),0) -> 1.6376693 | AN11: 0 | AO11: =AN11+AO10 -> 0 | AP11: =AN11/(P11) -> 0 | AQ11: =AO11/(Q11) -> 0 | AR11: =IF(AND(R11>0,AN11>0),AN11/(R11),0) -> 0 | AS11: =IF(AND(S11>0,AO11>0),AO11/(S11),0) -> 0 | AT11: ='3'!I46 -> 39136.98 | AU11: =AT11+AU10 -> 104389.58 | AV11: =IF(AND(L11>0,AT11>0),(AT11/(P11*1000)*1000),0) -> 890.89415 | AW11: =IF(AND(M11>0,AU11>0),(AU11/(Q11*1000)*1000),0) -> 963.67648 | AX11: =IF(AND(R11>0,AT11>0),(AT11/(R11*1000)*1000),0) -> 959.38079 | AY11: =IF(AND(S11>0,AU11>0),(AU11/(S11*1000)*1000),0) -> 996.82569 | AZ11: =+Listrik!S10 -> 18999 | BA11: =AZ11+BA10 -> 50855.6 | BB11: =IF(AND(L11>0,AZ11>0),(AZ11/(P11*1000)*1000),0) -> 432.4835 | BC11: =IF(AND(M11>0,BA11>0),(BA11/(Q11*1000)*1000),0) -> 469.47545 | BD11: =IF(AND(R11>0,AZ11>0),(AZ11/(R11*1000)*1000),0) -> 465.73025 | BE11: =IF(AND(S11>0,BA11>0),(BA11/(S11*1000)*1000),0) -> 485.6248 | BG11: =BF11+BG10 -> 0 | BH11: =IF(AND(L11>0,BF11>0),(BF11/(P11*1000)*1000),0) -> 0 | BI11: =IF(AND(U11>0,BG11>0),(BG11/(Q11*1000)*1000),0) -> 0 | BJ11: =IF(AND(L11>0,BF11>0),(BF11/(R11*1000)*1000),0) -> 0 | BK11: =IF(AND(AA11>0,BG11>0),(BG11/(S11*1000)*1000),0) -> 0 | BL11: =+SUM(Efficiency2!K19:K20) -> 54.611834 | BM11: =BM10+BL11 -> 162.5095 | BN11: =+R11/BL11 -> 0.74698095 | BO11: =+S11/BM11 -> 0.64440541
A12: =A11+1 -> 46085 | B12: Toilet | C12: 14/15,5 | D12: =+'4'!F42 -> 1000 | E12: =+'4'!G42 -> 763.77953 | F12: =1-(E12/D12) -> 0.23622047 | G12: =+P12/N12 -> 0.84485969 | H12: =+P12/L12 -> 0.7072162 | I12: =+R12/P12 -> 0.99451726 | J12: =+R12/L12 -> 0.70333872 | K12: =+S12/M12 -> 0.65913649 | L12: =+SUM(Efficiency1!K25:K26) -> 54.158827 | M12: =M11+L12 -> 216.66833 | N12: =+SUM(Efficiency1!C25:C26) -> 45.335338 | O12: =O11+N12 -> 182.00544 | P12: ='4'!I38 -> 38.302 | Q12: =Q11+P12 -> 146.6263 | R12: ='4'!I40 -> 38.092 | S12: =S11+R12 -> 142.814 | T12: =R12/P12 -> 0.99451726 | U12: =S12/Q12 -> 0.97399989 | V12: =R12/L12 -> 0.70333872 | W12: =S12/M12 -> 0.65913649 | AB12: =+[1]Report1!AY12 -> 3774.0961 | AC12: =AB12+AC11 -> 15592.758 | AD12: =AB12/P12 -> 98.535224 | AE12: =AC12/Q12 -> 106.34353 | AF12: =IF(AND(R12>0,AB12>0),(AB12/(R12*1000))*1000,0) -> 99.078445 | AG12: =IF(AND(S12>0,AC12>0),AC12/S12,0) -> 109.18228 | AH12: 59.3 | AI12: =AH12+AI11 -> 230.8 | AJ12: =AH12/(P12) -> 1.548222 | AK12: =AI12/(Q12) -> 1.5740696 | AL12: =IF(AND(R12>0,AH12>0),AH12/(R12),0) -> 1.5567573 | AM12: =IF(AND(S12>0,AI12>0),AI12/(S12),0) -> 1.6160881 | AN12: 0 | AO12: =AN12+AO11 -> 0 | AP12: =AN12/(P12) -> 0 | AQ12: =AO12/(Q12) -> 0 | AR12: =IF(AND(R12>0,AN12>0),AN12/(R12),0) -> 0 | AS12: =IF(AND(S12>0,AO12>0),AO12/(S12),0) -> 0 | AT12: ='4'!I46 -> 34663.36 | AU12: =AT12+AU11 -> 139052.94 | AV12: =IF(AND(L12>0,AT12>0),(AT12/(P12*1000)*1000),0) -> 905.00131 | AW12: =IF(AND(M12>0,AU12>0),(AU12/(Q12*1000)*1000),0) -> 948.34924 | AX12: =IF(AND(R12>0,AT12>0),(AT12/(R12*1000)*1000),0) -> 909.99055 | AY12: =IF(AND(S12>0,AU12>0),(AU12/(S12*1000)*1000),0) -> 973.66463 | AZ12: =+Listrik!S11 -> 20677.899 | BA12: =AZ12+BA11 -> 71533.499 | BB12: =IF(AND(L12>0,AZ12>0),(AZ12/(P12*1000)*1000),0) -> 539.86473 | BC12: =IF(AND(M12>0,BA12>0),(BA12/(Q12*1000)*1000),0) -> 487.86268 | BD12: =IF(AND(R12>0,AZ12>0),(AZ12/(R12*1000)*1000),0) -> 542.84099 | BE12: =IF(AND(S12>0,BA12>0),(BA12/(S12*1000)*1000),0) -> 500.88576 | BG12: =BF12+BG11 -> 0 | BH12: =IF(AND(L12>0,BF12>0),(BF12/(P12*1000)*1000),0) -> 0 | BI12: =IF(AND(U12>0,BG12>0),(BG12/(Q12*1000)*1000),0) -> 0 | BJ12: =IF(AND(L12>0,BF12>0),(BF12/(R12*1000)*1000),0) -> 0 | BK12: =IF(AND(AA12>0,BG12>0),(BG12/(S12*1000)*1000),0) -> 0 | BL12: =+SUM(Efficiency2!K25:K26) -> 54.158827 | BM12: =BM11+BL12 -> 216.66833 | BN12: =+R12/BL12 -> 0.70333872 | BO12: =+S12/BM12 -> 0.65913649
A13: =A12+1 -> 46086 | B13: Toilet | C13: 15,5/13,5 | D13: =+'5'!F42 -> 1000 | E13: =+'5'!G42 -> 770 | F13: =1-(E13/D13) -> 0.23 | G13: =+P13/N13 -> 0.94274705 | H13: =+P13/L13 -> 0.78734439 | I13: =+R13/P13 -> 1.0195386 | J13: =+R13/L13 -> 0.80272801 | K13: =+S13/M13 -> 0.68776414 | L13: =+SUM(Efficiency1!K32:K33) -> 53.953518 | M13: =M12+L13 -> 270.62184 | N13: =+SUM(Efficiency1!C32:C33) -> 45.059807 | O13: =O12+N13 -> 227.06525 | P13: ='5'!I38 -> 42.48 | Q13: =Q12+P13 -> 189.1063 | R13: ='5'!I40 -> 43.31 | S13: =S12+R13 -> 186.124 | T13: =R13/P13 -> 1.0195386 | U13: =S13/Q13 -> 0.9842295 | V13: =R13/L13 -> 0.80272801 | W13: =S13/M13 -> 0.68776414 | AB13: =+[1]Report1!AY13 -> 4091.4503 | AC13: =AB13+AC12 -> 19684.208 | AD13: =AB13/P13 -> 96.314743 | AE13: =AC13/Q13 -> 104.0907 | AF13: =IF(AND(R13>0,AB13>0),(AB13/(R13*1000))*1000,0) -> 94.468951 | AG13: =IF(AND(S13>0,AC13>0),AC13/S13,0) -> 105.75857 | AH13: 64.3 | AI13: =AH13+AI12 -> 295.1 | AJ13: =AH13/(P13) -> 1.5136535 | AK13: =AI13/(Q13) -> 1.560498 | AL13: =IF(AND(R13>0,AH13>0),AH13/(R13),0) -> 1.4846456 | AM13: =IF(AND(S13>0,AI13>0),AI13/(S13),0) -> 1.5855021 | AN13: 0 | AO13: =AN13+AO12 -> 0 | AP13: =AN13/(P13) -> 0 | AQ13: =AO13/(Q13) -> 0 | AR13: =IF(AND(R13>0,AN13>0),AN13/(R13),0) -> 0 | AS13: =IF(AND(S13>0,AO13>0),AO13/(S13),0) -> 0 | AT13: ='5'!I46 -> 39057.42 | AU13: =AT13+AU12 -> 178110.36 | AV13: =IF(AND(L13>0,AT13>0),(AT13/(P13*1000)*1000),0) -> 919.43079 | AW13: =IF(AND(M13>0,AU13>0),(AU13/(Q13*1000)*1000),0) -> 941.85313 | AX13: =IF(AND(R13>0,AT13>0),(AT13/(R13*1000)*1000),0) -> 901.81067 | AY13: =IF(AND(S13>0,AU13>0),(AU13/(S13*1000)*1000),0) -> 956.94462 | AZ13: =+Listrik!S12 -> 20494.485 | BA13: =AZ13+BA12 -> 92027.984 | BB13: =IF(AND(L13>0,AZ13>0),(AZ13/(P13*1000)*1000),0) -> 482.45021 | BC13: =IF(AND(M13>0,BA13>0),(BA13/(Q13*1000)*1000),0) -> 486.64684 | BD13: =IF(AND(R13>0,AZ13>0),(AZ13/(R13*1000)*1000),0) -> 473.20446 | BE13: =IF(AND(S13>0,BA13>0),(BA13/(S13*1000)*1000),0) -> 494.44448 | BG13: =BF13+BG12 -> 0 | BH13: =IF(AND(L13>0,BF13>0),(BF13/(P13*1000)*1000),0) -> 0 | BI13: =IF(AND(U13>0,BG13>0),(BG13/(Q13*1000)*1000),0) -> 0 | BJ13: =IF(AND(L13>0,BF13>0),(BF13/(R13*1000)*1000),0) -> 0 | BK13: =IF(AND(AA13>0,BG13>0),(BG13/(S13*1000)*1000),0) -> 0 | BL13: =+SUM(Efficiency2!K32:K33) -> 53.953518 | BM13: =BM12+BL13 -> 270.62184 | BN13: =+R13/BL13 -> 0.80272801 | BO13: =+S13/BM13 -> 0.68776414
A14: =A13+1 -> 46087 | B14: Toilet | C14: 13,5/20/14 | D14: =+'6'!F42 -> 1000 | E14: =+'6'!G42 -> 820 | F14: =1-(E14/D14) -> 0.18 | G14: =+P14/N14 -> 0.62109467 | H14: =+P14/L14 -> 0.49252936 | I14: =+R14/P14 -> 1.0017321 | J14: =+R14/L14 -> 0.49338248 | K14: =+S14/M14 -> 0.65546939 | L14: =+SUM(Efficiency1!K38:K40) -> 53.919629 | M14: =M13+L14 -> 324.54147 | N14: =+SUM(Efficiency1!C38:C40) -> 42.758377 | O14: =O13+N14 -> 269.82363 | P14: ='6'!I38 -> 26.557 | Q14: =Q13+P14 -> 215.6633 | R14: ='6'!I40 -> 26.603 | S14: =S13+R14 -> 212.727 | T14: =R14/P14 -> 1.0017321 | U14: =S14/Q14 -> 0.9863848 | V14: =R14/L14 -> 0.49338248 | W14: =S14/M14 -> 0.65546939 | AB14: =+[1]Report1!AY14 -> 2299.8884 | AC14: =AB14+AC13 -> 21984.096 | AD14: =AB14/P14 -> 86.601966 | AE14: =AC14/Q14 -> 101.93712 | AF14: =IF(AND(R14>0,AB14>0),(AB14/(R14*1000))*1000,0) -> 86.45222 | AG14: =IF(AND(S14>0,AC14>0),AC14/S14,0) -> 103.34418 | AH14: 46.5 | AI14: =AH14+AI13 -> 341.6 | AJ14: =AH14/(P14) -> 1.7509508 | AK14: =AI14/(Q14) -> 1.5839505 | AL14: =IF(AND(R14>0,AH14>0),AH14/(R14),0) -> 1.7479232 | AM14: =IF(AND(S14>0,AI14>0),AI14/(S14),0) -> 1.605814 | AN14: 0 | AO14: =AN14+AO13 -> 0 | AP14: =AN14/(P14) -> 0 | AQ14: =AO14/(Q14) -> 0 | AR14: =IF(AND(R14>0,AN14>0),AN14/(R14),0) -> 0 | AS14: =IF(AND(S14>0,AO14>0),AO14/(S14),0) -> 0 | AT14: ='6'!I46 -> 26909.02 | AU14: =AT14+AU13 -> 205019.38 | AV14: =IF(AND(L14>0,AT14>0),(AT14/(P14*1000)*1000),0) -> 1013.2553 | AW14: =IF(AND(M14>0,AU14>0),(AU14/(Q14*1000)*1000),0) -> 950.64566 | AX14: =IF(AND(R14>0,AT14>0),(AT14/(R14*1000)*1000),0) -> 1011.5032 | AY14: =IF(AND(S14>0,AU14>0),(AU14/(S14*1000)*1000),0) -> 963.76755 | AZ14: =+Listrik!S13 -> 17410.492 | BA14: =AZ14+BA13 -> 109438.48 | BB14: =IF(AND(L14>0,AZ14>0),(AZ14/(P14*1000)*1000),0) -> 655.58956 | BC14: =IF(AND(M14>0,BA14>0),(BA14/(Q14*1000)*1000),0) -> 507.45062 | BD14: =IF(AND(R14>0,AZ14>0),(AZ14/(R14*1000)*1000),0) -> 654.45596 | BE14: =IF(AND(S14>0,BA14>0),(BA14/(S14*1000)*1000),0) -> 514.45503 | BG14: =BF14+BG13 -> 0 | BH14: =IF(AND(L14>0,BF14>0),(BF14/(P14*1000)*1000),0) -> 0 | BI14: =IF(AND(U14>0,BG14>0),(BG14/(Q14*1000)*1000),0) -> 0 | BJ14: =IF(AND(L14>0,BF14>0),(BF14/(R14*1000)*1000),0) -> 0 | BK14: =IF(AND(AA14>0,BG14>0),(BG14/(S14*1000)*1000),0) -> 0 | BL14: =+SUM(Efficiency2!K38:K40) -> 41.820542 | BM14: =BM13+BL14 -> 312.44239 | BN14: =+R14/BL14 -> 0.6361228 | BO14: =+S14/BM14 -> 0.68085193
A15: =A14+1 -> 46088 | B15: Toilet | C15: 20/17 | D15: =+'7'!F42 -> 850 | E15: =+'7'!G42 -> 663 | F15: =1-(E15/D15) -> 0.22 | G15: =+P15/N15 -> 0.72028391 | H15: =+P15/L15 -> 0.68386766 | I15: =+R15/P15 -> 0.8634045 | J15: =+R15/L15 -> 0.59045442 | K15: =+S15/M15 -> 0.64616853 | L15: =+SUM(Efficiency1!K44:K45) -> 54.178611 | M15: =M14+L15 -> 378.72008 | N15: =+SUM(Efficiency1!C44:C45) -> 51.439438 | O15: =O14+N15 -> 321.26307 | P15: ='7'!I38 -> 37.051 | Q15: =Q14+P15 -> 252.7143 | R15: ='7'!I40 -> 31.99 | S15: =S14+R15 -> 244.717 | T15: =R15/P15 -> 0.8634045 | U15: =S15/Q15 -> 0.96835438 | V15: =R15/L15 -> 0.59045442 | W15: =S15/M15 -> 0.64616853 | AB15: =+[1]Report1!AY15 -> 4350.4668 | AC15: =AB15+AC14 -> 26334.563 | AD15: =AB15/P15 -> 117.41834 | AE15: =AC15/Q15 -> 104.20686 | AF15: =IF(AND(R15>0,AB15>0),(AB15/(R15*1000))*1000,0) -> 135.99459 | AG15: =IF(AND(S15>0,AC15>0),AC15/S15,0) -> 107.61232 | AH15: 50.2 | AI15: =AH15+AI14 -> 391.8 | AJ15: =AH15/(P15) -> 1.3548892 | AK15: =AI15/(Q15) -> 1.5503674 | AL15: =IF(AND(R15>0,AH15>0),AH15/(R15),0) -> 1.5692404 | AM15: =IF(AND(S15>0,AI15>0),AI15/(S15),0) -> 1.601033 | AN15: 0 | AO15: =AN15+AO14 -> 0 | AP15: =AN15/(P15) -> 0 | AQ15: =AO15/(Q15) -> 0 | AR15: =IF(AND(R15>0,AN15>0),AN15/(R15),0) -> 0 | AS15: =IF(AND(S15>0,AO15>0),AO15/(S15),0) -> 0 | AT15: ='7'!I46 -> 28849.02 | AU15: =AT15+AU14 -> 233868.4 | AV15: =IF(AND(L15>0,AT15>0),(AT15/(P15*1000)*1000),0) -> 778.63 | AW15: =IF(AND(M15>0,AU15>0),(AU15/(Q15*1000)*1000),0) -> 925.42606 | AX15: =IF(AND(R15>0,AT15>0),(AT15/(R15*1000)*1000),0) -> 901.81369 | AY15: =IF(AND(S15>0,AU15>0),(AU15/(S15*1000)*1000),0) -> 955.66879 | AZ15: =+Listrik!S14 -> 16581.4 | BA15: =AZ15+BA14 -> 126019.88 | BB15: =IF(AND(L15>0,AZ15>0),(AZ15/(P15*1000)*1000),0) -> 447.52908 | BC15: =IF(AND(M15>0,BA15>0),(BA15/(Q15*1000)*1000),0) -> 498.66539 | BD15: =IF(AND(R15>0,AZ15>0),(AZ15/(R15*1000)*1000),0) -> 518.33073 | BE15: =IF(AND(S15>0,BA15>0),(BA15/(S15*1000)*1000),0) -> 514.96167 | BG15: =BF15+BG14 -> 0 | BH15: =IF(AND(L15>0,BF15>0),(BF15/(P15*1000)*1000),0) -> 0 | BI15: =IF(AND(U15>0,BG15>0),(BG15/(Q15*1000)*1000),0) -> 0 | BJ15: =IF(AND(L15>0,BF15>0),(BF15/(R15*1000)*1000),0) -> 0 | BK15: =IF(AND(AA15>0,BG15>0),(BG15/(S15*1000)*1000),0) -> 0 | BL15: =+SUM(Efficiency2!K44:K45) -> 39.691989 | BM15: =BM14+BL15 -> 352.13437 | BN15: =+R15/BL15 -> 0.80595609 | BO15: =+S15/BM15 -> 0.69495346
A16: =A15+1 -> 46089 | B16: Toilet | C16: 17/16 | D16: =+'8'!F42 -> 887.01389 | E16: =+'8'!G42 -> 710.19583 | F16: =1-(E16/D16) -> 0.1993408 | G16: =+P16/N16 -> 0.99826436 | H16: =+P16/L16 -> 0.83649155 | I16: =+R16/P16 -> 1.0314253 | J16: =+R16/L16 -> 0.86277856 | K16: =+S16/M16 -> 0.67250557 | L16: =+SUM(Efficiency1!K50:K51) -> 52.421331 | M16: =M15+L16 -> 431.14141 | N16: =+SUM(Efficiency1!C50:C51) -> 43.92624 | O16: =O15+N16 -> 365.18931 | P16: ='8'!I38 -> 43.85 | Q16: =Q15+P16 -> 296.5643 | R16: ='8'!I40 -> 45.228 | S16: =S15+R16 -> 289.945 | T16: =R16/P16 -> 1.0314253 | U16: =S16/Q16 -> 0.97768005 | V16: =R16/L16 -> 0.86277856 | W16: =S16/M16 -> 0.67250557 | AB16: =+[1]Report1!AY16 -> 3957.045 | AC16: =AB16+AC15 -> 30291.608 | AD16: =AB16/P16 -> 90.240478 | AE16: =AC16/Q16 -> 102.14179 | AF16: =IF(AND(R16>0,AB16>0),(AB16/(R16*1000))*1000,0) -> 87.491045 | AG16: =IF(AND(S16>0,AC16>0),AC16/S16,0) -> 104.47364 | AH16: 62.4 | AI16: =AH16+AI15 -> 454.2 | AJ16: =AH16/(P16) -> 1.4230331 | AK16: =AI16/(Q16) -> 1.5315397 | AL16: =IF(AND(R16>0,AH16>0),AH16/(R16),0) -> 1.3796763 | AM16: =IF(AND(S16>0,AI16>0),AI16/(S16),0) -> 1.566504 | AN16: 0 | AO16: =AN16+AO15 -> 0 | AP16: =AN16/(P16) -> 0 | AQ16: =AO16/(Q16) -> 0 | AR16: =IF(AND(R16>0,AN16>0),AN16/(R16),0) -> 0 | AS16: =IF(AND(S16>0,AO16>0),AO16/(S16),0) -> 0 | AT16: ='8'!I46 -> 35576.46 | AU16: =AT16+AU15 -> 269444.86 | AV16: =IF(AND(L16>0,AT16>0),(AT16/(P16*1000)*1000),0) -> 811.32178 | AW16: =IF(AND(M16>0,AU16>0),(AU16/(Q16*1000)*1000),0) -> 908.5546 | AX16: =IF(AND(R16>0,AT16>0),(AT16/(R16*1000)*1000),0) -> 786.60255 | AY16: =IF(AND(S16>0,AU16>0),(AU16/(S16*1000)*1000),0) -> 929.29645 | AZ16: =+Listrik!S15 -> 23735.356 | BA16: =AZ16+BA15 -> 149755.23 | BB16: =IF(AND(L16>0,AZ16>0),(AZ16/(P16*1000)*1000),0) -> 541.2852 | BC16: =IF(AND(M16>0,BA16>0),(BA16/(Q16*1000)*1000),0) -> 504.96716 | BD16: =IF(AND(R16>0,AZ16>0),(AZ16/(R16*1000)*1000),0) -> 524.7934 | BE16: =IF(AND(S16>0,BA16>0),(BA16/(S16*1000)*1000),0) -> 516.49531 | BG16: =BF16+BG15 -> 0 | BH16: =IF(AND(L16>0,BF16>0),(BF16/(P16*1000)*1000),0) -> 0 | BI16: =IF(AND(U16>0,BG16>0),(BG16/(Q16*1000)*1000),0) -> 0 | BJ16: =IF(AND(L16>0,BF16>0),(BF16/(R16*1000)*1000),0) -> 0 | BK16: =IF(AND(AA16>0,BG16>0),(BG16/(S16*1000)*1000),0) -> 0 | BL16: =+SUM(Efficiency2!K50:K51) -> 52.421331 | BM16: =BM15+BL16 -> 404.5557 | BN16: =+R16/BL16 -> 0.86277856 | BO16: =+S16/BM16 -> 0.71669982
A17: =A16+1 -> 46090 | B17: Toilet/Napkin | C17: 16/15,5 | D17: =+'9'!F42 -> 972.19444 | E17: =+'9'!G42 -> 826.83722 | F17: =1-(E17/D17) -> 0.14951456 | G17: =+P17/N17 -> 0.97699893 | H17: =+P17/L17 -> 0.90545036 | I17: =+R17/P17 -> 1.0090622 | J17: =+R17/L17 -> 0.9136557 | K17: =+S17/M17 -> 0.6984778 | L17: =+SUM(Efficiency1!K55:K56) -> 52.039297 | M17: =M16+L17 -> 483.18071 | N17: =+SUM(Efficiency1!C55:C56) -> 48.228303 | O17: =O16+N17 -> 413.41761 | P17: ='9'!I38 -> 47.119 | Q17: =Q16+P17 -> 343.6833 | R17: ='9'!I40 -> 47.546 | S17: =S16+R17 -> 337.491 | T17: =R17/P17 -> 1.0090622 | U17: =S17/Q17 -> 0.98198254 | V17: =R17/L17 -> 0.9136557 | W17: =S17/M17 -> 0.6984778 | AB17: =+[1]Report1!AY17 -> 4468.3045 | AC17: =AB17+AC16 -> 34759.913 | AD17: =AB17/P17 -> 94.830206 | AE17: =AC17/Q17 -> 101.13937 | AF17: =IF(AND(R17>0,AB17>0),(AB17/(R17*1000))*1000,0) -> 93.978557 | AG17: =IF(AND(S17>0,AC17>0),AC17/S17,0) -> 102.99508 | AH17: 68.6 | AI17: =AH17+AI16 -> 522.8 | AJ17: =AH17/(P17) -> 1.4558883 | AK17: =AI17/(Q17) -> 1.5211679 | AL17: =IF(AND(R17>0,AH17>0),AH17/(R17),0) -> 1.4428133 | AM17: =IF(AND(S17>0,AI17>0),AI17/(S17),0) -> 1.5490783 | AN17: 0 | AO17: =AN17+AO16 -> 0 | AP17: =AN17/(P17) -> 0 | AQ17: =AO17/(Q17) -> 0 | AR17: =IF(AND(R17>0,AN17>0),AN17/(R17),0) -> 0 | AS17: =IF(AND(S17>0,AO17>0),AO17/(S17),0) -> 0 | AT17: ='9'!I46 -> 40975.1 | AU17: =AT17+AU16 -> 310419.96 | AV17: =IF(AND(L17>0,AT17>0),(AT17/(P17*1000)*1000),0) -> 869.60886 | AW17: =IF(AND(M17>0,AU17>0),(AU17/(Q17*1000)*1000),0) -> 903.21514 | AX17: =IF(AND(R17>0,AT17>0),(AT17/(R17*1000)*1000),0) -> 861.7991 | AY17: =IF(AND(S17>0,AU17>0),(AU17/(S17*1000)*1000),0) -> 919.78737 | AZ17: =+Listrik!S16 -> 21141.094 | BA17: =AZ17+BA16 -> 170896.33 | BB17: =IF(AND(L17>0,AZ17>0),(AZ17/(P17*1000)*1000),0) -> 448.6745 | BC17: =IF(AND(M17>0,BA17>0),(BA17/(Q17*1000)*1000),0) -> 497.24943 | BD17: =IF(AND(R17>0,AZ17>0),(AZ17/(R17*1000)*1000),0) -> 444.64506 | BE17: =IF(AND(S17>0,BA17>0),(BA17/(S17*1000)*1000),0) -> 506.37299 | BG17: =BF17+BG16 -> 0 | BH17: =IF(AND(L17>0,BF17>0),(BF17/(P17*1000)*1000),0) -> 0 | BI17: =IF(AND(U17>0,BG17>0),(BG17/(Q17*1000)*1000),0) -> 0 | BJ17: =IF(AND(L17>0,BF17>0),(BF17/(R17*1000)*1000),0) -> 0 | BK17: =IF(AND(AA17>0,BG17>0),(BG17/(S17*1000)*1000),0) -> 0 | BL17: =+SUM(Efficiency2!K55:K56) -> 52.039297 | BM17: =BM16+BL17 -> 456.595 | BN17: =+R17/BL17 -> 0.9136557 | BO17: =+S17/BM17 -> 0.73914738
A18: =A17+1 -> 46091 | B18: Napkin/Towel | C18: 15,5/22 | D18: =+'10'!F42 -> 756.25 | E18: =+'10'!G42 -> 650.375 | F18: =1-(E18/D18) -> 0.14 | G18: =+P18/N18 -> 1.0505192 | H18: =+P18/L18 -> 1.0476336 | I18: =+R18/P18 -> 0.95134021 | J18: =+R18/L18 -> 0.99665595 | K18: =+S18/M18 -> 0.72739221 | L18: =+SUM(Efficiency1!K60:K61) -> 51.885508 | M18: =M17+L18 -> 535.06622 | N18: =+SUM(Efficiency1!C60:C61) -> 51.742984 | O18: =O17+N18 -> 465.16059 | P18: ='10'!I38 -> 54.357 | Q18: =Q17+P18 -> 398.0403 | R18: ='10'!I40 -> 51.712 | S18: =S17+R18 -> 389.203 | T18: =R18/P18 -> 0.95134021 | U18: =S18/Q18 -> 0.97779798 | V18: =R18/L18 -> 0.99665595 | W18: =S18/M18 -> 0.72739221 | AB18: =+[1]Report1!AY18 -> 4436.1318 | AC18: =AB18+AC17 -> 39196.045 | AD18: =AB18/P18 -> 81.611049 | AE18: =AC18/Q18 -> 98.472553 | AF18: =IF(AND(R18>0,AB18>0),(AB18/(R18*1000))*1000,0) -> 85.785345 | AG18: =IF(AND(S18>0,AC18>0),AC18/S18,0) -> 100.70849 | AH18: 68.7 | AI18: =AH18+AI17 -> 591.5 | AJ18: =AH18/(P18) -> 1.2638667 | AK18: =AI18/(Q18) -> 1.4860304 | AL18: =IF(AND(R18>0,AH18>0),AH18/(R18),0) -> 1.3285118 | AM18: =IF(AND(S18>0,AI18>0),AI18/(S18),0) -> 1.5197725 | AN18: 0 | AO18: =AN18+AO17 -> 0 | AP18: =AN18/(P18) -> 0 | AQ18: =AO18/(Q18) -> 0 | AR18: =IF(AND(R18>0,AN18>0),AN18/(R18),0) -> 0 | AS18: =IF(AND(S18>0,AO18>0),AO18/(S18),0) -> 0 | AT18: ='10'!I46 -> 38474.32 | AU18: =AT18+AU17 -> 348894.28 | AV18: =IF(AND(L18>0,AT18>0),(AT18/(P18*1000)*1000),0) -> 707.80801 | AW18: =IF(AND(M18>0,AU18>0),(AU18/(Q18*1000)*1000),0) -> 876.53004 | AX18: =IF(AND(R18>0,AT18>0),(AT18/(R18*1000)*1000),0) -> 744.01145 | AY18: =IF(AND(S18>0,AU18>0),(AU18/(S18*1000)*1000),0) -> 896.43266 | AZ18: =+Listrik!S17 -> 28224.049 | BA18: =AZ18+BA17 -> 199120.38 | BB18: =IF(AND(L18>0,AZ18>0),(AZ18/(P18*1000)*1000),0) -> 519.23485 | BC18: =IF(AND(M18>0,BA18>0),(BA18/(Q18*1000)*1000),0) -> 500.2518 | BD18: =IF(AND(R18>0,AZ18>0),(AZ18/(R18*1000)*1000),0) -> 545.79303 | BE18: =IF(AND(S18>0,BA18>0),(BA18/(S18*1000)*1000),0) -> 511.61059 | BG18: =BF18+BG17 -> 0 | BH18: =IF(AND(L18>0,BF18>0),(BF18/(P18*1000)*1000),0) -> 0 | BI18: =IF(AND(U18>0,BG18>0),(BG18/(Q18*1000)*1000),0) -> 0 | BJ18: =IF(AND(L18>0,BF18>0),(BF18/(R18*1000)*1000),0) -> 0 | BK18: =IF(AND(AA18>0,BG18>0),(BG18/(S18*1000)*1000),0) -> 0 | BL18: =+SUM(Efficiency2!K60:K61) -> 51.885508 | BM18: =BM17+BL18 -> 508.48051 | BN18: =+R18/BL18 -> 0.99665595 | BO18: =+S18/BM18 -> 0.76542364
A19: =A18+1 -> 46092 | B19: Towel | C19: 22 | D19: =+'11'!F42 -> 740 | E19: =+'11'!G42 -> 636.4 | F19: =1-(E19/D19) -> 0.14 | G19: =+P19/N19 -> 1.0536502 | H19: =+P19/L19 -> 1.0536502 | I19: =+R19/P19 -> 0.95950104 | J19: =+R19/L19 -> 1.0109785 | K19: =+S19/M19 -> 0.75242931 | L19: =+Efficiency1!K65 -> 51.814161 | M19: =M18+L19 -> 586.88038 | N19: =+Efficiency1!C65 -> 51.814161 | O19: =O18+N19 -> 516.97475 | P19: ='11'!I38 -> 54.594 | Q19: =Q18+P19 -> 452.6343 | R19: ='11'!I40 -> 52.383 | S19: =S18+R19 -> 441.586 | T19: =R19/P19 -> 0.95950104 | U19: =S19/Q19 -> 0.97559111 | V19: =R19/L19 -> 1.0109785 | W19: =S19/M19 -> 0.75242931 | AB19: =+[1]Report1!AY19 -> 4422.8808 | AC19: =AB19+AC18 -> 43618.925 | AD19: =AB19/P19 -> 81.014046 | AE19: =AC19/Q19 -> 96.366814 | AF19: =IF(AND(R19>0,AB19>0),(AB19/(R19*1000))*1000,0) -> 84.433515 | AG19: =IF(AND(S19>0,AC19>0),AC19/S19,0) -> 98.777872 | AH19: 68.1 | AI19: =AH19+AI18 -> 659.6 | AJ19: =AH19/(P19) -> 1.2473898 | AK19: =AI19/(Q19) -> 1.4572471 | AL19: =IF(AND(R19>0,AH19>0),AH19/(R19),0) -> 1.3000401 | AM19: =IF(AND(S19>0,AI19>0),AI19/(S19),0) -> 1.4937068 | AN19: 0 | AO19: =AN19+AO18 -> 0 | AP19: =AN19/(P19) -> 0 | AQ19: =AO19/(Q19) -> 0 | AR19: =IF(AND(R19>0,AN19>0),AN19/(R19),0) -> 0 | AS19: =IF(AND(S19>0,AO19>0),AO19/(S19),0) -> 0 | AT19: ='11'!I46 -> 37643.74 | AU19: =AT19+AU18 -> 386538.02 | AV19: =IF(AND(L19>0,AT19>0),(AT19/(P19*1000)*1000),0) -> 689.52156 | AW19: =IF(AND(M19>0,AU19>0),(AU19/(Q19*1000)*1000),0) -> 853.97421 | AX19: =IF(AND(R19>0,AT19>0),(AT19/(R19*1000)*1000),0) -> 718.62513 | AY19: =IF(AND(S19>0,AU19>0),(AU19/(S19*1000)*1000),0) -> 875.3403 | AZ19: =+Listrik!S18 -> 27891.951 | BA19: =AZ19+BA18 -> 227012.33 | BB19: =IF(AND(L19>0,AZ19>0),(AZ19/(P19*1000)*1000),0) -> 510.89774 | BC19: =IF(AND(M19>0,BA19>0),(BA19/(Q19*1000)*1000),0) -> 501.53584 | BD19: =IF(AND(R19>0,AZ19>0),(AZ19/(R19*1000)*1000),0) -> 532.46189 | BE19: =IF(AND(S19>0,BA19>0),(BA19/(S19*1000)*1000),0) -> 514.08407 | BG19: =BF19+BG18 -> 0 | BH19: =IF(AND(L19>0,BF19>0),(BF19/(P19*1000)*1000),0) -> 0 | BI19: =IF(AND(U19>0,BG19>0),(BG19/(Q19*1000)*1000),0) -> 0 | BJ19: =IF(AND(L19>0,BF19>0),(BF19/(R19*1000)*1000),0) -> 0 | BK19: =IF(AND(AA19>0,BG19>0),(BG19/(S19*1000)*1000),0) -> 0 | BL19: =+Efficiency2!K65 -> 51.814161 | BM19: =BM18+BL19 -> 560.29467 | BN19: =+R19/BL19 -> 1.0109785 | BO19: =+S19/BM19 -> 0.78813172
A20: =A19+1 -> 46093 | B20: Towel/Napkin | C20: 22/15,5 | D20: =+'12'!F42 -> 756.25 | E20: =+'12'!G42 -> 650.375 | F20: =1-(E20/D20) -> 0.14 | G20: =+P20/N20 -> 1.0187145 | H20: =+P20/L20 -> 1.0159758 | I20: =+R20/P20 -> 0.99044417 | J20: =+R20/L20 -> 1.0062674 | K20: =+S20/M20 -> 0.77302053 | L20: =+SUM(Efficiency1!K70:K71) -> 51.810287 | M20: =M19+L20 -> 638.69067 | N20: =+SUM(Efficiency1!C70:C71) -> 51.671002 | O20: =O19+N20 -> 568.64576 | P20: ='12'!I38 -> 52.638 | Q20: =Q19+P20 -> 505.2723 | R20: ='12'!I40 -> 52.135 | S20: =S19+R20 -> 493.721 | T20: =R20/P20 -> 0.99044417 | U20: =S20/Q20 -> 0.97713847 | V20: =R20/L20 -> 1.0062674 | W20: =S20/M20 -> 0.77302053 | AB20: =+[1]Report1!AY20 -> 4342.4235 | AC20: =AB20+AC19 -> 47961.349 | AD20: =AB20/P20 -> 82.495982 | AE20: =AC20/Q20 -> 94.921785 | AF20: =IF(AND(R20>0,AB20>0),(AB20/(R20*1000))*1000,0) -> 83.291905 | AG20: =IF(AND(S20>0,AC20>0),AC20/S20,0) -> 97.142615 | AH20: 68.1 | AI20: =AH20+AI19 -> 727.7 | AJ20: =AH20/(P20) -> 1.2937422 | AK20: =AI20/(Q20) -> 1.4402135 | AL20: =IF(AND(R20>0,AH20>0),AH20/(R20),0) -> 1.3062242 | AM20: =IF(AND(S20>0,AI20>0),AI20/(S20),0) -> 1.4739094 | AN20: 0 | AO20: =AN20+AO19 -> 0 | AP20: =AN20/(P20) -> 0 | AQ20: =AO20/(Q20) -> 0 | AR20: =IF(AND(R20>0,AN20>0),AN20/(R20),0) -> 0 | AS20: =IF(AND(S20>0,AO20>0),AO20/(S20),0) -> 0 | AT20: ='12'!I46 -> 37147.78 | AU20: =AT20+AU19 -> 423685.8 | AV20: =IF(AND(L20>0,AT20>0),(AT20/(P20*1000)*1000),0) -> 705.72172 | AW20: =IF(AND(M20>0,AU20>0),(AU20/(Q20*1000)*1000),0) -> 838.52964 | AX20: =IF(AND(R20>0,AT20>0),(AT20/(R20*1000)*1000),0) -> 712.53055 | AY20: =IF(AND(S20>0,AU20>0),(AU20/(S20*1000)*1000),0) -> 858.14823 | AZ20: =+Listrik!S19 -> 24819.9 | BA20: =AZ20+BA19 -> 251832.23 | BB20: =IF(AND(L20>0,AZ20>0),(AZ20/(P20*1000)*1000),0) -> 471.52057 | BC20: =IF(AND(M20>0,BA20>0),(BA20/(Q20*1000)*1000),0) -> 498.40893 | BD20: =IF(AND(R20>0,AZ20>0),(AZ20/(R20*1000)*1000),0) -> 476.06982 | BE20: =IF(AND(S20>0,BA20>0),(BA20/(S20*1000)*1000),0) -> 510.06991 | BG20: =BF20+BG19 -> 0 | BH20: =IF(AND(L20>0,BF20>0),(BF20/(P20*1000)*1000),0) -> 0 | BI20: =IF(AND(U20>0,BG20>0),(BG20/(Q20*1000)*1000),0) -> 0 | BJ20: =IF(AND(L20>0,BF20>0),(BF20/(R20*1000)*1000),0) -> 0 | BK20: =IF(AND(AA20>0,BG20>0),(BG20/(S20*1000)*1000),0) -> 0 | BL20: =+SUM(Efficiency2!K70:K71) -> 51.810287 | BM20: =BM19+BL20 -> 612.10496 | BN20: =+R20/BL20 -> 1.0062674 | BO20: =+S20/BM20 -> 0.80659533
A21: =A20+1 -> 46094 | B21: Napkin/Towel | C21: 15,5/22 | D21: =+'13'!F42 -> 929.49306 | E21: =+'13'!G42 -> 799.36403 | F21: =1-(E21/D21) -> 0.14 | G21: =+P21/N21 -> 0.99862968 | H21: =+P21/L21 -> 0.98437294 | I21: =+R21/P21 -> 0.95219007 | J21: =+R21/L21 -> 0.93731013 | K21: =+S21/M21 -> 0.78537881 | L21: =+SUM(Efficiency1!K75:K76) -> 51.951855 | M21: =M20+L21 -> 690.64252 | N21: =+SUM(Efficiency1!C75:C76) -> 51.210174 | O21: =O20+N21 -> 619.85593 | P21: ='13'!I38 -> 51.14 | Q21: =Q20+P21 -> 556.4123 | R21: ='13'!I40 -> 48.695 | S21: =S20+R21 -> 542.416 | T21: =R21/P21 -> 0.95219007 | U21: =S21/Q21 -> 0.97484545 | V21: =R21/L21 -> 0.93731013 | W21: =S21/M21 -> 0.78537881 | AB21: =+[1]Report1!AY21 -> 4363.8426 | AC21: =AB21+AC20 -> 52325.191 | AD21: =AB21/P21 -> 85.331299 | AE21: =AC21/Q21 -> 94.040321 | AF21: =IF(AND(R21>0,AB21>0),(AB21/(R21*1000))*1000,0) -> 89.615825 | AG21: =IF(AND(S21>0,AC21>0),AC21/S21,0) -> 96.466903 | AH21: 69.6 | AI21: =AH21+AI20 -> 797.3 | AJ21: =AH21/(P21) -> 1.3609699 | AK21: =AI21/(Q21) -> 1.4329302 | AL21: =IF(AND(R21>0,AH21>0),AH21/(R21),0) -> 1.4293049 | AM21: =IF(AND(S21>0,AI21>0),AI21/(S21),0) -> 1.469905 | AN21: 0 | AO21: =AN21+AO20 -> 0 | AP21: =AN21/(P21) -> 0 | AQ21: =AO21/(Q21) -> 0 | AR21: =IF(AND(R21>0,AN21>0),AN21/(R21),0) -> 0 | AS21: =IF(AND(S21>0,AO21>0),AO21/(S21),0) -> 0 | AT21: ='13'!I46 -> 41775.78 | AU21: =AT21+AU20 -> 465461.58 | AV21: =IF(AND(L21>0,AT21>0),(AT21/(P21*1000)*1000),0) -> 816.8905 | AW21: =IF(AND(M21>0,AU21>0),(AU21/(Q21*1000)*1000),0) -> 836.54078 | AX21: =IF(AND(R21>0,AT21>0),(AT21/(R21*1000)*1000),0) -> 857.90697 | AY21: =IF(AND(S21>0,AU21>0),(AU21/(S21*1000)*1000),0) -> 858.12657 | AZ21: =+Listrik!S20 -> 24769.549 | BA21: =AZ21+BA20 -> 276601.78 | BB21: =IF(AND(L21>0,AZ21>0),(AZ21/(P21*1000)*1000),0) -> 484.34785 | BC21: =IF(AND(M21>0,BA21>0),(BA21/(Q21*1000)*1000),0) -> 497.11657 | BD21: =IF(AND(R21>0,AZ21>0),(AZ21/(R21*1000)*1000),0) -> 508.66719 | BE21: =IF(AND(S21>0,BA21>0),(BA21/(S21*1000)*1000),0) -> 509.94398 | BG21: =BF21+BG20 -> 0 | BH21: =IF(AND(L21>0,BF21>0),(BF21/(P21*1000)*1000),0) -> 0 | BI21: =IF(AND(U21>0,BG21>0),(BG21/(Q21*1000)*1000),0) -> 0 | BJ21: =IF(AND(L21>0,BF21>0),(BF21/(R21*1000)*1000),0) -> 0 | BK21: =IF(AND(AA21>0,BG21>0),(BG21/(S21*1000)*1000),0) -> 0 | BL21: =+SUM(Efficiency2!K75:K76) -> 51.951855 | BM21: =BM20+BL21 -> 664.05681 | BN21: =+R21/BL21 -> 0.93731013 | BO21: =+S21/BM21 -> 0.81682168
A22: =A21+1 -> 46095 | B22: Towel | C22: 22 | D22: =+'14'!F42 -> 743.33333 | E22: =+'14'!G42 -> 639.26667 | F22: =1-(E22/D22) -> 0.14 | G22: =+P22/N22 -> 1.0145145 | H22: =+P22/L22 -> 1.0145145 | I22: =+R22/P22 -> 0.97640286 | J22: =+R22/L22 -> 0.99057482 | K22: =+S22/M22 -> 0.7997589 | L22: =+Efficiency1!K80 -> 52.047558 | M22: =M21+L22 -> 742.69008 | N22: =+Efficiency1!C80 -> 52.047558 | O22: =O21+N22 -> 671.90349 | P22: ='14'!I38 -> 52.803 | Q22: =Q21+P22 -> 609.2153 | R22: ='14'!I40 -> 51.557 | S22: =S21+R22 -> 593.973 | T22: =R22/P22 -> 0.97640286 | U22: =S22/Q22 -> 0.97498044 | V22: =R22/L22 -> 0.99057482 | W22: =S22/M22 -> 0.7997589 | AB22: =+[1]Report1!AY22 -> 4389.4904 | AC22: =AB22+AC21 -> 56714.682 | AD22: =AB22/P22 -> 83.129564 | AE22: =AC22/Q22 -> 93.094644 | AF22: =IF(AND(R22>0,AB22>0),(AB22/(R22*1000))*1000,0) -> 85.138591 | AG22: =IF(AND(S22>0,AC22>0),AC22/S22,0) -> 95.483602 | AH22: 69.6 | AI22: =AH22+AI21 -> 866.9 | AJ22: =AH22/(P22) -> 1.3181069 | AK22: =AI22/(Q22) -> 1.4229781 | AL22: =IF(AND(R22>0,AH22>0),AH22/(R22),0) -> 1.3499622 | AM22: =IF(AND(S22>0,AI22>0),AI22/(S22),0) -> 1.459494 | AN22: 0 | AO22: =AN22+AO21 -> 0 | AP22: =AN22/(P22) -> 0 | AQ22: =AO22/(Q22) -> 0 | AR22: =IF(AND(R22>0,AN22>0),AN22/(R22),0) -> 0 | AS22: =IF(AND(S22>0,AO22>0),AO22/(S22),0) -> 0 | AT22: ='14'!I46 -> 37134.6 | AU22: =AT22+AU21 -> 502596.18 | AV22: =IF(AND(L22>0,AT22>0),(AT22/(P22*1000)*1000),0) -> 703.26686 | AW22: =IF(AND(M22>0,AU22>0),(AU22/(Q22*1000)*1000),0) -> 824.98942 | AX22: =IF(AND(R22>0,AT22>0),(AT22/(R22*1000)*1000),0) -> 720.26301 | AY22: =IF(AND(S22>0,AU22>0),(AU22/(S22*1000)*1000),0) -> 846.15998 | AZ22: =+Listrik!S21 -> 27480 | BA22: =AZ22+BA21 -> 304081.78 | BB22: =IF(AND(L22>0,AZ22>0),(AZ22/(P22*1000)*1000),0) -> 520.42498 | BC22: =IF(AND(M22>0,BA22>0),(BA22/(Q22*1000)*1000),0) -> 499.1368 | BD22: =IF(AND(R22>0,AZ22>0),(AZ22/(R22*1000)*1000),0) -> 533.00231 | BE22: =IF(AND(S22>0,BA22>0),(BA22/(S22*1000)*1000),0) -> 511.94545 | BG22: =BF22+BG21 -> 0 | BH22: =IF(AND(L22>0,BF22>0),(BF22/(P22*1000)*1000),0) -> 0 | BI22: =IF(AND(U22>0,BG22>0),(BG22/(Q22*1000)*1000),0) -> 0 | BJ22: =IF(AND(L22>0,BF22>0),(BF22/(R22*1000)*1000),0) -> 0 | BK22: =IF(AND(AA22>0,BG22>0),(BG22/(S22*1000)*1000),0) -> 0 | BL22: =+Efficiency2!K80 -> 52.047558 | BM22: =BM21+BL22 -> 716.10437 | BN22: =+R22/BL22 -> 0.99057482 | BO22: =+S22/BM22 -> 0.82945032
A23: =A22+1 -> 46096 | B23: Towel | C23: 22 | D23: =+'15'!F42 -> 740 | E23: =+'15'!G42 -> 636.4 | F23: =1-(E23/D23) -> 0.14 | G23: =+P23/N23 -> 1.0222229 | H23: =+P23/L23 -> 1.0222229 | I23: =+R23/P23 -> 0.98848074 | J23: =+R23/L23 -> 1.0104477 | K23: =+S23/M23 -> 0.81347544 | L23: =+Efficiency1!K85 -> 51.71866 | M23: =M22+L23 -> 794.40874 | N23: =+Efficiency1!C85 -> 51.71866 | O23: =O22+N23 -> 723.62215 | P23: ='15'!I38 -> 52.868 | Q23: =Q22+P23 -> 662.0833 | R23: ='15'!I40 -> 52.259 | S23: =S22+R23 -> 646.232 | T23: =R23/P23 -> 0.98848074 | U23: =S23/Q23 -> 0.97605845 | V23: =R23/L23 -> 1.0104477 | W23: =S23/M23 -> 0.81347544 | AB23: =+[1]Report1!AY23 -> 4374.4161 | AC23: =AB23+AC22 -> 61089.098 | AD23: =AB23/P23 -> 82.742228 | AE23: =AC23/Q23 -> 92.267994 | AF23: =IF(AND(R23>0,AB23>0),(AB23/(R23*1000))*1000,0) -> 83.706464 | AG23: =IF(AND(S23>0,AC23>0),AC23/S23,0) -> 94.531218 | AH23: 69.4 | AI23: =AH23+AI22 -> 936.3 | AJ23: =AH23/(P23) -> 1.3127033 | AK23: =AI23/(Q23) -> 1.4141725 | AL23: =IF(AND(R23>0,AH23>0),AH23/(R23),0) -> 1.3280009 | AM23: =IF(AND(S23>0,AI23>0),AI23/(S23),0) -> 1.4488605 | AN23: 0 | AO23: =AN23+AO22 -> 0 | AP23: =AN23/(P23) -> 0 | AQ23: =AO23/(Q23) -> 0 | AR23: =IF(AND(R23>0,AN23>0),AN23/(R23),0) -> 0 | AS23: =IF(AND(S23>0,AO23>0),AO23/(S23),0) -> 0 | AT23: ='15'!I46 -> 38173.7 | AU23: =AT23+AU22 -> 540769.88 | AV23: =IF(AND(L23>0,AT23>0),(AT23/(P23*1000)*1000),0) -> 722.05682 | AW23: =IF(AND(M23>0,AU23>0),(AU23/(Q23*1000)*1000),0) -> 816.77016 | AX23: =IF(AND(R23>0,AT23>0),(AT23/(R23*1000)*1000),0) -> 730.47131 | AY23: =IF(AND(S23>0,AU23>0),(AU23/(S23*1000)*1000),0) -> 836.80455 | AZ23: =+Listrik!S22 -> 27466.4 | BA23: =AZ23+BA22 -> 331548.18 | BB23: =IF(AND(L23>0,AZ23>0),(AZ23/(P23*1000)*1000),0) -> 519.52788 | BC23: =IF(AND(M23>0,BA23>0),(BA23/(Q23*1000)*1000),0) -> 500.76505 | BD23: =IF(AND(R23>0,AZ23>0),(AZ23/(R23*1000)*1000),0) -> 525.5822 | BE23: =IF(AND(S23>0,BA23>0),(BA23/(S23*1000)*1000),0) -> 513.04822 | BG23: =BF23+BG22 -> 0 | BH23: =IF(AND(L23>0,BF23>0),(BF23/(P23*1000)*1000),0) -> 0 | BI23: =IF(AND(U23>0,BG23>0),(BG23/(Q23*1000)*1000),0) -> 0 | BJ23: =IF(AND(L23>0,BF23>0),(BF23/(R23*1000)*1000),0) -> 0 | BK23: =IF(AND(AA23>0,BG23>0),(BG23/(S23*1000)*1000),0) -> 0 | BL23: =+Efficiency2!K85 -> 51.71866 | BM23: =BM22+BL23 -> 767.82303 | BN23: =+R23/BL23 -> 1.0104477 | BO23: =+S23/BM23 -> 0.84164186
A24: =A23+1 -> 46097 | B24: Towel | C24: 22 | D24: =+'16'!F42 -> 740 | E24: =+'16'!G42 -> 636.4 | F24: =1-(E24/D24) -> 0.14 | G24: =+P24/N24 -> 1.0366665 | H24: =+P24/L24 -> 1.0366665 | I24: =+R24/P24 -> 0.99734604 | J24: =+R24/L24 -> 1.0339152 | K24: =+S24/M24 -> 0.82692364 | L24: =+Efficiency1!K90 -> 51.612549 | M24: =M23+L24 -> 846.02129 | N24: =+Efficiency1!C90 -> 51.612549 | O24: =O23+N24 -> 775.2347 | P24: ='16'!I38 -> 53.505 | Q24: =Q23+P24 -> 715.5883 | R24: ='16'!I40 -> 53.363 | S24: =S23+R24 -> 699.595 | T24: =R24/P24 -> 0.99734604 | U24: =S24/Q24 -> 0.97765014 | V24: =R24/L24 -> 1.0339152 | W24: =S24/M24 -> 0.82692364 | AB24: =+[1]Report1!AY24 -> 3865.9084 | AC24: =AB24+AC23 -> 64955.006 | AD24: =AB24/P24 -> 72.253217 | AE24: =AC24/Q24 -> 90.771476 | AF24: =IF(AND(R24>0,AB24>0),(AB24/(R24*1000))*1000,0) -> 72.445485 | AG24: =IF(AND(S24>0,AC24>0),AC24/S24,0) -> 92.846584 | AH24: 70.6 | AI24: =AH24+AI23 -> 1006.9 | AJ24: =AH24/(P24) -> 1.3195029 | AK24: =AI24/(Q24) -> 1.407094 | AL24: =IF(AND(R24>0,AH24>0),AH24/(R24),0) -> 1.3230141 | AM24: =IF(AND(S24>0,AI24>0),AI24/(S24),0) -> 1.4392613 | AN24: 0 | AO24: =AN24+AO23 -> 0 | AP24: =AN24/(P24) -> 0 | AQ24: =AO24/(Q24) -> 0 | AR24: =IF(AND(R24>0,AN24>0),AN24/(R24),0) -> 0 | AS24: =IF(AND(S24>0,AO24>0),AO24/(S24),0) -> 0 | AT24: ='16'!I46 -> 43306.8 | AU24: =AT24+AU23 -> 584076.68 | AV24: =IF(AND(L24>0,AT24>0),(AT24/(P24*1000)*1000),0) -> 809.39725 | AW24: =IF(AND(M24>0,AU24>0),(AU24/(Q24*1000)*1000),0) -> 816.21888 | AX24: =IF(AND(R24>0,AT24>0),(AT24/(R24*1000)*1000),0) -> 811.55107 | AY24: =IF(AND(S24>0,AU24>0),(AU24/(S24*1000)*1000),0) -> 834.87829 | AZ24: =+Listrik!S23 -> 22899 | BA24: =AZ24+BA23 -> 354447.18 | BB24: =IF(AND(L24>0,AZ24>0),(AZ24/(P24*1000)*1000),0) -> 427.97869 | BC24: =IF(AND(M24>0,BA24>0),(BA24/(Q24*1000)*1000),0) -> 495.32276 | BD24: =IF(AND(R24>0,AZ24>0),(AZ24/(R24*1000)*1000),0) -> 429.11755 | BE24: =IF(AND(S24>0,BA24>0),(BA24/(S24*1000)*1000),0) -> 506.64624 | BG24: =BF24+BG23 -> 0 | BH24: =IF(AND(L24>0,BF24>0),(BF24/(P24*1000)*1000),0) -> 0 | BI24: =IF(AND(U24>0,BG24>0),(BG24/(Q24*1000)*1000),0) -> 0 | BJ24: =IF(AND(L24>0,BF24>0),(BF24/(R24*1000)*1000),0) -> 0 | BK24: =IF(AND(AA24>0,BG24>0),(BG24/(S24*1000)*1000),0) -> 0 | BL24: =+Efficiency2!K90 -> 51.612549 | BM24: =BM23+BL24 -> 819.43558 | BN24: =+R24/BL24 -> 1.0339152 | BO24: =+S24/BM24 -> 0.85375229
A25: =A24+1 -> 46098 | B25: Towel | C25: 22 | D25: =+'17'!F42 -> 740 | E25: =+'17'!G42 -> 636.4 | F25: =1-(E25/D25) -> 0.14 | G25: =+P25/N25 -> 1.0469934 | H25: =+P25/L25 -> 1.0469934 | I25: =+R25/P25 -> 0.98786039 | J25: =+R25/L25 -> 1.0342833 | K25: =+S25/M25 -> 0.8388465 | L25: =+Efficiency1!K95 -> 51.612549 | M25: =M24+L25 -> 897.63384 | N25: =+Efficiency1!C95 -> 51.612549 | O25: =O24+N25 -> 826.84725 | P25: ='17'!I38 -> 54.038 | Q25: =Q24+P25 -> 769.6263 | R25: ='17'!I40 -> 53.382 | S25: =S24+R25 -> 752.977 | T25: =R25/P25 -> 0.98786039 | U25: =S25/Q25 -> 0.97836703 | V25: =R25/L25 -> 1.0342833 | W25: =S25/M25 -> 0.8388465 | AB25: =+[1]Report1!AY25 -> 6150.8539 | AC25: =AB25+AC24 -> 71105.86 | AD25: =AB25/P25 -> 113.8246 | AE25: =AC25/Q25 -> 92.390112 | AF25: =IF(AND(R25>0,AB25>0),(AB25/(R25*1000))*1000,0) -> 115.22337 | AG25: =IF(AND(S25>0,AC25>0),AC25/S25,0) -> 94.432978 | AH25: 71.3 | AI25: =AH25+AI24 -> 1078.2 | AJ25: =AH25/(P25) -> 1.3194419 | AK25: =AI25/(Q25) -> 1.4009397 | AL25: =IF(AND(R25>0,AH25>0),AH25/(R25),0) -> 1.3356562 | AM25: =IF(AND(S25>0,AI25>0),AI25/(S25),0) -> 1.4319162 | AN25: 0 | AO25: =AN25+AO24 -> 0 | AP25: =AN25/(P25) -> 0 | AQ25: =AO25/(Q25) -> 0 | AR25: =IF(AND(R25>0,AN25>0),AN25/(R25),0) -> 0 | AS25: =IF(AND(S25>0,AO25>0),AO25/(S25),0) -> 0 | AT25: ='17'!I46 -> 42228.06 | AU25: =AT25+AU24 -> 626304.74 | AV25: =IF(AND(L25>0,AT25>0),(AT25/(P25*1000)*1000),0) -> 781.4512 | AW25: =IF(AND(M25>0,AU25>0),(AU25/(Q25*1000)*1000),0) -> 813.77773 | AX25: =IF(AND(R25>0,AT25>0),(AT25/(R25*1000)*1000),0) -> 791.05429 | AY25: =IF(AND(S25>0,AU25>0),(AU25/(S25*1000)*1000),0) -> 831.77141 | AZ25: =+Listrik!S24 -> 23934.249 | BA25: =AZ25+BA24 -> 378381.42 | BB25: =IF(AND(L25>0,AZ25>0),(AZ25/(P25*1000)*1000),0) -> 442.91515 | BC25: =IF(AND(M25>0,BA25>0),(BA25/(Q25*1000)*1000),0) -> 491.64305 | BD25: =IF(AND(R25>0,AZ25>0),(AZ25/(R25*1000)*1000),0) -> 448.35804 | BE25: =IF(AND(S25>0,BA25>0),(BA25/(S25*1000)*1000),0) -> 502.51392 | BG25: =BF25+BG24 -> 0 | BH25: =IF(AND(L25>0,BF25>0),(BF25/(P25*1000)*1000),0) -> 0 | BI25: =IF(AND(U25>0,BG25>0),(BG25/(Q25*1000)*1000),0) -> 0 | BJ25: =IF(AND(L25>0,BF25>0),(BF25/(R25*1000)*1000),0) -> 0 | BK25: =IF(AND(AA25>0,BG25>0),(BG25/(S25*1000)*1000),0) -> 0 | BL25: =+Efficiency2!K95 -> 51.612549 | BM25: =BM24+BL25 -> 871.04813 | BN25: =+R25/BL25 -> 1.0342833 | BO25: =+S25/BM25 -> 0.86444936
A26: =A25+1 -> 46099 | B26: Towel/Toilet | C26: 22/14 | D26: =+'18'!F42 -> 1042.6875 | E26: =+'18'!G42 -> 823.18625 | F26: =1-(E26/D26) -> 0.2105149 | G26: =+P26/N26 -> 0.99800276 | H26: =+P26/L26 -> 0.91729613 | I26: =+R26/P26 -> 0.96933947 | J26: =+R26/L26 -> 0.88917135 | K26: =+S26/M26 -> 0.84159419 | L26: =+SUM(Efficiency1!K100:K102) -> 51.840402 | M26: =M25+L26 -> 949.47424 | N26: =+SUM(Efficiency1!C100:C102) -> 47.648165 | O26: =O25+N26 -> 874.49541 | P26: ='18'!I38 -> 47.553 | Q26: =Q25+P26 -> 817.1793 | R26: ='18'!I40 -> 46.095 | S26: =S25+R26 -> 799.072 | T26: =R26/P26 -> 0.96933947 | U26: =S26/Q26 -> 0.9778417 | V26: =R26/L26 -> 0.88917135 | W26: =S26/M26 -> 0.84159419 | AB26: =+[1]Report1!AY26 -> 5268.0415 | AC26: =AB26+AC25 -> 76373.902 | AD26: =AB26/P26 -> 110.78253 | AE26: =AC26/Q26 -> 93.460397 | AF26: =IF(AND(R26>0,AB26>0),(AB26/(R26*1000))*1000,0) -> 114.28662 | AG26: =IF(AND(S26>0,AC26>0),AC26/S26,0) -> 95.578248 | AH26: 65.9 | AI26: =AH26+AI25 -> 1144.1 | AJ26: =AH26/(P26) -> 1.3858221 | AK26: =AI26/(Q26) -> 1.4000599 | AL26: =IF(AND(R26>0,AH26>0),AH26/(R26),0) -> 1.4296561 | AM26: =IF(AND(S26>0,AI26>0),AI26/(S26),0) -> 1.4317859 | AN26: 0 | AO26: =AN26+AO25 -> 0 | AP26: =AN26/(P26) -> 0 | AQ26: =AO26/(Q26) -> 0 | AR26: =IF(AND(R26>0,AN26>0),AN26/(R26),0) -> 0 | AS26: =IF(AND(S26>0,AO26>0),AO26/(S26),0) -> 0 | AT26: ='18'!I46 -> 43771.28 | AU26: =AT26+AU25 -> 670076.02 | AV26: =IF(AND(L26>0,AT26>0),(AT26/(P26*1000)*1000),0) -> 920.47358 | AW26: =IF(AND(M26>0,AU26>0),(AU26/(Q26*1000)*1000),0) -> 819.98653 | AX26: =IF(AND(R26>0,AT26>0),(AT26/(R26*1000)*1000),0) -> 949.58846 | AY26: =IF(AND(S26>0,AU26>0),(AU26/(S26*1000)*1000),0) -> 838.56776 | AZ26: =+Listrik!S25 -> 20906.954 | BA26: =AZ26+BA25 -> 399288.38 | BB26: =IF(AND(L26>0,AZ26>0),(AZ26/(P26*1000)*1000),0) -> 439.65584 | BC26: =IF(AND(M26>0,BA26>0),(BA26/(Q26*1000)*1000),0) -> 488.61783 | BD26: =IF(AND(R26>0,AZ26>0),(AZ26/(R26*1000)*1000),0) -> 453.5623 | BE26: =IF(AND(S26>0,BA26>0),(BA26/(S26*1000)*1000),0) -> 499.69011 | BG26: =BF26+BG25 -> 0 | BH26: =IF(AND(L26>0,BF26>0),(BF26/(P26*1000)*1000),0) -> 0 | BI26: =IF(AND(U26>0,BG26>0),(BG26/(Q26*1000)*1000),0) -> 0 | BJ26: =IF(AND(L26>0,BF26>0),(BF26/(R26*1000)*1000),0) -> 0 | BK26: =IF(AND(AA26>0,BG26>0),(BG26/(S26*1000)*1000),0) -> 0 | BL26: =+SUM(Efficiency2!K100:K102) -> 51.840402 | BM26: =BM25+BL26 -> 922.88853 | BN26: =+R26/BL26 -> 0.88917135 | BO26: =+S26/BM26 -> 0.86583804
A27: =A26+1 -> 46100 | B27: Toilet | C27: 14 | D27: =+'19'!F42 -> 1150 | E27: =+'19'!G42 -> 897 | F27: =1-(E27/D27) -> 0.22 | G27: =+P27/N27 -> 0.95001617 | H27: =+P27/L27 -> 0.95001617 | I27: =+R27/P27 -> 1.0047625 | J27: =+R27/L27 -> 0.95454063 | K27: =+S27/M27 -> 0.84721545 | L27: =+Efficiency1!K105 -> 49.72968 | M27: =M26+L27 -> 999.20392 | N27: =+Efficiency1!C105 -> 49.72968 | O27: =O26+N27 -> 924.22509 | P27: ='19'!I38 -> 47.244 | Q27: =Q26+P27 -> 864.4233 | R27: ='19'!I40 -> 47.469 | S27: =S26+R27 -> 846.541 | T27: =R27/P27 -> 1.0047625 | U27: =S27/Q27 -> 0.97931303 | V27: =R27/L27 -> 0.95454063 | W27: =S27/M27 -> 0.84721545 | AB27: =+[1]Report1!AY27 -> 5297.5257 | AC27: =AB27+AC26 -> 81671.427 | AD27: =AB27/P27 -> 112.13118 | AE27: =AC27/Q27 -> 94.480826 | AF27: =IF(AND(R27>0,AB27>0),(AB27/(R27*1000))*1000,0) -> 111.59969 | AG27: =IF(AND(S27>0,AC27>0),AC27/S27,0) -> 96.476635 | AH27: 65.2 | AI27: =AH27+AI26 -> 1209.3 | AJ27: =AH27/(P27) -> 1.3800694 | AK27: =AI27/(Q27) -> 1.3989674 | AL27: =IF(AND(R27>0,AH27>0),AH27/(R27),0) -> 1.373528 | AM27: =IF(AND(S27>0,AI27>0),AI27/(S27),0) -> 1.4285191 | AN27: 0 | AO27: =AN27+AO26 -> 0 | AP27: =AN27/(P27) -> 0 | AQ27: =AO27/(Q27) -> 0 | AR27: =IF(AND(R27>0,AN27>0),AN27/(R27),0) -> 0 | AS27: =IF(AND(S27>0,AO27>0),AO27/(S27),0) -> 0 | AT27: ='19'!I46 -> 42535.16 | AU27: =AT27+AU26 -> 712611.18 | AV27: =IF(AND(L27>0,AT27>0),(AT27/(P27*1000)*1000),0) -> 900.32935 | AW27: =IF(AND(M27>0,AU27>0),(AU27/(Q27*1000)*1000),0) -> 824.37757 | AX27: =IF(AND(R27>0,AT27>0),(AT27/(R27*1000)*1000),0) -> 896.06185 | AY27: =IF(AND(S27>0,AU27>0),(AU27/(S27*1000)*1000),0) -> 841.79169 | AZ27: =+Listrik!S26 -> 23509.288 | BA27: =AZ27+BA26 -> 422797.67 | BB27: =IF(AND(L27>0,AZ27>0),(AZ27/(P27*1000)*1000),0) -> 497.61426 | BC27: =IF(AND(M27>0,BA27>0),(BA27/(Q27*1000)*1000),0) -> 489.10952 | BD27: =IF(AND(R27>0,AZ27>0),(AZ27/(R27*1000)*1000),0) -> 495.2556 | BE27: =IF(AND(S27>0,BA27>0),(BA27/(S27*1000)*1000),0) -> 499.44145 | BG27: =BF27+BG26 -> 0 | BH27: =IF(AND(L27>0,BF27>0),(BF27/(P27*1000)*1000),0) -> 0 | BI27: =IF(AND(U27>0,BG27>0),(BG27/(Q27*1000)*1000),0) -> 0 | BJ27: =IF(AND(L27>0,BF27>0),(BF27/(R27*1000)*1000),0) -> 0 | BK27: =IF(AND(AA27>0,BG27>0),(BG27/(S27*1000)*1000),0) -> 0 | BL27: =+Efficiency1!K105 -> 49.72968 | BM27: =BM26+BL27 -> 972.61821 | BN27: =+R27/BL27 -> 0.95454063 | BO27: =+S27/BM27 -> 0.87037338
A28: =A27+1 -> 46101 | B28: Toilet | C28: 14 | D28: =+'20'!F42 -> 1196.7361 | E28: =+'20'!G42 -> 933.45417 | F28: =1-(E28/D28) -> 0.22 | G28: =+P28/N28 -> 0.91548757 | H28: =+P28/L28 -> 0.91548757 | I28: =+R28/P28 -> 0.97849554 | J28: =+R28/L28 -> 0.89580051 | K28: =+S28/M28 -> 0.84957475 | L28: =+Efficiency1!K110 -> 50.997962 | M28: =M27+L28 -> 1050.2019 | N28: =+Efficiency1!C110 -> 50.997962 | O28: =O27+N28 -> 975.22305 | P28: ='20'!I38 -> 46.688 | Q28: =Q27+P28 -> 911.1113 | R28: ='20'!I40 -> 45.684 | S28: =S27+R28 -> 892.225 | T28: =R28/P28 -> 0.97849554 | U28: =S28/Q28 -> 0.97927114 | V28: =R28/L28 -> 0.89580051 | W28: =S28/M28 -> 0.84957475 | AB28: =+[1]Report1!AY28 -> 5579.8312 | AC28: =AB28+AC27 -> 87251.259 | AD28: =AB28/P28 -> 119.51318 | AE28: =AC28/Q28 -> 95.763557 | AF28: =IF(AND(R28>0,AB28>0),(AB28/(R28*1000))*1000,0) -> 122.13973 | AG28: =IF(AND(S28>0,AC28>0),AC28/S28,0) -> 97.790645 | AH28: 66.7 | AI28: =AH28+AI27 -> 1276 | AJ28: =AH28/(P28) -> 1.4286326 | AK28: =AI28/(Q28) -> 1.4004875 | AL28: =IF(AND(R28>0,AH28>0),AH28/(R28),0) -> 1.4600298 | AM28: =IF(AND(S28>0,AI28>0),AI28/(S28),0) -> 1.4301325 | AN28: 0 | AO28: =AN28+AO27 -> 0 | AP28: =AN28/(P28) -> 0 | AQ28: =AO28/(Q28) -> 0 | AR28: =IF(AND(R28>0,AN28>0),AN28/(R28),0) -> 0 | AS28: =IF(AND(S28>0,AO28>0),AO28/(S28),0) -> 0 | AT28: ='20'!I46 -> 41844.98 | AU28: =AT28+AU27 -> 754456.16 | AV28: =IF(AND(L28>0,AT28>0),(AT28/(P28*1000)*1000),0) -> 896.26842 | AW28: =IF(AND(M28>0,AU28>0),(AU28/(Q28*1000)*1000),0) -> 828.06147 | AX28: =IF(AND(R28>0,AT28>0),(AT28/(R28*1000)*1000),0) -> 915.96576 | AY28: =IF(AND(S28>0,AU28>0),(AU28/(S28*1000)*1000),0) -> 845.58958 | AZ28: =+Listrik!S27 -> 23386.455 | BA28: =AZ28+BA27 -> 446184.12 | BB28: =IF(AND(L28>0,AZ28>0),(AZ28/(P28*1000)*1000),0) -> 500.90933 | BC28: =IF(AND(M28>0,BA28>0),(BA28/(Q28*1000)*1000),0) -> 489.71418 | BD28: =IF(AND(R28>0,AZ28>0),(AZ28/(R28*1000)*1000),0) -> 511.91785 | BE28: =IF(AND(S28>0,BA28>0),(BA28/(S28*1000)*1000),0) -> 500.08027 | BG28: =BF28+BG27 -> 0 | BH28: =IF(AND(L28>0,BF28>0),(BF28/(P28*1000)*1000),0) -> 0 | BI28: =IF(AND(U28>0,BG28>0),(BG28/(Q28*1000)*1000),0) -> 0 | BJ28: =IF(AND(L28>0,BF28>0),(BF28/(R28*1000)*1000),0) -> 0 | BK28: =IF(AND(AA28>0,BG28>0),(BG28/(S28*1000)*1000),0) -> 0 | BL28: =+Efficiency2!K110 -> 50.997962 | BM28: =BM27+BL28 -> 1023.6162 | BN28: =+R28/BL28 -> 0.89580051 | BO28: =+S28/BM28 -> 0.8716402
A29: =A28+1 -> 46102 | B29: Toilet | C29: 14 | D29: =+'21'!F42 -> 1183.3333 | E29: =+'21'!G42 -> 923 | F29: =1-(E29/D29) -> 0.22 | G29: =+P29/N29 -> 0.98430068 | H29: =+P29/L29 -> 0.98430068 | I29: =+R29/P29 -> 0.94838053 | J29: =+R29/L29 -> 0.9334916 | K29: =+S29/M29 -> 0.85345223 | L29: =+Efficiency1!K115 -> 50.87673 | M29: =M28+L29 -> 1101.0786 | N29: =+Efficiency1!C115 -> 50.87673 | O29: =O28+N29 -> 1026.0998 | P29: ='21'!I38 -> 50.078 | Q29: =Q28+P29 -> 961.1893 | R29: ='21'!I40 -> 47.493 | S29: =S28+R29 -> 939.718 | T29: =R29/P29 -> 0.94838053 | U29: =S29/Q29 -> 0.97766174 | V29: =R29/L29 -> 0.9334916 | W29: =S29/M29 -> 0.85345223 | AB29: =+[1]Report1!AY29 -> 5701.758 | AC29: =AB29+AC28 -> 92953.017 | AD29: =AB29/P29 -> 113.85754 | AE29: =AC29/Q29 -> 96.706254 | AF29: =IF(AND(R29>0,AB29>0),(AB29/(R29*1000))*1000,0) -> 120.0547 | AG29: =IF(AND(S29>0,AC29>0),AC29/S29,0) -> 98.915863 | AH29: 67.7 | AI29: =AH29+AI28 -> 1343.7 | AJ29: =AH29/(P29) -> 1.351891 | AK29: =AI29/(Q29) -> 1.3979556 | AL29: =IF(AND(R29>0,AH29>0),AH29/(R29),0) -> 1.4254732 | AM29: =IF(AND(S29>0,AI29>0),AI29/(S29),0) -> 1.4298971 | AN29: 0 | AO29: =AN29+AO28 -> 0 | AP29: =AN29/(P29) -> 0 | AQ29: =AO29/(Q29) -> 0 | AR29: =IF(AND(R29>0,AN29>0),AN29/(R29),0) -> 0 | AS29: =IF(AND(S29>0,AO29>0),AO29/(S29),0) -> 0 | AT29: ='21'!I46 -> 42946.54 | AU29: =AT29+AU28 -> 797402.7 | AV29: =IF(AND(L29>0,AT29>0),(AT29/(P29*1000)*1000),0) -> 857.59295 | AW29: =IF(AND(M29>0,AU29>0),(AU29/(Q29*1000)*1000),0) -> 829.60006 | AX29: =IF(AND(R29>0,AT29>0),(AT29/(R29*1000)*1000),0) -> 904.27095 | AY29: =IF(AND(S29>0,AU29>0),(AU29/(S29*1000)*1000),0) -> 848.55531 | AZ29: =+Listrik!S28 -> 25186.545 | BA29: =AZ29+BA28 -> 471370.67 | BB29: =IF(AND(L29>0,AZ29>0),(AZ29/(P29*1000)*1000),0) -> 502.9463 | BC29: =IF(AND(M29>0,BA29>0),(BA29/(Q29*1000)*1000),0) -> 490.40357 | BD29: =IF(AND(R29>0,AZ29>0),(AZ29/(R29*1000)*1000),0) -> 530.32121 | BE29: =IF(AND(S29>0,BA29>0),(BA29/(S29*1000)*1000),0) -> 501.60864 | BG29: =BF29+BG28 -> 0 | BH29: =IF(AND(L29>0,BF29>0),(BF29/(P29*1000)*1000),0) -> 0 | BI29: =IF(AND(U29>0,BG29>0),(BG29/(Q29*1000)*1000),0) -> 0 | BJ29: =IF(AND(L29>0,BF29>0),(BF29/(R29*1000)*1000),0) -> 0 | BK29: =IF(AND(AA29>0,BG29>0),(BG29/(S29*1000)*1000),0) -> 0 | BL29: =+Efficiency2!K115 -> 50.87673 | BM29: =BM28+BL29 -> 1074.4929 | BN29: =+R29/BL29 -> 0.9334916 | BO29: =+S29/BM29 -> 0.87456883
A30: =A29+1 -> 46103 | B30: Toilet | C30: 14/14,5 | D30: =+'22'!F42 -> 1200 | E30: =+'22'!G42 -> 936 | F30: =1-(E30/D30) -> 0.22 | G30: =+P30/N30 -> 0.96786524 | H30: =+P30/L30 -> 0.96786524 | I30: =+R30/P30 -> 0.97322101 | J30: =+R30/L30 -> 0.94194679 | K30: =+S30/M30 -> 0.85735315 | L30: =+SUM(Efficiency1!K120:K121) -> 50.77463 | M30: =M29+L30 -> 1151.8532 | N30: =+SUM(Efficiency1!C120:C121) -> 50.77463 | O30: =O29+N30 -> 1076.8744 | P30: ='22'!I38 -> 49.143 | Q30: =Q29+P30 -> 1010.3323 | R30: ='22'!I40 -> 47.827 | S30: =S29+R30 -> 987.545 | T30: =R30/P30 -> 0.97322101 | U30: =S30/Q30 -> 0.97744574 | V30: =R30/L30 -> 0.94194679 | W30: =S30/M30 -> 0.85735315 | AB30: =+[1]Report1!AY30 -> 5694.4039 | AC30: =AB30+AC29 -> 98647.42 | AD30: =AB30/P30 -> 115.87416 | AE30: =AC30/Q30 -> 97.638589 | AF30: =IF(AND(R30>0,AB30>0),(AB30/(R30*1000))*1000,0) -> 119.06254 | AG30: =IF(AND(S30>0,AC30>0),AC30/S30,0) -> 99.89157 | AH30: 69 | AI30: =AH30+AI29 -> 1412.7 | AJ30: =AH30/(P30) -> 1.4040657 | AK30: =AI30/(Q30) -> 1.3982528 | AL30: =IF(AND(R30>0,AH30>0),AH30/(R30),0) -> 1.4426997 | AM30: =IF(AND(S30>0,AI30>0),AI30/(S30),0) -> 1.4305171 | AN30: 0 | AO30: =AN30+AO29 -> 0 | AP30: =AN30/(P30) -> 0 | AQ30: =AO30/(Q30) -> 0 | AR30: =IF(AND(R30>0,AN30>0),AN30/(R30),0) -> 0 | AS30: =IF(AND(S30>0,AO30>0),AO30/(S30),0) -> 0 | AT30: ='22'!I46 -> 42520.3 | AU30: =AT30+AU29 -> 839923 | AV30: =IF(AND(L30>0,AT30>0),(AT30/(P30*1000)*1000),0) -> 865.23615 | AW30: =IF(AND(M30>0,AU30>0),(AU30/(Q30*1000)*1000),0) -> 831.33341 | AX30: =IF(AND(R30>0,AT30>0),(AT30/(R30*1000)*1000),0) -> 889.04385 | AY30: =IF(AND(S30>0,AU30>0),(AU30/(S30*1000)*1000),0) -> 850.51618 | AZ30: =+Listrik!S29 -> 24632.653 | BA30: =AZ30+BA29 -> 496003.32 | BB30: =IF(AND(L30>0,AZ30>0),(AZ30/(P30*1000)*1000),0) -> 501.24439 | BC30: =IF(AND(M30>0,BA30>0),(BA30/(Q30*1000)*1000),0) -> 490.93087 | BD30: =IF(AND(R30>0,AZ30>0),(AZ30/(R30*1000)*1000),0) -> 515.03655 | BE30: =IF(AND(S30>0,BA30>0),(BA30/(S30*1000)*1000),0) -> 502.25895 | BG30: =BF30+BG29 -> 0 | BH30: =IF(AND(L30>0,BF30>0),(BF30/(P30*1000)*1000),0) -> 0 | BI30: =IF(AND(U30>0,BG30>0),(BG30/(Q30*1000)*1000),0) -> 0 | BJ30: =IF(AND(L30>0,BF30>0),(BF30/(R30*1000)*1000),0) -> 0 | BK30: =IF(AND(AA30>0,BG30>0),(BG30/(S30*1000)*1000),0) -> 0 | BL30: =+SUM(Efficiency2!K120:K121) -> 50.77463 | BM30: =BM29+BL30 -> 1125.2675 | BN30: =+R30/BL30 -> 0.94194679 | BO30: =+S30/BM30 -> 0.87760908
A31: =A30+1 -> 46104 | B31: Toilet | C31: 14,5/13 | D31: =+'23'!F42 -> 1235.8333 | E31: =+'23'!G42 -> 963.95 | F31: =1-(E31/D31) -> 0.22 | G31: =+P31/N31 -> 0.92635646 | H31: =+P31/L31 -> 0.92635646 | I31: =+R31/P31 -> 0.96744029 | J31: =+R31/L31 -> 0.89619457 | K31: =+S31/M31 -> 0.85900793 | L31: =+SUM(Efficiency1!K125:K126) -> 51.256727 | M31: =M30+L31 -> 1203.11 | N31: =+SUM(Efficiency1!C125:C126) -> 51.256727 | O31: =O30+N31 -> 1128.1311 | P31: ='23'!I38 -> 47.482 | Q31: =Q30+P31 -> 1057.8143 | R31: ='23'!I40 -> 45.936 | S31: =S30+R31 -> 1033.481 | T31: =R31/P31 -> 0.96744029 | U31: =S31/Q31 -> 0.97699662 | V31: =R31/L31 -> 0.89619457 | W31: =S31/M31 -> 0.85900793 | AB31: =+[1]Report1!AY31 -> 5370.5047 | AC31: =AB31+AC30 -> 104017.93 | AD31: =AB31/P31 -> 113.10612 | AE31: =AC31/Q31 -> 98.332879 | AF31: =IF(AND(R31>0,AB31>0),(AB31/(R31*1000))*1000,0) -> 116.91276 | AG31: =IF(AND(S31>0,AC31>0),AC31/S31,0) -> 100.64813 | AH31: 68.6 | AI31: =AH31+AI30 -> 1481.3 | AJ31: =AH31/(P31) -> 1.444758 | AK31: =AI31/(Q31) -> 1.4003403 | AL31: =IF(AND(R31>0,AH31>0),AH31/(R31),0) -> 1.4933821 | AM31: =IF(AND(S31>0,AI31>0),AI31/(S31),0) -> 1.4333113 | AN31: 0 | AO31: =AN31+AO30 -> 0 | AP31: =AN31/(P31) -> 0 | AQ31: =AO31/(Q31) -> 0 | AR31: =IF(AND(R31>0,AN31>0),AN31/(R31),0) -> 0 | AS31: =IF(AND(S31>0,AO31>0),AO31/(S31),0) -> 0 | AT31: ='23'!I46 -> 43564.02 | AU31: =AT31+AU30 -> 883487.02 | AV31: =IF(AND(L31>0,AT31>0),(AT31/(P31*1000)*1000),0) -> 917.48494 | AW31: =IF(AND(M31>0,AU31>0),(AU31/(Q31*1000)*1000),0) -> 835.20049 | AX31: =IF(AND(R31>0,AT31>0),(AT31/(R31*1000)*1000),0) -> 948.36338 | AY31: =IF(AND(S31>0,AU31>0),(AU31/(S31*1000)*1000),0) -> 854.86528 | AZ31: =+Listrik!S30 -> 27352.742 | BA31: =AZ31+BA30 -> 523356.06 | BB31: =IF(AND(L31>0,AZ31>0),(AZ31/(P31*1000)*1000),0) -> 576.0655 | BC31: =IF(AND(M31>0,BA31>0),(BA31/(Q31*1000)*1000),0) -> 494.7523 | BD31: =IF(AND(R31>0,AZ31>0),(AZ31/(R31*1000)*1000),0) -> 595.45328 | BE31: =IF(AND(S31>0,BA31>0),(BA31/(S31*1000)*1000),0) -> 506.40124 | BG31: =BF31+BG30 -> 0 | BH31: =IF(AND(L31>0,BF31>0),(BF31/(P31*1000)*1000),0) -> 0 | BI31: =IF(AND(U31>0,BG31>0),(BG31/(Q31*1000)*1000),0) -> 0 | BJ31: =IF(AND(L31>0,BF31>0),(BF31/(R31*1000)*1000),0) -> 0 | BK31: =IF(AND(AA31>0,BG31>0),(BG31/(S31*1000)*1000),0) -> 0 | BL31: =+SUM(Efficiency2!K125:K126) -> 51.256727 | BM31: =BM30+BL31 -> 1176.5243 | BN31: =+R31/BL31 -> 0.89619457 | BO31: =+S31/BM31 -> 0.87841878
A32: =A31+1 -> 46105 | B32: Toilet | C32: 13/15 | D32: =+'24'!F42 -> 1198.75 | E32: =+'24'!G42 -> 935.025 | F32: =1-(E32/D32) -> 0.22 | G32: =+P32/N32 -> 0.98277389 | H32: =+P32/L32 -> 0.98277389 | I32: =+R32/P32 -> 0.97255238 | J32: =+R32/L32 -> 0.95579909 | K32: =+S32/M32 -> 0.86312291 | L32: =+SUM(Efficiency1!K130:K131) -> 53.420223 | M32: =M31+L32 -> 1256.5302 | N32: =+SUM(Efficiency1!C130:C131) -> 53.420223 | O32: =O31+N32 -> 1181.5514 | P32: ='24'!I38 -> 52.5 | Q32: =Q31+P32 -> 1110.3143 | R32: ='24'!I40 -> 51.059 | S32: =S31+R32 -> 1084.54 | T32: =R32/P32 -> 0.97255238 | U32: =S32/Q32 -> 0.97678648 | V32: =R32/L32 -> 0.95579909 | W32: =S32/M32 -> 0.86312291 | AB32: =+[1]Report1!AY32 -> 5041.784 | AC32: =AB32+AC31 -> 109059.71 | AD32: =AB32/P32 -> 96.033981 | AE32: =AC32/Q32 -> 98.224178 | AF32: =IF(AND(R32>0,AB32>0),(AB32/(R32*1000))*1000,0) -> 98.744276 | AG32: =IF(AND(S32>0,AC32>0),AC32/S32,0) -> 100.55849 | AH32: 70.2 | AI32: =AH32+AI31 -> 1551.5 | AJ32: =AH32/(P32) -> 1.3371429 | AK32: =AI32/(Q32) -> 1.3973521 | AL32: =IF(AND(R32>0,AH32>0),AH32/(R32),0) -> 1.37488 | AM32: =IF(AND(S32>0,AI32>0),AI32/(S32),0) -> 1.4305604 | AN32: 0 | AO32: =AN32+AO31 -> 0 | AP32: =AN32/(P32) -> 0 | AQ32: =AO32/(Q32) -> 0 | AR32: =IF(AND(R32>0,AN32>0),AN32/(R32),0) -> 0 | AS32: =IF(AND(S32>0,AO32>0),AO32/(S32),0) -> 0 | AT32: =+'24'!I46 -> 45067.66 | AU32: =AT32+AU31 -> 928554.68 | AV32: =IF(AND(L32>0,AT32>0),(AT32/(P32*1000)*1000),0) -> 858.43162 | AW32: =IF(AND(M32>0,AU32>0),(AU32/(Q32*1000)*1000),0) -> 836.29895 | AX32: =IF(AND(R32>0,AT32>0),(AT32/(R32*1000)*1000),0) -> 882.65849 | AY32: =IF(AND(S32>0,AU32>0),(AU32/(S32*1000)*1000),0) -> 856.17375 | AZ32: =+Listrik!S31 -> 23016.402 | BA32: =AZ32+BA31 -> 546372.46 | BB32: =IF(AND(L32>0,AZ32>0),(AZ32/(P32*1000)*1000),0) -> 438.40766 | BC32: =IF(AND(M32>0,BA32>0),(BA32/(Q32*1000)*1000),0) -> 492.08811 | BD32: =IF(AND(R32>0,AZ32>0),(AZ32/(R32*1000)*1000),0) -> 450.78051 | BE32: =IF(AND(S32>0,BA32>0),(BA32/(S32*1000)*1000),0) -> 503.78268 | BG32: =BF32+BG31 -> 0 | BH32: =IF(AND(L32>0,BF32>0),(BF32/(P32*1000)*1000),0) -> 0 | BI32: =IF(AND(U32>0,BG32>0),(BG32/(Q32*1000)*1000),0) -> 0 | BJ32: =IF(AND(L32>0,BF32>0),(BF32/(R32*1000)*1000),0) -> 0 | BK32: =IF(AND(AA32>0,BG32>0),(BG32/(S32*1000)*1000),0) -> 0 | BL32: =+SUM(Efficiency2!K130:K131) -> 53.420223 | BM32: =BM31+BL32 -> 1229.9445 | BN32: =+R32/BL32 -> 0.95579909 | BO32: =+S32/BM32 -> 0.88177964
