Workbook

Sheet GRAFIK

Sheet Report1
A3: PAPER MACHINE 15 DAILY REPORT 1
A6: DATE | B6: GRADE | C6: GSM | D6: Speed yankee (mpm) | E6: Speed reel (mpm) | F6: Creep ( % ) | G6: Real Eff PM ( % ) | H6: Real Eff PM vs Target (%) | I6: Real Eff FG vs Real Eff PM (%) | J6: Eff FG vs Target (%) | L6: Kapasitas Target (ton) | N6: Kapasitas Teori Real (ton) | P6: PM PROD Timbangan (TON) | R6: FINSHED GOODS (TON) | T6: NET GROSS (Timbangan) (%) | V6: NET GROSS ( Scanner) (%) | X6: FRESH WATER | AB6: GAS HOOD | AH6: STEAM (TON) | AN6: STEAM (TON) DEINKING | AT6: POWER (kWh) | AZ6: POWER (kWh) DEINKING | BF6: POWER WPL (kWh) | BL6: Kapasitas Running (ton) | BN6: Eff FG vs Target Running(%)
X7: CONSUMPTION | Z7: /TON FG. | AB7: CONSUMPTION | AD7: /TON PM. | AF7: /TON FG. | AH7: CONSUMPTION | AJ7: /TON PM. | AL7: /TON FG. | AN7: CONSUMPTION | AP7: /TON PM. | AR7: /TON FG. | AT7: CONSUMPTION | AV7: /TON PM | AX7: /TON FG | AZ7: CONSUMPTION | BB7: /TON PM | BD7: /TON FG | BF7: CONSUMPTION | BH7: /TON PM | BJ7: /TON FG
J8: TODAY | K8: TODATE | L8: TODAY | M8: TODATE | N8: TODAY | O8: TODATE | P8: TODAY | Q8: TODATE | R8: TODAY | S8: TODATE | T8: TODAY | U8: TODATE | V8: TODAY | W8: TODATE | X8: TODAY | Y8: TODATE | Z8: TODAY | AA8: TODATE | AB8: TODAY | AC8: TODATE | AD8: TODAY | AE8: TODATE | AF8: TODAY | AG8: TODATE | AH8: TODAY | AI8: TODATE | AJ8: TODAY | AK8: TODATE | AL8: TODAY | AM8: TODATE | AN8: TODAY | AO8: TODATE | AP8: TODAY | AQ8: TODATE | AR8: TODAY | AS8: TODATE | AT8: TODAY | AU8: TODATE | AV8: TODAY | AW8: TODATE | AX8: TODAY | AY8: TODATE | AZ8: TODAY | BA8: TODATE | BB8: TODAY | BC8: TODATE | BD8: TODAY | BE8: TODATE | BF8: TODAY | BG8: TODATE | BH8: TODAY | BI8: TODATE | BJ8: TODAY | BK8: TODATE | BL8: TODAY | BM8: TODATE | BN8: TODAY | BO8: TODATE
A9: 45962 | B9: Toilet | C9: 14/13,5 | D9: =+'1'!F42 -> 1190.6923 | E9: =+'1'!G42 -> 916.83308 | F9: =1-(E9/D9) -> 0.23 | G9: =+P9/N9 -> 0.86841833 | H9: =+P9/L9 -> 0.77124113 | I9: =+R9/P9 -> 0.93641279 | J9: =+R9/L9 -> 0.72220006 | K9: =+S9/M9 -> 0.72220006 | L9: =+SUM(Efficiency1!K6:K7) -> 55.157846 | M9: =L9 -> 55.157846 | N9: =+SUM(Efficiency1!C6:C7) -> 48.985608 | O9: =N9 -> 48.985608 | P9: ='1'!I38 -> 42.54 | Q9: =P9 -> 42.54 | R9: ='1'!I40 -> 39.835 | S9: =R9 -> 39.835 | T9: =R9/P9 -> 0.93641279 | U9: =S9/Q9 -> 0.93641279 | V9: =R9/L9 -> 0.72220006 | W9: =S9/M9 -> 0.72220006 | AB9: =+[2]Report1!AY9 -> 4833.8352 | AC9: =AB9 -> 4833.8352 | AD9: =AB9/P9 -> 113.63035 | AE9: =AC9/Q9 -> 113.63035 | AF9: =IF(AND(R9>0,AB9>0),(AB9/(R9*1000))*1000,0) -> 121.34644 | AG9: =IF(AND(S9>0,AC9>0),AC9/S9,0) -> 121.34644 | AH9: 62.9 | AI9: =AH9 -> 62.9 | AJ9: =AH9/(P9) -> 1.4786084 | AK9: =AI9/(Q9) -> 1.4786084 | AL9: =IF(AND(R9>0,AH9>0),AH9/(R9),0) -> 1.5790134 | AM9: =IF(AND(S9>0,AI9>0),AI9/(S9),0) -> 1.5790134 | AN9: 7.9 | AO9: =AN9 -> 7.9 | AP9: =AN9/(P9) -> 0.18570757 | AQ9: =AO9/(Q9) -> 0.18570757 | AR9: =IF(AND(R9>0,AN9>0),AN9/(R9),0) -> 0.19831806 | AS9: =IF(AND(S9>0,AO9>0),AO9/(S9),0) -> 0.19831806 | AT9: ='1'!I46 -> 36391.3 | AU9: =AT9 -> 36391.3 | AV9: =IF(AND(L9>0,AT9>0),(AT9/(P9*1000)*1000),0) -> 855.46074 | AW9: =IF(AND(M9>0,AU9>0),(AU9/(Q9*1000)*1000),0) -> 855.46074 | AX9: =IF(AND(R9>0,AT9>0),(AT9/(R9*1000)*1000),0) -> 913.5509 | AY9: =IF(AND(S9>0,AU9>0),(AU9/(S9*1000)*1000),0) -> 913.5509 | AZ9: =+Listrik!S8 -> 22450.48 | BA9: =AZ9 -> 22450.48 | BB9: =IF(AND(L9>0,AZ9>0),(AZ9/(P9*1000)*1000),0) -> 527.74988 | BC9: =IF(AND(M9>0,BA9>0),(BA9/(Q9*1000)*1000),0) -> 527.74988 | BD9: =IF(AND(R9>0,AZ9>0),(AZ9/(R9*1000)*1000),0) -> 563.5868 | BE9: =IF(AND(S9>0,BA9>0),(BA9/(S9*1000)*1000),0) -> 563.5868 | BF9: =+Listrik!V8 -> 312 | BG9: =BF9 -> 312 | BH9: =IF(AND(L9>0,BF9>0),(BF9/(P9*1000)*1000),0) -> 7.3342736 | BI9: =IF(AND(M9>0,BG9>0),(BG9/(Q9*1000)*1000),0) -> 7.3342736 | BJ9: =IF(AND(R9>0,BF9>0),(BF9/(R9*1000)*1000),0) -> 7.8323083 | BK9: =IF(AND(S9>0,BG9>0),(BG9/(S9*1000)*1000),0) -> 7.8323083 | BL9: =+SUM(Efficiency2!K6:K7) -> 55.157846 | BM9: =BL9 -> 55.157846 | BN9: =+R9/BL9 -> 0.72220006 | BO9: =+S9/BM9 -> 0.72220006
A10: =A9+1 -> 45963 | B10: Toilet | C10: 13,5/14 | D10: =+'2'!F42 -> 1218.9722 | E10: =+'2'!G42 -> 938.60861 | F10: =1-(E10/D10) -> 0.23 | G10: =+P10/N10 -> 0.94752033 | H10: =+P10/L10 -> 0.87515046 | I10: =+R10/P10 -> 1.0178272 | J10: =+R10/L10 -> 0.89075191 | K10: =+S10/M10 -> 0.80644943 | L10: =+SUM(Efficiency1!K12:K13) -> 55.123093 | M10: =M9+L10 -> 110.28094 | N10: =+SUM(Efficiency1!C12:C13) -> 50.912892 | O10: =O9+N10 -> 99.8985 | P10: ='2'!I38 -> 48.241 | Q10: =Q9+P10 -> 90.781 | R10: ='2'!I40 -> 49.101 | S10: =S9+R10 -> 88.936 | T10: =R10/P10 -> 1.0178272 | U10: =S10/Q10 -> 0.97967636 | V10: =R10/L10 -> 0.89075191 | W10: =S10/M10 -> 0.80644943 | AB10: =+[2]Report1!AY10 -> 5758.1214 | AC10: =AB10+AC9 -> 10591.957 | AD10: =AB10/P10 -> 119.36157 | AE10: =AC10/Q10 -> 116.67592 | AF10: =IF(AND(R10>0,AB10>0),(AB10/(R10*1000))*1000,0) -> 117.27096 | AG10: =IF(AND(S10>0,AC10>0),AC10/S10,0) -> 119.09639 | AH10: 67.8 | AI10: =AH10+AI9 -> 130.7 | AJ10: =AH10/(P10) -> 1.4054435 | AK10: =AI10/(Q10) -> 1.4397286 | AL10: =IF(AND(R10>0,AH10>0),AH10/(R10),0) -> 1.3808273 | AM10: =IF(AND(S10>0,AI10>0),AI10/(S10),0) -> 1.4695961 | AN10: 10.9 | AO10: =AN10+AO9 -> 18.8 | AP10: =AN10/(P10) -> 0.22594888 | AQ10: =AO10/(Q10) -> 0.20709179 | AR10: =IF(AND(R10>0,AN10>0),AN10/(R10),0) -> 0.22199141 | AS10: =IF(AND(S10>0,AO10>0),AO10/(S10),0) -> 0.21138796 | AT10: ='2'!I46 -> 44439.78 | AU10: =AT10+AU9 -> 80831.08 | AV10: =IF(AND(L10>0,AT10>0),(AT10/(P10*1000)*1000),0) -> 921.20354 | AW10: =IF(AND(M10>0,AU10>0),(AU10/(Q10*1000)*1000),0) -> 890.39645 | AX10: =IF(AND(R10>0,AT10>0),(AT10/(R10*1000)*1000),0) -> 905.06874 | AY10: =IF(AND(S10>0,AU10>0),(AU10/(S10*1000)*1000),0) -> 908.86795 | AZ10: =+Listrik!S9 -> 24059.7 | BA10: =AZ10+BA9 -> 46510.18 | BB10: =IF(AND(L10>0,AZ10>0),(AZ10/(P10*1000)*1000),0) -> 498.73966 | BC10: =IF(AND(M10>0,BA10>0),(BA10/(Q10*1000)*1000),0) -> 512.33386 | BD10: =IF(AND(R10>0,AZ10>0),(AZ10/(R10*1000)*1000),0) -> 490.00428 | BE10: =IF(AND(S10>0,BA10>0),(BA10/(S10*1000)*1000),0) -> 522.96235 | BF10: =+Listrik!V9 -> 228 | BG10: =BF10+BG9 -> 540 | BH10: =IF(AND(L10>0,BF10>0),(BF10/(P10*1000)*1000),0) -> 4.7262702 | BI10: =IF(AND(M10>0,BG10>0),(BG10/(Q10*1000)*1000),0) -> 5.9483813 | BJ10: =IF(AND(R10>0,BF10>0),(BF10/(R10*1000)*1000),0) -> 4.6434899 | BK10: =IF(AND(S10>0,BG10>0),(BG10/(S10*1000)*1000),0) -> 6.071782 | BL10: =+SUM(Efficiency2!K12:K13) -> 55.123093 | BM10: =BM9+BL10 -> 110.28094 | BN10: =+R10/BL10 -> 0.89075191 | BO10: =+S10/BM10 -> 0.80644943
A11: =A10+1 -> 45964 | B11: Toilet | C11: 14 | D11: =+'3'!F42 -> 1223.3333 | E11: =+'3'!G42 -> 941.96667 | F11: =1-(E11/D11) -> 0.23 | G11: =+P11/N11 -> 0.96198683 | H11: =+P11/L11 -> 0.90874946 | I11: =+R11/P11 -> 0.9685984 | J11: =+R11/L11 -> 0.88021328 | K11: =+S11/M11 -> 0.83089635 | L11: =+Efficiency1!K17 -> 54.667433 | M11: =M10+L11 -> 164.94837 | N11: =+Efficiency1!C17 -> 51.642079 | O11: =O10+N11 -> 151.54058 | P11: ='3'!I38 -> 49.679 | Q11: =Q10+P11 -> 140.46 | R11: ='3'!I40 -> 48.119 | S11: =S10+R11 -> 137.055 | T11: =R11/P11 -> 0.9685984 | U11: =S11/Q11 -> 0.97575822 | V11: =R11/L11 -> 0.88021328 | W11: =S11/M11 -> 0.83089635 | AB11: =+[2]Report1!AY11 -> 5677.2508 | AC11: =AB11+AC10 -> 16269.208 | AD11: =AB11/P11 -> 114.27869 | AE11: =AC11/Q11 -> 115.82805 | AF11: =IF(AND(R11>0,AB11>0),(AB11/(R11*1000))*1000,0) -> 117.98356 | AG11: =IF(AND(S11>0,AC11>0),AC11/S11,0) -> 118.70568 | AH11: 69 | AI11: =AH11+AI10 -> 199.7 | AJ11: =AH11/(P11) -> 1.3889168 | AK11: =AI11/(Q11) -> 1.4217571 | AL11: =IF(AND(R11>0,AH11>0),AH11/(R11),0) -> 1.433945 | AM11: =IF(AND(S11>0,AI11>0),AI11/(S11),0) -> 1.4570793 | AN11: 9.9 | AO11: =AN11+AO10 -> 28.7 | AP11: =AN11/(P11) -> 0.19927937 | AQ11: =AO11/(Q11) -> 0.20432863 | AR11: =IF(AND(R11>0,AN11>0),AN11/(R11),0) -> 0.20573994 | AS11: =IF(AND(S11>0,AO11>0),AO11/(S11),0) -> 0.20940498 | AT11: ='3'!I46 -> 43607.08 | AU11: =AT11+AU10 -> 124438.16 | AV11: =IF(AND(L11>0,AT11>0),(AT11/(P11*1000)*1000),0) -> 877.77693 | AW11: =IF(AND(M11>0,AU11>0),(AU11/(Q11*1000)*1000),0) -> 885.93308 | AX11: =IF(AND(R11>0,AT11>0),(AT11/(R11*1000)*1000),0) -> 906.23413 | AY11: =IF(AND(S11>0,AU11>0),(AU11/(S11*1000)*1000),0) -> 907.94323 | AZ11: =+Listrik!S10 -> 20908.8 | BA11: =AZ11+BA10 -> 67418.98 | BB11: =IF(AND(L11>0,AZ11>0),(AZ11/(P11*1000)*1000),0) -> 420.87804 | BC11: =IF(AND(M11>0,BA11>0),(BA11/(Q11*1000)*1000),0) -> 479.98704 | BD11: =IF(AND(R11>0,AZ11>0),(AZ11/(R11*1000)*1000),0) -> 434.52275 | BE11: =IF(AND(S11>0,BA11>0),(BA11/(S11*1000)*1000),0) -> 491.91186 | BF11: =+Listrik!V10 -> 289.1 | BG11: =BF11+BG10 -> 829.1 | BH11: =IF(AND(L11>0,BF11>0),(BF11/(P11*1000)*1000),0) -> 5.8193603 | BI11: =IF(AND(M11>0,BG11>0),(BG11/(Q11*1000)*1000),0) -> 5.9027481 | BJ11: =IF(AND(R11>0,BF11>0),(BF11/(R11*1000)*1000),0) -> 6.0080218 | BK11: =IF(AND(S11>0,BG11>0),(BG11/(S11*1000)*1000),0) -> 6.0493962 | BL11: =+Efficiency2!K17 -> 54.667433 | BM11: =BM10+BL11 -> 164.94837 | BN11: =+R11/BL11 -> 0.88021328 | BO11: =+S11/BM11 -> 0.83089635
A12: =A11+1 -> 45965 | B12: Toilet | C12: 14/15 | D12: =+'4'!F42 -> 1194.1979 | E12: =+'4'!G42 -> 923.4341 | F12: =1-(E12/D12) -> 0.22673278 | G12: =+P12/N12 -> 0.97179805 | H12: =+P12/L12 -> 0.94179438 | I12: =+R12/P12 -> 0.97876377 | J12: =+R12/L12 -> 0.92179422 | K12: =+S12/M12 -> 0.85357949 | L12: =+SUM(Efficiency1!K22:K23) -> 54.849552 | M12: =M11+L12 -> 219.79792 | N12: =+SUM(Efficiency1!C22:C23) -> 53.156106 | O12: =O11+N12 -> 204.69668 | P12: ='4'!I38 -> 51.657 | Q12: =Q11+P12 -> 192.117 | R12: ='4'!I40 -> 50.56 | S12: =S11+R12 -> 187.615 | T12: =R12/P12 -> 0.97876377 | U12: =S12/Q12 -> 0.97656636 | V12: =R12/L12 -> 0.92179422 | W12: =S12/M12 -> 0.85357949 | AB12: =+[2]Report1!AY12 -> 5797.0014 | AC12: =AB12+AC11 -> 22066.209 | AD12: =AB12/P12 -> 112.22102 | AE12: =AC12/Q12 -> 114.85818 | AF12: =IF(AND(R12>0,AB12>0),(AB12/(R12*1000))*1000,0) -> 114.65588 | AG12: =IF(AND(S12>0,AC12>0),AC12/S12,0) -> 117.61431 | AH12: 68.5 | AI12: =AH12+AI11 -> 268.2 | AJ12: =AH12/(P12) -> 1.3260546 | AK12: =AI12/(Q12) -> 1.3960243 | AL12: =IF(AND(R12>0,AH12>0),AH12/(R12),0) -> 1.3548259 | AM12: =IF(AND(S12>0,AI12>0),AI12/(S12),0) -> 1.4295232 | AN12: 11.1 | AO12: =AN12+AO11 -> 39.8 | AP12: =AN12/(P12) -> 0.21487891 | AQ12: =AO12/(Q12) -> 0.20716543 | AR12: =IF(AND(R12>0,AN12>0),AN12/(R12),0) -> 0.21954114 | AS12: =IF(AND(S12>0,AO12>0),AO12/(S12),0) -> 0.21213656 | AT12: ='4'!I46 -> 40511.74 | AU12: =AT12+AU11 -> 164949.9 | AV12: =IF(AND(L12>0,AT12>0),(AT12/(P12*1000)*1000),0) -> 784.24492 | AW12: =IF(AND(M12>0,AU12>0),(AU12/(Q12*1000)*1000),0) -> 858.59086 | AX12: =IF(AND(R12>0,AT12>0),(AT12/(R12*1000)*1000),0) -> 801.26068 | AY12: =IF(AND(S12>0,AU12>0),(AU12/(S12*1000)*1000),0) -> 879.19356 | AZ12: =+Listrik!S11 -> 25540.8 | BA12: =AZ12+BA11 -> 92959.78 | BB12: =IF(AND(L12>0,AZ12>0),(AZ12/(P12*1000)*1000),0) -> 494.43057 | BC12: =IF(AND(M12>0,BA12>0),(BA12/(Q12*1000)*1000),0) -> 483.87066 | BD12: =IF(AND(R12>0,AZ12>0),(AZ12/(R12*1000)*1000),0) -> 505.15823 | BE12: =IF(AND(S12>0,BA12>0),(BA12/(S12*1000)*1000),0) -> 495.4816 | BF12: =+Listrik!V11 -> 323 | BG12: =BF12+BG11 -> 1152.1 | BH12: =IF(AND(L12>0,BF12>0),(BF12/(P12*1000)*1000),0) -> 6.2527828 | BI12: =IF(AND(M12>0,BG12>0),(BG12/(Q12*1000)*1000),0) -> 5.9968665 | BJ12: =IF(AND(R12>0,BF12>0),(BF12/(R12*1000)*1000),0) -> 6.3884494 | BK12: =IF(AND(S12>0,BG12>0),(BG12/(S12*1000)*1000),0) -> 6.140767 | BL12: =+SUM(Efficiency2!K22:K23) -> 54.849552 | BM12: =BM11+BL12 -> 219.79792 | BN12: =+R12/BL12 -> 0.92179422 | BO12: =+S12/BM12 -> 0.85357949
A13: =A12+1 -> 45966 | B13: Toilet/Towel | C13: 15/13,5/29/20 | D13: =+'5'!F42 -> 648.06859 | E13: =+'5'!G42 -> 543.40656 | F13: =1-(E13/D13) -> 0.16149839 | G13: =+P13/N13 -> 0.6001109 | H13: =+P13/L13 -> 0.5752344 | I13: =+R13/P13 -> 0.95383046 | J13: =+R13/L13 -> 0.54867609 | K13: =+S13/M13 -> 0.79449769 | L13: =+SUM(Efficiency1!K27:K30) -> 52.827161 | M13: =M12+L13 -> 272.62508 | N13: =+SUM(Efficiency1!C27:C30) -> 50.637307 | O13: =O12+N13 -> 255.33399 | P13: ='5'!I38 -> 30.388 | Q13: =Q12+P13 -> 222.505 | R13: ='5'!I40 -> 28.985 | S13: =S12+R13 -> 216.6 | T13: =R13/P13 -> 0.95383046 | U13: =S13/Q13 -> 0.97346127 | V13: =R13/L13 -> 0.54867609 | W13: =S13/M13 -> 0.79449769 | AB13: =+[2]Report1!AY13 -> 3284.0807 | AC13: =AB13+AC12 -> 25350.29 | AD13: =AB13/P13 -> 108.07163 | AE13: =AC13/Q13 -> 113.93133 | AF13: =IF(AND(R13>0,AB13>0),(AB13/(R13*1000))*1000,0) -> 113.30277 | AG13: =IF(AND(S13>0,AC13>0),AC13/S13,0) -> 117.03735 | AH13: 45.6 | AI13: =AH13+AI12 -> 313.8 | AJ13: =AH13/(P13) -> 1.5005923 | AK13: =AI13/(Q13) -> 1.4103054 | AL13: =IF(AND(R13>0,AH13>0),AH13/(R13),0) -> 1.5732275 | AM13: =IF(AND(S13>0,AI13>0),AI13/(S13),0) -> 1.4487535 | AN13: 6 | AO13: =AN13+AO12 -> 45.8 | AP13: =AN13/(P13) -> 0.19744636 | AQ13: =AO13/(Q13) -> 0.20583807 | AR13: =IF(AND(R13>0,AN13>0),AN13/(R13),0) -> 0.20700362 | AS13: =IF(AND(S13>0,AO13>0),AO13/(S13),0) -> 0.21144968 | AT13: ='5'!I46 -> 22984.56 | AU13: =AT13+AU12 -> 187934.46 | AV13: =IF(AND(L13>0,AT13>0),(AT13/(P13*1000)*1000),0) -> 756.36962 | AW13: =IF(AND(M13>0,AU13>0),(AU13/(Q13*1000)*1000),0) -> 844.63028 | AX13: =IF(AND(R13>0,AT13>0),(AT13/(R13*1000)*1000),0) -> 792.9812 | AY13: =IF(AND(S13>0,AU13>0),(AU13/(S13*1000)*1000),0) -> 867.65679 | AZ13: =+Listrik!S12 -> 13904.058 | BA13: =AZ13+BA12 -> 106863.84 | BB13: =IF(AND(L13>0,AZ13>0),(AZ13/(P13*1000)*1000),0) -> 457.55094 | BC13: =IF(AND(M13>0,BA13>0),(BA13/(Q13*1000)*1000),0) -> 480.27612 | BD13: =IF(AND(R13>0,AZ13>0),(AZ13/(R13*1000)*1000),0) -> 479.6984 | BE13: =IF(AND(S13>0,BA13>0),(BA13/(S13*1000)*1000),0) -> 493.36952 | BF13: =+Listrik!V12 -> 215.6 | BG13: =BF13+BG12 -> 1367.7 | BH13: =IF(AND(L13>0,BF13>0),(BF13/(P13*1000)*1000),0) -> 7.0949059 | BI13: =IF(AND(M13>0,BG13>0),(BG13/(Q13*1000)*1000),0) -> 6.1468282 | BJ13: =IF(AND(R13>0,BF13>0),(BF13/(R13*1000)*1000),0) -> 7.4383302 | BK13: =IF(AND(S13>0,BG13>0),(BG13/(S13*1000)*1000),0) -> 6.3144044 | BL13: =+SUM(Efficiency2!K27:K30) -> 52.827161 | BM13: =BM12+BL13 -> 272.62508 | BN13: =+R13/BL13 -> 0.54867609 | BO13: =+S13/BM13 -> 0.79449769
A14: =A13+1 -> 45967 | B14: Towel | C14: 20 | D14: =+'6'!F42 -> 875 | E14: =+'6'!G42 -> 743.75 | F14: =1-(E14/D14) -> 0.15 | G14: =+P14/N14 -> 1.0541256 | H14: =+P14/L14 -> 1.0541256 | I14: =+R14/P14 -> 0.95352907 | J14: =+R14/L14 -> 1.0051395 | K14: =+S14/M14 -> 0.83030316 | L14: =+Efficiency1!K33 -> 55.832054 | M14: =M13+L14 -> 328.45714 | N14: =+Efficiency1!C33 -> 55.832054 | O14: =O13+N14 -> 311.16605 | P14: ='6'!I38 -> 58.854 | Q14: =Q13+P14 -> 281.359 | R14: ='6'!I40 -> 56.119 | S14: =S13+R14 -> 272.719 | T14: =R14/P14 -> 0.95352907 | U14: =S14/Q14 -> 0.9692919 | V14: =R14/L14 -> 1.0051395 | W14: =S14/M14 -> 0.83030316 | AB14: =+[2]Report1!AY14 -> 5525.764 | AC14: =AB14+AC13 -> 30876.054 | AD14: =AB14/P14 -> 93.889354 | AE14: =AC14/Q14 -> 109.73899 | AF14: =IF(AND(R14>0,AB14>0),(AB14/(R14*1000))*1000,0) -> 98.465119 | AG14: =IF(AND(S14>0,AC14>0),AC14/S14,0) -> 113.21563 | AH14: 70.7 | AI14: =AH14+AI13 -> 384.5 | AJ14: =AH14/(P14) -> 1.2012777 | AK14: =AI14/(Q14) -> 1.3665815 | AL14: =IF(AND(R14>0,AH14>0),AH14/(R14),0) -> 1.2598229 | AM14: =IF(AND(S14>0,AI14>0),AI14/(S14),0) -> 1.4098761 | AN14: 11 | AO14: =AN14+AO13 -> 56.8 | AP14: =AN14/(P14) -> 0.18690318 | AQ14: =AO14/(Q14) -> 0.20187732 | AR14: =IF(AND(R14>0,AN14>0),AN14/(R14),0) -> 0.19601205 | AS14: =IF(AND(S14>0,AO14>0),AO14/(S14),0) -> 0.20827298 | AT14: ='6'!I46 -> 38259.78 | AU14: =AT14+AU13 -> 226194.24 | AV14: =IF(AND(L14>0,AT14>0),(AT14/(P14*1000)*1000),0) -> 650.07952 | AW14: =IF(AND(M14>0,AU14>0),(AU14/(Q14*1000)*1000),0) -> 803.93462 | AX14: =IF(AND(R14>0,AT14>0),(AT14/(R14*1000)*1000),0) -> 681.76161 | AY14: =IF(AND(S14>0,AU14>0),(AU14/(S14*1000)*1000),0) -> 829.40404 | AZ14: =+Listrik!S13 -> 26617.534 | BA14: =AZ14+BA13 -> 133481.37 | BB14: =IF(AND(L14>0,AZ14>0),(AZ14/(P14*1000)*1000),0) -> 452.26381 | BC14: =IF(AND(M14>0,BA14>0),(BA14/(Q14*1000)*1000),0) -> 474.41657 | BD14: =IF(AND(R14>0,AZ14>0),(AZ14/(R14*1000)*1000),0) -> 474.30521 | BE14: =IF(AND(S14>0,BA14>0),(BA14/(S14*1000)*1000),0) -> 489.44654 | BF14: =+Listrik!V13 -> 301.8 | BG14: =BF14+BG13 -> 1669.5 | BH14: =IF(AND(L14>0,BF14>0),(BF14/(P14*1000)*1000),0) -> 5.1279437 | BI14: =IF(AND(M14>0,BG14>0),(BG14/(Q14*1000)*1000),0) -> 5.9337004 | BJ14: =IF(AND(R14>0,BF14>0),(BF14/(R14*1000)*1000),0) -> 5.3778578 | BK14: =IF(AND(S14>0,BG14>0),(BG14/(S14*1000)*1000),0) -> 6.1216857 | BL14: =+Efficiency2!K33 -> 55.832054 | BM14: =BM13+BL14 -> 328.45714 | BN14: =+R14/BL14 -> 1.0051395 | BO14: =+S14/BM14 -> 0.83030316
A15: =A14+1 -> 45968 | B15: Towel | C15: 20/19 | D15: =+'7'!F42 -> 912.45139 | E15: =+'7'!G42 -> 775.58368 | F15: =1-(E15/D15) -> 0.15 | G15: =+P15/N15 -> 0.98274168 | H15: =+P15/L15 -> 0.98274168 | I15: =+R15/P15 -> 0.96982869 | J15: =+R15/L15 -> 0.95309108 | K15: =+S15/M15 -> 0.84912389 | L15: =+SUM(Efficiency1!K38:K39) -> 59.459165 | M15: =M14+L15 -> 387.9163 | N15: =+SUM(Efficiency1!C38:C39) -> 59.459165 | O15: =O14+N15 -> 370.62521 | P15: ='7'!I38 -> 58.433 | Q15: =Q14+P15 -> 339.792 | R15: ='7'!I40 -> 56.67 | S15: =S14+R15 -> 329.389 | T15: =R15/P15 -> 0.96982869 | U15: =S15/Q15 -> 0.96938421 | V15: =R15/L15 -> 0.95309108 | W15: =S15/M15 -> 0.84912389 | AB15: =+[2]Report1!AY15 -> 5630.8735 | AC15: =AB15+AC14 -> 36506.927 | AD15: =AB15/P15 -> 96.364614 | AE15: =AC15/Q15 -> 107.43904 | AF15: =IF(AND(R15>0,AB15>0),(AB15/(R15*1000))*1000,0) -> 99.362511 | AG15: =IF(AND(S15>0,AC15>0),AC15/S15,0) -> 110.83226 | AH15: 66.1 | AI15: =AH15+AI14 -> 450.6 | AJ15: =AH15/(P15) -> 1.1312101 | AK15: =AI15/(Q15) -> 1.3261054 | AL15: =IF(AND(R15>0,AH15>0),AH15/(R15),0) -> 1.166402 | AM15: =IF(AND(S15>0,AI15>0),AI15/(S15),0) -> 1.3679874 | AN15: 10.8 | AO15: =AN15+AO14 -> 67.6 | AP15: =AN15/(P15) -> 0.18482707 | AQ15: =AO15/(Q15) -> 0.19894524 | AR15: =IF(AND(R15>0,AN15>0),AN15/(R15),0) -> 0.19057702 | AS15: =IF(AND(S15>0,AO15>0),AO15/(S15),0) -> 0.20522847 | AT15: ='7'!I46 -> 37846.1 | AU15: =AT15+AU14 -> 264040.34 | AV15: =IF(AND(L15>0,AT15>0),(AT15/(P15*1000)*1000),0) -> 647.68367 | AW15: =IF(AND(M15>0,AU15>0),(AU15/(Q15*1000)*1000),0) -> 777.06462 | AX15: =IF(AND(R15>0,AT15>0),(AT15/(R15*1000)*1000),0) -> 667.83307 | AY15: =IF(AND(S15>0,AU15>0),(AU15/(S15*1000)*1000),0) -> 801.60643 | AZ15: =+Listrik!S14 -> 26562.965 | BA15: =AZ15+BA14 -> 160044.34 | BB15: =IF(AND(L15>0,AZ15>0),(AZ15/(P15*1000)*1000),0) -> 454.58842 | BC15: =IF(AND(M15>0,BA15>0),(BA15/(Q15*1000)*1000),0) -> 471.00678 | BD15: =IF(AND(R15>0,AZ15>0),(AZ15/(R15*1000)*1000),0) -> 468.73063 | BE15: =IF(AND(S15>0,BA15>0),(BA15/(S15*1000)*1000),0) -> 485.88246 | BF15: =+Listrik!V14 -> 327 | BG15: =BF15+BG14 -> 1996.5 | BH15: =IF(AND(L15>0,BF15>0),(BF15/(P15*1000)*1000),0) -> 5.5961529 | BI15: =IF(AND(M15>0,BG15>0),(BG15/(Q15*1000)*1000),0) -> 5.8756533 | BJ15: =IF(AND(R15>0,BF15>0),(BF15/(R15*1000)*1000),0) -> 5.7702488 | BK15: =IF(AND(S15>0,BG15>0),(BG15/(S15*1000)*1000),0) -> 6.0612224 | BL15: =+SUM(Efficiency2!K38:K39) -> 59.459165 | BM15: =BM14+BL15 -> 387.9163 | BN15: =+R15/BL15 -> 0.95309108 | BO15: =+S15/BM15 -> 0.84912389
A16: =A15+1 -> 45969 | B16: Towel | C16: 19/17 | D16: =+'8'!F42 -> 946.66667 | E16: =+'8'!G42 -> 804.66667 | F16: =1-(E16/D16) -> 0.15 | G16: =+P16/N16 -> 1.0159443 | H16: =+P16/L16 -> 1.0159443 | I16: =+R16/P16 -> 0.96276058 | J16: =+R16/L16 -> 0.97811113 | K16: =+S16/M16 -> 0.86452548 | L16: =+SUM(Efficiency1!K43:K44) -> 52.59934 | M16: =M15+L16 -> 440.51564 | N16: =+SUM(Efficiency1!C43:C44) -> 52.59934 | O16: =O15+N16 -> 423.22455 | P16: ='8'!I38 -> 53.438 | Q16: =Q15+P16 -> 393.23 | R16: ='8'!I40 -> 51.448 | S16: =S15+R16 -> 380.837 | T16: =R16/P16 -> 0.96276058 | U16: =S16/Q16 -> 0.96848409 | V16: =R16/L16 -> 0.97811113 | W16: =S16/M16 -> 0.86452548 | AB16: =+[2]Report1!AY16 -> 5736.9246 | AC16: =AB16+AC15 -> 42243.852 | AD16: =AB16/P16 -> 107.35665 | AE16: =AC16/Q16 -> 107.42785 | AF16: =IF(AND(R16>0,AB16>0),(AB16/(R16*1000))*1000,0) -> 111.50919 | AG16: =IF(AND(S16>0,AC16>0),AC16/S16,0) -> 110.92371 | AH16: 66.6 | AI16: =AH16+AI15 -> 517.2 | AJ16: =AH16/(P16) -> 1.2463041 | AK16: =AI16/(Q16) -> 1.3152608 | AL16: =IF(AND(R16>0,AH16>0),AH16/(R16),0) -> 1.294511 | AM16: =IF(AND(S16>0,AI16>0),AI16/(S16),0) -> 1.3580613 | AN16: 10.4 | AO16: =AN16+AO15 -> 78 | AP16: =AN16/(P16) -> 0.19461806 | AQ16: =AO16/(Q16) -> 0.1983572 | AR16: =IF(AND(R16>0,AN16>0),AN16/(R16),0) -> 0.20214586 | AS16: =IF(AND(S16>0,AO16>0),AO16/(S16),0) -> 0.20481203 | AT16: ='8'!I46 -> 41738.5 | AU16: =AT16+AU15 -> 305778.84 | AV16: =IF(AND(L16>0,AT16>0),(AT16/(P16*1000)*1000),0) -> 781.06404 | AW16: =IF(AND(M16>0,AU16>0),(AU16/(Q16*1000)*1000),0) -> 777.60812 | AX16: =IF(AND(R16>0,AT16>0),(AT16/(R16*1000)*1000),0) -> 811.27546 | AY16: =IF(AND(S16>0,AU16>0),(AU16/(S16*1000)*1000),0) -> 802.91264 | AZ16: =+Listrik!S15 -> 27933.703 | BA16: =AZ16+BA15 -> 187978.04 | BB16: =IF(AND(L16>0,AZ16>0),(AZ16/(P16*1000)*1000),0) -> 522.73107 | BC16: =IF(AND(M16>0,BA16>0),(BA16/(Q16*1000)*1000),0) -> 478.03586 | BD16: =IF(AND(R16>0,AZ16>0),(AZ16/(R16*1000)*1000),0) -> 542.95022 | BE16: =IF(AND(S16>0,BA16>0),(BA16/(S16*1000)*1000),0) -> 493.59185 | BF16: =+Listrik!V15 -> 297.1 | BG16: =BF16+BG15 -> 2293.6 | BH16: =IF(AND(L16>0,BF16>0),(BF16/(P16*1000)*1000),0) -> 5.5597141 | BI16: =IF(AND(M16>0,BG16>0),(BG16/(Q16*1000)*1000),0) -> 5.8327188 | BJ16: =IF(AND(R16>0,BF16>0),(BF16/(R16*1000)*1000),0) -> 5.7747629 | BK16: =IF(AND(S16>0,BG16>0),(BG16/(S16*1000)*1000),0) -> 6.0225241 | BL16: =+SUM(Efficiency2!K43:K44) -> 52.59934 | BM16: =BM15+BL16 -> 440.51564 | BN16: =+R16/BL16 -> 0.97811113 | BO16: =+S16/BM16 -> 0.86452548
A17: =A16+1 -> 45970 | B17: Towel/Facial/Toilet | C17: 17/14/16,5/13,5 | D17: =+'9'!F42 -> 1066.5278 | E17: =+'9'!G42 -> 857.82049 | F17: =1-(E17/D17) -> 0.19568857 | G17: =+P17/N17 -> 0.97288516 | H17: =+P17/L17 -> 0.93858327 | I17: =+R17/P17 -> 1.0100615 | J17: =+R17/L17 -> 0.94802685 | K17: =+S17/M17 -> 0.87351675 | L17: =+SUM(Efficiency1!K48:K51) -> 53.157777 | M17: =M16+L17 -> 493.67342 | N17: =+SUM(Efficiency1!C48:C51) -> 51.283545 | O17: =O16+N17 -> 474.5081 | P17: ='9'!I38 -> 49.893 | Q17: =Q16+P17 -> 443.123 | R17: ='9'!I40 -> 50.395 | S17: =S16+R17 -> 431.232 | T17: =R17/P17 -> 1.0100615 | U17: =S17/Q17 -> 0.97316546 | V17: =R17/L17 -> 0.94802685 | W17: =S17/M17 -> 0.87351675 | AB17: =+[2]Report1!AY17 -> 5178.5088 | AC17: =AB17+AC16 -> 47422.361 | AD17: =AB17/P17 -> 103.79229 | AE17: =AC17/Q17 -> 107.0185 | AF17: =IF(AND(R17>0,AB17>0),(AB17/(R17*1000))*1000,0) -> 102.75839 | AG17: =IF(AND(S17>0,AC17>0),AC17/S17,0) -> 109.96948 | AH17: 65.8 | AI17: =AH17+AI16 -> 583 | AJ17: =AH17/(P17) -> 1.3188223 | AK17: =AI17/(Q17) -> 1.3156618 | AL17: =IF(AND(R17>0,AH17>0),AH17/(R17),0) -> 1.3056851 | AM17: =IF(AND(S17>0,AI17>0),AI17/(S17),0) -> 1.3519405 | AN17: 10.8 | AO17: =AN17+AO16 -> 88.8 | AP17: =AN17/(P17) -> 0.21646323 | AQ17: =AO17/(Q17) -> 0.20039583 | AR17: =IF(AND(R17>0,AN17>0),AN17/(R17),0) -> 0.21430697 | AS17: =IF(AND(S17>0,AO17>0),AO17/(S17),0) -> 0.20592164 | AT17: ='9'!I46 -> 39197.94 | AU17: =AT17+AU16 -> 344976.78 | AV17: =IF(AND(L17>0,AT17>0),(AT17/(P17*1000)*1000),0) -> 785.64007 | AW17: =IF(AND(M17>0,AU17>0),(AU17/(Q17*1000)*1000),0) -> 778.51247 | AX17: =IF(AND(R17>0,AT17>0),(AT17/(R17*1000)*1000),0) -> 777.81407 | AY17: =IF(AND(S17>0,AU17>0),(AU17/(S17*1000)*1000),0) -> 799.97955 | AZ17: =+Listrik!S16 -> 25080.7 | BA17: =AZ17+BA16 -> 213058.74 | BB17: =IF(AND(L17>0,AZ17>0),(AZ17/(P17*1000)*1000),0) -> 502.68976 | BC17: =IF(AND(M17>0,BA17>0),(BA17/(Q17*1000)*1000),0) -> 480.81174 | BD17: =IF(AND(R17>0,AZ17>0),(AZ17/(R17*1000)*1000),0) -> 497.68231 | BE17: =IF(AND(S17>0,BA17>0),(BA17/(S17*1000)*1000),0) -> 494.06987 | BF17: =+Listrik!V16 -> 296.4 | BG17: =BF17+BG16 -> 2590 | BH17: =IF(AND(L17>0,BF17>0),(BF17/(P17*1000)*1000),0) -> 5.9407131 | BI17: =IF(AND(M17>0,BG17>0),(BG17/(Q17*1000)*1000),0) -> 5.8448783 | BJ17: =IF(AND(R17>0,BF17>0),(BF17/(R17*1000)*1000),0) -> 5.8815359 | BK17: =IF(AND(S17>0,BG17>0),(BG17/(S17*1000)*1000),0) -> 6.0060478 | BL17: =+SUM(Efficiency2!K48:K51) -> 53.157777 | BM17: =BM16+BL17 -> 493.67342 | BN17: =+R17/BL17 -> 0.94802685 | BO17: =+S17/BM17 -> 0.87351675
A18: =A17+1 -> 45971 | B18: Toilet | C18: 13,5 | D18: =+'10'!F42 -> 1303.3333 | E18: =+'10'!G42 -> 1003.5667 | F18: =1-(E18/D18) -> 0.23 | G18: =+P18/N18 -> 0.96124669 | H18: =+P18/L18 -> 0.93146829 | I18: =+R18/P18 -> 0.99606882 | J18: =+R18/L18 -> 0.92780652 | K18: =+S18/M18 -> 0.87897349 | L18: =+Efficiency1!K53 -> 55.164519 | M18: =M17+L18 -> 548.83794 | N18: =+Efficiency1!C53 -> 53.455581 | O18: =O17+N18 -> 527.96368 | P18: ='10'!I38 -> 51.384 | Q18: =Q17+P18 -> 494.507 | R18: ='10'!I40 -> 51.182 | S18: =S17+R18 -> 482.414 | T18: =R18/P18 -> 0.99606882 | U18: =S18/Q18 -> 0.97554534 | V18: =R18/L18 -> 0.92780652 | W18: =S18/M18 -> 0.87897349 | AB18: =+[2]Report1!AY18 -> 6057.2294 | AC18: =AB18+AC17 -> 53479.59 | AD18: =AB18/P18 -> 117.88162 | AE18: =AC18/Q18 -> 108.14729 | AF18: =IF(AND(R18>0,AB18>0),(AB18/(R18*1000))*1000,0) -> 118.34687 | AG18: =IF(AND(S18>0,AC18>0),AC18/S18,0) -> 110.85829 | AH18: 65.9 | AI18: =AH18+AI17 -> 648.9 | AJ18: =AH18/(P18) -> 1.2825004 | AK18: =AI18/(Q18) -> 1.312216 | AL18: =IF(AND(R18>0,AH18>0),AH18/(R18),0) -> 1.287562 | AM18: =IF(AND(S18>0,AI18>0),AI18/(S18),0) -> 1.3451102 | AN18: 9.6 | AO18: =AN18+AO17 -> 98.4 | AP18: =AN18/(P18) -> 0.18682858 | AQ18: =AO18/(Q18) -> 0.19898606 | AR18: =IF(AND(R18>0,AN18>0),AN18/(R18),0) -> 0.18756594 | AS18: =IF(AND(S18>0,AO18>0),AO18/(S18),0) -> 0.20397418 | AT18: ='10'!I46 -> 42912.24 | AU18: =AT18+AU17 -> 387889.02 | AV18: =IF(AND(L18>0,AT18>0),(AT18/(P18*1000)*1000),0) -> 835.12844 | AW18: =IF(AND(M18>0,AU18>0),(AU18/(Q18*1000)*1000),0) -> 784.39541 | AX18: =IF(AND(R18>0,AT18>0),(AT18/(R18*1000)*1000),0) -> 838.42445 | AY18: =IF(AND(S18>0,AU18>0),(AU18/(S18*1000)*1000),0) -> 804.05838 | AZ18: =+Listrik!S17 -> 24949.2 | BA18: =AZ18+BA17 -> 238007.94 | BB18: =IF(AND(L18>0,AZ18>0),(AZ18/(P18*1000)*1000),0) -> 485.54414 | BC18: =IF(AND(M18>0,BA18>0),(BA18/(Q18*1000)*1000),0) -> 481.30348 | BD18: =IF(AND(R18>0,AZ18>0),(AZ18/(R18*1000)*1000),0) -> 487.46044 | BE18: =IF(AND(S18>0,BA18>0),(BA18/(S18*1000)*1000),0) -> 493.36864 | BF18: =+Listrik!V17 -> 310.1 | BG18: =BF18+BG17 -> 2900.1 | BH18: =IF(AND(L18>0,BF18>0),(BF18/(P18*1000)*1000),0) -> 6.0349525 | BI18: =IF(AND(M18>0,BG18>0),(BG18/(Q18*1000)*1000),0) -> 5.8646288 | BJ18: =IF(AND(R18>0,BF18>0),(BF18/(R18*1000)*1000),0) -> 6.0587707 | BK18: =IF(AND(S18>0,BG18>0),(BG18/(S18*1000)*1000),0) -> 6.0116415 | BL18: =+Efficiency2!K53 -> 55.164519 | BM18: =BM17+BL18 -> 548.83794 | BN18: =+R18/BL18 -> 0.92780652 | BO18: =+S18/BM18 -> 0.87897349
A19: =A18+1 -> 45972 | B19: Toilet | C19: 13,5 | D19: =+'11'!F42 -> 1303.3333 | E19: =+'11'!G42 -> 1003.5667 | F19: =1-(E19/D19) -> 0.23 | G19: =+P19/N19 -> 0.98320885 | H19: =+P19/L19 -> 0.95275009 | I19: =+R19/P19 -> 0.96375433 | J19: =+R19/L19 -> 0.91821702 | K19: =+S19/M19 -> 0.88255767 | L19: =+Efficiency1!K58 -> 55.164519 | M19: =M18+L19 -> 604.00246 | N19: =+Efficiency1!C58 -> 53.455581 | O19: =O18+N19 -> 581.41926 | P19: ='11'!I38 -> 52.558 | Q19: =Q18+P19 -> 547.065 | R19: ='11'!I40 -> 50.653 | S19: =S18+R19 -> 533.067 | T19: =R19/P19 -> 0.96375433 | U19: =S19/Q19 -> 0.97441255 | V19: =R19/L19 -> 0.91821702 | W19: =S19/M19 -> 0.88255767 | AB19: =+[2]Report1!AY19 -> 5520.4515 | AC19: =AB19+AC18 -> 59000.042 | AD19: =AB19/P19 -> 105.03542 | AE19: =AC19/Q19 -> 107.84832 | AF19: =IF(AND(R19>0,AB19>0),(AB19/(R19*1000))*1000,0) -> 108.98568 | AG19: =IF(AND(S19>0,AC19>0),AC19/S19,0) -> 110.68035 | AH19: 69.9 | AI19: =AH19+AI18 -> 718.8 | AJ19: =AH19/(P19) -> 1.3299593 | AK19: =AI19/(Q19) -> 1.3139206 | AL19: =IF(AND(R19>0,AH19>0),AH19/(R19),0) -> 1.3799775 | AM19: =IF(AND(S19>0,AI19>0),AI19/(S19),0) -> 1.3484234 | AN19: 9.8 | AO19: =AN19+AO18 -> 108.2 | AP19: =AN19/(P19) -> 0.18646067 | AQ19: =AO19/(Q19) -> 0.19778271 | AR19: =IF(AND(R19>0,AN19>0),AN19/(R19),0) -> 0.19347324 | AS19: =IF(AND(S19>0,AO19>0),AO19/(S19),0) -> 0.20297636 | AT19: ='11'!I46 -> 44245.74 | AU19: =AT19+AU18 -> 432134.76 | AV19: =IF(AND(L19>0,AT19>0),(AT19/(P19*1000)*1000),0) -> 841.84596 | AW19: =IF(AND(M19>0,AU19>0),(AU19/(Q19*1000)*1000),0) -> 789.91484 | AX19: =IF(AND(R19>0,AT19>0),(AT19/(R19*1000)*1000),0) -> 873.5068 | AY19: =IF(AND(S19>0,AU19>0),(AU19/(S19*1000)*1000),0) -> 810.6575 | AZ19: =+Listrik!S18 -> 22984 | BA19: =AZ19+BA18 -> 260991.94 | BB19: =IF(AND(L19>0,AZ19>0),(AZ19/(P19*1000)*1000),0) -> 437.30736 | BC19: =IF(AND(M19>0,BA19>0),(BA19/(Q19*1000)*1000),0) -> 477.07665 | BD19: =IF(AND(R19>0,AZ19>0),(AZ19/(R19*1000)*1000),0) -> 453.75397 | BE19: =IF(AND(S19>0,BA19>0),(BA19/(S19*1000)*1000),0) -> 489.60438 | BF19: =+Listrik!V18 -> 339.9 | BG19: =BF19+BG18 -> 3240 | BH19: =IF(AND(L19>0,BF19>0),(BF19/(P19*1000)*1000),0) -> 6.4671411 | BI19: =IF(AND(M19>0,BG19>0),(BG19/(Q19*1000)*1000),0) -> 5.9225138 | BJ19: =IF(AND(R19>0,BF19>0),(BF19/(R19*1000)*1000),0) -> 6.7103627 | BK19: =IF(AND(S19>0,BG19>0),(BG19/(S19*1000)*1000),0) -> 6.0780352 | BL19: =+Efficiency2!K58 -> 55.164519 | BM19: =BM18+BL19 -> 604.00246 | BN19: =+R19/BL19 -> 0.91821702 | BO19: =+S19/BM19 -> 0.88255767
A20: =A19+1 -> 45973 | B20: Toilet | C20: 13,5 | D20: =+'12'!F42 -> 1300 | E20: =+'12'!G42 -> 1001 | F20: =1-(E20/D20) -> 0.23 | G20: =+P20/N20 -> 0.95255215 | H20: =+P20/L20 -> 0.92068237 | I20: =+R20/P20 -> 0.96733545 | J20: =+R20/L20 -> 0.8906087 | K20: =+S20/M20 -> 0.88323144 | L20: =+Efficiency1!K63 -> 55.164519 | M20: =M19+L20 -> 659.16698 | N20: =+Efficiency1!C63 -> 53.318866 | O20: =O19+N20 -> 634.73812 | P20: ='12'!I38 -> 50.789 | Q20: =Q19+P20 -> 597.854 | R20: ='12'!I40 -> 49.13 | S20: =S19+R20 -> 582.197 | T20: =R20/P20 -> 0.96733545 | U20: =S20/Q20 -> 0.97381133 | V20: =R20/L20 -> 0.8906087 | W20: =S20/M20 -> 0.88323144 | AB20: =+[2]Report1!AY20 -> 5202.9033 | AC20: =AB20+AC19 -> 64202.945 | AD20: =AB20/P20 -> 102.44154 | AE20: =AC20/Q20 -> 107.389 | AF20: =IF(AND(R20>0,AB20>0),(AB20/(R20*1000))*1000,0) -> 105.90074 | AG20: =IF(AND(S20>0,AC20>0),AC20/S20,0) -> 110.27701 | AH20: 71.6 | AI20: =AH20+AI19 -> 790.4 | AJ20: =AH20/(P20) -> 1.4097541 | AK20: =AI20/(Q20) -> 1.3220619 | AL20: =IF(AND(R20>0,AH20>0),AH20/(R20),0) -> 1.457358 | AM20: =IF(AND(S20>0,AI20>0),AI20/(S20),0) -> 1.3576161 | AN20: 8.6 | AO20: =AN20+AO19 -> 116.8 | AP20: =AN20/(P20) -> 0.169328 | AQ20: =AO20/(Q20) -> 0.19536542 | AR20: =IF(AND(R20>0,AN20>0),AN20/(R20),0) -> 0.1750458 | AS20: =IF(AND(S20>0,AO20>0),AO20/(S20),0) -> 0.20061938 | AT20: ='12'!I46 -> 42773.86 | AU20: =AT20+AU19 -> 474908.62 | AV20: =IF(AND(L20>0,AT20>0),(AT20/(P20*1000)*1000),0) -> 842.18748 | AW20: =IF(AND(M20>0,AU20>0),(AU20/(Q20*1000)*1000),0) -> 794.35551 | AX20: =IF(AND(R20>0,AT20>0),(AT20/(R20*1000)*1000),0) -> 870.62609 | AY20: =IF(AND(S20>0,AU20>0),(AU20/(S20*1000)*1000),0) -> 815.71808 | AZ20: =+Listrik!S19 -> 23558.4 | BA20: =AZ20+BA19 -> 284550.34 | BB20: =IF(AND(L20>0,AZ20>0),(AZ20/(P20*1000)*1000),0) -> 463.84847 | BC20: =IF(AND(M20>0,BA20>0),(BA20/(Q20*1000)*1000),0) -> 475.95289 | BD20: =IF(AND(R20>0,AZ20>0),(AZ20/(R20*1000)*1000),0) -> 479.5115 | BE20: =IF(AND(S20>0,BA20>0),(BA20/(S20*1000)*1000),0) -> 488.75267 | BF20: =+Listrik!V19 -> 340.1 | BG20: =BF20+BG19 -> 3580.1 | BH20: =IF(AND(L20>0,BF20>0),(BF20/(P20*1000)*1000),0) -> 6.6963319 | BI20: =IF(AND(M20>0,BG20>0),(BG20/(Q20*1000)*1000),0) -> 5.9882513 | BJ20: =IF(AND(R20>0,BF20>0),(BF20/(R20*1000)*1000),0) -> 6.9224506 | BK20: =IF(AND(S20>0,BG20>0),(BG20/(S20*1000)*1000),0) -> 6.1492931 | BL20: =+Efficiency2!K63 -> 55.164519 | BM20: =BM19+BL20 -> 659.16698 | BN20: =+R20/BL20 -> 0.8906087 | BO20: =+S20/BM20 -> 0.88323144
A21: =A20+1 -> 45974 | B21: Toilet | C21: 13,5 | D21: =+'13'!F42 -> 1214.2355 | E21: =+'13'!G42 -> 934.96134 | F21: =1-(E21/D21) -> 0.23 | G21: =+P21/N21 -> 0.76923731 | H21: =+P21/L21 -> 0.69445 | I21: =+R21/P21 -> 0.76898379 | J21: =+R21/L21 -> 0.53402079 | K21: =+S21/M21 -> 0.85626352 | L21: =+Efficiency1!K68 -> 55.164519 | M21: =M20+L21 -> 714.3315 | N21: =+Efficiency1!C68 -> 49.801277 | O21: =O20+N21 -> 684.5394 | P21: ='13'!I38 -> 38.309 | Q21: =Q20+P21 -> 636.163 | R21: ='13'!I40 -> 29.459 | S21: =S20+R21 -> 611.656 | T21: =R21/P21 -> 0.76898379 | U21: =S21/Q21 -> 0.96147685 | V21: =R21/L21 -> 0.53402079 | W21: =S21/M21 -> 0.85626352 | AB21: =+[2]Report1!AY21 -> 4176.7593 | AC21: =AB21+AC20 -> 68379.704 | AD21: =AB21/P21 -> 109.02815 | AE21: =AC21/Q21 -> 107.48771 | AF21: =IF(AND(R21>0,AB21>0),(AB21/(R21*1000))*1000,0) -> 141.78211 | AG21: =IF(AND(S21>0,AC21>0),AC21/S21,0) -> 111.79438 | AH21: 61.5 | AI21: =AH21+AI20 -> 851.9 | AJ21: =AH21/(P21) -> 1.6053669 | AK21: =AI21/(Q21) -> 1.3391222 | AL21: =IF(AND(R21>0,AH21>0),AH21/(R21),0) -> 2.0876472 | AM21: =IF(AND(S21>0,AI21>0),AI21/(S21),0) -> 1.3927763 | AN21: 8.1 | AO21: =AN21+AO20 -> 124.9 | AP21: =AN21/(P21) -> 0.21143857 | AQ21: =AO21/(Q21) -> 0.19633333 | AR21: =IF(AND(R21>0,AN21>0),AN21/(R21),0) -> 0.27495842 | AS21: =IF(AND(S21>0,AO21>0),AO21/(S21),0) -> 0.20419975 | AT21: ='13'!I46 -> 37379.3 | AU21: =AT21+AU20 -> 512287.92 | AV21: =IF(AND(L21>0,AT21>0),(AT21/(P21*1000)*1000),0) -> 975.73155 | AW21: =IF(AND(M21>0,AU21>0),(AU21/(Q21*1000)*1000),0) -> 805.27777 | AX21: =IF(AND(R21>0,AT21>0),(AT21/(R21*1000)*1000),0) -> 1268.8584 | AY21: =IF(AND(S21>0,AU21>0),(AU21/(S21*1000)*1000),0) -> 837.54254 | AZ21: =+Listrik!S20 -> 19986.3 | BA21: =AZ21+BA20 -> 304536.64 | BB21: =IF(AND(L21>0,AZ21>0),(AZ21/(P21*1000)*1000),0) -> 521.71291 | BC21: =IF(AND(M21>0,BA21>0),(BA21/(Q21*1000)*1000),0) -> 478.70851 | BD21: =IF(AND(R21>0,AZ21>0),(AZ21/(R21*1000)*1000),0) -> 678.44462 | BE21: =IF(AND(S21>0,BA21>0),(BA21/(S21*1000)*1000),0) -> 497.88875 | BF21: =+Listrik!V20 -> 230.1 | BG21: =BF21+BG20 -> 3810.2 | BH21: =IF(AND(L21>0,BF21>0),(BF21/(P21*1000)*1000),0) -> 6.0064215 | BI21: =IF(AND(M21>0,BG21>0),(BG21/(Q21*1000)*1000),0) -> 5.9893455 | BJ21: =IF(AND(R21>0,BF21>0),(BF21/(R21*1000)*1000),0) -> 7.8108558 | BK21: =IF(AND(S21>0,BG21>0),(BG21/(S21*1000)*1000),0) -> 6.2293184 | BL21: =+Efficiency2!K68 -> 55.164519 | BM21: =BM20+BL21 -> 714.3315 | BN21: =+R21/BL21 -> 0.53402079 | BO21: =+S21/BM21 -> 0.85626352
A22: =A21+1 -> 45975 | B22: Toilet | C22: 13,5/15,5 | D22: =+'14'!F42 -> 1124.0417 | E22: =+'14'!G42 -> 865.51208 | F22: =1-(E22/D22) -> 0.23 | G22: =+P22/N22 -> 0.96124258 | H22: =+P22/L22 -> 0.89946145 | I22: =+R22/P22 -> 1.0931963 | J22: =+R22/L22 -> 0.9832879 | K22: =+S22/M22 -> 0.86525223 | L22: =+SUM(Efficiency1!K75:K76) -> 54.398107 | M22: =M21+L22 -> 768.7296 | N22: =+SUM(Efficiency1!C75:C76) -> 50.901824 | O22: =O21+N22 -> 735.44122 | P22: ='14'!I38 -> 48.929 | Q22: =Q21+P22 -> 685.092 | R22: ='14'!I40 -> 53.489 | S22: =S21+R22 -> 665.145 | T22: =R22/P22 -> 1.0931963 | U22: =S22/Q22 -> 0.9708842 | V22: =R22/L22 -> 0.9832879 | W22: =S22/M22 -> 0.86525223 | AB22: =+[2]Report1!AY22 -> 4647.6581 | AC22: =AB22+AC21 -> 73027.362 | AD22: =AB22/P22 -> 94.9878 | AE22: =AC22/Q22 -> 106.59497 | AF22: =IF(AND(R22>0,AB22>0),(AB22/(R22*1000))*1000,0) -> 86.889978 | AG22: =IF(AND(S22>0,AC22>0),AC22/S22,0) -> 109.79164 | AH22: 68.8 | AI22: =AH22+AI21 -> 920.7 | AJ22: =AH22/(P22) -> 1.4061191 | AK22: =AI22/(Q22) -> 1.3439071 | AL22: =IF(AND(R22>0,AH22>0),AH22/(R22),0) -> 1.2862458 | AM22: =IF(AND(S22>0,AI22>0),AI22/(S22),0) -> 1.3842095 | AN22: 9.7 | AO22: =AN22+AO21 -> 134.6 | AP22: =AN22/(P22) -> 0.19824644 | AQ22: =AO22/(Q22) -> 0.19646996 | AR22: =IF(AND(R22>0,AN22>0),AN22/(R22),0) -> 0.1813457 | AS22: =IF(AND(S22>0,AO22>0),AO22/(S22),0) -> 0.20236189 | AT22: ='14'!I46 -> 38079.38 | AU22: =AT22+AU21 -> 550367.3 | AV22: =IF(AND(L22>0,AT22>0),(AT22/(P22*1000)*1000),0) -> 778.25788 | AW22: =IF(AND(M22>0,AU22>0),(AU22/(Q22*1000)*1000),0) -> 803.34802 | AX22: =IF(AND(R22>0,AT22>0),(AT22/(R22*1000)*1000),0) -> 711.91049 | AY22: =IF(AND(S22>0,AU22>0),(AU22/(S22*1000)*1000),0) -> 827.43958 | AZ22: =+Listrik!S21 -> 23431.8 | BA22: =AZ22+BA21 -> 327968.44 | BB22: =IF(AND(L22>0,AZ22>0),(AZ22/(P22*1000)*1000),0) -> 478.89391 | BC22: =IF(AND(M22>0,BA22>0),(BA22/(Q22*1000)*1000),0) -> 478.72175 | BD22: =IF(AND(R22>0,AZ22>0),(AZ22/(R22*1000)*1000),0) -> 438.06764 | BE22: =IF(AND(S22>0,BA22>0),(BA22/(S22*1000)*1000),0) -> 493.07811 | BF22: =+Listrik!V21 -> 319.8 | BG22: =BF22+BG21 -> 4130 | BH22: =IF(AND(L22>0,BF22>0),(BF22/(P22*1000)*1000),0) -> 6.5360011 | BI22: =IF(AND(M22>0,BG22>0),(BG22/(Q22*1000)*1000),0) -> 6.0283874 | BJ22: =IF(AND(R22>0,BF22>0),(BF22/(R22*1000)*1000),0) -> 5.9787994 | BK22: =IF(AND(S22>0,BG22>0),(BG22/(S22*1000)*1000),0) -> 6.2091724 | BL22: =+SUM(Efficiency2!K75:K76) -> 54.398107 | BM22: =BM21+BL22 -> 768.7296 | BN22: =+R22/BL22 -> 0.9832879 | BO22: =+S22/BM22 -> 0.86525223
A23: =A22+1 -> 45976 | B23: Toilet | C23: 15,5 | D23: =+'15'!F42 -> 1170 | E23: =+'15'!G42 -> 900.9 | F23: =1-(E23/D23) -> 0.23 | G23: =+P23/N23 -> 0.9495067 | H23: =+P23/L23 -> 0.9495067 | I23: =+R23/P23 -> 0.97848606 | J23: =+R23/L23 -> 0.92907907 | K23: =+S23/M23 -> 0.86945538 | L23: =+Efficiency1!K80 -> 54.191297 | M23: =M22+L23 -> 822.9209 | N23: =+Efficiency1!C80 -> 54.191297 | O23: =O22+N23 -> 789.63252 | P23: ='15'!I38 -> 51.455 | Q23: =Q22+P23 -> 736.547 | R23: ='15'!I40 -> 50.348 | S23: =S22+R23 -> 715.493 | T23: =R23/P23 -> 0.97848606 | U23: =S23/Q23 -> 0.97141527 | V23: =R23/L23 -> 0.92907907 | W23: =S23/M23 -> 0.86945538 | AB23: =+[2]Report1!AY23 -> 5203.8418 | AC23: =AB23+AC22 -> 78231.204 | AD23: =AB23/P23 -> 101.13384 | AE23: =AC23/Q23 -> 106.21346 | AF23: =IF(AND(R23>0,AB23>0),(AB23/(R23*1000))*1000,0) -> 103.35747 | AG23: =IF(AND(S23>0,AC23>0),AC23/S23,0) -> 109.33888 | AH23: 70.8 | AI23: =AH23+AI22 -> 991.5 | AJ23: =AH23/(P23) -> 1.3759596 | AK23: =AI23/(Q23) -> 1.3461463 | AL23: =IF(AND(R23>0,AH23>0),AH23/(R23),0) -> 1.4062128 | AM23: =IF(AND(S23>0,AI23>0),AI23/(S23),0) -> 1.3857578 | AN23: 10.8 | AO23: =AN23+AO22 -> 145.4 | AP23: =AN23/(P23) -> 0.20989214 | AQ23: =AO23/(Q23) -> 0.19740763 | AR23: =IF(AND(R23>0,AN23>0),AN23/(R23),0) -> 0.21450703 | AS23: =IF(AND(S23>0,AO23>0),AO23/(S23),0) -> 0.20321652 | AT23: ='15'!I46 -> 36809.52 | AU23: =AT23+AU22 -> 587176.82 | AV23: =IF(AND(L23>0,AT23>0),(AT23/(P23*1000)*1000),0) -> 715.37304 | AW23: =IF(AND(M23>0,AU23>0),(AU23/(Q23*1000)*1000),0) -> 797.20211 | AX23: =IF(AND(R23>0,AT23>0),(AT23/(R23*1000)*1000),0) -> 731.10193 | AY23: =IF(AND(S23>0,AU23>0),(AU23/(S23*1000)*1000),0) -> 820.66047 | AZ23: =+Listrik!S22 -> 26779.45 | BA23: =AZ23+BA22 -> 354747.89 | BB23: =IF(AND(L23>0,AZ23>0),(AZ23/(P23*1000)*1000),0) -> 520.44408 | BC23: =IF(AND(M23>0,BA23>0),(BA23/(Q23*1000)*1000),0) -> 481.63646 | BD23: =IF(AND(R23>0,AZ23>0),(AZ23/(R23*1000)*1000),0) -> 531.88707 | BE23: =IF(AND(S23>0,BA23>0),(BA23/(S23*1000)*1000),0) -> 495.80903 | BF23: =+Listrik!V22 -> 330.1 | BG23: =BF23+BG22 -> 4460.1 | BH23: =IF(AND(L23>0,BF23>0),(BF23/(P23*1000)*1000),0) -> 6.4153144 | BI23: =IF(AND(M23>0,BG23>0),(BG23/(Q23*1000)*1000),0) -> 6.0554181 | BJ23: =IF(AND(R23>0,BF23>0),(BF23/(R23*1000)*1000),0) -> 6.5563677 | BK23: =IF(AND(S23>0,BG23>0),(BG23/(S23*1000)*1000),0) -> 6.233604 | BL23: =+Efficiency2!K80 -> 54.191297 | BM23: =BM22+BL23 -> 822.9209 | BN23: =+R23/BL23 -> 0.92907907 | BO23: =+S23/BM23 -> 0.86945538
A24: =A23+1 -> 45977 | B24: Toilet | C24: 15,5/16 | D24: =+'16'!F42 -> 1160 | E24: =+'16'!G42 -> 916 | F24: =1-(E24/D24) -> 0.21034483 | G24: =+P24/N24 -> 0.99420805 | H24: =+P24/L24 -> 0.99420805 | I24: =+R24/P24 -> 0.96858078 | J24: =+R24/L24 -> 0.9629708 | K24: =+S24/M24 -> 0.8752562 | L24: =+SUM(Efficiency1!K85:K86) -> 54.422211 | M24: =M23+L24 -> 877.34311 | N24: =+SUM(Efficiency1!C85:C86) -> 54.422211 | O24: =O23+N24 -> 844.05473 | P24: ='16'!I38 -> 54.107 | Q24: =Q23+P24 -> 790.654 | R24: ='16'!I40 -> 52.407 | S24: =S23+R24 -> 767.9 | T24: =R24/P24 -> 0.96858078 | U24: =S24/Q24 -> 0.97122129 | V24: =R24/L24 -> 0.9629708 | W24: =S24/M24 -> 0.8752562 | AB24: =+[2]Report1!AY24 -> 4431.3575 | AC24: =AB24+AC23 -> 82662.561 | AD24: =AB24/P24 -> 81.899893 | AE24: =AC24/Q24 -> 104.5496 | AF24: =IF(AND(R24>0,AB24>0),(AB24/(R24*1000))*1000,0) -> 84.556596 | AG24: =IF(AND(S24>0,AC24>0),AC24/S24,0) -> 107.64756 | AH24: 71.5 | AI24: =AH24+AI23 -> 1063 | AJ24: =AH24/(P24) -> 1.3214556 | AK24: =AI24/(Q24) -> 1.3444566 | AL24: =IF(AND(R24>0,AH24>0),AH24/(R24),0) -> 1.3643216 | AM24: =IF(AND(S24>0,AI24>0),AI24/(S24),0) -> 1.3842948 | AN24: 12 | AO24: =AN24+AO23 -> 157.4 | AP24: =AN24/(P24) -> 0.22178276 | AQ24: =AO24/(Q24) -> 0.1990757 | AR24: =IF(AND(R24>0,AN24>0),AN24/(R24),0) -> 0.22897705 | AS24: =IF(AND(S24>0,AO24>0),AO24/(S24),0) -> 0.20497461 | AT24: ='16'!I46 -> 43824.82 | AU24: =AT24+AU23 -> 631001.64 | AV24: =IF(AND(L24>0,AT24>0),(AT24/(P24*1000)*1000),0) -> 809.96581 | AW24: =IF(AND(M24>0,AU24>0),(AU24/(Q24*1000)*1000),0) -> 798.07557 | AX24: =IF(AND(R24>0,AT24>0),(AT24/(R24*1000)*1000),0) -> 836.23982 | AY24: =IF(AND(S24>0,AU24>0),(AU24/(S24*1000)*1000),0) -> 821.72371 | AZ24: =+Listrik!S23 -> 29148.448 | BA24: =AZ24+BA23 -> 383896.34 | BB24: =IF(AND(L24>0,AZ24>0),(AZ24/(P24*1000)*1000),0) -> 538.71861 | BC24: =IF(AND(M24>0,BA24>0),(BA24/(Q24*1000)*1000),0) -> 485.54278 | BD24: =IF(AND(R24>0,AZ24>0),(AZ24/(R24*1000)*1000),0) -> 556.19379 | BE24: =IF(AND(S24>0,BA24>0),(BA24/(S24*1000)*1000),0) -> 499.93012 | BF24: =+Listrik!V23 -> 270.1 | BG24: =BF24+BG23 -> 4730.2 | BH24: =IF(AND(L24>0,BF24>0),(BF24/(P24*1000)*1000),0) -> 4.9919604 | BI24: =IF(AND(M24>0,BG24>0),(BG24/(Q24*1000)*1000),0) -> 5.9826422 | BJ24: =IF(AND(R24>0,BF24>0),(BF24/(R24*1000)*1000),0) -> 5.1538917 | BK24: =IF(AND(S24>0,BG24>0),(BG24/(S24*1000)*1000),0) -> 6.1599167 | BL24: =+SUM(Efficiency2!K85:K86) -> 54.422211 | BM24: =BM23+BL24 -> 877.34311 | BN24: =+R24/BL24 -> 0.9629708 | BO24: =+S24/BM24 -> 0.8752562
A25: =A24+1 -> 45978 | B25: Toilet | C25: 16/15,5 | D25: =+'17'!F42 -> 1155.0486 | E25: =+'17'!G42 -> 913.40667 | F25: =1-(E25/D25) -> 0.209205 | G25: =+P25/N25 -> 0.96693736 | H25: =+P25/L25 -> 0.96693736 | I25: =+R25/P25 -> 0.96621283 | J25: =+R25/L25 -> 0.93426728 | K25: =+S25/M25 -> 0.87877768 | L25: =+SUM(Efficiency1!K90:K91) -> 55.677857 | M25: =M24+L25 -> 933.02097 | N25: =+SUM(Efficiency1!C90:C91) -> 55.677857 | O25: =O24+N25 -> 899.73259 | P25: ='17'!I38 -> 53.837 | Q25: =Q24+P25 -> 844.491 | R25: ='17'!I40 -> 52.018 | S25: =S24+R25 -> 819.918 | T25: =R25/P25 -> 0.96621283 | U25: =S25/Q25 -> 0.970902 | V25: =R25/L25 -> 0.93426728 | W25: =S25/M25 -> 0.87877768 | AB25: =+[2]Report1!AY25 -> 4932.4204 | AC25: =AB25+AC24 -> 87594.982 | AD25: =AB25/P25 -> 91.617669 | AE25: =AC25/Q25 -> 103.72518 | AF25: =IF(AND(R25>0,AB25>0),(AB25/(R25*1000))*1000,0) -> 94.821416 | AG25: =IF(AND(S25>0,AC25>0),AC25/S25,0) -> 106.83383 | AH25: 70.4 | AI25: =AH25+AI24 -> 1133.4 | AJ25: =AH25/(P25) -> 1.3076509 | AK25: =AI25/(Q25) -> 1.3421102 | AL25: =IF(AND(R25>0,AH25>0),AH25/(R25),0) -> 1.3533777 | AM25: =IF(AND(S25>0,AI25>0),AI25/(S25),0) -> 1.3823334 | AN25: 11.6 | AO25: =AN25+AO24 -> 169 | AP25: =AN25/(P25) -> 0.2154652 | AQ25: =AO25/(Q25) -> 0.20012055 | AR25: =IF(AND(R25>0,AN25>0),AN25/(R25),0) -> 0.22299973 | AS25: =IF(AND(S25>0,AO25>0),AO25/(S25),0) -> 0.20611817 | AT25: ='17'!I46 -> 41140.06 | AU25: =AT25+AU24 -> 672141.7 | AV25: =IF(AND(L25>0,AT25>0),(AT25/(P25*1000)*1000),0) -> 764.15959 | AW25: =IF(AND(M25>0,AU25>0),(AU25/(Q25*1000)*1000),0) -> 795.9134 | AX25: =IF(AND(R25>0,AT25>0),(AT25/(R25*1000)*1000),0) -> 790.88123 | AY25: =IF(AND(S25>0,AU25>0),(AU25/(S25*1000)*1000),0) -> 819.76698 | AZ25: =+Listrik!S24 -> 28612.683 | BA25: =AZ25+BA24 -> 412509.02 | BB25: =IF(AND(L25>0,AZ25>0),(AZ25/(P25*1000)*1000),0) -> 531.46875 | BC25: =IF(AND(M25>0,BA25>0),(BA25/(Q25*1000)*1000),0) -> 488.47059 | BD25: =IF(AND(R25>0,AZ25>0),(AZ25/(R25*1000)*1000),0) -> 550.0535 | BE25: =IF(AND(S25>0,BA25>0),(BA25/(S25*1000)*1000),0) -> 503.11009 | BF25: =+Listrik!V24 -> 342.1 | BG25: =BF25+BG24 -> 5072.3 | BH25: =IF(AND(L25>0,BF25>0),(BF25/(P25*1000)*1000),0) -> 6.354366 | BI25: =IF(AND(M25>0,BG25>0),(BG25/(Q25*1000)*1000),0) -> 6.0063399 | BJ25: =IF(AND(R25>0,BF25>0),(BF25/(R25*1000)*1000),0) -> 6.5765696 | BK25: =IF(AND(S25>0,BG25>0),(BG25/(S25*1000)*1000),0) -> 6.1863503 | BL25: =+SUM(Efficiency2!K90:K91) -> 55.677857 | BM25: =BM24+BL25 -> 933.02097 | BN25: =+R25/BL25 -> 0.93426728 | BO25: =+S25/BM25 -> 0.87877768
A26: =A25+1 -> 45979 | B26: Toilet | C26: 15,5/16 | D26: =+'18'!F42 -> 1150.4585 | E26: =+'18'!G42 -> 907.90348 | F26: =1-(E26/D26) -> 0.21083335 | G26: =+P26/N26 -> 0.85163295 | H26: =+P26/L26 -> 0.8487734 | I26: =+R26/P26 -> 1.0069399 | J26: =+R26/L26 -> 0.8546638 | K26: =+S26/M26 -> 0.87745873 | L26: =+SUM(Efficiency1!K95:K96) -> 53.986141 | M26: =M25+L26 -> 987.00711 | N26: =+SUM(Efficiency1!C95:C96) -> 53.80487 | O26: =O25+N26 -> 953.53746 | P26: ='18'!I38 -> 45.822 | Q26: =Q25+P26 -> 890.313 | R26: ='18'!I40 -> 46.14 | S26: =S25+R26 -> 866.058 | T26: =R26/P26 -> 1.0069399 | U26: =S26/Q26 -> 0.97275677 | V26: =R26/L26 -> 0.8546638 | W26: =S26/M26 -> 0.87745873 | AB26: =+[2]Report1!AY26 -> 4592.7878 | AC26: =AB26+AC25 -> 92187.77 | AD26: =AB26/P26 -> 100.23106 | AE26: =AC26/Q26 -> 103.54535 | AF26: =IF(AND(R26>0,AB26>0),(AB26/(R26*1000))*1000,0) -> 99.540265 | AG26: =IF(AND(S26>0,AC26>0),AC26/S26,0) -> 106.44526 | AH26: 65.6 | AI26: =AH26+AI25 -> 1199 | AJ26: =AH26/(P26) -> 1.4316267 | AK26: =AI26/(Q26) -> 1.3467174 | AL26: =IF(AND(R26>0,AH26>0),AH26/(R26),0) -> 1.4217599 | AM26: =IF(AND(S26>0,AI26>0),AI26/(S26),0) -> 1.3844338 | AN26: 9 | AO26: =AN26+AO25 -> 178 | AP26: =AN26/(P26) -> 0.1964122 | AQ26: =AO26/(Q26) -> 0.19992969 | AR26: =IF(AND(R26>0,AN26>0),AN26/(R26),0) -> 0.19505852 | AS26: =IF(AND(S26>0,AO26>0),AO26/(S26),0) -> 0.20552896 | AT26: ='18'!I46 -> 37422.88 | AU26: =AT26+AU25 -> 709564.58 | AV26: =IF(AND(L26>0,AT26>0),(AT26/(P26*1000)*1000),0) -> 816.70115 | AW26: =IF(AND(M26>0,AU26>0),(AU26/(Q26*1000)*1000),0) -> 796.98329 | AX26: =IF(AND(R26>0,AT26>0),(AT26/(R26*1000)*1000),0) -> 811.07239 | AY26: =IF(AND(S26>0,AU26>0),(AU26/(S26*1000)*1000),0) -> 819.30376 | AZ26: =+Listrik!S25 -> 20612.79 | BA26: =AZ26+BA25 -> 433121.81 | BB26: =IF(AND(L26>0,AZ26>0),(AZ26/(P26*1000)*1000),0) -> 449.84483 | BC26: =IF(AND(M26>0,BA26>0),(BA26/(Q26*1000)*1000),0) -> 486.48263 | BD26: =IF(AND(R26>0,AZ26>0),(AZ26/(R26*1000)*1000),0) -> 446.74447 | BE26: =IF(AND(S26>0,BA26>0),(BA26/(S26*1000)*1000),0) -> 500.10716 | BF26: =+Listrik!V25 -> 307.7 | BG26: =BF26+BG25 -> 5380 | BH26: =IF(AND(L26>0,BF26>0),(BF26/(P26*1000)*1000),0) -> 6.715115 | BI26: =IF(AND(M26>0,BG26>0),(BG26/(Q26*1000)*1000),0) -> 6.0428186 | BJ26: =IF(AND(R26>0,BF26>0),(BF26/(R26*1000)*1000),0) -> 6.668834 | BK26: =IF(AND(S26>0,BG26>0),(BG26/(S26*1000)*1000),0) -> 6.2120551 | BL26: =+SUM(Efficiency2!K95:K96) -> 53.986141 | BM26: =BM25+BL26 -> 987.00711 | BN26: =+R26/BL26 -> 0.8546638 | BO26: =+S26/BM26 -> 0.87745873
A27: =A26+1 -> 45980 | B27: Toilet | C27: 15,5 | D27: =+'19'!F42 -> 1148.3333 | E27: =+'19'!G42 -> 910.7 | F27: =1-(E27/D27) -> 0.20693759 | G27: =+P27/N27 -> 0.98170132 | H27: =+P27/L27 -> 0.98170132 | I27: =+R27/P27 -> 0.96480814 | J27: =+R27/L27 -> 0.94715343 | K27: =+S27/M27 -> 0.88100118 | L27: =+Efficiency1!K101 -> 52.854161 | M27: =M26+L27 -> 1039.8613 | N27: =+Efficiency1!C101 -> 52.854161 | O27: =O26+N27 -> 1006.3916 | P27: ='19'!I38 -> 51.887 | Q27: =Q26+P27 -> 942.2 | R27: ='19'!I40 -> 50.061 | S27: =S26+R27 -> 916.119 | T27: =R27/P27 -> 0.96480814 | U27: =S27/Q27 -> 0.97231904 | V27: =R27/L27 -> 0.94715343 | W27: =S27/M27 -> 0.88100118 | AB27: =+[2]Report1!AY27 -> 4936.0697 | AC27: =AB27+AC26 -> 97123.839 | AD27: =AB27/P27 -> 95.131145 | AE27: =AC27/Q27 -> 103.08198 | AF27: =IF(AND(R27>0,AB27>0),(AB27/(R27*1000))*1000,0) -> 98.601101 | AG27: =IF(AND(S27>0,AC27>0),AC27/S27,0) -> 106.01662 | AH27: 69.4 | AI27: =AH27+AI26 -> 1268.4 | AJ27: =AH27/(P27) -> 1.3375219 | AK27: =AI27/(Q27) -> 1.346211 | AL27: =IF(AND(R27>0,AH27>0),AH27/(R27),0) -> 1.3863087 | AM27: =IF(AND(S27>0,AI27>0),AI27/(S27),0) -> 1.3845363 | AN27: 10.4 | AO27: =AN27+AO26 -> 188.4 | AP27: =AN27/(P27) -> 0.20043556 | AQ27: =AO27/(Q27) -> 0.19995755 | AR27: =IF(AND(R27>0,AN27>0),AN27/(R27),0) -> 0.20774655 | AS27: =IF(AND(S27>0,AO27>0),AO27/(S27),0) -> 0.20565014 | AT27: ='19'!I46 -> 40906 | AU27: =AT27+AU26 -> 750470.58 | AV27: =IF(AND(L27>0,AT27>0),(AT27/(P27*1000)*1000),0) -> 788.36703 | AW27: =IF(AND(M27>0,AU27>0),(AU27/(Q27*1000)*1000),0) -> 796.50879 | AX27: =IF(AND(R27>0,AT27>0),(AT27/(R27*1000)*1000),0) -> 817.12311 | AY27: =IF(AND(S27>0,AU27>0),(AU27/(S27*1000)*1000),0) -> 819.1846 | AZ27: =+Listrik!S26 -> 27698 | BA27: =AZ27+BA26 -> 460819.81 | BB27: =IF(AND(L27>0,AZ27>0),(AZ27/(P27*1000)*1000),0) -> 533.81386 | BC27: =IF(AND(M27>0,BA27>0),(BA27/(Q27*1000)*1000),0) -> 489.08916 | BD27: =IF(AND(R27>0,AZ27>0),(AZ27/(R27*1000)*1000),0) -> 553.28499 | BE27: =IF(AND(S27>0,BA27>0),(BA27/(S27*1000)*1000),0) -> 503.01305 | BF27: =+Listrik!V26 -> 320.1 | BG27: =BF27+BG26 -> 5700.1 | BH27: =IF(AND(L27>0,BF27>0),(BF27/(P27*1000)*1000),0) -> 6.1691753 | BI27: =IF(AND(M27>0,BG27>0),(BG27/(Q27*1000)*1000),0) -> 6.0497771 | BJ27: =IF(AND(R27>0,BF27>0),(BF27/(R27*1000)*1000),0) -> 6.3941991 | BK27: =IF(AND(S27>0,BG27>0),(BG27/(S27*1000)*1000),0) -> 6.2220083 | BL27: =+Efficiency2!K101 -> 52.854161 | BM27: =BM26+BL27 -> 1039.8613 | BN27: =+R27/BL27 -> 0.94715343 | BO27: =+S27/BM27 -> 0.88100118
A28: =A27+1 -> 45981 | B28: Toilet | C28: 15,5/16/19 | D28: =+'20'!F42 -> 1011.1528 | E28: =+'20'!G42 -> 811.79806 | F28: =1-(E28/D28) -> 0.19715589 | G28: =+P28/N28 -> 0.99906318 | H28: =+P28/L28 -> 0.99906318 | I28: =+R28/P28 -> 0.96152121 | J28: =+R28/L28 -> 0.96062044 | K28: =+S28/M28 -> 0.88505585 | L28: =+SUM(Efficiency1!K106:K108) -> 55.797272 | M28: =M27+L28 -> 1095.6585 | N28: =+SUM(Efficiency1!C106:C108) -> 55.797272 | O28: =O27+N28 -> 1062.1889 | P28: ='20'!I38 -> 55.745 | Q28: =Q27+P28 -> 997.945 | R28: ='20'!I40 -> 53.6 | S28: =S27+R28 -> 969.719 | T28: =R28/P28 -> 0.96152121 | U28: =S28/Q28 -> 0.97171588 | V28: =R28/L28 -> 0.96062044 | W28: =S28/M28 -> 0.88505585 | AB28: =+[2]Report1!AY28 -> 4963.8619 | AC28: =AB28+AC27 -> 102087.7 | AD28: =AB28/P28 -> 89.045867 | AE28: =AC28/Q28 -> 102.29792 | AF28: =IF(AND(R28>0,AB28>0),(AB28/(R28*1000))*1000,0) -> 92.609363 | AG28: =IF(AND(S28>0,AC28>0),AC28/S28,0) -> 105.27555 | AH28: 69.7 | AI28: =AH28+AI27 -> 1338.1 | AJ28: =AH28/(P28) -> 1.2503364 | AK28: =AI28/(Q28) -> 1.3408555 | AL28: =IF(AND(R28>0,AH28>0),AH28/(R28),0) -> 1.3003731 | AM28: =IF(AND(S28>0,AI28>0),AI28/(S28),0) -> 1.3798843 | AN28: 10 | AO28: =AN28+AO27 -> 198.4 | AP28: =AN28/(P28) -> 0.17938829 | AQ28: =AO28/(Q28) -> 0.19880855 | AR28: =IF(AND(R28>0,AN28>0),AN28/(R28),0) -> 0.18656716 | AS28: =IF(AND(S28>0,AO28>0),AO28/(S28),0) -> 0.20459535 | AT28: ='20'!I46 -> 38019.06 | AU28: =AT28+AU27 -> 788489.64 | AV28: =IF(AND(L28>0,AT28>0),(AT28/(P28*1000)*1000),0) -> 682.0174 | AW28: =IF(AND(M28>0,AU28>0),(AU28/(Q28*1000)*1000),0) -> 790.11332 | AX28: =IF(AND(R28>0,AT28>0),(AT28/(R28*1000)*1000),0) -> 709.31082 | AY28: =IF(AND(S28>0,AU28>0),(AU28/(S28*1000)*1000),0) -> 813.11147 | AZ28: =+Listrik!S27 -> 25682.8 | BA28: =AZ28+BA27 -> 486502.61 | BB28: =IF(AND(L28>0,AZ28>0),(AZ28/(P28*1000)*1000),0) -> 460.71935 | BC28: =IF(AND(M28>0,BA28>0),(BA28/(Q28*1000)*1000),0) -> 487.50443 | BD28: =IF(AND(R28>0,AZ28>0),(AZ28/(R28*1000)*1000),0) -> 479.15672 | BE28: =IF(AND(S28>0,BA28>0),(BA28/(S28*1000)*1000),0) -> 501.69442 | BF28: =+Listrik!V27 -> 330.1 | BG28: =BF28+BG27 -> 6030.2 | BH28: =IF(AND(L28>0,BF28>0),(BF28/(P28*1000)*1000),0) -> 5.9216073 | BI28: =IF(AND(M28>0,BG28>0),(BG28/(Q28*1000)*1000),0) -> 6.0426176 | BJ28: =IF(AND(R28>0,BF28>0),(BF28/(R28*1000)*1000),0) -> 6.1585821 | BK28: =IF(AND(S28>0,BG28>0),(BG28/(S28*1000)*1000),0) -> 6.2185025 | BL28: =+SUM(Efficiency2!K106:K108) -> 55.797272 | BM28: =BM27+BL28 -> 1095.6585 | BN28: =+R28/BL28 -> 0.96062044 | BO28: =+S28/BM28 -> 0.88505585
A29: =A28+1 -> 45982 | B29: Toilet | C29: 19/20 | D29: =+'21'!F42 -> 921.18056 | E29: =+'21'!G42 -> 736.94444 | F29: =1-(E29/D29) -> 0.2 | G29: =+P29/N29 -> 1.013079 | H29: =+P29/L29 -> 1.0107276 | I29: =+R29/P29 -> 0.96647783 | J29: =+R29/L29 -> 0.97684578 | K29: =+S29/M29 -> 0.88944442 | L29: =+SUM(Efficiency1!K111:K112) -> 55.014826 | M29: =M28+L29 -> 1150.6734 | N29: =+SUM(Efficiency1!C111:C112) -> 54.88713 | O29: =O28+N29 -> 1117.076 | P29: ='21'!I38 -> 55.605 | Q29: =Q28+P29 -> 1053.55 | R29: ='21'!I40 -> 53.741 | S29: =S28+R29 -> 1023.46 | T29: =R29/P29 -> 0.96647783 | U29: =S29/Q29 -> 0.97143942 | V29: =R29/L29 -> 0.97684578 | W29: =S29/M29 -> 0.88944442 | AB29: =+[2]Report1!AY29 -> 4746.5879 | AC29: =AB29+AC28 -> 106834.29 | AD29: =AB29/P29 -> 85.362609 | AE29: =AC29/Q29 -> 101.4041 | AF29: =IF(AND(R29>0,AB29>0),(AB29/(R29*1000))*1000,0) -> 88.323401 | AG29: =IF(AND(S29>0,AC29>0),AC29/S29,0) -> 104.38541 | AH29: 70.3 | AI29: =AH29+AI28 -> 1408.4 | AJ29: =AH29/(P29) -> 1.2642748 | AK29: =AI29/(Q29) -> 1.3368136 | AL29: =IF(AND(R29>0,AH29>0),AH29/(R29),0) -> 1.308126 | AM29: =IF(AND(S29>0,AI29>0),AI29/(S29),0) -> 1.3761163 | AN29: 9.8 | AO29: =AN29+AO28 -> 208.2 | AP29: =AN29/(P29) -> 0.17624314 | AQ29: =AO29/(Q29) -> 0.19761758 | AR29: =IF(AND(R29>0,AN29>0),AN29/(R29),0) -> 0.18235612 | AS29: =IF(AND(S29>0,AO29>0),AO29/(S29),0) -> 0.20342759 | AT29: ='21'!I46 -> 38136.02 | AU29: =AT29+AU28 -> 826625.66 | AV29: =IF(AND(L29>0,AT29>0),(AT29/(P29*1000)*1000),0) -> 685.83796 | AW29: =IF(AND(M29>0,AU29>0),(AU29/(Q29*1000)*1000),0) -> 784.6098 | AX29: =IF(AND(R29>0,AT29>0),(AT29/(R29*1000)*1000),0) -> 709.62617 | AY29: =IF(AND(S29>0,AU29>0),(AU29/(S29*1000)*1000),0) -> 807.67754 | AZ29: =+Listrik!S28 -> 24315 | BA29: =AZ29+BA28 -> 510817.61 | BB29: =IF(AND(L29>0,AZ29>0),(AZ29/(P29*1000)*1000),0) -> 437.28082 | BC29: =IF(AND(M29>0,BA29>0),(BA29/(Q29*1000)*1000),0) -> 484.8537 | BD29: =IF(AND(R29>0,AZ29>0),(AZ29/(R29*1000)*1000),0) -> 452.44785 | BE29: =IF(AND(S29>0,BA29>0),(BA29/(S29*1000)*1000),0) -> 499.10853 | BF29: =+Listrik!V28 -> 349.8 | BG29: =BF29+BG28 -> 6380 | BH29: =IF(AND(L29>0,BF29>0),(BF29/(P29*1000)*1000),0) -> 6.2908012 | BI29: =IF(AND(M29>0,BG29>0),(BG29/(Q29*1000)*1000),0) -> 6.0557164 | BJ29: =IF(AND(R29>0,BF29>0),(BF29/(R29*1000)*1000),0) -> 6.5089969 | BK29: =IF(AND(S29>0,BG29>0),(BG29/(S29*1000)*1000),0) -> 6.2337561 | BL29: =+SUM(Efficiency2!K111:K112) -> 55.014826 | BM29: =BM28+BL29 -> 1150.6734 | BN29: =+R29/BL29 -> 0.97684578 | BO29: =+S29/BM29 -> 0.88944442
A30: =A29+1 -> 45983 | B30: Toilet | C30: 20/15 | D30: =+'22'!F42 -> 1120.5 | E30: =+'22'!G42 -> 884.64917 | F30: =1-(E30/D30) -> 0.21048713 | G30: =+P30/N30 -> 0.92042225 | H30: =+P30/L30 -> 0.90457886 | I30: =+R30/P30 -> 1.0295513 | J30: =+R30/L30 -> 0.93131034 | K30: =+S30/M30 -> 0.89135395 | L30: =+SUM(Efficiency1!K116:K117) -> 54.991336 | M30: =M29+L30 -> 1205.6647 | N30: =+SUM(Efficiency1!C116:C117) -> 54.04476 | O30: =O29+N30 -> 1171.1208 | P30: ='22'!I38 -> 49.744 | Q30: =Q29+P30 -> 1103.294 | R30: ='22'!I40 -> 51.214 | S30: =S29+R30 -> 1074.674 | T30: =R30/P30 -> 1.0295513 | U30: =S30/Q30 -> 0.9740595 | V30: =R30/L30 -> 0.93131034 | W30: =S30/M30 -> 0.89135395 | AB30: =+[2]Report1!AY30 -> 5286.2929 | AC30: =AB30+AC29 -> 112120.58 | AD30: =AB30/P30 -> 106.26996 | AE30: =AC30/Q30 -> 101.62349 | AF30: =IF(AND(R30>0,AB30>0),(AB30/(R30*1000))*1000,0) -> 103.21968 | AG30: =IF(AND(S30>0,AC30>0),AC30/S30,0) -> 104.32985 | AH30: 70.2 | AI30: =AH30+AI29 -> 1478.6 | AJ30: =AH30/(P30) -> 1.4112255 | AK30: =AI30/(Q30) -> 1.3401686 | AL30: =IF(AND(R30>0,AH30>0),AH30/(R30),0) -> 1.3707189 | AM30: =IF(AND(S30>0,AI30>0),AI30/(S30),0) -> 1.3758591 | AN30: 9.7 | AO30: =AN30+AO29 -> 217.9 | AP30: =AN30/(P30) -> 0.19499839 | AQ30: =AO30/(Q30) -> 0.19749949 | AR30: =IF(AND(R30>0,AN30>0),AN30/(R30),0) -> 0.18940134 | AS30: =IF(AND(S30>0,AO30>0),AO30/(S30),0) -> 0.20275916 | AT30: ='22'!I46 -> 39211.7 | AU30: =AT30+AU29 -> 865837.36 | AV30: =IF(AND(L30>0,AT30>0),(AT30/(P30*1000)*1000),0) -> 788.26994 | AW30: =IF(AND(M30>0,AU30>0),(AU30/(Q30*1000)*1000),0) -> 784.77483 | AX30: =IF(AND(R30>0,AT30>0),(AT30/(R30*1000)*1000),0) -> 765.64416 | AY30: =IF(AND(S30>0,AU30>0),(AU30/(S30*1000)*1000),0) -> 805.67443 | AZ30: =+Listrik!S29 -> 24598 | BA30: =AZ30+BA29 -> 535415.61 | BB30: =IF(AND(L30>0,AZ30>0),(AZ30/(P30*1000)*1000),0) -> 494.4918 | BC30: =IF(AND(M30>0,BA30>0),(BA30/(Q30*1000)*1000),0) -> 485.28825 | BD30: =IF(AND(R30>0,AZ30>0),(AZ30/(R30*1000)*1000),0) -> 480.29836 | BE30: =IF(AND(S30>0,BA30>0),(BA30/(S30*1000)*1000),0) -> 498.21212 | BF30: =+Listrik!V29 -> 340.1 | BG30: =BF30+BG29 -> 6720.1 | BH30: =IF(AND(L30>0,BF30>0),(BF30/(P30*1000)*1000),0) -> 6.8370055 | BI30: =IF(AND(M30>0,BG30>0),(BG30/(Q30*1000)*1000),0) -> 6.0909422 | BJ30: =IF(AND(R30>0,BF30>0),(BF30/(R30*1000)*1000),0) -> 6.6407623 | BK30: =IF(AND(S30>0,BG30>0),(BG30/(S30*1000)*1000),0) -> 6.2531521 | BL30: =+SUM(Efficiency2!K116:K117) -> 54.991336 | BM30: =BM29+BL30 -> 1205.6647 | BN30: =+R30/BL30 -> 0.93131034 | BO30: =+S30/BM30 -> 0.89135395
A31: =A30+1 -> 45984 | B31: Toilet | C31: 15 | D31: =+'23'!F42 -> 1153.3333 | E31: =+'23'!G42 -> 903.26667 | F31: =1-(E31/D31) -> 0.21682081 | G31: =+P31/N31 -> 0.93871881 | H31: =+P31/L31 -> 0.9097947 | I31: =+R31/P31 -> 0.98944027 | J31: =+R31/L31 -> 0.90018752 | K31: =+S31/M31 -> 0.89173278 | L31: =+Efficiency1!K121 -> 54.022078 | M31: =M30+L31 -> 1259.6868 | N31: =+Efficiency1!C121 -> 52.357532 | O31: =O30+N31 -> 1223.4783 | P31: ='23'!I38 -> 49.149 | Q31: =Q30+P31 -> 1152.443 | R31: ='23'!I40 -> 48.63 | S31: =S30+R31 -> 1123.304 | T31: =R31/P31 -> 0.98944027 | U31: =S31/Q31 -> 0.97471545 | V31: =R31/L31 -> 0.90018752 | W31: =S31/M31 -> 0.89173278 | AB31: =+[2]Report1!AY31 -> 4809.6642 | AC31: =AB31+AC30 -> 116930.25 | AD31: =AB31/P31 -> 97.858841 | AE31: =AC31/Q31 -> 101.46293 | AF31: =IF(AND(R31>0,AB31>0),(AB31/(R31*1000))*1000,0) -> 98.903232 | AG31: =IF(AND(S31>0,AC31>0),AC31/S31,0) -> 104.09493 | AH31: 69.1 | AI31: =AH31+AI30 -> 1547.7 | AJ31: =AH31/(P31) -> 1.4059289 | AK31: =AI31/(Q31) -> 1.3429731 | AL31: =IF(AND(R31>0,AH31>0),AH31/(R31),0) -> 1.4209336 | AM31: =IF(AND(S31>0,AI31>0),AI31/(S31),0) -> 1.3778105 | AN31: 10.5 | AO31: =AN31+AO30 -> 228.4 | AP31: =AN31/(P31) -> 0.21363609 | AQ31: =AO31/(Q31) -> 0.19818768 | AR31: =IF(AND(R31>0,AN31>0),AN31/(R31),0) -> 0.2159161 | AS31: =IF(AND(S31>0,AO31>0),AO31/(S31),0) -> 0.20332875 | AT31: ='23'!I46 -> 41851.6 | AU31: =AT31+AU30 -> 907688.96 | AV31: =IF(AND(L31>0,AT31>0),(AT31/(P31*1000)*1000),0) -> 851.52495 | AW31: =IF(AND(M31>0,AU31>0),(AU31/(Q31*1000)*1000),0) -> 787.62157 | AX31: =IF(AND(R31>0,AT31>0),(AT31/(R31*1000)*1000),0) -> 860.61279 | AY31: =IF(AND(S31>0,AU31>0),(AU31/(S31*1000)*1000),0) -> 808.05282 | AZ31: =+Listrik!S30 -> 22710.5 | BA31: =AZ31+BA30 -> 558126.11 | BB31: =IF(AND(L31>0,AZ31>0),(AZ31/(P31*1000)*1000),0) -> 462.07451 | BC31: =IF(AND(M31>0,BA31>0),(BA31/(Q31*1000)*1000),0) -> 484.29824 | BD31: =IF(AND(R31>0,AZ31>0),(AZ31/(R31*1000)*1000),0) -> 467.00596 | BE31: =IF(AND(S31>0,BA31>0),(BA31/(S31*1000)*1000),0) -> 496.86114 | BF31: =+Listrik!V30 -> 280.1 | BG31: =BF31+BG30 -> 7000.2 | BH31: =IF(AND(L31>0,BF31>0),(BF31/(P31*1000)*1000),0) -> 5.6989969 | BI31: =IF(AND(M31>0,BG31>0),(BG31/(Q31*1000)*1000),0) -> 6.0742267 | BJ31: =IF(AND(R31>0,BF31>0),(BF31/(R31*1000)*1000),0) -> 5.759819 | BK31: =IF(AND(S31>0,BG31>0),(BG31/(S31*1000)*1000),0) -> 6.2317948 | BL31: =+Efficiency2!K121 -> 54.022078 | BM31: =BM30+BL31 -> 1259.6868 | BN31: =+R31/BL31 -> 0.90018752 | BO31: =+S31/BM31 -> 0.89173278
