Workbook

Sheet eff all
A1: DATE | B1: PM 11 | L1: PM 12 | Z1: PM 14 | AN1: PM 15 | BF1: PM 16 | BT1: PM 17
B2: Eff Avaliable | D2: Eff Running | F2: PHP (ton) | H2: STEAM/Ton FG | J2: ELECTRIC/ton FG | L2: Eff Avaliable | N2: Eff Running | P2: PHP (ton) | R2: STEAM/ton FG | T2: STEAM DIP/ton FG | V2: ELECTRIC/ton FG | X2: ELECTRIC DIP/ton FG | Z2: Eff Avaliable | AB2: Eff Running | AD2: PHP (ton) | AF2: GAS /ton FG | AH2: STEAM /ton FG | AJ2: ELECTRIC /ton FG | AL2: Electric WPL /ton FG | AN2: Eff Avaliable | AP2: Eff Running | AR2: PHP (ton) | AT2: GAS /ton FG | AV2: STEAM /ton FG | AX2: STEAM DIP /ton FG | AZ2: ELECTRIC /ton FG | BB2: ELECTRIC DIP /ton FG | BD2: Electric WPL /ton FG | BF2: Eff Avaliable | BH2: Eff Running | BJ2: PHP (ton) | BL2: STEAM /ton FG | BN2: STEAM DIP/ton FG | BP2: ELECTRIC /ton FG | BR2: ELECTRIC DIP/ton FG | BT2: Eff Avaliable | BV2: Eff Running | BX2: PHP (ton) | BZ2: GAS /ton FG | CB2: STEAM /ton FG | CD2: STEAM DIP /ton FG | CF2: ELECTRIC /ton FG | CH2: ELECTRIC DIP /ton FG | CJ2: ELECTRIC WPL /ton FG
B3: Today | C3: Todate | D3: Today | E3: Todate | F3: Today | G3: Todate | H3: Today | I3: Todate | J3: Today | K3: Todate | L3: Today | M3: Todate | N3: Today | O3: Todate | P3: Today | Q3: Todate | R3: Today | S3: Todate | T3: Today | U3: Todate | V3: Today | W3: Todate | X3: Today | Y3: Todate | Z3: Today | AA3: Todate | AB3: Today | AC3: Todate | AD3: Today | AE3: Todate | AF3: Today | AG3: Todate | AH3: Today | AI3: Todate | AJ3: Today | AK3: Todate | AL3: Today | AM3: Todate | AN3: Today | AO3: Todate | AP3: Today | AQ3: Todate | AR3: Today | AS3: Todate | AT3: Today | AU3: Todate | AV3: Today | AW3: Todate | AX3: Today | AY3: Todate | AZ3: Today | BA3: Todate | BB3: Today | BC3: Todate | BD3: Today | BE3: Todate | BF3: Today | BG3: Todate | BH3: Today | BI3: Todate | BJ3: Today | BK3: Todate | BL3: Today | BM3: Todate | BN3: Today | BO3: Todate | BP3: Today | BQ3: Todate | BR3: Today | BS3: Todate | BT3: Today | BU3: Todate | BV3: Today | BW3: Todate | BX3: Today | BY3: Todate | BZ3: Today | CA3: Todate | CB3: Today | CC3: Todate | CD3: Today | CE3: Todate | CF3: Today | CG3: Todate | CH3: Today | CI3: Todate | CJ3: Today | CK3: Todate
A4: =+Report1!A9 -> 45870 | B4: =+Report1!J9 -> 0.11550917 | C4: =+Report1!K9 -> 0.11550917 | D4: =+Report1!AJ9 -> 0.11550917 | E4: =+Report1!AK9 -> 0.11550917 | F4: =+Report1!R9 -> 7.714 | G4: =+Report1!S9 -> 7.714 | H4: =+Report1!X9 -> 4.6392274 | I4: =+Report1!Y9 -> 4.6392274 | J4: =+Report1!AD9 -> 1959.5567 | K4: =+Report1!AE9 -> 1959.5567 | L4: =+[1]Report1!J9 -> 1.0736613 | M4: =+[1]Report1!K9 -> 1.0736613 | N4: =+[1]Report1!BJ9 -> 1.0736613 | O4: =+[1]Report1!BK9 -> 1.0736613 | P4: =+[1]Report1!R9 -> 80.169 | Q4: =+[1]Report1!S9 -> 80.169 | R4: =+[1]Report1!AL9 -> 2.300116 | S4: =+[1]Report1!AM9 -> 2.300116 | T4: =+[1]Report1!AR9 -> 0.23949407 | U4: =+[1]Report1!AS9 -> 0.23949407 | V4: =+[1]Report1!AX9 -> 428.99288 | W4: =+[1]Report1!AY9 -> 428.99288 | X4: =+[1]Report1!BD9 -> 393.75569 | Y4: =+[1]Report1!BE9 -> 393.75569 | Z4: =+[2]Report1!J9 -> 0.9357153 | AA4: =+[2]Report1!K9 -> 0.9357153 | AB4: =+[2]Report1!BC9 -> 0.9357153 | AC4: =+[2]Report1!BD9 -> 0.9357153 | AD4: =+[2]Report1!R9 -> 44.627 | AE4: =+[2]Report1!S9 -> 44.627 | AF4: =+[2]Report1!X9 -> 92.489962 | AG4: =+[2]Report1!Y9 -> 92.489962 | AH4: =+[2]Report1!AD9 -> 1.3332736 | AI4: =+[2]Report1!AE9 -> 1.3332736 | AJ4: =+[2]Report1!AJ9 -> 841.77785 | AK4: =+[2]Report1!AK9 -> 841.77785 | AL4: 0 | AM4: 0 | AN4: =+[3]Report1!J9 -> 0.89220756 | AO4: =+[3]Report1!K9 -> 0.89220756 | AP4: =+[3]Report1!BN9 -> 0.89220756 | AQ4: =+[3]Report1!BO9 -> 0.89220756 | AR4: =+[3]Report1!R9 -> 45.592 | AS4: =+[3]Report1!S9 -> 45.592 | AT4: =+[3]Report1!AF9 -> 119.11206 | AU4: =+[3]Report1!AG9 -> 119.11206 | AV4: =+[3]Report1!AL9 -> 1.5879979 | AW4: =+[3]Report1!AM9 -> 1.5879979 | AX4: =+[3]Report1!AR9 -> 0.19082295 | AY4: =+[3]Report1!AS9 -> 0.19082295 | AZ4: =+[3]Report1!AX9 -> 938.67389 | BA4: =+[3]Report1!AY9 -> 938.67389 | BB4: =+[3]Report1!BD9 -> 545.80854 | BC4: =+[3]Report1!BE9 -> 545.80854 | BD4: =+[3]Report1!BJ9 -> 15.30229 | BE4: =+[3]Report1!BK9 -> 15.30229 | BF4: =+[4]Report1!J9 -> 0.84364074 | BG4: =+[4]Report1!K9 -> 0.84364074 | BH4: =+[4]Report1!AN9 -> 0.84364074 | BI4: =+[4]Report1!AO9 -> 0.84364074 | BJ4: =+[4]Report1!R9 -> 45.37 | BK4: =+[4]Report1!S9 -> 45.37 | BL4: =+[4]Report1!AD9 -> 2.8080229 | BM4: =+[4]Report1!AE9 -> 2.8080229 | BN4: 0 | BO4: 0 | BP4: =+[4]Report1!AJ9 -> 1046.0847 | BQ4: =+[4]Report1!AK9 -> 1046.0847 | BR4: 0 | BS4: 0 | BT4: =+[5]Report1!J9 -> 1.0117807 | BU4: =+[5]Report1!K9 -> 1.0117807 | BV4: =+[5]Report1!BG9 -> 1.0117807 | BW4: =+[5]Report1!BH9 -> 1.0117807 | BX4: =+[5]Report1!R9 -> 52.126 | BY4: =+[5]Report1!S9 -> 52.126 | BZ4: =+[5]Report1!X9 -> 70.730409 | CA4: =+[5]Report1!Y9 -> 70.730409 | CB4: =+[5]Report1!AD9 -> 1.8800599 | CC4: =+[5]Report1!AE9 -> 1.8800599 | CD4: =+[5]Report1!AJ9 -> 0.17649541 | CE4: =+[5]Report1!AK9 -> 0.17649541 | CF4: =+[5]Report1!AP9 -> 741.15998 | CG4: =+[5]Report1!AQ9 -> 741.15998 | CH4: =+[5]Report1!AV9 -> 496.87674 | CI4: =+[5]Report1!AW9 -> 496.87674 | CJ4: =+[5]Report1!BB9 -> 13.930438 | CK4: =+[5]Report1!BC9 -> 13.930438
A5: =1+A4 -> 45871 | B5: =+Report1!J10 -> 0.66209517 | C5: =+Report1!K10 -> 0.38887501 | D5: =+Report1!AJ10 -> 0.66209517 | E5: =+Report1!AK10 -> 0.38887501 | F5: =+Report1!R10 -> 44.24 | G5: =+Report1!S10 -> 51.954 | H5: =+Report1!X10 -> 2.8289783 | I5: =+Report1!Y10 -> 3.0977596 | J5: =+Report1!AD10 -> 1027.8359 | K5: =+Report1!AE10 -> 1166.1755 | L5: =+[1]Report1!J10 -> 1.0084007 | M5: =+[1]Report1!K10 -> 1.04268 | N5: =+[1]Report1!BJ10 -> 1.0084007 | O5: =+[1]Report1!BK10 -> 1.04268 | P5: =+[1]Report1!R10 -> 68.052 | Q5: =+[1]Report1!S10 -> 148.221 | R5: =+[1]Report1!AL10 -> 2.6821107 | S5: =+[1]Report1!AM10 -> 2.4754994 | T5: =+[1]Report1!AR10 -> 0.26303415 | U5: =+[1]Report1!AS10 -> 0.25030191 | V5: =+[1]Report1!AX10 -> 531.0276 | W5: =+[1]Report1!AY10 -> 475.83959 | X5: =+[1]Report1!BD10 -> 461.5735 | Y5: =+[1]Report1!BE10 -> 424.89256 | Z5: =+[2]Report1!J10 -> 0.95928274 | AA5: =+[2]Report1!K10 -> 0.94749902 | AB5: =+[2]Report1!BC10 -> 0.95928274 | AC5: =+[2]Report1!BD10 -> 0.94749902 | AD5: =+[2]Report1!R10 -> 45.751 | AE5: =+[2]Report1!S10 -> 90.378 | AF5: =+[2]Report1!X10 -> 88.30606 | AG5: =+[2]Report1!Y10 -> 90.371994 | AH5: =+[2]Report1!AD10 -> 1.326747 | AI5: =+[2]Report1!AE10 -> 1.3299697 | AJ5: =+[2]Report1!AJ10 -> 853.34659 | AK5: =+[2]Report1!AK10 -> 847.63416 | AL5: 0 | AM5: 0 | AN5: =+[3]Report1!J10 -> 0.89586703 | AO5: =+[3]Report1!K10 -> 0.89403729 | AP5: =+[3]Report1!BN10 -> 0.89586703 | AQ5: =+[3]Report1!BO10 -> 0.89403729 | AR5: =+[3]Report1!R10 -> 45.779 | AS5: =+[3]Report1!S10 -> 91.371 | AT5: =+[3]Report1!AF10 -> 118.40145 | AU5: =+[3]Report1!AG10 -> 118.75603 | AV5: =+[3]Report1!AL10 -> 1.5487451 | AW5: =+[3]Report1!AM10 -> 1.5683313 | AX5: =+[3]Report1!AR10 -> 0.24028485 | AY5: =+[3]Report1!AS10 -> 0.21560451 | AZ5: =+[3]Report1!AX10 -> 922.07038 | BA5: =+[3]Report1!AY10 -> 930.35515 | BB5: =+[3]Report1!BD10 -> 516.82577 | BC5: =+[3]Report1!BE10 -> 531.2875 | BD5: =+[3]Report1!BJ10 -> 15.458529 | BE5: =+[3]Report1!BK10 -> 15.380569 | BF5: =+[4]Report1!J10 -> 0.84293414 | BG5: =+[4]Report1!K10 -> 0.84328744 | BH5: =+[4]Report1!AN10 -> 0.84293414 | BI5: =+[4]Report1!AO10 -> 0.84328744 | BJ5: =+[4]Report1!R10 -> 45.332 | BK5: =+[4]Report1!S10 -> 90.702 | BL5: =+[4]Report1!AD10 -> 2.8302303 | BM5: =+[4]Report1!AE10 -> 2.819122 | BN5: 0 | BO5: 0 | BP5: =+[4]Report1!AJ10 -> 1034.3913 | BQ5: =+[4]Report1!AK10 -> 1040.2405 | BR5: 0 | BS5: 0 | BT5: =+[5]Report1!J10 -> 0.81839596 | BU5: =+[5]Report1!K10 -> 0.91508831 | BV5: =+[5]Report1!BG10 -> 0.81839596 | BW5: =+[5]Report1!BH10 -> 0.91508831 | BX5: =+[5]Report1!R10 -> 42.163 | BY5: =+[5]Report1!S10 -> 94.289 | BZ5: =+[5]Report1!X10 -> 87.911428 | CA5: =+[5]Report1!Y10 -> 78.413207 | CB5: =+[5]Report1!AD10 -> 2.3077106 | CC5: =+[5]Report1!AE10 -> 2.0712915 | CD5: =+[5]Report1!AJ10 -> 0.25140526 | CE5: =+[5]Report1!AK10 -> 0.20999268 | CF5: =+[5]Report1!AP10 -> 913.04853 | CG5: =+[5]Report1!AQ10 -> 818.02299 | CH5: =+[5]Report1!AV10 -> 539.14411 | CI5: =+[5]Report1!AW10 -> 515.77734 | CJ5: =+[5]Report1!BB10 -> 16.126082 | CK5: =+[5]Report1!BC10 -> 14.912259
A6: =1+A5 -> 45872 | B6: =+Report1!J11 -> 0.78055074 | C6: =+Report1!K11 -> 0.51856923 | D6: =+Report1!AJ11 -> 0.78055074 | E6: =+Report1!AK11 -> 0.51856923 | F6: =+Report1!R11 -> 51.625 | G6: =+Report1!S11 -> 103.579 | H6: =+Report1!X11 -> 2.6112349 | I6: =+Report1!Y11 -> 2.8552699 | J6: =+Report1!AD11 -> 946.31477 | K6: =+Report1!AE11 -> 1056.5943 | L6: =+[1]Report1!J11 -> 0.9111034 | M6: =+[1]Report1!K11 -> 1.0044027 | N6: =+[1]Report1!BJ11 -> 0.9111034 | O6: =+[1]Report1!BK11 -> 1.0044027 | P6: =+[1]Report1!R11 -> 53.136 | Q6: =+[1]Report1!S11 -> 201.357 | R6: =+[1]Report1!AL11 -> 2.8942148 | S6: =+[1]Report1!AM11 -> 2.585994 | T6: =+[1]Report1!AR11 -> 0.28605842 | U6: =+[1]Report1!AS11 -> 0.25973768 | V6: =+[1]Report1!AX11 -> 677.61875 | W6: =+[1]Report1!AY11 -> 529.08699 | X6: =+[1]Report1!BD11 -> 477.86811 | Y6: =+[1]Report1!BE11 -> 438.87225 | Z6: =+[2]Report1!J11 -> 0.6285838 | AA6: =+[2]Report1!K11 -> 0.84119395 | AB6: =+[2]Report1!BC11 -> 0.6285838 | AC6: =+[2]Report1!BD11 -> 0.84119395 | AD6: =+[2]Report1!R11 -> 29.979 | AE6: =+[2]Report1!S11 -> 120.357 | AF6: =+[2]Report1!X11 -> 96.908809 | AG6: =+[2]Report1!Y11 -> 92.00021 | AH6: =+[2]Report1!AD11 -> 1.5777711 | AI6: =+[2]Report1!AE11 -> 1.391693 | AJ6: =+[2]Report1!AJ11 -> 969.79552 | AK6: =+[2]Report1!AK11 -> 878.0626 | AL6: 0 | AM6: 0 | AN6: =+[3]Report1!J11 -> 0.98639502 | AO6: =+[3]Report1!K11 -> 0.9248232 | AP6: =+[3]Report1!BN11 -> 0.98639502 | AQ6: =+[3]Report1!BO11 -> 0.9248232 | AR6: =+[3]Report1!R11 -> 50.405 | AS6: =+[3]Report1!S11 -> 141.776 | AT6: =+[3]Report1!AF11 -> 107.65144 | AU6: =+[3]Report1!AG11 -> 114.80806 | AV6: =+[3]Report1!AL11 -> 1.4145422 | AW6: =+[3]Report1!AM11 -> 1.5136553 | AX6: =+[3]Report1!AR11 -> 0.22418411 | AY6: =+[3]Report1!AS11 -> 0.21865478 | AZ6: =+[3]Report1!AX11 -> 861.8887 | BA6: =+[3]Report1!AY11 -> 906.01357 | BB6: =+[3]Report1!BD11 -> 523.57207 | BC6: =+[3]Report1!BE11 -> 528.54446 | BD6: =+[3]Report1!BJ11 -> 13.930166 | BE6: =+[3]Report1!BK11 -> 14.864914 | BF6: =+[4]Report1!J11 -> 0.9951688 | BG6: =+[4]Report1!K11 -> 0.89391456 | BH6: =+[4]Report1!AN11 -> 0.9951688 | BI6: =+[4]Report1!AO11 -> 0.89391456 | BJ6: =+[4]Report1!R11 -> 53.519 | BK6: =+[4]Report1!S11 -> 144.221 | BL6: =+[4]Report1!AD11 -> 2.4122274 | BM6: =+[4]Report1!AE11 -> 2.6681274 | BN6: 0 | BO6: 0 | BP6: =+[4]Report1!AJ11 -> 888.73699 | BQ6: =+[4]Report1!AK11 -> 984.01901 | BR6: 0 | BS6: 0 | BT6: =+[5]Report1!J11 -> 0.97878317 | BU6: =+[5]Report1!K11 -> 0.93631993 | BV6: =+[5]Report1!BG11 -> 0.97878317 | BW6: =+[5]Report1!BH11 -> 0.93631993 | BX6: =+[5]Report1!R11 -> 50.426 | BY6: =+[5]Report1!S11 -> 144.715 | BZ6: =+[5]Report1!X11 -> 76.004443 | CA6: =+[5]Report1!Y11 -> 77.573872 | CB6: =+[5]Report1!AD11 -> 1.9672391 | CC6: =+[5]Report1!AE11 -> 2.0350344 | CD6: =+[5]Report1!AJ11 -> 0.22805695 | CE6: =+[5]Report1!AK11 -> 0.21628719 | CF6: =+[5]Report1!AP11 -> 764.3195 | CG6: =+[5]Report1!AQ11 -> 799.30999 | CH6: =+[5]Report1!AV11 -> 523.35402 | CI6: =+[5]Report1!AW11 -> 518.41744 | CJ6: =+[5]Report1!BB11 -> 13.924364 | CK6: =+[5]Report1!BC11 -> 14.568027
A7: =1+A6 -> 45873 | B7: =+Report1!J12 -> 0.68443016 | C7: =+Report1!K12 -> 0.55881791 | D7: =+Report1!AJ12 -> 0.68443016 | E7: =+Report1!AK12 -> 0.55881791 | F7: =+Report1!R12 -> 43.804 | G7: =+Report1!S12 -> 147.383 | H7: =+Report1!X12 -> 2.9611223 | I7: =+Report1!Y12 -> 2.8867305 | J7: =+Report1!AD12 -> 1199.9922 | K7: =+Report1!AE12 -> 1099.2139 | L7: =+[1]Report1!J12 -> 0.80052628 | M7: =+[1]Report1!K12 -> 0.96132157 | N7: =+[1]Report1!BJ12 -> 0.80052628 | O7: =+[1]Report1!BK12 -> 0.96132157 | P7: =+[1]Report1!R12 -> 42.998 | Q7: =+[1]Report1!S12 -> 244.355 | R7: =+[1]Report1!AL12 -> 3.4281594 | S7: =+[1]Report1!AM12 -> 2.7341859 | T7: =+[1]Report1!AR12 -> 0.23722034 | U7: =+[1]Report1!AS12 -> 0.25577541 | V7: =+[1]Report1!AX12 -> 879.37323 | W7: =+[1]Report1!AY12 -> 590.72522 | X7: =+[1]Report1!BD12 -> 389.64603 | Y7: =+[1]Report1!BE12 -> 430.21015 | Z7: =+[2]Report1!J12 -> 0.92728638 | AA7: =+[2]Report1!K12 -> 0.86271705 | AB7: =+[2]Report1!BC12 -> 0.92728638 | AC7: =+[2]Report1!BD12 -> 0.86271705 | AD7: =+[2]Report1!R12 -> 44.225 | AE7: =+[2]Report1!S12 -> 164.582 | AF7: =+[2]Report1!X12 -> 96.42879 | AG7: =+[2]Report1!Y12 -> 93.190218 | AH7: =+[2]Report1!AD12 -> 1.3408705 | AI7: =+[2]Report1!AE12 -> 1.3780365 | AJ7: =+[2]Report1!AJ12 -> 828.13929 | AK7: =+[2]Report1!AK12 -> 864.64765 | AL7: 0 | AM7: 0 | AN7: =+[3]Report1!J12 -> 0.93655179 | AO7: =+[3]Report1!K12 -> 0.92775535 | AP7: =+[3]Report1!BN12 -> 0.93655179 | AQ7: =+[3]Report1!BO12 -> 0.92775535 | AR7: =+[3]Report1!R12 -> 47.858 | AS7: =+[3]Report1!S12 -> 189.634 | AT7: =+[3]Report1!AF12 -> 112.83688 | AU7: =+[3]Report1!AG12 -> 114.31059 | AV7: =+[3]Report1!AL12 -> 1.4668394 | AW7: =+[3]Report1!AM12 -> 1.5018404 | AX7: =+[3]Report1!AR12 -> 0.17969827 | AY7: =+[3]Report1!AS12 -> 0.20882331 | AZ7: =+[3]Report1!AX12 -> 917.59915 | BA7: =+[3]Report1!AY12 -> 908.93743 | BB7: =+[3]Report1!BD12 -> 460.94697 | BC7: =+[3]Report1!BE12 -> 511.48486 | BD7: =+[3]Report1!BJ12 -> 14.375862 | BE7: =+[3]Report1!BK12 -> 14.741492 | BF7: =+[4]Report1!J12 -> 0.87419463 | BG7: =+[4]Report1!K12 -> 0.88908077 | BH7: =+[4]Report1!AN12 -> 0.87419463 | BI7: =+[4]Report1!AO12 -> 0.88908077 | BJ7: =+[4]Report1!R12 -> 45.798 | BK7: =+[4]Report1!S12 -> 190.019 | BL7: =+[4]Report1!AD12 -> 2.8625704 | BM7: =+[4]Report1!AE12 -> 2.7149917 | BN7: 0 | BO7: 0 | BP7: =+[4]Report1!AJ12 -> 1011.0104 | BQ7: =+[4]Report1!AK12 -> 990.52442 | BR7: 0 | BS7: 0 | BT7: =+[5]Report1!J12 -> 0.94454342 | BU7: =+[5]Report1!K12 -> 0.9383758 | BV7: =+[5]Report1!BG12 -> 0.94454342 | BW7: =+[5]Report1!BH12 -> 0.9383758 | BX7: =+[5]Report1!R12 -> 48.662 | BY7: =+[5]Report1!S12 -> 193.377 | BZ7: =+[5]Report1!X12 -> 79.349173 | CA7: =+[5]Report1!Y12 -> 78.020614 | CB7: =+[5]Report1!AD12 -> 2.0221117 | CC7: =+[5]Report1!AE12 -> 2.0317825 | CD7: =+[5]Report1!AJ12 -> 0.17467428 | CE7: =+[5]Report1!AK12 -> 0.20581558 | CF7: =+[5]Report1!AP12 -> 770.8893 | CG7: =+[5]Report1!AQ12 -> 792.15812 | CH7: =+[5]Report1!AV12 -> 453.33114 | CI7: =+[5]Report1!AW12 -> 502.03892 | CJ7: =+[5]Report1!BB12 -> 14.138342 | CK7: =+[5]Report1!BC12 -> 14.4599
A8: =1+A7 -> 45874 | B8: =+Report1!J13 -> 0.76602829 | C8: =+Report1!K13 -> 0.60434139 | D8: =+Report1!AJ13 -> 0.76602829 | E8: =+Report1!AK13 -> 0.60434139 | F8: =+Report1!R13 -> 56.883 | G8: =+Report1!S13 -> 204.266 | H8: =+Report1!X13 -> 2.659037 | I8: =+Report1!Y13 -> 2.8233235 | J8: =+Report1!AD13 -> 989.88977 | K8: =+Report1!AE13 -> 1068.7698 | L8: =+[1]Report1!J13 -> 0.04548657 | M8: =+[1]Report1!K13 -> 0.80530974 | N8: =+[1]Report1!BJ13 -> 0.34593654 | O8: =+[1]Report1!BK13 -> 0.94514415 | P8: =+[1]Report1!R13 -> 2.374 | Q8: =+[1]Report1!S13 -> 246.729 | R8: =+[1]Report1!AL13 -> 19.467987 | S8: =+[1]Report1!AM13 -> 2.8951968 | T8: =+[1]Report1!AR13 -> 0 | U8: =+[1]Report1!AS13 -> 0.25331437 | V8: =+[1]Report1!AX13 -> 4236.3732 | W8: =+[1]Report1!AY13 -> 625.80325 | X8: =+[1]Report1!BD13 -> 264.1112 | Y8: =+[1]Report1!BE13 -> 428.61196 | Z8: =+[2]Report1!J13 -> 0.89698838 | AA8: =+[2]Report1!K13 -> 0.86957132 | AB8: =+[2]Report1!BC13 -> 0.89698838 | AC8: =+[2]Report1!BD13 -> 0.86957132 | AD8: =+[2]Report1!R13 -> 42.78 | AE8: =+[2]Report1!S13 -> 207.362 | AF8: =+[2]Report1!X13 -> 96.845417 | AG8: =+[2]Report1!Y13 -> 93.944308 | AH8: =+[2]Report1!AD13 -> 1.2973352 | AI8: =+[2]Report1!AE13 -> 1.3613873 | AJ8: =+[2]Report1!AJ13 -> 848.47826 | AK8: =+[2]Report1!AK13 -> 861.31181 | AL8: 0 | AM8: 0 | AN8: =+[3]Report1!J13 -> 0.93103322 | AO8: =+[3]Report1!K13 -> 0.92841093 | AP8: =+[3]Report1!BN13 -> 0.93103322 | AQ8: =+[3]Report1!BO13 -> 0.92841093 | AR8: =+[3]Report1!R13 -> 47.576 | AS8: =+[3]Report1!S13 -> 237.21 | AT8: =+[3]Report1!AF13 -> 115.54347 | AU8: =+[3]Report1!AG13 -> 114.55786 | AV8: =+[3]Report1!AL13 -> 1.4797377 | AW8: =+[3]Report1!AM13 -> 1.4974074 | AX8: =+[3]Report1!AR13 -> 0.20808811 | AY8: =+[3]Report1!AS13 -> 0.20867586 | AZ8: =+[3]Report1!AX13 -> 852.27636 | BA8: =+[3]Report1!AY13 -> 897.57321 | BB8: =+[3]Report1!BD13 -> 537.45481 | BC8: =+[3]Report1!BE13 -> 516.69352 | BD8: =+[3]Report1!BJ13 -> 3.9578779 | BE8: =+[3]Report1!BK13 -> 12.578677 | BF8: =+[4]Report1!J13 -> 0.85371022 | BG8: =+[4]Report1!K13 -> 0.88208327 | BH8: =+[4]Report1!AN13 -> 0.85371022 | BI8: =+[4]Report1!AO13 -> 0.88208327 | BJ8: =+[4]Report1!R13 -> 44.999 | BK8: =+[4]Report1!S13 -> 235.018 | BL8: =+[4]Report1!AD13 -> 2.7778395 | BM8: =+[4]Report1!AE13 -> 2.7270252 | BN8: 0 | BO8: 0 | BP8: =+[4]Report1!AJ13 -> 966.99593 | BQ8: =+[4]Report1!AK13 -> 986.01941 | BR8: 0 | BS8: 0 | BT8: =+[5]Report1!J13 -> 0.82618231 | BU8: =+[5]Report1!K13 -> 0.91567728 | BV8: =+[5]Report1!BG13 -> 0.82618231 | BW8: =+[5]Report1!BH13 -> 0.91567728 | BX8: =+[5]Report1!R13 -> 43.182 | BY8: =+[5]Report1!S13 -> 236.559 | BZ8: =+[5]Report1!X13 -> 89.709996 | CA8: =+[5]Report1!Y13 -> 80.15442 | CB8: =+[5]Report1!AD13 -> 2.2578852 | CC8: =+[5]Report1!AE13 -> 2.0730558 | CD8: =+[5]Report1!AJ13 -> 0.22926219 | CE8: =+[5]Report1!AK13 -> 0.21009558 | CF8: =+[5]Report1!AP13 -> 904.5864 | CG8: =+[5]Report1!AQ13 -> 812.68102 | CH8: =+[5]Report1!AV13 -> 592.14372 | CI8: =+[5]Report1!AW13 -> 518.48685 | CJ8: =+[5]Report1!BB13 -> 4.3606132 | CK8: =+[5]Report1!BC13 -> 12.616354
A9: =1+A8 -> 45875 | B9: =+Report1!J14 -> 0.92060276 | C9: =+Report1!K14 -> 0.66482753 | D9: =+Report1!AJ14 -> 0.92060276 | E9: =+Report1!AK14 -> 0.66482753 | F9: =+Report1!R14 -> 73.584 | G9: =+Report1!S14 -> 277.85 | H9: =+Report1!X14 -> 2.2536965 | I9: =+Report1!Y14 -> 2.6724672 | J9: =+Report1!AD14 -> 776.10595 | K9: =+Report1!AE14 -> 991.26262 | L9: =+[1]Report1!J14 -> 0.60009357 | M9: =+[1]Report1!K14 -> 0.77405446 | N9: =+[1]Report1!BJ14 -> 0.67266853 | O9: =+[1]Report1!BK14 -> 0.90200281 | P9: =+[1]Report1!R14 -> 33.033 | Q9: =+[1]Report1!S14 -> 279.762 | R9: =+[1]Report1!AL14 -> 3.9973663 | S9: =+[1]Report1!AM14 -> 3.0253358 | T9: =+[1]Report1!AR14 -> 0 | U9: =+[1]Report1!AS14 -> 0.22340418 | V9: =+[1]Report1!AX14 -> 1370.7223 | W9: =+[1]Report1!AY14 -> 713.75984 | X9: =+[1]Report1!BD14 -> 18.5572 | Y9: =+[1]Report1!BE14 -> 380.19459 | Z9: =+[2]Report1!J14 -> 0.89021991 | AA9: =+[2]Report1!K14 -> 0.87303251 | AB9: =+[2]Report1!BC14 -> 0.89021991 | AC9: =+[2]Report1!BD14 -> 0.87303251 | AD9: =+[2]Report1!R14 -> 42.75 | AE9: =+[2]Report1!S14 -> 250.112 | AF9: =+[2]Report1!X14 -> 94.947025 | AG9: =+[2]Report1!Y14 -> 94.115695 | AH9: =+[2]Report1!AD14 -> 1.354386 | AI9: =+[2]Report1!AE14 -> 1.3601906 | AJ9: =+[2]Report1!AJ14 -> 914.59602 | AK9: =+[2]Report1!AK14 -> 870.41933 | AL9: 0 | AM9: 0 | AN9: =+[3]Report1!J14 -> 0.94067469 | AO9: =+[3]Report1!K14 -> 0.93052832 | AP9: =+[3]Report1!BN14 -> 0.94067469 | AQ9: =+[3]Report1!BO14 -> 0.93052832 | AR9: =+[3]Report1!R14 -> 50.156 | AS9: =+[3]Report1!S14 -> 287.366 | AT9: =+[3]Report1!AF14 -> 110.53196 | AU9: =+[3]Report1!AG14 -> 113.85519 | AV9: =+[3]Report1!AL14 -> 1.4335274 | AW9: =+[3]Report1!AM14 -> 1.4862579 | AX9: =+[3]Report1!AR14 -> 0.1933966 | AY9: =+[3]Report1!AS14 -> 0.20600906 | AZ9: =+[3]Report1!AX14 -> 881.03078 | BA9: =+[3]Report1!AY14 -> 894.68594 | BB9: =+[3]Report1!BD14 -> 459.88159 | BC9: =+[3]Report1!BE14 -> 506.77774 | BD9: =+[3]Report1!BJ14 -> 4.1689927 | BE9: =+[3]Report1!BK14 -> 11.110876 | BF9: =+[4]Report1!J14 -> 0.93469207 | BG9: =+[4]Report1!K14 -> 0.89073683 | BH9: =+[4]Report1!AN14 -> 0.93469207 | BI9: =+[4]Report1!AO14 -> 0.89073683 | BJ9: =+[4]Report1!R14 -> 49.028 | BK9: =+[4]Report1!S14 -> 284.046 | BL9: =+[4]Report1!AD14 -> 2.5944358 | BM9: =+[4]Report1!AE14 -> 2.7041395 | BN9: 0 | BO9: 0 | BP9: =+[4]Report1!AJ14 -> 967.11002 | BQ9: =+[4]Report1!AK14 -> 982.75554 | BR9: 0 | BS9: 0 | BT9: =+[5]Report1!J14 -> 0.95001356 | BU9: =+[5]Report1!K14 -> 0.92166585 | BV9: =+[5]Report1!BG14 -> 0.95001356 | BW9: =+[5]Report1!BH14 -> 0.92166585 | BX9: =+[5]Report1!R14 -> 51.848 | BY9: =+[5]Report1!S14 -> 288.407 | BZ9: =+[5]Report1!X14 -> 71.751541 | CA9: =+[5]Report1!Y14 -> 78.643803 | CB9: =+[5]Report1!AD14 -> 1.818778 | CC9: =+[5]Report1!AE14 -> 2.0273433 | CD9: =+[5]Report1!AJ14 -> 0.17744175 | CE9: =+[5]Report1!AK14 -> 0.20422528 | CF9: =+[5]Report1!AP14 -> 739.63258 | CG9: =+[5]Report1!AQ14 -> 799.54883 | CH9: =+[5]Report1!AV14 -> 427.42785 | CI9: =+[5]Report1!AW14 -> 502.11683 | CJ9: =+[5]Report1!BB14 -> 3.8747878 | CK9: =+[5]Report1!BC14 -> 11.04485
A10: =1+A9 -> 45876 | B10: =+Report1!J15 -> 0.93472606 | C10: =+Report1!K15 -> 0.70548494 | D10: =+Report1!AJ15 -> 0.93472606 | E10: =+Report1!AK15 -> 0.70548494 | F10: =+Report1!R15 -> 69.284 | G10: =+Report1!S15 -> 347.134 | H10: =+Report1!X15 -> 2.0695399 | I10: =+Report1!Y15 -> 2.5521297 | J10: =+Report1!AD15 -> 788.33988 | K10: =+Report1!AE15 -> 950.76155 | L10: =+[1]Report1!J15 -> 0.55646884 | M10: =+[1]Report1!K15 -> 0.74460828 | N10: =+[1]Report1!BJ15 -> 0.55646884 | O10: =+[1]Report1!BK15 -> 0.84870395 | P10: =+[1]Report1!R15 -> 31.478 | Q10: =+[1]Report1!S15 -> 311.24 | R10: =+[1]Report1!AL15 -> 3.4532689 | S10: =+[1]Report1!AM15 -> 3.0686159 | T10: =+[1]Report1!AR15 -> 0 | U10: =+[1]Report1!AS15 -> 0.20080966 | V10: =+[1]Report1!AX15 -> 1113.3779 | W10: =+[1]Report1!AY15 -> 754.17617 | X10: =+[1]Report1!BD15 -> 15.058136 | Y10: =+[1]Report1!BE15 -> 343.26565 | Z10: =+[2]Report1!J15 -> 0.92251305 | AA10: =+[2]Report1!K15 -> 0.88077142 | AB10: =+[2]Report1!BC15 -> 0.92251305 | AC10: =+[2]Report1!BD15 -> 0.88077142 | AD10: =+[2]Report1!R15 -> 48.999 | AE10: =+[2]Report1!S15 -> 299.111 | AF10: =+[2]Report1!X15 -> 95.878767 | AG10: =+[2]Report1!Y15 -> 94.404514 | AH10: =+[2]Report1!AD15 -> 1.2592094 | AI10: =+[2]Report1!AE15 -> 1.3436483 | AJ10: =+[2]Report1!AJ15 -> 729.79734 | AK10: =+[2]Report1!AK15 -> 847.38328 | AL10: 0 | AM10: 0 | AN10: =+[3]Report1!J15 -> 0.94103816 | AO10: =+[3]Report1!K15 -> 0.93211222 | AP10: =+[3]Report1!BN15 -> 0.97564619 | AQ10: =+[3]Report1!BO15 -> 0.93712195 | AR10: =+[3]Report1!R15 -> 51.569 | AS10: =+[3]Report1!S15 -> 338.935 | AT10: =+[3]Report1!AF15 -> 98.312337 | AU10: =+[3]Report1!AG15 -> 111.49035 | AV10: =+[3]Report1!AL15 -> 1.2546297 | AW10: =+[3]Report1!AM15 -> 1.4510157 | AX10: =+[3]Report1!AR15 -> 0.12604472 | AY10: =+[3]Report1!AS15 -> 0.19384248 | AZ10: =+[3]Report1!AX15 -> 759.16423 | BA10: =+[3]Report1!AY15 -> 874.0663 | BB10: =+[3]Report1!BD15 -> 338.61273 | BC10: =+[3]Report1!BE15 -> 481.19141 | BD10: =+[3]Report1!BJ15 -> 4.1265101 | BE10: =+[3]Report1!BK15 -> 10.048204 | BF10: =+[4]Report1!J15 -> 0.86945414 | BG10: =+[4]Report1!K15 -> 0.88777858 | BH10: =+[4]Report1!AN15 -> 0.86945414 | BI10: =+[4]Report1!AO15 -> 0.88777858 | BJ10: =+[4]Report1!R15 -> 44.76 | BK10: =+[4]Report1!S15 -> 328.806 | BL10: =+[4]Report1!AD15 -> 2.8686327 | BM10: =+[4]Report1!AE15 -> 2.7265318 | BN10: 0 | BO10: 0 | BP10: =+[4]Report1!AJ15 -> 1024.3151 | BQ10: =+[4]Report1!AK15 -> 988.413 | BR10: 0 | BS10: 0 | BT10: =+[5]Report1!J15 -> 0.67586399 | BU10: =+[5]Report1!K15 -> 0.88630096 | BV10: =+[5]Report1!BG15 -> 0.75153988 | BW10: =+[5]Report1!BH15 -> 0.89932998 | BX10: =+[5]Report1!R15 -> 35.542 | BY10: =+[5]Report1!S15 -> 323.949 | BZ10: =+[5]Report1!X15 -> 99.014333 | CA10: =+[5]Report1!Y15 -> 80.878752 | CB10: =+[5]Report1!AD15 -> 2.4421811 | CC10: =+[5]Report1!AE15 -> 2.0728571 | CD10: =+[5]Report1!AJ15 -> 0.14630578 | CE10: =+[5]Report1!AK15 -> 0.19787065 | CF10: =+[5]Report1!AP15 -> 955.2272 | CG10: =+[5]Report1!AQ15 -> 816.62905 | CH10: =+[5]Report1!AV15 -> 386.02442 | CI10: =+[5]Report1!AW15 -> 489.37978 | CJ10: =+[5]Report1!BB15 -> 4.7042935 | CK10: =+[5]Report1!BC15 -> 10.349197
A11: =1+A10 -> 45877 | B11: =+Report1!J16 -> 0.9714059 | C11: =+Report1!K16 -> 0.73948209 | D11: =+Report1!AJ16 -> 0.9714059 | E11: =+Report1!AK16 -> 0.73948209 | F11: =+Report1!R16 -> 70.066 | G11: =+Report1!S16 -> 417.2 | H11: =+Report1!X16 -> 2.1457768 | I11: =+Report1!Y16 -> 2.4838854 | J11: =+Report1!AD16 -> 827.79865 | K11: =+Report1!AE16 -> 930.11074 | L11: =+[1]Report1!J16 -> 0.86040661 | M11: =+[1]Report1!K16 -> 0.76319655 | N11: =+[1]Report1!BJ16 -> 0.86040661 | O11: =+[1]Report1!BK16 -> 0.85079812 | P11: =+[1]Report1!R16 -> 68.77 | Q11: =+[1]Report1!S16 -> 380.01 | R11: =+[1]Report1!AL16 -> 2.1362804 | S11: =+[1]Report1!AM16 -> 2.8998921 | T11: =+[1]Report1!AR16 -> 0 | U11: =+[1]Report1!AS16 -> 0.16446936 | V11: =+[1]Report1!AX16 -> 636.78653 | W11: =+[1]Report1!AY16 -> 732.93229 | X11: =+[1]Report1!BD16 -> 7.5468954 | Y11: =+[1]Report1!BE16 -> 282.51099 | Z11: =+[2]Report1!J16 -> 0.82670871 | AA11: =+[2]Report1!K16 -> 0.87347982 | AB11: =+[2]Report1!BC16 -> 0.82670871 | AC11: =+[2]Report1!BD16 -> 0.87347982 | AD11: =+[2]Report1!R16 -> 43.769 | AE11: =+[2]Report1!S16 -> 342.88 | AF11: =+[2]Report1!X16 -> 103.36941 | AG11: =+[2]Report1!Y16 -> 95.548893 | AH11: =+[2]Report1!AD16 -> 1.3000069 | AI11: =+[2]Report1!AE16 -> 1.3380775 | AJ11: =+[2]Report1!AJ16 -> 811.08867 | AK11: =+[2]Report1!AK16 -> 842.75023 | AL11: 0 | AM11: 0 | AN11: =+[3]Report1!J16 -> 0.071476657 | AO11: =+[3]Report1!K16 -> 0.82278523 | AP11: =+[3]Report1!BN16 -> 0.10140531 | AQ11: =+[3]Report1!BO16 -> 0.85899929 | AR11: =+[3]Report1!R16 -> 3.782 | AS11: =+[3]Report1!S16 -> 342.717 | AT11: =+[3]Report1!AF16 -> 467.83211 | AU11: =+[3]Report1!AG16 -> 115.4227 | AV11: =+[3]Report1!AL16 -> 7.244844 | AW11: =+[3]Report1!AM16 -> 1.5149526 | AX11: =+[3]Report1!AR16 -> 0 | AY11: =+[3]Report1!AS16 -> 0.19170336 | AZ11: =+[3]Report1!AX16 -> 5105.9069 | BA11: =+[3]Report1!AY16 -> 920.76611 | BB11: =+[3]Report1!BD16 -> 220.12163 | BC11: =+[3]Report1!BE16 -> 478.31042 | BD11: =+[3]Report1!BJ16 -> 1.3220518 | BE11: =+[3]Report1!BK16 -> 9.9519078 | BF11: =+[4]Report1!J16 -> 0.97512506 | BG11: =+[4]Report1!K16 -> 0.89843793 | BH11: =+[4]Report1!AN16 -> 0.97512506 | BI11: =+[4]Report1!AO16 -> 0.89843793 | BJ11: =+[4]Report1!R16 -> 50.2 | BK11: =+[4]Report1!S16 -> 379.006 | BL11: =+[4]Report1!AD16 -> 2.5796813 | BM11: =+[4]Report1!AE16 -> 2.7070812 | BN11: 0 | BO11: 0 | BP11: =+[4]Report1!AJ16 -> 889.82689 | BQ11: =+[4]Report1!AK16 -> 975.3551 | BR11: 0 | BS11: 0 | BT11: =+[5]Report1!J16 -> 0.1941175 | BU11: =+[5]Report1!K16 -> 0.79796022 | BV11: =+[5]Report1!BG16 -> 0.25296761 | BW11: =+[5]Report1!BH16 -> 0.83323028 | BX11: =+[5]Report1!R16 -> 10.38 | BY11: =+[5]Report1!S16 -> 334.329 | BZ11: =+[5]Report1!X16 -> 88.466588 | CA11: =+[5]Report1!Y16 -> 81.114333 | CB11: =+[5]Report1!AD16 -> 2.3709056 | CC11: =+[5]Report1!AE16 -> 2.0821107 | CD11: =+[5]Report1!AJ16 -> 0 | CE11: =+[5]Report1!AK16 -> 0.19172731 | CF11: =+[5]Report1!AP16 -> 1500.3189 | CG11: =+[5]Report1!AQ16 -> 837.85575 | CH11: =+[5]Report1!AV16 -> 80.202312 | CI11: =+[5]Report1!AW16 -> 476.67594 | CJ11: =+[5]Report1!BB16 -> 0.48169557 | CK11: =+[5]Report1!BC16 -> 10.042838
A12: =1+A11 -> 45878 | B12: =+Report1!J17 -> 0.98913092 | C12: =+Report1!K17 -> 0.76885769 | D12: =+Report1!AJ17 -> 0.98913092 | E12: =+Report1!AK17 -> 0.76885769 | F12: =+Report1!R17 -> 74.421 | G12: =+Report1!S17 -> 491.621 | H12: =+Report1!X17 -> 2.1352978 | I12: =+Report1!Y17 -> 2.4311167 | J12: =+Report1!AD17 -> 777.38031 | K12: =+Report1!AE17 -> 906.99059 | L12: =+[1]Report1!J17 -> 0.83020676 | M12: =+[1]Report1!K17 -> 0.77264687 | N12: =+[1]Report1!BJ17 -> 0.83020676 | O12: =+[1]Report1!BK17 -> 0.84761241 | P12: =+[1]Report1!R17 -> 67.869 | Q12: =+[1]Report1!S17 -> 447.879 | R12: =+[1]Report1!AL17 -> 2.3344531 | S12: =+[1]Report1!AM17 -> 2.8142087 | T12: =+[1]Report1!AR17 -> 0 | U12: =+[1]Report1!AS17 -> 0.13954662 | V12: =+[1]Report1!AX17 -> 667.80754 | W12: =+[1]Report1!AY17 -> 723.06366 | X12: =+[1]Report1!BD17 -> 6.6451546 | Y12: =+[1]Report1!BE17 -> 240.70787 | Z12: =+[2]Report1!J17 -> 0.9569716 | AA12: =+[2]Report1!K17 -> 0.88236428 | AB12: =+[2]Report1!BC17 -> 0.9569716 | AC12: =+[2]Report1!BD17 -> 0.88236428 | AD12: =+[2]Report1!R17 -> 44.734 | AE12: =+[2]Report1!S17 -> 387.614 | AF12: =+[2]Report1!X17 -> 93.762407 | AG12: =+[2]Report1!Y17 -> 95.342717 | AH12: =+[2]Report1!AD17 -> 1.2093709 | AI12: =+[2]Report1!AE17 -> 1.3232236 | AJ12: =+[2]Report1!AJ17 -> 869.88465 | AK12: =+[2]Report1!AK17 -> 845.88178 | AL12: 0 | AM12: 0 | AN12: =+[3]Report1!J17 -> 0.79384984 | AO12: =+[3]Report1!K17 -> 0.81951947 | AP12: =+[3]Report1!BN17 -> 0.79384984 | AQ12: =+[3]Report1!BO17 -> 0.85136058 | AR12: =+[3]Report1!R17 -> 42.068 | AS12: =+[3]Report1!S17 -> 384.785 | AT12: =+[3]Report1!AF17 -> 123.12678 | AU12: =+[3]Report1!AG17 -> 116.26498 | AV12: =+[3]Report1!AL17 -> 1.5902824 | AW12: =+[3]Report1!AM17 -> 1.5231883 | AX12: =+[3]Report1!AR17 -> 0 | AY12: =+[3]Report1!AS17 -> 0.1707447 | AZ12: =+[3]Report1!AX17 -> 1056.9416 | BA12: =+[3]Report1!AY17 -> 935.65399 | BB12: =+[3]Report1!BD17 -> 21.524674 | BC12: =+[3]Report1!BE17 -> 428.37068 | BD12: =+[3]Report1!BJ17 -> 0 | BE12: =+[3]Report1!BK17 -> 8.8638798 | BF12: =+[4]Report1!J17 -> 0.94919295 | BG12: =+[4]Report1!K17 -> 0.90395817 | BH12: =+[4]Report1!AN17 -> 0.94919295 | BI12: =+[4]Report1!AO17 -> 0.90395817 | BJ12: =+[4]Report1!R17 -> 48.865 | BK12: =+[4]Report1!S17 -> 427.871 | BL12: =+[4]Report1!AD17 -> 2.6419728 | BM12: =+[4]Report1!AE17 -> 2.6996455 | BN12: 0 | BO12: 0 | BP12: =+[4]Report1!AJ17 -> 989.6476 | BQ12: =+[4]Report1!AK17 -> 976.98737 | BR12: 0 | BS12: 0 | BT12: =+[5]Report1!J17 -> 0.85309949 | BU12: =+[5]Report1!K17 -> 0.80414306 | BV12: =+[5]Report1!BG17 -> 0.85309949 | BW12: =+[5]Report1!BH17 -> 0.83554525 | BX12: =+[5]Report1!R17 -> 45.141 | BY12: =+[5]Report1!S17 -> 379.47 | BZ12: =+[5]Report1!X17 -> 89.806051 | CA12: =+[5]Report1!Y17 -> 82.148283 | CB12: =+[5]Report1!AD17 -> 2.0557808 | CC12: =+[5]Report1!AE17 -> 2.0789786 | CD12: =+[5]Report1!AJ17 -> 0 | CE12: =+[5]Report1!AK17 -> 0.16891981 | CF12: =+[5]Report1!AP17 -> 912.80942 | CG12: =+[5]Report1!AQ17 -> 846.77209 | CH12: =+[5]Report1!AV17 -> 20.05937 | CI12: =+[5]Report1!AW17 -> 422.35773 | CJ12: =+[5]Report1!BB17 -> 0 | CK12: =+[5]Report1!BC17 -> 8.8481619
A13: =1+A12 -> 45879 | B13: =+Report1!J18 -> 1.019359 | C13: =+Report1!K18 -> 0.7967745 | D13: =+Report1!AJ18 -> 1.019359 | E13: =+Report1!AK18 -> 0.7967745 | F13: =+Report1!R18 -> 81.749 | G13: =+Report1!S18 -> 573.37 | H13: =+Report1!X18 -> 2.1023988 | I13: =+Report1!Y18 -> 2.3842493 | J13: =+Report1!AD18 -> 675.02404 | K13: =+Report1!AE18 -> 873.91764 | L13: =+[1]Report1!J18 -> 0.97203049 | M13: =+[1]Report1!K18 -> 0.79608713 | N13: =+[1]Report1!BJ18 -> 0.97203049 | O13: =+[1]Report1!BK18 -> 0.86347766 | P13: =+[1]Report1!R18 -> 75.067 | Q13: =+[1]Report1!S18 -> 522.946 | R13: =+[1]Report1!AL18 -> 2.0930369 | S13: =+[1]Report1!AM18 -> 2.7106871 | T13: =+[1]Report1!AR18 -> 0 | U13: =+[1]Report1!AS18 -> 0.11951521 | V13: =+[1]Report1!AX18 -> 604.44416 | W13: =+[1]Report1!AY18 -> 706.03626 | X13: =+[1]Report1!BD18 -> 6.0612519 | Y13: =+[1]Report1!BE18 -> 207.0252 | Z13: =+[2]Report1!J18 -> 0.91104547 | AA13: =+[2]Report1!K18 -> 0.88490805 | AB13: =+[2]Report1!BC18 -> 0.91104547 | AC13: =+[2]Report1!BD18 -> 0.88490805 | AD13: =+[2]Report1!R18 -> 38.95 | AE13: =+[2]Report1!S18 -> 426.564 | AF13: =+[2]Report1!X18 -> 101.64432 | AG13: =+[2]Report1!Y18 -> 95.918123 | AH13: =+[2]Report1!AD18 -> 1.3247754 | AI13: =+[2]Report1!AE18 -> 1.3233653 | AJ13: =+[2]Report1!AJ18 -> 942.29884 | AK13: =+[2]Report1!AK18 -> 854.68572 | AL13: 0 | AM13: 0 | AN13: =+[3]Report1!J18 -> 0.92215643 | AO13: =+[3]Report1!K18 -> 0.82993453 | AP13: =+[3]Report1!BN18 -> 0.92215643 | AQ13: =+[3]Report1!BO18 -> 0.85879439 | AR13: =+[3]Report1!R18 -> 48.898 | AS13: =+[3]Report1!S18 -> 433.683 | AT13: =+[3]Report1!AF18 -> 101.9003 | AU13: =+[3]Report1!AG18 -> 114.64535 | AV13: =+[3]Report1!AL18 -> 1.3988302 | AW13: =+[3]Report1!AM18 -> 1.5091668 | AX13: =+[3]Report1!AR18 -> 0 | AY13: =+[3]Report1!AS18 -> 0.15149314 | AZ13: =+[3]Report1!AX18 -> 883.72817 | BA13: =+[3]Report1!AY18 -> 929.79932 | BB13: =+[3]Report1!BD18 -> 13.364555 | BC13: =+[3]Report1!BE18 -> 381.57851 | BD13: =+[3]Report1!BJ18 -> 0.10225367 | BE13: =+[3]Report1!BK18 -> 7.8760016 | BF13: =+[4]Report1!J18 -> 0.99338438 | BG13: =+[4]Report1!K18 -> 0.91273031 | BH13: =+[4]Report1!AN18 -> 0.99338438 | BI13: =+[4]Report1!AO18 -> 0.91273031 | BJ13: =+[4]Report1!R18 -> 51.14 | BK13: =+[4]Report1!S18 -> 479.011 | BL13: =+[4]Report1!AD18 -> 2.5048885 | BM13: =+[4]Report1!AE18 -> 2.6788529 | BN13: 0 | BO13: 0 | BP13: =+[4]Report1!AJ18 -> 899.25323 | BQ13: =+[4]Report1!AK18 -> 968.68835 | BR13: 0 | BS13: 0 | BT13: =+[5]Report1!J18 -> 0.83168639 | BU13: =+[5]Report1!K18 -> 0.8069538 | BV13: =+[5]Report1!BG18 -> 0.83168639 | BW13: =+[5]Report1!BH18 -> 0.8351377 | BX13: =+[5]Report1!R18 -> 44.602 | BY13: =+[5]Report1!S18 -> 424.072 | BZ13: =+[5]Report1!X18 -> 91.929353 | CA13: =+[5]Report1!Y18 -> 83.177012 | CB13: =+[5]Report1!AD18 -> 2.1770324 | CC13: =+[5]Report1!AE18 -> 2.0892914 | CD13: =+[5]Report1!AJ18 -> 0 | CE13: =+[5]Report1!AK18 -> 0.15115358 | CF13: =+[5]Report1!AP18 -> 915.62733 | CG13: =+[5]Report1!AQ18 -> 854.01398 | CH13: =+[5]Report1!AV18 -> 14.651809 | CI13: =+[5]Report1!AW18 -> 379.47704 | CJ13: =+[5]Report1!BB18 -> 0.1121026 | CK13: =+[5]Report1!BC18 -> 7.9293422
A14: =1+A13 -> 45880 | B14: =+Report1!J19 -> 0.72974618 | C14: =+Report1!K19 -> 0.78979691 | D14: =+Report1!AJ19 -> 0.72974618 | E14: =+Report1!AK19 -> 0.78979691 | F14: =+Report1!R19 -> 61.018 | G14: =+Report1!S19 -> 634.388 | H14: =+Report1!X19 -> 2.8267233 | I14: =+Report1!Y19 -> 2.4268082 | J14: =+Report1!AD19 -> 914.61896 | K14: =+Report1!AE19 -> 877.83246 | L14: =+[1]Report1!J19 -> 0.86127935 | M14: =+[1]Report1!K19 -> 0.80110245 | N14: =+[1]Report1!BJ19 -> 0.86127935 | O14: =+[1]Report1!BK19 -> 0.86329541 | P14: =+[1]Report1!R19 -> 47.153 | Q14: =+[1]Report1!S19 -> 570.099 | R14: =+[1]Report1!AL19 -> 2.8393527 | S14: =+[1]Report1!AM19 -> 2.7213291 | T14: =+[1]Report1!AR19 -> 0 | U14: =+[1]Report1!AS19 -> 0.10963008 | V14: =+[1]Report1!AX19 -> 965.59561 | W14: =+[1]Report1!AY19 -> 727.50447 | X14: =+[1]Report1!BD19 -> 9.7342693 | Y14: =+[1]Report1!BE19 -> 190.70723 | Z14: =+[2]Report1!J19 -> 0.90631825 | AA14: =+[2]Report1!K19 -> 0.88672809 | AB14: =+[2]Report1!BC19 -> 0.90631825 | AC14: =+[2]Report1!BD19 -> 0.88672809 | AD14: =+[2]Report1!R19 -> 40.589 | AE14: =+[2]Report1!S19 -> 467.153 | AF14: =+[2]Report1!X19 -> 98.498282 | AG14: =+[2]Report1!Y19 -> 96.142302 | AH14: =+[2]Report1!AD19 -> 1.2959176 | AI14: =+[2]Report1!AE19 -> 1.3209805 | AJ14: =+[2]Report1!AJ19 -> 964.01045 | AK14: =+[2]Report1!AK19 -> 864.1845 | AL14: 0 | AM14: 0 | AN14: =+[3]Report1!J19 -> 0.8907 | AO14: =+[3]Report1!K19 -> 0.83553262 | AP14: =+[3]Report1!BN19 -> 0.8907 | AQ14: =+[3]Report1!BO19 -> 0.86182623 | AR14: =+[3]Report1!R19 -> 47.23 | AS14: =+[3]Report1!S19 -> 480.913 | AT14: =+[3]Report1!AF19 -> 105.03134 | AU14: =+[3]Report1!AG19 -> 113.70117 | AV14: =+[3]Report1!AL19 -> 1.4567012 | AW14: =+[3]Report1!AM19 -> 1.5040142 | AX14: =+[3]Report1!AR19 -> 0 | AY14: =+[3]Report1!AS19 -> 0.13661515 | AZ14: =+[3]Report1!AX19 -> 1009.9136 | BA14: =+[3]Report1!AY19 -> 937.66727 | BB14: =+[3]Report1!BD19 -> 25.333474 | BC14: =+[3]Report1!BE19 -> 346.59203 | BD14: =+[3]Report1!BJ19 -> 0 | BE14: =+[3]Report1!BK19 -> 7.1025071 | BF14: =+[4]Report1!J19 -> 0.86547206 | BG14: =+[4]Report1!K19 -> 0.90850869 | BH14: =+[4]Report1!AN19 -> 0.86547206 | BI14: =+[4]Report1!AO19 -> 0.90850869 | BJ14: =+[4]Report1!R19 -> 44.555 | BK14: =+[4]Report1!S19 -> 523.566 | BL14: =+[4]Report1!AD19 -> 2.8885647 | BM14: =+[4]Report1!AE19 -> 2.6966992 | BN14: 0 | BO14: 0 | BP14: =+[4]Report1!AJ19 -> 1140.0403 | BQ14: =+[4]Report1!AK19 -> 983.27025 | BR14: 0 | BS14: 0 | BT14: =+[5]Report1!J19 -> 0.58917596 | BU14: =+[5]Report1!K19 -> 0.788935 | BV14: =+[5]Report1!BG19 -> 0.58917596 | BW14: =+[5]Report1!BH19 -> 0.8141369 | BX14: =+[5]Report1!R19 -> 27.929 | BY14: =+[5]Report1!S19 -> 452.001 | BZ14: =+[5]Report1!X19 -> 124.5452 | CA14: =+[5]Report1!Y19 -> 85.733139 | CB14: =+[5]Report1!AD19 -> 3.0720756 | CC14: =+[5]Report1!AE19 -> 2.1500174 | CD14: =+[5]Report1!AJ19 -> 0 | CE14: =+[5]Report1!AK19 -> 0.14181385 | CF14: =+[5]Report1!AP19 -> 1428.5565 | CG14: =+[5]Report1!AQ19 -> 889.51478 | CH14: =+[5]Report1!AV19 -> 42.840775 | CI14: =+[5]Report1!AW19 -> 358.67639 | CJ14: =+[5]Report1!BB19 -> 0 | CK14: =+[5]Report1!BC19 -> 7.4393906
A15: =1+A14 -> 45881 | B15: =+Report1!J20 -> 1.0214102 | C15: =+Report1!K20 -> 0.81146342 | D15: =+Report1!AJ20 -> 1.0214102 | E15: =+Report1!AK20 -> 0.81146342 | F15: =+Report1!R20 -> 84.668 | G15: =+Report1!S20 -> 719.056 | H15: =+Report1!X20 -> 2.0147163 | I15: =+Report1!Y20 -> 2.3782849 | J15: =+Report1!AD20 -> 628.37814 | K15: =+Report1!AE20 -> 848.45951 | L15: =+[1]Report1!J20 -> 0.91022184 | M15: =+[1]Report1!K20 -> 0.80878019 | N15: =+[1]Report1!BJ20 -> 0.91022184 | O15: =+[1]Report1!BK20 -> 0.8668342 | P15: =+[1]Report1!R20 -> 49.026 | Q15: =+[1]Report1!S20 -> 619.125 | R15: =+[1]Report1!AL20 -> 2.3781463 | S15: =+[1]Report1!AM20 -> 2.6941538 | T15: =+[1]Report1!AR20 -> 0 | U15: =+[1]Report1!AS20 -> 0.10094892 | V15: =+[1]Report1!AX20 -> 943.06858 | W15: =+[1]Report1!AY20 -> 744.57412 | X15: =+[1]Report1!BD20 -> 9.3011871 | Y15: =+[1]Report1!BE20 -> 176.34242 | Z15: =+[2]Report1!J20 -> 0.91632864 | AA15: =+[2]Report1!K20 -> 0.88905804 | AB15: =+[2]Report1!BC20 -> 0.91632864 | AC15: =+[2]Report1!BD20 -> 0.88905804 | AD15: =+[2]Report1!R20 -> 41.245 | AE15: =+[2]Report1!S20 -> 508.398 | AF15: =+[2]Report1!X20 -> 92.054258 | AG15: =+[2]Report1!Y20 -> 95.81065 | AH15: =+[2]Report1!AD20 -> 1.3262214 | AI15: =+[2]Report1!AE20 -> 1.3214057 | AJ15: =+[2]Report1!AJ20 -> 954.38283 | AK15: =+[2]Report1!AK20 -> 871.50205 | AL15: 0 | AM15: 0 | AN15: =+[3]Report1!J20 -> 0.9307551 | AO15: =+[3]Report1!K20 -> 0.84355662 | AP15: =+[3]Report1!BN20 -> 0.9307551 | AQ15: =+[3]Report1!BO20 -> 0.86780152 | AR15: =+[3]Report1!R20 -> 49.297 | AS15: =+[3]Report1!S20 -> 530.21 | AT15: =+[3]Report1!AF20 -> 96.987303 | AU15: =+[3]Report1!AG20 -> 112.14717 | AV15: =+[3]Report1!AL20 -> 1.3956225 | AW15: =+[3]Report1!AM20 -> 1.4939364 | AX15: =+[3]Report1!AR20 -> 0 | AY15: =+[3]Report1!AS20 -> 0.12391317 | AZ15: =+[3]Report1!AX20 -> 925.68554 | BA15: =+[3]Report1!AY20 -> 936.55325 | BB15: =+[3]Report1!BD20 -> 13.885226 | BC15: =+[3]Report1!BE20 -> 315.65816 | BD15: =+[3]Report1!BJ20 -> 0 | BE15: =+[3]Report1!BK20 -> 6.4421418 | BF15: =+[4]Report1!J20 -> 0.86990538 | BG15: =+[4]Report1!K20 -> 0.9052866 | BH15: =+[4]Report1!AN20 -> 0.86990538 | BI15: =+[4]Report1!AO20 -> 0.9052866 | BJ15: =+[4]Report1!R20 -> 45.654 | BK15: =+[4]Report1!S20 -> 569.22 | BL15: =+[4]Report1!AD20 -> 2.9000745 | BM15: =+[4]Report1!AE20 -> 2.7130108 | BN15: 0 | BO15: 0 | BP15: =+[4]Report1!AJ20 -> 1073.8222 | BQ15: =+[4]Report1!AK20 -> 990.53292 | BR15: 0 | BS15: 0 | BT15: =+[5]Report1!J20 -> 0.79201524 | BU15: =+[5]Report1!K20 -> 0.78917269 | BV15: =+[5]Report1!BG20 -> 0.79201524 | BW15: =+[5]Report1!BH20 -> 0.81237967 | BX15: =+[5]Report1!R20 -> 37.943 | BY15: =+[5]Report1!S20 -> 489.944 | BZ15: =+[5]Report1!X20 -> 98.912553 | CA15: =+[5]Report1!Y20 -> 86.7538 | CB15: =+[5]Report1!AD20 -> 2.3877922 | CC15: =+[5]Report1!AE20 -> 2.1684315 | CD15: =+[5]Report1!AJ20 -> 0 | CE15: =+[5]Report1!AK20 -> 0.13083128 | CF15: =+[5]Report1!AP20 -> 1116.5506 | CG15: =+[5]Report1!AQ20 -> 907.09724 | CH15: =+[5]Report1!AV20 -> 18.040218 | CI15: =+[5]Report1!AW20 -> 332.29632 | CJ15: =+[5]Report1!BB20 -> 0 | CK15: =+[5]Report1!BC20 -> 6.8632578
A16: =1+A15 -> 45882 | B16: =+Report1!J21 -> 0.96594056 | C16: =+Report1!K21 -> 0.82405085 | D16: =+Report1!AJ21 -> 0.96594056 | E16: =+Report1!AK21 -> 0.82405085 | F16: =+Report1!R21 -> 75.933 | G16: =+Report1!S21 -> 794.989 | H16: =+Report1!X21 -> 2.1604177 | I16: =+Report1!Y21 -> 2.3574754 | J16: =+Report1!AD21 -> 735.31008 | K16: =+Report1!AE21 -> 837.65209 | L16: =+[1]Report1!J21 -> 0.80938962 | M16: =+[1]Report1!K21 -> 0.80881996 | N16: =+[1]Report1!BJ21 -> 0.80938962 | O16: =+[1]Report1!BK21 -> 0.86283531 | P16: =+[1]Report1!R21 -> 43.254 | Q16: =+[1]Report1!S21 -> 662.379 | R16: =+[1]Report1!AL21 -> 2.6957276 | S16: =+[1]Report1!AM21 -> 2.6942566 | T16: =+[1]Report1!AR21 -> 0 | U16: =+[1]Report1!AS21 -> 0.094356856 | V16: =+[1]Report1!AX21 -> 1051.8063 | W16: =+[1]Report1!AY21 -> 764.63668 | X16: =+[1]Report1!BD21 -> 12.276321 | Y16: =+[1]Report1!BE21 -> 165.62874 | Z16: =+[2]Report1!J21 -> 0.95002271 | AA16: =+[2]Report1!K21 -> 0.89368668 | AB16: =+[2]Report1!BC21 -> 0.95002271 | AC16: =+[2]Report1!BD21 -> 0.89368668 | AD16: =+[2]Report1!R21 -> 44.635 | AE16: =+[2]Report1!S21 -> 553.033 | AF16: =+[2]Report1!X21 -> 84.983097 | AG16: =+[2]Report1!Y21 -> 94.936764 | AH16: =+[2]Report1!AD21 -> 1.2815055 | AI16: =+[2]Report1!AE21 -> 1.3181854 | AJ16: =+[2]Report1!AJ21 -> 841.57769 | AK16: =+[2]Report1!AK21 -> 869.08687 | AL16: 0 | AM16: 0 | AN16: =+[3]Report1!J21 -> 0.92316887 | AO16: =+[3]Report1!K21 -> 0.84911219 | AP16: =+[3]Report1!BN21 -> 0.92316887 | AQ16: =+[3]Report1!BO21 -> 0.87176829 | AR16: =+[3]Report1!R21 -> 43.529 | AS16: =+[3]Report1!S21 -> 573.739 | AT16: =+[3]Report1!AF21 -> 95.849752 | AU16: =+[3]Report1!AG21 -> 110.91071 | AV16: =+[3]Report1!AL21 -> 1.5690689 | AW16: =+[3]Report1!AM21 -> 1.4996366 | AX16: =+[3]Report1!AR21 -> 0 | AY16: =+[3]Report1!AS21 -> 0.114512 | AZ16: =+[3]Report1!AX21 -> 1013.8946 | BA16: =+[3]Report1!AY21 -> 942.42107 | BB16: =+[3]Report1!BD21 -> 19.240047 | BC16: =+[3]Report1!BE21 -> 293.16921 | BD16: =+[3]Report1!BJ21 -> 0.11486595 | BE16: =+[3]Report1!BK21 -> 5.9620977 | BF16: =+[4]Report1!J21 -> 0.90148879 | BG16: =+[4]Report1!K21 -> 0.90498737 | BH16: =+[4]Report1!AN21 -> 0.90148879 | BI16: =+[4]Report1!AO21 -> 0.90498737 | BJ16: =+[4]Report1!R21 -> 48.481 | BK16: =+[4]Report1!S21 -> 617.701 | BL16: =+[4]Report1!AD21 -> 2.7515934 | BM16: =+[4]Report1!AE21 -> 2.716039 | BN16: 0 | BO16: 0 | BP16: =+[4]Report1!AJ21 -> 929.1507 | BQ16: =+[4]Report1!AK21 -> 985.71527 | BR16: 0 | BS16: 0 | BT16: =+[5]Report1!J21 -> 0.77611566 | BU16: =+[5]Report1!K21 -> 0.78822605 | BV16: =+[5]Report1!BG21 -> 0.77611566 | BW16: =+[5]Report1!BH21 -> 0.80967896 | BX16: =+[5]Report1!R21 -> 37.664 | BY16: =+[5]Report1!S21 -> 527.608 | BZ16: =+[5]Report1!X21 -> 99.313287 | CA16: =+[5]Report1!Y21 -> 87.650376 | CB16: =+[5]Report1!AD21 -> 2.3736194 | CC16: =+[5]Report1!AE21 -> 2.1830791 | CD16: =+[5]Report1!AJ21 -> 0 | CE16: =+[5]Report1!AK21 -> 0.12149171 | CF16: =+[5]Report1!AP21 -> 1052.2264 | CG16: =+[5]Report1!AQ21 -> 917.45748 | CH16: =+[5]Report1!AV21 -> 22.236088 | CI16: =+[5]Report1!AW21 -> 310.16226 | CJ16: =+[5]Report1!BB21 -> 0.13275276 | CK16: =+[5]Report1!BC21 -> 6.3827918
... A34: =1+A33 -> 45900 | B34: =+Report1!J39 -> 0.81840226 | C34: =+Report1!K39 -> 0.89986679 | D34: =+Report1!AJ39 -> 0.81840226 | E34: =+Report1!AK39 -> 0.9000777 | F34: =+Report1!R39 -> 48.325 | G34: =+Report1!S39 -> 1865.517 | H34: =+Report1!X39 -> 2.5416244 | I34: =+Report1!Y39 -> 2.2984749 | J34: =+Report1!AD39 -> 1214.9641 | K34: =+Report1!AE39 -> 910.11683 | L34: =+[1]Report1!J39 -> 0.96985461 | M34: =+[1]Report1!K39 -> 0.88665976 | N34: =+[1]Report1!BJ39 -> 0.96985461 | O34: =+[1]Report1!BK39 -> 0.91130228 | P34: =+[1]Report1!R39 -> 73.796 | Q34: =+[1]Report1!S39 -> 1681.041 | R34: =+[1]Report1!AL39 -> 1.8394628 | S34: =+[1]Report1!AM39 -> 2.3611024 | T34: =+[1]Report1!AR39 -> 0.2601767 | U34: =+[1]Report1!AS39 -> 0.085601719 | V34: =+[1]Report1!AX39 -> 434.63345 | W34: =+[1]Report1!AY39 -> 751.4219 | X34: =+[1]Report1!BD39 -> 425.84964 | Y34: =+[1]Report1!BE39 -> 160.39778 | Z34: =+[2]Report1!J39 -> 0.96751082 | AA34: =+[2]Report1!K39 -> 0.90643195 | AB34: =+[2]Report1!BC39 -> 0.96751082 | AC34: =+[2]Report1!BD39 -> 0.90643195 | AD34: =+[2]Report1!R39 -> 43.789 | AE34: =+[2]Report1!S39 -> 1304.522 | AF34: =+[2]Report1!X39 -> 84.332541 | AG34: =+[2]Report1!Y39 -> 93.687913 | AH34: =+[2]Report1!AD39 -> 1.3222499 | AI34: =+[2]Report1!AE39 -> 1.3601917 | AJ34: =+[2]Report1!AJ39 -> 758.02462 | AK34: =+[2]Report1!AK39 -> 867.99488 | AL34: 0 | AM34: 0 | AN34: =+[3]Report1!J39 -> 0.9150774 | AO34: =+[3]Report1!K39 -> 0.89554899 | AP34: =+[3]Report1!BN39 -> 0.9150774 | AQ34: =+[3]Report1!BO39 -> 0.90516623 | AR34: =+[3]Report1!R39 -> 48.391 | AS34: =+[3]Report1!S39 -> 1480.133 | AT34: =+[3]Report1!AF39 -> 104.29079 | AU34: =+[3]Report1!AG39 -> 101.44643 | AV34: =+[3]Report1!AL39 -> 1.5147445 | AW34: =+[3]Report1!AM39 -> 1.4403435 | AX34: =+[3]Report1!AR39 -> 0.194251 | AY34: =+[3]Report1!AS39 -> 0.14586527 | AZ34: =+[3]Report1!AX39 -> 804.14003 | BA34: =+[3]Report1!AY39 -> 849.36179 | BB34: =+[3]Report1!BD39 -> 524.61015 | BC34: =+[3]Report1!BE39 -> 387.77383 | BD34: =+[3]Report1!BJ39 -> 6.6127999 | BE34: =+[3]Report1!BK39 -> 4.1014476 | BF34: =+[4]Report1!J39 -> 0.93663135 | BG34: =+[4]Report1!K39 -> 0.90695193 | BH34: =+[4]Report1!AN39 -> 0.93663135 | BI34: =+[4]Report1!AO39 -> 0.90825057 | BJ34: =+[4]Report1!R39 -> 47.916 | BK34: =+[4]Report1!S39 -> 1465.16 | BL34: =+[4]Report1!AD39 -> 2.9656065 | BM34: =+[4]Report1!AE39 -> 2.8592099 | BN34: 0 | BO34: 0 | BP34: =+[4]Report1!AJ39 -> 1029.8587 | BQ34: =+[4]Report1!AK39 -> 1013.159 | BR34: 0 | BS34: 0 | BT34: =+[5]Report1!J39 -> 0.9631827 | BU34: =+[5]Report1!K39 -> 0.86462303 | BV34: =+[5]Report1!BG39 -> 0.9631827 | BW34: =+[5]Report1!BH39 -> 0.87445113 | BX34: =+[5]Report1!R39 -> 51.353 | BY34: =+[5]Report1!S39 -> 1364.354 | BZ34: =+[5]Report1!X39 -> 71.786006 | CA34: =+[5]Report1!Y39 -> 84.357026 | CB34: =+[5]Report1!AD39 -> 1.8440987 | CC34: =+[5]Report1!AE39 -> 2.0277802 | CD34: =+[5]Report1!AJ39 -> 0.17720484 | CE34: =+[5]Report1!AK39 -> 0.074687361 | CF34: =+[5]Report1!AP39 -> 755.06222 | CG34: =+[5]Report1!AQ39 -> 883.67534 | CH34: =+[5]Report1!AV39 -> 514.52865 | CI34: =+[5]Report1!AW39 -> 193.15194 | CJ34: =+[5]Report1!BB39 -> 0 | CK34: =+[5]Report1!BC39 -> 2.4682832
A36: Desember
A37: November
A38: Oktober
A39: September
A40: Agustus | B40: =+C34 -> 0.89986679 | D40: =+E34 -> 0.9000777 | F40: =+G34 -> 1865.517 | H40: =+I34 -> 2.2984749 | J40: =+K34 -> 910.11683 | L40: =+M34 -> 0.88665976 | N40: =+O34 -> 0.91130228 | P40: =+Q34 -> 1681.041 | R40: =+S34 -> 2.3611024 | T40: =+U34 -> 0.085601719 | V40: =+W34 -> 751.4219 | X40: =+Y34 -> 160.39778 | Z40: =+AA34 -> 0.90643195 | AB40: =+AC34 -> 0.90643195 | AD40: =+AE34 -> 1304.522 | AF40: =+AG34 -> 93.687913 | AH40: =+AI34 -> 1.3601917 | AJ40: =+AK34 -> 867.99488 | AL40: =+AM34 -> 0 | AN40: =+AO34 -> 0.89554899 | AP40: =+AQ34 -> 0.90516623 | AR40: =+AS34 -> 1480.133 | AT40: =+AU34 -> 101.44643 | AV40: =+AW34 -> 1.4403435 | AX40: =+AY34 -> 0.14586527 | AZ40: =+BA34 -> 849.36179 | BB40: =+BC34 -> 387.77383 | BD40: =+BE34 -> 4.1014476 | BF40: =+BG34 -> 0.90695193 | BH40: =+BI34 -> 0.90825057 | BJ40: =+BK34 -> 1465.16 | BL40: =+BM34 -> 2.8592099 | BN40: =+BO34 -> 0 | BP40: =+BQ34 -> 1013.159 | BR40: =+BS34 -> 0 | BT40: =+BU34 -> 0.86462303 | BV40: =+BW34 -> 0.87445113 | BX40: =+BY34 -> 1364.354 | BZ40: =+CA34 -> 84.357026 | CB40: =+CC34 -> 2.0277802 | CD40: =+CE34 -> 0.074687361 | CF40: =+CG34 -> 883.67534 | CH40: =+CI34 -> 193.15194 | CJ40: =+CK34 -> 2.4682832
A41: Juli | B41: =+'[6]eff all'!$B$41:$C$41 -> 0.83939759 | D41: =+'[6]eff all'!$D$41:$E$41 -> 0.84053151 | F41: =+'[6]eff all'!$F$41:$G$41 -> 1669.03 | H41: =+'[6]eff all'!$H$41:$I$41 -> 2.439188 | J41: =+'[6]eff all'!$J$41:$K$41 -> 1033.4659 | L41: =+'[6]eff all'!$L$41:$M$41 -> 0.88164645 | N41: =+'[6]eff all'!$N$41:$O$41 -> 0.90721678 | P41: =+'[6]eff all'!$P$41:$Q$41 -> 1849.253 | R41: =+'[6]eff all'!$R$41:$S$41 -> 2.6039628 | T41: =+'[6]eff all'!$T$41:$U$41 -> 0.22857878 | V41: =+'[6]eff all'!$V$41:$W$41 -> 604.72262 | X41: =+'[6]eff all'!$X$41:$Y$41 -> 521.78582 | Z41: =+'[6]eff all'!$Z$41:$AA$41 -> 0.88193173 | AB41: =+'[6]eff all'!$AB$41:$AC$41 -> 0.88340653 | AD41: =+'[6]eff all'!$AD$41:$AE$41 -> 1253.705 | AF41: =+'[6]eff all'!$AF$41:$AG$41 -> 98.517031 | AH41: =+'[6]eff all'!$AH$41:$AI$41 -> 1.4871122 | AJ41: =+'[6]eff all'!$AJ$41:$AK$41 -> 885.26052 | AL41: =+'[6]eff all'!$AL$41:$AM$41 -> 0 | AN41: =+'[6]eff all'!$AN$41:$AO$41 -> 0.88320077 | AP41: =+'[6]eff all'!$AP$41:$AQ$41 -> 0.8953444 | AR41: =+'[6]eff all'!$AR$41:$AS$41 -> 1406.635 | AT41: =+'[6]eff all'!$AT$41:$AU$41 -> 105.33379 | AV41: =+'[6]eff all'!$AV$41:$AW$41 -> 1.5242049 | AX41: =+'[6]eff all'!$AX$41:$AY$41 -> 0.080760112 | AZ41: =+'[6]eff all'!$AZ$41:$BA$41 -> 927.60065 | BB41: =+'[6]eff all'!$BB$41:$BC$41 -> 240.27392 | BD41: =+'[6]eff all'!$BD$41:$BE$41 -> 16.955358 | BF41: =+'[6]eff all'!$BF$41:$BG$41 -> 0.88101947 | BH41: =+'[6]eff all'!$BH$41:$BI$41 -> 0.8836277 | BJ41: =+'[6]eff all'!$BJ$41:$BK$41 -> 1457.009 | BL41: =+'[6]eff all'!$BL$41:$BM$41 -> 2.7597633 | BN41: =+'[6]eff all'!$BN$41:$BO$41 -> 0 | BP41: =+'[6]eff all'!$BP$41:$BQ$41 -> 932.94369 | BR41: =+'[6]eff all'!$BR$41:$BS$41 -> 0 | BT41: =+'[6]eff all'!$BT$41:$BU$41 -> 0.89958178 | BV41: =+'[6]eff all'!$BV$41:$BW$41 -> 0.90458737 | BX41: =+'[6]eff all'!$BX$41:$BY$41 -> 1385.694 | BZ41: =+'[6]eff all'!$BZ$41:$CA$41 -> 82.805082 | CB41: =+'[6]eff all'!$CB$41:$CC$41 -> 1.975097 | CD41: =+'[6]eff all'!$CD$41:$CE$41 -> 0.056505982 | CF41: =+'[6]eff all'!$CF$41:$CG$41 -> 886.8081 | CH41: =+'[6]eff all'!$CH$41:$CI$41 -> 150.23872 | CJ41: =+'[6]eff all'!$CJ$41:$CK$41 -> 14.750731
A42: Juni | B42: =+'[7]eff all'!$B$42:$C$42 -> 0.89683017 | D42: =+'[7]eff all'!$D$42:$E$42 -> 0.91651255 | F42: =+'[7]eff all'!$F$42:$G$42 -> 1608.12 | H42: =+'[7]eff all'!$H$42:$I$42 -> 2.3160038 | J42: =+'[7]eff all'!$J$42:$K$42 -> 1025.4408 | L42: =+'[7]eff all'!$L$42:$M$42 -> 0.92866755 | N42: =+'[7]eff all'!$N$42:$O$42 -> 0.93793898 | P42: =+'[7]eff all'!$P$42:$Q$42 -> 1827.359 | R42: =+'[7]eff all'!$R$42:$S$42 -> 2.0916447 | T42: =+'[7]eff all'!$T$42:$U$42 -> 0.23153633 | V42: =+'[7]eff all'!$V$42:$W$42 -> 614.27863 | X42: =+'[7]eff all'!$X$42:$Y$42 -> 437.11553 | Z42: =+'[7]eff all'!$Z$42:$AA$42 -> 0.83629624 | AB42: =+'[7]eff all'!$AB$42:$AC$42 -> 0.84011645 | AD42: =+'[7]eff all'!$AD$42:$AE$42 -> 1132.285 | AF42: =+'[7]eff all'!$AF$42:$AG$42 -> 111.282 | AH42: =+'[7]eff all'!$AH$42:$AI$42 -> 1.6594762 | AJ42: =+'[7]eff all'!$AJ$42:$AK$42 -> 964.83334 | AL42: =+'[7]eff all'!$AL$42:$AM$42 -> 0 | AN42: =+'[7]eff all'!$AN$42:$AO$42 -> 0.84149356 | AP42: =+'[7]eff all'!$AP$42:$AQ$42 -> 0.85108231 | AR42: =+'[7]eff all'!$AR$42:$AS$42 -> 1316.344 | AT42: =+'[7]eff all'!$AT$42:$AU$42 -> 121.83944 | AV42: =+'[7]eff all'!$AV$42:$AW$42 -> 1.4904159 | AX42: =+'[7]eff all'!$AX$42:$AY$42 -> 0.19523772 | AZ42: =+'[7]eff all'!$AZ$42:$BA$42 -> 883.634 | BB42: =+'[7]eff all'!$BB$42:$BC$42 -> 521.8822 | BD42: =+'[7]eff all'!$BD$42:$BE$42 -> 0 | BF42: =+'[7]eff all'!$BF$42:$BG$42 -> 0.81559728 | BH42: =+'[7]eff all'!$BH$42:$BI$42 -> 0.82877821 | BJ42: =+'[7]eff all'!$BJ$42:$BK$42 -> 1259.735 | BL42: =+'[7]eff all'!$BL$42:$BM$42 -> 2.8948152 | BN42: =+'[7]eff all'!$BN$42:$BO$42 -> 0 | BP42: =+'[7]eff all'!$BP$42:$BQ$42 -> 971.0194 | BR42: =+'[7]eff all'!$BR$42:$BS$42 -> 0 | BT42: =+'[7]eff all'!$BT$42:$BU$42 -> 0.90927146 | BV42: =+'[7]eff all'!$BV$42:$BW$42 -> 0.93351911 | BX42: =+'[7]eff all'!$BX$42:$BY$42 -> 1433.06 | BZ42: =+'[7]eff all'!$BZ$42:$CA$42 -> 77.094083 | CB42: =+'[7]eff all'!$CB$42:$CC$42 -> 1.8864528 | CD42: =+'[7]eff all'!$CD$42:$CE$42 -> 0.14263185 | CF42: =+'[7]eff all'!$CF$42:$CG$42 -> 754.59782 | CH42: =+'[7]eff all'!$CH$42:$CI$42 -> 384.70371 | CJ42: 0
A43: Mei | B43: =+'[8]eff all'!$B$43:$C$43 -> 0.81728993 | D43: =+'[8]eff all'!$D$43:$E$43 -> 0.81728993 | F43: =+'[8]eff all'!$F$43:$G$43 -> 1753.698 | H43: =+'[8]eff all'!$H$43:$I$43 -> 2.3283627 | J43: =+'[8]eff all'!$J$43:$K$43 -> 919.17355 | L43: =+'[8]eff all'!$L$43:$M$43 -> 0.88541366 | N43: =+'[8]eff all'!$N$43:$O$43 -> 0.92564375 | P43: =+'[8]eff all'!$P$43:$Q$43 -> 1848.366 | R43: =+'[8]eff all'!$R$43:$S$43 -> 2.3081273 | T43: =+'[8]eff all'!$T$43:$U$43 -> 0.22165523 | V43: =+'[8]eff all'!$V$43:$W$43 -> 640.41015 | X43: =+'[8]eff all'!$X$43:$Y$43 -> 434.93518 | Z43: =+'[8]eff all'!$Z$43:$AA$43 -> 0.80335181 | AB43: =+'[8]eff all'!$AB$43:$AC$43 -> 0.86162049 | AD43: =+'[8]eff all'!$AD$43:$AE$43 -> 1130.835 | AF43: =+'[8]eff all'!$AF$43:$AG$43 -> 107.89352 | AH43: =+'[8]eff all'!$AH$43:$AI$43 -> 1.5947508 | AJ43: =+'[8]eff all'!$AJ$43:$AK$43 -> 914.38362 | AL43: =+'[8]eff all'!$AL$43:$AM$43 -> 20.16563 | AN43: =+'[8]eff all'!$AN$43:$AO$43 -> 0.85071019 | AP43: =+'[8]eff all'!$AP$43:$AQ$43 -> 0.85071019 | AR43: =+'[8]eff all'!$AR$43:$AS$43 -> 1375.357 | AT43: =+'[8]eff all'!$AT$43:$AU$43 -> 113.79765 | AV43: =+'[8]eff all'!$AV$43:$AW$43 -> 1.4656558 | AX43: =+'[8]eff all'!$AX$43:$AY$43 -> 0.18613349 | AZ43: =+'[8]eff all'!$AZ$43:$BA$43 -> 878.46065 | BB43: =+'[8]eff all'!$BB$43:$BC$43 -> 550.25946 | BD43: =+'[8]eff all'!$BD$43:$BE$43 -> 0 | BF43: =+'[8]eff all'!$BF$43:$BG$43 -> 0.89363459 | BH43: =+'[8]eff all'!$BH$43:$BI$43 -> 0.89363459 | BJ43: =+'[8]eff all'!$BJ$43:$BK$43 -> 1430.692 | BL43: =+'[8]eff all'!$BL$43:$BM$43 -> 2.6821286 | BN43: =+'[8]eff all'!$BN$43:$BO$43 -> 0 | BP43: =+'[8]eff all'!$BP$43:$BQ$43 -> 974.33569 | BR43: =+'[8]eff all'!$BR$43:$BS$43 -> 0 | BT43: =+'[8]eff all'!$BT$43:$BU$43 -> 0.90863448 | BV43: =+'[8]eff all'!$BV$43:$BW$43 -> 0.9187839 | BX43: =+'[8]eff all'!$BX$43:$BY$43 -> 1460.105 | BZ43: =+'[8]eff all'!$BZ$43:$CA$43 -> 77.669648 | CB43: =+'[8]eff all'!$CB$43:$CC$43 -> 2.0032806 | CD43: =+'[8]eff all'!$CD$43:$CE$43 -> 0.083692611 | CF43: =+'[8]eff all'!$CF$43:$CG$43 -> 840.76602 | CH43: =+'[8]eff all'!$CH$43:$CI$43 -> 246.27503 | CJ43: =+'[8]eff all'!$CJ$43:$CK$43 -> 19.550649
A44: April | B44: =+'[9]eff all'!$B$44:$C$44 -> 0.8512863 | D44: =+'[9]eff all'!$D$44:$E$44 -> 0.88261389 | F44: =+'[9]eff all'!$F$44:$G$44 -> 1626.863 | H44: =+'[9]eff all'!$H$44:$I$44 -> 2.4992418 | J44: =+'[9]eff all'!$J$44:$K$44 -> 943.70529 | L44: =+'[9]eff all'!$L$44:$M$44 -> 0.91684997 | N44: =+'[9]eff all'!$N$44:$O$44 -> 0.94547697 | P44: =+'[9]eff all'!$P$44:$Q$44 -> 1788.166 | R44: =+'[9]eff all'!$R$44:$S$44 -> 2.1331811 | T44: =+'[9]eff all'!$T$44:$U$44 -> 0.2123125 | V44: =+'[9]eff all'!$V$44:$W$44 -> 722.25094 | X44: =+'[9]eff all'!$X$44:$Y$44 -> 464.24761 | Z44: =+'[9]eff all'!$Z$44:$AA$44 -> 0.8620695 | AB44: =+'[9]eff all'!$AB$44:$AC$44 -> 0.90942581 | AD44: =+'[9]eff all'!$AD$44:$AE$44 -> 1188.791 | AF44: =+'[9]eff all'!$AF$44:$AG$44 -> 106.25948 | AH44: =+'[9]eff all'!$AH$44:$AI$44 -> 1.5097692 | AJ44: =+'[9]eff all'!$AJ$44:$AK$44 -> 921.84495 | AL44: =+'[9]eff all'!$AL$44:$AM$44 -> 7.553893 | AN44: =+'[9]eff all'!$AN$44:$AO$44 -> 0.9113018 | AP44: =+'[9]eff all'!$AP$44:$AQ$44 -> 0.94321744 | AR44: =+'[9]eff all'!$AR$44:$AS$44 -> 1441.538 | AT44: =+'[9]eff all'!$AT$44:$AU$44 -> 98.381361 | AV44: =+'[9]eff all'!$AV$44:$AW$44 -> 1.4245896 | AX44: =+'[9]eff all'!$AX$44:$AY$44 -> 0.063755313 | AZ44: =+'[9]eff all'!$AZ$44:$BA$44 -> 884.49349 | BB44: =+'[9]eff all'!$BB$44:$BC$44 -> 178.97537 | BD44: =+'[9]eff all'!$BD$44:$BE$44 -> 0 | BF44: =+'[9]eff all'!$BF$44:$BG$44 -> 0.83968008 | BH44: =+'[9]eff all'!$BH$44:$BI$44 -> 0.88025535 | BJ44: =+'[9]eff all'!$BJ$44:$BK$44 -> 1283.722 | BL44: =+'[9]eff all'!$BL$44:$BM$44 -> 2.9010175 | BN44: =+'[9]eff all'!$BN$44:$BO$44 -> 0 | BP44: =+'[9]eff all'!$BP$44:$BQ$44 -> 1018.1901 | BR44: =+'[9]eff all'!$BR$44:$BS$44 -> 0 | BT44: =+'[9]eff all'!$BT$44:$BU$44 -> 0.86479672 | BV44: =+'[9]eff all'!$BV$44:$BW$44 -> 0.91368892 | BX44: =+'[9]eff all'!$BX$44:$BY$44 -> 1364.988 | BZ44: =+'[9]eff all'!$BZ$44:$CA$44 -> 71.774412 | CB44: =+'[9]eff all'!$CB$44:$CC$44 -> 1.9880761 | CD44: =+'[9]eff all'!$CD$44:$CE$44 -> 0.17403816 | CF44: =+'[9]eff all'!$CF$44:$CG$44 -> 844.20452 | CH44: =+'[9]eff all'!$CH$44:$CI$44 -> 469.40955 | CJ44: =+'[9]eff all'!$CJ$44:$CK$44 -> 0
A45: Maret | B45: =+'[10]eff all'!$B$45:$C$45 -> 0.84979165 | D45: =+'[10]eff all'!$D$45:$E$45 -> 0.85889247 | F45: =+'[10]eff all'!$F$45:$G$45 -> 1534.469 | H45: =+'[10]eff all'!$H$45:$I$45 -> 2.430719 | J45: =+'[10]eff all'!$J$45:$K$45 -> 1009.2877 | L45: =+'[10]eff all'!$L$45:$M$45 -> 0.85741706 | N45: =+'[10]eff all'!$N$45:$O$45 -> 0.89481521 | P45: =+'[10]eff all'!$P$45:$Q$45 -> 1704.768 | R45: =+'[10]eff all'!$R$45:$S$45 -> 2.4058077 | T45: =+'[10]eff all'!$T$45:$U$45 -> 0.14817265 | V45: =+'[10]eff all'!$V$45:$W$45 -> 708.7489 | X45: =+'[10]eff all'!$X$45:$Y$45 -> 419.01831 | Z45: =+'[10]eff all'!$Z$45:$AA$45 -> 0.87132155 | AB45: =+'[10]eff all'!$AB$45:$AC$45 -> 0.87132155 | AD45: =+'[10]eff all'!$AD$45:$AE$45 -> 1204.645 | AF45: =+'[10]eff all'!$AF$45:$AG$45 -> 105.43836 | AH45: =+'[10]eff all'!$AH$45:$AI$45 -> 1.5603767 | AJ45: =+'[10]eff all'!$AJ$45:$AK$45 -> 928.04959 | AL45: =+'[10]eff all'!$AL$45:$AM$45 -> 0 | AN45: =+'[10]eff all'!$AN$45:$AO$45 -> 0.47758007 | AP45: =+'[10]eff all'!$AP$45:$AQ$45 -> 0.86385626 | AR45: =+'[10]eff all'!$AR$45:$AS$45 -> 764.21 | AT45: =+'[10]eff all'!$AT$45:$AU$45 -> 117.91594 | AV45: =+'[10]eff all'!$AV$45:$AW$45 -> 1.737088 | AX45: =+'[10]eff all'!$AX$45:$AY$45 -> 0 | AZ45: =+'[10]eff all'!$AZ$45:$BA$45 -> 1171.1575 | BB45: =+'[10]eff all'!$BB$45:$BC$45 -> 0 | BD45: =+'[10]eff all'!$BD$45:$BE$45 -> 23.422881 | BF45: =+'[10]eff all'!$BF$45:$BG$45 -> 0.79411424 | BH45: =+'[10]eff all'!$BH$45:$BI$45 -> 0.80751482 | BJ45: =+'[10]eff all'!$BJ$45:$BK$45 -> 1316.452 | BL45: =+'[10]eff all'!$BL$45:$BM$45 -> 2.6146035 | BN45: =+'[10]eff all'!$BN$45:$BO$45 -> 0 | BP45: =+'[10]eff all'!$BP$45:$BQ$45 -> 1083.3644 | BR45: =+'[10]eff all'!$BR$45:$BS$45 -> 0 | BT45: =+'[10]eff all'!$BT$45:$BU$45 -> 0.7921511 | BV45: =+'[10]eff all'!$BV$45:$BW$45 -> 0.80246911 | BX45: =+'[10]eff all'!$BX$45:$BY$45 -> 1219.024 | BZ45: =+'[10]eff all'!$BZ$45:$CA$45 -> 89.967609 | CB45: =+'[10]eff all'!$CB$45:$CC$45 -> 2.2528679 | CD45: =+'[10]eff all'!$CD$45:$CE$45 -> 0 | CF45: =+'[10]eff all'!$CF$45:$CG$45 -> 1093.3749 | CH45: =+'[10]eff all'!$CH$45:$CI$45 -> 0 | CJ45: =+'[10]eff all'!$CJ$45:$CK$45 -> 3.7653073
