Workbook

Sheet eff all
A1: DATE | B1: PM 11 | L1: PM 12 | Z1: PM 14 | AN1: PM 15 | BF1: PM 16 | BT1: PM 17
B2: Eff Avaliable | D2: Eff Running | F2: PHP (ton) | H2: STEAM/Ton FG | J2: ELECTRIC/ton FG | L2: Eff Avaliable | N2: Eff Running | P2: PHP (ton) | R2: STEAM/ton FG | T2: STEAM DIP/ton FG | V2: ELECTRIC/ton FG | X2: ELECTRIC DIP/ton FG | Z2: Eff Avaliable | AB2: Eff Running | AD2: PHP (ton) | AF2: GAS /ton FG | AH2: STEAM /ton FG | AJ2: ELECTRIC /ton FG | AL2: Electric WPL /ton FG | AN2: Eff Avaliable | AP2: Eff Running | AR2: PHP (ton) | AT2: GAS /ton FG | AV2: STEAM /ton FG | AX2: STEAM DIP /ton FG | AZ2: ELECTRIC /ton FG | BB2: ELECTRIC DIP /ton FG | BD2: Electric WPL /ton FG | BF2: Eff Avaliable | BH2: Eff Running | BJ2: PHP (ton) | BL2: STEAM /ton FG | BN2: STEAM DIP/ton FG | BP2: ELECTRIC /ton FG | BR2: ELECTRIC DIP/ton FG | BT2: Eff Avaliable | BV2: Eff Running | BX2: PHP (ton) | BZ2: GAS /ton FG | CB2: STEAM /ton FG | CD2: STEAM DIP /ton FG | CF2: ELECTRIC /ton FG | CH2: ELECTRIC DIP /ton FG | CJ2: ELECTRIC WPL /ton FG
B3: Today | C3: Todate | D3: Today | E3: Todate | F3: Today | G3: Todate | H3: Today | I3: Todate | J3: Today | K3: Todate | L3: Today | M3: Todate | N3: Today | O3: Todate | P3: Today | Q3: Todate | R3: Today | S3: Todate | T3: Today | U3: Todate | V3: Today | W3: Todate | X3: Today | Y3: Todate | Z3: Today | AA3: Todate | AB3: Today | AC3: Todate | AD3: Today | AE3: Todate | AF3: Today | AG3: Todate | AH3: Today | AI3: Todate | AJ3: Today | AK3: Todate | AL3: Today | AM3: Todate | AN3: Today | AO3: Todate | AP3: Today | AQ3: Todate | AR3: Today | AS3: Todate | AT3: Today | AU3: Todate | AV3: Today | AW3: Todate | AX3: Today | AY3: Todate | AZ3: Today | BA3: Todate | BB3: Today | BC3: Todate | BD3: Today | BE3: Todate | BF3: Today | BG3: Todate | BH3: Today | BI3: Todate | BJ3: Today | BK3: Todate | BL3: Today | BM3: Todate | BN3: Today | BO3: Todate | BP3: Today | BQ3: Todate | BR3: Today | BS3: Todate | BT3: Today | BU3: Todate | BV3: Today | BW3: Todate | BX3: Today | BY3: Todate | BZ3: Today | CA3: Todate | CB3: Today | CC3: Todate | CD3: Today | CE3: Todate | CF3: Today | CG3: Todate | CH3: Today | CI3: Todate | CJ3: Today | CK3: Todate
A4: =+Report1!A9 -> 45992 | B4: =+Report1!J9 -> 0.57448452 | C4: =+Report1!K9 -> 0.57448452 | D4: =+Report1!AJ9 -> 0.57448452 | E4: =+Report1!AK9 -> 0.57448452 | F4: =+Report1!R9 -> 41.514 | G4: =+Report1!S9 -> 41.514 | H4: =+Report1!X9 -> 3.3730067 | I4: =+Report1!Y9 -> 3.3730067 | J4: =+Report1!AD9 -> 1260.9399 | K4: =+Report1!AE9 -> 1260.9399 | L4: =+[1]Report1!J9 -> 0.90824861 | M4: =+[1]Report1!K9 -> 0.90824861 | N4: =+[1]Report1!BJ9 -> 0.90824861 | O4: =+[1]Report1!BK9 -> 0.90824861 | P4: =+[1]Report1!R9 -> 60.009 | Q4: =+[1]Report1!S9 -> 60.009 | R4: =+[1]Report1!AL9 -> 1.6696329 | S4: =+[1]Report1!AM9 -> 1.6696329 | T4: =+[1]Report1!AR9 -> 0.31995201 | U4: =+[1]Report1!AS9 -> 0.31995201 | V4: =+[1]Report1!AX9 -> 552.30199 | W4: =+[1]Report1!AY9 -> 552.30199 | X4: =+[1]Report1!BD9 -> 494.04256 | Y4: =+[1]Report1!BE9 -> 494.04256 | Z4: =+[2]Report1!J9 -> 0.51059755 | AA4: =+[2]Report1!K9 -> 0.51059755 | AB4: =+[2]Report1!BC9 -> 0.51059755 | AC4: =+[2]Report1!BD9 -> 0.51059755 | AD4: =+[2]Report1!R9 -> 23.289 | AE4: =+[2]Report1!S9 -> 23.289 | AF4: =+[2]Report1!X9 -> 127.95504 | AG4: =+[2]Report1!Y9 -> 127.95504 | AH4: =+[2]Report1!AD9 -> 1.5329125 | AI4: =+[2]Report1!AE9 -> 1.5329125 | AJ4: =+[2]Report1!AJ9 -> 1603.618 | AK4: =+[2]Report1!AK9 -> 1603.618 | AN4: =+[3]Report1!J9 -> 0.70699367 | AO4: =+[3]Report1!K9 -> 0.70699367 | AP4: =+[3]Report1!BN9 -> 0.70699367 | AQ4: =+[3]Report1!BO9 -> 0.70699367 | AR4: =+[3]Report1!R9 -> 38.92 | AS4: =+[3]Report1!S9 -> 38.92 | AT4: =+[3]Report1!AF9 -> 117.41015 | AU4: =+[3]Report1!AG9 -> 117.41015 | AV4: =+[3]Report1!AL9 -> 1.5647482 | AW4: =+[3]Report1!AM9 -> 1.5647482 | AX4: =+[3]Report1!AR9 -> 0.22353546 | AY4: =+[3]Report1!AS9 -> 0.22353546 | AZ4: =+[3]Report1!AX9 -> 1160.5 | BA4: =+[3]Report1!AY9 -> 1160.5 | BB4: =+[3]Report1!BD9 -> 563.78484 | BC4: =+[3]Report1!BE9 -> 563.78484 | BD4: =+[3]Report1!BJ9 -> 8.532888 | BE4: =+[3]Report1!BK9 -> 8.532888 | BF4: =+[4]Report1!J9 -> 1.0202573 | BG4: =+[4]Report1!K9 -> 1.0202573 | BH4: =+[4]Report1!AN9 -> 1.0202573 | BI4: =+[4]Report1!AO9 -> 1.0202573 | BJ4: =+[4]Report1!R9 -> 54.765 | BK4: =+[4]Report1!S9 -> 54.765 | BL4: =+[4]Report1!AD9 -> 2.3080435 | BM4: =+[4]Report1!AE9 -> 2.3080435 | BN4: 0 | BO4: 0 | BP4: =+[4]Report1!AJ9 -> 606.06884 | BQ4: =+[4]Report1!AK9 -> 606.06884 | BR4: 0 | BS4: 0 | BT4: =+[5]Report1!J9 -> 0.72471446 | BU4: =+[5]Report1!K9 -> 0.72471446 | BV4: =+[5]Report1!BA9 -> 0.74003978 | BW4: =+[5]Report1!BB9 -> 0.74003978 | BX4: =+[5]Report1!R9 -> 40.387 | BY4: =+[5]Report1!S9 -> 40.387 | BZ4: =+[5]Report1!X9 -> 98.062547 | CA4: =+[5]Report1!Y9 -> 98.062547 | CB4: =+[5]Report1!AD9 -> 2.4017629 | CC4: =+[5]Report1!AE9 -> 2.4017629 | CD4: =+[5]Report1!AJ9 -> 0.25503256 | CE4: =+[5]Report1!AK9 -> 0.25503256 | CF4: =+[5]Report1!AP9 -> 1147.283 | CG4: =+[5]Report1!AQ9 -> 1147.283 | CH4: =+[5]Report1!AV9 -> 637.79419 | CI4: =+[5]Report1!AW9 -> 637.79419
A5: =1+A4 -> 45993 | B5: =+Report1!J10 -> 0.55551258 | C5: =+Report1!K10 -> 0.56446973 | D5: =+Report1!AJ10 -> 0.55551258 | E5: =+Report1!AK10 -> 0.56446973 | F5: =+Report1!R10 -> 44.883 | G5: =+Report1!S10 -> 86.397 | H5: =+Report1!X10 -> 3.0830381 | I5: =+Report1!Y10 -> 3.2223688 | J5: =+Report1!AD10 -> 636.67536 | K5: =+Report1!AE10 -> 936.63623 | L5: =+[1]Report1!J10 -> 0.65938128 | M5: =+[1]Report1!K10 -> 0.78260306 | N5: =+[1]Report1!BJ10 -> 0.65938128 | O5: =+[1]Report1!BK10 -> 0.78260306 | P5: =+[1]Report1!R10 -> 44.423 | Q5: =+[1]Report1!S10 -> 104.432 | R5: =+[1]Report1!AL10 -> 2.7579182 | S5: =+[1]Report1!AM10 -> 2.1325647 | T5: =+[1]Report1!AR10 -> 0.37818247 | U5: =+[1]Report1!AS10 -> 0.34472192 | V5: =+[1]Report1!AX10 -> 693.06103 | W5: =+[1]Report1!AY10 -> 612.17769 | X5: =+[1]Report1!BD10 -> 406.50114 | Y5: =+[1]Report1!BE10 -> 456.80443 | Z5: =+[2]Report1!J10 -> 0.91595944 | AA5: =+[2]Report1!K10 -> 0.71466356 | AB5: =+[2]Report1!BC10 -> 0.91595944 | AC5: =+[2]Report1!BD10 -> 0.71466356 | AD5: =+[2]Report1!R10 -> 42.353 | AE5: =+[2]Report1!S10 -> 65.642 | AF5: =+[2]Report1!X10 -> 108.84738 | AG5: =+[2]Report1!Y10 -> 115.62655 | AH5: =+[2]Report1!AD10 -> 1.2844427 | AI5: =+[2]Report1!AE10 -> 1.3725968 | AJ5: =+[2]Report1!AJ10 -> 796.06876 | AK5: =+[2]Report1!AK10 -> 1082.5776 | AN5: =+[3]Report1!J10 -> 0.93591974 | AO5: =+[3]Report1!K10 -> 0.82098895 | AP5: =+[3]Report1!BN10 -> 0.93591974 | AQ5: =+[3]Report1!BO10 -> 0.82098895 | AR5: =+[3]Report1!R10 -> 51.103 | AS5: =+[3]Report1!S10 -> 90.023 | AT5: =+[3]Report1!AF10 -> 102.26877 | AU5: =+[3]Report1!AG10 -> 108.8149 | AV5: =+[3]Report1!AL10 -> 1.3619553 | AW5: =+[3]Report1!AM10 -> 1.4496295 | AX5: =+[3]Report1!AR10 -> 0.17415807 | AY5: =+[3]Report1!AS10 -> 0.19550559 | AZ5: =+[3]Report1!AX10 -> 875.40653 | BA5: =+[3]Report1!AY10 -> 998.66212 | BB5: =+[3]Report1!BD10 -> 479.97979 | BC5: =+[3]Report1!BE10 -> 516.21156 | BD5: =+[3]Report1!BJ10 -> 6.2755611 | BE5: =+[3]Report1!BK10 -> 7.2514802 | BF5: =+[4]Report1!J10 -> 0.98022825 | BG5: =+[4]Report1!K10 -> 1.0001501 | BH5: =+[4]Report1!AN10 -> 0.98022825 | BI5: =+[4]Report1!AO10 -> 1.0001501 | BJ5: =+[4]Report1!R10 -> 53.106 | BK5: =+[4]Report1!S10 -> 107.871 | BL5: =+[4]Report1!AD10 -> 2.4196889 | BM5: =+[4]Report1!AE10 -> 2.3630077 | BN5: 0 | BO5: 0 | BP5: =+[4]Report1!AJ10 -> 615.2205 | BQ5: =+[4]Report1!AK10 -> 610.5743 | BR5: 0 | BS5: 0 | BT5: =+[5]Report1!J10 -> 0.96817879 | BU5: =+[5]Report1!K10 -> 0.84594844 | BV5: =+[5]Report1!BA10 -> 0.96817879 | BW5: =+[5]Report1!BB10 -> 0.85483597 | BX5: =+[5]Report1!R10 -> 53.515 | BY5: =+[5]Report1!S10 -> 93.902 | BZ5: =+[5]Report1!X10 -> 67.322171 | CA5: =+[5]Report1!Y10 -> 80.543525 | CB5: =+[5]Report1!AD10 -> 1.7938896 | CC5: =+[5]Report1!AE10 -> 2.0553343 | CD5: =+[5]Report1!AJ10 -> 0.1868635 | CE5: =+[5]Report1!AK10 -> 0.21618283 | CF5: =+[5]Report1!AP10 -> 827.35308 | CG5: =+[5]Report1!AQ10 -> 964.9541 | CH5: =+[5]Report1!AV10 -> 516.85869 | CI5: =+[5]Report1!AW10 -> 568.87273
A6: =1+A5 -> 45994 | B6: =+Report1!J11 -> 0.29165502 | C6: =+Report1!K11 -> 0.46912956 | D6: =+Report1!AJ11 -> 0.29165502 | E6: =+Report1!AK11 -> 0.46912956 | F6: =+Report1!R11 -> 23.981 | G6: =+Report1!S11 -> 110.378 | H6: =+Report1!X11 -> 2.8229015 | I6: =+Report1!Y11 -> 3.1355796 | J6: =+Report1!AD11 -> 2492.1897 | K6: =+Report1!AE11 -> 1274.5996 | L6: =+[1]Report1!J11 -> 0.73430615 | M6: =+[1]Report1!K11 -> 0.76632515 | N6: =+[1]Report1!BJ11 -> 0.89610242 | O6: =+[1]Report1!BK11 -> 0.81598097 | P6: =+[1]Report1!R11 -> 49.815 | Q6: =+[1]Report1!S11 -> 154.247 | R6: =+[1]Report1!AL11 -> 2.1755495 | S6: =+[1]Report1!AM11 -> 2.1464469 | T6: =+[1]Report1!AR11 -> 0.19672789 | U6: =+[1]Report1!AS11 -> 0.29692636 | V6: =+[1]Report1!AX11 -> 193.14383 | W6: =+[1]Report1!AY11 -> 476.84817 | X6: =+[1]Report1!BD11 -> 10.217806 | Y6: =+[1]Report1!BE11 -> 312.57658 | Z6: =+[2]Report1!J11 -> 0.9163842 | AA6: =+[2]Report1!K11 -> 0.7817886 | AB6: =+[2]Report1!BC11 -> 0.9163842 | AC6: =+[2]Report1!BD11 -> 0.7817886 | AD6: =+[2]Report1!R11 -> 41.977 | AE6: =+[2]Report1!S11 -> 107.619 | AF6: =+[2]Report1!X11 -> 115.8244 | AG6: =+[2]Report1!Y11 -> 115.70372 | AH6: =+[2]Report1!AD11 -> 1.2530672 | AI6: =+[2]Report1!AE11 -> 1.325974 | AJ6: =+[2]Report1!AJ11 -> 967.40691 | AK6: =+[2]Report1!AK11 -> 1037.6551 | AN6: =+[3]Report1!J11 -> 0.93162214 | AO6: =+[3]Report1!K11 -> 0.85710952 | AP6: =+[3]Report1!BN11 -> 0.93162214 | AQ6: =+[3]Report1!BO11 -> 0.85710952 | AR6: =+[3]Report1!R11 -> 49.52 | AS6: =+[3]Report1!S11 -> 139.543 | AT6: =+[3]Report1!AF11 -> 106.79286 | AU6: =+[3]Report1!AG11 -> 108.09733 | AV6: =+[3]Report1!AL11 -> 1.4297254 | AW6: =+[3]Report1!AM11 -> 1.4425661 | AX6: =+[3]Report1!AR11 -> 0.21203554 | AY6: =+[3]Report1!AS11 -> 0.20137162 | AZ6: =+[3]Report1!AX11 -> 954.94426 | BA6: =+[3]Report1!AY11 -> 983.14785 | BB6: =+[3]Report1!BD11 -> 490.3958 | BC6: =+[3]Report1!BE11 -> 507.05025 | BD6: =+[3]Report1!BJ11 -> 5.8582391 | BE6: =+[3]Report1!BK11 -> 6.757057 | BF6: =+[4]Report1!J11 -> 1.0538755 | BG6: =+[4]Report1!K11 -> 1.0181138 | BH6: =+[4]Report1!AN11 -> 1.0538755 | BI6: =+[4]Report1!AO11 -> 1.0181138 | BJ6: =+[4]Report1!R11 -> 57.096 | BK6: =+[4]Report1!S11 -> 164.967 | BL6: =+[4]Report1!AD11 -> 2.2523469 | BM6: =+[4]Report1!AE11 -> 2.3247074 | BN6: 0 | BO6: 0 | BP6: =+[4]Report1!AJ11 -> 601.07258 | BQ6: =+[4]Report1!AK11 -> 607.2857 | BR6: 0 | BS6: 0 | BT6: =+[5]Report1!J11 -> 0.97062118 | BU6: =+[5]Report1!K11 -> 0.88739248 | BV6: =+[5]Report1!BA11 -> 0.97062118 | BW6: =+[5]Report1!BB11 -> 0.8935946 | BX6: =+[5]Report1!R11 -> 53.65 | BY6: =+[5]Report1!S11 -> 147.552 | BZ6: =+[5]Report1!X11 -> 66.442816 | CA6: =+[5]Report1!Y11 -> 75.416498 | CB6: =+[5]Report1!AD11 -> 1.7651445 | CC6: =+[5]Report1!AE11 -> 1.9498211 | CD6: =+[5]Report1!AJ11 -> 0.20689655 | CE6: =+[5]Report1!AK11 -> 0.21280633 | CF6: =+[5]Report1!AP11 -> 961.00056 | CG6: =+[5]Report1!AQ11 -> 963.51659 | CH6: =+[5]Report1!AV11 -> 471.12022 | CI6: =+[5]Report1!AW11 -> 533.32986
A7: =1+A6 -> 45995 | B7: =+Report1!J12 -> 0.90880857 | C7: =+Report1!K12 -> 0.57830322 | D7: =+Report1!AJ12 -> 0.90880857 | E7: =+Report1!AK12 -> 0.57830322 | F7: =+Report1!R12 -> 70.632 | G7: =+Report1!S12 -> 181.01 | H7: =+Report1!X12 -> 2.1512629 | I7: =+Report1!Y12 -> 2.7514889 | J7: =+Report1!AD12 -> 693.66803 | K7: =+Report1!AE12 -> 1047.914 | L7: =+[1]Report1!J12 -> 0 | M7: =+[1]Report1!K12 -> 0.57315121 | N7: =+[1]Report1!BJ12 -> 0 | O7: =+[1]Report1!BK12 -> 0.76632515 | P7: =+[1]Report1!R12 -> 0 | Q7: =+[1]Report1!S12 -> 154.247 | R7: =+[1]Report1!AL12 -> 0 | S7: =+[1]Report1!AM12 -> 2.1865385 | T7: =+[1]Report1!AR12 -> 0 | U7: =+[1]Report1!AS12 -> 0.29692636 | V7: =+[1]Report1!AX12 -> 0 | W7: =+[1]Report1!AY12 -> 629.63675 | X7: =+[1]Report1!BD12 -> 0 | Y7: =+[1]Report1!BE12 -> 319.51351 | Z7: =+[2]Report1!J12 -> 0.89503757 | AA7: =+[2]Report1!K12 -> 0.80962902 | AB7: =+[2]Report1!BC12 -> 0.89503757 | AC7: =+[2]Report1!BD12 -> 0.80962902 | AD7: =+[2]Report1!R12 -> 40.162 | AE7: =+[2]Report1!S12 -> 147.781 | AF7: =+[2]Report1!X12 -> 120.04289 | AG7: =+[2]Report1!Y12 -> 116.88296 | AH7: =+[2]Report1!AD12 -> 1.2897764 | AI7: =+[2]Report1!AE12 -> 1.3161367 | AJ7: =+[2]Report1!AJ12 -> 810.00747 | AK7: =+[2]Report1!AK12 -> 975.78796 | AN7: =+[3]Report1!J12 -> 0.93469721 | AO7: =+[3]Report1!K12 -> 0.87642288 | AP7: =+[3]Report1!BN12 -> 0.93469721 | AQ7: =+[3]Report1!BO12 -> 0.87642288 | AR7: =+[3]Report1!R12 -> 50.434 | AS7: =+[3]Report1!S12 -> 189.977 | AT7: =+[3]Report1!AF12 -> 102.42855 | AU7: =+[3]Report1!AG12 -> 106.59242 | AV7: =+[3]Report1!AL12 -> 1.3324345 | AW7: =+[3]Report1!AM12 -> 1.413329 | AX7: =+[3]Report1!AR12 -> 0.19629615 | AY7: =+[3]Report1!AS12 -> 0.20002421 | AZ7: =+[3]Report1!AX12 -> 838.15521 | BA7: =+[3]Report1!AY12 -> 944.65604 | BB7: =+[3]Report1!BD12 -> 448.90352 | BC7: =+[3]Report1!BE12 -> 491.61379 | BD7: =+[3]Report1!BJ12 -> 2.7778879 | BE7: =+[3]Report1!BK12 -> 5.7006901 | BF7: =+[4]Report1!J12 -> 0.75773604 | BG7: =+[4]Report1!K12 -> 0.95286894 | BH7: =+[4]Report1!AN12 -> 0.75773604 | BI7: =+[4]Report1!AO12 -> 0.95286894 | BJ7: =+[4]Report1!R12 -> 41.052 | BK7: =+[4]Report1!S12 -> 206.019 | BL7: =+[4]Report1!AD12 -> 2.9426094 | BM7: =+[4]Report1!AE12 -> 2.4478325 | BN7: 0 | BO7: 0 | BP7: =+[4]Report1!AJ12 -> 711.33002 | BQ7: =+[4]Report1!AK12 -> 628.0179 | BR7: 0 | BS7: 0 | BT7: =+[5]Report1!J12 -> 0.90945141 | BU7: =+[5]Report1!K12 -> 0.89290363 | BV7: =+[5]Report1!BA12 -> 0.99213613 | BW7: =+[5]Report1!BB12 -> 0.9167653 | BX7: =+[5]Report1!R12 -> 50.363 | BY7: =+[5]Report1!S12 -> 197.915 | BZ7: =+[5]Report1!X12 -> 69.990978 | CA7: =+[5]Report1!Y12 -> 74.035878 | CB7: =+[5]Report1!AD12 -> 1.8624784 | CC7: =+[5]Report1!AE12 -> 1.9275952 | CD7: =+[5]Report1!AJ12 -> 0.19657288 | CE7: =+[5]Report1!AK12 -> 0.20867544 | CF7: =+[5]Report1!AP12 -> 492.08824 | CG7: =+[5]Report1!AQ12 -> 843.55324 | CH7: =+[5]Report1!AV12 -> 449.53637 | CI7: =+[5]Report1!AW12 -> 512.00711
A8: =1+A7 -> 45996 | B8: =+Report1!J13 -> 0.96078195 | C8: =+Report1!K13 -> 0.65573572 | D8: =+Report1!AJ13 -> 0.96078195 | E8: =+Report1!AK13 -> 0.65573572 | F8: =+Report1!R13 -> 76.336 | G8: =+Report1!S13 -> 257.346 | H8: =+Report1!X13 -> 1.4329543 | I8: =+Report1!Y13 -> 2.3603747 | J8: =+Report1!AD13 -> 731.94587 | K8: =+Report1!AE13 -> 954.18907 | L8: =+[1]Report1!J13 -> 0.60005298 | M8: =+[1]Report1!K13 -> 0.57775515 | N8: =+[1]Report1!BJ13 -> 0.60005298 | O8: =+[1]Report1!BK13 -> 0.73035368 | P8: =+[1]Report1!R13 -> 33.343 | Q8: =+[1]Report1!S13 -> 187.59 | R8: =+[1]Report1!AL13 -> 3.2806286 | S8: =+[1]Report1!AM13 -> 2.3810065 | T8: =+[1]Report1!AR13 -> 0.22493477 | U8: =+[1]Report1!AS13 -> 0.28413028 | V8: =+[1]Report1!AX13 -> 951.84087 | W8: =+[1]Report1!AY13 -> 686.9066 | X8: =+[1]Report1!BD13 -> 641.25903 | Y8: =+[1]Report1!BE13 -> 376.70185 | Z8: =+[2]Report1!J13 -> 1.0347328 | AA8: =+[2]Report1!K13 -> 0.85309468 | AB8: =+[2]Report1!BC13 -> 1.0347328 | AC8: =+[2]Report1!BD13 -> 0.85309468 | AD8: =+[2]Report1!R13 -> 45.196 | AE8: =+[2]Report1!S13 -> 192.977 | AF8: =+[2]Report1!X13 -> 105.77035 | AG8: =+[2]Report1!Y13 -> 114.28034 | AH8: =+[2]Report1!AD13 -> 1.2036463 | AI8: =+[2]Report1!AE13 -> 1.289791 | AJ8: =+[2]Report1!AJ13 -> 759.44376 | AK8: =+[2]Report1!AK13 -> 925.11926 | AN8: =+[3]Report1!J13 -> 0.95856381 | AO8: =+[3]Report1!K13 -> 0.89293709 | AP8: =+[3]Report1!BN13 -> 0.95856381 | AQ8: =+[3]Report1!BO13 -> 0.89293709 | AR8: =+[3]Report1!R13 -> 52.286 | AS8: =+[3]Report1!S13 -> 242.263 | AT8: =+[3]Report1!AF13 -> 103.63266 | AU8: =+[3]Report1!AG13 -> 105.95363 | AV8: =+[3]Report1!AL13 -> 1.3043645 | AW8: =+[3]Report1!AM13 -> 1.3898119 | AX8: =+[3]Report1!AR13 -> 0.17595532 | AY8: =+[3]Report1!AS13 -> 0.19482959 | AZ8: =+[3]Report1!AX13 -> 847.52745 | BA8: =+[3]Report1!AY13 -> 923.69342 | BB8: =+[3]Report1!BD13 -> 469.88678 | BC8: =+[3]Report1!BE13 -> 486.92459 | BD8: =+[3]Report1!BJ13 -> 2.8650117 | BE8: =+[3]Report1!BK13 -> 5.0886846 | BF8: =+[4]Report1!J13 -> 0.95252474 | BG8: =+[4]Report1!K13 -> 0.95279941 | BH8: =+[4]Report1!AN13 -> 0.95252474 | BI8: =+[4]Report1!AO13 -> 0.95279941 | BJ8: =+[4]Report1!R13 -> 52.134 | BK8: =+[4]Report1!S13 -> 258.153 | BL8: =+[4]Report1!AD13 -> 2.4993287 | BM8: =+[4]Report1!AE13 -> 2.4582321 | BN8: 0 | BO8: 0 | BP8: =+[4]Report1!AJ13 -> 697.69862 | BQ8: =+[4]Report1!AK13 -> 642.08992 | BR8: 0 | BS8: 0 | BT8: =+[5]Report1!J13 -> 0.14079745 | BU8: =+[5]Report1!K13 -> 0.74584891 | BV8: =+[5]Report1!BA13 -> 0.18772994 | BW8: =+[5]Report1!BB13 -> 0.80183285 | BX8: =+[5]Report1!R13 -> 7.585 | BY8: =+[5]Report1!S13 -> 205.5 | BZ8: =+[5]Report1!X13 -> 224.39893 | CA8: =+[5]Report1!Y13 -> 79.585775 | CB8: =+[5]Report1!AD13 -> 5.4845089 | CC8: =+[5]Report1!AE13 -> 2.0588808 | CD8: =+[5]Report1!AJ13 -> 0 | CE8: =+[5]Report1!AK13 -> 0.20097324 | CF8: =+[5]Report1!AP13 -> 7136.1424 | CG8: =+[5]Report1!AQ13 -> 1075.8126 | CH8: =+[5]Report1!AV13 -> 0 | CI8: =+[5]Report1!AW13 -> 493.10894
A9: =1+A8 -> 45997 | B9: =+Report1!J14 -> 1.0548482 | C9: =+Report1!K14 -> 0.71494296 | D9: =+Report1!AJ14 -> 1.0548482 | E9: =+Report1!AK14 -> 0.71494296 | F9: =+Report1!R14 -> 72.11 | G9: =+Report1!S14 -> 329.456 | H9: =+Report1!X14 -> 1.9805159 | I9: =+Report1!Y14 -> 2.2772328 | J9: =+Report1!AD14 -> 758.06379 | K9: =+Report1!AE14 -> 911.26196 | L9: =+[1]Report1!J14 -> 0.73952524 | M9: =+[1]Report1!K14 -> 0.60007309 | N9: =+[1]Report1!BJ14 -> 0.73952524 | O9: =+[1]Report1!BK14 -> 0.73189696 | P9: =+[1]Report1!R14 -> 38.428 | Q9: =+[1]Report1!S14 -> 226.018 | R9: =+[1]Report1!AL14 -> 3.2365723 | S9: =+[1]Report1!AM14 -> 2.5264713 | T9: =+[1]Report1!AR14 -> 0.23160196 | U9: =+[1]Report1!AS14 -> 0.27519932 | V9: =+[1]Report1!AX14 -> 949.07281 | W9: =+[1]Report1!AY14 -> 731.48059 | X9: =+[1]Report1!BD14 -> 509.13396 | Y9: =+[1]Report1!BE14 -> 399.2182 | Z9: =+[2]Report1!J14 -> 0.92907022 | AA9: =+[2]Report1!K14 -> 0.86534015 | AB9: =+[2]Report1!BC14 -> 0.92907022 | AC9: =+[2]Report1!BD14 -> 0.86534015 | AD9: =+[2]Report1!R14 -> 40.382 | AE9: =+[2]Report1!S14 -> 233.359 | AF9: =+[2]Report1!X14 -> 114.51853 | AG9: =+[2]Report1!Y14 -> 114.32156 | AH9: =+[2]Report1!AD14 -> 1.3768511 | AI9: =+[2]Report1!AE14 -> 1.3048565 | AJ9: =+[2]Report1!AJ14 -> 841.81021 | AK9: =+[2]Report1!AK14 -> 910.70291 | AN9: =+[3]Report1!J14 -> 0.96946344 | AO9: =+[3]Report1!K14 -> 0.90528152 | AP9: =+[3]Report1!BN14 -> 0.96946344 | AQ9: =+[3]Report1!BO14 -> 0.90528152 | AR9: =+[3]Report1!R14 -> 50.589 | AS9: =+[3]Report1!S14 -> 292.852 | AT9: =+[3]Report1!AF14 -> 102.39669 | AU9: =+[3]Report1!AG14 -> 105.33919 | AV9: =+[3]Report1!AL14 -> 1.3797466 | AW9: =+[3]Report1!AM14 -> 1.3880732 | AX9: =+[3]Report1!AR14 -> 0.21546186 | AY9: =+[3]Report1!AS14 -> 0.19839373 | AZ9: =+[3]Report1!AX14 -> 785.82261 | BA9: =+[3]Report1!AY14 -> 899.8768 | BB9: =+[3]Report1!BD14 -> 443.57469 | BC9: =+[3]Report1!BE14 -> 479.43607 | BD9: =+[3]Report1!BJ14 -> 2.5717053 | BE9: =+[3]Report1!BK14 -> 4.6538866 | BF9: =+[4]Report1!J14 -> 0.90094567 | BG9: =+[4]Report1!K14 -> 0.94443053 | BH9: =+[4]Report1!AN14 -> 0.90094567 | BI9: =+[4]Report1!AO14 -> 0.94443053 | BJ9: =+[4]Report1!R14 -> 46.979 | BK9: =+[4]Report1!S14 -> 305.132 | BL9: =+[4]Report1!AD14 -> 2.7416505 | BM9: =+[4]Report1!AE14 -> 2.501868 | BN9: 0 | BO9: 0 | BP9: =+[4]Report1!AJ14 -> 1110.8261 | BQ9: =+[4]Report1!AK14 -> 714.25789 | BR9: 0 | BS9: 0 | BT9: =+[5]Report1!J14 -> 0.69217015 | BU9: =+[5]Report1!K14 -> 0.73806048 | BV9: =+[5]Report1!BA14 -> 0.69217015 | BW9: =+[5]Report1!BB14 -> 0.7849115 | BX9: =+[5]Report1!R14 -> 32.367 | BY9: =+[5]Report1!S14 -> 237.867 | BZ9: =+[5]Report1!X14 -> 114.13992 | CA9: =+[5]Report1!Y14 -> 84.287621 | CB9: =+[5]Report1!AD14 -> 2.9258195 | CC9: =+[5]Report1!AE14 -> 2.1768467 | CD9: =+[5]Report1!AJ14 -> 0 | CE9: =+[5]Report1!AK14 -> 0.17362644 | CF9: =+[5]Report1!AP14 -> 1310.4842 | CG9: =+[5]Report1!AQ14 -> 1107.7448 | CH9: =+[5]Report1!AV14 -> 0 | CI9: =+[5]Report1!AW14 -> 426.0107
A10: =1+A9 -> 45998 | B10: =+Report1!J15 -> 1.0597551 | C10: =+Report1!K15 -> 0.76073971 | D10: =+Report1!AJ15 -> 1.0597551 | E10: =+Report1!AK15 -> 0.76073971 | F10: =+Report1!R15 -> 74.795 | G10: =+Report1!S15 -> 404.251 | H10: =+Report1!X15 -> 1.9182699 | I10: =+Report1!Y15 -> 2.210817 | J10: =+Report1!AD15 -> 678.03436 | K10: =+Report1!AE15 -> 868.10991 | L10: =+[1]Report1!J15 -> 0.93770625 | M10: =+[1]Report1!K15 -> 0.64079475 | N10: =+[1]Report1!BJ15 -> 0.93770625 | O10: =+[1]Report1!BK15 -> 0.76139099 | P10: =+[1]Report1!R15 -> 48.44 | Q10: =+[1]Report1!S15 -> 274.458 | R10: =+[1]Report1!AL15 -> 2.5624897 | S10: =+[1]Report1!AM15 -> 2.5328283 | T10: =+[1]Report1!AR15 -> 0.18166804 | U10: =+[1]Report1!AS15 -> 0.25869168 | V10: =+[1]Report1!AX15 -> 736.8429 | W10: =+[1]Report1!AY15 -> 732.427 | X10: =+[1]Report1!BD15 -> 480.98679 | Y10: =+[1]Report1!BE15 -> 413.64981 | Z10: =+[2]Report1!J15 -> 0.97750804 | AA10: =+[2]Report1!K15 -> 0.88066234 | AB10: =+[2]Report1!BC15 -> 0.97750804 | AC10: =+[2]Report1!BD15 -> 0.88066234 | AD10: =+[2]Report1!R15 -> 41.706 | AE10: =+[2]Report1!S15 -> 275.065 | AF10: =+[2]Report1!X15 -> 114.99405 | AG10: =+[2]Report1!Y15 -> 114.42352 | AH10: =+[2]Report1!AD15 -> 1.3091641 | AI10: =+[2]Report1!AE15 -> 1.3055096 | AJ10: =+[2]Report1!AJ15 -> 922.73486 | AK10: =+[2]Report1!AK15 -> 912.52722 | AN10: =+[3]Report1!J15 -> 0.79564141 | AO10: =+[3]Report1!K15 -> 0.88973627 | AP10: =+[3]Report1!BN15 -> 0.79564141 | AQ10: =+[3]Report1!BO15 -> 0.88973627 | AR10: =+[3]Report1!R15 -> 42.522 | AS10: =+[3]Report1!S15 -> 335.374 | AT10: =+[3]Report1!AF15 -> 110.50462 | AU10: =+[3]Report1!AG15 -> 105.99411 | AV10: =+[3]Report1!AL15 -> 1.4909929 | AW10: =+[3]Report1!AM15 -> 1.4011223 | AX10: =+[3]Report1!AR15 -> 0.19519308 | AY10: =+[3]Report1!AS15 -> 0.19798792 | AZ10: =+[3]Report1!AX15 -> 992.27647 | BA10: =+[3]Report1!AY15 -> 911.59213 | BB10: =+[3]Report1!BD15 -> 498.96524 | BC10: =+[3]Report1!BE15 -> 481.91217 | BD10: =+[3]Report1!BJ15 -> 3.525234 | BE10: =+[3]Report1!BK15 -> 4.510785 | BF10: =+[4]Report1!J15 -> 0.86403462 | BG10: =+[4]Report1!K15 -> 0.93338087 | BH10: =+[4]Report1!AN15 -> 0.86403462 | BI10: =+[4]Report1!AO15 -> 0.93338087 | BJ10: =+[4]Report1!R15 -> 44.481 | BK10: =+[4]Report1!S15 -> 349.613 | BL10: =+[4]Report1!AD15 -> 2.7989479 | BM10: =+[4]Report1!AE15 -> 2.5396653 | BN10: 0 | BO10: 0 | BP10: =+[4]Report1!AJ15 -> 1210.5249 | BQ10: =+[4]Report1!AK15 -> 777.39757 | BR10: 0 | BS10: 0 | BT10: =+[5]Report1!J15 -> 0.71056284 | BU10: =+[5]Report1!K15 -> 0.7347038 | BV10: =+[5]Report1!BA15 -> 0.71056284 | BW10: =+[5]Report1!BB15 -> 0.77533373 | BX10: =+[5]Report1!R15 -> 31.842 | BY10: =+[5]Report1!S15 -> 269.709 | BZ10: =+[5]Report1!X15 -> 121.48046 | CA10: =+[5]Report1!Y15 -> 88.67863 | CB10: =+[5]Report1!AD15 -> 2.8892657 | CC10: =+[5]Report1!AE15 -> 2.2609553 | CD10: =+[5]Report1!AJ15 -> 0 | CE10: =+[5]Report1!AK15 -> 0.153128 | CF10: =+[5]Report1!AP15 -> 1382.3058 | CG10: =+[5]Report1!AQ15 -> 1140.1596 | CH10: =+[5]Report1!AV15 -> 0 | CI10: =+[5]Report1!AW15 -> 375.71563
A11: =1+A10 -> 45999 | B11: =+Report1!J16 -> 1.0979342 | C11: =+Report1!K16 -> 0.80622244 | D11: =+Report1!AJ16 -> 1.0979342 | E11: =+Report1!AK16 -> 0.80622244 | F11: =+Report1!R16 -> 90.967 | G11: =+Report1!S16 -> 495.218 | H11: =+Report1!X16 -> 1.6259743 | I11: =+Report1!Y16 -> 2.1033868 | J11: =+Report1!AD16 -> 625.83552 | K11: =+Report1!AE16 -> 823.60633 | L11: =+[1]Report1!J16 -> 0.88884951 | M11: =+[1]Report1!K16 -> 0.66753231 | N11: =+[1]Report1!BJ16 -> 0.88884951 | O11: =+[1]Report1!BK16 -> 0.77739062 | P11: =+[1]Report1!R16 -> 45.993 | Q11: =+[1]Report1!S16 -> 320.451 | R11: =+[1]Report1!AL16 -> 2.5711304 | S11: =+[1]Report1!AM16 -> 2.5383257 | T11: =+[1]Report1!AR16 -> 0.17176527 | U11: =+[1]Report1!AS16 -> 0.24621549 | V11: =+[1]Report1!AX16 -> 746.71515 | W11: =+[1]Report1!AY16 -> 734.47772 | X11: =+[1]Report1!BD16 -> 465.36647 | Y11: =+[1]Report1!BE16 -> 421.07249 | Z11: =+[2]Report1!J16 -> 0.85490802 | AA11: =+[2]Report1!K16 -> 0.87750063 | AB11: =+[2]Report1!BC16 -> 0.85490802 | AC11: =+[2]Report1!BD16 -> 0.87750063 | AD11: =+[2]Report1!R16 -> 37.368 | AE11: =+[2]Report1!S16 -> 312.433 | AF11: =+[2]Report1!X16 -> 135.31267 | AG11: =+[2]Report1!Y16 -> 116.92193 | AH11: =+[2]Report1!AD16 -> 1.5253693 | AI11: =+[2]Report1!AE16 -> 1.3318055 | AJ11: =+[2]Report1!AJ16 -> 979.19022 | AK11: =+[2]Report1!AK16 -> 920.50033 | AN11: =+[3]Report1!J16 -> 0.98960422 | AO11: =+[3]Report1!K16 -> 0.9024652 | AP11: =+[3]Report1!BN16 -> 0.98960422 | AQ11: =+[3]Report1!BO16 -> 0.9024652 | AR11: =+[3]Report1!R16 -> 54.489 | AS11: =+[3]Report1!S16 -> 389.863 | AT11: =+[3]Report1!AF16 -> 94.149589 | AU11: =+[3]Report1!AG16 -> 104.33867 | AV11: =+[3]Report1!AL16 -> 1.2791573 | AW11: =+[3]Report1!AM16 -> 1.3840759 | AX11: =+[3]Report1!AR16 -> 0.16884142 | AY11: =+[3]Report1!AS16 -> 0.19391427 | AZ11: =+[3]Report1!AX16 -> 689.32041 | BA11: =+[3]Report1!AY16 -> 880.52644 | BB11: =+[3]Report1!BD16 -> 433.67285 | BC11: =+[3]Report1!BE16 -> 475.17003 | BD11: =+[3]Report1!BJ16 -> 2.3876379 | BE11: =+[3]Report1!BK16 -> 4.2140444 | BF11: =+[4]Report1!J16 -> 1.0523192 | BG11: =+[4]Report1!K16 -> 0.94775257 | BH11: =+[4]Report1!AN16 -> 1.0523192 | BI11: =+[4]Report1!AO16 -> 0.94775257 | BJ11: =+[4]Report1!R16 -> 54.174 | BK11: =+[4]Report1!S16 -> 403.787 | BL11: =+[4]Report1!AD16 -> 2.2833832 | BM11: =+[4]Report1!AE16 -> 2.5052812 | BN11: 0 | BO11: 0 | BP11: =+[4]Report1!AJ16 -> 950.11727 | BQ11: =+[4]Report1!AK16 -> 800.57047 | BR11: 0 | BS11: 0 | BT11: =+[5]Report1!J16 -> 0.91403027 | BU11: =+[5]Report1!K16 -> 0.75472289 | BV11: =+[5]Report1!BA16 -> 0.91403027 | BW11: =+[5]Report1!BB16 -> 0.7915731 | BX11: =+[5]Report1!R16 -> 42.165 | BY11: =+[5]Report1!S16 -> 311.874 | BZ11: =+[5]Report1!X16 -> 89.019785 | CA11: =+[5]Report1!Y16 -> 88.724753 | CB11: =+[5]Report1!AD16 -> 2.1107554 | CC11: =+[5]Report1!AE16 -> 2.2406485 | CD11: =+[5]Report1!AJ16 -> 0 | CE11: =+[5]Report1!AK16 -> 0.13242527 | CF11: =+[5]Report1!AP16 -> 949.82775 | CG11: =+[5]Report1!AQ16 -> 1114.427 | CH11: =+[5]Report1!AV16 -> 0 | CI11: =+[5]Report1!AW16 -> 324.91932
A12: =1+A11 -> 46000 | B12: =+Report1!J17 -> 0.82735468 | C12: =+Report1!K17 -> 0.80826482 | D12: =+Report1!AJ17 -> 0.82735468 | E12: =+Report1!AK17 -> 0.80826482 | F12: =+Report1!R17 -> 54.371 | G12: =+Report1!S17 -> 549.589 | H12: =+Report1!X17 -> 2.4790605 | I12: =+Report1!Y17 -> 2.1405523 | J12: =+Report1!AD17 -> 1040.2924 | K12: =+Report1!AE17 -> 845.04315 | L12: =+[1]Report1!J17 -> 0.90604789 | M12: =+[1]Report1!K17 -> 0.69265777 | N12: =+[1]Report1!BJ17 -> 0.90604789 | O12: =+[1]Report1!BK17 -> 0.79290499 | P12: =+[1]Report1!R17 -> 51.213 | Q12: =+[1]Report1!S17 -> 371.664 | R12: =+[1]Report1!AL17 -> 2.6473942 | S12: =+[1]Report1!AM17 -> 2.5533546 | T12: =+[1]Report1!AR17 -> 0.18354715 | U12: =+[1]Report1!AS17 -> 0.23758018 | V12: =+[1]Report1!AX17 -> 675.54293 | W12: =+[1]Report1!AY17 -> 726.35687 | X12: =+[1]Report1!BD17 -> 565.3916 | Y12: =+[1]Report1!BE17 -> 440.95877 | Z12: =+[2]Report1!J17 -> 0.90977725 | AA12: =+[2]Report1!K17 -> 0.88082373 | AB12: =+[2]Report1!BC17 -> 0.90977725 | AC12: =+[2]Report1!BD17 -> 0.88082373 | AD12: =+[2]Report1!R17 -> 37.178 | AE12: =+[2]Report1!S17 -> 349.611 | AF12: =+[2]Report1!X17 -> 141.93137 | AG12: =+[2]Report1!Y17 -> 119.58146 | AH12: =+[2]Report1!AD17 -> 1.4551617 | AI12: =+[2]Report1!AE17 -> 1.3449234 | AJ12: =+[2]Report1!AJ17 -> 1069.4045 | AK12: =+[2]Report1!AK17 -> 936.33496 | AN12: =+[3]Report1!J17 -> 0.84895799 | AO12: =+[3]Report1!K17 -> 0.89652289 | AP12: =+[3]Report1!BN17 -> 0.84895799 | AQ12: =+[3]Report1!BO17 -> 0.89652289 | AR12: =+[3]Report1!R17 -> 45.818 | AS12: =+[3]Report1!S17 -> 435.681 | AT12: =+[3]Report1!AF17 -> 100.40254 | AU12: =+[3]Report1!AG17 -> 103.92473 | AV12: =+[3]Report1!AL17 -> 1.3859182 | AW12: =+[3]Report1!AM17 -> 1.3842697 | AX12: =+[3]Report1!AR17 -> 0.17896896 | AY12: =+[3]Report1!AS17 -> 0.19234256 | AZ12: =+[3]Report1!AX17 -> 936.71308 | BA12: =+[3]Report1!AY17 -> 886.43526 | BB12: =+[3]Report1!BD17 -> 535.26125 | BC12: =+[3]Report1!BE17 -> 481.48947 | BD12: =+[3]Report1!BJ17 -> 1.7482212 | BE12: =+[3]Report1!BK17 -> 3.9547283 | BF12: =+[4]Report1!J17 -> 0.95636071 | BG12: =+[4]Report1!K17 -> 0.94868058 | BH12: =+[4]Report1!AN17 -> 0.95636071 | BI12: =+[4]Report1!AO17 -> 0.94868058 | BJ12: =+[4]Report1!R17 -> 49.234 | BK12: =+[4]Report1!S17 -> 453.021 | BL12: =+[4]Report1!AD17 -> 2.4617135 | BM12: =+[4]Report1!AE17 -> 2.5005463 | BN12: 0 | BO12: 0 | BP12: =+[4]Report1!AJ17 -> 1045.9562 | BQ12: =+[4]Report1!AK17 -> 827.23882 | BR12: 0 | BS12: 0 | BT12: =+[5]Report1!J17 -> 0.940531 | BU12: =+[5]Report1!K17 -> 0.77351643 | BV12: =+[5]Report1!BA17 -> 0.940531 | BW12: =+[5]Report1!BB17 -> 0.80729741 | BX12: =+[5]Report1!R17 -> 43.734 | BY12: =+[5]Report1!S17 -> 355.608 | BZ12: =+[5]Report1!X17 -> 86.958241 | CA12: =+[5]Report1!Y17 -> 88.507501 | CB12: =+[5]Report1!AD17 -> 2.0716148 | CC12: =+[5]Report1!AE17 -> 2.2198601 | CD12: =+[5]Report1!AJ17 -> 0 | CE12: =+[5]Report1!AK17 -> 0.11613912 | CF12: =+[5]Report1!AP17 -> 1083.7873 | CG12: =+[5]Report1!AQ17 -> 1110.6588 | CH12: =+[5]Report1!AV17 -> 0 | CI12: =+[5]Report1!AW17 -> 284.95953
A13: =1+A12 -> 46001 | B13: =+Report1!J18 -> 0.94746434 | C13: =+Report1!K18 -> 0.81993914 | D13: =+Report1!AJ18 -> 0.94746434 | E13: =+Report1!AK18 -> 0.81993914 | F13: =+Report1!R18 -> 58.977 | G13: =+Report1!S18 -> 608.566 | H13: =+Report1!X18 -> 2.1234888 | I13: =+Report1!Y18 -> 2.1388987 | J13: =+Report1!AD18 -> 961.71694 | K13: =+Report1!AE18 -> 856.35017 | L13: =+[1]Report1!J18 -> 0.83809516 | M13: =+[1]Report1!K18 -> 0.70898163 | N13: =+[1]Report1!BJ18 -> 0.83809516 | O13: =+[1]Report1!BK18 -> 0.7986184 | P13: =+[1]Report1!R18 -> 56.856 | Q13: =+[1]Report1!S18 -> 428.52 | R13: =+[1]Report1!AL18 -> 2.2436858 | S13: =+[1]Report1!AM18 -> 2.5122678 | T13: =+[1]Report1!AR18 -> 0.19698888 | U13: =+[1]Report1!AS18 -> 0.23219453 | V13: =+[1]Report1!AX18 -> 396.42254 | W13: =+[1]Report1!AY18 -> 682.58121 | X13: =+[1]Report1!BD18 -> 595.31237 | Y13: =+[1]Report1!BE18 -> 461.43839 | Z13: =+[2]Report1!J18 -> 0.92095308 | AA13: =+[2]Report1!K18 -> 0.88456868 | AB13: =+[2]Report1!BC18 -> 0.92095308 | AC13: =+[2]Report1!BD18 -> 0.88456868 | AD13: =+[2]Report1!R18 -> 37.624 | AE13: =+[2]Report1!S18 -> 387.235 | AF13: =+[2]Report1!X18 -> 136.53917 | AG13: =+[2]Report1!Y18 -> 121.22909 | AH13: =+[2]Report1!AD18 -> 1.4299383 | AI13: =+[2]Report1!AE18 -> 1.3531835 | AJ13: =+[2]Report1!AJ18 -> 1036.9073 | AK13: =+[2]Report1!AK18 -> 946.10663 | AN13: =+[3]Report1!J18 -> 0.95105316 | AO13: =+[3]Report1!K18 -> 0.90190956 | AP13: =+[3]Report1!BN18 -> 0.95105316 | AQ13: =+[3]Report1!BO18 -> 0.90190956 | AR13: =+[3]Report1!R18 -> 50.66 | AS13: =+[3]Report1!S18 -> 486.341 | AT13: =+[3]Report1!AF18 -> 95.92954 | AU13: =+[3]Report1!AG18 -> 103.0919 | AV13: =+[3]Report1!AL18 -> 1.3541255 | AW13: =+[3]Report1!AM18 -> 1.3811297 | AX13: =+[3]Report1!AR18 -> 0.19147256 | AY13: =+[3]Report1!AS18 -> 0.19225194 | AZ13: =+[3]Report1!AX18 -> 744.42558 | BA13: =+[3]Report1!AY18 -> 871.64274 | BB13: =+[3]Report1!BD18 -> 283.29886 | BC13: =+[3]Report1!BE18 -> 460.84482 | BD13: =+[3]Report1!BJ18 -> 3.94394 | BE13: =+[3]Report1!BK18 -> 3.9536046 | BF13: =+[4]Report1!J18 -> 0.96135288 | BG13: =+[4]Report1!K18 -> 0.94991379 | BH13: =+[4]Report1!AN18 -> 0.96135288 | BI13: =+[4]Report1!AO18 -> 0.94991379 | BJ13: =+[4]Report1!R18 -> 49.491 | BK13: =+[4]Report1!S18 -> 502.512 | BL13: =+[4]Report1!AD18 -> 2.4044776 | BM13: =+[4]Report1!AE18 -> 2.4910848 | BN13: 0 | BO13: 0 | BP13: =+[4]Report1!AJ18 -> 1102.8664 | BQ13: =+[4]Report1!AK18 -> 854.3846 | BR13: 0 | BS13: 0 | BT13: =+[5]Report1!J18 -> 0.78936587 | BU13: =+[5]Report1!K18 -> 0.77510967 | BV13: =+[5]Report1!BA18 -> 0.78936587 | BW13: =+[5]Report1!BB18 -> 0.80542438 | BX13: =+[5]Report1!R18 -> 40.556 | BY13: =+[5]Report1!S18 -> 396.164 | BZ13: =+[5]Report1!X18 -> 99.740107 | CA13: =+[5]Report1!Y18 -> 89.657403 | CB13: =+[5]Report1!AD18 -> 2.3449058 | CC13: =+[5]Report1!AE18 -> 2.2326612 | CD13: =+[5]Report1!AJ18 -> 0 | CE13: =+[5]Report1!AK18 -> 0.10424976 | CF13: =+[5]Report1!AP18 -> 1096.8991 | CG13: =+[5]Report1!AQ18 -> 1109.2502 | CH13: =+[5]Report1!AV18 -> 0 | CI13: =+[5]Report1!AW18 -> 255.78772
A14: =1+A13 -> 46002 | B14: =+Report1!J19 -> 0.89446438 | C14: =+Report1!K19 -> 0.82495235 | D14: =+Report1!AJ19 -> 0.93299368 | E14: =+Report1!AK19 -> 0.82725041 | F14: =+Report1!R19 -> 47.879 | G14: =+Report1!S19 -> 656.445 | H14: =+Report1!X19 -> 2.6365839 | I14: =+Report1!Y19 -> 2.1751982 | J14: =+Report1!AD19 -> 1159.9081 | K14: =+Report1!AE19 -> 878.49072 | L14: =+[1]Report1!J19 -> 0.69310599 | M14: =+[1]Report1!K19 -> 0.70737957 | N14: =+[1]Report1!BJ19 -> 0.69310599 | O14: =+[1]Report1!BK19 -> 0.78677571 | P14: =+[1]Report1!R19 -> 47.02 | Q14: =+[1]Report1!S19 -> 475.54 | R14: =+[1]Report1!AL19 -> 2.0714164 | S14: =+[1]Report1!AM19 -> 2.4686777 | T14: =+[1]Report1!AR19 -> 0.22756274 | U14: =+[1]Report1!AS19 -> 0.23173655 | V14: =+[1]Report1!AX19 -> 745.69247 | W14: =+[1]Report1!AY19 -> 688.82147 | X14: =+[1]Report1!BD19 -> 626.65419 | Y14: =+[1]Report1!BE19 -> 477.77445 | Z14: =+[2]Report1!J19 -> 0.89961009 | AA14: =+[2]Report1!K19 -> 0.88584767 | AB14: =+[2]Report1!BC19 -> 0.89961009 | AC14: =+[2]Report1!BD19 -> 0.88584767 | AD14: =+[2]Report1!R19 -> 36.599 | AE14: =+[2]Report1!S19 -> 423.834 | AF14: =+[2]Report1!X19 -> 141.0617 | AG14: =+[2]Report1!Y19 -> 122.94168 | AH14: =+[2]Report1!AD19 -> 1.4426624 | AI14: =+[2]Report1!AE19 -> 1.3609102 | AJ14: =+[2]Report1!AJ19 -> 952.62821 | AK14: =+[2]Report1!AK19 -> 946.66978 | AN14: =+[3]Report1!J19 -> 0.81937936 | AO14: =+[3]Report1!K19 -> 0.89437407 | AP14: =+[3]Report1!BN19 -> 0.81937936 | AQ14: =+[3]Report1!BO19 -> 0.89437407 | AR14: =+[3]Report1!R19 -> 44.396 | AS14: =+[3]Report1!S19 -> 530.737 | AT14: =+[3]Report1!AF19 -> 92.971037 | AU14: =+[3]Report1!AG19 -> 102.2453 | AV14: =+[3]Report1!AL19 -> 1.3717452 | AW14: =+[3]Report1!AM19 -> 1.3803447 | AX14: =+[3]Report1!AR19 -> 0.22524552 | AY14: =+[3]Report1!AS19 -> 0.19501184 | AZ14: =+[3]Report1!AX19 -> 850.87035 | BA14: =+[3]Report1!AY19 -> 869.90513 | BB14: =+[3]Report1!BD19 -> 500.737 | BC14: =+[3]Report1!BE19 -> 464.18179 | BD14: =+[3]Report1!BJ19 -> 3.1556897 | BE14: =+[3]Report1!BK19 -> 3.8868592 | BF14: =+[4]Report1!J19 -> 0.81819209 | BG14: =+[4]Report1!K19 -> 0.93823206 | BH14: =+[4]Report1!AN19 -> 0.81819209 | BI14: =+[4]Report1!AO19 -> 0.93823206 | BJ14: =+[4]Report1!R19 -> 42.121 | BK14: =+[4]Report1!S19 -> 544.633 | BL14: =+[4]Report1!AD19 -> 2.8536834 | BM14: =+[4]Report1!AE19 -> 2.5191276 | BN14: 0 | BO14: 0 | BP14: =+[4]Report1!AJ19 -> 1153.524 | BQ14: =+[4]Report1!AK19 -> 877.51954 | BR14: 0 | BS14: 0 | BT14: =+[5]Report1!J19 -> 0.93024437 | BU14: =+[5]Report1!K19 -> 0.78922915 | BV14: =+[5]Report1!BA19 -> 0.93024437 | BW14: =+[5]Report1!BB19 -> 0.81718723 | BX14: =+[5]Report1!R19 -> 47.606 | BY14: =+[5]Report1!S19 -> 443.77 | BZ14: =+[5]Report1!X19 -> 84.206626 | CA14: =+[5]Report1!Y19 -> 89.072664 | CB14: =+[5]Report1!AD19 -> 1.9955468 | CC14: =+[5]Report1!AE19 -> 2.2072245 | CD14: =+[5]Report1!AJ19 -> 0 | CE14: =+[5]Report1!AK19 -> 0.093066228 | CF14: =+[5]Report1!AP19 -> 865.8181 | CG14: =+[5]Report1!AQ19 -> 1083.1357 | CH14: =+[5]Report1!AV19 -> 0 | CI14: =+[5]Report1!AW19 -> 228.34776
A15: =1+A14 -> 46003 | B15: =+Report1!J20 -> 1.0314661 | C15: =+Report1!K20 -> 0.83777021 | D15: =+Report1!AJ20 -> 1.0314661 | E15: =+Report1!AK20 -> 0.83995875 | F15: =+Report1!R20 -> 54.315 | G15: =+Report1!S20 -> 710.76 | H15: =+Report1!X20 -> 2.2876185 | I15: =+Report1!Y20 -> 2.1837892 | J15: =+Report1!AD20 -> 1102.7981 | K15: =+Report1!AE20 -> 895.63189 | L15: =+[1]Report1!J20 -> 0.88654408 | M15: =+[1]Report1!K20 -> 0.72360625 | N15: =+[1]Report1!BJ20 -> 0.88654408 | O15: =+[1]Report1!BK20 -> 0.79672464 | P15: =+[1]Report1!R20 -> 59.353 | Q15: =+[1]Report1!S20 -> 534.893 | R15: =+[1]Report1!AL20 -> 2.1571445 | S15: =+[1]Report1!AM20 -> 2.4341093 | T15: =+[1]Report1!AR20 -> 0.21565885 | U15: =+[1]Report1!AS20 -> 0.22995253 | V15: =+[1]Report1!AX20 -> 711.37129 | W15: =+[1]Report1!AY20 -> 691.32365 | X15: =+[1]Report1!BD20 -> 480.07346 | Y15: =+[1]Report1!BE20 -> 478.02955 | Z15: =+[2]Report1!J20 -> 0.96351061 | AA15: =+[2]Report1!K20 -> 0.89226272 | AB15: =+[2]Report1!BC20 -> 0.96351061 | AC15: =+[2]Report1!BD20 -> 0.89226272 | AD15: =+[2]Report1!R20 -> 41.507 | AE15: =+[2]Report1!S20 -> 465.341 | AF15: =+[2]Report1!X20 -> 127.0278 | AG15: =+[2]Report1!Y20 -> 123.30615 | AH15: =+[2]Report1!AD20 -> 1.2528007 | AI15: =+[2]Report1!AE20 -> 1.3512671 | AJ15: =+[2]Report1!AJ20 -> 1010.3954 | AK15: =+[2]Report1!AK20 -> 952.35391 | AN15: =+[3]Report1!J20 -> 0.87376279 | AO15: =+[3]Report1!K20 -> 0.8926597 | AP15: =+[3]Report1!BN20 -> 0.87376279 | AQ15: =+[3]Report1!BO20 -> 0.8926597 | AR15: =+[3]Report1!R20 -> 47.04 | AS15: =+[3]Report1!S20 -> 577.777 | AT15: =+[3]Report1!AF20 -> 104.0462 | AU15: =+[3]Report1!AG20 -> 102.39192 | AV15: =+[3]Report1!AL20 -> 1.4413265 | AW15: =+[3]Report1!AM20 -> 1.3853096 | AX15: =+[3]Report1!AR20 -> 0.21258503 | AY15: =+[3]Report1!AS20 -> 0.19644257 | AZ15: =+[3]Report1!AX20 -> 849.03231 | BA15: =+[3]Report1!AY20 -> 868.20576 | BB15: =+[3]Report1!BD20 -> 416.52211 | BC15: =+[3]Report1!BE20 -> 460.30156 | BD15: =+[3]Report1!BJ20 -> 2.7657313 | BE15: =+[3]Report1!BK20 -> 3.795582 | BF15: =+[4]Report1!J20 -> 0.83132325 | BG15: =+[4]Report1!K20 -> 0.92952321 | BH15: =+[4]Report1!AN20 -> 0.83132325 | BI15: =+[4]Report1!AO20 -> 0.92952321 | BJ15: =+[4]Report1!R20 -> 42.797 | BK15: =+[4]Report1!S20 -> 587.43 | BL15: =+[4]Report1!AD20 -> 2.7992616 | BM15: =+[4]Report1!AE20 -> 2.5395366 | BN15: 0 | BO15: 0 | BP15: =+[4]Report1!AJ20 -> 1248.4561 | BQ15: =+[4]Report1!AK20 -> 904.54399 | BR15: 0 | BS15: 0 | BT15: =+[5]Report1!J20 -> 0.90534701 | BU15: =+[5]Report1!K20 -> 0.79846658 | BV15: =+[5]Report1!BA20 -> 0.90534701 | BW15: =+[5]Report1!BB20 -> 0.82442857 | BX15: =+[5]Report1!R20 -> 43.997 | BY15: =+[5]Report1!S20 -> 487.767 | BZ15: =+[5]Report1!X20 -> 90.190783 | CA15: =+[5]Report1!Y20 -> 89.173519 | CB15: =+[5]Report1!AD20 -> 2.1569652 | CC15: =+[5]Report1!AE20 -> 2.202691 | CD15: =+[5]Report1!AJ20 -> 0 | CE15: =+[5]Report1!AK20 -> 0.084671575 | CF15: =+[5]Report1!AP20 -> 1039.2814 | CG15: =+[5]Report1!AQ20 -> 1079.18 | CH15: =+[5]Report1!AV20 -> 0 | CI15: =+[5]Report1!AW20 -> 207.7506
A16: =1+A15 -> 46004 | B16: =+Report1!J21 -> 0.88974942 | C16: =+Report1!K21 -> 0.8410105 | D16: =+Report1!AJ21 -> 0.88974942 | E16: =+Report1!AK21 -> 0.84307021 | F16: =+Report1!R21 -> 50.185 | G16: =+Report1!S21 -> 760.945 | H16: =+Report1!X21 -> 2.4976587 | I16: =+Report1!Y21 -> 2.2044892 | J16: =+Report1!AD21 -> 1139.2014 | K16: =+Report1!AE21 -> 911.69551 | L16: =+[1]Report1!J21 -> 0.8377358 | M16: =+[1]Report1!K21 -> 0.73324632 | N16: =+[1]Report1!BJ21 -> 0.8377358 | O16: =+[1]Report1!BK21 -> 0.80050645 | P16: =+[1]Report1!R21 -> 57.132 | Q16: =+[1]Report1!S21 -> 592.025 | R16: =+[1]Report1!AL21 -> 2.334121 | S16: =+[1]Report1!AM21 -> 2.4244601 | T16: =+[1]Report1!AR21 -> 0.18028425 | U16: =+[1]Report1!AS21 -> 0.22515941 | V16: =+[1]Report1!AX21 -> 713.8369 | W16: =+[1]Report1!AY21 -> 693.49624 | X16: =+[1]Report1!BD21 -> 427.62725 | Y16: =+[1]Report1!BE21 -> 473.16559 | Z16: =+[2]Report1!J21 -> 0.81833417 | AA16: =+[2]Report1!K21 -> 0.88679943 | AB16: =+[2]Report1!BC21 -> 0.81833417 | AC16: =+[2]Report1!BD21 -> 0.88679943 | AD16: =+[2]Report1!R21 -> 34.056 | AE16: =+[2]Report1!S21 -> 499.397 | AF16: =+[2]Report1!X21 -> 145.3013 | AG16: =+[2]Report1!Y21 -> 124.80609 | AH16: =+[2]Report1!AD21 -> 1.5063425 | AI16: =+[2]Report1!AE21 -> 1.3618424 | AJ16: =+[2]Report1!AJ21 -> 1203.0426 | AK16: =+[2]Report1!AK21 -> 969.44944 | AN16: =+[3]Report1!J21 -> 0.95742329 | AO16: =+[3]Report1!K21 -> 0.89776891 | AP16: =+[3]Report1!BN21 -> 0.95742329 | AQ16: =+[3]Report1!BO21 -> 0.89776891 | AR16: =+[3]Report1!R21 -> 53.075 | AS16: =+[3]Report1!S21 -> 630.852 | AT16: =+[3]Report1!AF21 -> 86.58978 | AU16: =+[3]Report1!AG21 -> 101.06245 | AV16: =+[3]Report1!AL21 -> 1.2962789 | AW16: =+[3]Report1!AM21 -> 1.3778192 | AX16: =+[3]Report1!AR21 -> 0.17899199 | AY16: =+[3]Report1!AS21 -> 0.19497442 | AZ16: =+[3]Report1!AX21 -> 780.23212 | BA16: =+[3]Report1!AY21 -> 860.80434 | BB16: =+[3]Report1!BD21 -> 399.82666 | BC16: =+[3]Report1!BE21 -> 455.21367 | BD16: =+[3]Report1!BJ21 -> 2.2628356 | BE16: =+[3]Report1!BK21 -> 3.6666286 | BF16: =+[4]Report1!J21 -> 0.94639578 | BG16: =+[4]Report1!K21 -> 0.93079413 | BH16: =+[4]Report1!AN21 -> 0.94639578 | BI16: =+[4]Report1!AO21 -> 0.93079413 | BJ16: =+[4]Report1!R21 -> 48.721 | BK16: =+[4]Report1!S21 -> 636.151 | BL16: =+[4]Report1!AD21 -> 2.3891135 | BM16: =+[4]Report1!AE21 -> 2.5280161 | BN16: 0 | BO16: 0 | BP16: =+[4]Report1!AJ21 -> 1102.5457 | BQ16: =+[4]Report1!AK21 -> 919.70838 | BR16: 0 | BS16: 0 | BT16: =+[5]Report1!J21 -> 1.0551092 | BU16: =+[5]Report1!K21 -> 0.81641224 | BV16: =+[5]Report1!BA21 -> 1.0551092 | BW16: =+[5]Report1!BB21 -> 0.84104553 | BX16: =+[5]Report1!R21 -> 48.458 | BY16: =+[5]Report1!S21 -> 536.225 | BZ16: =+[5]Report1!X21 -> 74.205835 | CA16: =+[5]Report1!Y21 -> 87.820907 | CB16: =+[5]Report1!AD21 -> 1.923315 | CC16: =+[5]Report1!AE21 -> 2.1774442 | CD16: =+[5]Report1!AJ21 -> 0 | CE16: =+[5]Report1!AK21 -> 0.077019908 | CF16: =+[5]Report1!AP21 -> 990.65856 | CG16: =+[5]Report1!AQ21 -> 1071.1804 | CH16: =+[5]Report1!AV21 -> 0 | CI16: =+[5]Report1!AW21 -> 188.97643
... A26: =1+A25 -> 46014 | B26: =+Report1!J31 -> 0.99405536 | C26: =+Report1!K31 -> 0.86689387 | D26: =+Report1!AJ31 -> 0.99405536 | E26: =+Report1!AK31 -> 0.86808586 | F26: =+Report1!R31 -> 80.235 | G26: =+Report1!S31 -> 1395.562 | H26: =+Report1!X31 -> 2.1354272 | I26: =+Report1!Y31 -> 2.2306913 | J26: =+Report1!AD31 -> 695.23774 | K26: =+Report1!AE31 -> 889.06839 | L26: =+[1]Report1!J31 -> 0.96970947 | M26: =+[1]Report1!K31 -> 0.83554952 | N26: =+[1]Report1!BJ31 -> 0.96970947 | O26: =+[1]Report1!BK31 -> 0.87452304 | P26: =+[1]Report1!R31 -> 75.752 | Q26: =+[1]Report1!S31 -> 1241.036 | R26: =+[1]Report1!AL31 -> 1.5401178 | S26: =+[1]Report1!AM31 -> 2.1600759 | T26: =+[1]Report1!AR31 -> 0.17908029 | U26: =+[1]Report1!AS31 -> 0.205607 | V26: =+[1]Report1!AX31 -> 441.79428 | W26: =+[1]Report1!AY31 -> 624.23386 | X26: =+[1]Report1!BD31 -> 481.94857 | Y26: =+[1]Report1!BE31 -> 490.95118 | Z26: =+[2]Report1!J31 -> 0.93279582 | AA26: =+[2]Report1!K31 -> 0.87700632 | AB26: =+[2]Report1!BC31 -> 0.93279582 | AC26: =+[2]Report1!BD31 -> 0.87700632 | AD26: =+[2]Report1!R31 -> 41.517 | AE26: =+[2]Report1!S31 -> 867.112 | AF26: =+[2]Report1!X31 -> 123.82933 | AG26: =+[2]Report1!Y31 -> 130.26727 | AH26: =+[2]Report1!AD31 -> 1.2139605 | AI26: =+[2]Report1!AE31 -> 1.354035 | AJ26: =+[2]Report1!AJ31 -> 923.53494 | AK26: =+[2]Report1!AK31 -> 993.22816 | AN26: =+[3]Report1!J31 -> 0.8673274 | AO26: =+[3]Report1!K31 -> 0.88396161 | AP26: =+[3]Report1!BN31 -> 0.8673274 | AQ26: =+[3]Report1!BO31 -> 0.88396161 | AR26: =+[3]Report1!R31 -> 43.62 | AS26: =+[3]Report1!S31 -> 1084.15 | AT26: =+[3]Report1!AF31 -> 108.8337 | AU26: =+[3]Report1!AG31 -> 101.82408 | AV26: =+[3]Report1!AL31 -> 1.4695094 | AW26: =+[3]Report1!AM31 -> 1.3973159 | AX26: =+[3]Report1!AR31 -> 0.17731109 | AY26: =+[3]Report1!AS31 -> 0.19363954 | AZ26: =+[3]Report1!AX31 -> 919.12884 | BA26: =+[3]Report1!AY31 -> 877.7476 | BB26: =+[3]Report1!BD31 -> 420.97964 | BC26: =+[3]Report1!BE31 -> 446.94962 | BD26: =+[3]Report1!BJ31 -> 2.7556167 | BE26: =+[3]Report1!BK31 -> 3.3207582 | BF26: =+[4]Report1!J31 -> 0.91998201 | BG26: =+[4]Report1!K31 -> 0.93017523 | BH26: =+[4]Report1!AN31 -> 0.91998201 | BI26: =+[4]Report1!AO31 -> 0.93017523 | BJ26: =+[4]Report1!R31 -> 50.735 | BK26: =+[4]Report1!S31 -> 1145.537 | BL26: =+[4]Report1!AD31 -> 2.3672021 | BM26: =+[4]Report1!AE31 -> 2.4518632 | BN26: 0 | BO26: 0 | BP26: =+[4]Report1!AJ31 -> 944.12662 | BQ26: =+[4]Report1!AK31 -> 905.94461 | BR26: 0 | BS26: 0 | BT26: =+[5]Report1!J31 -> 0.81035246 | BU26: =+[5]Report1!K31 -> 0.84751808 | BV26: =+[5]Report1!BA31 -> 0.81035246 | BW26: =+[5]Report1!BB31 -> 0.86198798 | BX26: =+[5]Report1!R31 -> 42.019 | BY26: =+[5]Report1!S31 -> 971.237 | BZ26: =+[5]Report1!X31 -> 99.399124 | CA26: =+[5]Report1!Y31 -> 90.11818 | CB26: =+[5]Report1!AD31 -> 2.3798758 | CC26: =+[5]Report1!AE31 -> 2.1909174 | CD26: =+[5]Report1!AJ31 -> 0 | CE26: =+[5]Report1!AK31 -> 0.042523092 | CF26: =+[5]Report1!AP31 -> 1020.344 | CG26: =+[5]Report1!AQ31 -> 1037.1072 | CH26: =+[5]Report1!AV31 -> 0 | CI26: =+[5]Report1!AW31 -> 104.33487
A27: =1+A26 -> 46015 | B27: =+Report1!J32 -> 0.96728506 | C27: =+Report1!K32 -> 0.87158703 | D27: =+Report1!AJ32 -> 0.96728506 | E27: =+Report1!AK32 -> 0.87272937 | F27: =+Report1!R32 -> 76.366 | G27: =+Report1!S32 -> 1471.928 | H27: =+Report1!X32 -> 2.2506613 | I27: =+Report1!Y32 -> 2.2317274 | J27: =+Report1!AD32 -> 713.26742 | K27: =+Report1!AE32 -> 879.94755 | L27: =+[1]Report1!J32 -> 0.98974383 | M27: =+[1]Report1!K32 -> 0.84304872 | N27: =+[1]Report1!BJ32 -> 0.98974383 | O27: =+[1]Report1!BK32 -> 0.88037489 | P27: =+[1]Report1!R32 -> 75.151 | Q27: =+[1]Report1!S32 -> 1316.187 | R27: =+[1]Report1!AL32 -> 1.5275113 | S27: =+[1]Report1!AM32 -> 2.1239581 | T27: =+[1]Report1!AR32 -> 0.079676901 | U27: =+[1]Report1!AS32 -> 0.19841671 | V27: =+[1]Report1!AX32 -> 418.839 | W27: =+[1]Report1!AY32 -> 612.50632 | X27: =+[1]Report1!BD32 -> 482.31073 | Y27: =+[1]Report1!BE32 -> 490.45783 | Z27: =+[2]Report1!J32 -> 0.91794846 | AA27: =+[2]Report1!K32 -> 0.87874062 | AB27: =+[2]Report1!BC32 -> 0.91794846 | AC27: =+[2]Report1!BD32 -> 0.87874062 | AD27: =+[2]Report1!R32 -> 40.146 | AE27: =+[2]Report1!S32 -> 907.258 | AF27: =+[2]Report1!X32 -> 131.92624 | AG27: =+[2]Report1!Y32 -> 130.34068 | AH27: =+[2]Report1!AD32 -> 1.2454541 | AI27: =+[2]Report1!AE32 -> 1.3492303 | AJ27: =+[2]Report1!AJ32 -> 979.90784 | AK27: =+[2]Report1!AK32 -> 992.63874 | AL27: =+[6]Report1!AP32 -> 0 | AM27: =+[6]Report1!AQ32 -> 0 | AN27: =+[3]Report1!J32 -> 0.82813259 | AO27: =+[3]Report1!K32 -> 0.88170369 | AP27: =+[3]Report1!BN32 -> 0.82813259 | AQ27: =+[3]Report1!BO32 -> 0.88170369 | AR27: =+[3]Report1!R32 -> 42.809 | AS27: =+[3]Report1!S32 -> 1126.959 | AT27: =+[3]Report1!AF32 -> 108.9373 | AU27: =+[3]Report1!AG32 -> 102.09428 | AV27: =+[3]Report1!AL32 -> 1.5066925 | AW27: =+[3]Report1!AM32 -> 1.4014707 | AX27: =+[3]Report1!AR32 -> 0.084379481 | AY27: =+[3]Report1!AS32 -> 0.18948916 | AZ27: =+[3]Report1!AX32 -> 962.16637 | BA27: =+[3]Report1!AY32 -> 880.95436 | BB27: =+[3]Report1!BD32 -> 492.97031 | BC27: =+[3]Report1!BE32 -> 448.69777 | BD27: =+[3]Report1!BJ32 -> 2.9222827 | BE27: =+[3]Report1!BK32 -> 3.3056216 | BF27: =+[4]Report1!J32 -> 0.99410497 | BG27: =+[4]Report1!K32 -> 0.93278636 | BH27: =+[4]Report1!AN32 -> 0.99410497 | BI27: =+[4]Report1!AO32 -> 0.93278636 | BJ27: =+[4]Report1!R32 -> 52.133 | BK27: =+[4]Report1!S32 -> 1197.67 | BL27: =+[4]Report1!AD32 -> 2.3113959 | BM27: =+[4]Report1!AE32 -> 2.4457488 | BN27: 0 | BO27: 0 | BP27: =+[4]Report1!AJ32 -> 931.33656 | BQ27: =+[4]Report1!AK32 -> 907.04989 | BR27: 0 | BS27: 0 | BT27: =+[5]Report1!J32 -> 0.97226642 | BU27: =+[5]Report1!K32 -> 0.85289188 | BV27: =+[5]Report1!BA32 -> 0.97226642 | BW27: =+[5]Report1!BB32 -> 0.86681602 | BX27: =+[5]Report1!R32 -> 50.157 | BY27: =+[5]Report1!S32 -> 1021.394 | BZ27: =+[5]Report1!X32 -> 83.84059 | CA27: =+[5]Report1!Y32 -> 89.80991 | CB27: =+[5]Report1!AD32 -> 2.0535518 | CC27: =+[5]Report1!AE32 -> 2.1841718 | CD27: =+[5]Report1!AJ32 -> 0 | CE27: =+[5]Report1!AK32 -> 0.040434935 | CF27: =+[5]Report1!AP32 -> 828.3504 | CG27: =+[5]Report1!AQ32 -> 1026.8559 | CH27: =+[5]Report1!AV32 -> 0 | CI27: =+[5]Report1!AW32 -> 99.211359
A28: =1+A27 -> 46016 | B28: =+Report1!J33 -> 0.98312552 | C28: =+Report1!K33 -> 0.87655847 | D28: =+Report1!AJ33 -> 0.98312552 | E28: =+Report1!AK33 -> 0.87765606 | F28: =+Report1!R33 -> 77.454 | G28: =+Report1!S33 -> 1549.382 | H28: =+Report1!X33 -> 2.1978981 | I28: =+Report1!Y33 -> 2.2300362 | J28: =+Report1!AD33 -> 682.02882 | K28: =+Report1!AE33 -> 870.05354 | L28: =+[1]Report1!J33 -> 0.95414717 | M28: =+[1]Report1!K33 -> 0.84823866 | N28: =+[1]Report1!BJ33 -> 0.95414717 | O28: =+[1]Report1!BK33 -> 0.88396629 | P28: =+[1]Report1!R33 -> 72.998 | Q28: =+[1]Report1!S33 -> 1389.185 | R28: =+[1]Report1!AL33 -> 1.5763309 | S28: =+[1]Report1!AM33 -> 2.0951817 | T28: =+[1]Report1!AR33 -> 0.088197797 | U28: =+[1]Report1!AS33 -> 0.19262499 | V28: =+[1]Report1!AX33 -> 412.38376 | W28: =+[1]Report1!AY33 -> 601.99041 | X28: =+[1]Report1!BD33 -> 553.69106 | Y28: =+[1]Report1!BE33 -> 493.78057 | Z28: =+[2]Report1!J33 -> 0.93150629 | AA28: =+[2]Report1!K33 -> 0.88087736 | AB28: =+[2]Report1!BC33 -> 0.93150629 | AC28: =+[2]Report1!BD33 -> 0.88087736 | AD28: =+[2]Report1!R33 -> 40.589 | AE28: =+[2]Report1!S33 -> 947.847 | AF28: =+[2]Report1!X33 -> 125.33919 | AG28: =+[2]Report1!Y33 -> 130.12651 | AH28: =+[2]Report1!AD33 -> 1.2885264 | AI28: =+[2]Report1!AE33 -> 1.3466308 | AJ28: =+[2]Report1!AJ33 -> 947.93811 | AK28: =+[2]Report1!AK33 -> 990.72456 | AL28: =+[6]Report1!AP33 -> 0 | AM28: =+[6]Report1!AQ33 -> 0 | AN28: =+[3]Report1!J33 -> 0.91819997 | AO28: =+[3]Report1!K33 -> 0.88314357 | AP28: =+[3]Report1!BN33 -> 0.91819997 | AQ28: =+[3]Report1!BO33 -> 0.88314357 | AR28: =+[3]Report1!R33 -> 48.204 | AS28: =+[3]Report1!S33 -> 1175.163 | AT28: =+[3]Report1!AF33 -> 102.39055 | AU28: =+[3]Report1!AG33 -> 102.10643 | AV28: =+[3]Report1!AL33 -> 1.3795536 | AW28: =+[3]Report1!AM33 -> 1.4005717 | AX28: =+[3]Report1!AR33 -> 0.090484964 | AY28: =+[3]Report1!AS33 -> 0.18542811 | AZ28: =+[3]Report1!AX33 -> 792.37947 | BA28: =+[3]Report1!AY33 -> 877.3211 | BB28: =+[3]Report1!BD33 -> 485.96714 | BC28: =+[3]Report1!BE33 -> 450.22653 | BD28: =+[3]Report1!BJ33 -> 2.7736287 | BE28: =+[3]Report1!BK33 -> 3.2837998 | BF28: =+[4]Report1!J33 -> 0.90277429 | BG28: =+[4]Report1!K33 -> 0.93162193 | BH28: =+[4]Report1!AN33 -> 0.90277429 | BI28: =+[4]Report1!AO33 -> 0.93162193 | BJ28: =+[4]Report1!R33 -> 46.788 | BK28: =+[4]Report1!S33 -> 1244.458 | BL28: =+[4]Report1!AD33 -> 2.6459776 | BM28: =+[4]Report1!AE33 -> 2.4532768 | BN28: 0 | BO28: 0 | BP28: =+[4]Report1!AJ33 -> 1098.932 | BQ28: =+[4]Report1!AK33 -> 914.2641 | BR28: 0 | BS28: 0 | BT28: =+[5]Report1!J33 -> 0.95994036 | BU28: =+[5]Report1!K33 -> 0.85734837 | BV28: =+[5]Report1!BA33 -> 0.95994036 | BW28: =+[5]Report1!BB33 -> 0.87075345 | BX28: =+[5]Report1!R33 -> 49.937 | BY28: =+[5]Report1!S33 -> 1071.331 | BZ28: =+[5]Report1!X33 -> 86.348273 | CA28: =+[5]Report1!Y33 -> 89.648556 | CB28: =+[5]Report1!AD33 -> 2.0445762 | CC28: =+[5]Report1!AE33 -> 2.177665 | CD28: =+[5]Report1!AJ33 -> 0 | CE28: =+[5]Report1!AK33 -> 0.038550177 | CF28: =+[5]Report1!AP33 -> 900.6318 | CG28: =+[5]Report1!AQ33 -> 1020.9723 | CH28: =+[5]Report1!AV33 -> 0 | CI28: =+[5]Report1!AW33 -> 94.586908
A29: =1+A28 -> 46017 | B29: =+Report1!J34 -> 0.91172477 | C29: =+Report1!K34 -> 0.87797148 | D29: =+Report1!AJ34 -> 0.91172477 | E29: =+Report1!AK34 -> 0.87902662 | F29: =+Report1!R34 -> 67.464 | G29: =+Report1!S34 -> 1616.846 | H29: =+Report1!X34 -> 2.3086535 | I29: =+Report1!Y34 -> 2.2333166 | J29: =+Report1!AD34 -> 845.98245 | K29: =+Report1!AE34 -> 869.04916 | L29: =+[1]Report1!J34 -> 0.97862741 | M29: =+[1]Report1!K34 -> 0.85433861 | N29: =+[1]Report1!BJ34 -> 0.97862741 | O29: =+[1]Report1!BK34 -> 0.88857226 | P29: =+[1]Report1!R34 -> 78.66 | Q29: =+[1]Report1!S34 -> 1467.845 | R29: =+[1]Report1!AL34 -> 1.5057971 | S29: =+[1]Report1!AM34 -> 2.0635973 | T29: =+[1]Report1!AR34 -> 0.087719298 | U29: =+[1]Report1!AS34 -> 0.18700323 | V29: =+[1]Report1!AX34 -> 434.63056 | W29: =+[1]Report1!AY34 -> 593.0218 | X29: =+[1]Report1!BD34 -> 477.85914 | Y29: =+[1]Report1!BE34 -> 492.92736 | Z29: =+[2]Report1!J34 -> 0.88724325 | AA29: =+[2]Report1!K34 -> 0.88112627 | AB29: =+[2]Report1!BC34 -> 0.88724325 | AC29: =+[2]Report1!BD34 -> 0.88112627 | AD29: =+[2]Report1!R34 -> 38.848 | AE29: =+[2]Report1!S34 -> 986.695 | AF29: =+[2]Report1!X34 -> 139.66254 | AG29: =+[2]Report1!Y34 -> 130.50196 | AH29: =+[2]Report1!AD34 -> 1.315383 | AI29: =+[2]Report1!AE34 -> 1.3454006 | AJ29: =+[2]Report1!AJ34 -> 1042.6112 | AK29: =+[2]Report1!AK34 -> 992.76743 | AL29: =+[6]Report1!AP34 -> 0 | AM29: =+[6]Report1!AQ34 -> 0 | AN29: =+[3]Report1!J34 -> 0.87025556 | AO29: =+[3]Report1!K34 -> 0.88265313 | AP29: =+[3]Report1!BN34 -> 0.87025556 | AQ29: =+[3]Report1!BO34 -> 0.88265313 | AR29: =+[3]Report1!R34 -> 45.81 | AS29: =+[3]Report1!S34 -> 1220.973 | AT29: =+[3]Report1!AF34 -> 100.16026 | AU29: =+[3]Report1!AG34 -> 102.03342 | AV29: =+[3]Report1!AL34 -> 1.4145383 | AW29: =+[3]Report1!AM34 -> 1.4010957 | AX29: =+[3]Report1!AR34 -> 0.08513425 | AY29: =+[3]Report1!AS34 -> 0.18166515 | AZ29: =+[3]Report1!AX34 -> 881.32198 | BA29: =+[3]Report1!AY34 -> 877.47121 | BB29: =+[3]Report1!BD34 -> 401.65029 | BC29: =+[3]Report1!BE34 -> 448.40398 | BD29: =+[3]Report1!BJ34 -> 2.9207597 | BE29: =+[3]Report1!BK34 -> 3.2701788 | BF29: =+[4]Report1!J34 -> 0.88392484 | BG29: =+[4]Report1!K34 -> 0.92978104 | BH29: =+[4]Report1!AN34 -> 0.88392484 | BI29: =+[4]Report1!AO34 -> 0.92978104 | BJ29: =+[4]Report1!R34 -> 47.401 | BK29: =+[4]Report1!S34 -> 1291.859 | BL29: =+[4]Report1!AD34 -> 2.5041666 | BM29: =+[4]Report1!AE34 -> 2.4551441 | BN29: 0 | BO29: 0 | BP29: =+[4]Report1!AJ34 -> 1051.1749 | BQ29: =+[4]Report1!AK34 -> 919.28764 | BR29: 0 | BS29: 0 | BT29: =+[5]Report1!J34 -> 0.9139253 | BU29: =+[5]Report1!K34 -> 0.85954889 | BV29: =+[5]Report1!BA34 -> 0.9139253 | BW29: =+[5]Report1!BB34 -> 0.8724578 | BX29: =+[5]Report1!R34 -> 46.216 | BY29: =+[5]Report1!S34 -> 1117.547 | BZ29: =+[5]Report1!X34 -> 95.833653 | CA29: =+[5]Report1!Y34 -> 89.904339 | CB29: =+[5]Report1!AD34 -> 2.1875541 | CC29: =+[5]Report1!AE34 -> 2.1780739 | CD29: =+[5]Report1!AJ34 -> 0 | CE29: =+[5]Report1!AK34 -> 0.03695594 | CF29: =+[5]Report1!AP34 -> 981.1178 | CG29: =+[5]Report1!AQ34 -> 1019.3242 | CH29: =+[5]Report1!AV34 -> 0 | CI29: =+[5]Report1!AW34 -> 90.67528
A30: =1+A29 -> 46018 | B30: =+Report1!J35 -> 0.843469 | C30: =+Report1!K35 -> 0.87673656 | D30: =+Report1!AJ35 -> 0.843469 | E30: =+Report1!AK35 -> 0.87775246 | F30: =+Report1!R35 -> 57.66 | G30: =+Report1!S35 -> 1674.506 | H30: =+Report1!X35 -> 2.4779917 | I30: =+Report1!Y35 -> 2.2417417 | J30: =+Report1!AD35 -> 950.13978 | K30: =+Report1!AE35 -> 871.84144 | L30: =+[1]Report1!J35 -> 0.93182345 | M30: =+[1]Report1!K35 -> 0.85783366 | N30: =+[1]Report1!BJ35 -> 0.93182345 | O30: =+[1]Report1!BK35 -> 0.89059767 | P30: =+[1]Report1!R35 -> 75.625 | Q30: =+[1]Report1!S35 -> 1543.47 | R30: =+[1]Report1!AL35 -> 1.6126281 | S30: =+[1]Report1!AM35 -> 2.0415013 | T30: =+[1]Report1!AR35 -> 0.084628099 | U30: =+[1]Report1!AS35 -> 0.18198718 | V30: =+[1]Report1!AX35 -> 422.10235 | W30: =+[1]Report1!AY35 -> 584.64731 | X30: =+[1]Report1!BD35 -> 532.32 | Y30: =+[1]Report1!BE35 -> 494.85747 | Z30: =+[2]Report1!J35 -> 0.97340971 | AA30: =+[2]Report1!K35 -> 0.88461576 | AB30: =+[2]Report1!BC35 -> 0.97340971 | AC30: =+[2]Report1!BD35 -> 0.88461576 | AD30: =+[2]Report1!R35 -> 42.837 | AE30: =+[2]Report1!S35 -> 1029.532 | AF30: =+[2]Report1!X35 -> 122.70769 | AG30: =+[2]Report1!Y35 -> 130.17765 | AH30: =+[2]Report1!AD35 -> 1.2302449 | AI30: =+[2]Report1!AE35 -> 1.3406091 | AJ30: =+[2]Report1!AJ35 -> 953.73299 | AK30: =+[2]Report1!AK35 -> 991.14328 | AL30: =+[6]Report1!AP35 -> 0 | AM30: =+[6]Report1!AQ35 -> 0 | AN30: =+[3]Report1!J35 -> 0.96192326 | AO30: =+[3]Report1!K35 -> 0.88562435 | AP30: =+[3]Report1!BN35 -> 0.96192326 | AQ30: =+[3]Report1!BO35 -> 0.88562435 | AR30: =+[3]Report1!R35 -> 51.817 | AS30: =+[3]Report1!S35 -> 1272.79 | AT30: =+[3]Report1!AF35 -> 93.803588 | AU30: =+[3]Report1!AG35 -> 101.69837 | AV30: =+[3]Report1!AL35 -> 1.2872223 | AW30: =+[3]Report1!AM35 -> 1.3964597 | AX30: =+[3]Report1!AR35 -> 0.084914217 | AY30: =+[3]Report1!AS35 -> 0.17772629 | AZ30: =+[3]Report1!AX35 -> 818.36193 | BA30: =+[3]Report1!AY35 -> 875.06479 | BB30: =+[3]Report1!BD35 -> 434.63149 | BC30: =+[3]Report1!BE35 -> 447.84328 | BD30: =+[3]Report1!BJ35 -> 2.510759 | BE30: =+[3]Report1!BK35 -> 3.2392618 | BF30: =+[4]Report1!J35 -> 0.95056341 | BG30: =+[4]Report1!K35 -> 0.93053969 | BH30: =+[4]Report1!AN35 -> 0.95056341 | BI30: =+[4]Report1!AO35 -> 0.93053969 | BJ30: =+[4]Report1!R35 -> 50.04 | BK30: =+[4]Report1!S35 -> 1341.899 | BL30: =+[4]Report1!AD35 -> 2.3441247 | BM30: =+[4]Report1!AE35 -> 2.4510041 | BN30: 0 | BO30: 0 | BP30: =+[4]Report1!AJ35 -> 987.67445 | BQ30: =+[4]Report1!AK35 -> 921.83782 | BR30: 0 | BS30: 0 | BT30: =+[5]Report1!J35 -> 0.84750799 | BU30: =+[5]Report1!K35 -> 0.85912347 | BV30: =+[5]Report1!BA35 -> 0.84750799 | BW30: =+[5]Report1!BB35 -> 0.87156353 | BX30: =+[5]Report1!R35 -> 40.357 | BY30: =+[5]Report1!S35 -> 1157.904 | BZ30: =+[5]Report1!X35 -> 104.2186 | CA30: =+[5]Report1!Y35 -> 90.403241 | CB30: =+[5]Report1!AD35 -> 2.4927522 | CC30: =+[5]Report1!AE35 -> 2.1890416 | CD30: =+[5]Report1!AJ35 -> 0 | CE30: =+[5]Report1!AK35 -> 0.035667896 | CF30: =+[5]Report1!AP35 -> 1056.8662 | CG30: =+[5]Report1!AQ35 -> 1020.6326 | CH30: =+[5]Report1!AV35 -> 0 | CI30: =+[5]Report1!AW35 -> 87.51493
