Workbook

Sheet eff all
A1: DATE | B1: PM 11 | L1: PM 12 | Z1: PM 14 | AN1: PM 15 | BF1: PM 16 | BT1: PM 17
B2: Eff Avaliable | D2: Eff Running | F2: PHP (ton) | H2: STEAM/Ton FG | J2: ELECTRIC/ton FG | L2: Eff Avaliable | N2: Eff Running | P2: PHP (ton) | R2: STEAM/ton FG | T2: STEAM DIP/ton FG | V2: ELECTRIC/ton FG | X2: ELECTRIC DIP/ton FG | Z2: Eff Avaliable | AB2: Eff Running | AD2: PHP (ton) | AF2: GAS /ton FG | AH2: STEAM /ton FG | AJ2: ELECTRIC /ton FG | AL2: Electric WPL /ton FG | AN2: Eff Avaliable | AP2: Eff Running | AR2: PHP (ton) | AT2: GAS /ton FG | AV2: STEAM /ton FG | AX2: STEAM DIP /ton FG | AZ2: ELECTRIC /ton FG | BB2: ELECTRIC DIP /ton FG | BD2: Electric WPL /ton FG | BF2: Eff Avaliable | BH2: Eff Running | BJ2: PHP (ton) | BL2: STEAM /ton FG | BN2: STEAM DIP/ton FG | BP2: ELECTRIC /ton FG | BR2: ELECTRIC DIP/ton FG | BT2: Eff Avaliable | BV2: Eff Running | BX2: PHP (ton) | BZ2: GAS /ton FG | CB2: STEAM /ton FG | CD2: STEAM DIP /ton FG | CF2: ELECTRIC /ton FG | CH2: ELECTRIC DIP /ton FG | CJ2: ELECTRIC WPL /ton FG
B3: Today | C3: Todate | D3: Today | E3: Todate | F3: Today | G3: Todate | H3: Today | I3: Todate | J3: Today | K3: Todate | L3: Today | M3: Todate | N3: Today | O3: Todate | P3: Today | Q3: Todate | R3: Today | S3: Todate | T3: Today | U3: Todate | V3: Today | W3: Todate | X3: Today | Y3: Todate | Z3: Today | AA3: Todate | AB3: Today | AC3: Todate | AD3: Today | AE3: Todate | AF3: Today | AG3: Todate | AH3: Today | AI3: Todate | AJ3: Today | AK3: Todate | AL3: Today | AM3: Todate | AN3: Today | AO3: Todate | AP3: Today | AQ3: Todate | AR3: Today | AS3: Todate | AT3: Today | AU3: Todate | AV3: Today | AW3: Todate | AX3: Today | AY3: Todate | AZ3: Today | BA3: Todate | BB3: Today | BC3: Todate | BD3: Today | BE3: Todate | BF3: Today | BG3: Todate | BH3: Today | BI3: Todate | BJ3: Today | BK3: Todate | BL3: Today | BM3: Todate | BN3: Today | BO3: Todate | BP3: Today | BQ3: Todate | BR3: Today | BS3: Todate | BT3: Today | BU3: Todate | BV3: Today | BW3: Todate | BX3: Today | BY3: Todate | BZ3: Today | CA3: Todate | CB3: Today | CC3: Todate | CD3: Today | CE3: Todate | CF3: Today | CG3: Todate | CH3: Today | CI3: Todate | CJ3: Today | CK3: Todate
A4: =+Report1!A9 -> 45931 | B4: =+Report1!J9 -> 0.27966994 | C4: =+Report1!K9 -> 0.27966994 | D4: =+Report1!AJ9 -> 0.40002229 | E4: =+Report1!AK9 -> 0.40002229 | F4: =+Report1!R9 -> 17.941 | G4: =+Report1!S9 -> 17.941 | H4: =+Report1!X9 -> 2.9326125 | I4: =+Report1!Y9 -> 2.9326125 | J4: =+Report1!AD9 -> 1661.5183 | K4: =+Report1!AE9 -> 1661.5183 | L4: =+[1]Report1!J9 -> 0 | M4: =+[1]Report1!K9 -> 0 | N4: =+[1]Report1!BJ9 -> #DIV/0! | O4: =+[1]Report1!BK9 -> #DIV/0! | P4: =+[1]Report1!R9 -> 0 | Q4: =+[1]Report1!S9 -> 0 | R4: =+[1]Report1!AL9 -> 0 | S4: =+[1]Report1!AM9 -> 0 | T4: =+[1]Report1!AR9 -> 0 | U4: =+[1]Report1!AS9 -> 0 | V4: =+[1]Report1!AX9 -> 0 | W4: =+[1]Report1!AY9 -> 0 | X4: =+[1]Report1!BD9 -> 0 | Y4: =+[1]Report1!BE9 -> 0 | Z4: =+[2]Report1!J9 -> 0.20474 | AA4: =+[2]Report1!K9 -> 0.20474 | AB4: =+[2]Report1!BC9 -> 0.40948 | AC4: =+[2]Report1!BD9 -> 0.40948 | AD4: =+[2]Report1!R9 -> 8.913 | AE4: =+[2]Report1!S9 -> 8.913 | AF4: =+[2]Report1!X9 -> 244.31698 | AG4: =+[2]Report1!Y9 -> 244.31698 | AH4: =+[2]Report1!AD9 -> 4.3980702 | AI4: =+[2]Report1!AE9 -> 4.3980702 | AJ4: =+[2]Report1!AJ9 -> 2759.7105 | AK4: =+[2]Report1!AK9 -> 2759.7105 | AL4: =+[3]Report1!AP9 -> 0 | AM4: =+[3]Report1!AQ9 -> 0 | AN4: =+[4]Report1!J9 -> 0.57523912 | AO4: =+[4]Report1!K9 -> 0.57523912 | AP4: =+[4]Report1!BN9 -> 0.65489845 | AQ4: =+[4]Report1!BO9 -> 0.65489845 | AR4: =+[4]Report1!R9 -> 29.349 | AS4: =+[4]Report1!S9 -> 29.349 | AT4: =+[4]Report1!AF9 -> 137.80377 | AU4: =+[4]Report1!AG9 -> 137.80377 | AV4: =+[4]Report1!AL9 -> 1.6457119 | AW4: =+[4]Report1!AM9 -> 1.6457119 | AX4: =+[4]Report1!AR9 -> 0 | AY4: =+[4]Report1!AS9 -> 0 | AZ4: =+[4]Report1!AX9 -> 1246.9692 | BA4: =+[4]Report1!AY9 -> 1246.9692 | BB4: =+[4]Report1!BD9 -> 0 | BC4: =+[4]Report1!BE9 -> 0 | BD4: =+[4]Report1!BJ9 -> 0 | BE4: =+[4]Report1!BK9 -> 0 | BF4: =+[5]Report1!J9 -> 0.37609655 | BG4: =+[5]Report1!K9 -> 0.37609655 | BH4: =+[5]Report1!AN9 -> 0.4828526 | BI4: =+[5]Report1!AO9 -> 0.4828526 | BJ4: =+[5]Report1!R9 -> 18.686 | BK4: =+[5]Report1!S9 -> 18.686 | BL4: =+[5]Report1!AD9 -> 4.2598737 | BM4: =+[5]Report1!AE9 -> 4.2598737 | BN4: 0 | BO4: 0 | BP4: =+[5]Report1!AJ9 -> 2001.7446 | BQ4: =+[5]Report1!AK9 -> 2001.7446 | BR4: 0 | BS4: 0 | BT4: =+[6]Report1!J9 -> 0.063779031 | BU4: =+[6]Report1!K9 -> 0.063779031 | BV4: =+[6]Report1!BA9 -> #DIV/0! | BW4: =+[6]Report1!BB9 -> #DIV/0! | BX4: =+[6]Report1!R9 -> 3.364 | BY4: =+[6]Report1!S9 -> 3.364 | BZ4: =+[6]Report1!X9 -> 0 | CA4: =+[6]Report1!Y9 -> 0 | CB4: =+[6]Report1!AD9 -> 0.11890606 | CC4: =+[6]Report1!AE9 -> 0.11890606 | CD4: =+[6]Report1!AJ9 -> 0 | CE4: =+[6]Report1!AK9 -> 0 | CF4: =+[6]Report1!AP9 -> 1542.0036 | CG4: =+[6]Report1!AQ9 -> 1542.0036 | CH4: =+[6]Report1!AV9 -> 0 | CI4: =+[6]Report1!AW9 -> 0
A5: =1+A4 -> 45932 | B5: =+Report1!J10 -> 0.75908102 | C5: =+Report1!K10 -> 0.53436518 | D5: =+Report1!AJ10 -> 0.75908102 | E5: =+Report1!AK10 -> 0.62209629 | F5: =+Report1!R10 -> 55.192 | G5: =+Report1!S10 -> 73.133 | H5: =+Report1!X10 -> 2.7908936 | I5: =+Report1!Y10 -> 2.8256601 | J5: =+Report1!AD10 -> 1050.2279 | K5: =+Report1!AE10 -> 1200.1898 | L5: =+[1]Report1!J10 -> 0.63705352 | M5: =+[1]Report1!K10 -> 0.28260253 | N5: =+[1]Report1!BJ10 -> 0.76446422 | O5: =+[1]Report1!BK10 -> 0.76446422 | P5: =+[1]Report1!R10 -> 35.399 | Q5: =+[1]Report1!S10 -> 35.399 | R5: =+[1]Report1!AL10 -> 4.1513602 | S5: =+[1]Report1!AM10 -> 4.2126331 | T5: =+[1]Report1!AR10 -> 0.42939066 | U5: =+[1]Report1!AS10 -> 0.42939066 | V5: =+[1]Report1!AX10 -> 942.90714 | W5: =+[1]Report1!AY10 -> 1207.4415 | X5: =+[1]Report1!BD10 -> 981.29891 | Y5: =+[1]Report1!BE10 -> 1224.5261 | Z5: =+[2]Report1!J10 -> 0.84868927 | AA5: =+[2]Report1!K10 -> 0.52514178 | AB5: =+[2]Report1!BC10 -> 0.84868927 | AC5: =+[2]Report1!BD10 -> 0.70133105 | AD5: =+[2]Report1!R10 -> 36.587 | AE5: =+[2]Report1!S10 -> 45.5 | AF5: =+[2]Report1!X10 -> 125.28724 | AG5: =+[2]Report1!Y10 -> 148.60399 | AH5: =+[2]Report1!AD10 -> 1.656326 | AI5: =+[2]Report1!AE10 -> 2.1934066 | AJ5: =+[2]Report1!AJ10 -> 1112.8045 | AK5: =+[2]Report1!AK10 -> 1435.4171 | AL5: =+[3]Report1!AP10 -> 0 | AM5: =+[3]Report1!AQ10 -> 0 | AN5: =+[4]Report1!J10 -> 0.91422026 | AO5: =+[4]Report1!K10 -> 0.74490575 | AP5: =+[4]Report1!BN10 -> 0.91422026 | AQ5: =+[4]Report1!BO10 -> 0.79308985 | AR5: =+[4]Report1!R10 -> 46.741 | AS5: =+[4]Report1!S10 -> 76.09 | AT5: =+[4]Report1!AF10 -> 119.51212 | AU5: =+[4]Report1!AG10 -> 126.56747 | AV5: =+[4]Report1!AL10 -> 1.4312916 | AW5: =+[4]Report1!AM10 -> 1.5139966 | AX5: =+[4]Report1!AR10 -> 0 | AY5: =+[4]Report1!AS10 -> 0 | AZ5: =+[4]Report1!AX10 -> 958.56272 | BA5: =+[4]Report1!AY10 -> 1069.8052 | BB5: =+[4]Report1!BD10 -> 0 | BC5: =+[4]Report1!BE10 -> 0 | BD5: =+[4]Report1!BJ10 -> 0 | BE5: =+[4]Report1!BK10 -> 0 | BF5: =+[5]Report1!J10 -> 0.95144341 | BG5: =+[5]Report1!K10 -> 0.67262167 | BH5: =+[5]Report1!AN10 -> 0.95144341 | BI5: =+[5]Report1!AO10 -> 0.75333867 | BJ5: =+[5]Report1!R10 -> 50.273 | BK5: =+[5]Report1!S10 -> 68.959 | BL5: =+[5]Report1!AD10 -> 2.3352495 | BM5: =+[5]Report1!AE10 -> 2.85677 | BN5: 0 | BO5: 0 | BP5: =+[5]Report1!AJ10 -> 877.57564 | BQ5: =+[5]Report1!AK10 -> 1182.1946 | BR5: 0 | BS5: 0 | BT5: =+[6]Report1!J10 -> 0 | BU5: =+[6]Report1!K10 -> 0.031889516 | BV5: =+[6]Report1!BA10 -> #DIV/0! | BW5: =+[6]Report1!BB10 -> #DIV/0! | BX5: =+[6]Report1!R10 -> 0 | BY5: =+[6]Report1!S10 -> 3.364 | BZ5: =+[6]Report1!X10 -> 0 | CA5: =+[6]Report1!Y10 -> 0 | CB5: =+[6]Report1!AD10 -> 0 | CC5: =+[6]Report1!AE10 -> 0.14863258 | CD5: =+[6]Report1!AJ10 -> 0 | CE5: =+[6]Report1!AK10 -> 0 | CF5: =+[6]Report1!AP10 -> 0 | CG5: =+[6]Report1!AQ10 -> 2806.6231 | CH5: =+[6]Report1!AV10 -> 0 | CI5: =+[6]Report1!AW10 -> 0
A6: =1+A5 -> 45933 | B6: =+Report1!J11 -> 1.04961 | C6: =+Report1!K11 -> 0.72564174 | D6: =+Report1!AJ11 -> 1.04961 | E6: =+Report1!AK11 -> 0.79624621 | F6: =+Report1!R11 -> 84.813 | G6: =+Report1!S11 -> 157.946 | H6: =+Report1!X11 -> 1.8975747 | I6: =+Report1!Y11 -> 2.3273017 | J6: =+Report1!AD11 -> 651.81305 | K6: =+Report1!AE11 -> 905.72537 | L6: =+[1]Report1!J11 -> 0.89617874 | M6: =+[1]Report1!K11 -> 0.4794761 | N6: =+[1]Report1!BJ11 -> 0.89617874 | O6: =+[1]Report1!BK11 -> 0.83835935 | P6: =+[1]Report1!R11 -> 53.036 | Q6: =+[1]Report1!S11 -> 88.435 | R6: =+[1]Report1!AL11 -> 2.5553963 | S6: =+[1]Report1!AM11 -> 3.2187595 | T6: =+[1]Report1!AR11 -> 0.19043668 | U6: =+[1]Report1!AS11 -> 0.28608583 | V6: =+[1]Report1!AX11 -> 680.19326 | W6: =+[1]Report1!AY11 -> 891.24159 | X6: =+[1]Report1!BD11 -> 513.5606 | Y6: =+[1]Report1!BE11 -> 798.14779 | Z6: =+[2]Report1!J11 -> 0.85738843 | AA6: =+[2]Report1!K11 -> 0.63456998 | AB6: =+[2]Report1!BC11 -> 0.85738843 | AC6: =+[2]Report1!BD11 -> 0.76314407 | AD6: =+[2]Report1!R11 -> 36.483 | AE6: =+[2]Report1!S11 -> 81.983 | AF6: =+[2]Report1!X11 -> 123.84804 | AG6: =+[2]Report1!Y11 -> 137.58742 | AH6: =+[2]Report1!AD11 -> 1.5267385 | AI6: =+[2]Report1!AE11 -> 1.8967347 | AJ6: =+[2]Report1!AJ11 -> 1072.6152 | AK6: =+[2]Report1!AK11 -> 1273.9678 | AL6: =+[3]Report1!AP11 -> 0 | AM6: =+[3]Report1!AQ11 -> 0 | AN6: =+[4]Report1!J11 -> 0.91821354 | AO6: =+[4]Report1!K11 -> 0.80302507 | AP6: =+[4]Report1!BN11 -> 0.91821354 | AQ6: =+[4]Report1!BO11 -> 0.83681617 | AR6: =+[4]Report1!R11 -> 47.324 | AS6: =+[4]Report1!S11 -> 123.414 | AT6: =+[4]Report1!AF11 -> 130.7297 | AU6: =+[4]Report1!AG11 -> 128.1635 | AV6: =+[4]Report1!AL11 -> 1.4516947 | AW6: =+[4]Report1!AM11 -> 1.4901065 | AX6: =+[4]Report1!AR11 -> 0.18595216 | AY6: =+[4]Report1!AS11 -> 0.071304714 | AZ6: =+[4]Report1!AX11 -> 894.30775 | BA6: =+[4]Report1!AY11 -> 1002.5094 | BB6: =+[4]Report1!BD11 -> 485.05621 | BC6: =+[4]Report1!BE11 -> 185.99835 | BD6: =+[4]Report1!BJ11 -> 4.0148762 | BE6: =+[4]Report1!BK11 -> 1.5395336 | BF6: =+[5]Report1!J11 -> 0.79954858 | BG6: =+[5]Report1!K11 -> 0.71604177 | BH6: =+[5]Report1!AN11 -> 0.79954858 | BI6: =+[5]Report1!AO11 -> 0.77034534 | BJ6: =+[5]Report1!R11 -> 42.622 | BK6: =+[5]Report1!S11 -> 111.581 | BL6: =+[5]Report1!AD11 -> 2.9327577 | BM6: =+[5]Report1!AE11 -> 2.885796 | BN6: 0 | BO6: 0 | BP6: =+[5]Report1!AJ11 -> 1059.4163 | BQ6: =+[5]Report1!AK11 -> 1135.2954 | BR6: 0 | BS6: 0 | BT6: =+[6]Report1!J11 -> 0 | BU6: =+[6]Report1!K11 -> 0.021259677 | BV6: =+[6]Report1!BA11 -> #DIV/0! | BW6: =+[6]Report1!BB11 -> #DIV/0! | BX6: =+[6]Report1!R11 -> 0 | BY6: =+[6]Report1!S11 -> 3.364 | BZ6: =+[6]Report1!X11 -> 0 | CA6: =+[6]Report1!Y11 -> 0 | CB6: =+[6]Report1!AD11 -> 0 | CC6: =+[6]Report1!AE11 -> 0.1783591 | CD6: =+[6]Report1!AJ11 -> 0 | CE6: =+[6]Report1!AK11 -> 0 | CF6: =+[6]Report1!AP11 -> 0 | CG6: =+[6]Report1!AQ11 -> 3318.5791 | CH6: =+[6]Report1!AV11 -> 0 | CI6: =+[6]Report1!AW11 -> 0
A7: =1+A6 -> 45934 | B7: =+Report1!J12 -> 0.76859272 | C7: =+Report1!K12 -> 0.73703148 | D7: =+Report1!AJ12 -> 0.76859272 | E7: =+Report1!AK12 -> 0.78840194 | F7: =+Report1!R12 -> 60.373 | G7: =+Report1!S12 -> 218.319 | H7: =+Report1!X12 -> 2.4247925 | I7: =+Report1!Y12 -> 2.3542614 | J7: =+Report1!AD12 -> 804.43973 | K7: =+Report1!AE12 -> 877.71628 | L7: =+[1]Report1!J12 -> 0.55182441 | M7: =+[1]Report1!K12 -> 0.49705656 | N7: =+[1]Report1!BJ12 -> 0.55182441 | O7: =+[1]Report1!BK12 -> 0.73535189 | P7: =+[1]Report1!R12 -> 32.671 | Q7: =+[1]Report1!S12 -> 121.106 | R7: =+[1]Report1!AL12 -> 3.7707753 | S7: =+[1]Report1!AM12 -> 3.3676779 | T7: =+[1]Report1!AR12 -> 0.25710875 | U7: =+[1]Report1!AS12 -> 0.27826862 | V7: =+[1]Report1!AX12 -> 906.68666 | W7: =+[1]Report1!AY12 -> 895.40824 | X7: =+[1]Report1!BD12 -> 688.39338 | Y7: =+[1]Report1!BE12 -> 768.53913 | Z7: =+[2]Report1!J12 -> 0.91146148 | AA7: =+[2]Report1!K12 -> 0.70620875 | AB7: =+[2]Report1!BC12 -> 0.91146148 | AC7: =+[2]Report1!BD12 -> 0.80699389 | AD7: =+[2]Report1!R12 -> 41.1 | AE7: =+[2]Report1!S12 -> 123.083 | AF7: =+[2]Report1!X12 -> 108.17045 | AG7: =+[2]Report1!Y12 -> 127.76447 | AH7: =+[2]Report1!AD12 -> 1.4793187 | AI7: =+[2]Report1!AE12 -> 1.7573507 | AJ7: =+[2]Report1!AJ12 -> 902.34647 | AK7: =+[2]Report1!AK12 -> 1149.8756 | AL7: =+[3]Report1!AP12 -> 0 | AM7: =+[3]Report1!AQ12 -> 0 | AN7: =+[4]Report1!J12 -> 0.79414901 | AO7: =+[4]Report1!K12 -> 0.80079737 | AP7: =+[4]Report1!BN12 -> 0.79414901 | AQ7: =+[4]Report1!BO12 -> 0.82577361 | AR7: =+[4]Report1!R12 -> 40.896 | AS7: =+[4]Report1!S12 -> 164.31 | AT7: =+[4]Report1!AF12 -> 143.4271 | AU7: =+[4]Report1!AG12 -> 131.96254 | AV7: =+[4]Report1!AL12 -> 1.5038146 | AW7: =+[4]Report1!AM12 -> 1.4935183 | AX7: =+[4]Report1!AR12 -> 0.21273474 | AY7: =+[4]Report1!AS12 -> 0.10650599 | AZ7: =+[4]Report1!AX12 -> 934.23415 | BA7: =+[4]Report1!AY12 -> 985.51604 | BB7: =+[4]Report1!BD12 -> 540.60299 | BC7: =+[4]Report1!BE12 -> 274.25781 | BD7: =+[4]Report1!BJ12 -> 3.6678404 | BE7: =+[4]Report1!BK12 -> 2.0692593 | BF7: =+[5]Report1!J12 -> 0.88507614 | BG7: =+[5]Report1!K12 -> 0.75890216 | BH7: =+[5]Report1!AN12 -> 0.88507614 | BI7: =+[5]Report1!AO12 -> 0.80105226 | BJ7: =+[5]Report1!R12 -> 46.851 | BK7: =+[5]Report1!S12 -> 158.432 | BL7: =+[5]Report1!AD12 -> 2.7021835 | BM7: =+[5]Report1!AE12 -> 2.8314987 | BN7: 0 | BO7: 0 | BP7: =+[5]Report1!AJ12 -> 1068.1283 | BQ7: =+[5]Report1!AK12 -> 1115.433 | BR7: 0 | BS7: 0 | BT7: =+[6]Report1!J12 -> 0 | BU7: =+[6]Report1!K12 -> 0.015944758 | BV7: =+[6]Report1!BA12 -> #DIV/0! | BW7: =+[6]Report1!BB12 -> #DIV/0! | BX7: =+[6]Report1!R12 -> 0 | BY7: =+[6]Report1!S12 -> 3.364 | BZ7: =+[6]Report1!X12 -> 0 | CA7: =+[6]Report1!Y12 -> 0 | CB7: =+[6]Report1!AD12 -> 0 | CC7: =+[6]Report1!AE12 -> 0.20808561 | CD7: =+[6]Report1!AJ12 -> 0 | CE7: =+[6]Report1!AK12 -> 0 | CF7: =+[6]Report1!AP12 -> 0 | CG7: =+[6]Report1!AQ12 -> 4500.6361 | CH7: =+[6]Report1!AV12 -> 0 | CI7: =+[6]Report1!AW12 -> 0
A8: =1+A7 -> 45935 | B8: =+Report1!J13 -> 0.8903163 | C8: =+Report1!K13 -> 0.76944113 | D8: =+Report1!AJ13 -> 0.8903163 | E8: =+Report1!AK13 -> 0.81111725 | F8: =+Report1!R13 -> 70.711 | G8: =+Report1!S13 -> 289.03 | H8: =+Report1!X13 -> 2.072167 | I8: =+Report1!Y13 -> 2.2852472 | J8: =+Report1!AD13 -> 697.06948 | K8: =+Report1!AE13 -> 833.52116 | L8: =+[1]Report1!J13 -> 0.71890526 | M8: =+[1]Report1!K13 -> 0.54222786 | N8: =+[1]Report1!BJ13 -> 0.71890526 | O8: =+[1]Report1!BK13 -> 0.7308383 | P8: =+[1]Report1!R13 -> 44.783 | Q8: =+[1]Report1!S13 -> 165.889 | R8: =+[1]Report1!AL13 -> 2.7971105 | S8: =+[1]Report1!AM13 -> 3.2136489 | T8: =+[1]Report1!AR13 -> 0.23669696 | U8: =+[1]Report1!AS13 -> 0.26704604 | V8: =+[1]Report1!AX13 -> 701.36257 | W8: =+[1]Report1!AY13 -> 843.02413 | X8: =+[1]Report1!BD13 -> 578.13545 | Y8: =+[1]Report1!BE13 -> 717.13821 | Z8: =+[2]Report1!J13 -> 0.92939545 | AA8: =+[2]Report1!K13 -> 0.75069483 | AB8: =+[2]Report1!BC13 -> 0.92939545 | AC8: =+[2]Report1!BD13 -> 0.83410195 | AD8: =+[2]Report1!R13 -> 40.324 | AE8: =+[2]Report1!S13 -> 163.407 | AF8: =+[2]Report1!X13 -> 105.11704 | AG8: =+[2]Report1!Y13 -> 122.17576 | AH8: =+[2]Report1!AD13 -> 1.5003472 | AI8: =+[2]Report1!AE13 -> 1.6939299 | AJ8: =+[2]Report1!AJ13 -> 976.60153 | AK8: =+[2]Report1!AK13 -> 1107.1167 | AL8: =+[3]Report1!AP13 -> 0 | AM8: =+[3]Report1!AQ13 -> 0 | AN8: =+[4]Report1!J13 -> 0.61549655 | AO8: =+[4]Report1!K13 -> 0.76362119 | AP8: =+[4]Report1!BN13 -> 0.61549655 | AQ8: =+[4]Report1!BO13 -> 0.78254128 | AR8: =+[4]Report1!R13 -> 31.696 | AS8: =+[4]Report1!S13 -> 196.006 | AT8: =+[4]Report1!AF13 -> 154.55453 | AU8: =+[4]Report1!AG13 -> 135.61588 | AV8: =+[4]Report1!AL13 -> 2.1012115 | AW8: =+[4]Report1!AM13 -> 1.591788 | AX8: =+[4]Report1!AR13 -> 0.29025745 | AY8: =+[4]Report1!AS13 -> 0.13622032 | AZ8: =+[4]Report1!AX13 -> 1215.3104 | BA8: =+[4]Report1!AY13 -> 1022.6759 | BB8: =+[4]Report1!BD13 -> 662.74483 | BC8: =+[4]Report1!BE13 -> 337.07978 | BD8: =+[4]Report1!BJ13 -> 3.8175164 | BE8: =+[4]Report1!BK13 -> 2.3519688 | BF8: =+[5]Report1!J13 -> 0.86866891 | BG8: =+[5]Report1!K13 -> 0.77983074 | BH8: =+[5]Report1!AN13 -> 0.86866891 | BI8: =+[5]Report1!AO13 -> 0.81451777 | BJ8: =+[5]Report1!R13 -> 42.722 | BK8: =+[5]Report1!S13 -> 201.154 | BL8: =+[5]Report1!AD13 -> 2.8861008 | BM8: =+[5]Report1!AE13 -> 2.8430953 | BN8: 0 | BO8: 0 | BP8: =+[5]Report1!AJ13 -> 1140.8867 | BQ8: =+[5]Report1!AK13 -> 1120.839 | BR8: 0 | BS8: 0 | BT8: =+[6]Report1!J13 -> 0 | BU8: =+[6]Report1!K13 -> 0.012755806 | BV8: =+[6]Report1!BA13 -> #DIV/0! | BW8: =+[6]Report1!BB13 -> #DIV/0! | BX8: =+[6]Report1!R13 -> 0 | BY8: =+[6]Report1!S13 -> 3.364 | BZ8: =+[6]Report1!X13 -> 0 | CA8: =+[6]Report1!Y13 -> 0 | CB8: =+[6]Report1!AD13 -> 0 | CC8: =+[6]Report1!AE13 -> 0.23781213 | CD8: =+[6]Report1!AJ13 -> 0 | CE8: =+[6]Report1!AK13 -> 0 | CF8: =+[6]Report1!AP13 -> 0 | CG8: =+[6]Report1!AQ13 -> 5398.5196 | CH8: =+[6]Report1!AV13 -> 0 | CI8: =+[6]Report1!AW13 -> 0
A9: =1+A8 -> 45936 | B9: =+Report1!J14 -> 0.82304459 | C9: =+Report1!K14 -> 0.77853842 | D9: =+Report1!AJ14 -> 0.82304459 | E9: =+Report1!AK14 -> 0.8132317 | F9: =+Report1!R14 -> 63.195 | G9: =+Report1!S14 -> 352.225 | H9: =+Report1!X14 -> 2.2893583 | I9: =+Report1!Y14 -> 2.2859848 | J9: =+Report1!AD14 -> 842.38848 | K9: =+Report1!AE14 -> 835.1121 | L9: =+[1]Report1!J14 -> 0.92244268 | M9: =+[1]Report1!K14 -> 0.60950089 | N9: =+[1]Report1!BJ14 -> 0.92244268 | O9: =+[1]Report1!BK14 -> 0.77388286 | P9: =+[1]Report1!R14 -> 60.667 | Q9: =+[1]Report1!S14 -> 226.556 | R9: =+[1]Report1!AL14 -> 2.2418119 | S9: =+[1]Report1!AM14 -> 2.9534111 | T9: =+[1]Report1!AR14 -> 0.16977929 | U9: =+[1]Report1!AS14 -> 0.24100002 | V9: =+[1]Report1!AX14 -> 594.68261 | W9: =+[1]Report1!AY14 -> 776.52342 | X9: =+[1]Report1!BD14 -> 432.94378 | Y9: =+[1]Report1!BE14 -> 641.03683 | Z9: =+[2]Report1!J14 -> 0.95068274 | AA9: =+[2]Report1!K14 -> 0.7842481 | AB9: =+[2]Report1!BC14 -> 0.95068274 | AC9: =+[2]Report1!BD14 -> 0.85543695 | AD9: =+[2]Report1!R14 -> 41.719 | AE9: =+[2]Report1!S14 -> 205.126 | AF9: =+[2]Report1!X14 -> 107.09364 | AG9: =+[2]Report1!Y14 -> 119.10832 | AH9: =+[2]Report1!AD14 -> 1.4166207 | AI9: =+[2]Report1!AE14 -> 1.6375301 | AJ9: =+[2]Report1!AJ14 -> 897.06704 | AK9: =+[2]Report1!AK14 -> 1064.3963 | AL9: =+[3]Report1!AP14 -> 0 | AM9: =+[3]Report1!AQ14 -> 0 | AN9: =+[4]Report1!J14 -> 0.60328659 | AO9: =+[4]Report1!K14 -> 0.73598063 | AP9: =+[4]Report1!BN14 -> 0.60328659 | AQ9: =+[4]Report1!BO14 -> 0.75100806 | AR9: =+[4]Report1!R14 -> 32.256 | AS9: =+[4]Report1!S14 -> 228.262 | AT9: =+[4]Report1!AF14 -> 155.08 | AU9: =+[4]Report1!AG14 -> 138.36638 | AV9: =+[4]Report1!AL14 -> 1.8446181 | AW9: =+[4]Report1!AM14 -> 1.6275157 | AX9: =+[4]Report1!AR14 -> 0.21081349 | AY9: =+[4]Report1!AS14 -> 0.14676118 | AZ9: =+[4]Report1!AX14 -> 1128.3092 | BA9: =+[4]Report1!AY14 -> 1037.6031 | BB9: =+[4]Report1!BD14 -> 515.5506 | BC9: =+[4]Report1!BE14 -> 362.29973 | BD9: =+[4]Report1!BJ14 -> 3.0691964 | BE9: =+[4]Report1!BK14 -> 2.4533212 | BF9: =+[5]Report1!J14 -> 0.87306104 | BG9: =+[5]Report1!K14 -> 0.79531404 | BH9: =+[5]Report1!AN14 -> 0.87306104 | BI9: =+[5]Report1!AO14 -> 0.82459839 | BJ9: =+[5]Report1!R14 -> 44.849 | BK9: =+[5]Report1!S14 -> 246.003 | BL9: =+[5]Report1!AD14 -> 2.7782113 | BM9: =+[5]Report1!AE14 -> 2.8312663 | BN9: 0 | BO9: 0 | BP9: =+[5]Report1!AJ14 -> 1130.4484 | BQ9: =+[5]Report1!AK14 -> 1122.5909 | BR9: 0 | BS9: 0 | BT9: =+[6]Report1!J14 -> 0 | BU9: =+[6]Report1!K14 -> 0.010629839 | BV9: =+[6]Report1!BA14 -> #DIV/0! | BW9: =+[6]Report1!BB14 -> #DIV/0! | BX9: =+[6]Report1!R14 -> 0 | BY9: =+[6]Report1!S14 -> 3.364 | BZ9: =+[6]Report1!X14 -> 0 | CA9: =+[6]Report1!Y14 -> 0 | CB9: =+[6]Report1!AD14 -> 0 | CC9: =+[6]Report1!AE14 -> 0.26753864 | CD9: =+[6]Report1!AJ14 -> 0 | CE9: =+[6]Report1!AK14 -> 0 | CF9: =+[6]Report1!AP14 -> 0 | CG9: =+[6]Report1!AQ14 -> 6062.83 | CH9: =+[6]Report1!AV14 -> 0 | CI9: =+[6]Report1!AW14 -> 0
A10: =1+A9 -> 45937 | B10: =+Report1!J15 -> 0.85142903 | C10: =+Report1!K15 -> 0.78797623 | D10: =+Report1!AJ15 -> 0.85142903 | E10: =+Report1!AK15 -> 0.81836821 | F10: =+Report1!R15 -> 57.294 | G10: =+Report1!S15 -> 409.519 | H10: =+Report1!X15 -> 2.4499948 | I10: =+Report1!Y15 -> 2.3089307 | J10: =+Report1!AD15 -> 1012.9036 | K10: =+Report1!AE15 -> 859.98613 | L10: =+[1]Report1!J15 -> 1.0472504 | M10: =+[1]Report1!K15 -> 0.67572565 | N10: =+[1]Report1!BJ15 -> 1.0472504 | O10: =+[1]Report1!BK15 -> 0.82433443 | P10: =+[1]Report1!R15 -> 69.388 | Q10: =+[1]Report1!S15 -> 295.944 | R10: =+[1]Report1!AL15 -> 1.7545253 | S10: =+[1]Report1!AM15 -> 2.6723164 | T10: =+[1]Report1!AR15 -> 0.18879345 | U10: =+[1]Report1!AS15 -> 0.2287595 | V10: =+[1]Report1!AX15 -> 518.71001 | W10: =+[1]Report1!AY15 -> 716.07564 | X10: =+[1]Report1!BD15 -> 502.37217 | Y10: =+[1]Report1!BE15 -> 608.52506 | Z10: =+[2]Report1!J15 -> 0.96700039 | AA10: =+[2]Report1!K15 -> 0.81047101 | AB10: =+[2]Report1!BC15 -> 0.96700039 | AC10: =+[2]Report1!BD15 -> 0.87267366 | AD10: =+[2]Report1!R15 -> 42.372 | AE10: =+[2]Report1!S15 -> 247.498 | AF10: =+[2]Report1!X15 -> 99.457189 | AG10: =+[2]Report1!Y15 -> 115.74402 | AH10: =+[2]Report1!AD15 -> 1.3900689 | AI10: =+[2]Report1!AE15 -> 1.5951644 | AJ10: =+[2]Report1!AJ15 -> 930.64524 | AK10: =+[2]Report1!AK15 -> 1041.498 | AL10: =+[3]Report1!AP15 -> 0 | AM10: =+[3]Report1!AQ15 -> 0 | AN10: =+[4]Report1!J15 -> 0.82758586 | AO10: =+[4]Report1!K15 -> 0.7496527 | AP10: =+[4]Report1!BN15 -> 0.82758586 | AQ10: =+[4]Report1!BO15 -> 0.76263522 | AR10: =+[4]Report1!R15 -> 45.029 | AS10: =+[4]Report1!S15 -> 273.291 | AT10: =+[4]Report1!AF15 -> 110.61316 | AU10: =+[4]Report1!AG15 -> 133.7936 | AV10: =+[4]Report1!AL15 -> 1.381332 | AW10: =+[4]Report1!AM15 -> 1.5869531 | AX10: =+[4]Report1!AR15 -> 0.148793 | AY10: =+[4]Report1!AS15 -> 0.14709595 | AZ10: =+[4]Report1!AX15 -> 851.30249 | BA10: =+[4]Report1!AY15 -> 1006.9071 | BB10: =+[4]Report1!BD15 -> 384.40561 | BC10: =+[4]Report1!BE15 -> 365.94202 | BD10: =+[4]Report1!BJ15 -> 2.6649493 | BE10: =+[4]Report1!BK15 -> 2.4881902 | BF10: =+[5]Report1!J15 -> 0.87556478 | BG10: =+[5]Report1!K15 -> 0.80655069 | BH10: =+[5]Report1!AN15 -> 0.87556478 | BI10: =+[5]Report1!AO15 -> 0.83195948 | BJ10: =+[5]Report1!R15 -> 44.095 | BK10: =+[5]Report1!S15 -> 290.098 | BL10: =+[5]Report1!AD15 -> 2.7985032 | BM10: =+[5]Report1!AE15 -> 2.8262863 | BN10: 0 | BO10: 0 | BP10: =+[5]Report1!AJ15 -> 1250.0646 | BQ10: =+[5]Report1!AK15 -> 1141.9669 | BR10: 0 | BS10: 0 | BT10: =+[6]Report1!J15 -> 0 | BU10: =+[6]Report1!K15 -> 0.0091112902 | BV10: =+[6]Report1!BA15 -> #DIV/0! | BW10: =+[6]Report1!BB15 -> #DIV/0! | BX10: =+[6]Report1!R15 -> 0 | BY10: =+[6]Report1!S15 -> 3.364 | BZ10: =+[6]Report1!X15 -> 0 | CA10: =+[6]Report1!Y15 -> 0 | CB10: =+[6]Report1!AD15 -> 0 | CC10: =+[6]Report1!AE15 -> 0.29726516 | CD10: =+[6]Report1!AJ15 -> 0 | CE10: =+[6]Report1!AK15 -> 0 | CF10: =+[6]Report1!AP15 -> 0 | CG10: =+[6]Report1!AQ15 -> 6933.3115 | CH10: =+[6]Report1!AV15 -> 0 | CI10: =+[6]Report1!AW15 -> 0
A11: =1+A10 -> 45938 | B11: =+Report1!J16 -> 0.97948993 | C11: =+Report1!K16 -> 0.80853871 | D11: =+Report1!AJ16 -> 0.97948993 | E11: =+Report1!AK16 -> 0.8362607 | F11: =+Report1!R16 -> 61.23 | G11: =+Report1!S16 -> 470.749 | H11: =+Report1!X16 -> 2.192324 | I11: =+Report1!Y16 -> 2.2937638 | J11: =+Report1!AD16 -> 943.56133 | K11: =+Report1!AE16 -> 870.8567 | L11: =+[1]Report1!J16 -> 0.94454587 | M11: =+[1]Report1!K16 -> 0.71156213 | N11: =+[1]Report1!BJ16 -> 0.94454587 | O11: =+[1]Report1!BK16 -> 0.84332739 | P11: =+[1]Report1!R16 -> 63.63 | Q11: =+[1]Report1!S16 -> 359.574 | R11: =+[1]Report1!AL16 -> 1.9104668 | S11: =+[1]Report1!AM16 -> 2.5374999 | T11: =+[1]Report1!AR16 -> 0.16658809 | U11: =+[1]Report1!AS16 -> 0.21775768 | V11: =+[1]Report1!AX16 -> 510.78721 | W11: =+[1]Report1!AY16 -> 679.74792 | X11: =+[1]Report1!BD16 -> 423.43863 | Y11: =+[1]Report1!BE16 -> 575.77227 | Z11: =+[2]Report1!J16 -> 0.98571547 | AA11: =+[2]Report1!K16 -> 0.83245902 | AB11: =+[2]Report1!BC16 -> 0.98571547 | AC11: =+[2]Report1!BD16 -> 0.88779997 | AD11: =+[2]Report1!R16 -> 43.187 | AE11: =+[2]Report1!S16 -> 290.685 | AF11: =+[2]Report1!X16 -> 103.00174 | AG11: =+[2]Report1!Y16 -> 113.85091 | AH11: =+[2]Report1!AD16 -> 1.3707829 | AI11: =+[2]Report1!AE16 -> 1.5618281 | AJ11: =+[2]Report1!AJ16 -> 875.36203 | AK11: =+[2]Report1!AK16 -> 1016.8152 | AL11: =+[3]Report1!AP16 -> 0 | AM11: =+[3]Report1!AQ16 -> 0 | AN11: =+[4]Report1!J16 -> 0.89908567 | AO11: =+[4]Report1!K16 -> 0.76876774 | AP11: =+[4]Report1!BN16 -> 0.89908567 | AQ11: =+[4]Report1!BO16 -> 0.7803526 | AR11: =+[4]Report1!R16 -> 48.077 | AS11: =+[4]Report1!S16 -> 321.368 | AT11: =+[4]Report1!AF16 -> 122.38001 | AU11: =+[4]Report1!AG16 -> 132.08611 | AV11: =+[4]Report1!AL16 -> 1.3644778 | AW11: =+[4]Report1!AM16 -> 1.5536706 | AX11: =+[4]Report1!AR16 -> 0.17263972 | AY11: =+[4]Report1!AS16 -> 0.15091733 | AZ11: =+[4]Report1!AX16 -> 846.02325 | BA11: =+[4]Report1!AY16 -> 982.83874 | BB11: =+[4]Report1!BD16 -> 419.52701 | BC11: =+[4]Report1!BE16 -> 373.95839 | BD11: =+[4]Report1!BJ16 -> 2.7039957 | BE11: =+[4]Report1!BK16 -> 2.520475 | BF11: =+[5]Report1!J16 -> 0.87151233 | BG11: =+[5]Report1!K16 -> 0.81515145 | BH11: =+[5]Report1!AN16 -> 0.87151233 | BI11: =+[5]Report1!AO16 -> 0.83733872 | BJ11: =+[5]Report1!R16 -> 47.835 | BK11: =+[5]Report1!S16 -> 337.933 | BL11: =+[5]Report1!AD16 -> 2.5817916 | BM11: =+[5]Report1!AE16 -> 2.7916776 | BN11: 0 | BO11: 0 | BP11: =+[5]Report1!AJ16 -> 1012.9303 | BQ11: =+[5]Report1!AK16 -> 1123.7016 | BR11: 0 | BS11: 0 | BT11: =+[6]Report1!J16 -> 0 | BU11: =+[6]Report1!K16 -> 0.0079723789 | BV11: =+[6]Report1!BA16 -> #DIV/0! | BW11: =+[6]Report1!BB16 -> #DIV/0! | BX11: =+[6]Report1!R16 -> 0 | BY11: =+[6]Report1!S16 -> 3.364 | BZ11: =+[6]Report1!X16 -> 0 | CA11: =+[6]Report1!Y16 -> 0 | CB11: =+[6]Report1!AD16 -> 0 | CC11: =+[6]Report1!AE16 -> 0.77288942 | CD11: =+[6]Report1!AJ16 -> 0 | CE11: =+[6]Report1!AK16 -> 0 | CF11: =+[6]Report1!AP16 -> 0 | CG11: =+[6]Report1!AQ16 -> 7658.4185 | CH11: =+[6]Report1!AV16 -> 0 | CI11: =+[6]Report1!AW16 -> 0
A12: =1+A11 -> 45939 | B12: =+Report1!J17 -> 0.94994402 | C12: =+Report1!K17 -> 0.82162852 | D12: =+Report1!AJ17 -> 0.94994402 | E12: =+Report1!AK17 -> 0.84711068 | F12: =+Report1!R17 -> 56.421 | G12: =+Report1!S17 -> 527.17 | H12: =+Report1!X17 -> 2.3658921 | I12: =+Report1!Y17 -> 2.3014834 | J12: =+Report1!AD17 -> 1057.7597 | K12: =+Report1!AE17 -> 890.86022 | L12: =+[1]Report1!J17 -> 0.98030034 | M12: =+[1]Report1!K17 -> 0.74353555 | N12: =+[1]Report1!BJ17 -> 0.98030034 | O12: =+[1]Report1!BK17 -> 0.86222529 | P12: =+[1]Report1!R17 -> 66.897 | Q12: =+[1]Report1!S17 -> 426.471 | R12: =+[1]Report1!AL17 -> 1.8717282 | S12: =+[1]Report1!AM17 -> 2.4330658 | T12: =+[1]Report1!AR17 -> 0.21077178 | U12: =+[1]Report1!AS17 -> 0.21666186 | V12: =+[1]Report1!AX17 -> 461.21336 | W12: =+[1]Report1!AY17 -> 645.4682 | X12: =+[1]Report1!BD17 -> 552.15032 | Y12: =+[1]Report1!BE17 -> 572.06689 | Z12: =+[2]Report1!J17 -> 0.83407045 | AA12: =+[2]Report1!K17 -> 0.83263867 | AB12: =+[2]Report1!BC17 -> 0.83407045 | AC12: =+[2]Report1!BD17 -> 0.88145885 | AD12: =+[2]Report1!R17 -> 36.543 | AE12: =+[2]Report1!S17 -> 327.228 | AF12: =+[2]Report1!X17 -> 118.16663 | AG12: =+[2]Report1!Y17 -> 114.33286 | AH12: =+[2]Report1!AD17 -> 1.5953808 | AI12: =+[2]Report1!AE17 -> 1.5655751 | AJ12: =+[2]Report1!AJ17 -> 1029.4683 | AK12: =+[2]Report1!AK17 -> 1018.2282 | AL12: =+[3]Report1!AP17 -> 0 | AM12: =+[3]Report1!AQ17 -> 0 | AN12: =+[4]Report1!J17 -> 0.56729199 | AO12: =+[4]Report1!K17 -> 0.74634942 | AP12: =+[4]Report1!BN17 -> 0.56729199 | AQ12: =+[4]Report1!BO17 -> 0.75632826 | AR12: =+[4]Report1!R17 -> 29.691 | AS12: =+[4]Report1!S17 -> 351.059 | AT12: =+[4]Report1!AF17 -> 151.50503 | AU12: =+[4]Report1!AG17 -> 133.72848 | AV12: =+[4]Report1!AL17 -> 1.7884207 | AW12: =+[4]Report1!AM17 -> 1.5735247 | AX12: =+[4]Report1!AR17 -> 0.23576168 | AY12: =+[4]Report1!AS17 -> 0.15809308 | AZ12: =+[4]Report1!AX17 -> 1108.7488 | BA12: =+[4]Report1!AY17 -> 993.48765 | BB12: =+[4]Report1!BD17 -> 589.73426 | BC12: =+[4]Report1!BE17 -> 392.20775 | BD12: =+[4]Report1!BJ17 -> 3.368024 | BE12: =+[4]Report1!BK17 -> 2.5921569 | BF12: =+[5]Report1!J17 -> 0.99998578 | BG12: =+[5]Report1!K17 -> 0.83747379 | BH12: =+[5]Report1!AN17 -> 0.99998578 | BI12: =+[5]Report1!AO17 -> 0.85745005 | BJ12: =+[5]Report1!R17 -> 56.943 | BK12: =+[5]Report1!S17 -> 394.876 | BL12: =+[5]Report1!AD17 -> 2.1899092 | BM12: =+[5]Report1!AE17 -> 2.7048998 | BN12: 0 | BO12: 0 | BP12: =+[5]Report1!AJ17 -> 1038.9288 | BQ12: =+[5]Report1!AK17 -> 1111.4769 | BR12: 0 | BS12: 0 | BT12: =+[6]Report1!J17 -> 0.33723214 | BU12: =+[6]Report1!K17 -> 0.044702661 | BV12: =+[6]Report1!BA17 -> 0.43567002 | BW12: =+[6]Report1!BB17 -> 0.517698 | BX12: =+[6]Report1!R17 -> 17.867 | BY12: =+[6]Report1!S17 -> 21.231 | BZ12: =+[6]Report1!X17 -> 154.95052 | CA12: =+[6]Report1!Y17 -> 130.39899 | CB12: =+[6]Report1!AD17 -> 3.5764258 | CC12: =+[6]Report1!AE17 -> 3.1322123 | CD12: =+[6]Report1!AJ17 -> 0 | CE12: =+[6]Report1!AK17 -> 0 | CF12: =+[6]Report1!AP17 -> 932.99715 | CG12: =+[6]Report1!AQ17 -> 1998.6237 | CH12: =+[6]Report1!AV17 -> 0 | CI12: =+[6]Report1!AW17 -> 0
A13: =1+A12 -> 45940 | B13: =+Report1!J18 -> 0.80516097 | C13: =+Report1!K18 -> 0.82020298 | D13: =+Report1!AJ18 -> 0.80516097 | E13: =+Report1!AK18 -> 0.84337663 | F13: =+Report1!R18 -> 48.959 | G13: =+Report1!S18 -> 576.129 | H13: =+Report1!X18 -> 2.5410241 | I13: =+Report1!Y18 -> 2.3218394 | J13: =+Report1!AD18 -> 1207.2824 | K13: =+Report1!AE18 -> 917.74953 | L13: =+[1]Report1!J18 -> 0.96058493 | M13: =+[1]Report1!K18 -> 0.76704967 | N13: =+[1]Report1!BJ18 -> 0.96058493 | O13: =+[1]Report1!BK18 -> 0.87437203 | P13: =+[1]Report1!R18 -> 66.941 | Q13: =+[1]Report1!S18 -> 493.412 | R13: =+[1]Report1!AL18 -> 2.044218 | S13: =+[1]Report1!AM18 -> 2.380311 | T13: =+[1]Report1!AR18 -> 0.18225004 | U13: =+[1]Report1!AS18 -> 0.21199322 | V13: =+[1]Report1!AX18 -> 482.91794 | W13: =+[1]Report1!AY18 -> 623.41508 | X13: =+[1]Report1!BD18 -> 466.54218 | Y13: =+[1]Report1!BE18 -> 557.7504 | Z13: =+[2]Report1!J18 -> 0.82035301 | AA13: =+[2]Report1!K18 -> 0.83140641 | AB13: =+[2]Report1!BC18 -> 0.82035301 | AC13: =+[2]Report1!BD18 -> 0.87500845 | AD13: =+[2]Report1!R18 -> 35.942 | AE13: =+[2]Report1!S18 -> 363.17 | AF13: =+[2]Report1!X18 -> 116.37519 | AG13: =+[2]Report1!Y18 -> 114.53499 | AH13: =+[2]Report1!AD18 -> 1.6387513 | AI13: =+[2]Report1!AE18 -> 1.5728171 | AJ13: =+[2]Report1!AJ18 -> 1084.4511 | AK13: =+[2]Report1!AK18 -> 1024.7821 | AL13: =+[3]Report1!AP18 -> 0 | AM13: =+[3]Report1!AQ18 -> 0 | AN13: =+[4]Report1!J18 -> 0.79855671 | AO13: =+[4]Report1!K18 -> 0.75150994 | AP13: =+[4]Report1!BN18 -> 0.79855671 | AQ13: =+[4]Report1!BO18 -> 0.76055263 | AR13: =+[4]Report1!R18 -> 41.201 | AS13: =+[4]Report1!S18 -> 392.26 | AT13: =+[4]Report1!AF18 -> 125.67449 | AU13: =+[4]Report1!AG18 -> 132.88253 | AV13: =+[4]Report1!AL18 -> 1.4854008 | AW13: =+[4]Report1!AM18 -> 1.5642686 | AX13: =+[4]Report1!AR18 -> 0.18446154 | AY13: =+[4]Report1!AS18 -> 0.16086269 | AZ13: =+[4]Report1!AX18 -> 1001.8529 | BA13: =+[4]Report1!AY18 -> 994.36629 | BB13: =+[4]Report1!BD18 -> 444.92124 | BC13: =+[4]Report1!BE18 -> 397.74451 | BD13: =+[4]Report1!BJ18 -> 2.8882794 | BE13: =+[4]Report1!BK18 -> 2.6232601 | BF13: =+[5]Report1!J18 -> 0.71953197 | BG13: =+[5]Report1!K18 -> 0.82500006 | BH13: =+[5]Report1!AN18 -> 0.71953197 | BI13: =+[5]Report1!AO18 -> 0.84255324 | BJ13: =+[5]Report1!R18 -> 40.125 | BK13: =+[5]Report1!S18 -> 435.001 | BL13: =+[5]Report1!AD18 -> 3.1102804 | BM13: =+[5]Report1!AE18 -> 2.7422925 | BN13: 0 | BO13: 0 | BP13: =+[5]Report1!AJ18 -> 1295.3131 | BQ13: =+[5]Report1!AK18 -> 1128.4342 | BR13: 0 | BS13: 0 | BT13: =+[6]Report1!J18 -> 0.73928463 | BU13: =+[6]Report1!K18 -> 0.11276736 | BV13: =+[6]Report1!BA18 -> 0.73928463 | BW13: =+[6]Report1!BB18 -> 0.64115707 | BX13: =+[6]Report1!R18 -> 38.145 | BY13: =+[6]Report1!S18 -> 59.376 | BZ13: =+[6]Report1!X18 -> 99.602258 | CA13: =+[6]Report1!Y18 -> 110.61421 | CB13: =+[6]Report1!AD18 -> 2.4957399 | CC13: =+[6]Report1!AE18 -> 2.7233226 | CD13: =+[6]Report1!AJ18 -> 0 | CE13: =+[6]Report1!AK18 -> 0 | CF13: =+[6]Report1!AP18 -> 938.93256 | CG13: =+[6]Report1!AQ18 -> 1317.845 | CH13: =+[6]Report1!AV18 -> 0 | CI13: =+[6]Report1!AW18 -> 0
A14: =1+A13 -> 45941 | B14: =+Report1!J19 -> 0.89387042 | C14: =+Report1!K19 -> 0.82562571 | D14: =+Report1!AJ19 -> 0.89387042 | E14: =+Report1!AK19 -> 0.84719061 | F14: =+Report1!R19 -> 49.891 | G14: =+Report1!S19 -> 626.02 | H14: =+Report1!X19 -> 2.4571165 | I14: =+Report1!Y19 -> 2.3326204 | J14: =+Report1!AD19 -> 1140.3415 | K14: =+Report1!AE19 -> 935.48912 | L14: =+[1]Report1!J19 -> 0.90271028 | M14: =+[1]Report1!K19 -> 0.77990833 | N14: =+[1]Report1!BJ19 -> 0.90271028 | O14: =+[1]Report1!BK19 -> 0.87739384 | P14: =+[1]Report1!R19 -> 60.803 | Q14: =+[1]Report1!S19 -> 554.215 | R14: =+[1]Report1!AL19 -> 2.2938177 | S14: =+[1]Report1!AM19 -> 2.3708218 | T14: =+[1]Report1!AR19 -> 0.1891354 | U14: =+[1]Report1!AS19 -> 0.20948549 | V14: =+[1]Report1!AX19 -> 583.78978 | W14: =+[1]Report1!AY19 -> 619.06778 | X14: =+[1]Report1!BD19 -> 472.20443 | Y14: =+[1]Report1!BE19 -> 548.36514 | Z14: =+[2]Report1!J19 -> 0.91753522 | AA14: =+[2]Report1!K19 -> 0.83925863 | AB14: =+[2]Report1!BC19 -> 0.91753522 | AC14: =+[2]Report1!BD19 -> 0.87906946 | AD14: =+[2]Report1!R19 -> 40.205 | AE14: =+[2]Report1!S19 -> 403.375 | AF14: =+[2]Report1!X19 -> 102.55969 | AG14: =+[2]Report1!Y19 -> 113.34139 | AH14: =+[2]Report1!AD19 -> 1.4699664 | AI14: =+[2]Report1!AE19 -> 1.5625659 | AJ14: =+[2]Report1!AJ19 -> 967.6105 | AK14: =+[2]Report1!AK19 -> 1019.0837 | AL14: =+[3]Report1!AP19 -> 0 | AM14: =+[3]Report1!AQ19 -> 0 | AN14: =+[4]Report1!J19 -> 0.86145438 | AO14: =+[4]Report1!K19 -> 0.76138295 | AP14: =+[4]Report1!BN19 -> 0.86145438 | AQ14: =+[4]Report1!BO19 -> 0.76971274 | AR14: =+[4]Report1!R19 -> 44.362 | AS14: =+[4]Report1!S19 -> 436.622 | AT14: =+[4]Report1!AF19 -> 122.18345 | AU14: =+[4]Report1!AG19 -> 131.79547 | AV14: =+[4]Report1!AL19 -> 1.4426762 | AW14: =+[4]Report1!AM19 -> 1.5519145 | AX14: =+[4]Report1!AR19 -> 0.18709707 | AY14: =+[4]Report1!AS19 -> 0.16352818 | AZ14: =+[4]Report1!AX19 -> 950.65101 | BA14: =+[4]Report1!AY19 -> 989.92469 | BB14: =+[4]Report1!BD19 -> 444.86845 | BC14: =+[4]Report1!BE19 -> 402.53243 | BD14: =+[4]Report1!BJ19 -> 2.6914927 | BE14: =+[4]Report1!BK19 -> 2.6301927 | BF14: =+[5]Report1!J19 -> 0.97475649 | BG14: =+[5]Report1!K19 -> 0.83913283 | BH14: =+[5]Report1!AN19 -> 0.97475649 | BI14: =+[5]Report1!AO19 -> 0.85526941 | BJ14: =+[5]Report1!R19 -> 53.558 | BK14: =+[5]Report1!S19 -> 488.559 | BL14: =+[5]Report1!AD19 -> 2.259233 | BM14: =+[5]Report1!AE19 -> 2.6893374 | BN14: 0 | BO14: 0 | BP14: =+[5]Report1!AJ19 -> 910.47407 | BQ14: =+[5]Report1!AK19 -> 1104.5404 | BR14: 0 | BS14: 0 | BT14: =+[6]Report1!J19 -> 0.68754318 | BU14: =+[6]Report1!K19 -> 0.16405009 | BV14: =+[6]Report1!BA19 -> 0.68754318 | BW14: =+[6]Report1!BB19 -> 0.65775086 | BX14: =+[6]Report1!R19 -> 35.464 | BY14: =+[6]Report1!S19 -> 94.84 | BZ14: =+[6]Report1!X19 -> 116.0976 | CA14: =+[6]Report1!Y19 -> 112.66464 | CB14: =+[6]Report1!AD19 -> 2.7746447 | CC14: =+[6]Report1!AE19 -> 2.7425137 | CD14: =+[6]Report1!AJ19 -> 0 | CE14: =+[6]Report1!AK19 -> 0 | CF14: =+[6]Report1!AP19 -> 1129.8548 | CG14: =+[6]Report1!AQ19 -> 1247.5488 | CH14: =+[6]Report1!AV19 -> 0 | CI14: =+[6]Report1!AW19 -> 0
A15: =1+A14 -> 45942 | B15: =+Report1!J20 -> 0.80351983 | C15: =+Report1!K20 -> 0.82398319 | D15: =+Report1!AJ20 -> 0.80351983 | E15: =+Report1!AK20 -> 0.84386746 | F15: =+Report1!R20 -> 48.903 | G15: =+Report1!S20 -> 674.923 | H15: =+Report1!X20 -> 2.5551193 | I15: =+Report1!Y20 -> 2.348742 | J15: =+Report1!AD20 -> 1167.8441 | K15: =+Report1!AE20 -> 952.3249 | L15: =+[1]Report1!J20 -> 0.75947247 | M15: =+[1]Report1!K20 -> 0.7781398 | N15: =+[1]Report1!BJ20 -> 0.75947247 | O15: =+[1]Report1!BK20 -> 0.86603616 | P15: =+[1]Report1!R20 -> 51.13 | Q15: =+[1]Report1!S20 -> 605.345 | R15: =+[1]Report1!AL20 -> 2.4602777 | S15: =+[1]Report1!AM20 -> 2.3783776 | T15: =+[1]Report1!AR20 -> 0.19949149 | U15: =+[1]Report1!AS20 -> 0.20864135 | V15: =+[1]Report1!AX20 -> 658.86212 | W15: =+[1]Report1!AY20 -> 622.42898 | X15: =+[1]Report1!BD20 -> 555.87135 | Y15: =+[1]Report1!BE20 -> 548.99915 | Z15: =+[2]Report1!J20 -> 0.8774019 | AA15: =+[2]Report1!K20 -> 0.84261756 | AB15: =+[2]Report1!BC20 -> 0.8774019 | AC15: =+[2]Report1!BD20 -> 0.87891629 | AD15: =+[2]Report1!R20 -> 40.722 | AE15: =+[2]Report1!S20 -> 444.097 | AF15: =+[2]Report1!X20 -> 102.71237 | AG15: =+[2]Report1!Y20 -> 112.36675 | AH15: =+[2]Report1!AD20 -> 1.4832277 | AI15: =+[2]Report1!AE20 -> 1.5552908 | AJ15: =+[2]Report1!AJ20 -> 930.4818 | AK15: =+[2]Report1!AK20 -> 1010.9593 | AL15: =+[3]Report1!AP20 -> 0 | AM15: =+[3]Report1!AQ20 -> 0 | AN15: =+[4]Report1!J20 -> 0.83798892 | AO15: =+[4]Report1!K20 -> 0.76770866 | AP15: =+[4]Report1!BN20 -> 0.83798892 | AQ15: =+[4]Report1!BO20 -> 0.77540715 | AR15: =+[4]Report1!R20 -> 43.253 | AS15: =+[4]Report1!S20 -> 479.875 | AT15: =+[4]Report1!AF20 -> 121.73825 | AU15: =+[4]Report1!AG20 -> 130.88898 | AV15: =+[4]Report1!AL20 -> 1.5027859 | AW15: =+[4]Report1!AM20 -> 1.5474863 | AX15: =+[4]Report1!AR20 -> 0.20114212 | AY15: =+[4]Report1!AS20 -> 0.16691847 | AZ15: =+[4]Report1!AX20 -> 970.82468 | BA15: =+[4]Report1!AY20 -> 988.20314 | BB15: =+[4]Report1!BD20 -> 534.95938 | BC15: =+[4]Report1!BE20 -> 414.46858 | BD15: =+[4]Report1!BJ20 -> 2.8113657 | BE15: =+[4]Report1!BK20 -> 2.6465225 | BF15: =+[5]Report1!J20 -> 0.9186246 | BG15: =+[5]Report1!K20 -> 0.84603596 | BH15: =+[5]Report1!AN20 -> 0.9186246 | BI15: =+[5]Report1!AO20 -> 0.86086768 | BJ15: =+[5]Report1!R20 -> 50.863 | BK15: =+[5]Report1!S20 -> 539.422 | BL15: =+[5]Report1!AD20 -> 2.4084305 | BM15: =+[5]Report1!AE20 -> 2.6628502 | BN15: 0 | BO15: 0 | BP15: =+[5]Report1!AJ20 -> 982.53387 | BQ15: =+[5]Report1!AK20 -> 1093.0362 | BR15: 0 | BS15: 0 | BT15: =+[6]Report1!J20 -> 0.86841446 | BU15: =+[6]Report1!K20 -> 0.22171346 | BV15: =+[6]Report1!BA20 -> 0.86841446 | BW15: =+[6]Report1!BB20 -> 0.71322999 | BX15: =+[6]Report1!R20 -> 44.765 | BY15: =+[6]Report1!S20 -> 139.605 | BZ15: =+[6]Report1!X20 -> 80.058134 | CA15: =+[6]Report1!Y20 -> 102.20921 | CB15: =+[6]Report1!AD20 -> 2.0194348 | CC15: =+[6]Report1!AE20 -> 2.5106551 | CD15: =+[6]Report1!AJ20 -> 0 | CE15: =+[6]Report1!AK20 -> 0 | CF15: =+[6]Report1!AP20 -> 830.70747 | CG15: =+[6]Report1!AQ20 -> 1113.8867 | CH15: =+[6]Report1!AV20 -> 0 | CI15: =+[6]Report1!AW20 -> 0
A16: =1+A15 -> 45943 | B16: =+Report1!J21 -> 0.92987401 | C16: =+Report1!K21 -> 0.83112327 | D16: =+Report1!AJ21 -> 0.92987401 | E16: =+Report1!AK21 -> 0.84979707 | F16: =+Report1!R21 -> 55.071 | G16: =+Report1!S21 -> 729.994 | H16: =+Report1!X21 -> 2.1780429 | I16: =+Report1!Y21 -> 2.3358644 | J16: =+Report1!AD21 -> 963.3553 | K16: =+Report1!AE21 -> 953.15704 | L16: =+[1]Report1!J21 -> 0.81169827 | M16: =+[1]Report1!K21 -> 0.78081266 | N16: =+[1]Report1!BJ21 -> 0.81169827 | O16: =+[1]Report1!BK21 -> 0.86126237 | P16: =+[1]Report1!R21 -> 54.646 | Q16: =+[1]Report1!S21 -> 659.991 | R16: =+[1]Report1!AL21 -> 2.4825605 | S16: =+[1]Report1!AM21 -> 2.3870038 | T16: =+[1]Report1!AR21 -> 0.18665593 | U16: =+[1]Report1!AS21 -> 0.206821 | V16: =+[1]Report1!AX21 -> 595.07393 | W16: =+[1]Report1!AY21 -> 620.16403 | X16: =+[1]Report1!BD21 -> 482.10848 | Y16: =+[1]Report1!BE21 -> 543.46073 | Z16: =+[2]Report1!J21 -> 0.8536474 | AA16: =+[2]Report1!K21 -> 0.84350837 | AB16: =+[2]Report1!BC21 -> 0.8536474 | AC16: =+[2]Report1!BD21 -> 0.87679494 | AD16: =+[2]Report1!R21 -> 39.529 | AE16: =+[2]Report1!S21 -> 483.626 | AF16: =+[2]Report1!X21 -> 107.56071 | AG16: =+[2]Report1!Y21 -> 111.97393 | AH16: =+[2]Report1!AD21 -> 1.5431708 | AI16: =+[2]Report1!AE21 -> 1.5543002 | AJ16: =+[2]Report1!AJ21 -> 950.7688 | AK16: =+[2]Report1!AK21 -> 1006.0396 | AL16: =+[3]Report1!AP21 -> 0 | AM16: =+[3]Report1!AQ21 -> 0 | AN16: =+[4]Report1!J21 -> 0.65129983 | AO16: =+[4]Report1!K21 -> 0.75849162 | AP16: =+[4]Report1!BN21 -> 0.65129983 | AQ16: =+[4]Report1!BO21 -> 0.76548989 | AR16: =+[4]Report1!R21 -> 35.006 | AS16: =+[4]Report1!S21 -> 514.881 | AT16: =+[4]Report1!AF21 -> 134.85413 | AU16: =+[4]Report1!AG21 -> 131.15856 | AV16: =+[4]Report1!AL21 -> 1.6025824 | AW16: =+[4]Report1!AM21 -> 1.5512322 | AX16: =+[4]Report1!AR21 -> 0.19710907 | AY16: =+[4]Report1!AS21 -> 0.16897108 | AZ16: =+[4]Report1!AX21 -> 935.63789 | BA16: =+[4]Report1!AY21 -> 984.6293 | BB16: =+[4]Report1!BD21 -> 496.24921 | BC16: =+[4]Report1!BE21 -> 420.02873 | BD16: =+[4]Report1!BJ21 -> 3.1423185 | BE16: =+[4]Report1!BK21 -> 2.680231 | BF16: =+[5]Report1!J21 -> 0.8829953 | BG16: =+[5]Report1!K21 -> 0.84889087 | BH16: =+[5]Report1!AN21 -> 0.8829953 | BI16: =+[5]Report1!AO21 -> 0.86260453 | BJ16: =+[5]Report1!R21 -> 47.128 | BK16: =+[5]Report1!S21 -> 586.55 | BL16: =+[5]Report1!AD21 -> 2.5950603 | BM16: =+[5]Report1!AE21 -> 2.6574035 | BN16: 0 | BO16: 0 | BP16: =+[5]Report1!AJ21 -> 947.30118 | BQ16: =+[5]Report1!AK21 -> 1081.3267 | BR16: 0 | BS16: 0 | BT16: =+[6]Report1!J21 -> 0.81946711 | BU16: =+[6]Report1!K21 -> 0.26693728 | BV16: =+[6]Report1!BA21 -> 0.81946711 | BW16: =+[6]Report1!BB21 -> 0.73537211 | BX16: =+[6]Report1!R21 -> 42.233 | BY16: =+[6]Report1!S21 -> 181.838 | BZ16: =+[6]Report1!X21 -> 93.920133 | CA16: =+[6]Report1!Y21 -> 100.28402 | CB16: =+[6]Report1!AD21 -> 2.2328511 | CC16: =+[6]Report1!AE21 -> 2.4461334 | CD16: =+[6]Report1!AJ21 -> 0 | CE16: =+[6]Report1!AK21 -> 0 | CF16: =+[6]Report1!AP21 -> 951.49315 | CG16: =+[6]Report1!AQ21 -> 1076.1698 | CH16: =+[6]Report1!AV21 -> 0 | CI16: =+[6]Report1!AW21 -> 0
... A34: =1+A33 -> 45961 | B34: =+Report1!J39 -> 0.79466555 | C34: =+Report1!K39 -> 0.81961611 | D34: =+Report1!AJ39 -> 0.79466555 | E34: =+Report1!AK39 -> 0.83793084 | F34: =+Report1!R39 -> 60.962 | G34: =+Report1!S39 -> 1655.884 | H34: =+Report1!X39 -> 2.5448148 | I34: =+Report1!Y39 -> 2.3800164 | J34: =+Report1!AD39 -> 906.79407 | K34: =+Report1!AE39 -> 987.22519 | L34: =+[1]Report1!J39 -> 0.73917938 | M34: =+[1]Report1!K39 -> 0.84175524 | N34: =+[1]Report1!BJ39 -> 0.73917938 | O34: =+[1]Report1!BK39 -> 0.87679264 | P34: =+[1]Report1!R39 -> 41.704 | Q34: =+[1]Report1!S39 -> 1649.297 | R34: =+[1]Report1!AL39 -> 2.9641521 | S34: =+[1]Report1!AM39 -> 2.3196877 | T34: =+[1]Report1!AR39 -> 0.32610781 | U34: =+[1]Report1!AS39 -> 0.24616549 | V34: =+[1]Report1!AX39 -> 898.98259 | W34: =+[1]Report1!AY39 -> 616.10298 | X34: =+[1]Report1!BD39 -> 525.58508 | Y34: =+[1]Report1!BE39 -> 486.41123 | Z34: =+[2]Report1!J39 -> 0 | AA34: =+[2]Report1!K39 -> 0.51081757 | AB34: =+[2]Report1!BC39 -> #DIV/0! | AC34: =+[2]Report1!BD39 -> 0.80748846 | AD34: =+[2]Report1!R39 -> 0 | AE34: =+[2]Report1!S39 -> 700.591 | AF34: =+[2]Report1!X39 -> 0 | AG34: =+[2]Report1!Y39 -> 110.32386 | AH34: =+[2]Report1!AD39 -> 0 | AI34: =+[2]Report1!AE39 -> 1.9417891 | AJ34: =+[2]Report1!AJ39 -> 0 | AK34: =+[2]Report1!AK39 -> 1127.8883 | AL34: =+[3]Report1!AP39 -> 0 | AM34: =+[3]Report1!AQ39 -> 0 | AN34: =+[4]Report1!J39 -> 0.78131922 | AO34: =+[4]Report1!K39 -> 0.78888926 | AP34: =+[4]Report1!BN39 -> 0.78131922 | AQ34: =+[4]Report1!BO39 -> 0.80397213 | AR34: =+[4]Report1!R39 -> 41.746 | AS34: =+[4]Report1!S39 -> 1297.219 | AT34: =+[4]Report1!AF39 -> 124.92287 | AU34: =+[4]Report1!AG39 -> 120.0559 | AV34: =+[4]Report1!AL39 -> 1.4779859 | AW34: =+[4]Report1!AM39 -> 1.4886461 | AX34: =+[4]Report1!AR39 -> 0.21319408 | AY34: =+[4]Report1!AS39 -> 0.19526387 | AZ34: =+[4]Report1!AX39 -> 931.10669 | BA34: =+[4]Report1!AY39 -> 913.20617 | BB34: =+[4]Report1!BD39 -> 501.86365 | BC34: =+[4]Report1!BE39 -> 493.47212 | BD34: =+[4]Report1!BJ39 -> 5.5095099 | BE34: =+[4]Report1!BK39 -> 2.9987227 | BF34: =+[5]Report1!J39 -> 0.84111559 | BG34: =+[5]Report1!K39 -> 0.84480151 | BH34: =+[5]Report1!AN39 -> 0.84111559 | BI34: =+[5]Report1!AO39 -> 0.85404309 | BJ34: =+[5]Report1!R39 -> 45.202 | BK34: =+[5]Report1!S39 -> 1387.38 | BL34: =+[5]Report1!AD39 -> 3.103845 | BM34: =+[5]Report1!AE39 -> 2.841471 | BN34: 0 | BO34: 0 | BP34: =+[5]Report1!AJ39 -> 1309.8969 | BQ34: =+[5]Report1!AK39 -> 1094.5931 | BR34: 0 | BS34: 0 | BT34: =+[6]Report1!J39 -> 0.74858932 | BU34: =+[6]Report1!K39 -> 0.56906056 | BV34: =+[6]Report1!BA39 -> 0.74858932 | BW34: =+[6]Report1!BB39 -> 0.79794558 | BX34: =+[6]Report1!R39 -> 39.34 | BY34: =+[6]Report1!S39 -> 904.638 | BZ34: =+[6]Report1!X39 -> 85.230546 | CA34: =+[6]Report1!Y39 -> 98.183246 | CB34: =+[6]Report1!AD39 -> 2.0081342 | CC34: =+[6]Report1!AE39 -> 2.3456897 | CD34: =+[6]Report1!AJ39 -> 0.20843925 | CE34: =+[6]Report1!AK39 -> 0.013817682 | CF34: =+[6]Report1!AP39 -> 646.66955 | CG34: =+[6]Report1!AQ39 -> 1025.3921 | CH34: =+[6]Report1!AV39 -> 491.59126 | CI34: =+[6]Report1!AW39 -> 32.403016
A36: Desember
A37: November
A38: Oktober | B38: =+C34 -> 0.81961611 | D38: =+E34 -> 0.83793084 | F38: =+G34 -> 1655.884 | H38: =+I34 -> 2.3800164 | J38: =+K34 -> 987.22519 | L38: =+M34 -> 0.84175524 | N38: =+O34 -> 0.87679264 | P38: =+Q34 -> 1649.297 | R38: =+S34 -> 2.3196877 | T38: =+U34 -> 0.24616549 | V38: =+W34 -> 616.10298 | X38: =+Y34 -> 486.41123 | Z38: =+AA34 -> 0.51081757 | AB38: =+AC34 -> 0.80748846 | AD38: =+AE34 -> 700.591 | AF38: =+AG34 -> 110.32386 | AH38: =+AI34 -> 1.9417891 | AJ38: =+AK34 -> 1127.8883 | AL38: =+AM34 -> 0 | AN38: =+AO34 -> 0.78888926 | AP38: =+AQ34 -> 0.80397213 | AR38: =+AS34 -> 1297.219 | AT38: =+AU34 -> 120.0559 | AV38: =+AW34 -> 1.4886461 | AX38: =+AY34 -> 0.19526387 | AZ38: =+BA34 -> 913.20617 | BB38: =+BC34 -> 493.47212 | BD38: =+BE34 -> 2.9987227 | BF38: =+BG34 -> 0.84480151 | BH38: =+BI34 -> 0.85404309 | BJ38: =+BK34 -> 1387.38 | BL38: =+BM34 -> 2.841471 | BN38: =+BO34 -> 0 | BP38: =+BQ34 -> 1094.5931 | BR38: =+BS34 -> 0 | BT38: =+BU34 -> 0.56906056 | BV38: =+BW34 -> 0.79794558 | BX38: =+BY34 -> 904.638 | BZ38: =+CA34 -> 98.183246 | CB38: =+CC34 -> 2.3456897 | CD38: =+CE34 -> 0.013817682 | CF38: =+CG34 -> 1025.3921 | CH38: =+CI34 -> 32.403016 | CJ38: =+CK34 -> 0
A39: September | B39: =+'[7]eff all'!$B$39:$C$39 -> 0.90399081 | D39: =+'[7]eff all'!$D$39:$E$39 -> 0.90437904 | F39: =+'[7]eff all'!$F$39:$G$39 -> 1787.584 | H39: =+'[7]eff all'!$H$39:$I$39 -> 2.2781229 | J39: =+'[7]eff all'!$J$39:$K$39 -> 915.86318 | L39: =+'[7]eff all'!$L$39:$M$39 -> 0.91235679 | N39: =+'[7]eff all'!$N$39:$O$39 -> 0.91641187 | P39: =+'[7]eff all'!$P$39:$Q$39 -> 1733.483 | R39: =+'[7]eff all'!$R$39:$S$39 -> 2.0999496 | T39: =+'[7]eff all'!$T$39:$U$39 -> 0.29126331 | V39: =+'[7]eff all'!$V$39:$W$39 -> 594.57701 | X39: =+'[7]eff all'!$X$39:$Y$39 -> 459.61051 | Z39: =+'[7]eff all'!$Z$39:$AA$39 -> 0.31795967 | AB39: =+'[7]eff all'!$AB$39:$AC$39 -> 0.77060412 | AD39: =+'[7]eff all'!$AD$39:$AE$39 -> 413.672 | AF39: =+'[7]eff all'!$AF$39:$AG$39 -> 99.280285 | AH39: =+'[7]eff all'!$AH$39:$AI$39 -> 1.8947379 | AJ39: =+'[7]eff all'!$AJ$39:$AK$39 -> 1272.9031 | AL39: =+'[7]eff all'!$AL$39:$AM$39 -> 0 | AN39: =+'[7]eff all'!$AN$39:$AO$39 -> 0.88030658 | AP39: =+'[7]eff all'!$AP$39:$AQ$39 -> 0.89025454 | AR39: =+'[7]eff all'!$AR$39:$AS$39 -> 1341.886 | AT39: =+'[7]eff all'!$AT$39:$AU$39 -> 122.30106 | AV39: =+'[7]eff all'!$AV$39:$AW$39 -> 1.4501977 | AX39: =+'[7]eff all'!$AX$39:$AY$39 -> 0.063790814 | AZ39: =+'[7]eff all'!$AZ$39:$BA$39 -> 910.28922 | BB39: =+'[7]eff all'!$BB$39:$BC$39 -> 164.14175 | BD39: =+'[7]eff all'!$BD$39:$BE$39 -> 2.0120934 | BF39: =+'[7]eff all'!$BF$39:$BG$39 -> 0.8468278 | BH39: =+'[7]eff all'!$BH$39:$BI$39 -> 0.8468278 | BJ39: =+'[7]eff all'!$BJ$39:$BK$39 -> 1322.914 | BL39: =+'[7]eff all'!$BL$39:$BM$39 -> 2.6480179 | BN39: =+'[7]eff all'!$BN$39:$BO$39 -> 0 | BP39: =+'[7]eff all'!$BP$39:$BQ$39 -> 1045.6073 | BR39: =+'[7]eff all'!$BR$39:$BS$39 -> 0 | BT39: =+'[7]eff all'!$BT$39:$BU$39 -> 0.84513582 | BV39: =+'[7]eff all'!$BV$39:$BW$39 -> 0.84822809 | BX39: =+'[7]eff all'!$BX$39:$BY$39 -> 1346.375 | BZ39: =+'[7]eff all'!$BZ$39:$CA$39 -> 79.267994 | CB39: =+'[7]eff all'!$CB$39:$CC$39 -> 1.957107 | CD39: =+'[7]eff all'!$CD$39:$CE$39 -> 0.21004549 | CF39: =+'[7]eff all'!$CF$39:$CG$39 -> 810.9602 | CH39: =+'[7]eff all'!$CH$39:$CI$39 -> 541.04427 | CJ39: =+'[7]eff all'!$CJ$39:$CK$393 -> 2.8892396
A40: Agustus | B40: =+'[8]eff all'!$B$40:$C$40 -> 0.89986679 | D40: =+'[8]eff all'!$D$40:$E$40 -> 0.9000777 | F40: =+'[8]eff all'!$F$40:$G$40 -> 1865.517 | H40: =+'[8]eff all'!$H$40:$I$40 -> 2.2984749 | J40: =+'[8]eff all'!$J$40:$K$40 -> 910.11683 | L40: =+'[8]eff all'!$L$40:$M$40 -> 0.88665976 | N40: =+'[8]eff all'!$N$40:$O$40 -> 0.91130228 | P40: =+'[8]eff all'!$P$40:$Q$40 -> 1681.041 | R40: =+'[8]eff all'!$R$40:$S$40 -> 2.3611024 | T40: =+'[8]eff all'!$T$40:$U$40 -> 0.085601719 | V40: =+'[8]eff all'!$V$40:$W$40 -> 751.4219 | X40: =+'[8]eff all'!$X$40:$Y$40 -> 160.39778 | Z40: =+'[8]eff all'!$Z$40:$AA$40 -> 0.90643195 | AB40: =+'[8]eff all'!$AB$40:$AC$40 -> 0.90643195 | AD40: =+'[8]eff all'!$AD$40:$AE$40 -> 1304.522 | AF40: =+'[8]eff all'!$AF$40:$AG$40 -> 93.687913 | AH40: =+'[8]eff all'!$AH$40:$AI$40 -> 1.3601917 | AJ40: =+'[8]eff all'!$AJ$40:$AK$40 -> 867.99488 | AL40: =+'[8]eff all'!$AL$40:$AM$40 -> 0 | AN40: =+'[8]eff all'!$AN$40:$AO$40 -> 0.89554899 | AP40: =+'[8]eff all'!$AP$40:$AQ$40 -> 0.90516623 | AR40: =+'[8]eff all'!$AR$40:$AS$40 -> 1480.133 | AT40: =+'[8]eff all'!$AT$40:$AU$40 -> 101.44643 | AV40: =+'[8]eff all'!$AV$40:$AW$40 -> 1.4403435 | AX40: =+'[8]eff all'!$AX$40:$AY$40 -> 0.14586527 | AZ40: =+'[8]eff all'!$AZ$40:$BA$40 -> 849.36179 | BB40: =+'[8]eff all'!$BB$40:$BC$40 -> 387.77383 | BD40: =+'[8]eff all'!$BD$40:$BE$40 -> 4.1014476 | BF40: =+'[8]eff all'!$BF$40:$BG$40 -> 0.90695193 | BH40: =+'[8]eff all'!$BH$40:$BI$40 -> 0.90825057 | BJ40: =+'[8]eff all'!$BJ$40:$BK$40 -> 1465.16 | BL40: =+'[8]eff all'!$BL$40:$BM$40 -> 2.8592099 | BN40: =+'[8]eff all'!$BN$40:$BO$40 -> 0 | BP40: =+'[8]eff all'!$BP$40:$BQ$40 -> 1013.159 | BR40: =+'[8]eff all'!$BR$40:$BS$40 -> 0 | BT40: =+'[8]eff all'!$BT$40:$BU$40 -> 0.86462303 | BV40: =+'[8]eff all'!$BV$40:$BW$40 -> 0.87445113 | BX40: =+'[8]eff all'!$BX$40:$BY$40 -> 1364.354 | BZ40: =+'[8]eff all'!$BZ$40:$CA$40 -> 84.357026 | CB40: =+'[8]eff all'!$CB$40:$CC$40 -> 2.0277802 | CD40: =+'[8]eff all'!$CD$40:$CE$40 -> 0.074687361 | CF40: =+'[8]eff all'!$CF$40:$CG$40 -> 883.67534 | CH40: =+'[8]eff all'!$CH$40:$CI$40 -> 193.15194 | CJ40: =+'[8]eff all'!$CJ$40:$CK$40 -> 2.4682832
A41: Juli | B41: =+'[9]eff all'!$B$41:$C$41 -> 0.83939759 | D41: =+'[9]eff all'!$D$41:$E$41 -> 0.84053151 | F41: =+'[9]eff all'!$F$41:$G$41 -> 1669.03 | H41: =+'[9]eff all'!$H$41:$I$41 -> 2.439188 | J41: =+'[9]eff all'!$J$41:$K$41 -> 1033.4659 | L41: =+'[9]eff all'!$L$41:$M$41 -> 0.88164645 | N41: =+'[9]eff all'!$N$41:$O$41 -> 0.90721678 | P41: =+'[9]eff all'!$P$41:$Q$41 -> 1849.253 | R41: =+'[9]eff all'!$R$41:$S$41 -> 2.6039628 | T41: =+'[9]eff all'!$T$41:$U$41 -> 0.22857878 | V41: =+'[9]eff all'!$V$41:$W$41 -> 604.72262 | X41: =+'[9]eff all'!$X$41:$Y$41 -> 521.78582 | Z41: =+'[9]eff all'!$Z$41:$AA$41 -> 0.88193173 | AB41: =+'[9]eff all'!$AB$41:$AC$41 -> 0.88340653 | AD41: =+'[9]eff all'!$AD$41:$AE$41 -> 1253.705 | AF41: =+'[9]eff all'!$AF$41:$AG$41 -> 98.517031 | AH41: =+'[9]eff all'!$AH$41:$AI$41 -> 1.4871122 | AJ41: =+'[9]eff all'!$AJ$41:$AK$41 -> 885.26052 | AL41: =+'[9]eff all'!$AL$41:$AM$41 -> 0 | AN41: =+'[9]eff all'!$AN$41:$AO$41 -> 0.88320077 | AP41: =+'[9]eff all'!$AP$41:$AQ$41 -> 0.8953444 | AR41: =+'[9]eff all'!$AR$41:$AS$41 -> 1406.635 | AT41: =+'[9]eff all'!$AT$41:$AU$41 -> 105.33379 | AV41: =+'[9]eff all'!$AV$41:$AW$41 -> 1.5242049 | AX41: =+'[9]eff all'!$AX$41:$AY$41 -> 0.080760112 | AZ41: =+'[9]eff all'!$AZ$41:$BA$41 -> 927.60065 | BB41: =+'[9]eff all'!$BB$41:$BC$41 -> 240.27392 | BD41: =+'[9]eff all'!$BD$41:$BE$41 -> 16.955358 | BF41: =+'[9]eff all'!$BF$41:$BG$41 -> 0.88101947 | BH41: =+'[9]eff all'!$BH$41:$BI$41 -> 0.8836277 | BJ41: =+'[9]eff all'!$BJ$41:$BK$41 -> 1457.009 | BL41: =+'[9]eff all'!$BL$41:$BM$41 -> 2.7597633 | BN41: =+'[9]eff all'!$BN$41:$BO$41 -> 0 | BP41: =+'[9]eff all'!$BP$41:$BQ$41 -> 932.94369 | BR41: =+'[9]eff all'!$BR$41:$BS$41 -> 0 | BT41: =+'[9]eff all'!$BT$41:$BU$41 -> 0.89958178 | BV41: =+'[9]eff all'!$BV$41:$BW$41 -> 0.90458737 | BX41: =+'[9]eff all'!$BX$41:$BY$41 -> 1385.694 | BZ41: =+'[9]eff all'!$BZ$41:$CA$41 -> 82.805082 | CB41: =+'[9]eff all'!$CB$41:$CC$41 -> 1.975097 | CD41: =+'[9]eff all'!$CD$41:$CE$41 -> 0.056505982 | CF41: =+'[9]eff all'!$CF$41:$CG$41 -> 886.8081 | CH41: =+'[9]eff all'!$CH$41:$CI$41 -> 150.23872 | CJ41: =+'[9]eff all'!$CJ$41:$CK$41 -> 14.750731
A42: Juni | B42: =+'[10]eff all'!$B$42:$C$42 -> 0.89683017 | D42: =+'[10]eff all'!$D$42:$E$42 -> 0.91651255 | F42: =+'[10]eff all'!$F$42:$G$42 -> 1608.12 | H42: =+'[10]eff all'!$H$42:$I$42 -> 2.3160038 | J42: =+'[10]eff all'!$J$42:$K$42 -> 1025.4408 | L42: =+'[10]eff all'!$L$42:$M$42 -> 0.92866755 | N42: =+'[10]eff all'!$N$42:$O$42 -> 0.93793898 | P42: =+'[10]eff all'!$P$42:$Q$42 -> 1827.359 | R42: =+'[10]eff all'!$R$42:$S$42 -> 2.0916447 | T42: =+'[10]eff all'!$T$42:$U$42 -> 0.23153633 | V42: =+'[10]eff all'!$V$42:$W$42 -> 614.27863 | X42: =+'[10]eff all'!$X$42:$Y$42 -> 437.11553 | Z42: =+'[10]eff all'!$Z$42:$AA$42 -> 0.83629624 | AB42: =+'[10]eff all'!$AB$42:$AC$42 -> 0.84011645 | AD42: =+'[10]eff all'!$AD$42:$AE$42 -> 1132.285 | AF42: =+'[10]eff all'!$AF$42:$AG$42 -> 111.282 | AH42: =+'[10]eff all'!$AH$42:$AI$42 -> 1.6594762 | AJ42: =+'[10]eff all'!$AJ$42:$AK$42 -> 964.83334 | AL42: =+'[10]eff all'!$AL$42:$AM$42 -> 0 | AN42: =+'[10]eff all'!$AN$42:$AO$42 -> 0.84149356 | AP42: =+'[10]eff all'!$AP$42:$AQ$42 -> 0.85108231 | AR42: =+'[10]eff all'!$AR$42:$AS$42 -> 1316.344 | AT42: =+'[10]eff all'!$AT$42:$AU$42 -> 121.83944 | AV42: =+'[10]eff all'!$AV$42:$AW$42 -> 1.4904159 | AX42: =+'[10]eff all'!$AX$42:$AY$42 -> 0.19523772 | AZ42: =+'[10]eff all'!$AZ$42:$BA$42 -> 883.634 | BB42: =+'[10]eff all'!$BB$42:$BC$42 -> 521.8822 | BD42: =+'[10]eff all'!$BD$42:$BE$42 -> 0 | BF42: =+'[10]eff all'!$BF$42:$BG$42 -> 0.81559728 | BH42: =+'[10]eff all'!$BH$42:$BI$42 -> 0.82877821 | BJ42: =+'[10]eff all'!$BJ$42:$BK$42 -> 1259.735 | BL42: =+'[10]eff all'!$BL$42:$BM$42 -> 2.8948152 | BN42: =+'[10]eff all'!$BN$42:$BO$42 -> 0 | BP42: =+'[10]eff all'!$BP$42:$BQ$42 -> 971.0194 | BR42: =+'[10]eff all'!$BR$42:$BS$42 -> 0 | BT42: =+'[10]eff all'!$BT$42:$BU$42 -> 0.90927146 | BV42: =+'[10]eff all'!$BV$42:$BW$42 -> 0.93351911 | BX42: =+'[10]eff all'!$BX$42:$BY$42 -> 1433.06 | BZ42: =+'[10]eff all'!$BZ$42:$CA$42 -> 77.094083 | CB42: =+'[10]eff all'!$CB$42:$CC$42 -> 1.8864528 | CD42: =+'[10]eff all'!$CD$42:$CE$42 -> 0.14263185 | CF42: =+'[10]eff all'!$CF$42:$CG$42 -> 754.59782 | CH42: =+'[10]eff all'!$CH$42:$CI$42 -> 384.70371 | CJ42: 0
A43: Mei | B43: =+'[11]eff all'!$B$43:$C$43 -> 0.81728993 | D43: =+'[11]eff all'!$D$43:$E$43 -> 0.81728993 | F43: =+'[11]eff all'!$F$43:$G$43 -> 1753.698 | H43: =+'[11]eff all'!$H$43:$I$43 -> 2.3283627 | J43: =+'[11]eff all'!$J$43:$K$43 -> 919.17355 | L43: =+'[11]eff all'!$L$43:$M$43 -> 0.88541366 | N43: =+'[11]eff all'!$N$43:$O$43 -> 0.92564375 | P43: =+'[11]eff all'!$P$43:$Q$43 -> 1848.366 | R43: =+'[11]eff all'!$R$43:$S$43 -> 2.3081273 | T43: =+'[11]eff all'!$T$43:$U$43 -> 0.22165523 | V43: =+'[11]eff all'!$V$43:$W$43 -> 640.41015 | X43: =+'[11]eff all'!$X$43:$Y$43 -> 434.93518 | Z43: =+'[11]eff all'!$Z$43:$AA$43 -> 0.80335181 | AB43: =+'[11]eff all'!$AB$43:$AC$43 -> 0.86162049 | AD43: =+'[11]eff all'!$AD$43:$AE$43 -> 1130.835 | AF43: =+'[11]eff all'!$AF$43:$AG$43 -> 107.89352 | AH43: =+'[11]eff all'!$AH$43:$AI$43 -> 1.5947508 | AJ43: =+'[11]eff all'!$AJ$43:$AK$43 -> 914.38362 | AL43: =+'[11]eff all'!$AL$43:$AM$43 -> 20.16563 | AN43: =+'[11]eff all'!$AN$43:$AO$43 -> 0.85071019 | AP43: =+'[11]eff all'!$AP$43:$AQ$43 -> 0.85071019 | AR43: =+'[11]eff all'!$AR$43:$AS$43 -> 1375.357 | AT43: =+'[11]eff all'!$AT$43:$AU$43 -> 113.79765 | AV43: =+'[11]eff all'!$AV$43:$AW$43 -> 1.4656558 | AX43: =+'[11]eff all'!$AX$43:$AY$43 -> 0.18613349 | AZ43: =+'[11]eff all'!$AZ$43:$BA$43 -> 878.46065 | BB43: =+'[11]eff all'!$BB$43:$BC$43 -> 550.25946 | BD43: =+'[11]eff all'!$BD$43:$BE$43 -> 0 | BF43: =+'[11]eff all'!$BF$43:$BG$43 -> 0.89363459 | BH43: =+'[11]eff all'!$BH$43:$BI$43 -> 0.89363459 | BJ43: =+'[11]eff all'!$BJ$43:$BK$43 -> 1430.692 | BL43: =+'[11]eff all'!$BL$43:$BM$43 -> 2.6821286 | BN43: =+'[11]eff all'!$BN$43:$BO$43 -> 0 | BP43: =+'[11]eff all'!$BP$43:$BQ$43 -> 974.33569 | BR43: =+'[11]eff all'!$BR$43:$BS$43 -> 0 | BT43: =+'[11]eff all'!$BT$43:$BU$43 -> 0.90863448 | BV43: =+'[11]eff all'!$BV$43:$BW$43 -> 0.9187839 | BX43: =+'[11]eff all'!$BX$43:$BY$43 -> 1460.105 | BZ43: =+'[11]eff all'!$BZ$43:$CA$43 -> 77.669648 | CB43: =+'[11]eff all'!$CB$43:$CC$43 -> 2.0032806 | CD43: =+'[11]eff all'!$CD$43:$CE$43 -> 0.083692611 | CF43: =+'[11]eff all'!$CF$43:$CG$43 -> 840.76602 | CH43: =+'[11]eff all'!$CH$43:$CI$43 -> 246.27503 | CJ43: =+'[11]eff all'!$CJ$43:$CK$43 -> 19.550649
A44: April | B44: =+'[12]eff all'!$B$44:$C$44 -> 0.8512863 | D44: =+'[12]eff all'!$D$44:$E$44 -> 0.88261389 | F44: =+'[12]eff all'!$F$44:$G$44 -> 1626.863 | H44: =+'[12]eff all'!$H$44:$I$44 -> 2.4992418 | J44: =+'[12]eff all'!$J$44:$K$44 -> 943.70529 | L44: =+'[12]eff all'!$L$44:$M$44 -> 0.91684997 | N44: =+'[12]eff all'!$N$44:$O$44 -> 0.94547697 | P44: =+'[12]eff all'!$P$44:$Q$44 -> 1788.166 | R44: =+'[12]eff all'!$R$44:$S$44 -> 2.1331811 | T44: =+'[12]eff all'!$T$44:$U$44 -> 0.2123125 | V44: =+'[12]eff all'!$V$44:$W$44 -> 722.25094 | X44: =+'[12]eff all'!$X$44:$Y$44 -> 464.24761 | Z44: =+'[12]eff all'!$Z$44:$AA$44 -> 0.8620695 | AB44: =+'[12]eff all'!$AB$44:$AC$44 -> 0.90942581 | AD44: =+'[12]eff all'!$AD$44:$AE$44 -> 1188.791 | AF44: =+'[12]eff all'!$AF$44:$AG$44 -> 106.25948 | AH44: =+'[12]eff all'!$AH$44:$AI$44 -> 1.5097692 | AJ44: =+'[12]eff all'!$AJ$44:$AK$44 -> 921.84495 | AL44: =+'[12]eff all'!$AL$44:$AM$44 -> 7.553893 | AN44: =+'[12]eff all'!$AN$44:$AO$44 -> 0.9113018 | AP44: =+'[12]eff all'!$AP$44:$AQ$44 -> 0.94321744 | AR44: =+'[12]eff all'!$AR$44:$AS$44 -> 1441.538 | AT44: =+'[12]eff all'!$AT$44:$AU$44 -> 98.381361 | AV44: =+'[12]eff all'!$AV$44:$AW$44 -> 1.4245896 | AX44: =+'[12]eff all'!$AX$44:$AY$44 -> 0.063755313 | AZ44: =+'[12]eff all'!$AZ$44:$BA$44 -> 884.49349 | BB44: =+'[12]eff all'!$BB$44:$BC$44 -> 178.97537 | BD44: =+'[12]eff all'!$BD$44:$BE$44 -> 0 | BF44: =+'[12]eff all'!$BF$44:$BG$44 -> 0.83968008 | BH44: =+'[12]eff all'!$BH$44:$BI$44 -> 0.88025535 | BJ44: =+'[12]eff all'!$BJ$44:$BK$44 -> 1283.722 | BL44: =+'[12]eff all'!$BL$44:$BM$44 -> 2.9010175 | BN44: =+'[12]eff all'!$BN$44:$BO$44 -> 0 | BP44: =+'[12]eff all'!$BP$44:$BQ$44 -> 1018.1901 | BR44: =+'[12]eff all'!$BR$44:$BS$44 -> 0 | BT44: =+'[12]eff all'!$BT$44:$BU$44 -> 0.86479672 | BV44: =+'[12]eff all'!$BV$44:$BW$44 -> 0.91368892 | BX44: =+'[12]eff all'!$BX$44:$BY$44 -> 1364.988 | BZ44: =+'[12]eff all'!$BZ$44:$CA$44 -> 71.774412 | CB44: =+'[12]eff all'!$CB$44:$CC$44 -> 1.9880761 | CD44: =+'[12]eff all'!$CD$44:$CE$44 -> 0.17403816 | CF44: =+'[12]eff all'!$CF$44:$CG$44 -> 844.20452 | CH44: =+'[12]eff all'!$CH$44:$CI$44 -> 469.40955 | CJ44: =+'[12]eff all'!$CJ$44:$CK$44 -> 0
