Workbook

Sheet eff all
A1: DATE | B1: PM 11 | L1: PM 12 | Z1: PM 14 | AN1: PM 15 | BF1: PM 16 | BT1: PM 17
B2: Eff Avaliable | D2: Eff Running | F2: PHP (ton) | H2: STEAM/Ton FG | J2: ELECTRIC/ton FG | L2: Eff Avaliable | N2: Eff Running | P2: PHP (ton) | R2: STEAM/ton FG | T2: STEAM DIP/ton FG | V2: ELECTRIC/ton FG | X2: ELECTRIC DIP/ton FG | Z2: Eff Avaliable | AB2: Eff Running | AD2: PHP (ton) | AF2: GAS /ton FG | AH2: STEAM /ton FG | AJ2: ELECTRIC /ton FG | AL2: Electric WPL /ton FG | AN2: Eff Avaliable | AP2: Eff Running | AR2: PHP (ton) | AT2: GAS /ton FG | AV2: STEAM /ton FG | AX2: STEAM DIP /ton FG | AZ2: ELECTRIC /ton FG | BB2: ELECTRIC DIP /ton FG | BD2: Electric WPL /ton FG | BF2: Eff Avaliable | BH2: Eff Running | BJ2: PHP (ton) | BL2: STEAM /ton FG | BN2: STEAM DIP/ton FG | BP2: ELECTRIC /ton FG | BR2: ELECTRIC DIP/ton FG | BT2: Eff Avaliable | BV2: Eff Running | BX2: PHP (ton) | BZ2: GAS /ton FG | CB2: STEAM /ton FG | CD2: STEAM DIP /ton FG | CF2: ELECTRIC /ton FG | CH2: ELECTRIC DIP /ton FG | CJ2: ELECTRIC WPL /ton FG
B3: Today | C3: Todate | D3: Today | E3: Todate | F3: Today | G3: Todate | H3: Today | I3: Todate | J3: Today | K3: Todate | L3: Today | M3: Todate | N3: Today | O3: Todate | P3: Today | Q3: Todate | R3: Today | S3: Todate | T3: Today | U3: Todate | V3: Today | W3: Todate | X3: Today | Y3: Todate | Z3: Today | AA3: Todate | AB3: Today | AC3: Todate | AD3: Today | AE3: Todate | AF3: Today | AG3: Todate | AH3: Today | AI3: Todate | AJ3: Today | AK3: Todate | AL3: Today | AM3: Todate | AN3: Today | AO3: Todate | AP3: Today | AQ3: Todate | AR3: Today | AS3: Todate | AT3: Today | AU3: Todate | AV3: Today | AW3: Todate | AX3: Today | AY3: Todate | AZ3: Today | BA3: Todate | BB3: Today | BC3: Todate | BD3: Today | BE3: Todate | BF3: Today | BG3: Todate | BH3: Today | BI3: Todate | BJ3: Today | BK3: Todate | BL3: Today | BM3: Todate | BN3: Today | BO3: Todate | BP3: Today | BQ3: Todate | BR3: Today | BS3: Todate | BT3: Today | BU3: Todate | BV3: Today | BW3: Todate | BX3: Today | BY3: Todate | BZ3: Today | CA3: Todate | CB3: Today | CC3: Todate | CD3: Today | CE3: Todate | CF3: Today | CG3: Todate | CH3: Today | CI3: Todate | CJ3: Today | CK3: Todate
A4: 45839 | B4: =+Report1!J9 -> 0.99094273 | C4: =+Report1!K9 -> 0.99094273 | D4: =+Report1!AJ9 -> 0.99094273 | E4: =+Report1!AK9 -> 0.99094273 | F4: =+Report1!R9 -> 68.672 | G4: =+Report1!S9 -> 68.672 | H4: =+Report1!X9 -> 2.0336382 | I4: =+Report1!Y9 -> 2.0336382 | J4: =+Report1!AD9 -> 870.29736 | K4: =+Report1!AE9 -> 870.29736 | L4: =+[1]Report1!J9 -> 0.87283823 | M4: =+[1]Report1!K9 -> 0.87283823 | N4: =+[1]Report1!BJ9 -> 0.90228791 | O4: =+[1]Report1!BK9 -> 0.90228791 | P4: =+[1]Report1!R9 -> 59.787 | Q4: =+[1]Report1!S9 -> 59.787 | R4: =+[1]Report1!AL9 -> 2.0316791 | S4: =+[1]Report1!AM9 -> 2.0316791 | T4: =+[1]Report1!AR9 -> 0.26761671 | U4: =+[1]Report1!AS9 -> 0.26761671 | V4: =+[1]Report1!AX9 -> 622.43615 | W4: =+[1]Report1!AY9 -> 622.43615 | X4: =+[1]Report1!BD9 -> 530.73411 | Y4: =+[1]Report1!BE9 -> 530.73411 | Z4: =+[2]Report1!J9 -> 0.7960581 | AA4: =+[2]Report1!K9 -> 0.7960581 | AB4: =+[2]Report1!BC9 -> 0.84102785 | AC4: =+[2]Report1!BD9 -> 0.84102785 | AD4: =+[2]Report1!R9 -> 35.332 | AE4: =+[2]Report1!S9 -> 35.332 | AF4: =+[2]Report1!X9 -> 111.72373 | AG4: =+[2]Report1!Y9 -> 111.72373 | AH4: =+[2]Report1!AD9 -> 1.6330805 | AI4: =+[2]Report1!AE9 -> 1.6330805 | AJ4: =+[2]Report1!AJ9 -> 1031.5029 | AK4: =+[2]Report1!AK9 -> 1031.5029 | AL4: =+[3]Report1!AP9 -> 0 | AM4: =+[3]Report1!AQ9 -> 0 | AN4: =+[4]Report1!J9 -> 0.55958666 | AO4: =+[4]Report1!K9 -> 0.55958666 | AP4: =+[4]Report1!BN9 -> 0.55958666 | AQ4: =+[4]Report1!BO9 -> 0.55958666 | AR4: =+[4]Report1!R9 -> 28.595 | AS4: =+[4]Report1!S9 -> 28.595 | AT4: =+[4]Report1!AF9 -> 151.92345 | AU4: =+[4]Report1!AG9 -> 151.92345 | AV4: =+[4]Report1!AL9 -> 2.0108411 | AW4: =+[4]Report1!AM9 -> 2.0108411 | AX4: =+[4]Report1!AR9 -> 0.26927785 | AY4: =+[4]Report1!AS9 -> 0.26927785 | AZ4: =+[4]Report1!AX9 -> 1170.3116 | BA4: =+[4]Report1!AY9 -> 1170.3116 | BB4: =+[4]Report1!BD9 -> 758.87393 | BC4: =+[4]Report1!BE9 -> 758.87393 | BD4: =+[4]Report1!BJ9 -> 0 | BE4: =+[4]Report1!BK9 -> 0 | BF4: =+[5]Report1!J9 -> 0.69481654 | BG4: =+[5]Report1!K9 -> 0.69481654 | BH4: =+[5]Report1!AN9 -> 0.69481654 | BI4: =+[5]Report1!AO9 -> 0.69481654 | BJ4: =+[5]Report1!R9 -> 36.506 | BK4: =+[5]Report1!S9 -> 36.506 | BL4: =+[5]Report1!AD9 -> 3.6487153 | BM4: =+[5]Report1!AE9 -> 3.6487153 | BN4: 0 | BO4: 0 | BP4: =+[5]Report1!AJ9 -> 1068.8222 | BQ4: =+[5]Report1!AK9 -> 1068.8222 | BR4: 0 | BS4: 0 | BT4: =+[6]Report1!J9 -> 0.43564258 | BU4: =+[6]Report1!K9 -> 0.43564258 | BV4: =+[6]Report1!BG9 -> 0.4884309 | BW4: =+[6]Report1!BH9 -> 0.4884309 | BX4: =+[6]Report1!R9 -> 20.062 | BY4: =+[6]Report1!S9 -> 20.062 | BZ4: =+[6]Report1!X9 -> 132.60524 | CA4: =+[6]Report1!Y9 -> 132.60524 | CB4: =+[6]Report1!AD9 -> 3.1602034 | CC4: =+[6]Report1!AE9 -> 3.1602034 | CD4: =+[6]Report1!AJ9 -> 0 | CE4: =+[6]Report1!AK9 -> 0 | CF4: =+[6]Report1!AP9 -> 1533.8334 | CG4: =+[6]Report1!AQ9 -> 1533.8334 | CH4: =+[6]Report1!AV9 -> 0 | CI4: =+[6]Report1!AW9 -> 0 | CJ4: =+[6]Report1!BB9 -> 0 | CK4: =+[6]Report1!BC9 -> 0
A5: =1+A4 -> 45840 | B5: =+Report1!J10 -> 0.99122114 | C5: =+Report1!K10 -> 0.99108287 | D5: =+Report1!AJ10 -> 0.99815275 | E5: =+Report1!AK10 -> 0.99455957 | F5: =+Report1!R10 -> 69.627 | G5: =+Report1!S10 -> 138.299 | H5: =+Report1!X10 -> 2.0488316 | I5: =+Report1!Y10 -> 2.0412874 | J5: =+Report1!AD10 -> 855.42103 | K5: =+Report1!AE10 -> 862.80783 | L5: =+[1]Report1!J10 -> 0.96540934 | M5: =+[1]Report1!K10 -> 0.91888568 | N5: =+[1]Report1!BJ10 -> 0.99655158 | O5: =+[1]Report1!BK10 -> 0.9492111 | P5: =+[1]Report1!R10 -> 65.451 | Q5: =+[1]Report1!S10 -> 125.238 | R5: =+[1]Report1!AL10 -> 2.1193565 | S5: =+[1]Report1!AM10 -> 2.0775004 | T5: =+[1]Report1!AR10 -> 0.22917908 | U5: =+[1]Report1!AS10 -> 0.24752871 | V5: =+[1]Report1!AX10 -> 610.97004 | W5: =+[1]Report1!AY10 -> 616.44381 | X5: =+[1]Report1!BD10 -> 452.6898 | Y5: =+[1]Report1!BE10 -> 489.94714 | Z5: =+[2]Report1!J10 -> 0.8370308 | AA5: =+[2]Report1!K10 -> 0.81659189 | AB5: =+[2]Report1!BC10 -> 0.8370308 | AC5: =+[2]Report1!BD10 -> 0.8389698 | AD5: =+[2]Report1!R10 -> 37.323 | AE5: =+[2]Report1!S10 -> 72.655 | AF5: =+[2]Report1!X10 -> 100.50054 | AG5: =+[2]Report1!Y10 -> 105.95835 | AH5: =+[2]Report1!AD10 -> 1.5888326 | AI5: =+[2]Report1!AE10 -> 1.6103503 | AJ5: =+[2]Report1!AJ10 -> 926.51716 | AK5: =+[2]Report1!AK10 -> 977.57154 | AL5: =+[3]Report1!AP10 -> 0 | AM5: =+[3]Report1!AQ10 -> 0 | AN5: =+[4]Report1!J10 -> 0.59463544 | AO5: =+[4]Report1!K10 -> 0.57711105 | AP5: =+[4]Report1!BN10 -> 0.65115972 | AQ5: =+[4]Report1!BO10 -> 0.60329576 | AR5: =+[4]Report1!R10 -> 30.386 | AS5: =+[4]Report1!S10 -> 58.981 | AT5: =+[4]Report1!AF10 -> 124.9005 | AU5: =+[4]Report1!AG10 -> 138.00169 | AV5: =+[4]Report1!AL10 -> 1.9318107 | AW5: =+[4]Report1!AM10 -> 1.970126 | AX5: =+[4]Report1!AR10 -> 0.08885671 | AY5: =+[4]Report1!AS10 -> 0.17632797 | AZ5: =+[4]Report1!AX10 -> 1152.5176 | BA5: =+[4]Report1!AY10 -> 1161.1444 | BB5: =+[4]Report1!BD10 -> 434.73968 | BC5: =+[4]Report1!BE10 -> 591.88552 | BD5: =+[4]Report1!BJ10 -> 0 | BE5: =+[4]Report1!BK10 -> 0 | BF5: =+[5]Report1!J10 -> 0.72883595 | BG5: =+[5]Report1!K10 -> 0.71173595 | BH5: =+[5]Report1!AN10 -> 0.77046479 | BI5: =+[5]Report1!AO10 -> 0.73138986 | BJ5: =+[5]Report1!R10 -> 37.889 | BK5: =+[5]Report1!S10 -> 74.395 | BL5: =+[5]Report1!AD10 -> 3.705561 | BM5: =+[5]Report1!AE10 -> 3.6776665 | BN5: 0 | BO5: 0 | BP5: =+[5]Report1!AJ10 -> 1183.9126 | BQ5: =+[5]Report1!AK10 -> 1127.4372 | BR5: 0 | BS5: 0 | BT5: =+[6]Report1!J10 -> 0.77542102 | BU5: =+[6]Report1!K10 -> 0.60392217 | BV5: =+[6]Report1!BG10 -> 0.81385296 | BW5: =+[6]Report1!BH10 -> 0.65496921 | BX5: =+[6]Report1!R10 -> 35.039 | BY5: =+[6]Report1!S10 -> 55.101 | BZ5: =+[6]Report1!X10 -> 71.657067 | CA5: =+[6]Report1!Y10 -> 93.847992 | CB5: =+[6]Report1!AD10 -> 2.0120437 | CC5: =+[6]Report1!AE10 -> 2.4300829 | CD5: =+[6]Report1!AJ10 -> 0 | CE5: =+[6]Report1!AK10 -> 0 | CF5: =+[6]Report1!AP10 -> 992.72025 | CG5: =+[6]Report1!AQ10 -> 1189.7368 | CH5: =+[6]Report1!AV10 -> 0 | CI5: =+[6]Report1!AW10 -> 0 | CJ5: =+[6]Report1!BB10 -> 0 | CK5: =+[6]Report1!BC10 -> 0
A6: =1+A5 -> 45841 | B6: =+Report1!J11 -> 0.9140773 | C6: =+Report1!K11 -> 0.96267081 | D6: =+Report1!AJ11 -> 0.93934384 | E6: =+Report1!AK11 -> 0.97449166 | F6: =+Report1!R11 -> 74.579 | G6: =+Report1!S11 -> 212.878 | H6: =+Report1!X11 -> 2.083187 | I6: =+Report1!Y11 -> 2.0559663 | J6: =+Report1!AD11 -> 773.43864 | K6: =+Report1!AE11 -> 831.49851 | L6: =+[1]Report1!J11 -> 0.99304793 | M6: =+[1]Report1!K11 -> 0.94406248 | N6: =+[1]Report1!BJ11 -> 1.0020946 | O6: =+[1]Report1!BK11 -> 0.96744266 | P6: =+[1]Report1!R11 -> 69.563 | Q6: =+[1]Report1!S11 -> 194.801 | R6: =+[1]Report1!AL11 -> 2.1498498 | S6: =+[1]Report1!AM11 -> 2.1033362 | T6: =+[1]Report1!AR11 -> 0.2228196 | U6: =+[1]Report1!AS11 -> 0.23870514 | V6: =+[1]Report1!AX11 -> 589.34089 | W6: =+[1]Report1!AY11 -> 606.76542 | X6: =+[1]Report1!BD11 -> 435.14512 | Y6: =+[1]Report1!BE11 -> 470.37746 | Z6: =+[2]Report1!J11 -> 0.91724471 | AA6: =+[2]Report1!K11 -> 0.84957779 | AB6: =+[2]Report1!BC11 -> 0.91724471 | AC6: =+[2]Report1!BD11 -> 0.86509041 | AD6: =+[2]Report1!R11 -> 39.783 | AE6: =+[2]Report1!S11 -> 112.438 | AF6: =+[2]Report1!X11 -> 102.53546 | AG6: =+[2]Report1!Y11 -> 104.74726 | AH6: =+[2]Report1!AD11 -> 1.5433728 | AI6: =+[2]Report1!AE11 -> 1.5866522 | AJ6: =+[2]Report1!AJ11 -> 933.37054 | AK6: =+[2]Report1!AK11 -> 961.93226 | AL6: =+[3]Report1!AP11 -> 0 | AM6: =+[3]Report1!AQ11 -> 0 | AN6: =+[4]Report1!J11 -> 0.60619657 | AO6: =+[4]Report1!K11 -> 0.58678601 | AP6: =+[4]Report1!BN11 -> 0.82055154 | AQ6: =+[4]Report1!BO11 -> 0.66368102 | AR6: =+[4]Report1!R11 -> 30.88 | AS6: =+[4]Report1!S11 -> 89.861 | AT6: =+[4]Report1!AF11 -> 113.48988 | AU6: =+[4]Report1!AG11 -> 129.5784 | AV6: =+[4]Report1!AL11 -> 1.6547927 | AW6: =+[4]Report1!AM11 -> 1.8617643 | AX6: =+[4]Report1!AR11 -> 0.084196891 | AY6: =+[4]Report1!AS11 -> 0.14466788 | AZ6: =+[4]Report1!AX11 -> 1138.6749 | BA6: =+[4]Report1!AY11 -> 1153.423 | BB6: =+[4]Report1!BD11 -> 239.63731 | BC6: =+[4]Report1!BE11 -> 470.83829 | BD6: =+[4]Report1!BJ11 -> 0 | BE6: =+[4]Report1!BK11 -> 0 | BF6: =+[5]Report1!J11 -> 0.88011508 | BG6: =+[5]Report1!K11 -> 0.76778703 | BH6: =+[5]Report1!AN11 -> 0.91308769 | BI6: =+[5]Report1!AO11 -> 0.79149024 | BJ6: =+[5]Report1!R11 -> 45.905 | BK6: =+[5]Report1!S11 -> 120.3 | BL6: =+[5]Report1!AD11 -> 3.2196928 | BM6: =+[5]Report1!AE11 -> 3.5029094 | BN6: 0 | BO6: 0 | BP6: =+[5]Report1!AJ11 -> 1036.8897 | BQ6: =+[5]Report1!AK11 -> 1092.8854 | BR6: 0 | BS6: 0 | BT6: =+[6]Report1!J11 -> 0.85057527 | BU6: =+[6]Report1!K11 -> 0.6856189 | BV6: =+[6]Report1!BG11 -> 0.86867262 | BW6: =+[6]Report1!BH11 -> 0.72862511 | BX6: =+[6]Report1!R11 -> 38.435 | BY6: =+[6]Report1!S11 -> 93.536 | BZ6: =+[6]Report1!X11 -> 83.186272 | CA6: =+[6]Report1!Y11 -> 89.466971 | CB6: =+[6]Report1!AD11 -> 2.2297385 | CC6: =+[6]Report1!AE11 -> 2.3477592 | CD6: =+[6]Report1!AJ11 -> 0 | CE6: =+[6]Report1!AK11 -> 0 | CF6: =+[6]Report1!AP11 -> 1046.9213 | CG6: =+[6]Report1!AQ11 -> 1131.0523 | CH6: =+[6]Report1!AV11 -> 0 | CI6: =+[6]Report1!AW11 -> 0 | CJ6: =+[6]Report1!BB11 -> 0 | CK6: =+[6]Report1!BC11 -> 0
A7: =1+A6 -> 45842 | B7: =+Report1!J12 -> 0.94664245 | C7: =+Report1!K12 -> 0.95829495 | D7: =+Report1!AJ12 -> 0.94664245 | E7: =+Report1!AK12 -> 0.96682097 | F7: =+Report1!R12 -> 78.611 | G7: =+Report1!S12 -> 291.489 | H7: =+Report1!X12 -> 2.032769 | I7: =+Report1!Y12 -> 2.0497103 | J7: =+Report1!AD12 -> 752.43795 | K7: =+Report1!AE12 -> 810.17685 | L7: =+[1]Report1!J12 -> 0.98739656 | M7: =+[1]Report1!K12 -> 0.95489406 | N7: =+[1]Report1!BJ12 -> 0.98739656 | O7: =+[1]Report1!BK12 -> 0.97252232 | P7: =+[1]Report1!R12 -> 67.898 | Q7: =+[1]Report1!S12 -> 262.699 | R7: =+[1]Report1!AL12 -> 2.1459542 | S7: =+[1]Report1!AM12 -> 2.1143514 | T7: =+[1]Report1!AR12 -> 0.24742997 | U7: =+[1]Report1!AS12 -> 0.24096019 | V7: =+[1]Report1!AX12 -> 611.17485 | W7: =+[1]Report1!AY12 -> 607.90509 | X7: =+[1]Report1!BD12 -> 498.88067 | Y7: =+[1]Report1!BE12 -> 477.74449 | Z7: =+[2]Report1!J12 -> 0.96262026 | AA7: =+[2]Report1!K12 -> 0.87755786 | AB7: =+[2]Report1!BC12 -> 0.96262026 | AC7: =+[2]Report1!BD12 -> 0.88956102 | AD7: =+[2]Report1!R12 -> 41.906 | AE7: =+[2]Report1!S12 -> 154.344 | AF7: =+[2]Report1!X12 -> 102.76159 | AG7: =+[2]Report1!Y12 -> 104.20813 | AH7: =+[2]Report1!AD12 -> 1.481888 | AI7: =+[2]Report1!AE12 -> 1.5582076 | AJ7: =+[2]Report1!AJ12 -> 920.86813 | AK7: =+[2]Report1!AK12 -> 950.78293 | AL7: =+[3]Report1!AP12 -> 0 | AM7: =+[3]Report1!AQ12 -> 0 | AN7: =+[4]Report1!J12 -> 0.086822782 | AO7: =+[4]Report1!K12 -> 0.45840062 | AP7: =+[4]Report1!BN12 -> 0.09365154 | AQ7: =+[4]Report1!BO12 -> 0.51208428 | AR7: =+[4]Report1!R12 -> 4.594 | AS7: =+[4]Report1!S12 -> 94.455 | AT7: =+[4]Report1!AF12 -> 371.94786 | AU7: =+[4]Report1!AG12 -> 141.36651 | AV7: =+[4]Report1!AL12 -> 6.8785372 | AW7: =+[4]Report1!AM12 -> 2.1057646 | AX7: =+[4]Report1!AR12 -> 0 | AY7: =+[4]Report1!AS12 -> 0.13763168 | AZ7: =+[4]Report1!AX12 -> 4505.8555 | BA7: =+[4]Report1!AY12 -> 1316.4749 | BB7: =+[4]Report1!BD12 -> 0 | BC7: =+[4]Report1!BE12 -> 447.93817 | BD7: =+[4]Report1!BJ12 -> 0 | BE7: =+[4]Report1!BK12 -> 0 | BF7: =+[5]Report1!J12 -> 0.923445 | BG7: =+[5]Report1!K12 -> 0.80666235 | BH7: =+[5]Report1!AN12 -> 0.923445 | BI7: =+[5]Report1!AO12 -> 0.82520319 | BJ7: =+[5]Report1!R12 -> 48.165 | BK7: =+[5]Report1!S12 -> 168.465 | BL7: =+[5]Report1!AD12 -> 3.128828 | BM7: =+[5]Report1!AE12 -> 3.3959576 | BN7: 0 | BO7: 0 | BP7: =+[5]Report1!AJ12 -> 929.85602 | BQ7: =+[5]Report1!AK12 -> 1046.2744 | BR7: 0 | BS7: 0 | BT7: =+[6]Report1!J12 -> 0.93192598 | BU7: =+[6]Report1!K12 -> 0.74690258 | BV7: =+[6]Report1!BG12 -> 0.93192598 | BW7: =+[6]Report1!BH12 -> 0.78155523 | BX7: =+[6]Report1!R12 -> 42.111 | BY7: =+[6]Report1!S12 -> 135.647 | BZ7: =+[6]Report1!X12 -> 84.822124 | CA7: =+[6]Report1!Y12 -> 88.024999 | CB7: =+[6]Report1!AD12 -> 2.0018522 | CC7: =+[6]Report1!AE12 -> 2.2403739 | CD7: =+[6]Report1!AJ12 -> 0 | CE7: =+[6]Report1!AK12 -> 0 | CF7: =+[6]Report1!AP12 -> 1017.6243 | CG7: =+[6]Report1!AQ12 -> 1095.8391 | CH7: =+[6]Report1!AV12 -> 0 | CI7: =+[6]Report1!AW12 -> 0 | CJ7: =+[6]Report1!BB12 -> 0 | CK7: =+[6]Report1!BC12 -> 0
A8: =1+A7 -> 45843 | B8: =+Report1!J13 -> 0.95324641 | C8: =+Report1!K13 -> 0.95726238 | D8: =+Report1!AJ13 -> 0.95324641 | E8: =+Report1!AK13 -> 0.96402497 | F8: =+Report1!R13 -> 74.552 | G8: =+Report1!S13 -> 366.041 | H8: =+Report1!X13 -> 2.0579193 | I8: =+Report1!Y13 -> 2.0513822 | J8: =+Report1!AD13 -> 788.8832 | K8: =+Report1!AE13 -> 805.83995 | L8: =+[1]Report1!J13 -> 0.9959051 | M8: =+[1]Report1!K13 -> 0.96316812 | N8: =+[1]Report1!BJ13 -> 0.9959051 | O8: =+[1]Report1!BK13 -> 0.9773091 | P8: =+[1]Report1!R13 -> 69.247 | Q8: =+[1]Report1!S13 -> 331.946 | R8: =+[1]Report1!AL13 -> 2.1263015 | S8: =+[1]Report1!AM13 -> 2.1168443 | T8: =+[1]Report1!AR13 -> 0.22528052 | U8: =+[1]Report1!AS13 -> 0.23768926 | V8: =+[1]Report1!AX13 -> 591.68094 | W8: =+[1]Report1!AY13 -> 604.52058 | X8: =+[1]Report1!BD13 -> 458.73467 | Y8: =+[1]Report1!BE13 -> 473.77887 | Z8: =+[2]Report1!J13 -> 0.90884413 | AA8: =+[2]Report1!K13 -> 0.8839903 | AB8: =+[2]Report1!BC13 -> 0.90884413 | AC8: =+[2]Report1!BD13 -> 0.89356857 | AD8: =+[2]Report1!R13 -> 41.37 | AE8: =+[2]Report1!S13 -> 195.714 | AF8: =+[2]Report1!X13 -> 103.3777 | AG8: =+[2]Report1!Y13 -> 104.03259 | AH8: =+[2]Report1!AD13 -> 1.4914189 | AI8: =+[2]Report1!AE13 -> 1.5440898 | AJ8: =+[2]Report1!AJ13 -> 961.87624 | AK8: =+[2]Report1!AK13 -> 953.12783 | AL8: =+[3]Report1!AP13 -> 0 | AM8: =+[3]Report1!AQ13 -> 0 | AN8: =+[4]Report1!J13 -> 0.85459483 | AO8: =+[4]Report1!K13 -> 0.53381833 | AP8: =+[4]Report1!BN13 -> 0.85459483 | AQ8: =+[4]Report1!BO13 -> 0.58333023 | AR8: =+[4]Report1!R13 -> 41.401 | AS8: =+[4]Report1!S13 -> 135.856 | AT8: =+[4]Report1!AF13 -> 109.18777 | AU8: =+[4]Report1!AG13 -> 131.5603 | AV8: =+[4]Report1!AL13 -> 1.688365 | AW8: =+[4]Report1!AM13 -> 1.9785655 | AX8: =+[4]Report1!AR13 -> 0 | AY8: =+[4]Report1!AS13 -> 0.095689554 | AZ8: =+[4]Report1!AX13 -> 1086.9984 | BA8: =+[4]Report1!AY13 -> 1246.5438 | BB8: =+[4]Report1!BD13 -> 0 | BC8: =+[4]Report1!BE13 -> 311.43269 | BD8: =+[4]Report1!BJ13 -> 0 | BE8: =+[4]Report1!BK13 -> 0 | BF8: =+[5]Report1!J13 -> 0.8647254 | BG8: =+[5]Report1!K13 -> 0.81843475 | BH8: =+[5]Report1!AN13 -> 0.8647254 | BI8: =+[5]Report1!AO13 -> 0.83336256 | BJ8: =+[5]Report1!R13 -> 45.927 | BK8: =+[5]Report1!S13 -> 214.392 | BL8: =+[5]Report1!AD13 -> 3.2399242 | BM8: =+[5]Report1!AE13 -> 3.3625322 | BN8: 0 | BO8: 0 | BP8: =+[5]Report1!AJ13 -> 976.91402 | BQ8: =+[5]Report1!AK13 -> 1031.4161 | BR8: 0 | BS8: 0 | BT8: =+[6]Report1!J13 -> 0.87734603 | BU8: =+[6]Report1!K13 -> 0.77408761 | BV8: =+[6]Report1!BG13 -> 0.87734603 | BW8: =+[6]Report1!BH13 -> 0.80224464 | BX8: =+[6]Report1!R13 -> 41.949 | BY8: =+[6]Report1!S13 -> 177.596 | BZ8: =+[6]Report1!X13 -> 83.691662 | CA8: =+[6]Report1!Y13 -> 87.001445 | CB8: =+[6]Report1!AD13 -> 2.0763308 | CC8: =+[6]Report1!AE13 -> 2.2016262 | CD8: =+[6]Report1!AJ13 -> 0 | CE8: =+[6]Report1!AK13 -> 0 | CF8: =+[6]Report1!AP13 -> 1004.7136 | CG8: =+[6]Report1!AQ13 -> 1074.3148 | CH8: =+[6]Report1!AV13 -> 0 | CI8: =+[6]Report1!AW13 -> 0 | CJ8: =+[6]Report1!BB13 -> 0 | CK8: =+[6]Report1!BC13 -> 0
A9: =1+A8 -> 45844 | B9: =+Report1!J14 -> 0.89766145 | C9: =+Report1!K14 -> 0.94715096 | D9: =+Report1!AJ14 -> 0.89766145 | E9: =+Report1!AK14 -> 0.9527003 | F9: =+Report1!R14 -> 70.131 | G9: =+Report1!S14 -> 436.172 | H9: =+Report1!X14 -> 2.1183927 | I9: =+Report1!Y14 -> 2.0621567 | J9: =+Report1!AD14 -> 789.10411 | K9: =+Report1!AE14 -> 803.14903 | L9: =+[1]Report1!J14 -> 0.99404705 | M9: =+[1]Report1!K14 -> 0.96849148 | N9: =+[1]Report1!BJ14 -> 0.99404705 | O9: =+[1]Report1!BK14 -> 0.98022961 | P9: =+[1]Report1!R14 -> 71.363 | Q9: =+[1]Report1!S14 -> 403.309 | R9: =+[1]Report1!AL14 -> 2.1418102 | S9: =+[1]Report1!AM14 -> 2.1212619 | T9: =+[1]Report1!AR14 -> 0.2059891 | U9: =+[1]Report1!AS14 -> 0.23208012 | V9: =+[1]Report1!AX14 -> 558.14764 | W9: =+[1]Report1!AY14 -> 596.31518 | X9: =+[1]Report1!BD14 -> 409.17562 | Y9: =+[1]Report1!BE14 -> 462.34773 | Z9: =+[2]Report1!J14 -> 0.91062769 | AA9: =+[2]Report1!K14 -> 0.88860181 | AB9: =+[2]Report1!BC14 -> 0.91062769 | AC9: =+[2]Report1!BD14 -> 0.89654829 | AD9: =+[2]Report1!R14 -> 42.211 | AE9: =+[2]Report1!S14 -> 237.925 | AF9: =+[2]Report1!X14 -> 97.936679 | AG9: =+[2]Report1!Y14 -> 102.9511 | AH9: =+[2]Report1!AD14 -> 1.492502 | AI9: =+[2]Report1!AE14 -> 1.5349375 | AJ9: =+[2]Report1!AJ14 -> 886.27751 | AK9: =+[2]Report1!AK14 -> 941.26771 | AL9: =+[3]Report1!AP14 -> 0 | AM9: =+[3]Report1!AQ14 -> 0 | AN9: =+[4]Report1!J14 -> 0.82134858 | AO9: =+[4]Report1!K14 -> 0.57733187 | AP9: =+[4]Report1!BN14 -> 0.82134858 | AQ9: =+[4]Report1!BO14 -> 0.62214694 | AR9: =+[4]Report1!R14 -> 37.275 | AS9: =+[4]Report1!S14 -> 173.131 | AT9: =+[4]Report1!AF14 -> 105.98292 | AU9: =+[4]Report1!AG14 -> 126.05351 | AV9: =+[4]Report1!AL14 -> 1.8189135 | AW9: =+[4]Report1!AM14 -> 1.9441925 | AX9: =+[4]Report1!AR14 -> 0 | AY9: =+[4]Report1!AS14 -> 0.07508765 | AZ9: =+[4]Report1!AX14 -> 1139.119 | BA9: =+[4]Report1!AY14 -> 1223.4153 | BB9: =+[4]Report1!BD14 -> 0 | BC9: =+[4]Report1!BE14 -> 244.38142 | BD9: =+[4]Report1!BJ14 -> 0 | BE9: =+[4]Report1!BK14 -> 0 | BF9: =+[5]Report1!J14 -> 0.82235152 | BG9: =+[5]Report1!K14 -> 0.81910916 | BH9: =+[5]Report1!AN14 -> 0.82235152 | BI9: =+[5]Report1!AO14 -> 0.83143808 | BJ9: =+[5]Report1!R14 -> 44.807 | BK9: =+[5]Report1!S14 -> 259.199 | BL9: =+[5]Report1!AD14 -> 3.2294061 | BM9: =+[5]Report1!AE14 -> 3.3395191 | BN9: 0 | BO9: 0 | BP9: =+[5]Report1!AJ14 -> 916.04336 | BQ9: =+[5]Report1!AK14 -> 1011.4719 | BR9: 0 | BS9: 0 | BT9: =+[6]Report1!J14 -> 0.88337241 | BU9: =+[6]Report1!K14 -> 0.7942603 | BV9: =+[6]Report1!BG14 -> 0.88337241 | BW9: =+[6]Report1!BH14 -> 0.81766108 | BX9: =+[6]Report1!R14 -> 45.879 | BY9: =+[6]Report1!S14 -> 223.475 | BZ9: =+[6]Report1!X14 -> 79.894536 | CA9: =+[6]Report1!Y14 -> 85.54241 | CB9: =+[6]Report1!AD14 -> 2.0772031 | CC9: =+[6]Report1!AE14 -> 2.1760823 | CD9: =+[6]Report1!AJ14 -> 0 | CE9: =+[6]Report1!AK14 -> 0 | CF9: =+[6]Report1!AP14 -> 840.29327 | CG9: =+[6]Report1!AQ14 -> 1026.2706 | CH9: =+[6]Report1!AV14 -> 0 | CI9: =+[6]Report1!AW14 -> 0 | CJ9: =+[6]Report1!BB14 -> 0 | CK9: =+[6]Report1!BC14 -> 0
A10: =1+A9 -> 45845 | B10: =+Report1!J15 -> 0.7651949 | C10: =+Report1!K15 -> 0.9203766 | D10: =+Report1!AJ15 -> 0.7651949 | E10: =+Report1!AK15 -> 0.92497162 | F10: =+Report1!R15 -> 60.798 | G10: =+Report1!S15 -> 496.97 | H10: =+Report1!X15 -> 1.8849469 | I10: =+Report1!Y15 -> 2.0404773 | J10: =+Report1!AD15 -> 785.2334 | K10: =+Report1!AE15 -> 800.95728 | L10: =+[1]Report1!J15 -> 0.99039365 | M10: =+[1]Report1!K15 -> 0.97167803 | N10: =+[1]Report1!BJ15 -> 1.1068627 | O10: =+[1]Report1!BK15 -> 0.99714695 | P10: =+[1]Report1!R15 -> 70.221 | Q10: =+[1]Report1!S15 -> 473.53 | R10: =+[1]Report1!AL15 -> 2.0121189 | S10: =+[1]Report1!AM15 -> 2.1050768 | T10: =+[1]Report1!AR15 -> 0.13955939 | U10: =+[1]Report1!AS15 -> 0.21835998 | V10: =+[1]Report1!AX15 -> 508.55627 | W10: =+[1]Report1!AY15 -> 583.30118 | X10: =+[1]Report1!BD15 -> 363.42405 | Y10: =+[1]Report1!BE15 -> 447.67808 | Z10: =+[2]Report1!J15 -> 0.88237815 | AA10: =+[2]Report1!K15 -> 0.8876939 | AB10: =+[2]Report1!BC15 -> 0.88237815 | AC10: =+[2]Report1!BD15 -> 0.89446538 | AD10: =+[2]Report1!R15 -> 40.352 | AE10: =+[2]Report1!S15 -> 278.277 | AF10: =+[2]Report1!X15 -> 102.87943 | AG10: =+[2]Report1!Y15 -> 102.94071 | AH10: =+[2]Report1!AD15 -> 1.5439136 | AI10: =+[2]Report1!AE15 -> 1.5362391 | AJ10: =+[2]Report1!AJ15 -> 944.20648 | AK10: =+[2]Report1!AK15 -> 941.69385 | AL10: =+[3]Report1!AP15 -> 0 | AM10: =+[3]Report1!AQ15 -> 0 | AN10: =+[4]Report1!J15 -> 0.90295752 | AO10: =+[4]Report1!K15 -> 0.6199729 | AP10: =+[4]Report1!BN15 -> 0.90295752 | AQ10: =+[4]Report1!BO15 -> 0.66137507 | AR10: =+[4]Report1!R15 -> 40.802 | AS10: =+[4]Report1!S15 -> 213.933 | AT10: =+[4]Report1!AF15 -> 94.988414 | AU10: =+[4]Report1!AG15 -> 120.12867 | AV10: =+[4]Report1!AL15 -> 1.6249203 | AW10: =+[4]Report1!AM15 -> 1.8832999 | AX10: =+[4]Report1!AR15 -> 0 | AY10: =+[4]Report1!AS15 -> 0.060766689 | AZ10: =+[4]Report1!AX15 -> 1064.4238 | BA10: =+[4]Report1!AY15 -> 1193.0919 | BB10: =+[4]Report1!BD15 -> 0 | BC10: =+[4]Report1!BE15 -> 197.7722 | BD10: =+[4]Report1!BJ15 -> 0 | BE10: =+[4]Report1!BK15 -> 0 | BF10: =+[5]Report1!J15 -> 0.11559759 | BG10: =+[5]Report1!K15 -> 0.72262749 | BH10: =+[5]Report1!AN15 -> 0.11559759 | BI10: =+[5]Report1!AO15 -> 0.73199321 | BJ10: =+[5]Report1!R15 -> 5.814 | BK10: =+[5]Report1!S15 -> 265.013 | BL10: =+[5]Report1!AD15 -> 7.4475404 | BM10: =+[5]Report1!AE15 -> 3.4296431 | BN10: 0 | BO10: 0 | BP10: =+[5]Report1!AJ15 -> 3126.6649 | BQ10: =+[5]Report1!AK15 -> 1057.8762 | BR10: 0 | BS10: 0 | BT10: =+[6]Report1!J15 -> 0.9353874 | BU10: =+[6]Report1!K15 -> 0.81615983 | BV10: =+[6]Report1!BG15 -> 0.9353874 | BW10: =+[6]Report1!BH15 -> 0.83638201 | BX10: =+[6]Report1!R15 -> 48.341 | BY10: =+[6]Report1!S15 -> 271.816 | BZ10: =+[6]Report1!X15 -> 78.523241 | CA10: =+[6]Report1!Y15 -> 84.294089 | CB10: =+[6]Report1!AD15 -> 1.9817546 | CC10: =+[6]Report1!AE15 -> 2.1415222 | CD10: =+[6]Report1!AJ15 -> 0 | CE10: =+[6]Report1!AK15 -> 0 | CF10: =+[6]Report1!AP15 -> 807.97729 | CG10: =+[6]Report1!AQ15 -> 987.44835 | CH10: =+[6]Report1!AV15 -> 0 | CI10: =+[6]Report1!AW15 -> 0 | CJ10: =+[6]Report1!BB15 -> 0 | CK10: =+[6]Report1!BC15 -> 0
A11: =1+A10 -> 45846 | B11: =+Report1!J16 -> 0.15586048 | C11: =+Report1!K16 -> 0.82419168 | D11: =+Report1!AJ16 -> 0.15586048 | E11: =+Report1!AK16 -> 0.82778655 | F11: =+Report1!R16 -> 12.112 | G11: =+Report1!S16 -> 509.082 | H11: =+Report1!X16 -> 9.0530878 | I11: =+Report1!Y16 -> 2.2073202 | J11: =+Report1!AD16 -> 3460.0908 | K11: =+Report1!AE16 -> 864.22297 | L11: =+[1]Report1!J16 -> 0.032789366 | M11: =+[1]Report1!K16 -> 0.87991138 | N11: =+[1]Report1!BJ16 -> 0.27774522 | O11: =+[1]Report1!BK16 -> 0.98782792 | P11: =+[1]Report1!R16 -> 1.731 | Q11: =+[1]Report1!S16 -> 475.261 | R11: =+[1]Report1!AL16 -> 15.581745 | S11: =+[1]Report1!AM16 -> 2.1541616 | T11: =+[1]Report1!AR16 -> 2.8307337 | U11: =+[1]Report1!AS16 -> 0.22787479 | V11: =+[1]Report1!AX16 -> 4360.0404 | W11: =+[1]Report1!AY16 -> 597.05686 | X11: =+[1]Report1!BD16 -> 12597.343 | Y11: =+[1]Report1!BE16 -> 491.9297 | Z11: =+[2]Report1!J16 -> 0.81886143 | AA11: =+[2]Report1!K16 -> 0.87867824 | AB11: =+[2]Report1!BC16 -> 0.81886143 | AC11: =+[2]Report1!BD16 -> 0.88449721 | AD11: =+[2]Report1!R16 -> 38.69 | AE11: =+[2]Report1!S16 -> 316.967 | AF11: =+[2]Report1!X16 -> 112.52801 | AG11: =+[2]Report1!Y16 -> 104.11096 | AH11: =+[2]Report1!AD16 -> 1.6257431 | AI11: =+[2]Report1!AE16 -> 1.5471642 | AJ11: =+[2]Report1!AJ16 -> 949.04678 | AK11: =+[2]Report1!AK16 -> 942.59137 | AL11: =+[3]Report1!AP16 -> 0 | AM11: =+[3]Report1!AQ16 -> 0 | AN11: =+[4]Report1!J16 -> 0.79964255 | AO11: =+[4]Report1!K16 -> 0.6415151 | AP11: =+[4]Report1!BN16 -> 0.79964255 | AQ11: =+[4]Report1!BO16 -> 0.67891982 | AR11: =+[4]Report1!R16 -> 37.591 | AS11: =+[4]Report1!S16 -> 251.524 | AT11: =+[4]Report1!AF16 -> 109.88356 | AU11: =+[4]Report1!AG16 -> 118.59751 | AV11: =+[4]Report1!AL16 -> 1.7983028 | AW11: =+[4]Report1!AM16 -> 1.8705968 | AX11: =+[4]Report1!AR16 -> 0 | AY11: =+[4]Report1!AS16 -> 0.051684929 | AZ11: =+[4]Report1!AX16 -> 1130.021 | BA11: =+[4]Report1!AY16 -> 1183.6658 | BB11: =+[4]Report1!BD16 -> 0 | BC11: =+[4]Report1!BE16 -> 168.21456 | BD11: =+[4]Report1!BJ16 -> 28.996302 | BE11: =+[4]Report1!BK16 -> 4.3335825 | BF11: =+[5]Report1!J16 -> 0.82757595 | BG11: =+[5]Report1!K16 -> 0.73618571 | BH11: =+[5]Report1!AN16 -> 0.82757595 | BI11: =+[5]Report1!AO16 -> 0.74448061 | BJ11: =+[5]Report1!R16 -> 45.026 | BK11: =+[5]Report1!S16 -> 310.039 | BL11: =+[5]Report1!AD16 -> 2.7806156 | BM11: =+[5]Report1!AE16 -> 3.3353868 | BN11: 0 | BO11: 0 | BP11: =+[5]Report1!AJ16 -> 881.24117 | BQ11: =+[5]Report1!AK16 -> 1032.224 | BR11: 0 | BS11: 0 | BT11: =+[6]Report1!J16 -> 0.9816939 | BU11: =+[6]Report1!K16 -> 0.83838285 | BV11: =+[6]Report1!BG16 -> 0.9850964 | BW11: =+[6]Report1!BH16 -> 0.85671302 | BX11: =+[6]Report1!R16 -> 50.699 | BY11: =+[6]Report1!S16 -> 322.515 | BZ11: =+[6]Report1!X16 -> 73.663358 | CA11: =+[6]Report1!Y16 -> 82.62295 | CB11: =+[6]Report1!AD16 -> 1.8422454 | CC11: =+[6]Report1!AE16 -> 2.0944762 | CD11: =+[6]Report1!AJ16 -> 0 | CE11: =+[6]Report1!AK16 -> 0 | CF11: =+[6]Report1!AP16 -> 799.46557 | CG11: =+[6]Report1!AQ16 -> 957.89766 | CH11: =+[6]Report1!AV16 -> 0 | CI11: =+[6]Report1!AW16 -> 0 | CJ11: =+[6]Report1!BB16 -> 0 | CK11: =+[6]Report1!BC16 -> 0
A12: =1+A11 -> 45847 | B12: =+Report1!J17 -> 0.84062529 | C12: =+Report1!K17 -> 0.82603075 | D12: =+Report1!AJ17 -> 0.84062529 | E12: =+Report1!AK17 -> 0.82922888 | F12: =+Report1!R17 -> 65.429 | G12: =+Report1!S17 -> 574.511 | H12: =+Report1!X17 -> 2.1731801 | I12: =+Report1!Y17 -> 2.2034321 | J12: =+Report1!AD17 -> 806.65546 | K12: =+Report1!AE17 -> 857.66682 | L12: =+[1]Report1!J17 -> 0.31866178 | M12: =+[1]Report1!K17 -> 0.82217008 | N12: =+[1]Report1!BJ17 -> 0.31866178 | O12: =+[1]Report1!BK17 -> 0.91150388 | P12: =+[1]Report1!R17 -> 19.738 | Q12: =+[1]Report1!S17 -> 494.999 | R12: =+[1]Report1!AL17 -> 5.2952173 | S12: =+[1]Report1!AM17 -> 2.2794107 | T12: =+[1]Report1!AR17 -> 0.2989158 | U12: =+[1]Report1!AS17 -> 0.23070754 | V12: =+[1]Report1!AX17 -> 1216.2321 | W12: =+[1]Report1!AY17 -> 621.74637 | X12: =+[1]Report1!BD17 -> 1196.5751 | Y12: =+[1]Report1!BE17 -> 520.02731 | Z12: =+[2]Report1!J17 -> 1.0134814 | AA12: =+[2]Report1!K17 -> 0.89354809 | AB12: =+[2]Report1!BC17 -> 1.0134814 | AC12: =+[2]Report1!BD17 -> 0.89880894 | AD12: =+[2]Report1!R17 -> 45.328 | AE12: =+[2]Report1!S17 -> 362.295 | AF12: =+[2]Report1!X17 -> 99.10689 | AG12: =+[2]Report1!Y17 -> 103.48489 | AH12: =+[2]Report1!AD17 -> 1.3744264 | AI12: =+[2]Report1!AE17 -> 1.5255524 | AJ12: =+[2]Report1!AJ17 -> 811.93655 | AK12: =+[2]Report1!AK17 -> 926.24469 | AL12: =+[3]Report1!AP17 -> 0 | AM12: =+[3]Report1!AQ17 -> 0 | AN12: =+[4]Report1!J17 -> 0.95244056 | AO12: =+[4]Report1!K17 -> 0.67528993 | AP12: =+[4]Report1!BN17 -> 0.95244056 | AQ12: =+[4]Report1!BO17 -> 0.71016598 | AR12: =+[4]Report1!R17 -> 45.508 | AS12: =+[4]Report1!S17 -> 297.032 | AT12: =+[4]Report1!AF17 -> 94.812259 | AU12: =+[4]Report1!AG17 -> 114.95339 | AV12: =+[4]Report1!AL17 -> 1.553573 | AW12: =+[4]Report1!AM17 -> 1.8220259 | AX12: =+[4]Report1!AR17 -> 0 | AY12: =+[4]Report1!AS17 -> 0.043766328 | AZ12: =+[4]Report1!AX17 -> 975.72866 | BA12: =+[4]Report1!AY17 -> 1151.808 | BB12: =+[4]Report1!BD17 -> 0 | BC12: =+[4]Report1!BE17 -> 142.44257 | BD12: =+[4]Report1!BJ17 -> 82.842577 | BE12: =+[4]Report1!BK17 -> 16.361873 | BF12: =+[5]Report1!J17 -> 0.91368518 | BG12: =+[5]Report1!K17 -> 0.75576891 | BH12: =+[5]Report1!AN17 -> 0.91700706 | BI12: =+[5]Report1!AO17 -> 0.7636438 | BJ12: =+[5]Report1!R17 -> 47.718 | BK12: =+[5]Report1!S17 -> 357.757 | BL12: =+[5]Report1!AD17 -> 2.6027914 | BM12: =+[5]Report1!AE17 -> 3.2376725 | BN12: 0 | BO12: 0 | BP12: =+[5]Report1!AJ17 -> 921.98311 | BQ12: =+[5]Report1!AK17 -> 1017.52 | BR12: 0 | BS12: 0 | BT12: =+[6]Report1!J17 -> 0.91168308 | BU12: =+[6]Report1!K17 -> 0.84638117 | BV12: =+[6]Report1!BG17 -> 0.91168308 | BW12: =+[6]Report1!BH17 -> 0.86282775 | BX12: =+[6]Report1!R17 -> 42.956 | BY12: =+[6]Report1!S17 -> 365.471 | BZ12: =+[6]Report1!X17 -> 83.479994 | CA12: =+[6]Report1!Y17 -> 82.723683 | CB12: =+[6]Report1!AD17 -> 2.0160164 | CC12: =+[6]Report1!AE17 -> 2.0852544 | CD12: =+[6]Report1!AJ17 -> 0 | CE12: =+[6]Report1!AK17 -> 0 | CF12: =+[6]Report1!AP17 -> 907.3282 | CG12: =+[6]Report1!AQ17 -> 951.95393 | CH12: =+[6]Report1!AV17 -> 0 | CI12: =+[6]Report1!AW17 -> 0 | CJ12: =+[6]Report1!BB17 -> 0 | CK12: =+[6]Report1!BC17 -> 0
A13: =1+A12 -> 45848 | B13: =+Report1!J18 -> 0.88034017 | C13: =+Report1!K18 -> 0.83075725 | D13: =+Report1!AJ18 -> 0.88034017 | E13: =+Report1!AK18 -> 0.83369277 | F13: =+Report1!R18 -> 58.366 | G13: =+Report1!S18 -> 632.877 | H13: =+Report1!X18 -> 2.277062 | I13: =+Report1!Y18 -> 2.2102225 | J13: =+Report1!AD18 -> 909.17006 | K13: =+Report1!AE18 -> 862.41661 | L13: =+[1]Report1!J18 -> 0.77901133 | M13: =+[1]Report1!K18 -> 0.81825351 | N13: =+[1]Report1!BJ18 -> 0.77901133 | O13: =+[1]Report1!BK18 -> 0.8983042 | P13: =+[1]Report1!R18 -> 46.81 | Q13: =+[1]Report1!S18 -> 541.809 | R13: =+[1]Report1!AL18 -> 4.025721 | S13: =+[1]Report1!AM18 -> 2.4302845 | T13: =+[1]Report1!AR18 -> 0.20081179 | U13: =+[1]Report1!AS18 -> 0.22812467 | V13: =+[1]Report1!AX18 -> 708.01602 | W13: =+[1]Report1!AY18 -> 629.1997 | X13: =+[1]Report1!BD18 -> 676.86392 | Y13: =+[1]Report1!BE18 -> 533.57733 | Z13: =+[2]Report1!J18 -> 0.94552493 | AA13: =+[2]Report1!K18 -> 0.89884313 | AB13: =+[2]Report1!BC18 -> 0.94552493 | AC13: =+[2]Report1!BD18 -> 0.9035932 | AD13: =+[2]Report1!R18 -> 43.485 | AE13: =+[2]Report1!S18 -> 405.78 | AF13: =+[2]Report1!X18 -> 99.934951 | AG13: =+[2]Report1!Y18 -> 103.10446 | AH13: =+[2]Report1!AD18 -> 1.5062665 | AI13: =+[2]Report1!AE18 -> 1.5234856 | AJ13: =+[2]Report1!AJ18 -> 836.83615 | AK13: =+[2]Report1!AK18 -> 916.66332 | AL13: =+[3]Report1!AP18 -> 0 | AM13: =+[3]Report1!AQ18 -> 0 | AN13: =+[4]Report1!J18 -> 0.88444198 | AO13: =+[4]Report1!K18 -> 0.69578332 | AP13: =+[4]Report1!BN18 -> 0.88444198 | AQ13: =+[4]Report1!BO18 -> 0.7280336 | AR13: =+[4]Report1!R18 -> 42.259 | AS13: =+[4]Report1!S18 -> 339.291 | AT13: =+[4]Report1!AF18 -> 106.03576 | AU13: =+[4]Report1!AG18 -> 113.84269 | AV13: =+[4]Report1!AL18 -> 1.6990464 | AW13: =+[4]Report1!AM18 -> 1.8067087 | AX13: =+[4]Report1!AR18 -> 0 | AY13: =+[4]Report1!AS18 -> 0.038315193 | AZ13: =+[4]Report1!AX18 -> 987.95097 | BA13: =+[4]Report1!AY18 -> 1131.3994 | BB13: =+[4]Report1!BD18 -> 0 | BC13: =+[4]Report1!BE18 -> 124.70122 | BD13: =+[4]Report1!BJ18 -> 85.662226 | BE13: =+[4]Report1!BK18 -> 24.993295 | BF13: =+[5]Report1!J18 -> 1.0821527 | BG13: =+[5]Report1!K18 -> 0.78835081 | BH13: =+[5]Report1!AN18 -> 1.0821527 | BI13: =+[5]Report1!AO18 -> 0.7957375 | BJ13: =+[5]Report1!R18 -> 56.808 | BK13: =+[5]Report1!S18 -> 414.565 | BL13: =+[5]Report1!AD18 -> 2.1581467 | BM13: =+[5]Report1!AE18 -> 3.0897447 | BN13: 0 | BO13: 0 | BP13: =+[5]Report1!AJ18 -> 793.42813 | BQ13: =+[5]Report1!AK18 -> 986.81259 | BR13: 0 | BS13: 0 | BT13: =+[6]Report1!J18 -> 0.8661378 | BU13: =+[6]Report1!K18 -> 0.84829975 | BV13: =+[6]Report1!BG18 -> 0.8661378 | BW13: =+[6]Report1!BH18 -> 0.86315482 | BX13: =+[6]Report1!R18 -> 40.226 | BY13: =+[6]Report1!S18 -> 405.697 | BZ13: =+[6]Report1!X18 -> 93.132887 | CA13: =+[6]Report1!Y18 -> 83.755785 | CB13: =+[6]Report1!AD18 -> 2.1279769 | CC13: =+[6]Report1!AE18 -> 2.0894904 | CD13: =+[6]Report1!AJ18 -> 0 | CE13: =+[6]Report1!AK18 -> 0 | CF13: =+[6]Report1!AP18 -> 1022.3837 | CG13: =+[6]Report1!AQ18 -> 958.93724 | CH13: =+[6]Report1!AV18 -> 0 | CI13: =+[6]Report1!AW18 -> 0 | CJ13: =+[6]Report1!BB18 -> 0 | CK13: =+[6]Report1!BC18 -> 0
A14: =1+A13 -> 45849 | B14: =+Report1!J19 -> 0.88129264 | C14: =+Report1!K19 -> 0.83444155 | D14: =+Report1!AJ19 -> 0.88129264 | E14: =+Report1!AK19 -> 0.83717442 | F14: =+Report1!R19 -> 52.796 | G14: =+Report1!S19 -> 685.673 | H14: =+Report1!X19 -> 2.411338 | I14: =+Report1!Y19 -> 2.2257082 | J14: =+Report1!AD19 -> 1099.517 | K14: =+Report1!AE19 -> 880.67306 | L14: =+[1]Report1!J19 -> 0.802732 | M14: =+[1]Report1!K19 -> 0.81674935 | N14: =+[1]Report1!BJ19 -> 0.802732 | O14: =+[1]Report1!BK19 -> 0.88823189 | P14: =+[1]Report1!R19 -> 57.037 | Q14: =+[1]Report1!S19 -> 598.846 | R14: =+[1]Report1!AL19 -> 3.2793976 | S14: =+[1]Report1!AM19 -> 2.5111581 | T14: =+[1]Report1!AR19 -> 0.1648053 | U14: =+[1]Report1!AS19 -> 0.22209383 | V14: =+[1]Report1!AX19 -> 767.86034 | W14: =+[1]Report1!AY19 -> 642.40641 | X14: =+[1]Report1!BD19 -> 625.34846 | Y14: =+[1]Report1!BE19 -> 542.31806 | Z14: =+[2]Report1!J19 -> 0.94659439 | AA14: =+[2]Report1!K19 -> 0.90321316 | AB14: =+[2]Report1!BC19 -> 0.94659439 | AC14: =+[2]Report1!BD19 -> 0.9075474 | AD14: =+[2]Report1!R19 -> 43.048 | AE14: =+[2]Report1!S19 -> 448.828 | AF14: =+[2]Report1!X19 -> 103.18729 | AG14: =+[2]Report1!Y19 -> 103.11241 | AH14: =+[2]Report1!AD19 -> 1.5471102 | AI14: =+[2]Report1!AE19 -> 1.5257515 | AJ14: =+[2]Report1!AJ19 -> 873.67822 | AK14: =+[2]Report1!AK19 -> 912.54053 | AL14: =+[3]Report1!AP19 -> 0 | AM14: =+[3]Report1!AQ19 -> 0 | AN14: =+[4]Report1!J19 -> 0.93233824 | AO14: =+[4]Report1!K19 -> 0.71696211 | AP14: =+[4]Report1!BN19 -> 0.93233824 | AQ14: =+[4]Report1!BO19 -> 0.74709375 | AR14: =+[4]Report1!R19 -> 44.707 | AS14: =+[4]Report1!S19 -> 383.998 | AT14: =+[4]Report1!AF19 -> 104.99133 | AU14: =+[4]Report1!AG19 -> 112.81217 | AV14: =+[4]Report1!AL19 -> 1.6820632 | AW14: =+[4]Report1!AM19 -> 1.7921968 | AX14: =+[4]Report1!AR19 -> 0 | AY14: =+[4]Report1!AS19 -> 0.033854343 | AZ14: =+[4]Report1!AX19 -> 1016.6216 | BA14: =+[4]Report1!AY19 -> 1118.0364 | BB14: =+[4]Report1!BD19 -> 0 | BC14: =+[4]Report1!BE19 -> 110.18287 | BD14: =+[4]Report1!BJ19 -> 85.668911 | BE14: =+[4]Report1!BK19 -> 32.057459 | BF14: =+[5]Report1!J19 -> 0.92288355 | BG14: =+[5]Report1!K19 -> 0.8005705 | BH14: =+[5]Report1!AN19 -> 0.92288355 | BI14: =+[5]Report1!AO19 -> 0.80738455 | BJ14: =+[5]Report1!R19 -> 48.485 | BK14: =+[5]Report1!S19 -> 463.05 | BL14: =+[5]Report1!AD19 -> 2.4976797 | BM14: =+[5]Report1!AE19 -> 3.0277508 | BN14: 0 | BO14: 0 | BP14: =+[5]Report1!AJ19 -> 961.45169 | BQ14: =+[5]Report1!AK19 -> 984.1571 | BR14: 0 | BS14: 0 | BT14: =+[6]Report1!J19 -> 0.66322077 | BU14: =+[6]Report1!K19 -> 0.83168991 | BV14: =+[6]Report1!BG19 -> 0.66322077 | BW14: =+[6]Report1!BH19 -> 0.84492626 | BX14: =+[6]Report1!R19 -> 31.272 | BY14: =+[6]Report1!S19 -> 436.969 | BZ14: =+[6]Report1!X19 -> 121.16737 | CA14: =+[6]Report1!Y19 -> 86.433172 | CB14: =+[6]Report1!AD19 -> 2.7148887 | CC14: =+[6]Report1!AE19 -> 2.1342475 | CD14: =+[6]Report1!AJ19 -> 0 | CE14: =+[6]Report1!AK19 -> 0 | CF14: =+[6]Report1!AP19 -> 1348.4691 | CG14: =+[6]Report1!AQ19 -> 986.81436 | CH14: =+[6]Report1!AV19 -> 0 | CI14: =+[6]Report1!AW19 -> 0 | CJ14: =+[6]Report1!BB19 -> 0 | CK14: =+[6]Report1!BC19 -> 0
A15: =1+A14 -> 45850 | B15: =+Report1!J20 -> 0.78168732 | C15: =+Report1!K20 -> 0.83091104 | D15: =+Report1!AJ20 -> 0.78168732 | E15: =+Report1!AK20 -> 0.83344966 | F15: =+Report1!R20 -> 46.07 | G15: =+Report1!S20 -> 731.743 | H15: =+Report1!X20 -> 2.8061428 | I15: =+Report1!Y20 -> 2.2622519 | J15: =+Report1!AD20 -> 1273.5494 | K15: =+Report1!AE20 -> 905.40826 | L15: =+[1]Report1!J20 -> 0.86502013 | M15: =+[1]Report1!K20 -> 0.8210107 | N15: =+[1]Report1!BJ20 -> 0.86502013 | O15: =+[1]Report1!BK20 -> 0.8860205 | P15: =+[1]Report1!R20 -> 61.412 | Q15: =+[1]Report1!S20 -> 660.258 | R15: =+[1]Report1!AL20 -> 3.074562 | S15: =+[1]Report1!AM20 -> 2.5635615 | T15: =+[1]Report1!AR20 -> 0.1937732 | U15: =+[1]Report1!AS20 -> 0.21945967 | V15: =+[1]Report1!AX20 -> 742.3554 | W15: =+[1]Report1!AY20 -> 651.70288 | X15: =+[1]Report1!BD20 -> 599.2477 | Y15: =+[1]Report1!BE20 -> 547.61321 | Z15: =+[2]Report1!J20 -> 0.94875897 | AA15: =+[2]Report1!K20 -> 0.90706214 | AB15: =+[2]Report1!BC20 -> 0.94875897 | AC15: =+[2]Report1!BD20 -> 0.9110454 | AD15: =+[2]Report1!R20 -> 43.52 | AE15: =+[2]Report1!S20 -> 492.348 | AF15: =+[2]Report1!X20 -> 98.125608 | AG15: =+[2]Report1!Y20 -> 102.67161 | AH15: =+[2]Report1!AD20 -> 1.5372243 | AI15: =+[2]Report1!AE20 -> 1.5267656 | AJ15: =+[2]Report1!AJ20 -> 856.90303 | AK15: =+[2]Report1!AK20 -> 907.62258 | AL15: =+[3]Report1!AP20 -> 0 | AM15: =+[3]Report1!AQ20 -> 0 | AN15: =+[4]Report1!J20 -> 1.0099746 | AO15: =+[4]Report1!K20 -> 0.74096101 | AP15: =+[4]Report1!BN20 -> 1.0099746 | AQ15: =+[4]Report1!BO20 -> 0.76945266 | AR15: =+[4]Report1!R20 -> 48.257 | AS15: =+[4]Report1!S20 -> 432.255 | AT15: =+[4]Report1!AF20 -> 93.853043 | AU15: =+[4]Report1!AG20 -> 110.69557 | AV15: =+[4]Report1!AL20 -> 1.5458897 | AW15: =+[4]Report1!AM20 -> 1.7646991 | AX15: =+[4]Report1!AR20 -> 0 | AY15: =+[4]Report1!AS20 -> 0.03007484 | AZ15: =+[4]Report1!AX20 -> 936.90905 | BA15: =+[4]Report1!AY20 -> 1097.8153 | BB15: =+[4]Report1!BD20 -> 0 | BC15: =+[4]Report1!BE20 -> 97.882037 | BD15: =+[4]Report1!BJ20 -> 78.537829 | BE15: =+[4]Report1!BK20 -> 37.246533 | BF15: =+[5]Report1!J20 -> 0.82936628 | BG15: =+[5]Report1!K20 -> 0.80294806 | BH15: =+[5]Report1!AN20 -> 0.82936628 | BI15: =+[5]Report1!AO20 -> 0.80921366 | BJ15: =+[5]Report1!R20 -> 43.172 | BK15: =+[5]Report1!S20 -> 506.222 | BL15: =+[5]Report1!AD20 -> 2.8351709 | BM15: =+[5]Report1!AE20 -> 3.011327 | BN15: 0 | BO15: 0 | BP15: =+[5]Report1!AJ20 -> 1095.9912 | BQ15: =+[5]Report1!AK20 -> 993.69461 | BR15: 0 | BS15: 0 | BT15: =+[6]Report1!J20 -> 0.84570104 | BU15: =+[6]Report1!K20 -> 0.83284502 | BV15: =+[6]Report1!BG20 -> 0.84570104 | BW15: =+[6]Report1!BH20 -> 0.84499106 | BX15: =+[6]Report1!R20 -> 39.923 | BY15: =+[6]Report1!S20 -> 476.892 | BZ15: =+[6]Report1!X20 -> 95.020596 | CA15: =+[6]Report1!Y20 -> 87.152068 | CB15: =+[6]Report1!AD20 -> 2.1341082 | CC15: =+[6]Report1!AE20 -> 2.1342358 | CD15: =+[6]Report1!AJ20 -> 0 | CE15: =+[6]Report1!AK20 -> 0 | CF15: =+[6]Report1!AP20 -> 1079.4813 | CG15: =+[6]Report1!AQ20 -> 994.57197 | CH15: =+[6]Report1!AV20 -> 0 | CI15: =+[6]Report1!AW20 -> 0 | CJ15: =+[6]Report1!BB20 -> 0 | CK15: =+[6]Report1!BC20 -> 0
A16: =1+A15 -> 45851 | B16: =+Report1!J21 -> 0.60333694 | C16: =+Report1!K21 -> 0.81633737 | D16: =+Report1!AJ21 -> 0.60333694 | E16: =+Report1!AK21 -> 0.8186713 | F16: =+Report1!R21 -> 36.354 | G16: =+Report1!S21 -> 768.097 | H16: =+Report1!X21 -> 3.5524839 | I16: =+Report1!Y21 -> 2.3233185 | J16: =+Report1!AD21 -> 1532.1632 | K16: =+Report1!AE21 -> 935.07255 | L16: =+[1]Report1!J21 -> 0.97995064 | M16: =+[1]Report1!K21 -> 0.83287989 | N16: =+[1]Report1!BJ21 -> 0.97995064 | O16: =+[1]Report1!BK21 -> 0.89354587 | P16: =+[1]Report1!R21 -> 63.601 | Q16: =+[1]Report1!S21 -> 723.859 | R16: =+[1]Report1!AL21 -> 2.9070298 | S16: =+[1]Report1!AM21 -> 2.5937399 | T16: =+[1]Report1!AR21 -> 0.16037484 | U16: =+[1]Report1!AS21 -> 0.21426825 | V16: =+[1]Report1!AX21 -> 612.93675 | W16: =+[1]Report1!AY21 -> 648.29674 | X16: =+[1]Report1!BD21 -> 523.7339 | Y16: =+[1]Report1!BE21 -> 545.51508 | Z16: =+[2]Report1!J21 -> 0.89669886 | AA16: =+[2]Report1!K21 -> 0.90627991 | AB16: =+[2]Report1!BC21 -> 0.89669886 | AC16: =+[2]Report1!BD21 -> 0.90995811 | AD16: =+[2]Report1!R21 -> 39.738 | AE16: =+[2]Report1!S21 -> 532.086 | AF16: =+[2]Report1!X21 -> 99.788036 | AG16: =+[2]Report1!Y21 -> 102.45625 | AH16: =+[2]Report1!AD21 -> 1.5224722 | AI16: =+[2]Report1!AE21 -> 1.526445 | AJ16: =+[2]Report1!AJ21 -> 876.74921 | AK16: =+[2]Report1!AK21 -> 905.31685 | AL16: =+[3]Report1!AP21 -> 0 | AM16: =+[3]Report1!AQ21 -> 0 | AN16: =+[4]Report1!J21 -> 0.99454987 | AO16: =+[4]Report1!K21 -> 0.7601586 | AP16: =+[4]Report1!BN21 -> 0.99454987 | AQ16: =+[4]Report1!BO21 -> 0.78709722 | AR16: =+[4]Report1!R21 -> 47.52 | AS16: =+[4]Report1!S21 -> 479.775 | AT16: =+[4]Report1!AF21 -> 98.802557 | AU16: =+[4]Report1!AG21 -> 109.51761 | AV16: =+[4]Report1!AL21 -> 1.5677609 | AW16: =+[4]Report1!AM21 -> 1.7451931 | AX16: =+[4]Report1!AR21 -> 0 | AY16: =+[4]Report1!AS21 -> 0.027096035 | AZ16: =+[4]Report1!AX21 -> 940.4516 | BA16: =+[4]Report1!AY21 -> 1082.229 | BB16: =+[4]Report1!BD21 -> 0 | BC16: =+[4]Report1!BE21 -> 88.187171 | BD16: =+[4]Report1!BJ21 -> 86.279461 | BE16: =+[4]Report1!BK21 -> 42.103069 | BF16: =+[5]Report1!J21 -> 0.81142569 | BG16: =+[5]Report1!K21 -> 0.80359155 | BH16: =+[5]Report1!AN21 -> 0.81142569 | BI16: =+[5]Report1!AO21 -> 0.80938277 | BJ16: =+[5]Report1!R21 -> 42.02 | BK16: =+[5]Report1!S21 -> 548.242 | BL16: =+[5]Report1!AD21 -> 2.9295574 | BM16: =+[5]Report1!AE21 -> 3.0050598 | BN16: 0 | BO16: 0 | BP16: =+[5]Report1!AJ21 -> 1116.6403 | BQ16: =+[5]Report1!AK21 -> 1003.1178 | BR16: 0 | BS16: 0 | BT16: =+[6]Report1!J21 -> 0.79184063 | BU16: =+[6]Report1!K21 -> 0.82970891 | BV16: =+[6]Report1!BG21 -> 0.79184063 | BW16: =+[6]Report1!BH21 -> 0.8408713 | BX16: =+[6]Report1!R21 -> 37.55 | BY16: =+[6]Report1!S21 -> 514.442 | BZ16: =+[6]Report1!X21 -> 104.96739 | CA16: =+[6]Report1!Y21 -> 88.452439 | CB16: =+[6]Report1!AD21 -> 2.2130493 | CC16: =+[6]Report1!AE21 -> 2.1399886 | CD16: =+[6]Report1!AJ21 -> 0 | CE16: =+[6]Report1!AK21 -> 0 | CF16: =+[6]Report1!AP21 -> 1090.1349 | CG16: =+[6]Report1!AQ21 -> 1001.5473 | CH16: =+[6]Report1!AV21 -> 0 | CI16: =+[6]Report1!AW21 -> 0 | CJ16: =+[6]Report1!BB21 -> 0 | CK16: =+[6]Report1!BC21 -> 0
... A34: =1+A33 -> 45869 | B34: =+Report1!J39 -> 0.84132217 | C34: =+Report1!K39 -> 0.83939759 | D34: =+Report1!AJ39 -> 0.84132217 | E34: =+Report1!AK39 -> 0.84053151 | F34: =+Report1!R39 -> 50.648 | G34: =+Report1!S39 -> 1669.03 | H34: =+Report1!X39 -> 2.4645198 | I34: =+Report1!Y39 -> 2.439188 | J34: =+Report1!AD39 -> 1039.2122 | K34: =+Report1!AE39 -> 1033.4659 | L34: =+[1]Report1!J39 -> 1.0064663 | M34: =+[1]Report1!K39 -> 0.88164645 | N34: =+[1]Report1!BJ39 -> 1.0064663 | O34: =+[1]Report1!BK39 -> 0.90721678 | P34: =+[1]Report1!R39 -> 78.098 | Q34: =+[1]Report1!S39 -> 1849.253 | R34: =+[1]Report1!AL39 -> 2.2478168 | S34: =+[1]Report1!AM39 -> 2.6039628 | T34: =+[1]Report1!AR39 -> 0.24584496 | U34: =+[1]Report1!AS39 -> 0.22857878 | V34: =+[1]Report1!AX39 -> 419.64621 | W34: =+[1]Report1!AY39 -> 604.72262 | X34: =+[1]Report1!BD39 -> 422.54603 | Y34: =+[1]Report1!BE39 -> 521.78582 | Z34: =+[2]Report1!J39 -> 0.96785843 | AA34: =+[2]Report1!K39 -> 0.88193173 | AB34: =+[2]Report1!BC39 -> 0.96785843 | AC34: =+[2]Report1!BD39 -> 0.88340653 | AD34: =+[2]Report1!R39 -> 46.16 | AE34: =+[2]Report1!S39 -> 1253.705 | AF34: =+[2]Report1!X39 -> 90.473738 | AG34: =+[2]Report1!Y39 -> 98.517031 | AH34: =+[2]Report1!AD39 -> 1.3388215 | AI34: =+[2]Report1!AE39 -> 1.4871122 | AJ34: =+[2]Report1!AJ39 -> 830.24307 | AK34: =+[2]Report1!AK39 -> 885.26052 | AL34: =+[3]Report1!AP39 -> 0 | AM34: =+[3]Report1!AQ39 -> 0 | AN34: =+[4]Report1!J39 -> 0.98297038 | AO34: =+[4]Report1!K39 -> 0.88320077 | AP34: =+[4]Report1!BN39 -> 0.98297038 | AQ34: =+[4]Report1!BO39 -> 0.8953444 | AR34: =+[4]Report1!R39 -> 50.23 | AS34: =+[4]Report1!S39 -> 1406.635 | AT34: =+[4]Report1!AF39 -> 110.50624 | AU34: =+[4]Report1!AG39 -> 105.33379 | AV34: =+[4]Report1!AL39 -> 1.4334063 | AW34: =+[4]Report1!AM39 -> 1.5242049 | AX34: =+[4]Report1!AR39 -> 0.17917579 | AY34: =+[4]Report1!AS39 -> 0.080760112 | AZ34: =+[4]Report1!AX39 -> 846.98427 | BA34: =+[4]Report1!AY39 -> 927.60065 | BB34: =+[4]Report1!BD39 -> 483.91129 | BC34: =+[4]Report1!BE39 -> 240.27392 | BD34: =+[4]Report1!BJ39 -> 0 | BE34: =+[4]Report1!BK39 -> 16.955358 | BF34: =+[5]Report1!J39 -> 1.0666989 | BG34: =+[5]Report1!K39 -> 0.88101947 | BH34: =+[5]Report1!AN39 -> 1.0666989 | BI34: =+[5]Report1!AO39 -> 0.8836277 | BJ34: =+[5]Report1!R39 -> 56.478 | BK34: =+[5]Report1!S39 -> 1457.009 | BL34: =+[5]Report1!AD39 -> 2.2769928 | BM34: =+[5]Report1!AE39 -> 2.7597633 | BN34: 0 | BO34: 0 | BP34: =+[5]Report1!AJ39 -> 824.54903 | BQ34: =+[5]Report1!AK39 -> 932.94369 | BR34: 0 | BS34: 0 | BT34: =+[6]Report1!J39 -> 0.99336552 | BU34: =+[6]Report1!K39 -> 0.89958178 | BV34: =+[6]Report1!BG39 -> 0.99336552 | BW34: =+[6]Report1!BH39 -> 0.90458737 | BX34: =+[6]Report1!R39 -> 53.885 | BY34: =+[6]Report1!S39 -> 1385.694 | BZ34: =+[6]Report1!X39 -> 76.793243 | CA34: =+[6]Report1!Y39 -> 82.805082 | CB34: =+[6]Report1!AD39 -> 1.827967 | CC34: =+[6]Report1!AE39 -> 1.975097 | CD34: =+[6]Report1!AJ39 -> 0.18001299 | CE34: =+[6]Report1!AK39 -> 0.056505982 | CF34: =+[6]Report1!AP39 -> 697.15468 | CG34: =+[6]Report1!AQ39 -> 886.8081 | CH34: =+[6]Report1!AV39 -> 488.67841 | CI34: =+[6]Report1!AW39 -> 150.23872 | CJ34: =+[6]Report1!BB39 -> 0 | CK34: =+[6]Report1!BC39 -> 14.750731
A36: Desember
A37: November
A38: Oktober
A39: September
A40: Agustus
A41: Juli | B41: =+C34 -> 0.83939759 | D41: =+E34 -> 0.84053151 | F41: =+G34 -> 1669.03 | H41: =+I34 -> 2.439188 | J41: =+K34 -> 1033.4659 | L41: =+M34 -> 0.88164645 | N41: =+O34 -> 0.90721678 | P41: =+Q34 -> 1849.253 | R41: =+S34 -> 2.6039628 | T41: =+U34 -> 0.22857878 | V41: =+W34 -> 604.72262 | X41: =+Y34 -> 521.78582 | Z41: =+AA34 -> 0.88193173 | AB41: =+AC34 -> 0.88340653 | AD41: =+AE34 -> 1253.705 | AF41: =+AG34 -> 98.517031 | AH41: =+AI34 -> 1.4871122 | AJ41: =+AK34 -> 885.26052 | AL41: =+AM34 -> 0 | AN41: =+AO34 -> 0.88320077 | AP41: =+AQ34 -> 0.8953444 | AR41: =+AS34 -> 1406.635 | AT41: =+AU34 -> 105.33379 | AV41: =+AW34 -> 1.5242049 | AX41: =+AY34 -> 0.080760112 | AZ41: =+BA34 -> 927.60065 | BB41: =+BC34 -> 240.27392 | BD41: =+BE34 -> 16.955358 | BF41: =+BG34 -> 0.88101947 | BH41: =+BI34 -> 0.8836277 | BJ41: =+BK34 -> 1457.009 | BL41: =+BM34 -> 2.7597633 | BN41: =+BO34 -> 0 | BP41: =+BQ34 -> 932.94369 | BR41: =+BS34 -> 0 | BT41: =+BU34 -> 0.89958178 | BV41: =+BW34 -> 0.90458737 | BX41: =+BY34 -> 1385.694 | BZ41: =+CA34 -> 82.805082 | CB41: =+CC34 -> 1.975097 | CD41: =+CE34 -> 0.056505982 | CF41: =+CG34 -> 886.8081 | CH41: =+CI34 -> 150.23872 | CJ41: =+CK34 -> 14.750731
A42: Juni | B42: =+'[7]eff all'!$B$42:$C$42 -> 0.89683017 | D42: =+'[7]eff all'!$D$42:$E$42 -> 0.91651255 | F42: =+'[7]eff all'!$F$42:$G$42 -> 1608.12 | H42: =+'[7]eff all'!$H$42:$I$42 -> 2.3160038 | J42: =+'[7]eff all'!$J$42:$K$42 -> 1025.4408 | L42: =+'[7]eff all'!$L$42:$M$42 -> 0.92866755 | N42: =+'[7]eff all'!$N$42:$O$42 -> 0.93793898 | P42: =+'[7]eff all'!$P$42:$Q$42 -> 1827.359 | R42: =+'[7]eff all'!$R$42:$S$42 -> 2.0916447 | T42: =+'[7]eff all'!$T$42:$U$42 -> 0.23153633 | V42: =+'[7]eff all'!$V$42:$W$42 -> 614.27863 | X42: =+'[7]eff all'!$X$42:$Y$42 -> 437.11553 | Z42: =+'[7]eff all'!$Z$42:$AA$42 -> 0.83629624 | AB42: =+'[7]eff all'!$AB$42:$AC$42 -> 0.84011645 | AD42: =+'[7]eff all'!$AD$42:$AE$42 -> 1132.285 | AF42: =+'[7]eff all'!$AF$42:$AG$42 -> 111.282 | AH42: =+'[7]eff all'!$AH$42:$AI$42 -> 1.6594762 | AJ42: =+'[7]eff all'!$AJ$42:$AK$42 -> 964.83334 | AL42: =+'[7]eff all'!$AL$42:$AM$42 -> 0 | AN42: =+'[7]eff all'!$AN$42:$AO$42 -> 0.84149356 | AP42: =+'[7]eff all'!$AP$42:$AQ$42 -> 0.85108231 | AR42: =+'[7]eff all'!$AR$42:$AS$42 -> 1316.344 | AT42: =+'[7]eff all'!$AT$42:$AU$42 -> 121.83944 | AV42: =+'[7]eff all'!$AV$42:$AW$42 -> 1.4904159 | AX42: =+'[7]eff all'!$AX$42:$AY$42 -> 0.19523772 | AZ42: =+'[7]eff all'!$AZ$42:$BA$42 -> 883.634 | BB42: =+'[7]eff all'!$BB$42:$BC$42 -> 521.8822 | BD42: =+'[7]eff all'!$BD$42:$BE$42 -> 0 | BF42: =+'[7]eff all'!$BF$42:$BG$42 -> 0.81559728 | BH42: =+'[7]eff all'!$BH$42:$BI$42 -> 0.82877821 | BJ42: =+'[7]eff all'!$BJ$42:$BK$42 -> 1259.735 | BL42: =+'[7]eff all'!$BL$42:$BM$42 -> 2.8948152 | BN42: =+'[7]eff all'!$BN$42:$BO$42 -> 0 | BP42: =+'[7]eff all'!$BP$42:$BQ$42 -> 971.0194 | BR42: =+'[7]eff all'!$BR$42:$BS$42 -> 0 | BT42: =+'[7]eff all'!$BT$42:$BU$42 -> 0.90927146 | BV42: =+'[7]eff all'!$BV$42:$BW$42 -> 0.93351911 | BX42: =+'[7]eff all'!$BX$42:$BY$42 -> 1433.06 | BZ42: =+'[7]eff all'!$BZ$42:$CA$42 -> 77.094083 | CB42: =+'[7]eff all'!$CB$42:$CC$42 -> 1.8864528 | CD42: =+'[7]eff all'!$CD$42:$CE$42 -> 0.14263185 | CF42: =+'[7]eff all'!$CF$42:$CG$42 -> 754.59782 | CH42: =+'[7]eff all'!$CH$42:$CI$42 -> 384.70371 | CJ42: 0
A43: Mei | B43: =+'[8]eff all'!$B$43:$C$43 -> 0.81728993 | D43: =+'[8]eff all'!$D$43:$E$43 -> 0.81728993 | F43: =+'[8]eff all'!$F$43:$G$43 -> 1753.698 | H43: =+'[8]eff all'!$H$43:$I$43 -> 2.3283627 | J43: =+'[8]eff all'!$J$43:$K$43 -> 919.17355 | L43: =+'[8]eff all'!$L$43:$M$43 -> 0.88541366 | N43: =+'[8]eff all'!$N$43:$O$43 -> 0.92564375 | P43: =+'[8]eff all'!$P$43:$Q$43 -> 1848.366 | R43: =+'[8]eff all'!$R$43:$S$43 -> 2.3081273 | T43: =+'[8]eff all'!$T$43:$U$43 -> 0.22165523 | V43: =+'[8]eff all'!$V$43:$W$43 -> 618.58479 | X43: =+'[8]eff all'!$X$43:$Y$43 -> 420.83341 | Z43: =+'[8]eff all'!$Z$43:$AA$43 -> 0.80335181 | AB43: =+'[8]eff all'!$AB$43:$AC$43 -> 0.86162049 | AD43: =+'[8]eff all'!$AD$43:$AE$43 -> 1130.835 | AF43: =+'[8]eff all'!$AF$43:$AG$43 -> 107.89352 | AH43: =+'[8]eff all'!$AH$43:$AI$43 -> 1.5947508 | AJ43: =+'[8]eff all'!$AJ$43:$AK$43 -> 914.38362 | AL43: =+'[8]eff all'!$AL$43:$AM$43 -> 20.16563 | AN43: =+'[8]eff all'!$AN$43:$AO$43 -> 0.85071019 | AP43: =+'[8]eff all'!$AP$43:$AQ$43 -> 0.85071019 | AR43: =+'[8]eff all'!$AR$43:$AS$43 -> 1375.357 | AT43: =+'[8]eff all'!$AT$43:$AU$43 -> 113.79765 | AV43: =+'[8]eff all'!$AV$43:$AW$43 -> 1.4656558 | AX43: =+'[8]eff all'!$AX$43:$AY$43 -> 0.18613349 | AZ43: =+'[8]eff all'!$AZ$43:$BA$43 -> 878.46065 | BB43: =+'[8]eff all'!$BB$43:$BC$43 -> 550.25946 | BD43: =+'[8]eff all'!$BD$43:$BE$43 -> 0 | BF43: =+'[8]eff all'!$BF$43:$BG$43 -> 0.89363459 | BH43: =+'[8]eff all'!$BH$43:$BI$43 -> 0.89363459 | BJ43: =+'[8]eff all'!$BJ$43:$BK$43 -> 1430.692 | BL43: =+'[8]eff all'!$BL$43:$BM$43 -> 2.6821286 | BN43: =+'[8]eff all'!$BN$43:$BO$43 -> 0 | BP43: =+'[8]eff all'!$BP$43:$BQ$43 -> 974.33569 | BR43: =+'[8]eff all'!$BR$43:$BS$43 -> 0 | BT43: =+'[8]eff all'!$BT$43:$BU$43 -> 0.90863448 | BV43: =+'[8]eff all'!$BV$43:$BW$43 -> 0.9187839 | BX43: =+'[8]eff all'!$BX$43:$BY$43 -> 1460.105 | BZ43: =+'[8]eff all'!$BZ$43:$CA$43 -> 77.669648 | CB43: =+'[8]eff all'!$CB$43:$CC$43 -> 2.0032806 | CD43: =+'[8]eff all'!$CD$43:$CE$43 -> 0.083692611 | CF43: =+'[8]eff all'!$CF$43:$CG$43 -> 840.76602 | CH43: =+'[8]eff all'!$CH$43:$CI$43 -> 246.27503 | CJ43: =+'[8]eff all'!$CJ$43:$CK$43 -> 20.270491
A44: April | B44: =+'[9]eff all'!$B$44:$C$44 -> 0.8512863 | D44: =+'[9]eff all'!$D$44:$E$44 -> 0.88261389 | F44: =+'[9]eff all'!$F$44:$G$44 -> 1626.863 | H44: =+'[9]eff all'!$H$44:$I$44 -> 2.4992418 | J44: =+'[9]eff all'!$J$44:$K$44 -> 943.70529 | L44: =+'[9]eff all'!$L$44:$M$44 -> 0.91684997 | N44: =+'[9]eff all'!$N$44:$O$44 -> 0.94547697 | P44: =+'[9]eff all'!$P$44:$Q$44 -> 1788.166 | R44: =+'[9]eff all'!$R$44:$S$44 -> 2.1331811 | T44: =+'[9]eff all'!$T$44:$U$44 -> 0.2123125 | V44: =+'[9]eff all'!$V$44:$W$44 -> 722.25094 | X44: =+'[9]eff all'!$X$44:$Y$44 -> 464.24761 | Z44: =+'[9]eff all'!$Z$44:$AA$44 -> 0.8620695 | AB44: =+'[9]eff all'!$AB$44:$AC$44 -> 0.90942581 | AD44: =+'[9]eff all'!$AD$44:$AE$44 -> 1188.791 | AF44: =+'[9]eff all'!$AF$44:$AG$44 -> 106.25948 | AH44: =+'[9]eff all'!$AH$44:$AI$44 -> 1.5097692 | AJ44: =+'[9]eff all'!$AJ$44:$AK$44 -> 921.84495 | AL44: =+'[9]eff all'!$AL$44:$AM$44 -> 7.553893 | AN44: =+'[9]eff all'!$AN$44:$AO$44 -> 0.9113018 | AP44: =+'[9]eff all'!$AP$44:$AQ$44 -> 0.94321744 | AR44: =+'[9]eff all'!$AR$44:$AS$44 -> 1441.538 | AT44: =+'[9]eff all'!$AT$44:$AU$44 -> 98.381361 | AV44: =+'[9]eff all'!$AV$44:$AW$44 -> 1.4245896 | AX44: =+'[9]eff all'!$AX$44:$AY$44 -> 0.063755313 | AZ44: =+'[9]eff all'!$AZ$44:$BA$44 -> 884.49349 | BB44: =+'[9]eff all'!$BB$44:$BC$44 -> 178.97537 | BD44: =+'[9]eff all'!$BD$44:$BE$44 -> 0 | BF44: =+'[9]eff all'!$BF$44:$BG$44 -> 0.83968008 | BH44: =+'[9]eff all'!$BH$44:$BI$44 -> 0.88025535 | BJ44: =+'[9]eff all'!$BJ$44:$BK$44 -> 1283.722 | BL44: =+'[9]eff all'!$BL$44:$BM$44 -> 2.9010175 | BN44: =+'[9]eff all'!$BN$44:$BO$44 -> 0 | BP44: =+'[9]eff all'!$BP$44:$BQ$44 -> 1018.1901 | BR44: =+'[9]eff all'!$BR$44:$BS$44 -> 0 | BT44: =+'[9]eff all'!$BT$44:$BU$44 -> 0.86479672 | BV44: =+'[9]eff all'!$BV$44:$BW$44 -> 0.91368892 | BX44: =+'[9]eff all'!$BX$44:$BY$44 -> 1364.988 | BZ44: =+'[9]eff all'!$BZ$44:$CA$44 -> 71.774412 | CB44: =+'[9]eff all'!$CB$44:$CC$44 -> 1.9880761 | CD44: =+'[9]eff all'!$CD$44:$CE$44 -> 0.17403816 | CF44: =+'[9]eff all'!$CF$44:$CG$44 -> 844.20452 | CH44: =+'[9]eff all'!$CH$44:$CI$44 -> 469.40955 | CJ44: =+'[9]eff all'!$CJ$44:$CK$44 -> 0
A45: Maret | B45: =+'[10]eff all'!$B$45:$C$45 -> 0.84979165 | D45: =+'[10]eff all'!$D$45:$E$45 -> 0.85889247 | F45: =+'[10]eff all'!$F$45:$G$45 -> 1534.469 | H45: =+'[10]eff all'!$H$45:$I$45 -> 2.430719 | J45: =+'[10]eff all'!$J$45:$K$45 -> 1009.2877 | L45: =+'[10]eff all'!$L$45:$M$45 -> 0.85741706 | N45: =+'[10]eff all'!$N$45:$O$45 -> 0.89481521 | P45: =+'[10]eff all'!$P$45:$Q$45 -> 1704.768 | R45: =+'[10]eff all'!$R$45:$S$45 -> 2.4058077 | T45: =+'[10]eff all'!$T$45:$U$45 -> 0.14817265 | V45: =+'[10]eff all'!$V$45:$W$45 -> 708.7489 | X45: =+'[10]eff all'!$X$45:$Y$45 -> 419.01831 | Z45: =+'[10]eff all'!$Z$45:$AA$45 -> 0.87132155 | AB45: =+'[10]eff all'!$AB$45:$AC$45 -> 0.87132155 | AD45: =+'[10]eff all'!$AD$45:$AE$45 -> 1204.645 | AF45: =+'[10]eff all'!$AF$45:$AG$45 -> 105.43836 | AH45: =+'[10]eff all'!$AH$45:$AI$45 -> 1.5603767 | AJ45: =+'[10]eff all'!$AJ$45:$AK$45 -> 928.04959 | AL45: =+'[10]eff all'!$AL$45:$AM$45 -> 0 | AN45: =+'[10]eff all'!$AN$45:$AO$45 -> 0.47758007 | AP45: =+'[10]eff all'!$AP$45:$AQ$45 -> 0.86385626 | AR45: =+'[10]eff all'!$AR$45:$AS$45 -> 764.21 | AT45: =+'[10]eff all'!$AT$45:$AU$45 -> 117.91594 | AV45: =+'[10]eff all'!$AV$45:$AW$45 -> 1.737088 | AX45: =+'[10]eff all'!$AX$45:$AY$45 -> 0 | AZ45: =+'[10]eff all'!$AZ$45:$BA$45 -> 1171.1575 | BB45: =+'[10]eff all'!$BB$45:$BC$45 -> 0 | BD45: =+'[10]eff all'!$BD$45:$BE$45 -> 23.422881 | BF45: =+'[10]eff all'!$BF$45:$BG$45 -> 0.79411424 | BH45: =+'[10]eff all'!$BH$45:$BI$45 -> 0.80751482 | BJ45: =+'[10]eff all'!$BJ$45:$BK$45 -> 1316.452 | BL45: =+'[10]eff all'!$BL$45:$BM$45 -> 2.6146035 | BN45: =+'[10]eff all'!$BN$45:$BO$45 -> 0 | BP45: =+'[10]eff all'!$BP$45:$BQ$45 -> 1083.3644 | BR45: =+'[10]eff all'!$BR$45:$BS$45 -> 0 | BT45: =+'[10]eff all'!$BT$45:$BU$45 -> 0.7921511 | BV45: =+'[10]eff all'!$BV$45:$BW$45 -> 0.80246911 | BX45: =+'[10]eff all'!$BX$45:$BY$45 -> 1219.024 | BZ45: =+'[10]eff all'!$BZ$45:$CA$45 -> 89.967609 | CB45: =+'[10]eff all'!$CB$45:$CC$45 -> 2.2528679 | CD45: =+'[10]eff all'!$CD$45:$CE$45 -> 0 | CF45: =+'[10]eff all'!$CF$45:$CG$45 -> 1093.3749 | CH45: =+'[10]eff all'!$CH$45:$CI$45 -> 0 | CJ45: =+'[10]eff all'!$CJ$45:$CK$45 -> 3.7653073
A46: Februari | B46: =+'[11]eff all'!$B$46:$C$46 -> 0.83769524 | D46: =+'[11]eff all'!$D$46:$E$46 -> 0.8766254 | F46: =+'[11]eff all'!$F$46:$G$46 -> 1634.192 | H46: =+'[11]eff all'!$H$46:$I$46 -> 2.3108466 | J46: =+'[11]eff all'!$J$46:$K$46 -> 925.52626 | L46: =+'[11]eff all'!$L$46:$M$46 -> 0.8461717 | N46: =+'[11]eff all'!$N$46:$O$46 -> 0.92040515 | P46: =+'[11]eff all'!$P$46:$Q$46 -> 1544.163 | R46: =+'[11]eff all'!$R$46:$S$46 -> 2.2768451 | T46: =+'[11]eff all'!$T$46:$U$46 -> 0.21063191 | V46: =+'[11]eff all'!$V$46:$W$46 -> 556.96866 | X46: =+'[11]eff all'!$X$46:$Y$46 -> 505.65161 | Z46: =+'[11]eff all'!$Z$46:$AA$46 -> 0.81429519 | AB46: =+'[11]eff all'!$AB$46:$AC$46 -> 0.84116946 | AD46: =+'[11]eff all'!$AD$46:$AE$46 -> 1037.251 | AF46: =+'[11]eff all'!$AF$46:$AG$46 -> 107.29574 | AH46: =+'[11]eff all'!$AH$46:$AI$46 -> 1.5367544 | AJ46: =+'[11]eff all'!$AJ$46:$AK$46 -> 927.08315 | AL46: =+'[11]eff all'!$AL$46:$AM$46 -> 0 | AN46: =+'[11]eff all'!$AN$46:$AO$46 -> 0.88342597 | AP46: =+'[11]eff all'!$AP$46:$AQ$46 -> 0.90448559 | AR46: =+'[11]eff all'!$AR$46:$AS$46 -> 1294.864 | AT46: =+'[11]eff all'!$AT$46:$AU$46 -> 106.60048 | AV46: =+'[11]eff all'!$AV$46:$AW$46 -> 1.7585631 | AX46: =+'[11]eff all'!$AX$46:$AY$46 -> 0.073212322 | AZ46: =+'[11]eff all'!$AZ$46:$BA$46 -> 932.75272 | BB46: =+'[11]eff all'!$BB$46:$BC$46 -> 205.07134 | BD46: =+'[11]eff all'!$BD$46:$BE$46 -> 0 | BF46: =+'[11]eff all'!$BF$46:$BG$46 -> 0.85694754 | BH46: =+'[11]eff all'!$BH$46:$BI$46 -> 0.88509205 | BJ46: =+'[11]eff all'!$BJ$46:$BK$46 -> 1241.78 | BL46: =+'[11]eff all'!$BL$46:$BM$46 -> 2.5784761 | BN46: =+'[11]eff all'!$BN$46:$BO$46 -> 0 | BP46: =+'[11]eff all'!$BP$46:$BQ$46 -> 1074.7242 | BR46: =+'[11]eff all'!$BR$46:$BS$46 -> 0 | BT46: =+'[11]eff all'!$BT$46:$BU$46 -> 0.52741322 | BV46: =+'[11]eff all'!$BV$46:$BW$46 -> 0.87317352 | BX46: =+'[11]eff all'!$BX$46:$BY$46 -> 769.938 | BZ46: =+'[11]eff all'!$BZ$46:$CA$46 -> 79.808071 | CB46: =+'[11]eff all'!$CB$46:$CC$46 -> 2.0515938 | CD46: =+'[11]eff all'!$CD$46:$CE$46 -> 0.078512815 | CF46: =+'[11]eff all'!$CF$46:$CG$46 -> 1021.1664 | CH46: =+'[11]eff all'!$CH$46:$CI$46 -> 210.64553 | CJ46: =+'[11]eff all'!$CJ$46:$CK$46 -> 0
