Workbook

Sheet eff all
A1: DATE | B1: PM 11 | L1: PM 12 | Z1: PM 14 | AN1: PM 15 | BF1: PM 16 | BT1: PM 17
B2: Eff Avaliable | D2: Eff Running | F2: PHP (ton) | H2: STEAM/Ton FG | J2: ELECTRIC/ton FG | L2: Eff Avaliable | N2: Eff Running | P2: PHP (ton) | R2: STEAM/ton FG | T2: STEAM DIP/ton FG | V2: ELECTRIC/ton FG | X2: ELECTRIC DIP/ton FG | Z2: Eff Avaliable | AB2: Eff Running | AD2: PHP (ton) | AF2: GAS /ton FG | AH2: STEAM /ton FG | AJ2: ELECTRIC /ton FG | AL2: Electric WPL /ton FG | AN2: Eff Avaliable | AP2: Eff Running | AR2: PHP (ton) | AT2: GAS /ton FG | AV2: STEAM /ton FG | AX2: STEAM DIP /ton FG | AZ2: ELECTRIC /ton FG | BB2: ELECTRIC DIP /ton FG | BD2: Electric WPL /ton FG | BF2: Eff Avaliable | BH2: Eff Running | BJ2: PHP (ton) | BL2: STEAM /ton FG | BN2: STEAM DIP/ton FG | BP2: ELECTRIC /ton FG | BR2: ELECTRIC DIP/ton FG | BT2: Eff Avaliable | BV2: Eff Running | BX2: PHP (ton) | BZ2: GAS /ton FG | CB2: STEAM /ton FG | CD2: STEAM DIP /ton FG | CF2: ELECTRIC /ton FG | CH2: ELECTRIC DIP /ton FG | CJ2: ELECTRIC WPL /ton FG
B3: Today | C3: Todate | D3: Today | E3: Todate | F3: Today | G3: Todate | H3: Today | I3: Todate | J3: Today | K3: Todate | L3: Today | M3: Todate | N3: Today | O3: Todate | P3: Today | Q3: Todate | R3: Today | S3: Todate | T3: Today | U3: Todate | V3: Today | W3: Todate | X3: Today | Y3: Todate | Z3: Today | AA3: Todate | AB3: Today | AC3: Todate | AD3: Today | AE3: Todate | AF3: Today | AG3: Todate | AH3: Today | AI3: Todate | AJ3: Today | AK3: Todate | AL3: Today | AM3: Todate | AN3: Today | AO3: Todate | AP3: Today | AQ3: Todate | AR3: Today | AS3: Todate | AT3: Today | AU3: Todate | AV3: Today | AW3: Todate | AX3: Today | AY3: Todate | AZ3: Today | BA3: Todate | BB3: Today | BC3: Todate | BD3: Today | BE3: Todate | BF3: Today | BG3: Todate | BH3: Today | BI3: Todate | BJ3: Today | BK3: Todate | BL3: Today | BM3: Todate | BN3: Today | BO3: Todate | BP3: Today | BQ3: Todate | BR3: Today | BS3: Todate | BT3: Today | BU3: Todate | BV3: Today | BW3: Todate | BX3: Today | BY3: Todate | BZ3: Today | CA3: Todate | CB3: Today | CC3: Todate | CD3: Today | CE3: Todate | CF3: Today | CG3: Todate | CH3: Today | CI3: Todate | CJ3: Today | CK3: Todate
A4: =+Report1!A9 -> 45962 | B4: =+Report1!J9 -> 1.0026126 | C4: =+Report1!K9 -> 1.0026126 | D4: =+Report1!AJ9 -> 1.0026126 | E4: =+Report1!AK9 -> 1.0026126 | F4: =+Report1!R9 -> 59.673 | G4: =+Report1!S9 -> 59.673 | H4: =+Report1!X9 -> 2.5626665 | I4: =+Report1!Y9 -> 2.5626665 | J4: =+Report1!AD9 -> 851.52917 | K4: =+Report1!AE9 -> 851.52917 | L4: =+[1]Report1!J9 -> 0.82240431 | M4: =+[1]Report1!K9 -> 0.82240431 | N4: =+[1]Report1!BJ9 -> 0.82240431 | O4: =+[1]Report1!BK9 -> 0.82240431 | P4: =+[1]Report1!R9 -> 43.186 | Q4: =+[1]Report1!S9 -> 43.186 | R4: =+[1]Report1!AL9 -> 2.951952 | S4: =+[1]Report1!AM9 -> 2.951952 | T4: =+[1]Report1!AR9 -> 0.29639235 | U4: =+[1]Report1!AS9 -> 0.29639235 | V4: =+[1]Report1!AX9 -> 738.69425 | W4: =+[1]Report1!AY9 -> 738.69425 | X4: =+[1]Report1!BD9 -> 478.95151 | Y4: =+[1]Report1!BE9 -> 478.95151 | Z4: =+[2]Report1!J9 -> 0 | AA4: =+[2]Report1!K9 -> 0 | AB4: =+[2]Report1!BC9 -> #DIV/0! | AC4: =+[2]Report1!BD9 -> #DIV/0! | AD4: =+[2]Report1!R9 -> 0 | AE4: =+[2]Report1!S9 -> 0 | AF4: =+[2]Report1!X9 -> 0 | AG4: =+[2]Report1!Y9 -> 0 | AH4: =+[2]Report1!AD9 -> 0 | AI4: =+[2]Report1!AE9 -> 0 | AJ4: =+[2]Report1!AJ9 -> 0 | AK4: =+[2]Report1!AK9 -> 0 | AN4: =+[3]Report1!J9 -> 0.72220006 | AO4: =+[3]Report1!K9 -> 0.72220006 | AP4: =+[3]Report1!BN9 -> 0.72220006 | AQ4: =+[3]Report1!BO9 -> 0.72220006 | AR4: =+[3]Report1!R9 -> 39.835 | AS4: =+[3]Report1!S9 -> 39.835 | AT4: =+[3]Report1!AF9 -> 121.34644 | AU4: =+[3]Report1!AG9 -> 121.34644 | AV4: =+[3]Report1!AL9 -> 1.5790134 | AW4: =+[3]Report1!AM9 -> 1.5790134 | AX4: =+[3]Report1!AR9 -> 0.19831806 | AY4: =+[3]Report1!AS9 -> 0.19831806 | AZ4: =+[3]Report1!AX9 -> 913.5509 | BA4: =+[3]Report1!AY9 -> 913.5509 | BB4: =+[3]Report1!BD9 -> 563.5868 | BC4: =+[3]Report1!BE9 -> 563.5868 | BD4: =+[3]Report1!BJ9 -> 7.8323083 | BE4: =+[3]Report1!BK9 -> 7.8323083 | BF4: =+[4]Report1!J9 -> 0.94810264 | BG4: =+[4]Report1!K9 -> 0.94810264 | BH4: =+[4]Report1!AN9 -> 0.94810264 | BI4: =+[4]Report1!AO9 -> 0.94810264 | BJ4: =+[4]Report1!R9 -> 51.744 | BK4: =+[4]Report1!S9 -> 51.744 | BL4: =+[4]Report1!AD9 -> 2.6611781 | BM4: =+[4]Report1!AE9 -> 2.6611781 | BN4: 0 | BO4: 0 | BP4: =+[4]Report1!AJ9 -> 964.39394 | BQ4: =+[4]Report1!AK9 -> 964.39394 | BR4: 0 | BS4: 0 | BT4: =+[5]Report1!J9 -> 0.81787214 | BU4: =+[5]Report1!K9 -> 0.81787214 | BV4: =+[5]Report1!BG9 -> 0.81787214 | BW4: =+[5]Report1!BH9 -> 0.81787214 | BX4: =+[5]Report1!R9 -> 42.733 | BY4: =+[5]Report1!S9 -> 42.733 | BZ4: =+[5]Report1!X9 -> 76.829728 | CA4: =+[5]Report1!Y9 -> 76.829728 | CB4: =+[5]Report1!AD9 -> 2.0195165 | CC4: =+[5]Report1!AE9 -> 2.0195165 | CD4: =+[5]Report1!AJ9 -> 0.17082817 | CE4: =+[5]Report1!AK9 -> 0.17082817 | CF4: =+[5]Report1!AP9 -> 545.97852 | CG4: =+[5]Report1!AQ9 -> 545.97852 | CH4: =+[5]Report1!AV9 -> 484.95355 | CI4: =+[5]Report1!AW9 -> 484.95355
A5: =1+A4 -> 45963 | B5: =+Report1!J10 -> 0.85910239 | C5: =+Report1!K10 -> 0.9235392 | D5: =+Report1!AJ10 -> 0.85910239 | E5: =+Report1!AK10 -> 0.9235392 | F5: =+Report1!R10 -> 62.746 | G5: =+Report1!S10 -> 122.419 | H5: =+Report1!X10 -> 2.524384 | I5: =+Report1!Y10 -> 2.5430448 | J5: =+Report1!AD10 -> 934.36681 | K5: =+Report1!AE10 -> 893.9877 | L5: =+[1]Report1!J10 -> 0.92430698 | M5: =+[1]Report1!K10 -> 0.87307588 | N5: =+[1]Report1!BJ10 -> 0.92430698 | O5: =+[1]Report1!BK10 -> 0.87307588 | P5: =+[1]Report1!R10 -> 48.007 | Q5: =+[1]Report1!S10 -> 91.193 | R5: =+[1]Report1!AL10 -> 2.6909617 | S5: =+[1]Report1!AM10 -> 2.8145581 | T5: =+[1]Report1!AR10 -> 0.28329202 | U5: =+[1]Report1!AS10 -> 0.2894959 | V5: =+[1]Report1!AX10 -> 909.66463 | W5: =+[1]Report1!AY10 -> 828.69869 | X5: =+[1]Report1!BD10 -> 463.43242 | Y5: =+[1]Report1!BE10 -> 470.78175 | Z5: =+[2]Report1!J10 -> 0 | AA5: =+[2]Report1!K10 -> 0 | AB5: =+[2]Report1!BC10 -> #DIV/0! | AC5: =+[2]Report1!BD10 -> #DIV/0! | AD5: =+[2]Report1!R10 -> 0 | AE5: =+[2]Report1!S10 -> 0 | AF5: =+[2]Report1!X10 -> 0 | AG5: =+[2]Report1!Y10 -> 0 | AH5: =+[2]Report1!AD10 -> 0 | AI5: =+[2]Report1!AE10 -> 0 | AJ5: =+[2]Report1!AJ10 -> 0 | AK5: =+[2]Report1!AK10 -> 0 | AN5: =+[3]Report1!J10 -> 0.89075191 | AO5: =+[3]Report1!K10 -> 0.80644943 | AP5: =+[3]Report1!BN10 -> 0.89075191 | AQ5: =+[3]Report1!BO10 -> 0.80644943 | AR5: =+[3]Report1!R10 -> 49.101 | AS5: =+[3]Report1!S10 -> 88.936 | AT5: =+[3]Report1!AF10 -> 117.27096 | AU5: =+[3]Report1!AG10 -> 119.09639 | AV5: =+[3]Report1!AL10 -> 1.3808273 | AW5: =+[3]Report1!AM10 -> 1.4695961 | AX5: =+[3]Report1!AR10 -> 0.22199141 | AY5: =+[3]Report1!AS10 -> 0.21138796 | AZ5: =+[3]Report1!AX10 -> 905.06874 | BA5: =+[3]Report1!AY10 -> 908.86795 | BB5: =+[3]Report1!BD10 -> 490.00428 | BC5: =+[3]Report1!BE10 -> 522.96235 | BD5: =+[3]Report1!BJ10 -> 4.6434899 | BE5: =+[3]Report1!BK10 -> 6.071782 | BF5: =+[4]Report1!J10 -> 1.0570738 | BG5: =+[4]Report1!K10 -> 1.0034081 | BH5: =+[4]Report1!AN10 -> 1.0570738 | BI5: =+[4]Report1!AO10 -> 1.0034081 | BJ5: =+[4]Report1!R10 -> 59.454 | BK5: =+[4]Report1!S10 -> 111.198 | BL5: =+[4]Report1!AD10 -> 2.274027 | BM5: =+[4]Report1!AE10 -> 2.4541808 | BN5: 0 | BO5: 0 | BP5: =+[4]Report1!AJ10 -> 776.3407 | BQ5: =+[4]Report1!AK10 -> 863.84791 | BR5: 0 | BS5: 0 | BT5: =+[5]Report1!J10 -> 0.49042025 | BU5: =+[5]Report1!K10 -> 0.65390364 | BV5: =+[5]Report1!BG10 -> 0.49042025 | BW5: =+[5]Report1!BH10 -> 0.65390364 | BX5: =+[5]Report1!R10 -> 25.7 | BY5: =+[5]Report1!S10 -> 68.433 | BZ5: =+[5]Report1!X10 -> 113.76959 | CA5: =+[5]Report1!Y10 -> 90.702487 | CB5: =+[5]Report1!AD10 -> 2.8754864 | CC5: =+[5]Report1!AE10 -> 2.3409758 | CD5: =+[5]Report1!AJ10 -> 0.31128405 | CE5: =+[5]Report1!AK10 -> 0.22357634 | CF5: =+[5]Report1!AP10 -> 779.36887 | CG5: =+[5]Report1!AQ10 -> 633.62822 | CH5: =+[5]Report1!AV10 -> 706.23735 | CI5: =+[5]Report1!AW10 -> 568.05664
A6: =1+A5 -> 45964 | B6: =+Report1!J11 -> 0.87121678 | C6: =+Report1!K11 -> 0.90458062 | D6: =+Report1!AJ11 -> 0.87121678 | E6: =+Report1!AK11 -> 0.90458062 | F6: =+Report1!R11 -> 65.622 | G6: =+Report1!S11 -> 188.041 | H6: =+Report1!X11 -> 2.545503 | I6: =+Report1!Y11 -> 2.5439027 | J6: =+Report1!AD11 -> 763.1142 | K6: =+Report1!AE11 -> 848.31585 | L6: =+[1]Report1!J11 -> 0.93399154 | M6: =+[1]Report1!K11 -> 0.89330664 | N6: =+[1]Report1!BJ11 -> 0.93399154 | O6: =+[1]Report1!BK11 -> 0.89330664 | P6: =+[1]Report1!R11 -> 48.51 | Q6: =+[1]Report1!S11 -> 139.703 | R6: =+[1]Report1!AL11 -> 2.828757 | S6: =+[1]Report1!AM11 -> 2.8194885 | T6: =+[1]Report1!AR11 -> 0.23088023 | U6: =+[1]Report1!AS11 -> 0.26914239 | V6: =+[1]Report1!AX11 -> 730.23748 | W6: =+[1]Report1!AY11 -> 794.50935 | X6: =+[1]Report1!BD11 -> 403.25706 | Y6: =+[1]Report1!BE11 -> 447.3347 | Z6: =+[2]Report1!J11 -> 0 | AA6: =+[2]Report1!K11 -> 0 | AB6: =+[2]Report1!BC11 -> #DIV/0! | AC6: =+[2]Report1!BD11 -> #DIV/0! | AD6: =+[2]Report1!R11 -> 0 | AE6: =+[2]Report1!S11 -> 0 | AF6: =+[2]Report1!X11 -> 0 | AG6: =+[2]Report1!Y11 -> 0 | AH6: =+[2]Report1!AD11 -> 0 | AI6: =+[2]Report1!AE11 -> 0 | AJ6: =+[2]Report1!AJ11 -> 0 | AK6: =+[2]Report1!AK11 -> 0 | AN6: =+[3]Report1!J11 -> 0.88021328 | AO6: =+[3]Report1!K11 -> 0.83089635 | AP6: =+[3]Report1!BN11 -> 0.88021328 | AQ6: =+[3]Report1!BO11 -> 0.83089635 | AR6: =+[3]Report1!R11 -> 48.119 | AS6: =+[3]Report1!S11 -> 137.055 | AT6: =+[3]Report1!AF11 -> 117.98356 | AU6: =+[3]Report1!AG11 -> 118.70568 | AV6: =+[3]Report1!AL11 -> 1.433945 | AW6: =+[3]Report1!AM11 -> 1.4570793 | AX6: =+[3]Report1!AR11 -> 0.20573994 | AY6: =+[3]Report1!AS11 -> 0.20940498 | AZ6: =+[3]Report1!AX11 -> 906.23413 | BA6: =+[3]Report1!AY11 -> 907.94323 | BB6: =+[3]Report1!BD11 -> 434.52275 | BC6: =+[3]Report1!BE11 -> 491.91186 | BD6: =+[3]Report1!BJ11 -> 6.0080218 | BE6: =+[3]Report1!BK11 -> 6.0493962 | BF6: =+[4]Report1!J11 -> 0.1459648 | BG6: =+[4]Report1!K11 -> 0.73265598 | BH6: =+[4]Report1!AN11 -> 0.1459648 | BI6: =+[4]Report1!AO11 -> 0.73265598 | BJ6: =+[4]Report1!R11 -> 7.465 | BK6: =+[4]Report1!S11 -> 118.663 | BL6: =+[4]Report1!AD11 -> 7.809779 | BM6: =+[4]Report1!AE11 -> 2.7910975 | BN6: 0 | BO6: 0 | BP6: =+[4]Report1!AJ11 -> 3508.0723 | BQ6: =+[4]Report1!AK11 -> 1030.1941 | BR6: 0 | BS6: 0 | BT6: =+[5]Report1!J11 -> 0.79433838 | BU6: =+[5]Report1!K11 -> 0.70073327 | BV6: =+[5]Report1!BG11 -> 0.79433838 | BW6: =+[5]Report1!BH11 -> 0.70073327 | BX6: =+[5]Report1!R11 -> 41.589 | BY6: =+[5]Report1!S11 -> 110.022 | BZ6: =+[5]Report1!X11 -> 82.4677 | CA6: =+[5]Report1!Y11 -> 87.589686 | CB6: =+[5]Report1!AD11 -> 2.1135396 | CC6: =+[5]Report1!AE11 -> 2.2550035 | CD6: =+[5]Report1!AJ11 -> 0.19476304 | CE6: =+[5]Report1!AK11 -> 0.21268474 | CF6: =+[5]Report1!AP11 -> 600.88196 | CG6: =+[5]Report1!AQ11 -> 621.24993 | CH6: =+[5]Report1!AV11 -> 411.33954 | CI6: =+[5]Report1!AW11 -> 508.8166
A7: =1+A6 -> 45965 | B7: =+Report1!J12 -> 0.79021127 | C7: =+Report1!K12 -> 0.87411367 | D7: =+Report1!AJ12 -> 0.79021127 | E7: =+Report1!AK12 -> 0.87411367 | F7: =+Report1!R12 -> 59.649 | G7: =+Report1!S12 -> 247.69 | H7: =+Report1!X12 -> 2.4652048 | I7: =+Report1!Y12 -> 2.5249505 | J7: =+Report1!AD12 -> 896.43984 | K7: =+Report1!AE12 -> 859.90512 | L7: =+[1]Report1!J12 -> 0.9080377 | M7: =+[1]Report1!K12 -> 0.89697926 | N7: =+[1]Report1!BJ12 -> 0.9080377 | O7: =+[1]Report1!BK12 -> 0.89697926 | P7: =+[1]Report1!R12 -> 47.162 | Q7: =+[1]Report1!S12 -> 186.865 | R7: =+[1]Report1!AL12 -> 2.9437047 | S7: =+[1]Report1!AM12 -> 2.8508388 | T7: =+[1]Report1!AR12 -> 0.32229337 | U7: =+[1]Report1!AS12 -> 0.28255693 | V7: =+[1]Report1!AX12 -> 806.59874 | W7: =+[1]Report1!AY12 -> 797.56054 | X7: =+[1]Report1!BD12 -> 507.8241 | Y7: =+[1]Report1!BE12 -> 462.60134 | Z7: =+[2]Report1!J12 -> 0 | AA7: =+[2]Report1!K12 -> 0 | AB7: =+[2]Report1!BC12 -> #DIV/0! | AC7: =+[2]Report1!BD12 -> #DIV/0! | AD7: =+[2]Report1!R12 -> 0 | AE7: =+[2]Report1!S12 -> 0 | AF7: =+[2]Report1!X12 -> 0 | AG7: =+[2]Report1!Y12 -> 0 | AH7: =+[2]Report1!AD12 -> 0 | AI7: =+[2]Report1!AE12 -> 0 | AJ7: =+[2]Report1!AJ12 -> 0 | AK7: =+[2]Report1!AK12 -> 0 | AN7: =+[3]Report1!J12 -> 0.92179422 | AO7: =+[3]Report1!K12 -> 0.85357949 | AP7: =+[3]Report1!BN12 -> 0.92179422 | AQ7: =+[3]Report1!BO12 -> 0.85357949 | AR7: =+[3]Report1!R12 -> 50.56 | AS7: =+[3]Report1!S12 -> 187.615 | AT7: =+[3]Report1!AF12 -> 114.65588 | AU7: =+[3]Report1!AG12 -> 117.61431 | AV7: =+[3]Report1!AL12 -> 1.3548259 | AW7: =+[3]Report1!AM12 -> 1.4295232 | AX7: =+[3]Report1!AR12 -> 0.21954114 | AY7: =+[3]Report1!AS12 -> 0.21213656 | AZ7: =+[3]Report1!AX12 -> 801.26068 | BA7: =+[3]Report1!AY12 -> 879.19356 | BB7: =+[3]Report1!BD12 -> 505.15823 | BC7: =+[3]Report1!BE12 -> 495.4816 | BD7: =+[3]Report1!BJ12 -> 6.3884494 | BE7: =+[3]Report1!BK12 -> 6.140767 | BF7: =+[4]Report1!J12 -> 0.84422829 | BG7: =+[4]Report1!K12 -> 0.7598969 | BH7: =+[4]Report1!AN12 -> 0.84422829 | BI7: =+[4]Report1!AO12 -> 0.7598969 | BJ7: =+[4]Report1!R12 -> 44.168 | BK7: =+[4]Report1!S12 -> 162.831 | BL7: =+[4]Report1!AD12 -> 3.1583952 | BM7: =+[4]Report1!AE12 -> 2.8907272 | BN7: 0 | BO7: 0 | BP7: =+[4]Report1!AJ12 -> 1147.9415 | BQ7: =+[4]Report1!AK12 -> 1062.1331 | BR7: 0 | BS7: 0 | BT7: =+[5]Report1!J12 -> 0.87173046 | BU7: =+[5]Report1!K12 -> 0.74349493 | BV7: =+[5]Report1!BG12 -> 0.87173046 | BW7: =+[5]Report1!BH12 -> 0.74349493 | BX7: =+[5]Report1!R12 -> 45.641 | BY7: =+[5]Report1!S12 -> 155.663 | BZ7: =+[5]Report1!X12 -> 89.305637 | CA7: =+[5]Report1!Y12 -> 88.09281 | CB7: =+[5]Report1!AD12 -> 2.2085406 | CC7: =+[5]Report1!AE12 -> 2.2413804 | CD7: =+[5]Report1!AJ12 -> 0.23005631 | CE7: =+[5]Report1!AK12 -> 0.21777815 | CF7: =+[5]Report1!AP12 -> 608.63566 | CG7: =+[5]Report1!AQ12 -> 617.55138 | CH7: =+[5]Report1!AV12 -> 537.65693 | CI7: =+[5]Report1!AW12 -> 517.2727
A8: =1+A7 -> 45966 | B8: =+Report1!J13 -> 0.90111446 | C8: =+Report1!K13 -> 0.87891146 | D8: =+Report1!AJ13 -> 0.90111446 | E8: =+Report1!AK13 -> 0.87891146 | F8: =+Report1!R13 -> 55.176 | G8: =+Report1!S13 -> 302.866 | H8: =+Report1!X13 -> 2.0944795 | I8: =+Report1!Y13 -> 2.4465275 | J8: =+Report1!AD13 -> 890.14354 | K8: =+Report1!AE13 -> 865.41395 | L8: =+[1]Report1!J13 -> 0.85890254 | M8: =+[1]Report1!K13 -> 0.8893807 | N8: =+[1]Report1!BJ13 -> 0.85890254 | O8: =+[1]Report1!BK13 -> 0.8893807 | P8: =+[1]Report1!R13 -> 44.61 | Q8: =+[1]Report1!S13 -> 231.475 | R8: =+[1]Report1!AL13 -> 3.1728312 | S8: =+[1]Report1!AM13 -> 2.9128934 | T8: =+[1]Report1!AR13 -> 0.34073078 | U8: =+[1]Report1!AS13 -> 0.29376823 | V8: =+[1]Report1!AX13 -> 835.6095 | W8: =+[1]Report1!AY13 -> 804.89336 | X8: =+[1]Report1!BD13 -> 519.99552 | Y8: =+[1]Report1!BE13 -> 473.66238 | Z8: =+[2]Report1!J13 -> 0 | AA8: =+[2]Report1!K13 -> 0 | AB8: =+[2]Report1!BC13 -> #DIV/0! | AC8: =+[2]Report1!BD13 -> #DIV/0! | AD8: =+[2]Report1!R13 -> 0 | AE8: =+[2]Report1!S13 -> 0 | AF8: =+[2]Report1!X13 -> 0 | AG8: =+[2]Report1!Y13 -> 0 | AH8: =+[2]Report1!AD13 -> 0 | AI8: =+[2]Report1!AE13 -> 0 | AJ8: =+[2]Report1!AJ13 -> 0 | AK8: =+[2]Report1!AK13 -> 0 | AN8: =+[3]Report1!J13 -> 0.54867609 | AO8: =+[3]Report1!K13 -> 0.79449769 | AP8: =+[3]Report1!BN13 -> 0.54867609 | AQ8: =+[3]Report1!BO13 -> 0.79449769 | AR8: =+[3]Report1!R13 -> 28.985 | AS8: =+[3]Report1!S13 -> 216.6 | AT8: =+[3]Report1!AF13 -> 113.30277 | AU8: =+[3]Report1!AG13 -> 117.03735 | AV8: =+[3]Report1!AL13 -> 1.5732275 | AW8: =+[3]Report1!AM13 -> 1.4487535 | AX8: =+[3]Report1!AR13 -> 0.20700362 | AY8: =+[3]Report1!AS13 -> 0.21144968 | AZ8: =+[3]Report1!AX13 -> 792.9812 | BA8: =+[3]Report1!AY13 -> 867.65679 | BB8: =+[3]Report1!BD13 -> 479.6984 | BC8: =+[3]Report1!BE13 -> 493.36952 | BD8: =+[3]Report1!BJ13 -> 7.4383302 | BE8: =+[3]Report1!BK13 -> 6.3144044 | BF8: =+[4]Report1!J13 -> 0.90952181 | BG8: =+[4]Report1!K13 -> 0.78934378 | BH8: =+[4]Report1!AN13 -> 0.90952181 | BI8: =+[4]Report1!AO13 -> 0.78934378 | BJ8: =+[4]Report1!R13 -> 47.754 | BK8: =+[4]Report1!S13 -> 210.585 | BL8: =+[4]Report1!AD13 -> 2.8186121 | BM8: =+[4]Report1!AE13 -> 2.8743738 | BN8: 0 | BO8: 0 | BP8: =+[4]Report1!AJ13 -> 1014.7364 | BQ8: =+[4]Report1!AK13 -> 1051.385 | BR8: 0 | BS8: 0 | BT8: =+[5]Report1!J13 -> 0.76888628 | BU8: =+[5]Report1!K13 -> 0.74857272 | BV8: =+[5]Report1!BG13 -> 0.76888628 | BW8: =+[5]Report1!BH13 -> 0.74857272 | BX8: =+[5]Report1!R13 -> 40.24 | BY8: =+[5]Report1!S13 -> 195.903 | BZ8: =+[5]Report1!X13 -> 89.461216 | CA8: =+[5]Report1!Y13 -> 88.373891 | CB8: =+[5]Report1!AD13 -> 2.1148111 | CC8: =+[5]Report1!AE13 -> 2.2153821 | CD8: =+[5]Report1!AJ13 -> 0.20626243 | CE8: =+[5]Report1!AK13 -> 0.21541273 | CF8: =+[5]Report1!AP13 -> 546.833 | CG8: =+[5]Report1!AQ13 -> 603.02527 | CH8: =+[5]Report1!AV13 -> 477.1581 | CI8: =+[5]Report1!AW13 -> 509.03285
A9: =1+A8 -> 45967 | B9: =+Report1!J14 -> 0.74072482 | C9: =+Report1!K14 -> 0.85845427 | D9: =+Report1!AJ14 -> 0.74072482 | E9: =+Report1!AK14 -> 0.85845427 | F9: =+Report1!R14 -> 44.353 | G9: =+Report1!S14 -> 347.219 | H9: =+Report1!X14 -> 2.6279395 | I9: =+Report1!Y14 -> 2.4697007 | J9: =+Report1!AD14 -> 1229.4496 | K9: =+Report1!AE14 -> 911.91507 | L9: =+[1]Report1!J14 -> 0.90230013 | M9: =+[1]Report1!K14 -> 0.89152998 | N9: =+[1]Report1!BJ14 -> 0.90230013 | O9: =+[1]Report1!BK14 -> 0.89152998 | P9: =+[1]Report1!R14 -> 46.864 | Q9: =+[1]Report1!S14 -> 278.339 | R9: =+[1]Report1!AL14 -> 3.0861002 | S9: =+[1]Report1!AM14 -> 2.9420563 | T9: =+[1]Report1!AR14 -> 0.30727211 | U9: =+[1]Report1!AS14 -> 0.29604188 | V9: =+[1]Report1!AX14 -> 867.68031 | W9: =+[1]Report1!AY14 -> 815.46481 | X9: =+[1]Report1!BD14 -> 453.6958 | Y9: =+[1]Report1!BE14 -> 470.3006 | Z9: =+[2]Report1!J14 -> 0 | AA9: =+[2]Report1!K14 -> 0 | AB9: =+[2]Report1!BC14 -> #DIV/0! | AC9: =+[2]Report1!BD14 -> #DIV/0! | AD9: =+[2]Report1!R14 -> 0 | AE9: =+[2]Report1!S14 -> 0 | AF9: =+[2]Report1!X14 -> 0 | AG9: =+[2]Report1!Y14 -> 0 | AH9: =+[2]Report1!AD14 -> 0 | AI9: =+[2]Report1!AE14 -> 0 | AJ9: =+[2]Report1!AJ14 -> 0 | AK9: =+[2]Report1!AK14 -> 0 | AN9: =+[3]Report1!J14 -> 1.0051395 | AO9: =+[3]Report1!K14 -> 0.83030316 | AP9: =+[3]Report1!BN14 -> 1.0051395 | AQ9: =+[3]Report1!BO14 -> 0.83030316 | AR9: =+[3]Report1!R14 -> 56.119 | AS9: =+[3]Report1!S14 -> 272.719 | AT9: =+[3]Report1!AF14 -> 98.465119 | AU9: =+[3]Report1!AG14 -> 113.21563 | AV9: =+[3]Report1!AL14 -> 1.2598229 | AW9: =+[3]Report1!AM14 -> 1.4098761 | AX9: =+[3]Report1!AR14 -> 0.19601205 | AY9: =+[3]Report1!AS14 -> 0.20827298 | AZ9: =+[3]Report1!AX14 -> 681.76161 | BA9: =+[3]Report1!AY14 -> 829.40404 | BB9: =+[3]Report1!BD14 -> 474.30521 | BC9: =+[3]Report1!BE14 -> 489.44654 | BD9: =+[3]Report1!BJ14 -> 5.3778578 | BE9: =+[3]Report1!BK14 -> 6.1216857 | BF9: =+[4]Report1!J14 -> 0.84156916 | BG9: =+[4]Report1!K14 -> 0.79786803 | BH9: =+[4]Report1!AN14 -> 0.84156916 | BI9: =+[4]Report1!AO14 -> 0.79786803 | BJ9: =+[4]Report1!R14 -> 43.794 | BK9: =+[4]Report1!S14 -> 254.379 | BL9: =+[4]Report1!AD14 -> 3.1282824 | BM9: =+[4]Report1!AE14 -> 2.9180868 | BN9: 0 | BO9: 0 | BP9: =+[4]Report1!AJ14 -> 1287.2051 | BQ9: =+[4]Report1!AK14 -> 1091.9839 | BR9: 0 | BS9: 0 | BT9: =+[5]Report1!J14 -> 0.70487072 | BU9: =+[5]Report1!K14 -> 0.74129155 | BV9: =+[5]Report1!BG14 -> 0.70487072 | BW9: =+[5]Report1!BH14 -> 0.74129155 | BX9: =+[5]Report1!R14 -> 36.878 | BY9: =+[5]Report1!S14 -> 232.781 | BZ9: =+[5]Report1!X14 -> 108.58062 | CA9: =+[5]Report1!Y14 -> 91.575113 | CB9: =+[5]Report1!AD14 -> 2.5245404 | CC9: =+[5]Report1!AE14 -> 2.2643601 | CD9: =+[5]Report1!AJ14 -> 0.21421986 | CE9: =+[5]Report1!AK14 -> 0.21522375 | CF9: =+[5]Report1!AP14 -> 726.44341 | CG9: =+[5]Report1!AQ14 -> 622.57762 | CH9: =+[5]Report1!AV14 -> 522.663 | CI9: =+[5]Report1!AW14 -> 511.19218
A10: =1+A9 -> 45968 | B10: =+Report1!J15 -> 0.78018144 | C10: =+Report1!K15 -> 0.84799102 | D10: =+Report1!AJ15 -> 0.78018144 | E10: =+Report1!AK15 -> 0.84799102 | F10: =+Report1!R15 -> 48.692 | G10: =+Report1!S15 -> 395.911 | H10: =+Report1!X15 -> 2.4436458 | I10: =+Report1!Y15 -> 2.4664963 | J10: =+Report1!AD15 -> 1053.0703 | K10: =+Report1!AE15 -> 929.27537 | L10: =+[1]Report1!J15 -> 0.90688638 | M10: =+[1]Report1!K15 -> 0.8937179 | N10: =+[1]Report1!BJ15 -> 0.90688638 | O10: =+[1]Report1!BK15 -> 0.8937179 | P10: =+[1]Report1!R15 -> 47.042 | Q10: =+[1]Report1!S15 -> 325.381 | R10: =+[1]Report1!AL15 -> 2.674206 | S10: =+[1]Report1!AM15 -> 2.9033318 | T10: =+[1]Report1!AR15 -> 0.27209727 | U10: =+[1]Report1!AS15 -> 0.29258008 | V10: =+[1]Report1!AX15 -> 738.89397 | W10: =+[1]Report1!AY15 -> 804.39457 | X10: =+[1]Report1!BD15 -> 396.26291 | Y10: =+[1]Report1!BE15 -> 459.5966 | Z10: =+[2]Report1!J15 -> 0 | AA10: =+[2]Report1!K15 -> 0 | AB10: =+[2]Report1!BC15 -> #DIV/0! | AC10: =+[2]Report1!BD15 -> #DIV/0! | AD10: =+[2]Report1!R15 -> 0 | AE10: =+[2]Report1!S15 -> 0 | AF10: =+[2]Report1!X15 -> 0 | AG10: =+[2]Report1!Y15 -> 0 | AH10: =+[2]Report1!AD15 -> 0 | AI10: =+[2]Report1!AE15 -> 0 | AJ10: =+[2]Report1!AJ15 -> 0 | AK10: =+[2]Report1!AK15 -> 0 | AN10: =+[3]Report1!J15 -> 0.95309108 | AO10: =+[3]Report1!K15 -> 0.84912389 | AP10: =+[3]Report1!BN15 -> 0.95309108 | AQ10: =+[3]Report1!BO15 -> 0.84912389 | AR10: =+[3]Report1!R15 -> 56.67 | AS10: =+[3]Report1!S15 -> 329.389 | AT10: =+[3]Report1!AF15 -> 99.362511 | AU10: =+[3]Report1!AG15 -> 110.83226 | AV10: =+[3]Report1!AL15 -> 1.166402 | AW10: =+[3]Report1!AM15 -> 1.3679874 | AX10: =+[3]Report1!AR15 -> 0.19057702 | AY10: =+[3]Report1!AS15 -> 0.20522847 | AZ10: =+[3]Report1!AX15 -> 667.83307 | BA10: =+[3]Report1!AY15 -> 801.60643 | BB10: =+[3]Report1!BD15 -> 468.73063 | BC10: =+[3]Report1!BE15 -> 485.88246 | BD10: =+[3]Report1!BJ15 -> 5.7702488 | BE10: =+[3]Report1!BK15 -> 6.0612224 | BF10: =+[4]Report1!J15 -> 0.89504879 | BG10: =+[4]Report1!K15 -> 0.81150422 | BH10: =+[4]Report1!AN15 -> 0.89504879 | BI10: =+[4]Report1!AO15 -> 0.81150422 | BJ10: =+[4]Report1!R15 -> 46.577 | BK10: =+[4]Report1!S15 -> 300.956 | BL10: =+[4]Report1!AD15 -> 2.928484 | BM10: =+[4]Report1!AE15 -> 2.9196959 | BN10: 0 | BO10: 0 | BP10: =+[4]Report1!AJ15 -> 1113.9039 | BQ10: =+[4]Report1!AK15 -> 1095.3763 | BR10: 0 | BS10: 0 | BT10: =+[5]Report1!J15 -> 0.76548655 | BU10: =+[5]Report1!K15 -> 0.74474324 | BV10: =+[5]Report1!BG15 -> 0.76548655 | BW10: =+[5]Report1!BH15 -> 0.74474324 | BX10: =+[5]Report1!R15 -> 39.999 | BY10: =+[5]Report1!S15 -> 272.78 | BZ10: =+[5]Report1!X15 -> 108.05586 | CA10: =+[5]Report1!Y15 -> 93.991762 | CB10: =+[5]Report1!AD15 -> 2.4725618 | CC10: =+[5]Report1!AE15 -> 2.2948897 | CD10: =+[5]Report1!AJ15 -> 0.22500563 | CE10: =+[5]Report1!AK15 -> 0.21665811 | CF10: =+[5]Report1!AP15 -> 681.16953 | CG10: =+[5]Report1!AQ15 -> 631.16922 | CH10: =+[5]Report1!AV15 -> 543.34696 | CI10: =+[5]Report1!AW15 -> 515.90719
A11: =1+A10 -> 45969 | B11: =+Report1!J16 -> 0.83272761 | C11: =+Report1!K16 -> 0.84632166 | D11: =+Report1!AJ16 -> 0.83272761 | E11: =+Report1!AK16 -> 0.84632166 | F11: =+Report1!R16 -> 47.743 | G11: =+Report1!S16 -> 443.654 | H11: =+Report1!X16 -> 2.3708816 | I11: =+Report1!Y16 -> 2.4562069 | J11: =+Report1!AD16 -> 1177.1045 | K11: =+Report1!AE16 -> 955.94504 | L11: =+[1]Report1!J16 -> 0.82066148 | M11: =+[1]Report1!K16 -> 0.88447993 | N11: =+[1]Report1!BJ16 -> 0.82066148 | O11: =+[1]Report1!BK16 -> 0.88447993 | P11: =+[1]Report1!R16 -> 43.25 | Q11: =+[1]Report1!S16 -> 368.631 | R11: =+[1]Report1!AL16 -> 3.0312139 | S11: =+[1]Report1!AM16 -> 2.9183357 | T11: =+[1]Report1!AR16 -> 0.33294798 | U11: =+[1]Report1!AS16 -> 0.29731629 | V11: =+[1]Report1!AX16 -> 935.9711 | W11: =+[1]Report1!AY16 -> 819.83192 | X11: =+[1]Report1!BD16 -> 569.89595 | Y11: =+[1]Report1!BE16 -> 472.53758 | Z11: =+[2]Report1!J16 -> 0 | AA11: =+[2]Report1!K16 -> 0 | AB11: =+[2]Report1!BC16 -> #DIV/0! | AC11: =+[2]Report1!BD16 -> #DIV/0! | AD11: =+[2]Report1!R16 -> 0 | AE11: =+[2]Report1!S16 -> 0 | AF11: =+[2]Report1!X16 -> 0 | AG11: =+[2]Report1!Y16 -> 0 | AH11: =+[2]Report1!AD16 -> 0 | AI11: =+[2]Report1!AE16 -> 0 | AJ11: =+[2]Report1!AJ16 -> 0 | AK11: =+[2]Report1!AK16 -> 0 | AN11: =+[3]Report1!J16 -> 0.97811113 | AO11: =+[3]Report1!K16 -> 0.86452548 | AP11: =+[3]Report1!BN16 -> 0.97811113 | AQ11: =+[3]Report1!BO16 -> 0.86452548 | AR11: =+[3]Report1!R16 -> 51.448 | AS11: =+[3]Report1!S16 -> 380.837 | AT11: =+[3]Report1!AF16 -> 111.50919 | AU11: =+[3]Report1!AG16 -> 110.92371 | AV11: =+[3]Report1!AL16 -> 1.294511 | AW11: =+[3]Report1!AM16 -> 1.3580613 | AX11: =+[3]Report1!AR16 -> 0.20214586 | AY11: =+[3]Report1!AS16 -> 0.20481203 | AZ11: =+[3]Report1!AX16 -> 811.27546 | BA11: =+[3]Report1!AY16 -> 802.91264 | BB11: =+[3]Report1!BD16 -> 542.95022 | BC11: =+[3]Report1!BE16 -> 493.59185 | BD11: =+[3]Report1!BJ16 -> 5.7747629 | BE11: =+[3]Report1!BK16 -> 6.0225241 | BF11: =+[4]Report1!J16 -> 1.0624655 | BG11: =+[4]Report1!K16 -> 0.84366601 | BH11: =+[4]Report1!AN16 -> 1.0624655 | BI11: =+[4]Report1!AO16 -> 0.84366601 | BJ11: =+[4]Report1!R16 -> 57.919 | BK11: =+[4]Report1!S16 -> 358.875 | BL11: =+[4]Report1!AD16 -> 2.3791847 | BM11: =+[4]Report1!AE16 -> 2.8324626 | BN11: 0 | BO11: 0 | BP11: =+[4]Report1!AJ16 -> 995.26926 | BQ11: =+[4]Report1!AK16 -> 1079.22 | BR11: 0 | BS11: 0 | BT11: =+[5]Report1!J16 -> 0.69176022 | BU11: =+[5]Report1!K16 -> 0.738118 | BV11: =+[5]Report1!BG16 -> 0.69176022 | BW11: =+[5]Report1!BH16 -> 0.738118 | BX11: =+[5]Report1!R16 -> 36.211 | BY11: =+[5]Report1!S16 -> 308.991 | BZ11: =+[5]Report1!X16 -> 117.61828 | CA11: =+[5]Report1!Y16 -> 96.76058 | CB11: =+[5]Report1!AD16 -> 2.7477838 | CC11: =+[5]Report1!AE16 -> 2.3479648 | CD11: =+[5]Report1!AJ16 -> 0.25958963 | CE11: =+[5]Report1!AK16 -> 0.2216893 | CF11: =+[5]Report1!AP16 -> 826.503 | CG11: =+[5]Report1!AQ16 -> 654.0606 | CH11: =+[5]Report1!AV16 -> 684.08486 | CI11: =+[5]Report1!AW16 -> 535.61612
A12: =1+A11 -> 45970 | B12: =+Report1!J17 -> 0.89529502 | C12: =+Report1!K17 -> 0.85130038 | D12: =+Report1!AJ17 -> 0.89529502 | E12: =+Report1!AK17 -> 0.85130038 | F12: =+Report1!R17 -> 53.112 | G12: =+Report1!S17 -> 496.766 | H12: =+Report1!X17 -> 2.2054526 | I12: =+Report1!Y17 -> 2.4293973 | J12: =+Report1!AD17 -> 1043.04 | K12: =+Report1!AE17 -> 965.25684 | L12: =+[1]Report1!J17 -> 0.77458077 | M12: =+[1]Report1!K17 -> 0.87142031 | N12: =+[1]Report1!BJ17 -> 0.77458077 | O12: =+[1]Report1!BK17 -> 0.87142031 | P12: =+[1]Report1!R17 -> 43.536 | Q12: =+[1]Report1!S17 -> 412.167 | R12: =+[1]Report1!AL17 -> 2.9492834 | S12: =+[1]Report1!AM17 -> 2.9216046 | T12: =+[1]Report1!AR17 -> 0.34913635 | U12: =+[1]Report1!AS17 -> 0.30278989 | V12: =+[1]Report1!AX17 -> 839.76273 | W12: =+[1]Report1!AY17 -> 821.93715 | X12: =+[1]Report1!BD17 -> 555.21867 | Y12: =+[1]Report1!BE17 -> 481.27094 | Z12: =+[2]Report1!J17 -> 0 | AA12: =+[2]Report1!K17 -> 0 | AB12: =+[2]Report1!BC17 -> #DIV/0! | AC12: =+[2]Report1!BD17 -> #DIV/0! | AD12: =+[2]Report1!R17 -> 0 | AE12: =+[2]Report1!S17 -> 0 | AF12: =+[2]Report1!X17 -> 0 | AG12: =+[2]Report1!Y17 -> 0 | AH12: =+[2]Report1!AD17 -> 0 | AI12: =+[2]Report1!AE17 -> 0 | AJ12: =+[2]Report1!AJ17 -> 0 | AK12: =+[2]Report1!AK17 -> 0 | AN12: =+[3]Report1!J17 -> 0.94802685 | AO12: =+[3]Report1!K17 -> 0.87351675 | AP12: =+[3]Report1!BN17 -> 0.94802685 | AQ12: =+[3]Report1!BO17 -> 0.87351675 | AR12: =+[3]Report1!R17 -> 50.395 | AS12: =+[3]Report1!S17 -> 431.232 | AT12: =+[3]Report1!AF17 -> 102.75839 | AU12: =+[3]Report1!AG17 -> 109.96948 | AV12: =+[3]Report1!AL17 -> 1.3056851 | AW12: =+[3]Report1!AM17 -> 1.3519405 | AX12: =+[3]Report1!AR17 -> 0.21430697 | AY12: =+[3]Report1!AS17 -> 0.20592164 | AZ12: =+[3]Report1!AX17 -> 777.81407 | BA12: =+[3]Report1!AY17 -> 799.97955 | BB12: =+[3]Report1!BD17 -> 497.68231 | BC12: =+[3]Report1!BE17 -> 494.06987 | BD12: =+[3]Report1!BJ17 -> 5.8815359 | BE12: =+[3]Report1!BK17 -> 6.0060478 | BF12: =+[4]Report1!J17 -> 0.96859019 | BG12: =+[4]Report1!K17 -> 0.85823173 | BH12: =+[4]Report1!AN17 -> 0.96859019 | BI12: =+[4]Report1!AO17 -> 0.85823173 | BJ12: =+[4]Report1!R17 -> 54.38 | BK12: =+[4]Report1!S17 -> 413.255 | BL12: =+[4]Report1!AD17 -> 2.5468922 | BM12: =+[4]Report1!AE17 -> 2.7948845 | BN12: 0 | BO12: 0 | BP12: =+[4]Report1!AJ17 -> 997.58146 | BQ12: =+[4]Report1!AK17 -> 1068.4772 | BR12: 0 | BS12: 0 | BT12: =+[5]Report1!J17 -> 0.97367385 | BU12: =+[5]Report1!K17 -> 0.76430278 | BV12: =+[5]Report1!BG17 -> 0.97367385 | BW12: =+[5]Report1!BH17 -> 0.76430278 | BX12: =+[5]Report1!R17 -> 50.976 | BY12: =+[5]Report1!S17 -> 359.967 | BZ12: =+[5]Report1!X17 -> 73.534432 | CA12: =+[5]Report1!Y17 -> 93.471455 | CB12: =+[5]Report1!AD17 -> 1.9911331 | CC12: =+[5]Report1!AE17 -> 2.2974328 | CD12: =+[5]Report1!AJ17 -> 0.21186441 | CE12: =+[5]Report1!AK17 -> 0.22029797 | CF12: =+[5]Report1!AP17 -> 571.40497 | CG12: =+[5]Report1!AQ17 -> 642.35549 | CH12: =+[5]Report1!AV17 -> 492.00997 | CI12: =+[5]Report1!AW17 -> 529.44092
A13: =1+A12 -> 45971 | B13: =+Report1!J18 -> 0.81277099 | C13: =+Report1!K18 -> 0.84807128 | D13: =+Report1!AJ18 -> 0.81277099 | E13: =+Report1!AK18 -> 0.84807128 | F13: =+Report1!R18 -> 43.385 | G13: =+Report1!S18 -> 540.151 | H13: =+Report1!X18 -> 2.7495909 | I13: =+Report1!Y18 -> 2.4551153 | J13: =+Report1!AD18 -> 1249.3313 | K13: =+Report1!AE18 -> 988.07374 | L13: =+[1]Report1!J18 -> 0.91681192 | M13: =+[1]Report1!K18 -> 0.87633816 | N13: =+[1]Report1!BJ18 -> 0.91681192 | O13: =+[1]Report1!BK18 -> 0.87633816 | P13: =+[1]Report1!R18 -> 52.69 | Q13: =+[1]Report1!S18 -> 464.857 | R13: =+[1]Report1!AL18 -> 2.4767508 | S13: =+[1]Report1!AM18 -> 2.8711819 | T13: =+[1]Report1!AR18 -> 0.25811349 | U13: =+[1]Report1!AS18 -> 0.29772597 | V13: =+[1]Report1!AX18 -> 734.9888 | W13: =+[1]Report1!AY18 -> 812.08184 | X13: =+[1]Report1!BD18 -> 444.10704 | Y13: =+[1]Report1!BE18 -> 477.05854 | Z13: =+[2]Report1!J18 -> 0 | AA13: =+[2]Report1!K18 -> 0 | AB13: =+[2]Report1!BC18 -> #DIV/0! | AC13: =+[2]Report1!BD18 -> #DIV/0! | AD13: =+[2]Report1!R18 -> 0 | AE13: =+[2]Report1!S18 -> 0 | AF13: =+[2]Report1!X18 -> 0 | AG13: =+[2]Report1!Y18 -> 0 | AH13: =+[2]Report1!AD18 -> 0 | AI13: =+[2]Report1!AE18 -> 0 | AJ13: =+[2]Report1!AJ18 -> 0 | AK13: =+[2]Report1!AK18 -> 0 | AN13: =+[3]Report1!J18 -> 0.92780652 | AO13: =+[3]Report1!K18 -> 0.87897349 | AP13: =+[3]Report1!BN18 -> 0.92780652 | AQ13: =+[3]Report1!BO18 -> 0.87897349 | AR13: =+[3]Report1!R18 -> 51.182 | AS13: =+[3]Report1!S18 -> 482.414 | AT13: =+[3]Report1!AF18 -> 118.34687 | AU13: =+[3]Report1!AG18 -> 110.85829 | AV13: =+[3]Report1!AL18 -> 1.287562 | AW13: =+[3]Report1!AM18 -> 1.3451102 | AX13: =+[3]Report1!AR18 -> 0.18756594 | AY13: =+[3]Report1!AS18 -> 0.20397418 | AZ13: =+[3]Report1!AX18 -> 838.42445 | BA13: =+[3]Report1!AY18 -> 804.05838 | BB13: =+[3]Report1!BD18 -> 487.46044 | BC13: =+[3]Report1!BE18 -> 493.36864 | BD13: =+[3]Report1!BJ18 -> 6.0587707 | BE13: =+[3]Report1!BK18 -> 6.0116415 | BF13: =+[4]Report1!J18 -> 0.95766095 | BG13: =+[4]Report1!K18 -> 0.86817834 | BH13: =+[4]Report1!AN18 -> 0.95766095 | BI13: =+[4]Report1!AO18 -> 0.86817834 | BJ13: =+[4]Report1!R18 -> 51.258 | BK13: =+[4]Report1!S18 -> 464.513 | BL13: =+[4]Report1!AD18 -> 2.6590971 | BM13: =+[4]Report1!AE18 -> 2.7799007 | BN13: 0 | BO13: 0 | BP13: =+[4]Report1!AJ18 -> 988.22584 | BQ13: =+[4]Report1!AK18 -> 1059.6217 | BR13: 0 | BS13: 0 | BT13: =+[5]Report1!J18 -> 0.88840863 | BU13: =+[5]Report1!K18 -> 0.77671844 | BV13: =+[5]Report1!BG18 -> 0.88840863 | BW13: =+[5]Report1!BH18 -> 0.77671844 | BX13: =+[5]Report1!R18 -> 46.512 | BY13: =+[5]Report1!S18 -> 406.479 | BZ13: =+[5]Report1!X18 -> 81.565415 | CA13: =+[5]Report1!Y18 -> 92.109088 | CB13: =+[5]Report1!AD18 -> 2.1327829 | CC13: =+[5]Report1!AE18 -> 2.2785925 | CD13: =+[5]Report1!AJ18 -> 0.1999484 | CE13: =+[5]Report1!AK18 -> 0.21796944 | CF13: =+[5]Report1!AP18 -> 594.5184 | CG13: =+[5]Report1!AQ18 -> 636.88166 | CH13: =+[5]Report1!AV18 -> 515.36808 | CI13: =+[5]Report1!AW18 -> 527.83061
A14: =1+A13 -> 45972 | B14: =+Report1!J19 -> 0.97658628 | C14: =+Report1!K19 -> 0.85786919 | D14: =+Report1!AJ19 -> 0.97658628 | E14: =+Report1!AK19 -> 0.85786919 | F14: =+Report1!R19 -> 51.335 | G14: =+Report1!S19 -> 591.486 | H14: =+Report1!X19 -> 2.3833837 | I14: =+Report1!Y19 -> 2.4488897 | J14: =+Report1!AD19 -> 1066.0512 | K14: =+Report1!AE19 -> 994.8414 | L14: =+[1]Report1!J19 -> 0.88547432 | M14: =+[1]Report1!K19 -> 0.87723124 | N14: =+[1]Report1!BJ19 -> 0.88547432 | O14: =+[1]Report1!BK19 -> 0.87723124 | P14: =+[1]Report1!R19 -> 50.889 | Q14: =+[1]Report1!S19 -> 515.746 | R14: =+[1]Report1!AL19 -> 2.6532256 | S14: =+[1]Report1!AM19 -> 2.849676 | T14: =+[1]Report1!AR19 -> 0.28296881 | U14: =+[1]Report1!AS19 -> 0.29626987 | V14: =+[1]Report1!AX19 -> 761.84853 | W14: =+[1]Report1!AY19 -> 807.12529 | X14: =+[1]Report1!BD19 -> 453.65403 | Y14: =+[1]Report1!BE19 -> 474.7492 | Z14: =+[2]Report1!J19 -> 0 | AA14: =+[2]Report1!K19 -> 0 | AB14: =+[2]Report1!BC19 -> #DIV/0! | AC14: =+[2]Report1!BD19 -> #DIV/0! | AD14: =+[2]Report1!R19 -> 0 | AE14: =+[2]Report1!S19 -> 0 | AF14: =+[2]Report1!X19 -> 0 | AG14: =+[2]Report1!Y19 -> 0 | AH14: =+[2]Report1!AD19 -> 0 | AI14: =+[2]Report1!AE19 -> 0 | AJ14: =+[2]Report1!AJ19 -> 0 | AK14: =+[2]Report1!AK19 -> 0 | AN14: =+[3]Report1!J19 -> 0.91821702 | AO14: =+[3]Report1!K19 -> 0.88255767 | AP14: =+[3]Report1!BN19 -> 0.91821702 | AQ14: =+[3]Report1!BO19 -> 0.88255767 | AR14: =+[3]Report1!R19 -> 50.653 | AS14: =+[3]Report1!S19 -> 533.067 | AT14: =+[3]Report1!AF19 -> 108.98568 | AU14: =+[3]Report1!AG19 -> 110.68035 | AV14: =+[3]Report1!AL19 -> 1.3799775 | AW14: =+[3]Report1!AM19 -> 1.3484234 | AX14: =+[3]Report1!AR19 -> 0.19347324 | AY14: =+[3]Report1!AS19 -> 0.20297636 | AZ14: =+[3]Report1!AX19 -> 873.5068 | BA14: =+[3]Report1!AY19 -> 810.6575 | BB14: =+[3]Report1!BD19 -> 453.75397 | BC14: =+[3]Report1!BE19 -> 489.60438 | BD14: =+[3]Report1!BJ19 -> 6.7103627 | BE14: =+[3]Report1!BK19 -> 6.0780352 | BF14: =+[4]Report1!J19 -> 0.89560871 | BG14: =+[4]Report1!K19 -> 0.87060047 | BH14: =+[4]Report1!AN19 -> 0.89560871 | BI14: =+[4]Report1!AO19 -> 0.87060047 | BJ14: =+[4]Report1!R19 -> 46.411 | BK14: =+[4]Report1!S19 -> 510.924 | BL14: =+[4]Report1!AD19 -> 2.7708948 | BM14: =+[4]Report1!AE19 -> 2.7790826 | BN14: 0 | BO14: 0 | BP14: =+[4]Report1!AJ19 -> 1155.146 | BQ14: =+[4]Report1!AK19 -> 1068.2988 | BR14: 0 | BS14: 0 | BT14: =+[5]Report1!J19 -> 0.91980834 | BU14: =+[5]Report1!K19 -> 0.78984708 | BV14: =+[5]Report1!BG19 -> 0.91980834 | BW14: =+[5]Report1!BH19 -> 0.78984708 | BX14: =+[5]Report1!R19 -> 48.627 | BY14: =+[5]Report1!S19 -> 455.106 | BZ14: =+[5]Report1!X19 -> 77.519659 | CA14: =+[5]Report1!Y19 -> 90.550242 | CB14: =+[5]Report1!AD19 -> 2.0790919 | CC14: =+[5]Report1!AE19 -> 2.2572763 | CD14: =+[5]Report1!AJ19 -> 0.18713883 | CE14: =+[5]Report1!AK19 -> 0.21467526 | CF14: =+[5]Report1!AP19 -> 596.70019 | CG14: =+[5]Report1!AQ19 -> 632.58836 | CH14: =+[5]Report1!AV19 -> 436.30082 | CI14: =+[5]Report1!AW19 -> 518.05087
A15: =1+A14 -> 45973 | B15: =+Report1!J20 -> 0.84842956 | C15: =+Report1!K20 -> 0.85714462 | D15: =+Report1!AJ20 -> 0.84842956 | E15: =+Report1!AK20 -> 0.85714462 | F15: =+Report1!R20 -> 48.635 | G15: =+Report1!S20 -> 640.121 | H15: =+Report1!X20 -> 2.5156986 | I15: =+Report1!Y20 -> 2.4539657 | J15: =+Report1!AD20 -> 1126.2601 | K15: =+Report1!AE20 -> 1004.8263 | L15: =+[1]Report1!J20 -> 0.88916362 | M15: =+[1]Report1!K20 -> 0.87832426 | N15: =+[1]Report1!BJ20 -> 0.88916362 | O15: =+[1]Report1!BK20 -> 0.87832426 | P15: =+[1]Report1!R20 -> 52.714 | Q15: =+[1]Report1!S20 -> 568.46 | R15: =+[1]Report1!AL20 -> 2.6122852 | S15: =+[1]Report1!AM20 -> 2.8276625 | T15: =+[1]Report1!AR20 -> 0.25799598 | U15: =+[1]Report1!AS20 -> 0.29272068 | V15: =+[1]Report1!AX20 -> 755.31908 | W15: =+[1]Report1!AY20 -> 802.32124 | X15: =+[1]Report1!BD20 -> 419.03479 | Y15: =+[1]Report1!BE20 -> 469.58273 | Z15: =+[2]Report1!J20 -> 0 | AA15: =+[2]Report1!K20 -> 0 | AB15: =+[2]Report1!BC20 -> #DIV/0! | AC15: =+[2]Report1!BD20 -> #DIV/0! | AD15: =+[2]Report1!R20 -> 0 | AE15: =+[2]Report1!S20 -> 0 | AF15: =+[2]Report1!X20 -> 0 | AG15: =+[2]Report1!Y20 -> 0 | AH15: =+[2]Report1!AD20 -> 0 | AI15: =+[2]Report1!AE20 -> 0 | AJ15: =+[2]Report1!AJ20 -> 0 | AK15: =+[2]Report1!AK20 -> 0 | AN15: =+[3]Report1!J20 -> 0.8906087 | AO15: =+[3]Report1!K20 -> 0.88323144 | AP15: =+[3]Report1!BN20 -> 0.8906087 | AQ15: =+[3]Report1!BO20 -> 0.88323144 | AR15: =+[3]Report1!R20 -> 49.13 | AS15: =+[3]Report1!S20 -> 582.197 | AT15: =+[3]Report1!AF20 -> 105.90074 | AU15: =+[3]Report1!AG20 -> 110.27701 | AV15: =+[3]Report1!AL20 -> 1.457358 | AW15: =+[3]Report1!AM20 -> 1.3576161 | AX15: =+[3]Report1!AR20 -> 0.1750458 | AY15: =+[3]Report1!AS20 -> 0.20061938 | AZ15: =+[3]Report1!AX20 -> 870.62609 | BA15: =+[3]Report1!AY20 -> 815.71808 | BB15: =+[3]Report1!BD20 -> 479.5115 | BC15: =+[3]Report1!BE20 -> 488.75267 | BD15: =+[3]Report1!BJ20 -> 6.9224506 | BE15: =+[3]Report1!BK20 -> 6.1492931 | BF15: =+[4]Report1!J20 -> 0.90895124 | BG15: =+[4]Report1!K20 -> 0.87370511 | BH15: =+[4]Report1!AN20 -> 0.90895124 | BI15: =+[4]Report1!AO20 -> 0.87370511 | BJ15: =+[4]Report1!R20 -> 46.987 | BK15: =+[4]Report1!S20 -> 557.911 | BL15: =+[4]Report1!AD20 -> 2.8199289 | BM15: =+[4]Report1!AE20 -> 2.7825227 | BN15: 0 | BO15: 0 | BP15: =+[4]Report1!AJ20 -> 1226.0353 | BQ15: =+[4]Report1!AK20 -> 1081.5833 | BR15: 0 | BS15: 0 | BT15: =+[5]Report1!J20 -> 1.018495 | BU15: =+[5]Report1!K20 -> 0.80941278 | BV15: =+[5]Report1!BG20 -> 1.018495 | BW15: =+[5]Report1!BH20 -> 0.80941278 | BX15: =+[5]Report1!R20 -> 54.917 | BY15: =+[5]Report1!S20 -> 510.023 | BZ15: =+[5]Report1!X20 -> 72.656859 | CA15: =+[5]Report1!Y20 -> 88.623562 | CB15: =+[5]Report1!AD20 -> 1.8591693 | CC15: =+[5]Report1!AE20 -> 2.2144099 | CD15: =+[5]Report1!AJ20 -> 0.1711674 | CE15: =+[5]Report1!AK20 -> 0.20999053 | CF15: =+[5]Report1!AP20 -> 521.22039 | CG15: =+[5]Report1!AQ20 -> 620.59676 | CH15: =+[5]Report1!AV20 -> 464.73041 | CI15: =+[5]Report1!AW20 -> 512.30956
A16: =1+A15 -> 45974 | B16: =+Report1!J21 -> 0.67228889 | C16: =+Report1!K21 -> 0.84227805 | D16: =+Report1!AJ21 -> 0.67228889 | E16: =+Report1!AK21 -> 0.84227805 | F16: =+Report1!R21 -> 43.909 | G16: =+Report1!S21 -> 684.03 | H16: =+Report1!X21 -> 2.1818762 | I16: =+Report1!Y21 -> 2.4364999 | J16: =+Report1!AD21 -> 878.80617 | K16: =+Report1!AE21 -> 996.73687 | L16: =+[1]Report1!J21 -> 0.94029852 | M16: =+[1]Report1!K21 -> 0.88380003 | N16: =+[1]Report1!BJ21 -> 0.94029852 | O16: =+[1]Report1!BK21 -> 0.88380003 | P16: =+[1]Report1!R21 -> 58.982 | Q16: =+[1]Report1!S21 -> 627.442 | R16: =+[1]Report1!AL21 -> 2.3828965 | S16: =+[1]Report1!AM21 -> 2.7858527 | T16: =+[1]Report1!AR21 -> 0.24414228 | U16: =+[1]Report1!AS21 -> 0.28815412 | V16: =+[1]Report1!AX21 -> 638.68553 | W16: =+[1]Report1!AY21 -> 786.93884 | X16: =+[1]Report1!BD21 -> 379.69211 | Y16: =+[1]Report1!BE21 -> 461.13266 | Z16: =+[2]Report1!J21 -> 0 | AA16: =+[2]Report1!K21 -> 0 | AB16: =+[2]Report1!BC21 -> #DIV/0! | AC16: =+[2]Report1!BD21 -> #DIV/0! | AD16: =+[2]Report1!R21 -> 0 | AE16: =+[2]Report1!S21 -> 0 | AF16: =+[2]Report1!X21 -> 0 | AG16: =+[2]Report1!Y21 -> 0 | AH16: =+[2]Report1!AD21 -> 0 | AI16: =+[2]Report1!AE21 -> 0 | AJ16: =+[2]Report1!AJ21 -> 0 | AK16: =+[2]Report1!AK21 -> 0 | AN16: =+[3]Report1!J21 -> 0.53402079 | AO16: =+[3]Report1!K21 -> 0.85626352 | AP16: =+[3]Report1!BN21 -> 0.53402079 | AQ16: =+[3]Report1!BO21 -> 0.85626352 | AR16: =+[3]Report1!R21 -> 29.459 | AS16: =+[3]Report1!S21 -> 611.656 | AT16: =+[3]Report1!AF21 -> 141.78211 | AU16: =+[3]Report1!AG21 -> 111.79438 | AV16: =+[3]Report1!AL21 -> 2.0876472 | AW16: =+[3]Report1!AM21 -> 1.3927763 | AX16: =+[3]Report1!AR21 -> 0.27495842 | AY16: =+[3]Report1!AS21 -> 0.20419975 | AZ16: =+[3]Report1!AX21 -> 1268.8584 | BA16: =+[3]Report1!AY21 -> 837.54254 | BB16: =+[3]Report1!BD21 -> 678.44462 | BC16: =+[3]Report1!BE21 -> 497.88875 | BD16: =+[3]Report1!BJ21 -> 7.8108558 | BE16: =+[3]Report1!BK21 -> 6.2293184 | BF16: =+[4]Report1!J21 -> 1.002162 | BG16: =+[4]Report1!K21 -> 0.88342041 | BH16: =+[4]Report1!AN21 -> 1.002162 | BI16: =+[4]Report1!AO21 -> 0.88342041 | BJ16: =+[4]Report1!R21 -> 52.359 | BK16: =+[4]Report1!S21 -> 610.27 | BL16: =+[4]Report1!AD21 -> 2.5191467 | BM16: =+[4]Report1!AE21 -> 2.7599259 | BN16: 0 | BO16: 0 | BP16: =+[4]Report1!AJ21 -> 1081.9267 | BQ16: =+[4]Report1!AK21 -> 1081.6128 | BR16: 0 | BS16: 0 | BT16: =+[5]Report1!J21 -> 0.64239115 | BU16: =+[5]Report1!K21 -> 0.79634963 | BV16: =+[5]Report1!BG21 -> 0.64239115 | BW16: =+[5]Report1!BH21 -> 0.79634963 | BX16: =+[5]Report1!R21 -> 34.345 | BY16: =+[5]Report1!S21 -> 544.368 | BZ16: =+[5]Report1!X21 -> 86.94834 | CA16: =+[5]Report1!Y21 -> 88.51787 | CB16: =+[5]Report1!AD21 -> 2.096375 | CC16: =+[5]Report1!AE21 -> 2.2069629 | CD16: =+[5]Report1!AJ21 -> 0.2096375 | CE16: =+[5]Report1!AK21 -> 0.20996826 | CF16: =+[5]Report1!AP21 -> 587.54695 | CG16: =+[5]Report1!AQ21 -> 618.5116 | CH16: =+[5]Report1!AV21 -> 516.04892 | CI16: =+[5]Report1!AW21 -> 512.54548
... A33: =1+A32 -> 45991 | B33: =+Report1!J38 -> 0.93511365 | C33: =+Report1!K38 -> 0.8526919 | D33: =+Report1!AJ38 -> 0.93511365 | E33: =+Report1!AK38 -> 0.8526919 | F33: =+Report1!R38 -> 58.089 | G33: =+Report1!S38 -> 1595.056 | H33: =+Report1!X38 -> 2.0557421 | I33: =+Report1!Y38 -> 2.3816926 | J33: =+Report1!AD38 -> 897.3575 | K33: =+Report1!AE38 -> 986.51592 | L33: =+[1]Report1!J38 -> 0.93989883 | M33: =+[1]Report1!K38 -> 0.90405789 | N33: =+[1]Report1!BJ38 -> 0.93989883 | O33: =+[1]Report1!BK38 -> 0.90405789 | P33: =+[1]Report1!R38 -> 65.747 | Q33: =+[1]Report1!S38 -> 1727.194 | R33: =+[1]Report1!AL38 -> 1.7229379 | S33: =+[1]Report1!AM38 -> 2.2665022 | T33: =+[1]Report1!AR38 -> 0.29202853 | U33: =+[1]Report1!AS38 -> 0.27727053 | V33: =+[1]Report1!AX38 -> 452.71876 | W33: =+[1]Report1!AY38 -> 627.66337 | X33: =+[1]Report1!BD38 -> 449.92167 | Y33: =+[1]Report1!BE38 -> 433.98773 | Z33: =+[2]Report1!J38 -> 0.83776074 | AA33: =+[2]Report1!K38 -> 0.3750124 | AB33: =+[2]Report1!BC38 -> 0.83776074 | AC33: =+[2]Report1!BD38 -> 0.78662425 | AD33: =+[2]Report1!R38 -> 41.049 | AE33: =+[2]Report1!S38 -> 500.227 | AF33: =+[2]Report1!X38 -> 113.94939 | AG33: =+[2]Report1!Y38 -> 127.56166 | AH33: =+[2]Report1!AD38 -> 1.2692148 | AI33: =+[2]Report1!AE38 -> 2.1896059 | AJ33: =+[2]Report1!AJ38 -> 918.81897 | AK33: =+[2]Report1!AK38 -> 1225.1601 | AN33: =+[3]Report1!J38 -> 0.90387639 | AO33: =+[3]Report1!K38 -> 0.89671049 | AP33: =+[3]Report1!BN38 -> 0.90387639 | AQ33: =+[3]Report1!BO38 -> 0.89671049 | AR33: =+[3]Report1!R38 -> 49.741 | AS33: =+[3]Report1!S38 -> 1468.263 | AT33: =+[3]Report1!AF38 -> 100.22614 | AU33: =+[3]Report1!AG38 -> 103.12302 | AV33: =+[3]Report1!AL38 -> 1.3409461 | AW33: =+[3]Report1!AM38 -> 1.3725743 | AX33: =+[3]Report1!AR38 -> 0.19702057 | AY33: =+[3]Report1!AS38 -> 0.20248416 | AZ33: =+[3]Report1!AX38 -> 885.11691 | BA33: =+[3]Report1!AY38 -> 823.1074 | BB33: =+[3]Report1!BD38 -> 477.36389 | BC33: =+[3]Report1!BE38 -> 492.04252 | BD33: =+[3]Report1!BJ38 -> 6.3344123 | BE33: =+[3]Report1!BK38 -> 6.326387 | BF33: =+[4]Report1!J38 -> 0.8895427 | BG33: =+[4]Report1!K38 -> 0.89079473 | BH33: =+[4]Report1!AN38 -> 0.8895427 | BI33: =+[4]Report1!AO38 -> 0.89079473 | BJ33: =+[4]Report1!R38 -> 45.418 | BK33: =+[4]Report1!S38 -> 1394.103 | BL33: =+[4]Report1!AD38 -> 2.7390022 | BM33: =+[4]Report1!AE38 -> 2.7063997 | BN33: 0 | BO33: 0 | BP33: =+[4]Report1!AJ38 -> 1249.0513 | BQ33: =+[4]Report1!AK38 -> 1148.9756 | BR33: 0 | BS33: 0 | BT33: =+[5]Report1!J38 -> 1.0145139 | BU33: =+[5]Report1!K38 -> 0.88250458 | BV33: =+[5]Report1!BG38 -> 1.0145139 | BW33: =+[5]Report1!BH38 -> 0.88250458 | BX33: =+[5]Report1!R38 -> 52.739 | BY33: =+[5]Report1!S38 -> 1387.303 | BZ33: =+[5]Report1!X38 -> 71.866041 | CA33: =+[5]Report1!Y38 -> 79.985776 | CB33: =+[5]Report1!AD38 -> 1.8657919 | CC33: =+[5]Report1!AE38 -> 2.0503812 | CD33: =+[5]Report1!AJ38 -> 0.189613 | CE33: =+[5]Report1!AK38 -> 0.20507416 | CF33: =+[5]Report1!AP38 -> 500.98788 | CG33: =+[5]Report1!AQ38 -> 562.52898 | CH33: =+[5]Report1!AV38 -> 468.60431 | CI33: =+[5]Report1!AW38 -> 497.97584
A36: Desember
A37: November | B37: =+C33 -> 0.8526919 | D37: =+E33 -> 0.8526919 | F37: =+G33 -> 1595.056 | H37: =+I33 -> 2.3816926 | J37: =+K33 -> 986.51592 | L37: =+M33 -> 0.90405789 | N37: =+O33 -> 0.90405789 | P37: =+Q33 -> 1727.194 | R37: =+S33 -> 2.2665022 | T37: =+U33 -> 0.27727053 | V37: =+W33 -> 627.66337 | X37: =+Y33 -> 433.98773 | Z37: =+AA33 -> 0.3750124 | AB37: =+AC33 -> 0.78662425 | AD37: =+AE33 -> 500.227 | AF37: =+AG33 -> 127.56166 | AH37: =+AI33 -> 2.1896059 | AJ37: =+AK33 -> 1225.1601 | AL37: =+AM33 -> 0 | AN37: =+AO33 -> 0.89671049 | AP37: =+AQ33 -> 0.89671049 | AR37: =+AS33 -> 1468.263 | AT37: =+AU33 -> 103.12302 | AV37: =+AW33 -> 1.3725743 | AX37: =+AY33 -> 0.20248416 | AZ37: =+BA33 -> 823.1074 | BB37: =+BC33 -> 492.04252 | BD37: =+BE33 -> 6.326387 | BF37: =+BG33 -> 0.89079473 | BH37: =+BI33 -> 0.89079473 | BJ37: =+BK33 -> 1394.103 | BL37: =+BM33 -> 2.7063997 | BN37: =+BO33 -> 0 | BP37: =+BQ33 -> 1148.9756 | BR37: =+BS33 -> 0 | BT37: =+BU33 -> 0.88250458 | BV37: =+BW33 -> 0.88250458 | BX37: =+BY33 -> 1387.303 | BZ37: =+CA33 -> 79.985776 | CB37: =+CC33 -> 2.0503812 | CD37: =+CE33 -> 0.20507416 | CF37: =+CG33 -> 562.52898 | CH37: =+CI33 -> 497.97584 | CJ37: =+CK33 -> 0
A38: Oktober | B38: =+'[6]eff all'!$B$38:$C$38 -> 0.81961611 | D38: =+'[6]eff all'!$D$38:$E$38 -> 0.83793084 | F38: =+'[6]eff all'!$F$38:$G$38 -> 1655.884 | H38: =+'[6]eff all'!$H$38:$I$38 -> 2.3800164 | J38: =+'[6]eff all'!$J$38:$K$38 -> 987.22519 | L38: =+'[6]eff all'!$L$38:$M$38 -> 0.84175524 | N38: =+'[6]eff all'!$N$38:$O$38 -> 0.87679264 | P38: =+'[6]eff all'!$P$38:$Q$38 -> 1649.297 | R38: =+'[6]eff all'!$R$38:$S$38 -> 2.3196877 | T38: =+'[6]eff all'!$T$38:$U$38 -> 0.24616549 | V38: =+'[6]eff all'!$V$38:$W$38 -> 616.10298 | X38: =+'[6]eff all'!$X$38:$Y$38 -> 486.41123 | Z38: =+'[6]eff all'!$Z$38:$AA$38 -> 0.51081757 | AB38: =+'[6]eff all'!$AB$38:$AC$38 -> 0.80748846 | AD38: =+'[6]eff all'!$AD$38:$AE$38 -> 700.591 | AF38: =+'[6]eff all'!$AF$38:$AG$38 -> 110.32386 | AH38: =+'[6]eff all'!$AH$38:$AI$38 -> 1.9417891 | AJ38: =+'[6]eff all'!$AJ$38:$AK$38 -> 1127.8883 | AL38: =+'[6]eff all'!$AL$38:$AM$38 -> 0 | AN38: =+'[6]eff all'!$AN$38:$AO$38 -> 0.78888926 | AP38: =+'[6]eff all'!$AP$38:$AQ$38 -> 0.80397213 | AR38: =+'[6]eff all'!$AR$38:$AS$38 -> 1297.219 | AT38: =+'[6]eff all'!$AT$38:$AU$38 -> 120.0559 | AV38: =+'[6]eff all'!$AV$38:$AW$38 -> 1.4886461 | AX38: =+'[6]eff all'!$AX$38:$AY$38 -> 0.19526387 | AZ38: =+'[6]eff all'!$AZ$38:$BA$38 -> 913.20617 | BB38: =+'[6]eff all'!$BB$38:$BC$38 -> 493.47212 | BD38: =+'[6]eff all'!$BD$38:$BE$38 -> 2.9987227 | BF38: =+'[6]eff all'!$BF$38:$BG$38 -> 0.84480151 | BH38: =+'[6]eff all'!$BH$38:$BI$38 -> 0.85404309 | BJ38: =+'[6]eff all'!$BJ$38:$BK$38 -> 1387.38 | BL38: =+'[6]eff all'!$BL$38:$BM$38 -> 2.841471 | BN38: =+'[6]eff all'!$BN$38:$BO$38 -> 0 | BP38: =+'[6]eff all'!$BP$38:$BQ$38 -> 1094.5931 | BR38: =+'[6]eff all'!$BR$38:$BS$38 -> 0 | BT38: =+'[6]eff all'!$BT$38:$BU$38 -> 0.56906056 | BV38: =+'[6]eff all'!$BV$38:$BW$38 -> 0.79794558 | BX38: =+'[6]eff all'!$BX$38:$BY$38 -> 904.638 | BZ38: =+'[6]eff all'!$BZ$38:$CA$38 -> 98.183246 | CB38: =+'[6]eff all'!$CB$38:$CC$38 -> 2.3456897 | CD38: =+'[6]eff all'!$CD$38:$CE$38 -> 0.013817682 | CF38: =+'[6]eff all'!$CF$38:$CG$38 -> 1025.3921 | CH38: =+'[6]eff all'!$CH$38:$CI$38 -> 32.403016 | CJ38: =+'[6]eff all'!$CJ$38:$CK$38 -> 0
A39: September | B39: =+'[7]eff all'!$B$39:$C$39 -> 0.90399081 | D39: =+'[7]eff all'!$D$39:$E$39 -> 0.90437904 | F39: =+'[7]eff all'!$F$39:$G$39 -> 1787.584 | H39: =+'[7]eff all'!$H$39:$I$39 -> 2.2781229 | J39: =+'[7]eff all'!$J$39:$K$39 -> 915.86318 | L39: =+'[7]eff all'!$L$39:$M$39 -> 0.91235679 | N39: =+'[7]eff all'!$N$39:$O$39 -> 0.91641187 | P39: =+'[7]eff all'!$P$39:$Q$39 -> 1733.483 | R39: =+'[7]eff all'!$R$39:$S$39 -> 2.0999496 | T39: =+'[7]eff all'!$T$39:$U$39 -> 0.29126331 | V39: =+'[7]eff all'!$V$39:$W$39 -> 594.57701 | X39: =+'[7]eff all'!$X$39:$Y$39 -> 459.61051 | Z39: =+'[7]eff all'!$Z$39:$AA$39 -> 0.31795967 | AB39: =+'[7]eff all'!$AB$39:$AC$39 -> 0.77060412 | AD39: =+'[7]eff all'!$AD$39:$AE$39 -> 413.672 | AF39: =+'[7]eff all'!$AF$39:$AG$39 -> 99.280285 | AH39: =+'[7]eff all'!$AH$39:$AI$39 -> 1.8947379 | AJ39: =+'[7]eff all'!$AJ$39:$AK$39 -> 1272.9031 | AL39: =+'[7]eff all'!$AL$39:$AM$39 -> 0 | AN39: =+'[7]eff all'!$AN$39:$AO$39 -> 0.88030658 | AP39: =+'[7]eff all'!$AP$39:$AQ$39 -> 0.89025454 | AR39: =+'[7]eff all'!$AR$39:$AS$39 -> 1341.886 | AT39: =+'[7]eff all'!$AT$39:$AU$39 -> 122.30106 | AV39: =+'[7]eff all'!$AV$39:$AW$39 -> 1.4501977 | AX39: =+'[7]eff all'!$AX$39:$AY$39 -> 0.063790814 | AZ39: =+'[7]eff all'!$AZ$39:$BA$39 -> 910.28922 | BB39: =+'[7]eff all'!$BB$39:$BC$39 -> 164.14175 | BD39: =+'[7]eff all'!$BD$39:$BE$39 -> 2.0120934 | BF39: =+'[7]eff all'!$BF$39:$BG$39 -> 0.8468278 | BH39: =+'[7]eff all'!$BH$39:$BI$39 -> 0.8468278 | BJ39: =+'[7]eff all'!$BJ$39:$BK$39 -> 1322.914 | BL39: =+'[7]eff all'!$BL$39:$BM$39 -> 2.6480179 | BN39: =+'[7]eff all'!$BN$39:$BO$39 -> 0 | BP39: =+'[7]eff all'!$BP$39:$BQ$39 -> 1045.6073 | BR39: =+'[7]eff all'!$BR$39:$BS$39 -> 0 | BT39: =+'[7]eff all'!$BT$39:$BU$39 -> 0.84513582 | BV39: =+'[7]eff all'!$BV$39:$BW$39 -> 0.84822809 | BX39: =+'[7]eff all'!$BX$39:$BY$39 -> 1346.375 | BZ39: =+'[7]eff all'!$BZ$39:$CA$39 -> 79.267994 | CB39: =+'[7]eff all'!$CB$39:$CC$39 -> 1.957107 | CD39: =+'[7]eff all'!$CD$39:$CE$39 -> 0.21004549 | CF39: =+'[7]eff all'!$CF$39:$CG$39 -> 810.9602 | CH39: =+'[7]eff all'!$CH$39:$CI$39 -> 541.04427 | CJ39: =+'[7]eff all'!$CJ$39:$CK$393 -> 2.8892396
A40: Agustus | B40: =+'[8]eff all'!$B$40:$C$40 -> 0.89986679 | D40: =+'[8]eff all'!$D$40:$E$40 -> 0.9000777 | F40: =+'[8]eff all'!$F$40:$G$40 -> 1865.517 | H40: =+'[8]eff all'!$H$40:$I$40 -> 2.2984749 | J40: =+'[8]eff all'!$J$40:$K$40 -> 910.11683 | L40: =+'[8]eff all'!$L$40:$M$40 -> 0.88665976 | N40: =+'[8]eff all'!$N$40:$O$40 -> 0.91130228 | P40: =+'[8]eff all'!$P$40:$Q$40 -> 1681.041 | R40: =+'[8]eff all'!$R$40:$S$40 -> 2.3611024 | T40: =+'[8]eff all'!$T$40:$U$40 -> 0.085601719 | V40: =+'[8]eff all'!$V$40:$W$40 -> 751.4219 | X40: =+'[8]eff all'!$X$40:$Y$40 -> 160.39778 | Z40: =+'[8]eff all'!$Z$40:$AA$40 -> 0.90643195 | AB40: =+'[8]eff all'!$AB$40:$AC$40 -> 0.90643195 | AD40: =+'[8]eff all'!$AD$40:$AE$40 -> 1304.522 | AF40: =+'[8]eff all'!$AF$40:$AG$40 -> 93.687913 | AH40: =+'[8]eff all'!$AH$40:$AI$40 -> 1.3601917 | AJ40: =+'[8]eff all'!$AJ$40:$AK$40 -> 867.99488 | AL40: =+'[8]eff all'!$AL$40:$AM$40 -> 0 | AN40: =+'[8]eff all'!$AN$40:$AO$40 -> 0.89554899 | AP40: =+'[8]eff all'!$AP$40:$AQ$40 -> 0.90516623 | AR40: =+'[8]eff all'!$AR$40:$AS$40 -> 1480.133 | AT40: =+'[8]eff all'!$AT$40:$AU$40 -> 101.44643 | AV40: =+'[8]eff all'!$AV$40:$AW$40 -> 1.4403435 | AX40: =+'[8]eff all'!$AX$40:$AY$40 -> 0.14586527 | AZ40: =+'[8]eff all'!$AZ$40:$BA$40 -> 849.36179 | BB40: =+'[8]eff all'!$BB$40:$BC$40 -> 387.77383 | BD40: =+'[8]eff all'!$BD$40:$BE$40 -> 4.1014476 | BF40: =+'[8]eff all'!$BF$40:$BG$40 -> 0.90695193 | BH40: =+'[8]eff all'!$BH$40:$BI$40 -> 0.90825057 | BJ40: =+'[8]eff all'!$BJ$40:$BK$40 -> 1465.16 | BL40: =+'[8]eff all'!$BL$40:$BM$40 -> 2.8592099 | BN40: =+'[8]eff all'!$BN$40:$BO$40 -> 0 | BP40: =+'[8]eff all'!$BP$40:$BQ$40 -> 1013.159 | BR40: =+'[8]eff all'!$BR$40:$BS$40 -> 0 | BT40: =+'[8]eff all'!$BT$40:$BU$40 -> 0.86462303 | BV40: =+'[8]eff all'!$BV$40:$BW$40 -> 0.87445113 | BX40: =+'[8]eff all'!$BX$40:$BY$40 -> 1364.354 | BZ40: =+'[8]eff all'!$BZ$40:$CA$40 -> 84.357026 | CB40: =+'[8]eff all'!$CB$40:$CC$40 -> 2.0277802 | CD40: =+'[8]eff all'!$CD$40:$CE$40 -> 0.074687361 | CF40: =+'[8]eff all'!$CF$40:$CG$40 -> 883.67534 | CH40: =+'[8]eff all'!$CH$40:$CI$40 -> 193.15194 | CJ40: =+'[8]eff all'!$CJ$40:$CK$40 -> 2.4682832
A41: Juli | B41: =+'[9]eff all'!$B$41:$C$41 -> 0.83939759 | D41: =+'[9]eff all'!$D$41:$E$41 -> 0.84053151 | F41: =+'[9]eff all'!$F$41:$G$41 -> 1669.03 | H41: =+'[9]eff all'!$H$41:$I$41 -> 2.439188 | J41: =+'[9]eff all'!$J$41:$K$41 -> 1033.4659 | L41: =+'[9]eff all'!$L$41:$M$41 -> 0.88164645 | N41: =+'[9]eff all'!$N$41:$O$41 -> 0.90721678 | P41: =+'[9]eff all'!$P$41:$Q$41 -> 1849.253 | R41: =+'[9]eff all'!$R$41:$S$41 -> 2.6039628 | T41: =+'[9]eff all'!$T$41:$U$41 -> 0.22857878 | V41: =+'[9]eff all'!$V$41:$W$41 -> 604.72262 | X41: =+'[9]eff all'!$X$41:$Y$41 -> 521.78582 | Z41: =+'[9]eff all'!$Z$41:$AA$41 -> 0.88193173 | AB41: =+'[9]eff all'!$AB$41:$AC$41 -> 0.88340653 | AD41: =+'[9]eff all'!$AD$41:$AE$41 -> 1253.705 | AF41: =+'[9]eff all'!$AF$41:$AG$41 -> 98.517031 | AH41: =+'[9]eff all'!$AH$41:$AI$41 -> 1.4871122 | AJ41: =+'[9]eff all'!$AJ$41:$AK$41 -> 885.26052 | AL41: =+'[9]eff all'!$AL$41:$AM$41 -> 0 | AN41: =+'[9]eff all'!$AN$41:$AO$41 -> 0.88320077 | AP41: =+'[9]eff all'!$AP$41:$AQ$41 -> 0.8953444 | AR41: =+'[9]eff all'!$AR$41:$AS$41 -> 1406.635 | AT41: =+'[9]eff all'!$AT$41:$AU$41 -> 105.33379 | AV41: =+'[9]eff all'!$AV$41:$AW$41 -> 1.5242049 | AX41: =+'[9]eff all'!$AX$41:$AY$41 -> 0.080760112 | AZ41: =+'[9]eff all'!$AZ$41:$BA$41 -> 927.60065 | BB41: =+'[9]eff all'!$BB$41:$BC$41 -> 240.27392 | BD41: =+'[9]eff all'!$BD$41:$BE$41 -> 16.955358 | BF41: =+'[9]eff all'!$BF$41:$BG$41 -> 0.88101947 | BH41: =+'[9]eff all'!$BH$41:$BI$41 -> 0.8836277 | BJ41: =+'[9]eff all'!$BJ$41:$BK$41 -> 1457.009 | BL41: =+'[9]eff all'!$BL$41:$BM$41 -> 2.7597633 | BN41: =+'[9]eff all'!$BN$41:$BO$41 -> 0 | BP41: =+'[9]eff all'!$BP$41:$BQ$41 -> 932.94369 | BR41: =+'[9]eff all'!$BR$41:$BS$41 -> 0 | BT41: =+'[9]eff all'!$BT$41:$BU$41 -> 0.89958178 | BV41: =+'[9]eff all'!$BV$41:$BW$41 -> 0.90458737 | BX41: =+'[9]eff all'!$BX$41:$BY$41 -> 1385.694 | BZ41: =+'[9]eff all'!$BZ$41:$CA$41 -> 82.805082 | CB41: =+'[9]eff all'!$CB$41:$CC$41 -> 1.975097 | CD41: =+'[9]eff all'!$CD$41:$CE$41 -> 0.056505982 | CF41: =+'[9]eff all'!$CF$41:$CG$41 -> 886.8081 | CH41: =+'[9]eff all'!$CH$41:$CI$41 -> 150.23872 | CJ41: =+'[9]eff all'!$CJ$41:$CK$41 -> 14.750731
A42: Juni | B42: =+'[10]eff all'!$B$42:$C$42 -> 0.89683017 | D42: =+'[10]eff all'!$D$42:$E$42 -> 0.91651255 | F42: =+'[10]eff all'!$F$42:$G$42 -> 1608.12 | H42: =+'[10]eff all'!$H$42:$I$42 -> 2.3160038 | J42: =+'[10]eff all'!$J$42:$K$42 -> 1025.4408 | L42: =+'[10]eff all'!$L$42:$M$42 -> 0.92866755 | N42: =+'[10]eff all'!$N$42:$O$42 -> 0.93793898 | P42: =+'[10]eff all'!$P$42:$Q$42 -> 1827.359 | R42: =+'[10]eff all'!$R$42:$S$42 -> 2.0916447 | T42: =+'[10]eff all'!$T$42:$U$42 -> 0.23153633 | V42: =+'[10]eff all'!$V$42:$W$42 -> 614.27863 | X42: =+'[10]eff all'!$X$42:$Y$42 -> 437.11553 | Z42: =+'[10]eff all'!$Z$42:$AA$42 -> 0.83629624 | AB42: =+'[10]eff all'!$AB$42:$AC$42 -> 0.84011645 | AD42: =+'[10]eff all'!$AD$42:$AE$42 -> 1132.285 | AF42: =+'[10]eff all'!$AF$42:$AG$42 -> 111.282 | AH42: =+'[10]eff all'!$AH$42:$AI$42 -> 1.6594762 | AJ42: =+'[10]eff all'!$AJ$42:$AK$42 -> 964.83334 | AL42: =+'[10]eff all'!$AL$42:$AM$42 -> 0 | AN42: =+'[10]eff all'!$AN$42:$AO$42 -> 0.84149356 | AP42: =+'[10]eff all'!$AP$42:$AQ$42 -> 0.85108231 | AR42: =+'[10]eff all'!$AR$42:$AS$42 -> 1316.344 | AT42: =+'[10]eff all'!$AT$42:$AU$42 -> 121.83944 | AV42: =+'[10]eff all'!$AV$42:$AW$42 -> 1.4904159 | AX42: =+'[10]eff all'!$AX$42:$AY$42 -> 0.19523772 | AZ42: =+'[10]eff all'!$AZ$42:$BA$42 -> 883.634 | BB42: =+'[10]eff all'!$BB$42:$BC$42 -> 521.8822 | BD42: =+'[10]eff all'!$BD$42:$BE$42 -> 0 | BF42: =+'[10]eff all'!$BF$42:$BG$42 -> 0.81559728 | BH42: =+'[10]eff all'!$BH$42:$BI$42 -> 0.82877821 | BJ42: =+'[10]eff all'!$BJ$42:$BK$42 -> 1259.735 | BL42: =+'[10]eff all'!$BL$42:$BM$42 -> 2.8948152 | BN42: =+'[10]eff all'!$BN$42:$BO$42 -> 0 | BP42: =+'[10]eff all'!$BP$42:$BQ$42 -> 971.0194 | BR42: =+'[10]eff all'!$BR$42:$BS$42 -> 0 | BT42: =+'[10]eff all'!$BT$42:$BU$42 -> 0.90927146 | BV42: =+'[10]eff all'!$BV$42:$BW$42 -> 0.93351911 | BX42: =+'[10]eff all'!$BX$42:$BY$42 -> 1433.06 | BZ42: =+'[10]eff all'!$BZ$42:$CA$42 -> 77.094083 | CB42: =+'[10]eff all'!$CB$42:$CC$42 -> 1.8864528 | CD42: =+'[10]eff all'!$CD$42:$CE$42 -> 0.14263185 | CF42: =+'[10]eff all'!$CF$42:$CG$42 -> 754.59782 | CH42: =+'[10]eff all'!$CH$42:$CI$42 -> 384.70371 | CJ42: 0
A43: Mei | B43: =+'[11]eff all'!$B$43:$C$43 -> 0.81728993 | D43: =+'[11]eff all'!$D$43:$E$43 -> 0.81728993 | F43: =+'[11]eff all'!$F$43:$G$43 -> 1753.698 | H43: =+'[11]eff all'!$H$43:$I$43 -> 2.3283627 | J43: =+'[11]eff all'!$J$43:$K$43 -> 919.17355 | L43: =+'[11]eff all'!$L$43:$M$43 -> 0.88541366 | N43: =+'[11]eff all'!$N$43:$O$43 -> 0.92564375 | P43: =+'[11]eff all'!$P$43:$Q$43 -> 1848.366 | R43: =+'[11]eff all'!$R$43:$S$43 -> 2.3081273 | T43: =+'[11]eff all'!$T$43:$U$43 -> 0.22165523 | V43: =+'[11]eff all'!$V$43:$W$43 -> 640.41015 | X43: =+'[11]eff all'!$X$43:$Y$43 -> 434.93518 | Z43: =+'[11]eff all'!$Z$43:$AA$43 -> 0.80335181 | AB43: =+'[11]eff all'!$AB$43:$AC$43 -> 0.86162049 | AD43: =+'[11]eff all'!$AD$43:$AE$43 -> 1130.835 | AF43: =+'[11]eff all'!$AF$43:$AG$43 -> 107.89352 | AH43: =+'[11]eff all'!$AH$43:$AI$43 -> 1.5947508 | AJ43: =+'[11]eff all'!$AJ$43:$AK$43 -> 914.38362 | AL43: =+'[11]eff all'!$AL$43:$AM$43 -> 20.16563 | AN43: =+'[11]eff all'!$AN$43:$AO$43 -> 0.85071019 | AP43: =+'[11]eff all'!$AP$43:$AQ$43 -> 0.85071019 | AR43: =+'[11]eff all'!$AR$43:$AS$43 -> 1375.357 | AT43: =+'[11]eff all'!$AT$43:$AU$43 -> 113.79765 | AV43: =+'[11]eff all'!$AV$43:$AW$43 -> 1.4656558 | AX43: =+'[11]eff all'!$AX$43:$AY$43 -> 0.18613349 | AZ43: =+'[11]eff all'!$AZ$43:$BA$43 -> 878.46065 | BB43: =+'[11]eff all'!$BB$43:$BC$43 -> 550.25946 | BD43: =+'[11]eff all'!$BD$43:$BE$43 -> 0 | BF43: =+'[11]eff all'!$BF$43:$BG$43 -> 0.89363459 | BH43: =+'[11]eff all'!$BH$43:$BI$43 -> 0.89363459 | BJ43: =+'[11]eff all'!$BJ$43:$BK$43 -> 1430.692 | BL43: =+'[11]eff all'!$BL$43:$BM$43 -> 2.6821286 | BN43: =+'[11]eff all'!$BN$43:$BO$43 -> 0 | BP43: =+'[11]eff all'!$BP$43:$BQ$43 -> 974.33569 | BR43: =+'[11]eff all'!$BR$43:$BS$43 -> 0 | BT43: =+'[11]eff all'!$BT$43:$BU$43 -> 0.90863448 | BV43: =+'[11]eff all'!$BV$43:$BW$43 -> 0.9187839 | BX43: =+'[11]eff all'!$BX$43:$BY$43 -> 1460.105 | BZ43: =+'[11]eff all'!$BZ$43:$CA$43 -> 77.669648 | CB43: =+'[11]eff all'!$CB$43:$CC$43 -> 2.0032806 | CD43: =+'[11]eff all'!$CD$43:$CE$43 -> 0.083692611 | CF43: =+'[11]eff all'!$CF$43:$CG$43 -> 840.76602 | CH43: =+'[11]eff all'!$CH$43:$CI$43 -> 246.27503 | CJ43: =+'[11]eff all'!$CJ$43:$CK$43 -> 19.550649
