Workbook

Sheet eff all value

Sheet Report1
A3: PAPER MACHINE 17 DAILY REPORT 1
A6: Date | B6: Grade | C6: GSM | D6: Speed yankee (mpm) | E6: Speed reel (mpm) | F6: Creep ( % ) | G6: Real Eff PM ( % ) | H6: Real Eff PM vs Target (%) | I6: Real Eff FG vs Real Eff PM (%) | J6: Eff FG vs Target (%) | L6: Kapasitas Target (ton) | N6: Kapasitas Teori Real (ton) | P6: PM PROD Timbangan (TON) | R6: FINSHED GOODS (TON) | T6: GAS HOOD | Z6: STEAM (TON) | AF6: STEAM DEINKING (TON) | AL6: POWER (kWh) | AR6: POWER DEINKING (kWh) | AX6: POWER WPL (kWh) | BD6: TOTALIZER | BE6: Kapasitas Running (ton) | BG6: Eff FG vs Target Running(%)
T7: CONSUMPTION | V7: /TON PM. | X7: /TON FG. | Z7: CONSUMPTION | AB7: /TON PM. | AD7: /TON FG. | AF7: CONSUMPTION | AH7: /TON PM. | AJ7: /TON FG. | AL7: CONSUMPTION | AN7: /TON PM | AP7: /TON FG | AR7: CONSUMPTION | AT7: /TON PM | AV7: /TON FG | AX7: CONSUMPTION | AZ7: /TON PM | BB7: /TON FG
J8: TODAY | K8: TODATE | L8: TODAY | M8: TODATE | N8: TODAY | O8: TODATE | P8: TODAY | Q8: TODATE | R8: TODAY | S8: TODATE | T8: TODAY | U8: TODATE | V8: TODAY | W8: TODATE | X8: TODAY | Y8: TODATE | Z8: TODAY | AA8: TODATE | AB8: TODAY | AC8: TODATE | AD8: TODAY | AE8: TODATE | AF8: TODAY | AG8: TODATE | AH8: TODAY | AI8: TODATE | AJ8: TODAY | AK8: TODATE | AL8: TODAY | AM8: TODATE | AN8: TODAY | AO8: TODATE | AP8: TODAY | AQ8: TODATE | AR8: TODAY | AS8: TODATE | AT8: TODAY | AU8: TODATE | AV8: TODAY | AW8: TODATE | AX8: TODAY | AY8: TODATE | AZ8: TODAY | BA8: TODATE | BB8: TODAY | BC8: TODATE | BE8: TODAY | BF8: TODATE | BG8: TODAY | BH8: TODATE
A9: 46082 | B9: Toilet | C9: 15 | D9: =+'1'!F42 -> 1127.8646 | E9: =+'1'!G42 -> 932.31562 | F9: =1-(E9/D9) -> 0.17337982 | G9: =+P9/N9 -> 0.97055379 | H9: =+P9/L9 -> 0.95602904 | I9: =+R9/P9 -> 1.1217561 | J9: =+R9/L9 -> 1.0724314 | K9: =+S9/M9 -> 1.0724314 | L9: =+Efficiency1!K6 -> 52.438784 | M9: =L9 -> 52.438784 | N9: =+Efficiency1!C6 -> 51.654015 | O9: =N9 -> 51.654015 | P9: ='1'!I38 -> 50.133 | Q9: =P9 -> 50.133 | R9: ='1'!I40 -> 56.237 | S9: =R9 -> 56.237 | T9: =+[1]Report1!AZ9 -> 3735.0527 | U9: =T9 -> 3735.0527 | V9: =T9/P9 -> 74.502876 | W9: =U9/Q9 -> 74.502876 | X9: =IF(AND(R9>0,T9>0),(T9/(R9*1000))*1000,0) -> 66.416286 | Y9: =IF(AND(S9>0,U9>0),U9/S9,0) -> 66.416286 | Z9: 100.8 | AA9: =Z9 -> 100.8 | AB9: =Z9/(P9) -> 2.0106517 | AC9: =AA9/(Q9) -> 2.0106517 | AD9: =IF(AND(R9>0,Z9>0),Z9/(R9),0) -> 1.7924142 | AE9: =IF(AND(S9>0,AA9>0),AA9/(S9),0) -> 1.7924142 | AF9: 0 | AG9: =AF9 -> 0 | AH9: =AF9/(P9) -> 0 | AI9: =AG9/(Q9) -> 0 | AJ9: =IF(AND(R9>0,AF9>0),AF9/(R9),0) -> 0 | AK9: =IF(AND(S9>0,AG9>0),AG9/(S9),0) -> 0 | AL9: ='1'!I46 -> 39310.92 | AM9: =AL9 -> 39310.92 | AN9: =IF(AND(L9>0,AL9>0),(AL9/(P9*1000)*1000),0) -> 784.13261 | AO9: =IF(AND(M9>0,AM9>0),(AM9/(Q9*1000)*1000),0) -> 784.13261 | AP9: =IF(AND(R9>0,AL9>0),(AL9/(R9*1000)*1000),0) -> 699.02235 | AQ9: =IF(AND(S9>0,AM9>0),(AM9/(S9*1000)*1000),0) -> 699.02235 | AR9: =+Listrik!AA8 -> 30967.4 | AS9: =AR9 -> 30967.4 | AT9: =IF(AND(L9>0,AR9>0),(AR9/(P9*1000)*1000),0) -> 617.7049 | AU9: =IF(AND(M9>0,AS9>0),(AS9/(Q9*1000)*1000),0) -> 617.7049 | AV9: =IF(AND(R9>0,AR9>0),(AR9/(R9*1000)*1000),0) -> 550.65882 | AW9: =IF(AND(S9>0,AS9>0),(AS9/(S9*1000)*1000),0) -> 550.65882 | AX9: 0 | AY9: =AX9 -> 0 | AZ9: =IF(AND(L9>0,AX9>0),(AX9/(P9*1000)*1000),0) -> 0 | BA9: =IF(AND(M9>0,AY9>0),(AY9/(Q9*1000)*1000),0) -> 0 | BB9: =IF(AND(R9>0,AX9>0),(AX9/(R9*1000)*1000),0) -> 0 | BC9: =IF(AND(S9>0,AY9>0),(AY9/(S9*1000)*1000),0) -> 0 | BE9: =+Efficiency2!K6 -> 52.438784 | BF9: =BE9 -> 52.438784 | BG9: =+R9/BE9 -> 1.0724314 | BH9: =+S9/BF9 -> 1.0724314
A10: =A9+1 -> 46083 | B10: Toilet | C10: 15 | D10: =+'2'!F42 -> 1124.6504 | E10: =+'2'!G42 -> 955.95286 | F10: =1-(E10/D10) -> 0.15 | G10: =+P10/N10 -> 0.98507254 | H10: =+P10/L10 -> 0.98507254 | I10: =+R10/P10 -> 1.0049834 | J10: =+R10/L10 -> 0.98998157 | K10: =+S10/M10 -> 1.0310012 | L10: =+Efficiency1!K10 -> 52.963612 | M10: =M9+L10 -> 105.4024 | N10: =+Efficiency1!C10 -> 52.963612 | O10: =O9+N10 -> 104.61763 | P10: ='2'!I38 -> 52.173 | Q10: =Q9+P10 -> 102.306 | R10: ='2'!I40 -> 52.433 | S10: =S9+R10 -> 108.67 | T10: =+[1]Report1!AZ10 -> 3946.6675 | U10: =T10+U9 -> 7681.7202 | V10: =T10/P10 -> 75.645785 | W10: =U10/Q10 -> 75.085725 | X10: =IF(AND(R10>0,T10>0),(T10/(R10*1000))*1000,0) -> 75.270679 | Y10: =IF(AND(S10>0,U10>0),U10/S10,0) -> 70.688509 | Z10: 99.2 | AA10: =Z10+AA9 -> 200 | AB10: =Z10/(P10) -> 1.9013666 | AC10: =AA10/(Q10) -> 1.9549196 | AD10: =IF(AND(R10>0,Z10>0),Z10/(R10),0) -> 1.8919383 | AE10: =IF(AND(S10>0,AA10>0),AA10/(S10),0) -> 1.8404343 | AF10: 0 | AG10: =+AF10+AG9 -> 0 | AH10: =AF10/(P10) -> 0 | AI10: =AG10/(Q10) -> 0 | AJ10: =IF(AND(R10>0,AF10>0),AF10/(R10),0) -> 0 | AK10: =IF(AND(S10>0,AG10>0),AG10/(S10),0) -> 0 | AL10: ='2'!I46 -> 36966.385 | AM10: =AL10+AM9 -> 76277.305 | AN10: =IF(AND(L10>0,AL10>0),(AL10/(P10*1000)*1000),0) -> 708.53478 | AO10: =IF(AND(M10>0,AM10>0),(AM10/(Q10*1000)*1000),0) -> 745.57998 | AP10: =IF(AND(R10>0,AL10>0),(AL10/(R10*1000)*1000),0) -> 705.02136 | AQ10: =IF(AND(S10>0,AM10>0),(AM10/(S10*1000)*1000),0) -> 701.91686 | AR10: =+Listrik!AA9 -> 29196 | AS10: =AR10+AS9 -> 60163.4 | AT10: =IF(AND(L10>0,AR10>0),(AR10/(P10*1000)*1000),0) -> 559.59979 | AU10: =IF(AND(M10>0,AS10>0),(AS10/(Q10*1000)*1000),0) -> 588.07304 | AV10: =IF(AND(R10>0,AR10>0),(AR10/(R10*1000)*1000),0) -> 556.8249 | AW10: =IF(AND(S10>0,AS10>0),(AS10/(S10*1000)*1000),0) -> 553.63394 | AX10: 0 | AY10: =AX10+AY9 -> 0 | AZ10: =IF(AND(L10>0,AX10>0),(AX10/(P10*1000)*1000),0) -> 0 | BA10: =IF(AND(M10>0,AY10>0),(AY10/(Q10*1000)*1000),0) -> 0 | BB10: =IF(AND(R10>0,AX10>0),(AX10/(R10*1000)*1000),0) -> 0 | BC10: =IF(AND(S10>0,AY10>0),(AY10/(S10*1000)*1000),0) -> 0 | BE10: =+Efficiency2!K10 -> 52.963612 | BF10: =BF9+BE10 -> 105.4024 | BG10: =+R10/BE10 -> 0.98998157 | BH10: =+S10/BF10 -> 1.0310012
A11: =A10+1 -> 46084 | B11: Toilet | C11: 15 | D11: =+'3'!F42 -> 1125 | E11: =+'3'!G42 -> 945 | F11: =1-(E11/D11) -> 0.16 | G11: =+P11/N11 -> 1.0134127 | H11: =+P11/L11 -> 1.0134127 | I11: =+R11/P11 -> 0.92948169 | J11: =+R11/L11 -> 0.94194859 | K11: =+S11/M11 -> 1.0012186 | L11: =+Efficiency1!K14 -> 52.963612 | M11: =M10+L11 -> 158.36601 | N11: =+Efficiency1!C14 -> 52.963612 | O11: =O10+N11 -> 157.58124 | P11: ='3'!I38 -> 53.674 | Q11: =Q10+P11 -> 155.98 | R11: ='3'!I40 -> 49.889 | S11: =S10+R11 -> 158.559 | T11: =+[1]Report1!AZ11 -> 3635.0489 | U11: =T11+U10 -> 11316.769 | V11: =T11/P11 -> 67.724577 | W11: =U11/Q11 -> 72.552694 | X11: =IF(AND(R11>0,T11>0),(T11/(R11*1000))*1000,0) -> 72.862734 | Y11: =IF(AND(S11>0,U11>0),U11/S11,0) -> 71.372607 | Z11: 100.36 | AA11: =Z11+AA10 -> 300.36 | AB11: =Z11/(P11) -> 1.8698066 | AC11: =AA11/(Q11) -> 1.9256315 | AD11: =IF(AND(R11>0,Z11>0),Z11/(R11),0) -> 2.0116659 | AE11: =IF(AND(S11>0,AA11>0),AA11/(S11),0) -> 1.8943106 | AG11: =+AF11+AG10 -> 0 | AH11: =AF11/(P11) -> 0 | AI11: =AG11/(Q11) -> 0 | AJ11: =IF(AND(R11>0,AF11>0),AF11/(R11),0) -> 0 | AK11: =IF(AND(S11>0,AG11>0),AG11/(S11),0) -> 0 | AL11: ='3'!I46 -> 35761.525 | AM11: =AL11+AM10 -> 112038.83 | AN11: =IF(AND(L11>0,AL11>0),(AL11/(P11*1000)*1000),0) -> 666.27279 | AO11: =IF(AND(M11>0,AM11>0),(AM11/(Q11*1000)*1000),0) -> 718.28972 | AP11: =IF(AND(R11>0,AL11>0),(AL11/(R11*1000)*1000),0) -> 716.82185 | AQ11: =IF(AND(S11>0,AM11>0),(AM11/(S11*1000)*1000),0) -> 706.60657 | AR11: =+Listrik!AA10 -> 21611 | AS11: =AR11+AS10 -> 81774.4 | AT11: =IF(AND(L11>0,AR11>0),(AR11/(P11*1000)*1000),0) -> 402.63442 | AU11: =IF(AND(M11>0,AS11>0),(AS11/(Q11*1000)*1000),0) -> 524.26208 | AV11: =IF(AND(R11>0,AR11>0),(AR11/(R11*1000)*1000),0) -> 433.18166 | AW11: =IF(AND(S11>0,AS11>0),(AS11/(S11*1000)*1000),0) -> 515.73484 | AX11: 0 | AY11: =AX11+AY10 -> 0 | AZ11: =IF(AND(L11>0,AX11>0),(AX11/(P11*1000)*1000),0) -> 0 | BA11: =IF(AND(M11>0,AY11>0),(AY11/(Q11*1000)*1000),0) -> 0 | BB11: =IF(AND(R11>0,AX11>0),(AX11/(R11*1000)*1000),0) -> 0 | BC11: =IF(AND(S11>0,AY11>0),(AY11/(S11*1000)*1000),0) -> 0 | BE11: =+Efficiency1!K14 -> 52.963612 | BF11: =BF10+BE11 -> 158.36601 | BG11: =+R11/BE11 -> 0.94194859 | BH11: =+S11/BF11 -> 1.0012186
A12: =A11+1 -> 46085 | B12: Toilet | C12: 15/14,5 | D12: =+'4'!F42 -> 1108.196 | E12: =+'4'!G42 -> 930.88462 | F12: =1-(E12/D12) -> 0.16 | G12: =+P12/N12 -> 0.70984923 | H12: =+P12/L12 -> 0.67601328 | I12: =+R12/P12 -> 1.0475738 | J12: =+R12/L12 -> 0.70817379 | K12: =+S12/M12 -> 0.92463319 | L12: =+SUM(Efficiency1!K18:K19) -> 56.031444 | M12: =M11+L12 -> 214.39745 | N12: =+SUM(Efficiency1!C18:C19) -> 53.360627 | O12: =O11+N12 -> 210.94187 | P12: ='4'!I38 -> 37.878 | Q12: =Q11+P12 -> 193.858 | R12: ='4'!I40 -> 39.68 | S12: =S11+R12 -> 198.239 | T12: =+[1]Report1!AZ12 -> 3119.1602 | U12: =T12+U11 -> 14435.929 | V12: =T12/P12 -> 82.347542 | W12: =U12/Q12 -> 74.466513 | X12: =IF(AND(R12>0,T12>0),(T12/(R12*1000))*1000,0) -> 78.607867 | Y12: =IF(AND(S12>0,U12>0),U12/S12,0) -> 72.820834 | Z12: 81.4 | AA12: =Z12+AA11 -> 381.76 | AB12: =Z12/(P12) -> 2.1490047 | AC12: =AA12/(Q12) -> 1.9692765 | AD12: =IF(AND(R12>0,Z12>0),Z12/(R12),0) -> 2.0514113 | AE12: =IF(AND(S12>0,AA12>0),AA12/(S12),0) -> 1.9257563 | AG12: =+AF12+AG11 -> 0 | AH12: =AF12/(P12) -> 0 | AI12: =AG12/(Q12) -> 0 | AJ12: =IF(AND(R12>0,AF12>0),AF12/(R12),0) -> 0 | AK12: =IF(AND(S12>0,AG12>0),AG12/(S12),0) -> 0 | AL12: ='4'!I46 -> 30472.534 | AM12: =AL12+AM11 -> 142511.36 | AN12: =IF(AND(L12>0,AL12>0),(AL12/(P12*1000)*1000),0) -> 804.49163 | AO12: =IF(AND(M12>0,AM12>0),(AM12/(Q12*1000)*1000),0) -> 735.13275 | AP12: =IF(AND(R12>0,AL12>0),(AL12/(R12*1000)*1000),0) -> 767.95701 | AQ12: =IF(AND(S12>0,AM12>0),(AM12/(S12*1000)*1000),0) -> 718.88662 | AR12: =+Listrik!AA11 -> 18324.901 | AS12: =AR12+AS11 -> 100099.3 | AT12: =IF(AND(L12>0,AR12>0),(AR12/(P12*1000)*1000),0) -> 483.78745 | AU12: =IF(AND(M12>0,AS12>0),(AS12/(Q12*1000)*1000),0) -> 516.35373 | AV12: =IF(AND(R12>0,AR12>0),(AR12/(R12*1000)*1000),0) -> 461.81706 | AW12: =IF(AND(S12>0,AS12>0),(AS12/(S12*1000)*1000),0) -> 504.94252 | AX12: 0 | AY12: =AX12+AY11 -> 0 | AZ12: =IF(AND(L12>0,AX12>0),(AX12/(P12*1000)*1000),0) -> 0 | BA12: =IF(AND(M12>0,AY12>0),(AY12/(Q12*1000)*1000),0) -> 0 | BB12: =IF(AND(R12>0,AX12>0),(AX12/(R12*1000)*1000),0) -> 0 | BC12: =IF(AND(S12>0,AY12>0),(AY12/(S12*1000)*1000),0) -> 0 | BE12: =+SUM(Efficiency2!K18:K19) -> 49.592868 | BF12: =BF11+BE12 -> 207.95888 | BG12: =+R12/BE12 -> 0.80011505 | BH12: =+S12/BF12 -> 0.95326058
A13: =A12+1 -> 46086 | B13: Toilet | C13: 14,5 | D13: =+'5'!F42 -> 1150 | E13: =+'5'!G42 -> 966 | F13: =1-(E13/D13) -> 0.16 | G13: =+P13/N13 -> 0.94966947 | H13: =+P13/L13 -> 0.93744196 | I13: =+R13/P13 -> 1.0285139 | J13: =+R13/L13 -> 0.96417212 | K13: =+S13/M13 -> 0.93284395 | L13: =+Efficiency1!K25 -> 56.191212 | M13: =M12+L13 -> 270.58866 | N13: =+Efficiency1!C25 -> 55.46772 | O13: =O12+N13 -> 266.40959 | P13: ='5'!I38 -> 52.676 | Q13: =Q12+P13 -> 246.534 | R13: ='5'!I40 -> 54.178 | S13: =S12+R13 -> 252.417 | T13: =+[1]Report1!AZ13 -> 3824.0561 | U13: =T13+U12 -> 18259.985 | V13: =T13/P13 -> 72.595796 | W13: =U13/Q13 -> 74.066804 | X13: =IF(AND(R13>0,T13>0),(T13/(R13*1000))*1000,0) -> 70.583191 | Y13: =IF(AND(S13>0,U13>0),U13/S13,0) -> 72.340553 | Z13: 96.2 | AA13: =Z13+AA12 -> 477.96 | AB13: =Z13/(P13) -> 1.8262586 | AC13: =AA13/(Q13) -> 1.9387184 | AD13: =IF(AND(R13>0,Z13>0),Z13/(R13),0) -> 1.7756285 | AE13: =IF(AND(S13>0,AA13>0),AA13/(S13),0) -> 1.8935333 | AG13: =+AF13+AG12 -> 0 | AH13: =AF13/(P13) -> 0 | AI13: =AG13/(Q13) -> 0 | AJ13: =IF(AND(R13>0,AF13>0),AF13/(R13),0) -> 0 | AK13: =IF(AND(S13>0,AG13>0),AG13/(S13),0) -> 0 | AL13: ='5'!I46 -> 37494.221 | AM13: =AL13+AM12 -> 180005.59 | AN13: =IF(AND(L13>0,AL13>0),(AL13/(P13*1000)*1000),0) -> 711.78946 | AO13: =IF(AND(M13>0,AM13>0),(AM13/(Q13*1000)*1000),0) -> 730.14507 | AP13: =IF(AND(R13>0,AL13>0),(AL13/(R13*1000)*1000),0) -> 692.05621 | AQ13: =IF(AND(S13>0,AM13>0),(AM13/(S13*1000)*1000),0) -> 713.12782 | AR13: =+Listrik!AA12 -> 23445.415 | AS13: =AR13+AS12 -> 123544.72 | AT13: =IF(AND(L13>0,AR13>0),(AR13/(P13*1000)*1000),0) -> 445.08723 | AU13: =IF(AND(M13>0,AS13>0),(AS13/(Q13*1000)*1000),0) -> 501.12648 | AV13: =IF(AND(R13>0,AR13>0),(AR13/(R13*1000)*1000),0) -> 432.74789 | AW13: =IF(AND(S13>0,AS13>0),(AS13/(S13*1000)*1000),0) -> 489.44689 | AX13: 0 | AY13: =AX13+AY12 -> 0 | AZ13: =IF(AND(L13>0,AX13>0),(AX13/(P13*1000)*1000),0) -> 0 | BA13: =IF(AND(M13>0,AY13>0),(AY13/(Q13*1000)*1000),0) -> 0 | BB13: =IF(AND(R13>0,AX13>0),(AX13/(R13*1000)*1000),0) -> 0 | BC13: =IF(AND(S13>0,AY13>0),(AY13/(S13*1000)*1000),0) -> 0 | BE13: =+Efficiency2!K25 -> 56.191212 | BF13: =BF12+BE13 -> 264.15009 | BG13: =+R13/BE13 -> 0.96417212 | BH13: =+S13/BF13 -> 0.95558174
A14: =A13+1 -> 46087 | B14: Toilet | C14: 14,5/15 | D14: =+'6'!F42 -> 1134.9451 | E14: =+'6'!G42 -> 953.35385 | F14: =1-(E14/D14) -> 0.16 | G14: =+P14/N14 -> 0.63123121 | H14: =+P14/L14 -> 0.62988869 | I14: =+R14/P14 -> 0.98611111 | J14: =+R14/L14 -> 0.62114024 | K14: =+S14/M14 -> 0.88166799 | L14: =+SUM(Efficiency1!K29:K30) -> 53.152248 | M14: =M13+L14 -> 323.74091 | N14: =+SUM(Efficiency1!C29:C30) -> 53.039202 | O14: =O13+N14 -> 319.44879 | P14: ='6'!I38 -> 33.48 | Q14: =Q13+P14 -> 280.014 | R14: ='6'!I40 -> 33.015 | S14: =S13+R14 -> 285.432 | T14: =+[1]Report1!AZ14 -> 2068.6607 | U14: =T14+U13 -> 20328.646 | V14: =T14/P14 -> 61.787954 | W14: =U14/Q14 -> 72.598678 | X14: =IF(AND(R14>0,T14>0),(T14/(R14*1000))*1000,0) -> 62.658207 | Y14: =IF(AND(S14>0,U14>0),U14/S14,0) -> 71.220628 | Z14: 63.6 | AA14: =Z14+AA13 -> 541.56 | AB14: =Z14/(P14) -> 1.8996416 | AC14: =AA14/(Q14) -> 1.9340462 | AD14: =IF(AND(R14>0,Z14>0),Z14/(R14),0) -> 1.9263971 | AE14: =IF(AND(S14>0,AA14>0),AA14/(S14),0) -> 1.8973346 | AG14: =+AF14+AG13 -> 0 | AH14: =AF14/(P14) -> 0 | AI14: =AG14/(Q14) -> 0 | AJ14: =IF(AND(R14>0,AF14>0),AF14/(R14),0) -> 0 | AK14: =IF(AND(S14>0,AG14>0),AG14/(S14),0) -> 0 | AL14: ='6'!I46 -> 27123.787 | AM14: =AL14+AM13 -> 207129.37 | AN14: =IF(AND(L14>0,AL14>0),(AL14/(P14*1000)*1000),0) -> 810.14895 | AO14: =IF(AND(M14>0,AM14>0),(AM14/(Q14*1000)*1000),0) -> 739.71077 | AP14: =IF(AND(R14>0,AL14>0),(AL14/(R14*1000)*1000),0) -> 821.5595 | AQ14: =IF(AND(S14>0,AM14>0),(AM14/(S14*1000)*1000),0) -> 725.66977 | AR14: =+Listrik!AA13 -> 20592.308 | AS14: =AR14+AS13 -> 144137.02 | AT14: =IF(AND(L14>0,AR14>0),(AR14/(P14*1000)*1000),0) -> 615.06296 | AU14: =IF(AND(M14>0,AS14>0),(AS14/(Q14*1000)*1000),0) -> 514.74935 | AV14: =IF(AND(R14>0,AR14>0),(AR14/(R14*1000)*1000),0) -> 623.72582 | AW14: =IF(AND(S14>0,AS14>0),(AS14/(S14*1000)*1000),0) -> 504.9785 | AX14: 0 | AY14: =AX14+AY13 -> 0 | AZ14: =IF(AND(L14>0,AX14>0),(AX14/(P14*1000)*1000),0) -> 0 | BA14: =IF(AND(M14>0,AY14>0),(AY14/(Q14*1000)*1000),0) -> 0 | BB14: =IF(AND(R14>0,AX14>0),(AX14/(R14*1000)*1000),0) -> 0 | BC14: =IF(AND(S14>0,AY14>0),(AY14/(S14*1000)*1000),0) -> 0 | BE14: =+SUM(Efficiency2!K29:K30) -> 33.796399 | BF14: =BF13+BE14 -> 297.94649 | BG14: =+R14/BE14 -> 0.97687923 | BH14: =+S14/BF14 -> 0.95799753
A15: =A14+1 -> 46088 | B15: Toilet | C15: 15 | D15: =+'7'!F42 -> 1149.5101 | E15: =+'7'!G42 -> 942.59829 | F15: =1-(E15/D15) -> 0.18 | G15: =+P15/N15 -> 0.89292766 | H15: =+P15/L15 -> 0.89254728 | I15: =+R15/P15 -> 0.82183908 | J15: =+R15/L15 -> 0.73353023 | K15: =+S15/M15 -> 0.86108323 | L15: =+Efficiency1!K34 -> 52.245972 | M15: =M14+L15 -> 375.98688 | N15: =+Efficiency1!C34 -> 52.223716 | O15: =O14+N15 -> 371.6725 | P15: ='7'!I38 -> 46.632 | Q15: =Q14+P15 -> 326.646 | R15: ='7'!I40 -> 38.324 | S15: =S14+R15 -> 323.756 | T15: =+[1]Report1!AZ15 -> 3997.8692 | U15: =T15+U14 -> 24326.515 | V15: =T15/P15 -> 85.732312 | W15: =U15/Q15 -> 74.473636 | X15: =IF(AND(R15>0,T15>0),(T15/(R15*1000))*1000,0) -> 104.31764 | Y15: =IF(AND(S15>0,U15>0),U15/S15,0) -> 75.138423 | Z15: 94.3 | AA15: =Z15+AA14 -> 635.86 | AB15: =Z15/(P15) -> 2.0222165 | AC15: =AA15/(Q15) -> 1.9466334 | AD15: =IF(AND(R15>0,Z15>0),Z15/(R15),0) -> 2.4605991 | AE15: =IF(AND(S15>0,AA15>0),AA15/(S15),0) -> 1.9640099 | AG15: =+AF15+AG14 -> 0 | AH15: =AF15/(P15) -> 0 | AI15: =AG15/(Q15) -> 0 | AJ15: =IF(AND(R15>0,AF15>0),AF15/(R15),0) -> 0 | AK15: =IF(AND(S15>0,AG15>0),AG15/(S15),0) -> 0 | AL15: ='7'!I46 -> 36777.095 | AM15: =AL15+AM14 -> 243906.47 | AN15: =IF(AND(L15>0,AL15>0),(AL15/(P15*1000)*1000),0) -> 788.66646 | AO15: =IF(AND(M15>0,AM15>0),(AM15/(Q15*1000)*1000),0) -> 746.69969 | AP15: =IF(AND(R15>0,AL15>0),(AL15/(R15*1000)*1000),0) -> 959.63612 | AQ15: =IF(AND(S15>0,AM15>0),(AM15/(S15*1000)*1000),0) -> 753.36509 | AR15: =+Listrik!AA14 -> 19486.9 | AS15: =AR15+AS14 -> 163623.92 | AT15: =IF(AND(L15>0,AR15>0),(AR15/(P15*1000)*1000),0) -> 417.88686 | AU15: =IF(AND(M15>0,AS15>0),(AS15/(Q15*1000)*1000),0) -> 500.92125 | AV15: =IF(AND(R15>0,AR15>0),(AR15/(R15*1000)*1000),0) -> 508.47772 | AW15: =IF(AND(S15>0,AS15>0),(AS15/(S15*1000)*1000),0) -> 505.39272 | AX15: 0 | AY15: =AX15+AY14 -> 0 | AZ15: =IF(AND(L15>0,AX15>0),(AX15/(P15*1000)*1000),0) -> 0 | BA15: =IF(AND(M15>0,AY15>0),(AY15/(Q15*1000)*1000),0) -> 0 | BB15: =IF(AND(R15>0,AX15>0),(AX15/(R15*1000)*1000),0) -> 0 | BC15: =IF(AND(S15>0,AY15>0),(AY15/(S15*1000)*1000),0) -> 0 | BE15: =+Efficiency2!K34 -> 46.658556 | BF15: =BF14+BE15 -> 344.60504 | BG15: =+R15/BE15 -> 0.82137133 | BH15: =+S15/BF15 -> 0.93949873
A16: =A15+1 -> 46089 | B16: Toilet | C16: 15 | D16: =+'8'!F42 -> 1148.4375 | E16: =+'8'!G42 -> 941.71875 | F16: =1-(E16/D16) -> 0.18 | G16: =+P16/N16 -> 1.0028944 | H16: =+P16/L16 -> 1.0015318 | I16: =+R16/P16 -> 0.8850667 | J16: =+R16/L16 -> 0.8864224 | K16: =+S16/M16 -> 0.8641747 | L16: =+Efficiency1!K40 -> 52.245972 | M16: =M15+L16 -> 428.23286 | N16: =+Efficiency1!C40 -> 52.174986 | O16: =O15+N16 -> 423.84749 | P16: ='8'!I38 -> 52.326 | Q16: =Q15+P16 -> 378.972 | R16: ='8'!I40 -> 46.312 | S16: =S15+R16 -> 370.068 | T16: =+[1]Report1!AZ16 -> 3559.8694 | U16: =T16+U15 -> 27886.385 | V16: =T16/P16 -> 68.032516 | W16: =U16/Q16 -> 73.584288 | X16: =IF(AND(R16>0,T16>0),(T16/(R16*1000))*1000,0) -> 76.867107 | Y16: =IF(AND(S16>0,U16>0),U16/S16,0) -> 75.354759 | Z16: 99.6 | AA16: =Z16+AA15 -> 735.46 | AB16: =Z16/(P16) -> 1.9034514 | AC16: =AA16/(Q16) -> 1.9406711 | AD16: =IF(AND(R16>0,Z16>0),Z16/(R16),0) -> 2.1506305 | AE16: =IF(AND(S16>0,AA16>0),AA16/(S16),0) -> 1.9873645 | AG16: =+AF16+AG15 -> 0 | AH16: =AF16/(P16) -> 0 | AI16: =AG16/(Q16) -> 0 | AJ16: =IF(AND(R16>0,AF16>0),AF16/(R16),0) -> 0 | AK16: =IF(AND(S16>0,AG16>0),AG16/(S16),0) -> 0 | AL16: ='8'!I46 -> 37494.252 | AM16: =AL16+AM15 -> 281400.72 | AN16: =IF(AND(L16>0,AL16>0),(AL16/(P16*1000)*1000),0) -> 716.55109 | AO16: =IF(AND(M16>0,AM16>0),(AM16/(Q16*1000)*1000),0) -> 742.53697 | AP16: =IF(AND(R16>0,AL16>0),(AL16/(R16*1000)*1000),0) -> 809.60124 | AQ16: =IF(AND(S16>0,AM16>0),(AM16/(S16*1000)*1000),0) -> 760.40274 | AR16: =+Listrik!AA15 -> 26268.044 | AS16: =AR16+AS15 -> 189891.97 | AT16: =IF(AND(L16>0,AR16>0),(AR16/(P16*1000)*1000),0) -> 502.00749 | AU16: =IF(AND(M16>0,AS16>0),(AS16/(Q16*1000)*1000),0) -> 501.07123 | AV16: =IF(AND(R16>0,AR16>0),(AR16/(R16*1000)*1000),0) -> 567.19736 | AW16: =IF(AND(S16>0,AS16>0),(AS16/(S16*1000)*1000),0) -> 513.12723 | AX16: 0 | AY16: =AX16+AY15 -> 0 | AZ16: =IF(AND(L16>0,AX16>0),(AX16/(P16*1000)*1000),0) -> 0 | BA16: =IF(AND(M16>0,AY16>0),(AY16/(Q16*1000)*1000),0) -> 0 | BB16: =IF(AND(R16>0,AX16>0),(AX16/(R16*1000)*1000),0) -> 0 | BC16: =IF(AND(S16>0,AY16>0),(AY16/(S16*1000)*1000),0) -> 0 | BE16: =+Efficiency2!K40 -> 52.245972 | BF16: =BF15+BE16 -> 396.85101 | BG16: =+R16/BE16 -> 0.8864224 | BH16: =+S16/BF16 -> 0.93251116
A17: =A16+1 -> 46090 | B17: Toilet | C17: 15/14,5 | D17: =+'9'!F42 -> 1150 | E17: =+'9'!G42 -> 943 | F17: =1-(E17/D17) -> 0.18 | G17: =+P17/N17 -> 1.034309 | H17: =+P17/L17 -> 1.0036291 | I17: =+R17/P17 -> 1.2008106 | J17: =+R17/L17 -> 1.2051685 | K17: =+S17/M17 -> 0.90333365 | L17: =+SUM(Efficiency1!K44:K45) -> 55.557378 | M17: =M16+L17 -> 483.79023 | N17: =+SUM(Efficiency1!C44:C45) -> 53.909424 | O17: =O16+N17 -> 477.75691 | P17: ='9'!I38 -> 55.759 | Q17: =Q16+P17 -> 434.731 | R17: ='9'!I40 -> 66.956 | S17: =S16+R17 -> 437.024 | T17: =+[1]Report1!AZ17 -> 3851.5604 | U17: =T17+U16 -> 31737.945 | V17: =T17/P17 -> 69.075134 | W17: =U17/Q17 -> 73.00594 | X17: =IF(AND(R17>0,T17>0),(T17/(R17*1000))*1000,0) -> 57.523753 | Y17: =IF(AND(S17>0,U17>0),U17/S17,0) -> 72.622888 | Z17: 96.6 | AA17: =Z17+AA16 -> 832.06 | AB17: =Z17/(P17) -> 1.7324557 | AC17: =AA17/(Q17) -> 1.9139652 | AD17: =IF(AND(R17>0,Z17>0),Z17/(R17),0) -> 1.4427385 | AE17: =IF(AND(S17>0,AA17>0),AA17/(S17),0) -> 1.9039229 | AG17: =+AF17+AG16 -> 0 | AH17: =AF17/(P17) -> 0 | AI17: =AG17/(Q17) -> 0 | AJ17: =IF(AND(R17>0,AF17>0),AF17/(R17),0) -> 0 | AK17: =IF(AND(S17>0,AG17>0),AG17/(S17),0) -> 0 | AL17: ='9'!I46 -> 44055.334 | AM17: =AL17+AM16 -> 325456.05 | AN17: =IF(AND(L17>0,AL17>0),(AL17/(P17*1000)*1000),0) -> 790.10266 | AO17: =IF(AND(M17>0,AM17>0),(AM17/(Q17*1000)*1000),0) -> 748.63779 | AP17: =IF(AND(R17>0,AL17>0),(AL17/(R17*1000)*1000),0) -> 657.97441 | AQ17: =IF(AND(S17>0,AM17>0),(AM17/(S17*1000)*1000),0) -> 744.7098 | AR17: =+Listrik!AA16 -> 23221.706 | AS17: =AR17+AS16 -> 213113.67 | AT17: =IF(AND(L17>0,AR17>0),(AR17/(P17*1000)*1000),0) -> 416.46561 | AU17: =IF(AND(M17>0,AS17>0),(AS17/(Q17*1000)*1000),0) -> 490.21964 | AV17: =IF(AND(R17>0,AR17>0),(AR17/(R17*1000)*1000),0) -> 346.82039 | AW17: =IF(AND(S17>0,AS17>0),(AS17/(S17*1000)*1000),0) -> 487.64753 | AX17: 0 | AY17: =AX17+AY16 -> 0 | AZ17: =IF(AND(L17>0,AX17>0),(AX17/(P17*1000)*1000),0) -> 0 | BA17: =IF(AND(M17>0,AY17>0),(AY17/(Q17*1000)*1000),0) -> 0 | BB17: =IF(AND(R17>0,AX17>0),(AX17/(R17*1000)*1000),0) -> 0 | BC17: =IF(AND(S17>0,AY17>0),(AY17/(S17*1000)*1000),0) -> 0 | BE17: =+SUM(Efficiency2!K44:K45) -> 55.557378 | BF17: =BF16+BE17 -> 452.40839 | BG17: =+R17/BE17 -> 1.2051685 | BH17: =+S17/BF17 -> 0.96599446
A18: =A17+1 -> 46091 | B18: Toilet | C18: 14,5 | D18: =+'10'!F42 -> 1150 | E18: =+'10'!G42 -> 943 | F18: =1-(E18/D18) -> 0.18 | G18: =+P18/N18 -> 1.0553112 | H18: =+P18/L18 -> 1.0198386 | I18: =+R18/P18 -> 0.96837703 | J18: =+R18/L18 -> 0.98758825 | K18: =+S18/M18 -> 0.91207882 | L18: =+Efficiency1!K48 -> 56.030436 | M18: =M17+L18 -> 539.82067 | N18: =+Efficiency1!C48 -> 54.14706 | O18: =O17+N18 -> 531.90397 | P18: ='10'!I38 -> 57.142 | Q18: =Q17+P18 -> 491.873 | R18: ='10'!I40 -> 55.335 | S18: =S17+R18 -> 492.359 | T18: =+[1]Report1!AZ18 -> 3763.2663 | U18: =T18+U17 -> 35501.211 | V18: =T18/P18 -> 65.858148 | W18: =U18/Q18 -> 72.175565 | X18: =IF(AND(R18>0,T18>0),(T18/(R18*1000))*1000,0) -> 68.008788 | Y18: =IF(AND(S18>0,U18>0),U18/S18,0) -> 72.104321 | Z18: 97.9 | AA18: =Z18+AA17 -> 929.96 | AB18: =Z18/(P18) -> 1.7132757 | AC18: =AA18/(Q18) -> 1.8906506 | AD18: =IF(AND(R18>0,Z18>0),Z18/(R18),0) -> 1.7692238 | AE18: =IF(AND(S18>0,AA18>0),AA18/(S18),0) -> 1.8887844 | AG18: =+AF18+AG17 -> 0 | AH18: =AF18/(P18) -> 0 | AI18: =AG18/(Q18) -> 0 | AJ18: =IF(AND(R18>0,AF18>0),AF18/(R18),0) -> 0 | AK18: =IF(AND(S18>0,AG18>0),AG18/(S18),0) -> 0 | AL18: ='10'!I46 -> 41034.571 | AM18: =AL18+AM17 -> 366490.63 | AN18: =IF(AND(L18>0,AL18>0),(AL18/(P18*1000)*1000),0) -> 718.11577 | AO18: =IF(AND(M18>0,AM18>0),(AM18/(Q18*1000)*1000),0) -> 745.09198 | AP18: =IF(AND(R18>0,AL18>0),(AL18/(R18*1000)*1000),0) -> 741.5663 | AQ18: =IF(AND(S18>0,AM18>0),(AM18/(S18*1000)*1000),0) -> 744.35651 | AR18: =+Listrik!AA17 -> 27725.951 | AS18: =AR18+AS17 -> 240839.62 | AT18: =IF(AND(L18>0,AR18>0),(AR18/(P18*1000)*1000),0) -> 485.21142 | AU18: =IF(AND(M18>0,AS18>0),(AS18/(Q18*1000)*1000),0) -> 489.63782 | AV18: =IF(AND(R18>0,AR18>0),(AR18/(R18*1000)*1000),0) -> 501.05631 | AW18: =IF(AND(S18>0,AS18>0),(AS18/(S18*1000)*1000),0) -> 489.15451 | AX18: 0 | AY18: =AX18+AY17 -> 0 | AZ18: =IF(AND(L18>0,AX18>0),(AX18/(P18*1000)*1000),0) -> 0 | BA18: =IF(AND(M18>0,AY18>0),(AY18/(Q18*1000)*1000),0) -> 0 | BB18: =IF(AND(R18>0,AX18>0),(AX18/(R18*1000)*1000),0) -> 0 | BC18: =IF(AND(S18>0,AY18>0),(AY18/(S18*1000)*1000),0) -> 0 | BE18: =+Efficiency2!K48 -> 56.030436 | BF18: =BF17+BE18 -> 508.43883 | BG18: =+R18/BE18 -> 0.98758825 | BH18: =+S18/BF18 -> 0.96837411
A19: =A18+1 -> 46092 | B19: Toilet | C19: 14,5/15 | D19: =+'11'!F42 -> 1157.2153 | E19: =+'11'!G42 -> 930.88333 | F19: =1-(E19/D19) -> 0.19558327 | G19: =+P19/N19 -> 0.97437023 | H19: =+P19/L19 -> 0.95378482 | I19: =+R19/P19 -> 0.91305893 | J19: =+R19/L19 -> 0.87086175 | K19: =+S19/M19 -> 0.9082009 | L19: =+SUM(Efficiency1!K52:K53) -> 56.064008 | M19: =M18+L19 -> 595.88468 | N19: =+SUM(Efficiency1!C52:C53) -> 54.87955 | O19: =O18+N19 -> 586.78352 | P19: ='11'!I38 -> 53.473 | Q19: =Q18+P19 -> 545.346 | R19: ='11'!I40 -> 48.824 | S19: =S18+R19 -> 541.183 | T19: =+[1]Report1!AZ19 -> 3672.0505 | U19: =T19+U18 -> 39173.262 | V19: =T19/P19 -> 68.671114 | W19: =U19/Q19 -> 71.831942 | X19: =IF(AND(R19>0,T19>0),(T19/(R19*1000))*1000,0) -> 75.209948 | Y19: =IF(AND(S19>0,U19>0),U19/S19,0) -> 72.384502 | Z19: 96.3 | AA19: =Z19+AA18 -> 1026.26 | AB19: =Z19/(P19) -> 1.8009089 | AC19: =AA19/(Q19) -> 1.8818512 | AD19: =IF(AND(R19>0,Z19>0),Z19/(R19),0) -> 1.9723906 | AE19: =IF(AND(S19>0,AA19>0),AA19/(S19),0) -> 1.8963271 | AG19: =+AF19+AG18 -> 0 | AH19: =AF19/(P19) -> 0 | AI19: =AG19/(Q19) -> 0 | AJ19: =IF(AND(R19>0,AF19>0),AF19/(R19),0) -> 0 | AK19: =IF(AND(S19>0,AG19>0),AG19/(S19),0) -> 0 | AL19: ='11'!I46 -> 42059.935 | AM19: =AL19+AM18 -> 408550.56 | AN19: =IF(AND(L19>0,AL19>0),(AL19/(P19*1000)*1000),0) -> 786.56397 | AO19: =IF(AND(M19>0,AM19>0),(AM19/(Q19*1000)*1000),0) -> 749.15844 | AP19: =IF(AND(R19>0,AL19>0),(AL19/(R19*1000)*1000),0) -> 861.46025 | AQ19: =IF(AND(S19>0,AM19>0),(AM19/(S19*1000)*1000),0) -> 754.92128 | AR19: =+Listrik!AA18 -> 25138.049 | AS19: =AR19+AS18 -> 265977.67 | AT19: =IF(AND(L19>0,AR19>0),(AR19/(P19*1000)*1000),0) -> 470.10733 | AU19: =IF(AND(M19>0,AS19>0),(AS19/(Q19*1000)*1000),0) -> 487.72279 | AV19: =IF(AND(R19>0,AR19>0),(AR19/(R19*1000)*1000),0) -> 514.87074 | AW19: =IF(AND(S19>0,AS19>0),(AS19/(S19*1000)*1000),0) -> 491.47455 | AX19: 0 | AY19: =AX19+AY18 -> 0 | AZ19: =IF(AND(L19>0,AX19>0),(AX19/(P19*1000)*1000),0) -> 0 | BA19: =IF(AND(M19>0,AY19>0),(AY19/(Q19*1000)*1000),0) -> 0 | BB19: =IF(AND(R19>0,AX19>0),(AX19/(R19*1000)*1000),0) -> 0 | BC19: =IF(AND(S19>0,AY19>0),(AY19/(S19*1000)*1000),0) -> 0 | BE19: =+SUM(Efficiency2!K52:K53) -> 56.064008 | BF19: =BF18+BE19 -> 564.50284 | BG19: =+R19/BE19 -> 0.87086175 | BH19: =+S19/BF19 -> 0.9586896
A20: =A19+1 -> 46093 | B20: Toilet | C20: 15/14 | D20: =+'12'!F42 -> 1187.5 | E20: =+'12'!G42 -> 954.06667 | F20: =1-(E20/D20) -> 0.19657544 | G20: =+P20/N20 -> 0.97927808 | H20: =+P20/L20 -> 0.9541275 | I20: =+R20/P20 -> 1.008939 | J20: =+R20/L20 -> 0.9626564 | K20: =+S20/M20 -> 0.9128016 | L20: =+SUM(Efficiency1!K56:K57) -> 54.989506 | M20: =M19+L20 -> 650.87418 | N20: =+SUM(Efficiency1!C56:C57) -> 53.577223 | O20: =O19+N20 -> 640.36075 | P20: ='12'!I38 -> 52.467 | Q20: =Q19+P20 -> 597.813 | R20: ='12'!I40 -> 52.936 | S20: =S19+R20 -> 594.119 | T20: =+[1]Report1!AZ20 -> 3690.0664 | U20: =T20+U19 -> 42863.328 | V20: =T20/P20 -> 70.331188 | W20: =U20/Q20 -> 71.700228 | X20: =IF(AND(R20>0,T20>0),(T20/(R20*1000))*1000,0) -> 69.708071 | Y20: =IF(AND(S20>0,U20>0),U20/S20,0) -> 72.146032 | Z20: 95.6 | AA20: =Z20+AA19 -> 1121.86 | AB20: =Z20/(P20) -> 1.8220977 | AC20: =AA20/(Q20) -> 1.8766069 | AD20: =IF(AND(R20>0,Z20>0),Z20/(R20),0) -> 1.8059544 | AE20: =IF(AND(S20>0,AA20>0),AA20/(S20),0) -> 1.8882749 | AG20: =+AF20+AG19 -> 0 | AH20: =AF20/(P20) -> 0 | AI20: =AG20/(Q20) -> 0 | AJ20: =IF(AND(R20>0,AF20>0),AF20/(R20),0) -> 0 | AK20: =IF(AND(S20>0,AG20>0),AG20/(S20),0) -> 0 | AL20: ='12'!I46 -> 40299.71 | AM20: =AL20+AM19 -> 448850.27 | AN20: =IF(AND(L20>0,AL20>0),(AL20/(P20*1000)*1000),0) -> 768.09633 | AO20: =IF(AND(M20>0,AM20>0),(AM20/(Q20*1000)*1000),0) -> 750.82053 | AP20: =IF(AND(R20>0,AL20>0),(AL20/(R20*1000)*1000),0) -> 761.29119 | AQ20: =IF(AND(S20>0,AM20>0),(AM20/(S20*1000)*1000),0) -> 755.48883 | AR20: =+Listrik!AA19 -> 23180.1 | AS20: =AR20+AS19 -> 289157.77 | AT20: =IF(AND(L20>0,AR20>0),(AR20/(P20*1000)*1000),0) -> 441.80342 | AU20: =IF(AND(M20>0,AS20>0),(AS20/(Q20*1000)*1000),0) -> 483.69268 | AV20: =IF(AND(R20>0,AR20>0),(AR20/(R20*1000)*1000),0) -> 437.88915 | AW20: =IF(AND(S20>0,AS20>0),(AS20/(S20*1000)*1000),0) -> 486.7001 | AX20: 0 | AY20: =AX20+AY19 -> 0 | AZ20: =IF(AND(L20>0,AX20>0),(AX20/(P20*1000)*1000),0) -> 0 | BA20: =IF(AND(M20>0,AY20>0),(AY20/(Q20*1000)*1000),0) -> 0 | BB20: =IF(AND(R20>0,AX20>0),(AX20/(R20*1000)*1000),0) -> 0 | BC20: =IF(AND(S20>0,AY20>0),(AY20/(S20*1000)*1000),0) -> 0 | BE20: =+SUM(Efficiency2!K56:K57) -> 54.989506 | BF20: =BF19+BE20 -> 619.49234 | BG20: =+R20/BE20 -> 0.9626564 | BH20: =+S20/BF20 -> 0.95904172
A21: =A20+1 -> 46094 | B21: Toilet | C21: 14/13,5 | D21: =+'13'!F42 -> 1225 | E21: =+'13'!G42 -> 1003.0708 | F21: =1-(E21/D21) -> 0.18116667 | G21: =+P21/N21 -> 0.98757808 | H21: =+P21/L21 -> 0.96172329 | I21: =+R21/P21 -> 0.948401 | J21: =+R21/L21 -> 0.91209932 | K21: =+S21/M21 -> 0.91274687 | L21: =+SUM(Efficiency1!K60:K61) -> 55.013745 | M21: =M20+L21 -> 705.88793 | N21: =+SUM(Efficiency1!C60:C61) -> 53.573486 | O21: =O20+N21 -> 693.93423 | P21: ='13'!I38 -> 52.908 | Q21: =Q20+P21 -> 650.721 | R21: ='13'!I40 -> 50.178 | S21: =S20+R21 -> 644.297 | T21: =+[1]Report1!AZ21 -> 3466.1579 | U21: =T21+U20 -> 46329.486 | V21: =T21/P21 -> 65.512926 | W21: =U21/Q21 -> 71.197159 | X21: =IF(AND(R21>0,T21>0),(T21/(R21*1000))*1000,0) -> 69.077243 | Y21: =IF(AND(S21>0,U21>0),U21/S21,0) -> 71.907034 | Z21: 95.9 | AA21: =Z21+AA20 -> 1217.76 | AB21: =Z21/(P21) -> 1.8125803 | AC21: =AA21/(Q21) -> 1.8714011 | AD21: =IF(AND(R21>0,Z21>0),Z21/(R21),0) -> 1.9111961 | AE21: =IF(AND(S21>0,AA21>0),AA21/(S21),0) -> 1.89006 | AG21: =+AF21+AG20 -> 0 | AH21: =AF21/(P21) -> 0 | AI21: =AG21/(Q21) -> 0 | AJ21: =IF(AND(R21>0,AF21>0),AF21/(R21),0) -> 0 | AK21: =IF(AND(S21>0,AG21>0),AG21/(S21),0) -> 0 | AL21: ='13'!I46 -> 40397.662 | AM21: =AL21+AM20 -> 489247.93 | AN21: =IF(AND(L21>0,AL21>0),(AL21/(P21*1000)*1000),0) -> 763.54544 | AO21: =IF(AND(M21>0,AM21>0),(AM21/(Q21*1000)*1000),0) -> 751.85515 | AP21: =IF(AND(R21>0,AL21>0),(AL21/(R21*1000)*1000),0) -> 805.08713 | AQ21: =IF(AND(S21>0,AM21>0),(AM21/(S21*1000)*1000),0) -> 759.35156 | AR21: =+Listrik!AA20 -> 24190.451 | AS21: =AR21+AS20 -> 313348.23 | AT21: =IF(AND(L21>0,AR21>0),(AR21/(P21*1000)*1000),0) -> 457.21726 | AU21: =IF(AND(M21>0,AS21>0),(AS21/(Q21*1000)*1000),0) -> 481.54005 | AV21: =IF(AND(R21>0,AR21>0),(AR21/(R21*1000)*1000),0) -> 482.09277 | AW21: =IF(AND(S21>0,AS21>0),(AS21/(S21*1000)*1000),0) -> 486.34128 | AX21: 0 | AY21: =AX21+AY20 -> 0 | AZ21: =IF(AND(L21>0,AX21>0),(AX21/(P21*1000)*1000),0) -> 0 | BA21: =IF(AND(M21>0,AY21>0),(AY21/(Q21*1000)*1000),0) -> 0 | BB21: =IF(AND(R21>0,AX21>0),(AX21/(R21*1000)*1000),0) -> 0 | BC21: =IF(AND(S21>0,AY21>0),(AY21/(S21*1000)*1000),0) -> 0 | BE21: =+SUM(Efficiency2!K60:K61) -> 55.013745 | BF21: =BF20+BE21 -> 674.50609 | BG21: =+R21/BE21 -> 0.91209932 | BH21: =+S21/BF21 -> 0.95521302
A22: =A21+1 -> 46095 | B22: Toilet | C22: 13,5 | D22: =+'14'!F42 -> 1225 | E22: =+'14'!G42 -> 1029 | F22: =1-(E22/D22) -> 0.16 | G22: =+P22/N22 -> 1.0038598 | H22: =+P22/L22 -> 0.98378259 | I22: =+R22/P22 -> 0.92890722 | J22: =+R22/L22 -> 0.91384275 | K22: =+S22/M22 -> 0.91282569 | L22: =+Efficiency1!K64 -> 54.70416 | M22: =M21+L22 -> 760.59209 | N22: =+Efficiency1!C64 -> 53.610077 | O22: =O21+N22 -> 747.54431 | P22: ='14'!I38 -> 53.817 | Q22: =Q21+P22 -> 704.538 | R22: ='14'!I40 -> 49.991 | S22: =S21+R22 -> 694.288 | T22: =+[1]Report1!AZ22 -> 3499.8967 | U22: =T22+U21 -> 49829.383 | V22: =T22/P22 -> 65.033293 | W22: =U22/Q22 -> 70.726324 | X22: =IF(AND(R22>0,T22>0),(T22/(R22*1000))*1000,0) -> 70.010537 | Y22: =IF(AND(S22>0,U22>0),U22/S22,0) -> 71.77048 | Z22: 95.6 | AA22: =Z22+AA21 -> 1313.36 | AB22: =Z22/(P22) -> 1.7763904 | AC22: =AA22/(Q22) -> 1.8641436 | AD22: =IF(AND(R22>0,Z22>0),Z22/(R22),0) -> 1.9123442 | AE22: =IF(AND(S22>0,AA22>0),AA22/(S22),0) -> 1.8916646 | AG22: =+AF22+AG21 -> 0 | AH22: =AF22/(P22) -> 0 | AI22: =AG22/(Q22) -> 0 | AJ22: =IF(AND(R22>0,AF22>0),AF22/(R22),0) -> 0 | AK22: =IF(AND(S22>0,AG22>0),AG22/(S22),0) -> 0 | AL22: ='14'!I46 -> 43210.253 | AM22: =AL22+AM21 -> 532458.19 | AN22: =IF(AND(L22>0,AL22>0),(AL22/(P22*1000)*1000),0) -> 802.91084 | AO22: =IF(AND(M22>0,AM22>0),(AM22/(Q22*1000)*1000),0) -> 755.7551 | AP22: =IF(AND(R22>0,AL22>0),(AL22/(R22*1000)*1000),0) -> 864.36064 | AQ22: =IF(AND(S22>0,AM22>0),(AM22/(S22*1000)*1000),0) -> 766.91256 | AR22: =+Listrik!AA21 -> 25840 | AS22: =AR22+AS21 -> 339188.23 | AT22: =IF(AND(L22>0,AR22>0),(AR22/(P22*1000)*1000),0) -> 480.14568 | AU22: =IF(AND(M22>0,AS22>0),(AS22/(Q22*1000)*1000),0) -> 481.43354 | AV22: =IF(AND(R22>0,AR22>0),(AR22/(R22*1000)*1000),0) -> 516.89304 | AW22: =IF(AND(S22>0,AS22>0),(AS22/(S22*1000)*1000),0) -> 488.5411 | AX22: 0 | AY22: =AX22+AY21 -> 0 | AZ22: =IF(AND(L22>0,AX22>0),(AX22/(P22*1000)*1000),0) -> 0 | BA22: =IF(AND(M22>0,AY22>0),(AY22/(Q22*1000)*1000),0) -> 0 | BB22: =IF(AND(R22>0,AX22>0),(AX22/(R22*1000)*1000),0) -> 0 | BC22: =IF(AND(S22>0,AY22>0),(AY22/(S22*1000)*1000),0) -> 0 | BE22: =+Efficiency2!K64 -> 54.70416 | BF22: =BF21+BE22 -> 729.21025 | BG22: =+R22/BE22 -> 0.91384275 | BH22: =+S22/BF22 -> 0.95210949
A23: =A22+1 -> 46096 | B23: Toilet | C23: 13,5 | D23: =+'15'!F42 -> 1225 | E23: =+'15'!G42 -> 1029 | F23: =1-(E23/D23) -> 0.16 | G23: =+P23/N23 -> 0.95049534 | H23: =+P23/L23 -> 0.93148543 | I23: =+R23/P23 -> 0.98879754 | J23: =+R23/L23 -> 0.9210505 | K23: =+S23/M23 -> 0.91336777 | L23: =+Efficiency1!K68 -> 53.665896 | M23: =M22+L23 -> 814.25799 | N23: =+Efficiency1!C68 -> 52.592578 | O23: =O22+N23 -> 800.13689 | P23: ='15'!I38 -> 49.989 | Q23: =Q22+P23 -> 754.527 | R23: ='15'!I40 -> 49.429 | S23: =S22+R23 -> 743.717 | T23: =+[1]Report1!AZ23 -> 3378.7757 | U23: =T23+U22 -> 53208.159 | V23: =T23/P23 -> 67.590385 | W23: =U23/Q23 -> 70.518562 | X23: =IF(AND(R23>0,T23>0),(T23/(R23*1000))*1000,0) -> 68.356142 | Y23: =IF(AND(S23>0,U23>0),U23/S23,0) -> 71.543556 | Z23: 96.5 | AA23: =Z23+AA22 -> 1409.86 | AB23: =Z23/(P23) -> 1.9304247 | AC23: =AA23/(Q23) -> 1.8685349 | AD23: =IF(AND(R23>0,Z23>0),Z23/(R23),0) -> 1.9522952 | AE23: =IF(AND(S23>0,AA23>0),AA23/(S23),0) -> 1.8956942 | AG23: =+AF23+AG22 -> 0 | AH23: =AF23/(P23) -> 0 | AI23: =AG23/(Q23) -> 0 | AJ23: =IF(AND(R23>0,AF23>0),AF23/(R23),0) -> 0 | AK23: =IF(AND(S23>0,AG23>0),AG23/(S23),0) -> 0 | AL23: ='15'!I46 -> 40973.65 | AM23: =AL23+AM22 -> 573431.84 | AN23: =IF(AND(L23>0,AL23>0),(AL23/(P23*1000)*1000),0) -> 819.65333 | AO23: =IF(AND(M23>0,AM23>0),(AM23/(Q23*1000)*1000),0) -> 759.98849 | AP23: =IF(AND(R23>0,AL23>0),(AL23/(R23*1000)*1000),0) -> 828.93949 | AQ23: =IF(AND(S23>0,AM23>0),(AM23/(S23*1000)*1000),0) -> 771.035 | AR23: =+Listrik!AA22 -> 23723.6 | AS23: =AR23+AS22 -> 362911.83 | AT23: =IF(AND(L23>0,AR23>0),(AR23/(P23*1000)*1000),0) -> 474.57641 | AU23: =IF(AND(M23>0,AS23>0),(AS23/(Q23*1000)*1000),0) -> 480.97924 | AV23: =IF(AND(R23>0,AR23>0),(AR23/(R23*1000)*1000),0) -> 479.95306 | AW23: =IF(AND(S23>0,AS23>0),(AS23/(S23*1000)*1000),0) -> 487.97032 | AX23: 0 | AY23: =AX23+AY22 -> 0 | AZ23: =IF(AND(L23>0,AX23>0),(AX23/(P23*1000)*1000),0) -> 0 | BA23: =IF(AND(M23>0,AY23>0),(AY23/(Q23*1000)*1000),0) -> 0 | BB23: =IF(AND(R23>0,AX23>0),(AX23/(R23*1000)*1000),0) -> 0 | BC23: =IF(AND(S23>0,AY23>0),(AY23/(S23*1000)*1000),0) -> 0 | BE23: =+Efficiency2!K68 -> 53.665896 | BF23: =BF22+BE23 -> 782.87614 | BG23: =+R23/BE23 -> 0.9210505 | BH23: =+S23/BF23 -> 0.94998041
A24: =A23+1 -> 46097 | B24: Toilet | C24: 13,5 | D24: =+'16'!F42 -> 1225 | E24: =+'16'!G42 -> 1020.8333 | F24: =1-(E24/D24) -> 0.16666667 | G24: =+P24/N24 -> 0.9497128 | H24: =+P24/L24 -> 0.92333188 | I24: =+R24/P24 -> 1.0120598 | J24: =+R24/L24 -> 0.93446708 | K24: =+S24/M24 -> 0.91467939 | L24: =+Efficiency1!K72 -> 53.973009 | M24: =M23+L24 -> 868.23099 | N24: =+Efficiency1!C72 -> 52.473759 | O24: =O23+N24 -> 852.61065 | P24: ='16'!I38 -> 49.835 | Q24: =Q23+P24 -> 804.362 | R24: ='16'!I40 -> 50.436 | S24: =S23+R24 -> 794.153 | T24: =+[1]Report1!AZ24 -> 3015.5204 | U24: =T24+U23 -> 56223.679 | V24: =T24/P24 -> 60.510092 | W24: =U24/Q24 -> 69.898478 | X24: =IF(AND(R24>0,T24>0),(T24/(R24*1000))*1000,0) -> 59.789048 | Y24: =IF(AND(S24>0,U24>0),U24/S24,0) -> 70.797037 | Z24: 95.6 | AA24: =Z24+AA23 -> 1505.46 | AB24: =Z24/(P24) -> 1.9183305 | AC24: =AA24/(Q24) -> 1.87162 | AD24: =IF(AND(R24>0,Z24>0),Z24/(R24),0) -> 1.8954715 | AE24: =IF(AND(S24>0,AA24>0),AA24/(S24),0) -> 1.8956801 | AG24: =+AF24+AG23 -> 0 | AH24: =AF24/(P24) -> 0 | AI24: =AG24/(Q24) -> 0 | AJ24: =IF(AND(R24>0,AF24>0),AF24/(R24),0) -> 0 | AK24: =IF(AND(S24>0,AG24>0),AG24/(S24),0) -> 0 | AL24: ='16'!I46 -> 39730.313 | AM24: =AL24+AM23 -> 613162.15 | AN24: =IF(AND(L24>0,AL24>0),(AL24/(P24*1000)*1000),0) -> 797.23715 | AO24: =IF(AND(M24>0,AM24>0),(AM24/(Q24*1000)*1000),0) -> 762.29627 | AP24: =IF(AND(R24>0,AL24>0),(AL24/(R24*1000)*1000),0) -> 787.7372 | AQ24: =IF(AND(S24>0,AM24>0),(AM24/(S24*1000)*1000),0) -> 772.09574 | AR24: =+Listrik!AA23 -> 20391 | AS24: =AR24+AS23 -> 383302.83 | AT24: =IF(AND(L24>0,AR24>0),(AR24/(P24*1000)*1000),0) -> 409.17026 | AU24: =IF(AND(M24>0,AS24>0),(AS24/(Q24*1000)*1000),0) -> 476.53025 | AV24: =IF(AND(R24>0,AR24>0),(AR24/(R24*1000)*1000),0) -> 404.29455 | AW24: =IF(AND(S24>0,AS24>0),(AS24/(S24*1000)*1000),0) -> 482.65614 | AX24: 0 | AY24: =AX24+AY23 -> 0 | AZ24: =IF(AND(L24>0,AX24>0),(AX24/(P24*1000)*1000),0) -> 0 | BA24: =IF(AND(M24>0,AY24>0),(AY24/(Q24*1000)*1000),0) -> 0 | BB24: =IF(AND(R24>0,AX24>0),(AX24/(R24*1000)*1000),0) -> 0 | BC24: =IF(AND(S24>0,AY24>0),(AY24/(S24*1000)*1000),0) -> 0 | BE24: =+Efficiency2!K72 -> 53.973009 | BF24: =BF23+BE24 -> 836.84915 | BG24: =+R24/BE24 -> 0.93446708 | BH24: =+S24/BF24 -> 0.94897987
A25: =A24+1 -> 46098 | B25: Toilet | C25: 13,5/15 | D25: =+'17'!F42 -> 1192.9167 | E25: =+'17'!G42 -> 946.23594 | F25: =1-(E25/D25) -> 0.2067879 | G25: =+P25/N25 -> 0.96467366 | H25: =+P25/L25 -> 0.93319399 | I25: =+R25/P25 -> 1.0521031 | J25: =+R25/L25 -> 0.9818163 | K25: =+S25/M25 -> 0.91854475 | L25: =+SUM(Efficiency1!K76:K77) -> 53.04149 | M25: =M24+L25 -> 921.27248 | N25: =+SUM(Efficiency1!C76:C77) -> 51.310616 | O25: =O24+N25 -> 903.92126 | P25: ='17'!I38 -> 49.498 | Q25: =Q24+P25 -> 853.86 | R25: ='17'!I40 -> 52.077 | S25: =S24+R25 -> 846.23 | T25: =+[1]Report1!AZ25 -> 4765.5036 | U25: =T25+U24 -> 60989.183 | V25: =T25/P25 -> 96.276689 | W25: =U25/Q25 -> 71.427614 | X25: =IF(AND(R25>0,T25>0),(T25/(R25*1000))*1000,0) -> 91.508796 | Y25: =IF(AND(S25>0,U25>0),U25/S25,0) -> 72.071639 | Z25: 94.7 | AA25: =Z25+AA24 -> 1600.16 | AB25: =Z25/(P25) -> 1.9132086 | AC25: =AA25/(Q25) -> 1.8740309 | AD25: =IF(AND(R25>0,Z25>0),Z25/(R25),0) -> 1.8184611 | AE25: =IF(AND(S25>0,AA25>0),AA25/(S25),0) -> 1.890928 | AG25: =+AF25+AG24 -> 0 | AH25: =AF25/(P25) -> 0 | AI25: =AG25/(Q25) -> 0 | AJ25: =IF(AND(R25>0,AF25>0),AF25/(R25),0) -> 0 | AK25: =IF(AND(S25>0,AG25>0),AG25/(S25),0) -> 0 | AL25: ='17'!I46 -> 42800.329 | AM25: =AL25+AM24 -> 655962.48 | AN25: =IF(AND(L25>0,AL25>0),(AL25/(P25*1000)*1000),0) -> 864.68805 | AO25: =IF(AND(M25>0,AM25>0),(AM25/(Q25*1000)*1000),0) -> 768.23189 | AP25: =IF(AND(R25>0,AL25>0),(AL25/(R25*1000)*1000),0) -> 821.86626 | AQ25: =IF(AND(S25>0,AM25>0),(AM25/(S25*1000)*1000),0) -> 775.15862 | AR25: =+Listrik!AA24 -> 21455.651 | AS25: =AR25+AS24 -> 404758.48 | AT25: =IF(AND(L25>0,AR25>0),(AR25/(P25*1000)*1000),0) -> 433.46501 | AU25: =IF(AND(M25>0,AS25>0),(AS25/(Q25*1000)*1000),0) -> 474.03377 | AV25: =IF(AND(R25>0,AR25>0),(AR25/(R25*1000)*1000),0) -> 411.9986 | AW25: =IF(AND(S25>0,AS25>0),(AS25/(S25*1000)*1000),0) -> 478.30788 | AX25: 0 | AY25: =AX25+AY24 -> 0 | AZ25: =IF(AND(L25>0,AX25>0),(AX25/(P25*1000)*1000),0) -> 0 | BA25: =IF(AND(M25>0,AY25>0),(AY25/(Q25*1000)*1000),0) -> 0 | BB25: =IF(AND(R25>0,AX25>0),(AX25/(R25*1000)*1000),0) -> 0 | BC25: =IF(AND(S25>0,AY25>0),(AY25/(S25*1000)*1000),0) -> 0 | BE25: =+SUM(Efficiency2!K76:K77) -> 53.04149 | BF25: =BF24+BE25 -> 889.89064 | BG25: =+R25/BE25 -> 0.9818163 | BH25: =+S25/BF25 -> 0.95093707
A26: =A25+1 -> 46099 | B26: Toilet /Towel | C26: 15/22 | D26: =+'18'!F42 -> 900 | E26: =+'18'!G42 -> 745.675 | F26: =1-(E26/D26) -> 0.17147222 | G26: =+P26/N26 -> 0.98228918 | H26: =+P26/L26 -> 0.97817569 | I26: =+R26/P26 -> 1.0440177 | J26: =+R26/L26 -> 1.0212328 | K26: =+S26/M26 -> 0.92463517 | L26: =+SUM(Efficiency1!K80:K81) -> 58.08568 | M26: =M25+L26 -> 979.35816 | N26: =+SUM(Efficiency1!C80:C81) -> 57.842437 | O26: =O25+N26 -> 961.7637 | P26: ='18'!I38 -> 56.818 | Q26: =Q25+P26 -> 910.678 | R26: ='18'!I40 -> 59.319 | S26: =S25+R26 -> 905.549 | T26: =+[1]Report1!AZ26 -> 3933.9585 | U26: =T26+U25 -> 64923.141 | V26: =T26/P26 -> 69.237891 | W26: =U26/Q26 -> 71.290996 | X26: =IF(AND(R26>0,T26>0),(T26/(R26*1000))*1000,0) -> 66.318692 | Y26: =IF(AND(S26>0,U26>0),U26/S26,0) -> 71.694785 | Z26: 98.9 | AA26: =Z26+AA25 -> 1699.06 | AB26: =Z26/(P26) -> 1.7406456 | AC26: =AA26/(Q26) -> 1.8657088 | AD26: =IF(AND(R26>0,Z26>0),Z26/(R26),0) -> 1.6672567 | AE26: =IF(AND(S26>0,AA26>0),AA26/(S26),0) -> 1.8762762 | AG26: =+AF26+AG25 -> 0 | AH26: =AF26/(P26) -> 0 | AI26: =AG26/(Q26) -> 0 | AJ26: =IF(AND(R26>0,AF26>0),AF26/(R26),0) -> 0 | AK26: =IF(AND(S26>0,AG26>0),AG26/(S26),0) -> 0 | AL26: ='18'!I46 -> 37462.56 | AM26: =AL26+AM25 -> 693425.04 | AN26: =IF(AND(L26>0,AL26>0),(AL26/(P26*1000)*1000),0) -> 659.34317 | AO26: =IF(AND(M26>0,AM26>0),(AM26/(Q26*1000)*1000),0) -> 761.43822 | AP26: =IF(AND(R26>0,AL26>0),(AL26/(R26*1000)*1000),0) -> 631.54402 | AQ26: =IF(AND(S26>0,AM26>0),(AM26/(S26*1000)*1000),0) -> 765.75098 | AR26: =+Listrik!AA25 -> 22982.946 | AS26: =AR26+AS25 -> 427741.42 | AT26: =IF(AND(L26>0,AR26>0),(AR26/(P26*1000)*1000),0) -> 404.50114 | AU26: =IF(AND(M26>0,AS26>0),(AS26/(Q26*1000)*1000),0) -> 469.69557 | AV26: =IF(AND(R26>0,AR26>0),(AR26/(R26*1000)*1000),0) -> 387.44662 | AW26: =IF(AND(S26>0,AS26>0),(AS26/(S26*1000)*1000),0) -> 472.35591 | AX26: 0 | AY26: =AX26+AY25 -> 0 | AZ26: =IF(AND(L26>0,AX26>0),(AX26/(P26*1000)*1000),0) -> 0 | BA26: =IF(AND(M26>0,AY26>0),(AY26/(Q26*1000)*1000),0) -> 0 | BB26: =IF(AND(R26>0,AX26>0),(AX26/(R26*1000)*1000),0) -> 0 | BC26: =IF(AND(S26>0,AY26>0),(AY26/(S26*1000)*1000),0) -> 0 | BE26: =+SUM(Efficiency2!K80:K81) -> 58.08568 | BF26: =BF25+BE26 -> 947.97632 | BG26: =+R26/BE26 -> 1.0212328 | BH26: =+S26/BF26 -> 0.95524432
A27: =A26+1 -> 46100 | B27: Towel | C27: 22 | D27: =+'19'!F42 -> 860 | E27: =+'19'!G42 -> 662.2 | F27: =1-(E27/D27) -> 0.23 | G27: =+P27/N27 -> 1.0281033 | H27: =+P27/L27 -> 1.0281033 | I27: =+R27/P27 -> 0.95829268 | J27: =+R27/L27 -> 0.98522387 | K27: =+S27/M27 -> 0.92806772 | L27: =+Efficiency1!K84 -> 58.816074 | M27: =M26+L27 -> 1038.1742 | N27: =+Efficiency1!C84 -> 58.816074 | O27: =O26+N27 -> 1020.5798 | P27: ='19'!I38 -> 60.469 | Q27: =Q26+P27 -> 971.147 | R27: ='19'!I40 -> 57.947 | S27: =S26+R27 -> 963.496 | T27: =+[1]Report1!AZ27 -> 3752.4743 | U27: =T27+U26 -> 68675.616 | V27: =T27/P27 -> 62.056167 | W27: =U27/Q27 -> 70.715984 | X27: =IF(AND(R27>0,T27>0),(T27/(R27*1000))*1000,0) -> 64.757008 | Y27: =IF(AND(S27>0,U27>0),U27/S27,0) -> 71.277531 | Z27: 100.1 | AA27: =Z27+AA26 -> 1799.16 | AB27: =Z27/(P27) -> 1.6553937 | AC27: =AA27/(Q27) -> 1.8526135 | AD27: =IF(AND(R27>0,Z27>0),Z27/(R27),0) -> 1.7274406 | AE27: =IF(AND(S27>0,AA27>0),AA27/(S27),0) -> 1.8673248 | AG27: =+AF27+AG26 -> 0 | AH27: =AF27/(P27) -> 0 | AI27: =AG27/(Q27) -> 0 | AJ27: =IF(AND(R27>0,AF27>0),AF27/(R27),0) -> 0 | AK27: =IF(AND(S27>0,AG27>0),AG27/(S27),0) -> 0 | AL27: ='19'!I46 -> 35820.32 | AM27: =AL27+AM26 -> 729245.36 | AN27: =IF(AND(L27>0,AL27>0),(AL27/(P27*1000)*1000),0) -> 592.37494 | AO27: =IF(AND(M27>0,AM27>0),(AM27/(Q27*1000)*1000),0) -> 750.91141 | AP27: =IF(AND(R27>0,AL27>0),(AL27/(R27*1000)*1000),0) -> 618.15659 | AQ27: =IF(AND(S27>0,AM27>0),(AM27/(S27*1000)*1000),0) -> 756.8743 | AR27: =+Listrik!AA26 -> 28270.912 | AS27: =AR27+AS26 -> 456012.33 | AT27: =IF(AND(L27>0,AR27>0),(AR27/(P27*1000)*1000),0) -> 467.52736 | AU27: =IF(AND(M27>0,AS27>0),(AS27/(Q27*1000)*1000),0) -> 469.56056 | AV27: =IF(AND(R27>0,AR27>0),(AR27/(R27*1000)*1000),0) -> 487.87533 | AW27: =IF(AND(S27>0,AS27>0),(AS27/(S27*1000)*1000),0) -> 473.28929 | AX27: 0 | AY27: =AX27+AY26 -> 0 | AZ27: =IF(AND(L27>0,AX27>0),(AX27/(P27*1000)*1000),0) -> 0 | BA27: =IF(AND(M27>0,AY27>0),(AY27/(Q27*1000)*1000),0) -> 0 | BB27: =IF(AND(R27>0,AX27>0),(AX27/(R27*1000)*1000),0) -> 0 | BC27: =IF(AND(S27>0,AY27>0),(AY27/(S27*1000)*1000),0) -> 0 | BE27: =+Efficiency2!K84 -> 58.816074 | BF27: =BF26+BE27 -> 1006.7924 | BG27: =+R27/BE27 -> 0.98522387 | BH27: =+S27/BF27 -> 0.95699571
A28: =A27+1 -> 46101 | B28: Towel | C28: 22 | D28: =+'20'!F42 -> 860 | E28: =+'20'!G42 -> 722.4 | F28: =1-(E28/D28) -> 0.16 | G28: =+P28/N28 -> 0.9641922 | H28: =+P28/L28 -> 0.9641922 | I28: =+R28/P28 -> 0.99107741 | J28: =+R28/L28 -> 0.95558911 | K28: =+S28/M28 -> 0.9295433 | L28: =+Efficiency1!K88 -> 58.816074 | M28: =M27+L28 -> 1096.9903 | N28: =+Efficiency1!C88 -> 58.816074 | O28: =O27+N28 -> 1079.3958 | P28: ='20'!I38 -> 56.71 | Q28: =Q27+P28 -> 1027.857 | R28: ='20'!I40 -> 56.204 | S28: =S27+R28 -> 1019.7 | T28: =+[1]Report1!AZ28 -> 3950.1688 | U28: =T28+U27 -> 72625.784 | V28: =T28/P28 -> 69.655595 | W28: =U28/Q28 -> 70.657479 | X28: =IF(AND(R28>0,T28>0),(T28/(R28*1000))*1000,0) -> 70.282699 | Y28: =IF(AND(S28>0,U28>0),U28/S28,0) -> 71.222697 | Z28: 100.3 | AA28: =Z28+AA27 -> 1899.46 | AB28: =Z28/(P28) -> 1.7686475 | AC28: =AA28/(Q28) -> 1.8479808 | AD28: =IF(AND(R28>0,Z28>0),Z28/(R28),0) -> 1.7845705 | AE28: =IF(AND(S28>0,AA28>0),AA28/(S28),0) -> 1.8627636 | AG28: =+AF28+AG27 -> 0 | AH28: =AF28/(P28) -> 0 | AI28: =AG28/(Q28) -> 0 | AJ28: =IF(AND(R28>0,AF28>0),AF28/(R28),0) -> 0 | AK28: =IF(AND(S28>0,AG28>0),AG28/(S28),0) -> 0 | AL28: ='20'!I46 -> 38239.96 | AM28: =AL28+AM27 -> 767485.32 | AN28: =IF(AND(L28>0,AL28>0),(AL28/(P28*1000)*1000),0) -> 674.30718 | AO28: =IF(AND(M28>0,AM28>0),(AM28/(Q28*1000)*1000),0) -> 746.68492 | AP28: =IF(AND(R28>0,AL28>0),(AL28/(R28*1000)*1000),0) -> 680.37791 | AQ28: =IF(AND(S28>0,AM28>0),(AM28/(S28*1000)*1000),0) -> 752.65796 | AR28: =+Listrik!AA27 -> 27003.445 | AS28: =AR28+AS27 -> 483015.78 | AT28: =IF(AND(L28>0,AR28>0),(AR28/(P28*1000)*1000),0) -> 476.16725 | AU28: =IF(AND(M28>0,AS28>0),(AS28/(Q28*1000)*1000),0) -> 469.92508 | AV28: =IF(AND(R28>0,AR28>0),(AR28/(R28*1000)*1000),0) -> 480.45415 | AW28: =IF(AND(S28>0,AS28>0),(AS28/(S28*1000)*1000),0) -> 473.6842 | AX28: 0 | AY28: =AX28+AY27 -> 0 | AZ28: =IF(AND(L28>0,AX28>0),(AX28/(P28*1000)*1000),0) -> 0 | BA28: =IF(AND(M28>0,AY28>0),(AY28/(Q28*1000)*1000),0) -> 0 | BB28: =IF(AND(R28>0,AX28>0),(AX28/(R28*1000)*1000),0) -> 0 | BC28: =IF(AND(S28>0,AY28>0),(AY28/(S28*1000)*1000),0) -> 0 | BE28: =+Efficiency2!K88 -> 58.816074 | BF28: =BF27+BE28 -> 1065.6085 | BG28: =+R28/BE28 -> 0.95558911 | BH28: =+S28/BF28 -> 0.95691807
A29: =A28+1 -> 46102 | B29: Towel | C29: 22 | D29: =+'21'!F42 -> 860 | E29: =+'21'!G42 -> 722.4 | F29: =1-(E29/D29) -> 0.16 | G29: =+P29/N29 -> 1.0237848 | H29: =+P29/L29 -> 1.0237848 | I29: =+R29/P29 -> 0.96178693 | J29: =+R29/L29 -> 0.98466279 | K29: =+S29/M29 -> 0.9323482 | L29: =+Efficiency1!K92 -> 58.816074 | M29: =M28+L29 -> 1155.8064 | N29: =+Efficiency1!C92 -> 58.816074 | O29: =O28+N29 -> 1138.2119 | P29: ='21'!I38 -> 60.215 | Q29: =Q28+P29 -> 1088.072 | R29: ='21'!I40 -> 57.914 | S29: =S28+R29 -> 1077.614 | T29: =+[1]Report1!AZ29 -> 4009.242 | U29: =T29+U28 -> 76635.026 | V29: =T29/P29 -> 66.582114 | W29: =U29/Q29 -> 70.431944 | X29: =IF(AND(R29>0,T29>0),(T29/(R29*1000))*1000,0) -> 69.22751 | Y29: =IF(AND(S29>0,U29>0),U29/S29,0) -> 71.11547 | Z29: 98.7 | AA29: =Z29+AA28 -> 1998.16 | AB29: =Z29/(P29) -> 1.6391265 | AC29: =AA29/(Q29) -> 1.8364226 | AD29: =IF(AND(R29>0,Z29>0),Z29/(R29),0) -> 1.7042511 | AE29: =IF(AND(S29>0,AA29>0),AA29/(S29),0) -> 1.8542447 | AG29: =+AF29+AG28 -> 0 | AH29: =AF29/(P29) -> 0 | AI29: =AG29/(Q29) -> 0 | AJ29: =IF(AND(R29>0,AF29>0),AF29/(R29),0) -> 0 | AK29: =IF(AND(S29>0,AG29>0),AG29/(S29),0) -> 0 | AL29: ='21'!I46 -> 35523.08 | AM29: =AL29+AM28 -> 803008.4 | AN29: =IF(AND(L29>0,AL29>0),(AL29/(P29*1000)*1000),0) -> 589.93739 | AO29: =IF(AND(M29>0,AM29>0),(AM29/(Q29*1000)*1000),0) -> 738.01035 | AP29: =IF(AND(R29>0,AL29>0),(AL29/(R29*1000)*1000),0) -> 613.37639 | AQ29: =IF(AND(S29>0,AM29>0),(AM29/(S29*1000)*1000),0) -> 745.17257 | AR29: =+Listrik!AA28 -> 29083.555 | AS29: =AR29+AS28 -> 512099.33 | AT29: =IF(AND(L29>0,AR29>0),(AR29/(P29*1000)*1000),0) -> 482.99518 | AU29: =IF(AND(M29>0,AS29>0),(AS29/(Q29*1000)*1000),0) -> 470.64839 | AV29: =IF(AND(R29>0,AR29>0),(AR29/(R29*1000)*1000),0) -> 502.18522 | AW29: =IF(AND(S29>0,AS29>0),(AS29/(S29*1000)*1000),0) -> 475.21593 | AX29: 0 | AY29: =AX29+AY28 -> 0 | AZ29: =IF(AND(L29>0,AX29>0),(AX29/(P29*1000)*1000),0) -> 0 | BA29: =IF(AND(M29>0,AY29>0),(AY29/(Q29*1000)*1000),0) -> 0 | BB29: =IF(AND(R29>0,AX29>0),(AX29/(R29*1000)*1000),0) -> 0 | BC29: =IF(AND(S29>0,AY29>0),(AY29/(S29*1000)*1000),0) -> 0 | BE29: =+Efficiency2!K92 -> 58.816074 | BF29: =BF28+BE29 -> 1124.4245 | BG29: =+R29/BE29 -> 0.98466279 | BH29: =+S29/BF29 -> 0.95836933
A30: =A29+1 -> 46103 | B30: Towel/Toilet | C30: 22/15 | D30: =+'22'!F42 -> 962.22222 | E30: =+'22'!G42 -> 781.88056 | F30: =1-(E30/D30) -> 0.18742206 | G30: =+P30/N30 -> 0.9677444 | H30: =+P30/L30 -> 0.95718118 | I30: =+R30/P30 -> 0.999468 | J30: =+R30/L30 -> 0.95667195 | K30: =+S30/M30 -> 0.93349041 | L30: =+SUM(Efficiency1!K96:K97) -> 56.949511 | M30: =M29+L30 -> 1212.7559 | N30: =+SUM(Efficiency1!C96:C97) -> 56.32789 | O30: =O29+N30 -> 1194.5398 | P30: ='22'!I38 -> 54.511 | Q30: =Q29+P30 -> 1142.583 | R30: ='22'!I40 -> 54.482 | S30: =S29+R30 -> 1132.096 | T30: =+[1]Report1!AZ30 -> 4020.5961 | U30: =T30+U29 -> 80655.623 | V30: =T30/P30 -> 73.757519 | W30: =U30/Q30 -> 70.590603 | X30: =IF(AND(R30>0,T30>0),(T30/(R30*1000))*1000,0) -> 73.796779 | Y30: =IF(AND(S30>0,U30>0),U30/S30,0) -> 71.244508 | Z30: 98.4 | AA30: =Z30+AA29 -> 2096.56 | AB30: =Z30/(P30) -> 1.8051402 | AC30: =AA30/(Q30) -> 1.8349302 | AD30: =IF(AND(R30>0,Z30>0),Z30/(R30),0) -> 1.8061011 | AE30: =IF(AND(S30>0,AA30>0),AA30/(S30),0) -> 1.8519278 | AG30: =+AF30+AG29 -> 0 | AH30: =AF30/(P30) -> 0 | AI30: =AG30/(Q30) -> 0 | AJ30: =IF(AND(R30>0,AF30>0),AF30/(R30),0) -> 0 | AK30: =IF(AND(S30>0,AG30>0),AG30/(S30),0) -> 0 | AL30: ='22'!I46 -> 37190.6 | AM30: =AL30+AM29 -> 840199 | AN30: =IF(AND(L30>0,AL30>0),(AL30/(P30*1000)*1000),0) -> 682.25863 | AO30: =IF(AND(M30>0,AM30>0),(AM30/(Q30*1000)*1000),0) -> 735.35052 | AP30: =IF(AND(R30>0,AL30>0),(AL30/(R30*1000)*1000),0) -> 682.62178 | AQ30: =IF(AND(S30>0,AM30>0),(AM30/(S30*1000)*1000),0) -> 742.16232 | AR30: =+Listrik!AA29 -> 26157.247 | AS30: =AR30+AS29 -> 538256.58 | AT30: =IF(AND(L30>0,AR30>0),(AR30/(P30*1000)*1000),0) -> 479.85264 | AU30: =IF(AND(M30>0,AS30>0),(AS30/(Q30*1000)*1000),0) -> 471.08751 | AV30: =IF(AND(R30>0,AR30>0),(AR30/(R30*1000)*1000),0) -> 480.10805 | AW30: =IF(AND(S30>0,AS30>0),(AS30/(S30*1000)*1000),0) -> 475.45136 | AX30: 0 | AY30: =AX30+AY29 -> 0 | AZ30: =IF(AND(L30>0,AX30>0),(AX30/(P30*1000)*1000),0) -> 0 | BA30: =IF(AND(M30>0,AY30>0),(AY30/(Q30*1000)*1000),0) -> 0 | BB30: =IF(AND(R30>0,AX30>0),(AX30/(R30*1000)*1000),0) -> 0 | BC30: =IF(AND(S30>0,AY30>0),(AY30/(S30*1000)*1000),0) -> 0 | BE30: =+SUM(Efficiency2!K96:K97) -> 56.949511 | BF30: =BF29+BE30 -> 1181.3741 | BG30: =+R30/BE30 -> 0.95667195 | BH30: =+S30/BF30 -> 0.95828751
A31: =A30+1 -> 46104 | B31: Toilet | C31: 15/13,5 | D31: =+'23'!F42 -> 1203.4375 | E31: =+'23'!G42 -> 971.30833 | F31: =1-(E31/D31) -> 0.19288843 | G31: =+P31/N31 -> 1.0243639 | H31: =+P31/L31 -> 0.99561244 | I31: =+R31/P31 -> 0.86728601 | J31: =+R31/L31 -> 0.86348074 | K31: =+S31/M31 -> 0.9305774 | L31: =+SUM(Efficiency1!K100:K101) -> 52.652014 | M31: =M30+L31 -> 1265.4079 | N31: =+SUM(Efficiency1!C100:C101) -> 51.174199 | O31: =O30+N31 -> 1245.714 | P31: ='23'!I38 -> 52.421 | Q31: =Q30+P31 -> 1195.004 | R31: ='23'!I40 -> 45.464 | S31: =S30+R31 -> 1177.56 | T31: =+[1]Report1!AZ31 -> 3910.1204 | U31: =T31+U30 -> 84565.743 | V31: =T31/P31 -> 74.590726 | W31: =U31/Q31 -> 70.766075 | X31: =IF(AND(R31>0,T31>0),(T31/(R31*1000))*1000,0) -> 86.004761 | Y31: =IF(AND(S31>0,U31>0),U31/S31,0) -> 71.814381 | Z31: 93.6 | AA31: =Z31+AA30 -> 2190.16 | AB31: =Z31/(P31) -> 1.785544 | AC31: =AA31/(Q31) -> 1.8327637 | AD31: =IF(AND(R31>0,Z31>0),Z31/(R31),0) -> 2.0587718 | AE31: =IF(AND(S31>0,AA31>0),AA31/(S31),0) -> 1.8599137 | AG31: =+AF31+AG30 -> 0 | AH31: =AF31/(P31) -> 0 | AI31: =AG31/(Q31) -> 0 | AJ31: =IF(AND(R31>0,AF31>0),AF31/(R31),0) -> 0 | AK31: =IF(AND(S31>0,AG31>0),AG31/(S31),0) -> 0 | AL31: ='23'!I46 -> 41518.04 | AM31: =AL31+AM30 -> 881717.04 | AN31: =IF(AND(L31>0,AL31>0),(AL31/(P31*1000)*1000),0) -> 792.0116 | AO31: =IF(AND(M31>0,AM31>0),(AM31/(Q31*1000)*1000),0) -> 737.83606 | AP31: =IF(AND(R31>0,AL31>0),(AL31/(R31*1000)*1000),0) -> 913.20693 | AQ31: =IF(AND(S31>0,AM31>0),(AM31/(S31*1000)*1000),0) -> 748.76613 | AR31: =+Listrik!AA30 -> 18237.158 | AS31: =AR31+AS30 -> 556493.74 | AT31: =IF(AND(L31>0,AR31>0),(AR31/(P31*1000)*1000),0) -> 347.89794 | AU31: =IF(AND(M31>0,AS31>0),(AS31/(Q31*1000)*1000),0) -> 465.68358 | AV31: =IF(AND(R31>0,AR31>0),(AR31/(R31*1000)*1000),0) -> 401.13404 | AW31: =IF(AND(S31>0,AS31>0),(AS31/(S31*1000)*1000),0) -> 472.58207 | AX31: 0 | AY31: =AX31+AY30 -> 0 | AZ31: =IF(AND(L31>0,AX31>0),(AX31/(P31*1000)*1000),0) -> 0 | BA31: =IF(AND(M31>0,AY31>0),(AY31/(Q31*1000)*1000),0) -> 0 | BB31: =IF(AND(R31>0,AX31>0),(AX31/(R31*1000)*1000),0) -> 0 | BC31: =IF(AND(S31>0,AY31>0),(AY31/(S31*1000)*1000),0) -> 0 | BE31: =+SUM(Efficiency2!K100:K101) -> 52.652014 | BF31: =BF30+BE31 -> 1234.0261 | BG31: =+R31/BE31 -> 0.86348074 | BH31: =+S31/BF31 -> 0.9542424
A32: =A31+1 -> 46105 | B32: Toilet | C32: 13,5 | D32: =+'24'!F42 -> 1225 | E32: =+'24'!G42 -> 1029 | F32: =1-(E32/D32) -> 0.16 | G32: =+P32/N32 -> 0.95368153 | H32: =+P32/L32 -> 0.9346079 | I32: =+R32/P32 -> 1.0080552 | J32: =+R32/L32 -> 0.94213632 | K32: =+S32/M32 -> 0.93104653 | L32: =+Efficiency1!K104 -> 53.53047 | M32: =M31+L32 -> 1318.9384 | N32: =+Efficiency1!C104 -> 52.459861 | O32: =O31+N32 -> 1298.1739 | P32: ='24'!I38 -> 50.03 | Q32: =Q31+P32 -> 1245.034 | R32: ='24'!I40 -> 50.433 | S32: =S31+R32 -> 1227.993 | T32: =+[1]Report1!AZ32 -> 3619.3398 | U32: =T32+U31 -> 88185.083 | V32: =T32/P32 -> 72.343389 | W32: =U32/Q32 -> 70.829457 | X32: =IF(AND(R32>0,T32>0),(T32/(R32*1000))*1000,0) -> 71.765308 | Y32: =IF(AND(S32>0,U32>0),U32/S32,0) -> 71.812366 | Z32: 94.9 | AA32: =Z32+AA31 -> 2285.06 | AB32: =Z32/(P32) -> 1.8968619 | AC32: =AA32/(Q32) -> 1.8353394 | AD32: =IF(AND(R32>0,Z32>0),Z32/(R32),0) -> 1.8817044 | AE32: =IF(AND(S32>0,AA32>0),AA32/(S32),0) -> 1.8608087 | AG32: =+AF32+AG31 -> 0 | AH32: =AF32/(P32) -> 0 | AI32: =AG32/(Q32) -> 0 | AJ32: =IF(AND(R32>0,AF32>0),AF32/(R32),0) -> 0 | AK32: =IF(AND(S32>0,AG32>0),AG32/(S32),0) -> 0 | AL32: =+'24'!I46 -> 42826.36 | AM32: =AL32+AM31 -> 924543.4 | AN32: =IF(AND(L32>0,AL32>0),(AL32/(P32*1000)*1000),0) -> 856.01359 | AO32: =IF(AND(M32>0,AM32>0),(AM32/(Q32*1000)*1000),0) -> 742.58486 | AP32: =IF(AND(R32>0,AL32>0),(AL32/(R32*1000)*1000),0) -> 849.17336 | AQ32: =IF(AND(S32>0,AM32>0),(AM32/(S32*1000)*1000),0) -> 752.8898 | AR32: =+Listrik!AA31 -> 20513.798 | AS32: =AR32+AS31 -> 577007.54 | AT32: =IF(AND(L32>0,AR32>0),(AR32/(P32*1000)*1000),0) -> 410.02994 | AU32: =IF(AND(M32>0,AS32>0),(AS32/(Q32*1000)*1000),0) -> 463.44721 | AV32: =IF(AND(R32>0,AR32>0),(AR32/(R32*1000)*1000),0) -> 406.75347 | AW32: =IF(AND(S32>0,AS32>0),(AS32/(S32*1000)*1000),0) -> 469.87852 | AX32: 0 | AY32: =AX32+AY31 -> 0 | AZ32: =IF(AND(L32>0,AX32>0),(AX32/(P32*1000)*1000),0) -> 0 | BA32: =IF(AND(M32>0,AY32>0),(AY32/(Q32*1000)*1000),0) -> 0 | BB32: =IF(AND(R32>0,AX32>0),(AX32/(R32*1000)*1000),0) -> 0 | BC32: =IF(AND(S32>0,AY32>0),(AY32/(S32*1000)*1000),0) -> 0 | BE32: =+Efficiency2!K104 -> 53.53047 | BF32: =BF31+BE32 -> 1287.5565 | BG32: =+R32/BE32 -> 0.94213632 | BH32: =+S32/BF32 -> 0.95373909
A33: =A32+1 -> 46106 | B33: Toilet | C33: 13,5 | D33: =+'25'!F42 -> 1225 | E33: =+'25'!G42 -> 1029 | F33: =1-(E33/D33) -> 0.16 | G33: =+P33/N33 -> 0.96504512 | H33: =+P33/L33 -> 0.94574421 | I33: =+R33/P33 -> 1.0802399 | J33: =+R33/L33 -> 1.0216306 | K33: =+S33/M33 -> 0.93452837 | L33: =+Efficiency1!K108 -> 52.723558 | M33: =M32+L33 -> 1371.6619 | N33: =+Efficiency1!C108 -> 51.669087 | O33: =O32+N33 -> 1349.843 | P33: ='25'!I38 -> 49.863 | Q33: =Q32+P33 -> 1294.897 | R33: ='25'!I40 -> 53.864 | S33: =S32+R33 -> 1281.857 | T33: =+[1]Report1!AZ33 -> 3619.8031 | U33: =T33+U32 -> 91804.886 | V33: =T33/P33 -> 72.594972 | W33: =U33/Q33 -> 70.897443 | X33: =IF(AND(R33>0,T33>0),(T33/(R33*1000))*1000,0) -> 67.202642 | Y33: =IF(AND(S33>0,U33>0),U33/S33,0) -> 71.618664 | Z33: 93.5 | AA33: =Z33+AA32 -> 2378.56 | AB33: =Z33/(P33) -> 1.8751379 | AC33: =AA33/(Q33) -> 1.836872 | AD33: =IF(AND(R33>0,Z33>0),Z33/(R33),0) -> 1.7358533 | AE33: =IF(AND(S33>0,AA33>0),AA33/(S33),0) -> 1.855558 | AG33: =+AF33+AG32 -> 0 | AH33: =AF33/(P33) -> 0 | AI33: =AG33/(Q33) -> 0 | AJ33: =IF(AND(R33>0,AF33>0),AF33/(R33),0) -> 0 | AK33: =IF(AND(S33>0,AG33>0),AG33/(S33),0) -> 0 | AL33: =+'25'!I46 -> 37579.775 | AM33: =AL33+AM32 -> 962123.17 | AN33: =IF(AND(L33>0,AL33>0),(AL33/(P33*1000)*1000),0) -> 753.66053 | AO33: =IF(AND(M33>0,AM33>0),(AM33/(Q33*1000)*1000),0) -> 743.01135 | AP33: =IF(AND(R33>0,AL33>0),(AL33/(R33*1000)*1000),0) -> 697.67888 | AQ33: =IF(AND(S33>0,AM33>0),(AM33/(S33*1000)*1000),0) -> 750.56982 | AR33: =+Listrik!AA32 -> 26694 | AS33: =AR33+AS32 -> 603701.54 | AT33: =IF(AND(L33>0,AR33>0),(AR33/(P33*1000)*1000),0) -> 535.34685 | AU33: =IF(AND(M33>0,AS33>0),(AS33/(Q33*1000)*1000),0) -> 466.21587 | AV33: =IF(AND(R33>0,AR33>0),(AR33/(R33*1000)*1000),0) -> 495.58146 | AW33: =IF(AND(S33>0,AS33>0),(AS33/(S33*1000)*1000),0) -> 470.95857 | AX33: 0 | AY33: =AX33+AY32 -> 0 | AZ33: =IF(AND(L33>0,AX33>0),(AX33/(P33*1000)*1000),0) -> 0 | BA33: =IF(AND(M33>0,AY33>0),(AY33/(Q33*1000)*1000),0) -> 0 | BB33: =IF(AND(R33>0,AX33>0),(AX33/(R33*1000)*1000),0) -> 0 | BC33: =IF(AND(S33>0,AY33>0),(AY33/(S33*1000)*1000),0) -> 0 | BE33: =+Efficiency2!K108 -> 52.723558 | BF33: =BF32+BE33 -> 1340.2801 | BG33: =+R33/BE33 -> 1.0216306 | BH33: =+S33/BF33 -> 0.95640978
