Workbook

Sheet Report1
A3: PAPER MACHINE 17 DAILY REPORT 1
A6: Date | B6: Grade | C6: GSM | D6: Speed yankee (mpm) | E6: Speed reel (mpm) | F6: Creep ( % ) | G6: Real Eff PM ( % ) | H6: Real Eff PM vs Target (%) | I6: Real Eff FG vs Real Eff PM (%) | J6: Eff FG vs Target (%) | L6: Kapasitas Target (ton) | N6: Kapasitas Teori Real (ton) | P6: PM PROD Timbangan (TON) | R6: FINSHED GOODS (TON) | T6: GAS HOOD | Z6: STEAM (TON) | AF6: STEAM DEINKING (TON) | AL6: POWER (kWh) | AR6: POWER DEINKING (kWh) | AX6: POWER WPL (kWh) | BD6: TOTALIZER | BE6: Kapasitas Running (ton) | BG6: Eff FG vs Target Running(%)
T7: CONSUMPTION | V7: /TON PM. | X7: /TON FG. | Z7: CONSUMPTION | AB7: /TON PM. | AD7: /TON FG. | AF7: CONSUMPTION | AH7: /TON PM. | AJ7: /TON FG. | AL7: CONSUMPTION | AN7: /TON PM | AP7: /TON FG | AR7: CONSUMPTION | AT7: /TON PM | AV7: /TON FG | AX7: CONSUMPTION | AZ7: /TON PM | BB7: /TON FG
J8: TODAY | K8: TODATE | L8: TODAY | M8: TODATE | N8: TODAY | O8: TODATE | P8: TODAY | Q8: TODATE | R8: TODAY | S8: TODATE | T8: TODAY | U8: TODATE | V8: TODAY | W8: TODATE | X8: TODAY | Y8: TODATE | Z8: TODAY | AA8: TODATE | AB8: TODAY | AC8: TODATE | AD8: TODAY | AE8: TODATE | AF8: TODAY | AG8: TODATE | AH8: TODAY | AI8: TODATE | AJ8: TODAY | AK8: TODATE | AL8: TODAY | AM8: TODATE | AN8: TODAY | AO8: TODATE | AP8: TODAY | AQ8: TODATE | AR8: TODAY | AS8: TODATE | AT8: TODAY | AU8: TODATE | AV8: TODAY | AW8: TODATE | AX8: TODAY | AY8: TODATE | AZ8: TODAY | BA8: TODATE | BB8: TODAY | BC8: TODATE | BE8: TODAY | BF8: TODATE | BG8: TODAY | BH8: TODATE
A9: 45839 | B9: Facial | C9: 12/11,5 | D9: =+'1'!F42 -> 1186.6174 | E9: =+'1'!G42 -> 909.38253 | F9: =1-(E9/D9) -> 0.23363457 | G9: =+P9/N9 -> 0.62843847 | H9: =+P9/L9 -> 0.56947097 | I9: =+R9/P9 -> 0.76499523 | J9: =+R9/L9 -> 0.43564258 | K9: =+S9/M9 -> 0.43564258 | L9: =+SUM(Efficiency1!K6:K7) -> 46.051513 | M9: =L9 -> 46.051513 | N9: =+SUM(Efficiency1!C6:C7) -> 41.730418 | O9: =N9 -> 41.730418 | P9: ='1'!I38 -> 26.225 | Q9: =P9 -> 26.225 | R9: ='1'!I40 -> 20.062 | S9: =R9 -> 20.062 | T9: =+[1]Report1!AZ9 -> 2660.3262 | U9: =T9 -> 2660.3262 | V9: =T9/P9 -> 101.44237 | W9: =U9/Q9 -> 101.44237 | X9: =IF(AND(R9>0,T9>0),(T9/(R9*1000))*1000,0) -> 132.60524 | Y9: =IF(AND(S9>0,U9>0),U9/S9,0) -> 132.60524 | Z9: 63.4 | AA9: =Z9 -> 63.4 | AB9: 63.4 | AC9: =AA9/(Q9) -> 2.4175405 | AD9: =IF(AND(R9>0,Z9>0),Z9/(R9),0) -> 3.1602034 | AE9: =IF(AND(S9>0,AA9>0),AA9/(S9),0) -> 3.1602034 | AF9: 0 | AG9: =AF9 -> 0 | AH9: =AF9/(P9) -> 0 | AI9: =AG9/(Q9) -> 0 | AJ9: =IF(AND(R9>0,AF9>0),AF9/(R9),0) -> 0 | AK9: =IF(AND(S9>0,AG9>0),AG9/(S9),0) -> 0 | AL9: ='1'!I46 -> 30771.765 | AM9: =AL9 -> 30771.765 | AN9: =IF(AND(L9>0,AL9>0),(AL9/(P9*1000)*1000),0) -> 1173.3752 | AO9: =IF(AND(M9>0,AM9>0),(AM9/(Q9*1000)*1000),0) -> 1173.3752 | AP9: =IF(AND(R9>0,AL9>0),(AL9/(R9*1000)*1000),0) -> 1533.8334 | AQ9: =IF(AND(S9>0,AM9>0),(AM9/(S9*1000)*1000),0) -> 1533.8334 | AR9: =+Listrik!AA8 -> 0 | AS9: =AR9 -> 0 | AT9: =IF(AND(L9>0,AR9>0),(AR9/(P9*1000)*1000),0) -> 0 | AU9: =IF(AND(M9>0,AS9>0),(AS9/(Q9*1000)*1000),0) -> 0 | AV9: =IF(AND(R9>0,AR9>0),(AR9/(R9*1000)*1000),0) -> 0 | AW9: =IF(AND(S9>0,AS9>0),(AS9/(S9*1000)*1000),0) -> 0 | AX9: =+Listrik!AD8 -> 0 | AY9: =AX9 -> 0 | AZ9: =IF(AND(L9>0,AX9>0),(AX9/(P9*1000)*1000),0) -> 0 | BA9: =IF(AND(M9>0,AY9>0),(AY9/(Q9*1000)*1000),0) -> 0 | BB9: =IF(AND(R9>0,AX9>0),(AX9/(R9*1000)*1000),0) -> 0 | BC9: =IF(AND(S9>0,AY9>0),(AY9/(S9*1000)*1000),0) -> 0 | BE9: =+SUM(Efficiency2!K6:K7) -> 41.074387 | BF9: =BE9 -> 41.074387 | BG9: =+R9/BE9 -> 0.4884309 | BH9: =+S9/BF9 -> 0.4884309
A10: =A9+1 -> 45840 | B10: Facial | C10: 11,5 | D10: =+'2'!F42 -> 1272.5532 | E10: =+'2'!G42 -> 979.86596 | F10: =1-(E10/D10) -> 0.23 | G10: =+P10/N10 -> 0.80509878 | H10: =+P10/L10 -> 0.75891187 | I10: =+R10/P10 -> 1.0217537 | J10: =+R10/L10 -> 0.77542102 | K10: =+S10/M10 -> 0.60392217 | L10: =+Efficiency1!K12 -> 45.187065 | M10: =M9+L10 -> 91.238578 | N10: =+Efficiency1!C12 -> 42.594773 | O10: =O9+N10 -> 84.325191 | P10: ='2'!I38 -> 34.293 | Q10: =Q9+P10 -> 60.518 | R10: ='2'!I40 -> 35.039 | S10: =S9+R10 -> 55.101 | T10: =+[1]Report1!AZ10 -> 2510.792 | U10: =T10+U9 -> 5171.1182 | V10: =T10/P10 -> 73.215874 | W10: =U10/Q10 -> 85.447606 | X10: =IF(AND(R10>0,T10>0),(T10/(R10*1000))*1000,0) -> 71.657067 | Y10: =IF(AND(S10>0,U10>0),U10/S10,0) -> 93.847992 | Z10: 70.5 | AA10: =Z10+AA9 -> 133.9 | AB10: 70.5 | AC10: =AA10/(Q10) -> 2.2125649 | AD10: =IF(AND(R10>0,Z10>0),Z10/(R10),0) -> 2.0120437 | AE10: =IF(AND(S10>0,AA10>0),AA10/(S10),0) -> 2.4300829 | AF10: 0 | AG10: =+AF10+AG9 -> 0 | AH10: =AF10/(P10) -> 0 | AI10: =AG10/(Q10) -> 0 | AJ10: =IF(AND(R10>0,AF10>0),AF10/(R10),0) -> 0 | AK10: =IF(AND(S10>0,AG10>0),AG10/(S10),0) -> 0 | AL10: ='2'!I46 -> 34783.925 | AM10: =AL10+AM9 -> 65555.69 | AN10: =IF(AND(L10>0,AL10>0),(AL10/(P10*1000)*1000),0) -> 1014.3156 | AO10: =IF(AND(M10>0,AM10>0),(AM10/(Q10*1000)*1000),0) -> 1083.2428 | AP10: =IF(AND(R10>0,AL10>0),(AL10/(R10*1000)*1000),0) -> 992.72025 | AQ10: =IF(AND(S10>0,AM10>0),(AM10/(S10*1000)*1000),0) -> 1189.7368 | AR10: =+Listrik!AA9 -> 0 | AS10: =AR10+AS9 -> 0 | AT10: =IF(AND(L10>0,AR10>0),(AR10/(P10*1000)*1000),0) -> 0 | AU10: =IF(AND(M10>0,AS10>0),(AS10/(Q10*1000)*1000),0) -> 0 | AV10: =IF(AND(R10>0,AR10>0),(AR10/(R10*1000)*1000),0) -> 0 | AW10: =IF(AND(S10>0,AS10>0),(AS10/(S10*1000)*1000),0) -> 0 | AX10: =+Listrik!AD9 -> 0 | AY10: =AX10+AY9 -> 0 | AZ10: =IF(AND(L10>0,AX10>0),(AX10/(P10*1000)*1000),0) -> 0 | BA10: =IF(AND(M10>0,AY10>0),(AY10/(Q10*1000)*1000),0) -> 0 | BB10: =IF(AND(R10>0,AX10>0),(AX10/(R10*1000)*1000),0) -> 0 | BC10: =IF(AND(S10>0,AY10>0),(AY10/(S10*1000)*1000),0) -> 0 | BE10: =+Efficiency2!K12 -> 43.053231 | BF10: =BF9+BE10 -> 84.127619 | BG10: =+R10/BE10 -> 0.81385296 | BH10: =+S10/BF10 -> 0.65496921
A11: =A10+1 -> 45841 | B11: Facial | C11: 11,5 | D11: =+'3'!F42 -> 1349.7872 | E11: =+'3'!G42 -> 1039.3362 | F11: =1-(E11/D11) -> 0.23 | G11: =+P11/N11 -> 0.90571163 | H11: =+P11/L11 -> 0.90556888 | I11: =+R11/P11 -> 0.93927175 | J11: =+R11/L11 -> 0.85057527 | K11: =+S11/M11 -> 0.6856189 | L11: =+Efficiency1!K19 -> 45.187065 | M11: =M10+L11 -> 136.42564 | N11: =+Efficiency1!C19 -> 45.179943 | O11: =O10+N11 -> 129.50513 | P11: ='3'!I38 -> 40.92 | Q11: =Q10+P11 -> 101.438 | R11: ='3'!I40 -> 38.435 | S11: =S10+R11 -> 93.536 | T11: =+[1]Report1!AZ11 -> 3197.2643 | U11: =T11+U10 -> 8368.3826 | V11: =T11/P11 -> 78.134515 | W11: =U11/Q11 -> 82.497511 | X11: =IF(AND(R11>0,T11>0),(T11/(R11*1000))*1000,0) -> 83.186272 | Y11: =IF(AND(S11>0,U11>0),U11/S11,0) -> 89.466971 | Z11: 85.7 | AA11: =Z11+AA10 -> 219.6 | AB11: 85.7 | AC11: =AA11/(Q11) -> 2.1648692 | AD11: =IF(AND(R11>0,Z11>0),Z11/(R11),0) -> 2.2297385 | AE11: =IF(AND(S11>0,AA11>0),AA11/(S11),0) -> 2.3477592 | AF11: 0 | AG11: =+AF11+AG10 -> 0 | AH11: =AF11/(P11) -> 0 | AI11: =AG11/(Q11) -> 0 | AJ11: =IF(AND(R11>0,AF11>0),AF11/(R11),0) -> 0 | AK11: =IF(AND(S11>0,AG11>0),AG11/(S11),0) -> 0 | AL11: ='3'!I46 -> 40238.42 | AM11: =AL11+AM10 -> 105794.11 | AN11: =IF(AND(L11>0,AL11>0),(AL11/(P11*1000)*1000),0) -> 983.3436 | AO11: =IF(AND(M11>0,AM11>0),(AM11/(Q11*1000)*1000),0) -> 1042.9436 | AP11: =IF(AND(R11>0,AL11>0),(AL11/(R11*1000)*1000),0) -> 1046.9213 | AQ11: =IF(AND(S11>0,AM11>0),(AM11/(S11*1000)*1000),0) -> 1131.0523 | AR11: =+Listrik!AA10 -> 0 | AS11: =AR11+AS10 -> 0 | AT11: =IF(AND(L11>0,AR11>0),(AR11/(P11*1000)*1000),0) -> 0 | AU11: =IF(AND(M11>0,AS11>0),(AS11/(Q11*1000)*1000),0) -> 0 | AV11: =IF(AND(R11>0,AR11>0),(AR11/(R11*1000)*1000),0) -> 0 | AW11: =IF(AND(S11>0,AS11>0),(AS11/(S11*1000)*1000),0) -> 0 | AX11: =+Listrik!AD10 -> 0 | AY11: =AX11+AY10 -> 0 | AZ11: =IF(AND(L11>0,AX11>0),(AX11/(P11*1000)*1000),0) -> 0 | BA11: =IF(AND(M11>0,AY11>0),(AY11/(Q11*1000)*1000),0) -> 0 | BB11: =IF(AND(R11>0,AX11>0),(AX11/(R11*1000)*1000),0) -> 0 | BC11: =IF(AND(S11>0,AY11>0),(AY11/(S11*1000)*1000),0) -> 0 | BE11: =+Efficiency2!K19 -> 44.245668 | BF11: =BF10+BE11 -> 128.37329 | BG11: =+R11/BE11 -> 0.86867262 | BH11: =+S11/BF11 -> 0.72862511
A12: =A11+1 -> 45842 | B12: Facial | C12: 11,5 | D12: =+'4'!F42 -> 1289.8681 | E12: =+'4'!G42 -> 993.1984 | F12: =1-(E12/D12) -> 0.23 | G12: =+P12/N12 -> 0.97645975 | H12: =+P12/L12 -> 0.9329661 | I12: =+R12/P12 -> 0.99888515 | J12: =+R12/L12 -> 0.93192598 | K12: =+S12/M12 -> 0.74690258 | L12: =+Efficiency1!K25 -> 45.187065 | M12: =M11+L12 -> 181.61271 | N12: =+Efficiency1!C25 -> 43.174335 | O12: =O11+N12 -> 172.67947 | P12: ='4'!I38 -> 42.158 | Q12: =Q11+P12 -> 143.596 | R12: ='4'!I40 -> 42.111 | S12: =S11+R12 -> 135.647 | T12: =+[1]Report1!AZ12 -> 3571.9445 | U12: =T12+U11 -> 11940.327 | V12: =T12/P12 -> 84.72756 | W12: =U12/Q12 -> 83.152226 | X12: =IF(AND(R12>0,T12>0),(T12/(R12*1000))*1000,0) -> 84.822124 | Y12: =IF(AND(S12>0,U12>0),U12/S12,0) -> 88.024999 | Z12: 84.3 | AA12: =Z12+AA11 -> 303.9 | AB12: 84.3 | AC12: =AA12/(Q12) -> 2.1163542 | AD12: =IF(AND(R12>0,Z12>0),Z12/(R12),0) -> 2.0018522 | AE12: =IF(AND(S12>0,AA12>0),AA12/(S12),0) -> 2.2403739 | AF12: 0 | AG12: =+AF12+AG11 -> 0 | AH12: =AF12/(P12) -> 0 | AI12: =AG12/(Q12) -> 0 | AJ12: =IF(AND(R12>0,AF12>0),AF12/(R12),0) -> 0 | AK12: =IF(AND(S12>0,AG12>0),AG12/(S12),0) -> 0 | AL12: ='4'!I46 -> 42853.175 | AM12: =AL12+AM11 -> 148647.28 | AN12: =IF(AND(L12>0,AL12>0),(AL12/(P12*1000)*1000),0) -> 1016.4898 | AO12: =IF(AND(M12>0,AM12>0),(AM12/(Q12*1000)*1000),0) -> 1035.1771 | AP12: =IF(AND(R12>0,AL12>0),(AL12/(R12*1000)*1000),0) -> 1017.6243 | AQ12: =IF(AND(S12>0,AM12>0),(AM12/(S12*1000)*1000),0) -> 1095.8391 | AR12: =+Listrik!AA11 -> 0 | AS12: =AR12+AS11 -> 0 | AT12: =IF(AND(L12>0,AR12>0),(AR12/(P12*1000)*1000),0) -> 0 | AU12: =IF(AND(M12>0,AS12>0),(AS12/(Q12*1000)*1000),0) -> 0 | AV12: =IF(AND(R12>0,AR12>0),(AR12/(R12*1000)*1000),0) -> 0 | AW12: =IF(AND(S12>0,AS12>0),(AS12/(S12*1000)*1000),0) -> 0 | AX12: =+Listrik!AD11 -> 0 | AY12: =AX12+AY11 -> 0 | AZ12: =IF(AND(L12>0,AX12>0),(AX12/(P12*1000)*1000),0) -> 0 | BA12: =IF(AND(M12>0,AY12>0),(AY12/(Q12*1000)*1000),0) -> 0 | BB12: =IF(AND(R12>0,AX12>0),(AX12/(R12*1000)*1000),0) -> 0 | BC12: =IF(AND(S12>0,AY12>0),(AY12/(S12*1000)*1000),0) -> 0 | BE12: =+Efficiency2!K25 -> 45.187065 | BF12: =BF11+BE12 -> 173.56035 | BG12: =+R12/BE12 -> 0.93192598 | BH12: =+S12/BF12 -> 0.78155523
A13: =A12+1 -> 45843 | B13: Facial | C13: 11,5/12/13 | D13: =+'5'!F42 -> 1350 | E13: =+'5'!G42 -> 1039.5 | F13: =1-(E13/D13) -> 0.23 | G13: =+P13/N13 -> 0.92406922 | H13: =+P13/L13 -> 0.92406922 | I13: =+R13/P13 -> 0.94943757 | J13: =+R13/L13 -> 0.87734603 | K13: =+S13/M13 -> 0.77408761 | L13: =+SUM(Efficiency1!K30:K32) -> 47.813518 | M13: =M12+L13 -> 229.42623 | N13: =+SUM(Efficiency1!C30:C32) -> 47.813518 | O13: =O12+N13 -> 220.49299 | P13: ='5'!I38 -> 44.183 | Q13: =Q12+P13 -> 187.779 | R13: ='5'!I40 -> 41.949 | S13: =S12+R13 -> 177.596 | T13: =+[1]Report1!AZ13 -> 3510.7815 | U13: =T13+U12 -> 15451.109 | V13: =T13/P13 -> 79.460008 | W13: =U13/Q13 -> 82.283475 | X13: =IF(AND(R13>0,T13>0),(T13/(R13*1000))*1000,0) -> 83.691662 | Y13: =IF(AND(S13>0,U13>0),U13/S13,0) -> 87.001445 | Z13: 87.1 | AA13: =Z13+AA12 -> 391 | AB13: 87.1 | AC13: =AA13/(Q13) -> 2.082235 | AD13: =IF(AND(R13>0,Z13>0),Z13/(R13),0) -> 2.0763308 | AE13: =IF(AND(S13>0,AA13>0),AA13/(S13),0) -> 2.2016262 | AF13: 0 | AG13: =+AF13+AG12 -> 0 | AH13: =AF13/(P13) -> 0 | AI13: =AG13/(Q13) -> 0 | AJ13: =IF(AND(R13>0,AF13>0),AF13/(R13),0) -> 0 | AK13: =IF(AND(S13>0,AG13>0),AG13/(S13),0) -> 0 | AL13: ='5'!I46 -> 42146.73 | AM13: =AL13+AM12 -> 190794.01 | AN13: =IF(AND(L13>0,AL13>0),(AL13/(P13*1000)*1000),0) -> 953.91282 | AO13: =IF(AND(M13>0,AM13>0),(AM13/(Q13*1000)*1000),0) -> 1016.0562 | AP13: =IF(AND(R13>0,AL13>0),(AL13/(R13*1000)*1000),0) -> 1004.7136 | AQ13: =IF(AND(S13>0,AM13>0),(AM13/(S13*1000)*1000),0) -> 1074.3148 | AR13: =+Listrik!AA12 -> 0 | AS13: =AR13+AS12 -> 0 | AT13: =IF(AND(L13>0,AR13>0),(AR13/(P13*1000)*1000),0) -> 0 | AU13: =IF(AND(M13>0,AS13>0),(AS13/(Q13*1000)*1000),0) -> 0 | AV13: =IF(AND(R13>0,AR13>0),(AR13/(R13*1000)*1000),0) -> 0 | AW13: =IF(AND(S13>0,AS13>0),(AS13/(S13*1000)*1000),0) -> 0 | AX13: =+Listrik!AD12 -> 0 | AY13: =AX13+AY12 -> 0 | AZ13: =IF(AND(L13>0,AX13>0),(AX13/(P13*1000)*1000),0) -> 0 | BA13: =IF(AND(M13>0,AY13>0),(AY13/(Q13*1000)*1000),0) -> 0 | BB13: =IF(AND(R13>0,AX13>0),(AX13/(R13*1000)*1000),0) -> 0 | BC13: =IF(AND(S13>0,AY13>0),(AY13/(S13*1000)*1000),0) -> 0 | BE13: =+SUM(Efficiency2!K30:K32) -> 47.813518 | BF13: =BF12+BE13 -> 221.37387 | BG13: =+R13/BE13 -> 0.87734603 | BH13: =+S13/BF13 -> 0.80224464
A14: =A13+1 -> 45844 | B14: Facial/Toilet | C14: 13/13 | D14: =+'6'!F42 -> 1316.6667 | E14: =+'6'!G42 -> 1075.7292 | F14: =1-(E14/D14) -> 0.18299051 | G14: =+P14/N14 -> 0.92193897 | H14: =+P14/L14 -> 0.92193897 | I14: =+R14/P14 -> 0.958168 | J14: =+R14/L14 -> 0.88337241 | K14: =+S14/M14 -> 0.7942603 | L14: =+SUM(Efficiency1!K35:K36) -> 51.936193 | M14: =M13+L14 -> 281.36242 | N14: =+SUM(Efficiency1!C35:C36) -> 51.936193 | O14: =O13+N14 -> 272.42918 | P14: ='6'!I38 -> 47.882 | Q14: =Q13+P14 -> 235.661 | R14: ='6'!I40 -> 45.879 | S14: =S13+R14 -> 223.475 | T14: =+[1]Report1!AZ14 -> 3665.4814 | U14: =T14+U13 -> 19116.59 | V14: =T14/P14 -> 76.552387 | W14: =U14/Q14 -> 81.119023 | X14: =IF(AND(R14>0,T14>0),(T14/(R14*1000))*1000,0) -> 79.894536 | Y14: =IF(AND(S14>0,U14>0),U14/S14,0) -> 85.54241 | Z14: 95.3 | AA14: =Z14+AA13 -> 486.3 | AB14: 95.3 | AC14: =AA14/(Q14) -> 2.0635574 | AD14: =IF(AND(R14>0,Z14>0),Z14/(R14),0) -> 2.0772031 | AE14: =IF(AND(S14>0,AA14>0),AA14/(S14),0) -> 2.1760823 | AF14: 0 | AG14: =+AF14+AG13 -> 0 | AH14: =AF14/(P14) -> 0 | AI14: =AG14/(Q14) -> 0 | AJ14: =IF(AND(R14>0,AF14>0),AF14/(R14),0) -> 0 | AK14: =IF(AND(S14>0,AG14>0),AG14/(S14),0) -> 0 | AL14: ='6'!I46 -> 38551.815 | AM14: =AL14+AM13 -> 229345.83 | AN14: =IF(AND(L14>0,AL14>0),(AL14/(P14*1000)*1000),0) -> 805.14212 | AO14: =IF(AND(M14>0,AM14>0),(AM14/(Q14*1000)*1000),0) -> 973.20231 | AP14: =IF(AND(R14>0,AL14>0),(AL14/(R14*1000)*1000),0) -> 840.29327 | AQ14: =IF(AND(S14>0,AM14>0),(AM14/(S14*1000)*1000),0) -> 1026.2706 | AR14: =+Listrik!AA13 -> 0 | AS14: =AR14+AS13 -> 0 | AT14: =IF(AND(L14>0,AR14>0),(AR14/(P14*1000)*1000),0) -> 0 | AU14: =IF(AND(M14>0,AS14>0),(AS14/(Q14*1000)*1000),0) -> 0 | AV14: =IF(AND(R14>0,AR14>0),(AR14/(R14*1000)*1000),0) -> 0 | AW14: =IF(AND(S14>0,AS14>0),(AS14/(S14*1000)*1000),0) -> 0 | AX14: =+Listrik!AD13 -> 0 | AY14: =AX14+AY13 -> 0 | AZ14: =IF(AND(L14>0,AX14>0),(AX14/(P14*1000)*1000),0) -> 0 | BA14: =IF(AND(M14>0,AY14>0),(AY14/(Q14*1000)*1000),0) -> 0 | BB14: =IF(AND(R14>0,AX14>0),(AX14/(R14*1000)*1000),0) -> 0 | BC14: =IF(AND(S14>0,AY14>0),(AY14/(S14*1000)*1000),0) -> 0 | BE14: =+SUM(Efficiency2!K35:K36) -> 51.936193 | BF14: =BF13+BE14 -> 273.31006 | BG14: =+R14/BE14 -> 0.88337241 | BH14: =+S14/BF14 -> 0.81766108
A15: =A14+1 -> 45845 | B15: Toilet | C15: 13 | D15: =+'7'!F42 -> 1300 | E15: =+'7'!G42 -> 1066 | F15: =1-(E15/D15) -> 0.18 | G15: =+P15/N15 -> 1.0044128 | H15: =+P15/L15 -> 0.99674553 | I15: =+R15/P15 -> 0.93844153 | J15: =+R15/L15 -> 0.9353874 | K15: =+S15/M15 -> 0.81615983 | L15: =+Efficiency1!K39 -> 51.680192 | M15: =M14+L15 -> 333.04261 | N15: =+Efficiency1!C39 -> 51.285686 | O15: =O14+N15 -> 323.71487 | P15: ='7'!I38 -> 51.512 | Q15: =Q14+P15 -> 287.173 | R15: ='7'!I40 -> 48.341 | S15: =S14+R15 -> 271.816 | T15: =+[1]Report1!AZ15 -> 3795.892 | U15: =T15+U14 -> 22912.482 | V15: =T15/P15 -> 73.68947 | W15: =U15/Q15 -> 79.786338 | X15: =IF(AND(R15>0,T15>0),(T15/(R15*1000))*1000,0) -> 78.523241 | Y15: =IF(AND(S15>0,U15>0),U15/S15,0) -> 84.294089 | Z15: 95.8 | AA15: =Z15+AA14 -> 582.1 | AB15: 95.8 | AC15: =AA15/(Q15) -> 2.0270011 | AD15: =IF(AND(R15>0,Z15>0),Z15/(R15),0) -> 1.9817546 | AE15: =IF(AND(S15>0,AA15>0),AA15/(S15),0) -> 2.1415222 | AF15: 0 | AG15: =+AF15+AG14 -> 0 | AH15: =AF15/(P15) -> 0 | AI15: =AG15/(Q15) -> 0 | AJ15: =IF(AND(R15>0,AF15>0),AF15/(R15),0) -> 0 | AK15: =IF(AND(S15>0,AG15>0),AG15/(S15),0) -> 0 | AL15: ='7'!I46 -> 39058.43 | AM15: =AL15+AM14 -> 268404.26 | AN15: =IF(AND(L15>0,AL15>0),(AL15/(P15*1000)*1000),0) -> 758.23944 | AO15: =IF(AND(M15>0,AM15>0),(AM15/(Q15*1000)*1000),0) -> 934.64309 | AP15: =IF(AND(R15>0,AL15>0),(AL15/(R15*1000)*1000),0) -> 807.97729 | AQ15: =IF(AND(S15>0,AM15>0),(AM15/(S15*1000)*1000),0) -> 987.44835 | AR15: =+Listrik!AA14 -> 0 | AS15: =AR15+AS14 -> 0 | AT15: =IF(AND(L15>0,AR15>0),(AR15/(P15*1000)*1000),0) -> 0 | AU15: =IF(AND(M15>0,AS15>0),(AS15/(Q15*1000)*1000),0) -> 0 | AV15: =IF(AND(R15>0,AR15>0),(AR15/(R15*1000)*1000),0) -> 0 | AW15: =IF(AND(S15>0,AS15>0),(AS15/(S15*1000)*1000),0) -> 0 | AX15: =+Listrik!AD14 -> 0 | AY15: =AX15+AY14 -> 0 | AZ15: =IF(AND(L15>0,AX15>0),(AX15/(P15*1000)*1000),0) -> 0 | BA15: =IF(AND(M15>0,AY15>0),(AY15/(Q15*1000)*1000),0) -> 0 | BB15: =IF(AND(R15>0,AX15>0),(AX15/(R15*1000)*1000),0) -> 0 | BC15: =IF(AND(S15>0,AY15>0),(AY15/(S15*1000)*1000),0) -> 0 | BE15: =+Efficiency2!K39 -> 51.680192 | BF15: =BF14+BE15 -> 324.99025 | BG15: =+R15/BE15 -> 0.9353874 | BH15: =+S15/BF15 -> 0.83638201
A16: =A15+1 -> 45846 | B16: Toilet/Facial | C16: 13/13 | D16: =+'8'!F42 -> 1328.4722 | E16: =+'8'!G42 -> 1050.9097 | F16: =1-(E16/D16) -> 0.20893361 | G16: =+P16/N16 -> 0.95060567 | H16: =+P16/L16 -> 0.94747916 | I16: =+R16/P16 -> 1.0361113 | J16: =+R16/L16 -> 0.9816939 | K16: =+S16/M16 -> 0.83838285 | L16: =+SUM(Efficiency1!K43:K45) -> 51.644407 | M16: =M15+L16 -> 384.68702 | N16: =+SUM(Efficiency1!C43:C45) -> 51.474551 | O16: =O15+N16 -> 375.18942 | P16: ='8'!I38 -> 48.932 | Q16: =Q15+P16 -> 336.105 | R16: ='8'!I40 -> 50.699 | S16: =S15+R16 -> 322.515 | T16: =+[1]Report1!AZ16 -> 3734.6586 | U16: =T16+U15 -> 26647.141 | V16: =T16/P16 -> 76.32344 | W16: =U16/Q16 -> 79.28219 | X16: =IF(AND(R16>0,T16>0),(T16/(R16*1000))*1000,0) -> 73.663358 | Y16: =IF(AND(S16>0,U16>0),U16/S16,0) -> 82.62295 | Z16: 93.4 | AA16: =Z16+AA15 -> 675.5 | AB16: 93.4 | AC16: =AA16/(Q16) -> 2.0097886 | AD16: =IF(AND(R16>0,Z16>0),Z16/(R16),0) -> 1.8422454 | AE16: =IF(AND(S16>0,AA16>0),AA16/(S16),0) -> 2.0944762 | AF16: 0 | AG16: =+AF16+AG15 -> 0 | AH16: =AF16/(P16) -> 0 | AI16: =AG16/(Q16) -> 0 | AJ16: =IF(AND(R16>0,AF16>0),AF16/(R16),0) -> 0 | AK16: =IF(AND(S16>0,AG16>0),AG16/(S16),0) -> 0 | AL16: ='8'!I46 -> 40532.105 | AM16: =AL16+AM15 -> 308936.36 | AN16: =IF(AND(L16>0,AL16>0),(AL16/(P16*1000)*1000),0) -> 828.33534 | AO16: =IF(AND(M16>0,AM16>0),(AM16/(Q16*1000)*1000),0) -> 919.16623 | AP16: =IF(AND(R16>0,AL16>0),(AL16/(R16*1000)*1000),0) -> 799.46557 | AQ16: =IF(AND(S16>0,AM16>0),(AM16/(S16*1000)*1000),0) -> 957.89766 | AR16: =+Listrik!AA15 -> 0 | AS16: =AR16+AS15 -> 0 | AT16: =IF(AND(L16>0,AR16>0),(AR16/(P16*1000)*1000),0) -> 0 | AU16: =IF(AND(M16>0,AS16>0),(AS16/(Q16*1000)*1000),0) -> 0 | AV16: =IF(AND(R16>0,AR16>0),(AR16/(R16*1000)*1000),0) -> 0 | AW16: =IF(AND(S16>0,AS16>0),(AS16/(S16*1000)*1000),0) -> 0 | AX16: =+Listrik!AD15 -> 0 | AY16: =AX16+AY15 -> 0 | AZ16: =IF(AND(L16>0,AX16>0),(AX16/(P16*1000)*1000),0) -> 0 | BA16: =IF(AND(M16>0,AY16>0),(AY16/(Q16*1000)*1000),0) -> 0 | BB16: =IF(AND(R16>0,AX16>0),(AX16/(R16*1000)*1000),0) -> 0 | BC16: =IF(AND(S16>0,AY16>0),(AY16/(S16*1000)*1000),0) -> 0 | BE16: =+SUM(Efficiency2!K43:K45) -> 51.466029 | BF16: =BF15+BE16 -> 376.45628 | BG16: =+R16/BE16 -> 0.9850964 | BH16: =+S16/BF16 -> 0.85671302
A17: =A16+1 -> 45847 | B17: Facial | C17: 13/12 | D17: =+'9'!F42 -> 1350 | E17: =+'9'!G42 -> 1039.5 | F17: =1-(E17/D17) -> 0.23 | G17: =+P17/N17 -> 0.88687264 | H17: =+P17/L17 -> 0.88687264 | I17: =+R17/P17 -> 1.0279752 | J17: =+R17/L17 -> 0.91168308 | K17: =+S17/M17 -> 0.84638117 | L17: =+SUM(Efficiency1!K48:K49) -> 47.11725 | M17: =M16+L17 -> 431.80427 | N17: =+SUM(Efficiency1!C48:C49) -> 47.11725 | O17: =O16+N17 -> 422.30667 | P17: ='9'!I38 -> 41.787 | Q17: =Q16+P17 -> 377.892 | R17: ='9'!I40 -> 42.956 | S17: =S16+R17 -> 365.471 | T17: =+[1]Report1!AZ17 -> 3585.9666 | U17: =T17+U16 -> 30233.107 | V17: =T17/P17 -> 85.815364 | W17: =U17/Q17 -> 80.004624 | X17: =IF(AND(R17>0,T17>0),(T17/(R17*1000))*1000,0) -> 83.479994 | Y17: =IF(AND(S17>0,U17>0),U17/S17,0) -> 82.723683 | Z17: 86.6 | AA17: =Z17+AA16 -> 762.1 | AB17: 86.6 | AC17: =AA17/(Q17) -> 2.0167138 | AD17: =IF(AND(R17>0,Z17>0),Z17/(R17),0) -> 2.0160164 | AE17: =IF(AND(S17>0,AA17>0),AA17/(S17),0) -> 2.0852544 | AF17: 0 | AG17: =+AF17+AG16 -> 0 | AH17: =AF17/(P17) -> 0 | AI17: =AG17/(Q17) -> 0 | AJ17: =IF(AND(R17>0,AF17>0),AF17/(R17),0) -> 0 | AK17: =IF(AND(S17>0,AG17>0),AG17/(S17),0) -> 0 | AL17: ='9'!I46 -> 38975.19 | AM17: =AL17+AM16 -> 347911.55 | AN17: =IF(AND(L17>0,AL17>0),(AL17/(P17*1000)*1000),0) -> 932.71089 | AO17: =IF(AND(M17>0,AM17>0),(AM17/(Q17*1000)*1000),0) -> 920.66399 | AP17: =IF(AND(R17>0,AL17>0),(AL17/(R17*1000)*1000),0) -> 907.3282 | AQ17: =IF(AND(S17>0,AM17>0),(AM17/(S17*1000)*1000),0) -> 951.95393 | AR17: =+Listrik!AA16 -> 0 | AS17: =AR17+AS16 -> 0 | AT17: =IF(AND(L17>0,AR17>0),(AR17/(P17*1000)*1000),0) -> 0 | AU17: =IF(AND(M17>0,AS17>0),(AS17/(Q17*1000)*1000),0) -> 0 | AV17: =IF(AND(R17>0,AR17>0),(AR17/(R17*1000)*1000),0) -> 0 | AW17: =IF(AND(S17>0,AS17>0),(AS17/(S17*1000)*1000),0) -> 0 | AX17: =+Listrik!AD16 -> 0 | AY17: =AX17+AY16 -> 0 | AZ17: =IF(AND(L17>0,AX17>0),(AX17/(P17*1000)*1000),0) -> 0 | BA17: =IF(AND(M17>0,AY17>0),(AY17/(Q17*1000)*1000),0) -> 0 | BB17: =IF(AND(R17>0,AX17>0),(AX17/(R17*1000)*1000),0) -> 0 | BC17: =IF(AND(S17>0,AY17>0),(AY17/(S17*1000)*1000),0) -> 0 | BE17: =+SUM(Efficiency2!K48:K49) -> 47.11725 | BF17: =BF16+BE17 -> 423.57353 | BG17: =+R17/BE17 -> 0.91168308 | BH17: =+S17/BF17 -> 0.86282775
A18: =A17+1 -> 45848 | B18: Facial | C18: 12 | D18: =+'10'!F42 -> 1343.3333 | E18: =+'10'!G42 -> 1034.3667 | F18: =1-(E18/D18) -> 0.23 | G18: =+P18/N18 -> 0.92699968 | H18: =+P18/L18 -> 0.9224219 | I18: =+R18/P18 -> 0.93898226 | J18: =+R18/L18 -> 0.8661378 | K18: =+S18/M18 -> 0.84829975 | L18: =+Efficiency1!K52 -> 46.442956 | M18: =M17+L18 -> 478.24722 | N18: =+Efficiency1!C52 -> 46.213608 | O18: =O17+N18 -> 468.52028 | P18: ='10'!I38 -> 42.84 | Q18: =Q17+P18 -> 420.732 | R18: ='10'!I40 -> 40.226 | S18: =S17+R18 -> 405.697 | T18: =+[1]Report1!AZ18 -> 3746.3635 | U18: =T18+U17 -> 33979.471 | V18: =T18/P18 -> 87.450129 | W18: =U18/Q18 -> 80.762744 | X18: =IF(AND(R18>0,T18>0),(T18/(R18*1000))*1000,0) -> 93.132887 | Y18: =IF(AND(S18>0,U18>0),U18/S18,0) -> 83.755785 | Z18: 85.6 | AA18: =Z18+AA17 -> 847.7 | AB18: 85.6 | AC18: =AA18/(Q18) -> 2.0148218 | AD18: =IF(AND(R18>0,Z18>0),Z18/(R18),0) -> 2.1279769 | AE18: =IF(AND(S18>0,AA18>0),AA18/(S18),0) -> 2.0894904 | AF18: 0 | AG18: =+AF18+AG17 -> 0 | AH18: =AF18/(P18) -> 0 | AI18: =AG18/(Q18) -> 0 | AJ18: =IF(AND(R18>0,AF18>0),AF18/(R18),0) -> 0 | AK18: =IF(AND(S18>0,AG18>0),AG18/(S18),0) -> 0 | AL18: ='10'!I46 -> 41126.405 | AM18: =AL18+AM17 -> 389037.96 | AN18: =IF(AND(L18>0,AL18>0),(AL18/(P18*1000)*1000),0) -> 960.00012 | AO18: =IF(AND(M18>0,AM18>0),(AM18/(Q18*1000)*1000),0) -> 924.66929 | AP18: =IF(AND(R18>0,AL18>0),(AL18/(R18*1000)*1000),0) -> 1022.3837 | AQ18: =IF(AND(S18>0,AM18>0),(AM18/(S18*1000)*1000),0) -> 958.93724 | AR18: =+Listrik!AA17 -> 0 | AS18: =AR18+AS17 -> 0 | AT18: =IF(AND(L18>0,AR18>0),(AR18/(P18*1000)*1000),0) -> 0 | AU18: =IF(AND(M18>0,AS18>0),(AS18/(Q18*1000)*1000),0) -> 0 | AV18: =IF(AND(R18>0,AR18>0),(AR18/(R18*1000)*1000),0) -> 0 | AW18: =IF(AND(S18>0,AS18>0),(AS18/(S18*1000)*1000),0) -> 0 | AX18: =+Listrik!AD17 -> 0 | AY18: =AX18+AY17 -> 0 | AZ18: =IF(AND(L18>0,AX18>0),(AX18/(P18*1000)*1000),0) -> 0 | BA18: =IF(AND(M18>0,AY18>0),(AY18/(Q18*1000)*1000),0) -> 0 | BB18: =IF(AND(R18>0,AX18>0),(AX18/(R18*1000)*1000),0) -> 0 | BC18: =IF(AND(S18>0,AY18>0),(AY18/(S18*1000)*1000),0) -> 0 | BE18: =+Efficiency2!K52 -> 46.442956 | BF18: =BF17+BE18 -> 470.01649 | BG18: =+R18/BE18 -> 0.8661378 | BH18: =+S18/BF18 -> 0.86315482
A19: =A18+1 -> 45849 | B19: Facial | C19: 12 | D19: =+'11'!F42 -> 1346.9792 | E19: =+'11'!G42 -> 1037.174 | F19: =1-(E19/D19) -> 0.23 | G19: =+P19/N19 -> 0.83439239 | H19: =+P19/L19 -> 0.8325253 | I19: =+R19/P19 -> 0.79663737 | J19: =+R19/L19 -> 0.66322077 | K19: =+S19/M19 -> 0.83168991 | L19: =+Efficiency1!K56 -> 47.15172 | M19: =M18+L19 -> 525.39894 | N19: =+Efficiency1!C56 -> 47.046211 | O19: =O18+N19 -> 515.56649 | P19: ='11'!I38 -> 39.255 | Q19: =Q18+P19 -> 459.987 | R19: ='11'!I40 -> 31.272 | S19: =S18+R19 -> 436.969 | T19: =+[1]Report1!AZ19 -> 3789.146 | U19: =T19+U18 -> 37768.617 | V19: =T19/P19 -> 96.526455 | W19: =U19/Q19 -> 82.108009 | X19: =IF(AND(R19>0,T19>0),(T19/(R19*1000))*1000,0) -> 121.16737 | Y19: =IF(AND(S19>0,U19>0),U19/S19,0) -> 86.433172 | Z19: 84.9 | AA19: =Z19+AA18 -> 932.6 | AB19: 84.9 | AC19: =AA19/(Q19) -> 2.0274486 | AD19: =IF(AND(R19>0,Z19>0),Z19/(R19),0) -> 2.7148887 | AE19: =IF(AND(S19>0,AA19>0),AA19/(S19),0) -> 2.1342475 | AF19: 0 | AG19: =+AF19+AG18 -> 0 | AH19: =AF19/(P19) -> 0 | AI19: =AG19/(Q19) -> 0 | AJ19: =IF(AND(R19>0,AF19>0),AF19/(R19),0) -> 0 | AK19: =IF(AND(S19>0,AG19>0),AG19/(S19),0) -> 0 | AL19: ='11'!I46 -> 42169.325 | AM19: =AL19+AM18 -> 431207.28 | AN19: =IF(AND(L19>0,AL19>0),(AL19/(P19*1000)*1000),0) -> 1074.2409 | AO19: =IF(AND(M19>0,AM19>0),(AM19/(Q19*1000)*1000),0) -> 937.43363 | AP19: =IF(AND(R19>0,AL19>0),(AL19/(R19*1000)*1000),0) -> 1348.4691 | AQ19: =IF(AND(S19>0,AM19>0),(AM19/(S19*1000)*1000),0) -> 986.81436 | AR19: =+Listrik!AA18 -> 0 | AS19: =AR19+AS18 -> 0 | AT19: =IF(AND(L19>0,AR19>0),(AR19/(P19*1000)*1000),0) -> 0 | AU19: =IF(AND(M19>0,AS19>0),(AS19/(Q19*1000)*1000),0) -> 0 | AV19: =IF(AND(R19>0,AR19>0),(AR19/(R19*1000)*1000),0) -> 0 | AW19: =IF(AND(S19>0,AS19>0),(AS19/(S19*1000)*1000),0) -> 0 | AX19: =+Listrik!AD18 -> 0 | AY19: =AX19+AY18 -> 0 | AZ19: =IF(AND(L19>0,AX19>0),(AX19/(P19*1000)*1000),0) -> 0 | BA19: =IF(AND(M19>0,AY19>0),(AY19/(Q19*1000)*1000),0) -> 0 | BB19: =IF(AND(R19>0,AX19>0),(AX19/(R19*1000)*1000),0) -> 0 | BC19: =IF(AND(S19>0,AY19>0),(AY19/(S19*1000)*1000),0) -> 0 | BE19: =+Efficiency2!K56 -> 47.15172 | BF19: =BF18+BE19 -> 517.16821 | BG19: =+R19/BE19 -> 0.66322077 | BH19: =+S19/BF19 -> 0.84492626
A20: =A19+1 -> 45850 | B20: Facial | C20: 12 | D20: =+'12'!F42 -> 1350 | E20: =+'12'!G42 -> 1039.5 | F20: =1-(E20/D20) -> 0.23 | G20: =+P20/N20 -> 0.90658185 | H20: =+P20/L20 -> 0.90658185 | I20: =+R20/P20 -> 0.93284576 | J20: =+R20/L20 -> 0.84570104 | K20: =+S20/M20 -> 0.83284502 | L20: =+Efficiency1!K60 -> 47.206989 | M20: =M19+L20 -> 572.60593 | N20: =+Efficiency1!C60 -> 47.206989 | O20: =O19+N20 -> 562.77348 | P20: ='12'!I38 -> 42.797 | Q20: =Q19+P20 -> 502.784 | R20: ='12'!I40 -> 39.923 | S20: =S19+R20 -> 476.892 | T20: =+[1]Report1!AZ20 -> 3793.5073 | U20: =T20+U19 -> 41562.124 | V20: =T20/P20 -> 88.63956 | W20: =U20/Q20 -> 82.663975 | X20: =IF(AND(R20>0,T20>0),(T20/(R20*1000))*1000,0) -> 95.020596 | Y20: =IF(AND(S20>0,U20>0),U20/S20,0) -> 87.152068 | Z20: 85.2 | AA20: =Z20+AA19 -> 1017.8 | AB20: 85.2 | AC20: =AA20/(Q20) -> 2.0243285 | AD20: =IF(AND(R20>0,Z20>0),Z20/(R20),0) -> 2.1341082 | AE20: =IF(AND(S20>0,AA20>0),AA20/(S20),0) -> 2.1342358 | AF20: 0 | AG20: =+AF20+AG19 -> 0 | AH20: =AF20/(P20) -> 0 | AI20: =AG20/(Q20) -> 0 | AJ20: =IF(AND(R20>0,AF20>0),AF20/(R20),0) -> 0 | AK20: =IF(AND(S20>0,AG20>0),AG20/(S20),0) -> 0 | AL20: ='12'!I46 -> 43096.13 | AM20: =AL20+AM19 -> 474303.41 | AN20: =IF(AND(L20>0,AL20>0),(AL20/(P20*1000)*1000),0) -> 1006.9895 | AO20: =IF(AND(M20>0,AM20>0),(AM20/(Q20*1000)*1000),0) -> 943.35423 | AP20: =IF(AND(R20>0,AL20>0),(AL20/(R20*1000)*1000),0) -> 1079.4813 | AQ20: =IF(AND(S20>0,AM20>0),(AM20/(S20*1000)*1000),0) -> 994.57197 | AR20: =+Listrik!AA19 -> 0 | AS20: =AR20+AS19 -> 0 | AT20: =IF(AND(L20>0,AR20>0),(AR20/(P20*1000)*1000),0) -> 0 | AU20: =IF(AND(M20>0,AS20>0),(AS20/(Q20*1000)*1000),0) -> 0 | AV20: =IF(AND(R20>0,AR20>0),(AR20/(R20*1000)*1000),0) -> 0 | AW20: =IF(AND(S20>0,AS20>0),(AS20/(S20*1000)*1000),0) -> 0 | AX20: =+Listrik!AD19 -> 0 | AY20: =AX20+AY19 -> 0 | AZ20: =IF(AND(L20>0,AX20>0),(AX20/(P20*1000)*1000),0) -> 0 | BA20: =IF(AND(M20>0,AY20>0),(AY20/(Q20*1000)*1000),0) -> 0 | BB20: =IF(AND(R20>0,AX20>0),(AX20/(R20*1000)*1000),0) -> 0 | BC20: =IF(AND(S20>0,AY20>0),(AY20/(S20*1000)*1000),0) -> 0 | BE20: =+Efficiency2!K60 -> 47.206989 | BF20: =BF19+BE20 -> 564.3752 | BG20: =+R20/BE20 -> 0.84570104 | BH20: =+S20/BF20 -> 0.84499106
A21: =A20+1 -> 45851 | B21: Facial | C21: 12 | D21: =+'13'!F42 -> 1314.9097 | E21: =+'13'!G42 -> 1012.4805 | F21: =1-(E21/D21) -> 0.23 | G21: =+P21/N21 -> 0.90202009 | H21: =+P21/L21 -> 0.87857407 | I21: =+R21/P21 -> 0.90127931 | J21: =+R21/L21 -> 0.79184063 | K21: =+S21/M21 -> 0.82970891 | L21: =+Efficiency1!K64 -> 47.421158 | M21: =M20+L21 -> 620.02709 | N21: =+Efficiency1!C64 -> 46.18855 | O21: =O20+N21 -> 608.96203 | P21: ='13'!I38 -> 41.663 | Q21: =Q20+P21 -> 544.447 | R21: ='13'!I40 -> 37.55 | S21: =S20+R21 -> 514.442 | T21: =+[1]Report1!AZ21 -> 3941.5255 | U21: =T21+U20 -> 45503.649 | V21: =T21/P21 -> 94.604937 | W21: =U21/Q21 -> 83.577739 | X21: =IF(AND(R21>0,T21>0),(T21/(R21*1000))*1000,0) -> 104.96739 | Y21: =IF(AND(S21>0,U21>0),U21/S21,0) -> 88.452439 | Z21: 83.1 | AA21: =Z21+AA20 -> 1100.9 | AB21: 83.1 | AC21: =AA21/(Q21) -> 2.0220517 | AD21: =IF(AND(R21>0,Z21>0),Z21/(R21),0) -> 2.2130493 | AE21: =IF(AND(S21>0,AA21>0),AA21/(S21),0) -> 2.1399886 | AF21: 0 | AG21: =+AF21+AG20 -> 0 | AH21: =AF21/(P21) -> 0 | AI21: =AG21/(Q21) -> 0 | AJ21: =IF(AND(R21>0,AF21>0),AF21/(R21),0) -> 0 | AK21: =IF(AND(S21>0,AG21>0),AG21/(S21),0) -> 0 | AL21: ='13'!I46 -> 40934.565 | AM21: =AL21+AM20 -> 515237.98 | AN21: =IF(AND(L21>0,AL21>0),(AL21/(P21*1000)*1000),0) -> 982.51602 | AO21: =IF(AND(M21>0,AM21>0),(AM21/(Q21*1000)*1000),0) -> 946.35103 | AP21: =IF(AND(R21>0,AL21>0),(AL21/(R21*1000)*1000),0) -> 1090.1349 | AQ21: =IF(AND(S21>0,AM21>0),(AM21/(S21*1000)*1000),0) -> 1001.5473 | AR21: =+Listrik!AA20 -> 0 | AS21: =AR21+AS20 -> 0 | AT21: =IF(AND(L21>0,AR21>0),(AR21/(P21*1000)*1000),0) -> 0 | AU21: =IF(AND(M21>0,AS21>0),(AS21/(Q21*1000)*1000),0) -> 0 | AV21: =IF(AND(R21>0,AR21>0),(AR21/(R21*1000)*1000),0) -> 0 | AW21: =IF(AND(S21>0,AS21>0),(AS21/(S21*1000)*1000),0) -> 0 | AX21: =+Listrik!AD20 -> 0 | AY21: =AX21+AY20 -> 0 | AZ21: =IF(AND(L21>0,AX21>0),(AX21/(P21*1000)*1000),0) -> 0 | BA21: =IF(AND(M21>0,AY21>0),(AY21/(Q21*1000)*1000),0) -> 0 | BB21: =IF(AND(R21>0,AX21>0),(AX21/(R21*1000)*1000),0) -> 0 | BC21: =IF(AND(S21>0,AY21>0),(AY21/(S21*1000)*1000),0) -> 0 | BE21: =+Efficiency2!K64 -> 47.421158 | BF21: =BF20+BE21 -> 611.79636 | BG21: =+R21/BE21 -> 0.79184063 | BH21: =+S21/BF21 -> 0.8408713
A22: =A21+1 -> 45852 | B22: Facial/Towel | C22: 12/15 | D22: =+'14'!F42 -> 1208.3333 | E22: =+'14'!G42 -> 950.08333 | F22: =1-(E22/D22) -> 0.21372414 | G22: =+P22/N22 -> 0.95067839 | H22: =+P22/L22 -> 0.95067839 | I22: =+R22/P22 -> 0.99006589 | J22: =+R22/L22 -> 0.94123425 | K22: =+S22/M22 -> 0.83836936 | L22: =+SUM(Efficiency1!K69:K70) -> 52.20167 | M22: =M21+L22 -> 672.22876 | N22: =+SUM(Efficiency1!C69:C70) -> 52.20167 | O22: =O21+N22 -> 661.1637 | P22: ='14'!I38 -> 49.627 | Q22: =Q21+P22 -> 594.074 | R22: ='14'!I40 -> 49.134 | S22: =S21+R22 -> 563.576 | T22: =+[1]Report1!AZ22 -> 3897.989 | U22: =T22+U21 -> 49401.639 | V22: =T22/P22 -> 78.545732 | W22: =U22/Q22 -> 83.157382 | X22: =IF(AND(R22>0,T22>0),(T22/(R22*1000))*1000,0) -> 79.333843 | Y22: =IF(AND(S22>0,U22>0),U22/S22,0) -> 87.657456 | Z22: 90.8 | AA22: =Z22+AA21 -> 1191.7 | AB22: 90.8 | AC22: =AA22/(Q22) -> 2.0059791 | AD22: =IF(AND(R22>0,Z22>0),Z22/(R22),0) -> 1.8480075 | AE22: =IF(AND(S22>0,AA22>0),AA22/(S22),0) -> 2.1145329 | AF22: 0 | AG22: =+AF22+AG21 -> 0 | AH22: =AF22/(P22) -> 0 | AI22: =AG22/(Q22) -> 0 | AJ22: =IF(AND(R22>0,AF22>0),AF22/(R22),0) -> 0 | AK22: =IF(AND(S22>0,AG22>0),AG22/(S22),0) -> 0 | AL22: ='14'!I46 -> 41816.96 | AM22: =AL22+AM21 -> 557054.94 | AN22: =IF(AND(L22>0,AL22>0),(AL22/(P22*1000)*1000),0) -> 842.62518 | AO22: =IF(AND(M22>0,AM22>0),(AM22/(Q22*1000)*1000),0) -> 937.68611 | AP22: =IF(AND(R22>0,AL22>0),(AL22/(R22*1000)*1000),0) -> 851.0799 | AQ22: =IF(AND(S22>0,AM22>0),(AM22/(S22*1000)*1000),0) -> 988.42914 | AR22: =+Listrik!AA21 -> 0 | AS22: =AR22+AS21 -> 0 | AT22: =IF(AND(L22>0,AR22>0),(AR22/(P22*1000)*1000),0) -> 0 | AU22: =IF(AND(M22>0,AS22>0),(AS22/(Q22*1000)*1000),0) -> 0 | AV22: =IF(AND(R22>0,AR22>0),(AR22/(R22*1000)*1000),0) -> 0 | AW22: =IF(AND(S22>0,AS22>0),(AS22/(S22*1000)*1000),0) -> 0 | AX22: =+Listrik!AD21 -> 0 | AY22: =AX22+AY21 -> 0 | AZ22: =IF(AND(L22>0,AX22>0),(AX22/(P22*1000)*1000),0) -> 0 | BA22: =IF(AND(M22>0,AY22>0),(AY22/(Q22*1000)*1000),0) -> 0 | BB22: =IF(AND(R22>0,AX22>0),(AX22/(R22*1000)*1000),0) -> 0 | BC22: =IF(AND(S22>0,AY22>0),(AY22/(S22*1000)*1000),0) -> 0 | BE22: =+SUM(Efficiency2!K69:K70) -> 52.20167 | BF22: =BF21+BE22 -> 663.99803 | BG22: =+R22/BE22 -> 0.94123425 | BH22: =+S22/BF22 -> 0.84876156
A23: =A22+1 -> 45853 | B23: Towel/Facial | C23: 15/12 | D23: =+'15'!F42 -> 1293.3333 | E23: =+'15'!G42 -> 1003.7333 | F23: =1-(E23/D23) -> 0.22391753 | G23: =+P23/N23 -> 1.0155787 | H23: =+P23/L23 -> 1.0155787 | I23: =+R23/P23 -> 1.0535312 | J23: =+R23/L23 -> 1.0699438 | K23: =+S23/M23 -> 0.85381641 | L23: =+SUM(Efficiency1!K73:K74) -> 48.045514 | M23: =M22+L23 -> 720.27428 | N23: =+SUM(Efficiency1!C73:C74) -> 48.045514 | O23: =O22+N23 -> 709.20921 | P23: ='15'!I38 -> 48.794 | Q23: =Q22+P23 -> 642.868 | R23: ='15'!I40 -> 51.406 | S23: =S22+R23 -> 614.982 | T23: =+[1]Report1!AZ23 -> 3756.5645 | U23: =T23+U22 -> 53158.203 | V23: =T23/P23 -> 76.988247 | W23: =U23/Q23 -> 82.689142 | X23: =IF(AND(R23>0,T23>0),(T23/(R23*1000))*1000,0) -> 73.076383 | Y23: =IF(AND(S23>0,U23>0),U23/S23,0) -> 86.438632 | Z23: 89 | AA23: =Z23+AA22 -> 1280.7 | AB23: 89 | AC23: =AA23/(Q23) -> 1.9921664 | AD23: =IF(AND(R23>0,Z23>0),Z23/(R23),0) -> 1.7313154 | AE23: =IF(AND(S23>0,AA23>0),AA23/(S23),0) -> 2.0825 | AF23: 0 | AG23: =+AF23+AG22 -> 0 | AH23: =AF23/(P23) -> 0 | AI23: =AG23/(Q23) -> 0 | AJ23: =IF(AND(R23>0,AF23>0),AF23/(R23),0) -> 0 | AK23: =IF(AND(S23>0,AG23>0),AG23/(S23),0) -> 0 | AL23: ='15'!I46 -> 40653.015 | AM23: =AL23+AM22 -> 597707.95 | AN23: =IF(AND(L23>0,AL23>0),(AL23/(P23*1000)*1000),0) -> 833.15602 | AO23: =IF(AND(M23>0,AM23>0),(AM23/(Q23*1000)*1000),0) -> 929.75223 | AP23: =IF(AND(R23>0,AL23>0),(AL23/(R23*1000)*1000),0) -> 790.82237 | AQ23: =IF(AND(S23>0,AM23>0),(AM23/(S23*1000)*1000),0) -> 971.9113 | AR23: =+Listrik!AA22 -> 0 | AS23: =AR23+AS22 -> 0 | AT23: =IF(AND(L23>0,AR23>0),(AR23/(P23*1000)*1000),0) -> 0 | AU23: =IF(AND(M23>0,AS23>0),(AS23/(Q23*1000)*1000),0) -> 0 | AV23: =IF(AND(R23>0,AR23>0),(AR23/(R23*1000)*1000),0) -> 0 | AW23: =IF(AND(S23>0,AS23>0),(AS23/(S23*1000)*1000),0) -> 0 | AX23: =+Listrik!AD22 -> 2300 | AY23: =AX23+AY22 -> 2300 | AZ23: =IF(AND(L23>0,AX23>0),(AX23/(P23*1000)*1000),0) -> 47.136943 | BA23: =IF(AND(M23>0,AY23>0),(AY23/(Q23*1000)*1000),0) -> 3.5777174 | BB23: =IF(AND(R23>0,AX23>0),(AX23/(R23*1000)*1000),0) -> 44.741859 | BC23: =IF(AND(S23>0,AY23>0),(AY23/(S23*1000)*1000),0) -> 3.7399469 | BE23: =+SUM(Efficiency2!K73:K74) -> 48.045514 | BF23: =BF22+BE23 -> 712.04354 | BG23: =+R23/BE23 -> 1.0699438 | BH23: =+S23/BF23 -> 0.86368595
A24: =A23+1 -> 45854 | B24: Facial | C24: 12/11,5 | D24: =+'16'!F42 -> 1350 | E24: =+'16'!G42 -> 1039.5 | F24: =1-(E24/D24) -> 0.23 | G24: =+P24/N24 -> 0.97939134 | H24: =+P24/L24 -> 0.97939134 | I24: =+R24/P24 -> 0.92307864 | J24: =+R24/L24 -> 0.90405523 | K24: =+S24/M24 -> 0.85680899 | L24: =+SUM(Efficiency1!K77:K78) -> 45.622213 | M24: =M23+L24 -> 765.89649 | N24: =+SUM(Efficiency1!C77:C78) -> 45.622213 | O24: =O23+N24 -> 754.83142 | P24: ='16'!I38 -> 44.682 | Q24: =Q23+P24 -> 687.55 | R24: ='16'!I40 -> 41.245 | S24: =S23+R24 -> 656.227 | T24: =+[1]Report1!AZ24 -> 3749.8233 | U24: =T24+U23 -> 56908.026 | V24: =T24/P24 -> 83.922459 | W24: =U24/Q24 -> 82.769291 | X24: =IF(AND(R24>0,T24>0),(T24/(R24*1000))*1000,0) -> 90.915828 | Y24: =IF(AND(S24>0,U24>0),U24/S24,0) -> 86.720032 | Z24: 84.93 | AA24: =Z24+AA23 -> 1365.63 | AB24: 84.93 | AC24: =AA24/(Q24) -> 1.9862265 | AD24: =IF(AND(R24>0,Z24>0),Z24/(R24),0) -> 2.0591587 | AE24: =IF(AND(S24>0,AA24>0),AA24/(S24),0) -> 2.0810329 | AF24: 0 | AG24: =+AF24+AG23 -> 0 | AH24: =AF24/(P24) -> 0 | AI24: =AG24/(Q24) -> 0 | AJ24: =IF(AND(R24>0,AF24>0),AF24/(R24),0) -> 0 | AK24: =IF(AND(S24>0,AG24>0),AG24/(S24),0) -> 0 | AL24: ='16'!I46 -> 41299.89 | AM24: =AL24+AM23 -> 639007.84 | AN24: =IF(AND(L24>0,AL24>0),(AL24/(P24*1000)*1000),0) -> 924.3071 | AO24: =IF(AND(M24>0,AM24>0),(AM24/(Q24*1000)*1000),0) -> 929.39836 | AP24: =IF(AND(R24>0,AL24>0),(AL24/(R24*1000)*1000),0) -> 1001.3308 | AQ24: =IF(AND(S24>0,AM24>0),(AM24/(S24*1000)*1000),0) -> 973.76037 | AR24: =+Listrik!AA23 -> 0 | AS24: =AR24+AS23 -> 0 | AT24: =IF(AND(L24>0,AR24>0),(AR24/(P24*1000)*1000),0) -> 0 | AU24: =IF(AND(M24>0,AS24>0),(AS24/(Q24*1000)*1000),0) -> 0 | AV24: =IF(AND(R24>0,AR24>0),(AR24/(R24*1000)*1000),0) -> 0 | AW24: =IF(AND(S24>0,AS24>0),(AS24/(S24*1000)*1000),0) -> 0 | AX24: =+Listrik!AD23 -> 3830 | AY24: =AX24+AY23 -> 6130 | AZ24: =IF(AND(L24>0,AX24>0),(AX24/(P24*1000)*1000),0) -> 85.716843 | BA24: =IF(AND(M24>0,AY24>0),(AY24/(Q24*1000)*1000),0) -> 8.9157152 | BB24: =IF(AND(R24>0,AX24>0),(AX24/(R24*1000)*1000),0) -> 92.859741 | BC24: =IF(AND(S24>0,AY24>0),(AY24/(S24*1000)*1000),0) -> 9.3412798 | BE24: =+SUM(Efficiency2!K77:K78) -> 45.622213 | BF24: =BF23+BE24 -> 757.66575 | BG24: =+R24/BE24 -> 0.90405523 | BH24: =+S24/BF24 -> 0.86611675
A25: =A24+1 -> 45855 | B25: Facial | C25: 11,5 | D25: =+'17'!F42 -> 1350 | E25: =+'17'!G42 -> 1039.5 | F25: =1-(E25/D25) -> 0.23 | G25: =+P25/N25 -> 0.93387344 | H25: =+P25/L25 -> 0.93387344 | I25: =+R25/P25 -> 0.94895614 | J25: =+R25/L25 -> 0.88620493 | K25: =+S25/M25 -> 0.8584467 | L25: =+Efficiency1!K81 -> 45.187065 | M25: =M24+L25 -> 811.08355 | N25: =+Efficiency1!C81 -> 45.187065 | O25: =O24+N25 -> 800.01849 | P25: ='17'!I38 -> 42.199 | Q25: =Q24+P25 -> 729.749 | R25: ='17'!I40 -> 40.045 | S25: =S24+R25 -> 696.272 | T25: =+[1]Report1!AZ25 -> 3692.4809 | U25: =T25+U24 -> 60600.507 | V25: =T25/P25 -> 87.501621 | W25: =U25/Q25 -> 83.042947 | X25: =IF(AND(R25>0,T25>0),(T25/(R25*1000))*1000,0) -> 92.208288 | Y25: =IF(AND(S25>0,U25>0),U25/S25,0) -> 87.03568 | Z25: 84.6 | AA25: =Z25+AA24 -> 1450.23 | AB25: 84.6 | AC25: =AA25/(Q25) -> 1.9872997 | AD25: =IF(AND(R25>0,Z25>0),Z25/(R25),0) -> 2.1126233 | AE25: =IF(AND(S25>0,AA25>0),AA25/(S25),0) -> 2.0828498 | AF25: 0 | AG25: =+AF25+AG24 -> 0 | AH25: =AF25/(P25) -> 0 | AI25: =AG25/(Q25) -> 0 | AJ25: =IF(AND(R25>0,AF25>0),AF25/(R25),0) -> 0 | AK25: =IF(AND(S25>0,AG25>0),AG25/(S25),0) -> 0 | AL25: ='17'!I46 -> 40405.75 | AM25: =AL25+AM24 -> 679413.59 | AN25: =IF(AND(L25>0,AL25>0),(AL25/(P25*1000)*1000),0) -> 957.50492 | AO25: =IF(AND(M25>0,AM25>0),(AM25/(Q25*1000)*1000),0) -> 931.02367 | AP25: =IF(AND(R25>0,AL25>0),(AL25/(R25*1000)*1000),0) -> 1009.0086 | AQ25: =IF(AND(S25>0,AM25>0),(AM25/(S25*1000)*1000),0) -> 975.78762 | AR25: =+Listrik!AA24 -> 0 | AS25: =AR25+AS24 -> 0 | AT25: =IF(AND(L25>0,AR25>0),(AR25/(P25*1000)*1000),0) -> 0 | AU25: =IF(AND(M25>0,AS25>0),(AS25/(Q25*1000)*1000),0) -> 0 | AV25: =IF(AND(R25>0,AR25>0),(AR25/(R25*1000)*1000),0) -> 0 | AW25: =IF(AND(S25>0,AS25>0),(AS25/(S25*1000)*1000),0) -> 0 | AX25: =+Listrik!AD24 -> 3650 | AY25: =AX25+AY24 -> 9780 | AZ25: =IF(AND(L25>0,AX25>0),(AX25/(P25*1000)*1000),0) -> 86.494941 | BA25: =IF(AND(M25>0,AY25>0),(AY25/(Q25*1000)*1000),0) -> 13.401868 | BB25: =IF(AND(R25>0,AX25>0),(AX25/(R25*1000)*1000),0) -> 91.147459 | BC25: =IF(AND(S25>0,AY25>0),(AY25/(S25*1000)*1000),0) -> 14.046235 | BE25: =+Efficiency2!K81 -> 45.187065 | BF25: =BF24+BE25 -> 802.85282 | BG25: =+R25/BE25 -> 0.88620493 | BH25: =+S25/BF25 -> 0.86724738
A26: =A25+1 -> 45856 | B26: Facial | C26: 11,5/12 | D26: =+'18'!F42 -> 1350 | E26: =+'18'!G42 -> 1039.5 | F26: =1-(E26/D26) -> 0.23 | G26: =+P26/N26 -> 1.0010798 | H26: =+P26/L26 -> 1.0010798 | I26: =+R26/P26 -> 1.026376 | J26: =+R26/L26 -> 1.0274843 | K26: =+S26/M26 -> 0.8677265 | L26: =+SUM(Efficiency1!K86:K87) -> 47.113129 | M26: =M25+L26 -> 858.19668 | N26: =+SUM(Efficiency1!C86:C87) -> 47.113129 | O26: =O25+N26 -> 847.13162 | P26: ='18'!I38 -> 47.164 | Q26: =Q25+P26 -> 776.913 | R26: ='18'!I40 -> 48.408 | S26: =S25+R26 -> 744.68 | T26: =+[1]Report1!AZ26 -> 3780.6825 | U26: =T26+U25 -> 64381.19 | V26: =T26/P26 -> 80.160344 | W26: =U26/Q26 -> 82.867953 | X26: =IF(AND(R26>0,T26>0),(T26/(R26*1000))*1000,0) -> 78.100365 | Y26: =IF(AND(S26>0,U26>0),U26/S26,0) -> 86.454839 | Z26: 85.9 | AA26: =Z26+AA25 -> 1536.13 | AB26: 85.9 | AC26: =AA26/(Q26) -> 1.9772227 | AD26: =IF(AND(R26>0,Z26>0),Z26/(R26),0) -> 1.7745001 | AE26: =IF(AND(S26>0,AA26>0),AA26/(S26),0) -> 2.0628055 | AF26: 0 | AG26: =+AF26+AG25 -> 0 | AH26: =AF26/(P26) -> 0 | AI26: =AG26/(Q26) -> 0 | AJ26: =IF(AND(R26>0,AF26>0),AF26/(R26),0) -> 0 | AK26: =IF(AND(S26>0,AG26>0),AG26/(S26),0) -> 0 | AL26: ='18'!I46 -> 39345.435 | AM26: =AL26+AM25 -> 718759.03 | AN26: =IF(AND(L26>0,AL26>0),(AL26/(P26*1000)*1000),0) -> 834.226 | AO26: =IF(AND(M26>0,AM26>0),(AM26/(Q26*1000)*1000),0) -> 925.14738 | AP26: =IF(AND(R26>0,AL26>0),(AL26/(R26*1000)*1000),0) -> 812.78787 | AQ26: =IF(AND(S26>0,AM26>0),(AM26/(S26*1000)*1000),0) -> 965.1918 | AR26: =+Listrik!AA25 -> 0 | AS26: =AR26+AS25 -> 0 | AT26: =IF(AND(L26>0,AR26>0),(AR26/(P26*1000)*1000),0) -> 0 | AU26: =IF(AND(M26>0,AS26>0),(AS26/(Q26*1000)*1000),0) -> 0 | AV26: =IF(AND(R26>0,AR26>0),(AR26/(R26*1000)*1000),0) -> 0 | AW26: =IF(AND(S26>0,AS26>0),(AS26/(S26*1000)*1000),0) -> 0 | AX26: =+Listrik!AD25 -> 4050 | AY26: =AX26+AY25 -> 13830 | AZ26: =IF(AND(L26>0,AX26>0),(AX26/(P26*1000)*1000),0) -> 85.870579 | BA26: =IF(AND(M26>0,AY26>0),(AY26/(Q26*1000)*1000),0) -> 17.801221 | BB26: =IF(AND(R26>0,AX26>0),(AX26/(R26*1000)*1000),0) -> 83.663857 | BC26: =IF(AND(S26>0,AY26>0),(AY26/(S26*1000)*1000),0) -> 18.571736 | BE26: =+SUM(Efficiency2!K86:K87) -> 47.113129 | BF26: =BF25+BE26 -> 849.96595 | BG26: =+R26/BE26 -> 1.0274843 | BH26: =+S26/BF26 -> 0.87612922
A27: =A26+1 -> 45857 | B27: Facial | C27: 12 | D27: =+'19'!F42 -> 1350 | E27: =+'19'!G42 -> 1039.5 | F27: =1-(E27/D27) -> 0.23 | G27: =+P27/N27 -> 0.96734206 | H27: =+P27/L27 -> 0.96734206 | I27: =+R27/P27 -> 0.88680225 | J27: =+R27/L27 -> 0.85784112 | K27: =+S27/M27 -> 0.86720515 | L27: =+Efficiency1!K90 -> 47.78041 | M27: =M26+L27 -> 905.97709 | N27: =+Efficiency1!C90 -> 47.78041 | O27: =O26+N27 -> 894.91203 | P27: ='19'!I38 -> 46.22 | Q27: =Q26+P27 -> 823.133 | R27: ='19'!I40 -> 40.988 | S27: =S26+R27 -> 785.668 | T27: =+[1]Report1!AZ27 -> 3788.8914 | U27: =T27+U26 -> 68170.081 | V27: =T27/P27 -> 81.97515 | W27: =U27/Q27 -> 82.817821 | X27: =IF(AND(R27>0,T27>0),(T27/(R27*1000))*1000,0) -> 92.439041 | Y27: =IF(AND(S27>0,U27>0),U27/S27,0) -> 86.767033 | Z27: 87.1 | AA27: =Z27+AA26 -> 1623.23 | AB27: 87.1 | AC27: =AA27/(Q27) -> 1.9720142 | AD27: =IF(AND(R27>0,Z27>0),Z27/(R27),0) -> 2.1250122 | AE27: =IF(AND(S27>0,AA27>0),AA27/(S27),0) -> 2.0660508 | AF27: 0 | AG27: =+AF27+AG26 -> 0 | AH27: =AF27/(P27) -> 0 | AI27: =AG27/(Q27) -> 0 | AJ27: =IF(AND(R27>0,AF27>0),AF27/(R27),0) -> 0 | AK27: =IF(AND(S27>0,AG27>0),AG27/(S27),0) -> 0 | AL27: ='19'!I46 -> 40886.005 | AM27: =AL27+AM26 -> 759645.03 | AN27: =IF(AND(L27>0,AL27>0),(AL27/(P27*1000)*1000),0) -> 884.59552 | AO27: =IF(AND(M27>0,AM27>0),(AM27/(Q27*1000)*1000),0) -> 922.87034 | AP27: =IF(AND(R27>0,AL27>0),(AL27/(R27*1000)*1000),0) -> 997.51159 | AQ27: =IF(AND(S27>0,AM27>0),(AM27/(S27*1000)*1000),0) -> 966.87791 | AR27: =+Listrik!AA26 -> 0 | AS27: =AR27+AS26 -> 0 | AT27: =IF(AND(L27>0,AR27>0),(AR27/(P27*1000)*1000),0) -> 0 | AU27: =IF(AND(M27>0,AS27>0),(AS27/(Q27*1000)*1000),0) -> 0 | AV27: =IF(AND(R27>0,AR27>0),(AR27/(R27*1000)*1000),0) -> 0 | AW27: =IF(AND(S27>0,AS27>0),(AS27/(S27*1000)*1000),0) -> 0 | AX27: =+Listrik!AD26 -> 3890 | AY27: =AX27+AY26 -> 17720 | AZ27: =IF(AND(L27>0,AX27>0),(AX27/(P27*1000)*1000),0) -> 84.1627 | BA27: =IF(AND(M27>0,AY27>0),(AY27/(Q27*1000)*1000),0) -> 21.527505 | BB27: =IF(AND(R27>0,AX27>0),(AX27/(R27*1000)*1000),0) -> 94.905826 | BC27: =IF(AND(S27>0,AY27>0),(AY27/(S27*1000)*1000),0) -> 22.554056 | BE27: =+Efficiency2!K90 -> 47.78041 | BF27: =BF26+BE27 -> 897.74636 | BG27: =+R27/BE27 -> 0.85784112 | BH27: =+S27/BF27 -> 0.87515588
A28: =A27+1 -> 45858 | B28: Facial | C28: 12 | D28: =+'20'!F42 -> 1350 | E28: =+'20'!G42 -> 1039.5 | F28: =1-(E28/D28) -> 0.23 | G28: =+P28/N28 -> 0.93716503 | H28: =+P28/L28 -> 0.93716503 | I28: =+R28/P28 -> 1.0495224 | J28: =+R28/L28 -> 0.98357574 | K28: =+S28/M28 -> 0.87302617 | L28: =+Efficiency1!K94 -> 47.704511 | M28: =M27+L28 -> 953.6816 | N28: =+Efficiency1!C94 -> 47.704511 | O28: =O27+N28 -> 942.61654 | P28: ='20'!I38 -> 44.707 | Q28: =Q27+P28 -> 867.84 | R28: ='20'!I40 -> 46.921 | S28: =S27+R28 -> 832.589 | T28: =+[1]Report1!AZ28 -> 3848.956 | U28: =T28+U27 -> 72019.037 | V28: =T28/P28 -> 86.092916 | W28: =U28/Q28 -> 82.986538 | X28: =IF(AND(R28>0,T28>0),(T28/(R28*1000))*1000,0) -> 82.030562 | Y28: =IF(AND(S28>0,U28>0),U28/S28,0) -> 86.500106 | Z28: 87.2 | AA28: =Z28+AA27 -> 1710.43 | AB28: 87.2 | AC28: =AA28/(Q28) -> 1.9709048 | AD28: =IF(AND(R28>0,Z28>0),Z28/(R28),0) -> 1.8584429 | AE28: =IF(AND(S28>0,AA28>0),AA28/(S28),0) -> 2.0543509 | AF28: 0 | AG28: =+AF28+AG27 -> 0 | AH28: =AF28/(P28) -> 0 | AI28: =AG28/(Q28) -> 0 | AJ28: =IF(AND(R28>0,AF28>0),AF28/(R28),0) -> 0 | AK28: =IF(AND(S28>0,AG28>0),AG28/(S28),0) -> 0 | AL28: ='20'!I46 -> 40534.33 | AM28: =AL28+AM27 -> 800179.36 | AN28: =IF(AND(L28>0,AL28>0),(AL28/(P28*1000)*1000),0) -> 906.66629 | AO28: =IF(AND(M28>0,AM28>0),(AM28/(Q28*1000)*1000),0) -> 922.03559 | AP28: =IF(AND(R28>0,AL28>0),(AL28/(R28*1000)*1000),0) -> 863.88461 | AQ28: =IF(AND(S28>0,AM28>0),(AM28/(S28*1000)*1000),0) -> 961.07367 | AR28: =+Listrik!AA27 -> 0 | AS28: =AR28+AS27 -> 0 | AT28: =IF(AND(L28>0,AR28>0),(AR28/(P28*1000)*1000),0) -> 0 | AU28: =IF(AND(M28>0,AS28>0),(AS28/(Q28*1000)*1000),0) -> 0 | AV28: =IF(AND(R28>0,AR28>0),(AR28/(R28*1000)*1000),0) -> 0 | AW28: =IF(AND(S28>0,AS28>0),(AS28/(S28*1000)*1000),0) -> 0 | AX28: =+Listrik!AD27 -> 2720 | AY28: =AX28+AY27 -> 20440 | AZ28: =IF(AND(L28>0,AX28>0),(AX28/(P28*1000)*1000),0) -> 60.840584 | BA28: =IF(AND(M28>0,AY28>0),(AY28/(Q28*1000)*1000),0) -> 23.552729 | BB28: =IF(AND(R28>0,AX28>0),(AX28/(R28*1000)*1000),0) -> 57.969779 | BC28: =IF(AND(S28>0,AY28>0),(AY28/(S28*1000)*1000),0) -> 24.549928 | BE28: =+Efficiency2!K94 -> 47.704511 | BF28: =BF27+BE28 -> 945.45087 | BG28: =+R28/BE28 -> 0.98357574 | BH28: =+S28/BF28 -> 0.88062641
A29: =A28+1 -> 45859 | B29: Facial | C29: 12 | D29: =+'21'!F42 -> 1350 | E29: =+'21'!G42 -> 1039.5 | F29: =1-(E29/D29) -> 0.23 | G29: =+P29/N29 -> 0.985854 | H29: =+P29/L29 -> 0.985854 | I29: =+R29/P29 -> 0.98838017 | J29: =+R29/L29 -> 0.97439854 | K29: =+S29/M29 -> 0.87775871 | L29: =+Efficiency1!K98 -> 46.702656 | M29: =M28+L29 -> 1000.3843 | N29: =+Efficiency1!C98 -> 46.702656 | O29: =O28+N29 -> 989.31919 | P29: ='21'!I38 -> 46.042 | Q29: =Q28+P29 -> 913.882 | R29: ='21'!I40 -> 45.507 | S29: =S28+R29 -> 878.096 | T29: =+[1]Report1!AZ29 -> 3772.4844 | U29: =T29+U28 -> 75791.522 | V29: =T29/P29 -> 81.935719 | W29: =U29/Q29 -> 82.933597 | X29: =IF(AND(R29>0,T29>0),(T29/(R29*1000))*1000,0) -> 82.89899 | Y29: =IF(AND(S29>0,U29>0),U29/S29,0) -> 86.31348 | Z29: 87.2 | AA29: =Z29+AA28 -> 1797.63 | AB29: 87.2 | AC29: =AA29/(Q29) -> 1.9670264 | AD29: =IF(AND(R29>0,Z29>0),Z29/(R29),0) -> 1.9161887 | AE29: =IF(AND(S29>0,AA29>0),AA29/(S29),0) -> 2.0471907 | AF29: 0 | AG29: =+AF29+AG28 -> 0 | AH29: =AF29/(P29) -> 0 | AI29: =AG29/(Q29) -> 0 | AJ29: =IF(AND(R29>0,AF29>0),AF29/(R29),0) -> 0 | AK29: =IF(AND(S29>0,AG29>0),AG29/(S29),0) -> 0 | AL29: ='21'!I46 -> 43722.395 | AM29: =AL29+AM28 -> 843901.76 | AN29: =IF(AND(L29>0,AL29>0),(AL29/(P29*1000)*1000),0) -> 949.6198 | AO29: =IF(AND(M29>0,AM29>0),(AM29/(Q29*1000)*1000),0) -> 923.4253 | AP29: =IF(AND(R29>0,AL29>0),(AL29/(R29*1000)*1000),0) -> 960.78395 | AQ29: =IF(AND(S29>0,AM29>0),(AM29/(S29*1000)*1000),0) -> 961.05865 | AR29: =+Listrik!AA28 -> 0 | AS29: =AR29+AS28 -> 0 | AT29: =IF(AND(L29>0,AR29>0),(AR29/(P29*1000)*1000),0) -> 0 | AU29: =IF(AND(M29>0,AS29>0),(AS29/(Q29*1000)*1000),0) -> 0 | AV29: =IF(AND(R29>0,AR29>0),(AR29/(R29*1000)*1000),0) -> 0 | AW29: =IF(AND(S29>0,AS29>0),(AS29/(S29*1000)*1000),0) -> 0 | AX29: =+Listrik!AD28 -> 0 | AY29: =AX29+AY28 -> 20440 | AZ29: =IF(AND(L29>0,AX29>0),(AX29/(P29*1000)*1000),0) -> 0 | BA29: =IF(AND(M29>0,AY29>0),(AY29/(Q29*1000)*1000),0) -> 22.366126 | BB29: =IF(AND(R29>0,AX29>0),(AX29/(R29*1000)*1000),0) -> 0 | BC29: =IF(AND(S29>0,AY29>0),(AY29/(S29*1000)*1000),0) -> 23.277637 | BE29: =+Efficiency2!K98 -> 46.702656 | BF29: =BF28+BE29 -> 992.15352 | BG29: =+R29/BE29 -> 0.97439854 | BH29: =+S29/BF29 -> 0.88504045
A30: =A29+1 -> 45860 | B30: Facial | C30: 12/13 | D30: =+'22'!F42 -> 1350 | E30: =+'22'!G42 -> 1039.5 | F30: =1-(E30/D30) -> 0.23 | G30: =+P30/N30 -> 0.95194478 | H30: =+P30/L30 -> 0.95194478 | I30: =+R30/P30 -> 0.94858293 | J30: =+R30/L30 -> 0.90299856 | K30: =+S30/M30 -> 0.87893897 | L30: =+SUM(Efficiency1!K102:K103) -> 49.074275 | M30: =M29+L30 -> 1049.4585 | N30: =+SUM(Efficiency1!C102:C103) -> 49.074275 | O30: =O29+N30 -> 1038.3935 | P30: ='22'!I38 -> 46.716 | Q30: =Q29+P30 -> 960.598 | R30: ='22'!I40 -> 44.314 | S30: =S29+R30 -> 922.41 | T30: =+[1]Report1!AZ30 -> 3729.7432 | U30: =T30+U29 -> 79521.265 | V30: =T30/P30 -> 79.838668 | W30: =U30/Q30 -> 82.783084 | X30: =IF(AND(R30>0,T30>0),(T30/(R30*1000))*1000,0) -> 84.166251 | Y30: =IF(AND(S30>0,U30>0),U30/S30,0) -> 86.210324 | Z30: 90 | AA30: =Z30+AA29 -> 1887.63 | AB30: 90 | AC30: =AA30/(Q30) -> 1.9650572 | AD30: =IF(AND(R30>0,Z30>0),Z30/(R30),0) -> 2.0309609 | AE30: =IF(AND(S30>0,AA30>0),AA30/(S30),0) -> 2.046411 | AF30: 0 | AG30: =+AF30+AG29 -> 0 | AH30: =AF30/(P30) -> 0 | AI30: =AG30/(Q30) -> 0 | AJ30: =IF(AND(R30>0,AF30>0),AF30/(R30),0) -> 0 | AK30: =IF(AND(S30>0,AG30>0),AG30/(S30),0) -> 0 | AL30: ='22'!I46 -> 45912.47 | AM30: =AL30+AM29 -> 889814.23 | AN30: =IF(AND(L30>0,AL30>0),(AL30/(P30*1000)*1000),0) -> 982.79968 | AO30: =IF(AND(M30>0,AM30>0),(AM30/(Q30*1000)*1000),0) -> 926.31281 | AP30: =IF(AND(R30>0,AL30>0),(AL30/(R30*1000)*1000),0) -> 1036.0714 | AQ30: =IF(AND(S30>0,AM30>0),(AM30/(S30*1000)*1000),0) -> 964.66238 | AR30: =+Listrik!AA29 -> 0 | AS30: =AR30+AS29 -> 0 | AT30: =IF(AND(L30>0,AR30>0),(AR30/(P30*1000)*1000),0) -> 0 | AU30: =IF(AND(M30>0,AS30>0),(AS30/(Q30*1000)*1000),0) -> 0 | AV30: =IF(AND(R30>0,AR30>0),(AR30/(R30*1000)*1000),0) -> 0 | AW30: =IF(AND(S30>0,AS30>0),(AS30/(S30*1000)*1000),0) -> 0 | AX30: =+Listrik!AD29 -> 0 | AY30: =AX30+AY29 -> 20440 | AZ30: =IF(AND(L30>0,AX30>0),(AX30/(P30*1000)*1000),0) -> 0 | BA30: =IF(AND(M30>0,AY30>0),(AY30/(Q30*1000)*1000),0) -> 21.278412 | BB30: =IF(AND(R30>0,AX30>0),(AX30/(R30*1000)*1000),0) -> 0 | BC30: =IF(AND(S30>0,AY30>0),(AY30/(S30*1000)*1000),0) -> 22.159343 | BE30: =+SUM(Efficiency2!K102:K103) -> 49.074275 | BF30: =BF29+BE30 -> 1041.2278 | BG30: =+R30/BE30 -> 0.90299856 | BH30: =+S30/BF30 -> 0.88588683
A31: =A30+1 -> 45861 | B31: Facial | C31: 13/12/12,5 | D31: =+'23'!F42 -> 1350 | E31: =+'23'!G42 -> 1039.5 | F31: =1-(E31/D31) -> 0.23 | G31: =+P31/N31 -> 0.92770546 | H31: =+P31/L31 -> 0.92770546 | I31: =+R31/P31 -> 0.97347154 | J31: =+R31/L31 -> 0.90309486 | K31: =+S31/M31 -> 0.88001829 | L31: =+SUM(Efficiency1!K106:K108) -> 49.084545 | M31: =M30+L31 -> 1098.5431 | N31: =+SUM(Efficiency1!C106:C108) -> 49.084545 | O31: =O30+N31 -> 1087.478 | P31: ='23'!I38 -> 45.536 | Q31: =Q30+P31 -> 1006.134 | R31: ='23'!I40 -> 44.328 | S31: =S30+R31 -> 966.738 | T31: =+[1]Report1!AZ31 -> 3622.0686 | U31: =T31+U30 -> 83143.333 | V31: =T31/P31 -> 79.542969 | W31: =U31/Q31 -> 82.636441 | X31: =IF(AND(R31>0,T31>0),(T31/(R31*1000))*1000,0) -> 81.710626 | Y31: =IF(AND(S31>0,U31>0),U31/S31,0) -> 86.003998 | Z31: 89 | AA31: =Z31+AA30 -> 1976.63 | AB31: 89 | AC31: =AA31/(Q31) -> 1.9645793 | AD31: =IF(AND(R31>0,Z31>0),Z31/(R31),0) -> 2.0077603 | AE31: =IF(AND(S31>0,AA31>0),AA31/(S31),0) -> 2.0446388 | AF31: 0 | AG31: =+AF31+AG30 -> 0 | AH31: =AF31/(P31) -> 0 | AI31: =AG31/(Q31) -> 0 | AJ31: =IF(AND(R31>0,AF31>0),AF31/(R31),0) -> 0 | AK31: =IF(AND(S31>0,AG31>0),AG31/(S31),0) -> 0 | AL31: ='23'!I46 -> 40393.515 | AM31: =AL31+AM30 -> 930207.74 | AN31: =IF(AND(L31>0,AL31>0),(AL31/(P31*1000)*1000),0) -> 887.0677 | AO31: =IF(AND(M31>0,AM31>0),(AM31/(Q31*1000)*1000),0) -> 924.53664 | AP31: =IF(AND(R31>0,AL31>0),(AL31/(R31*1000)*1000),0) -> 911.24154 | AQ31: =IF(AND(S31>0,AM31>0),(AM31/(S31*1000)*1000),0) -> 962.21287 | AR31: =+Listrik!AA30 -> 0 | AS31: =AR31+AS30 -> 0 | AT31: =IF(AND(L31>0,AR31>0),(AR31/(P31*1000)*1000),0) -> 0 | AU31: =IF(AND(M31>0,AS31>0),(AS31/(Q31*1000)*1000),0) -> 0 | AV31: =IF(AND(R31>0,AR31>0),(AR31/(R31*1000)*1000),0) -> 0 | AW31: =IF(AND(S31>0,AS31>0),(AS31/(S31*1000)*1000),0) -> 0 | AX31: =+Listrik!AD30 -> 0 | AY31: =AX31+AY30 -> 20440 | AZ31: =IF(AND(L31>0,AX31>0),(AX31/(P31*1000)*1000),0) -> 0 | BA31: =IF(AND(M31>0,AY31>0),(AY31/(Q31*1000)*1000),0) -> 20.315385 | BB31: =IF(AND(R31>0,AX31>0),(AX31/(R31*1000)*1000),0) -> 0 | BC31: =IF(AND(S31>0,AY31>0),(AY31/(S31*1000)*1000),0) -> 21.143267 | BE31: =+SUM(Efficiency2!K106:K108) -> 49.084545 | BF31: =BF30+BE31 -> 1090.3123 | BG31: =+R31/BE31 -> 0.90309486 | BH31: =+S31/BF31 -> 0.88666152
A32: =A31+1 -> 45862 | B32: Facial/Toilet | C32: 12,5/14,5/17 | D32: =+'24'!F42 -> 1133.4722 | E32: =+'24'!G42 -> 927.03194 | F32: =1-(E32/D32) -> 0.18213087 | G32: =+P32/N32 -> 0.95187923 | H32: =+P32/L32 -> 0.95187923 | I32: =+R32/P32 -> 0.94142703 | J32: =+R32/L32 -> 0.89612484 | K32: =+S32/M32 -> 0.88075337 | L32: =+SUM(Efficiency1!K111:K113) -> 52.533975 | M32: =M31+L32 -> 1151.0771 | N32: =+SUM(Efficiency1!C111:C113) -> 52.533975 | O32: =O31+N32 -> 1140.012 | P32: ='24'!I38 -> 50.006 | Q32: =Q31+P32 -> 1056.14 | R32: ='24'!I40 -> 47.077 | S32: =S31+R32 -> 1013.815 | T32: =+[1]Report1!AZ32 -> 3759.7835 | U32: =T32+U31 -> 86903.117 | V32: =T32/P32 -> 75.186648 | W32: =U32/Q32 -> 82.283709 | X32: =IF(AND(R32>0,T32>0),(T32/(R32*1000))*1000,0) -> 79.864552 | Y32: =IF(AND(S32>0,U32>0),U32/S32,0) -> 85.71891 | Z32: 91.05 | AA32: =Z32+AA31 -> 2067.68 | AB32: 91.05 | AC32: =AA32/(Q32) -> 1.9577708 | AD32: =IF(AND(R32>0,Z32>0),Z32/(R32),0) -> 1.9340655 | AE32: =IF(AND(S32>0,AA32>0),AA32/(S32),0) -> 2.0395042 | AF32: 7.9 | AG32: =+AF32+AG31 -> 7.9 | AH32: =AF32/(P32) -> 0.15798104 | AI32: =AG32/(Q32) -> 0.0074800689 | AJ32: =IF(AND(R32>0,AF32>0),AF32/(R32),0) -> 0.16781018 | AK32: =IF(AND(S32>0,AG32>0),AG32/(S32),0) -> 0.0077923487 | AL32: =+'24'!I46 -> 36466.875 | AM32: =AL32+AM31 -> 966674.62 | AN32: =IF(AND(L32>0,AL32>0),(AL32/(P32*1000)*1000),0) -> 729.24999 | AO32: =IF(AND(M32>0,AM32>0),(AM32/(Q32*1000)*1000),0) -> 915.29023 | AP32: =IF(AND(R32>0,AL32>0),(AL32/(R32*1000)*1000),0) -> 774.6219 | AQ32: =IF(AND(S32>0,AM32>0),(AM32/(S32*1000)*1000),0) -> 953.50199 | AR32: =+Listrik!AA31 -> 20531 | AS32: =AR32+AS31 -> 20531 | AT32: =IF(AND(L32>0,AR32>0),(AR32/(P32*1000)*1000),0) -> 410.57073 | AU32: =IF(AND(M32>0,AS32>0),(AS32/(Q32*1000)*1000),0) -> 19.439658 | AV32: =IF(AND(R32>0,AR32>0),(AR32/(R32*1000)*1000),0) -> 436.1153 | AW32: =IF(AND(S32>0,AS32>0),(AS32/(S32*1000)*1000),0) -> 20.251229 | AX32: =+Listrik!AD31 -> 0 | AY32: =AX32+AY31 -> 20440 | AZ32: =IF(AND(L32>0,AX32>0),(AX32/(P32*1000)*1000),0) -> 0 | BA32: =IF(AND(M32>0,AY32>0),(AY32/(Q32*1000)*1000),0) -> 19.353495 | BB32: =IF(AND(R32>0,AX32>0),(AX32/(R32*1000)*1000),0) -> 0 | BC32: =IF(AND(S32>0,AY32>0),(AY32/(S32*1000)*1000),0) -> 20.161469 | BE32: =+Efficiency2!K111+Efficiency2!K112+Efficiency2!K113 -> 52.24095 | BF32: =BF31+BE32 -> 1142.5533 | BG32: =+R32/BE32 -> 0.9011513 | BH32: =+S32/BF32 -> 0.88732404
A33: =A32+1 -> 45863 | B33: Toilet | C33: 17/19/20 | D33: =+'25'!F42 -> 1004.8264 | E33: =+'25'!G42 -> 803.86111 | F33: =1-(E33/D33) -> 0.2 | G33: =+P33/N33 -> 0.98957053 | H33: =+P33/L33 -> 0.98957053 | I33: =+R33/P33 -> 0.87141812 | J33: =+R33/L33 -> 0.86232969 | K33: =+S33/M33 -> 0.87990992 | L33: =+SUM(Efficiency1!K117:K119) -> 55.225978 | M33: =M32+L33 -> 1206.303 | N33: =+SUM(Efficiency1!C117:C119) -> 55.225978 | O33: =O32+N33 -> 1195.238 | P33: ='25'!I38 -> 54.65 | Q33: =Q32+P33 -> 1110.79 | R33: ='25'!I40 -> 47.623 | S33: =S32+R33 -> 1061.438 | T33: =+[1]Report1!AZ33 -> 3718.3625 | U33: =T33+U32 -> 90621.479 | V33: =T33/P33 -> 68.03957 | W33: =U33/Q33 -> 81.582909 | X33: =IF(AND(R33>0,T33>0),(T33/(R33*1000))*1000,0) -> 78.079132 | Y33: =IF(AND(S33>0,U33>0),U33/S33,0) -> 85.37614 | Z33: 89.8 | AA33: =Z33+AA32 -> 2157.48 | AB33: 89.8 | AC33: =AA33/(Q33) -> 1.9422933 | AD33: =IF(AND(R33>0,Z33>0),Z33/(R33),0) -> 1.8856435 | AE33: =IF(AND(S33>0,AA33>0),AA33/(S33),0) -> 2.0326011 | AF33: 9.3 | AG33: =+AF33+AG32 -> 17.2 | AH33: =AF33/(P33) -> 0.17017383 | AI33: =AG33/(Q33) -> 0.015484475 | AJ33: =IF(AND(R33>0,AF33>0),AF33/(R33),0) -> 0.19528379 | AK33: =IF(AND(S33>0,AG33>0),AG33/(S33),0) -> 0.016204432 | AL33: =+'25'!I46 -> 33439.905 | AM33: =AL33+AM32 -> 1000114.5 | AN33: =IF(AND(L33>0,AL33>0),(AL33/(P33*1000)*1000),0) -> 611.89213 | AO33: =IF(AND(M33>0,AM33>0),(AM33/(Q33*1000)*1000),0) -> 900.36328 | AP33: =IF(AND(R33>0,AL33>0),(AL33/(R33*1000)*1000),0) -> 702.17972 | AQ33: =IF(AND(S33>0,AM33>0),(AM33/(S33*1000)*1000),0) -> 942.22604 | AR33: =+Listrik!AA32 -> 27050 | AS33: =AR33+AS32 -> 47581 | AT33: =IF(AND(L33>0,AR33>0),(AR33/(P33*1000)*1000),0) -> 494.96798 | AU33: =IF(AND(M33>0,AS33>0),(AS33/(Q33*1000)*1000),0) -> 42.835279 | AV33: =IF(AND(R33>0,AR33>0),(AR33/(R33*1000)*1000),0) -> 568.00286 | AW33: =IF(AND(S33>0,AS33>0),(AS33/(S33*1000)*1000),0) -> 44.826923 | AX33: =+Listrik!AD32 -> 0 | AY33: =AX33+AY32 -> 20440 | AZ33: =IF(AND(L33>0,AX33>0),(AX33/(P33*1000)*1000),0) -> 0 | BA33: =IF(AND(M33>0,AY33>0),(AY33/(Q33*1000)*1000),0) -> 18.401318 | BB33: =IF(AND(R33>0,AX33>0),(AX33/(R33*1000)*1000),0) -> 0 | BC33: =IF(AND(S33>0,AY33>0),(AY33/(S33*1000)*1000),0) -> 19.256895 | BE33: =+SUM(Efficiency2!K117:K119) -> 55.225978 | BF33: =BF32+BE33 -> 1197.7793 | BG33: =+R33/BE33 -> 0.86232969 | BH33: =+S33/BF33 -> 0.88617162
