Workbook

Sheet Report1
A3: PAPER MACHINE 17 DAILY REPORT 1
A6: Date | B6: Grade | C6: GSM | D6: Speed yankee (mpm) | E6: Speed reel (mpm) | F6: Creep ( % ) | G6: Real Eff PM ( % ) | H6: Real Eff PM vs Target (%) | I6: Real Eff FG vs Real Eff PM (%) | J6: Eff FG vs Target (%) | L6: Kapasitas Target (ton) | N6: Kapasitas Teori Real (ton) | P6: PM PROD Timbangan (TON) | R6: FINSHED GOODS (TON) | T6: GAS HOOD | Z6: STEAM (TON) | AF6: STEAM DEINKING (TON) | AL6: POWER (kWh) | AR6: POWER DEINKING (kWh) | AX6: TOTALIZER | AY6: Kapasitas Running (ton) | BA6: Eff FG vs Target Running(%)
T7: CONSUMPTION | V7: /TON PM. | X7: /TON FG. | Z7: CONSUMPTION | AB7: /TON PM. | AD7: /TON FG. | AF7: CONSUMPTION | AH7: /TON PM. | AJ7: /TON FG. | AL7: CONSUMPTION | AN7: /TON PM | AP7: /TON FG | AR7: CONSUMPTION | AT7: /TON PM | AV7: /TON FG
J8: TODAY | K8: TODATE | L8: TODAY | M8: TODATE | N8: TODAY | O8: TODATE | P8: TODAY | Q8: TODATE | R8: TODAY | S8: TODATE | T8: TODAY | U8: TODATE | V8: TODAY | W8: TODATE | X8: TODAY | Y8: TODATE | Z8: TODAY | AA8: TODATE | AB8: TODAY | AC8: TODATE | AD8: TODAY | AE8: TODATE | AF8: TODAY | AG8: TODATE | AH8: TODAY | AI8: TODATE | AJ8: TODAY | AK8: TODATE | AL8: TODAY | AM8: TODATE | AN8: TODAY | AO8: TODATE | AP8: TODAY | AQ8: TODATE | AR8: TODAY | AS8: TODATE | AT8: TODAY | AU8: TODATE | AV8: TODAY | AW8: TODATE | AY8: TODAY | AZ8: TODATE | BA8: TODAY | BB8: TODATE
A9: 45931 | B9: STOP | C9: 17 | D9: =+'1'!F42 -> 0 | E9: =+'1'!G42 -> 0 | F9: =1-(E9/D9) -> #DIV/0! | G9: =+P9/N9 -> 0 | H9: =+P9/L9 -> 0 | I9: =+R9/P9 -> #DIV/0! | J9: =+R9/L9 -> 0.063779031 | K9: =+S9/M9 -> 0.063779031 | L9: =+Efficiency1!K6 -> 52.744608 | M9: =L9 -> 52.744608 | N9: =+Efficiency1!C6 -> 52.744608 | O9: =N9 -> 52.744608 | P9: ='1'!I38 -> 0 | Q9: =P9 -> 0 | R9: ='1'!I40 -> 3.364 | S9: =R9 -> 3.364 | T9: =+[1]Report1!AZ9 -> 0 | U9: =T9 -> 0 | V9: =T9/P9 -> #DIV/0! | W9: =U9/Q9 -> #DIV/0! | X9: =IF(AND(R9>0,T9>0),(T9/(R9*1000))*1000,0) -> 0 | Y9: =IF(AND(S9>0,U9>0),U9/S9,0) -> 0 | Z9: 0.4 | AA9: =Z9 -> 0.4 | AB9: =Z9/(P9) -> #DIV/0! | AC9: =AA9/(Q9) -> #DIV/0! | AD9: =IF(AND(R9>0,Z9>0),Z9/(R9),0) -> 0.11890606 | AE9: =IF(AND(S9>0,AA9>0),AA9/(S9),0) -> 0.11890606 | AF9: 0 | AG9: =AF9 -> 0 | AH9: =AF9/(P9) -> #DIV/0! | AI9: =AG9/(Q9) -> #DIV/0! | AJ9: =IF(AND(R9>0,AF9>0),AF9/(R9),0) -> 0 | AK9: =IF(AND(S9>0,AG9>0),AG9/(S9),0) -> 0 | AL9: ='1'!I46 -> 5187.3 | AM9: =AL9 -> 5187.3 | AN9: =IF(AND(L9>0,AL9>0),(AL9/(P9*1000)*1000),0) -> #DIV/0! | AO9: =IF(AND(M9>0,AM9>0),(AM9/(Q9*1000)*1000),0) -> #DIV/0! | AP9: =IF(AND(R9>0,AL9>0),(AL9/(R9*1000)*1000),0) -> 1542.0036 | AQ9: =IF(AND(S9>0,AM9>0),(AM9/(S9*1000)*1000),0) -> 1542.0036 | AR9: =+Listrik!AA8 -> 0 | AS9: =AR9 -> 0 | AT9: =IF(AND(L9>0,AR9>0),(AR9/(P9*1000)*1000),0) -> 0 | AU9: =IF(AND(M9>0,AS9>0),(AS9/(Q9*1000)*1000),0) -> 0 | AV9: =IF(AND(R9>0,AR9>0),(AR9/(R9*1000)*1000),0) -> 0 | AW9: =IF(AND(S9>0,AS9>0),(AS9/(S9*1000)*1000),0) -> 0 | AY9: =+Efficiency2!K6 -> 0 | AZ9: =AY9 -> 0 | BA9: =+R9/AY9 -> #DIV/0! | BB9: =+S9/AZ9 -> #DIV/0!
A10: =A9+1 -> 45932 | B10: STOP | C10: 17 | D10: =+'2'!F42 -> 0 | E10: =+'2'!G42 -> 0 | F10: =1-(E10/D10) -> #DIV/0! | G10: =+P10/N10 -> 0 | H10: =+P10/L10 -> 0 | I10: =+R10/P10 -> #DIV/0! | J10: =+R10/L10 -> 0 | K10: =+S10/M10 -> 0.031889516 | L10: =+Efficiency1!K11 -> 52.744608 | M10: =M9+L10 -> 105.48922 | N10: =+Efficiency1!C11 -> 52.744608 | O10: =O9+N10 -> 105.48922 | P10: ='2'!I38 -> 0 | Q10: =Q9+P10 -> 0 | R10: ='2'!I40 -> 0 | S10: =S9+R10 -> 3.364 | T10: =+[1]Report1!AZ10 -> 0 | U10: =T10+U9 -> 0 | V10: =T10/P10 -> #DIV/0! | W10: =U10/Q10 -> #DIV/0! | X10: =IF(AND(R10>0,T10>0),(T10/(R10*1000))*1000,0) -> 0 | Y10: =IF(AND(S10>0,U10>0),U10/S10,0) -> 0 | Z10: 0.1 | AA10: =Z10+AA9 -> 0.5 | AB10: =Z10/(P10) -> #DIV/0! | AC10: =AA10/(Q10) -> #DIV/0! | AD10: =IF(AND(R10>0,Z10>0),Z10/(R10),0) -> 0 | AE10: =IF(AND(S10>0,AA10>0),AA10/(S10),0) -> 0.14863258 | AF10: 0 | AG10: =+AF10+AG9 -> 0 | AH10: =AF10/(P10) -> #DIV/0! | AI10: =AG10/(Q10) -> #DIV/0! | AJ10: =IF(AND(R10>0,AF10>0),AF10/(R10),0) -> 0 | AK10: =IF(AND(S10>0,AG10>0),AG10/(S10),0) -> 0 | AL10: ='2'!I46 -> 4254.18 | AM10: =AL10+AM9 -> 9441.48 | AN10: =IF(AND(L10>0,AL10>0),(AL10/(P10*1000)*1000),0) -> #DIV/0! | AO10: =IF(AND(M10>0,AM10>0),(AM10/(Q10*1000)*1000),0) -> #DIV/0! | AP10: =IF(AND(R10>0,AL10>0),(AL10/(R10*1000)*1000),0) -> 0 | AQ10: =IF(AND(S10>0,AM10>0),(AM10/(S10*1000)*1000),0) -> 2806.6231 | AR10: =+Listrik!AA9 -> 0 | AS10: =AR10+AS9 -> 0 | AT10: =IF(AND(L10>0,AR10>0),(AR10/(P10*1000)*1000),0) -> 0 | AU10: =IF(AND(M10>0,AS10>0),(AS10/(Q10*1000)*1000),0) -> 0 | AV10: =IF(AND(R10>0,AR10>0),(AR10/(R10*1000)*1000),0) -> 0 | AW10: =IF(AND(S10>0,AS10>0),(AS10/(S10*1000)*1000),0) -> 0 | AY10: =+Efficiency2!K11 -> 0 | AZ10: =AZ9+AY10 -> 0 | BA10: =+R10/AY10 -> #DIV/0! | BB10: =+S10/AZ10 -> #DIV/0!
A11: =A10+1 -> 45933 | B11: STOP | C11: 17 | D11: =+'3'!F42 -> 0 | E11: =+'3'!G42 -> 0 | F11: =1-(E11/D11) -> #DIV/0! | G11: =+P11/N11 -> 0 | H11: =+P11/L11 -> 0 | I11: =+R11/P11 -> #DIV/0! | J11: =+R11/L11 -> 0 | K11: =+S11/M11 -> 0.021259677 | L11: =+Efficiency1!K16 -> 52.744608 | M11: =M10+L11 -> 158.23382 | N11: =+Efficiency1!C16 -> 52.744608 | O11: =O10+N11 -> 158.23382 | P11: ='3'!I38 -> 0 | Q11: =Q10+P11 -> 0 | R11: ='3'!I40 -> 0 | S11: =S10+R11 -> 3.364 | T11: =+[1]Report1!AZ11 -> 0 | U11: =T11+U10 -> 0 | V11: =T11/P11 -> #DIV/0! | W11: =U11/Q11 -> #DIV/0! | X11: =IF(AND(R11>0,T11>0),(T11/(R11*1000))*1000,0) -> 0 | Y11: =IF(AND(S11>0,U11>0),U11/S11,0) -> 0 | Z11: 0.1 | AA11: =Z11+AA10 -> 0.6 | AB11: =Z11/(P11) -> #DIV/0! | AC11: =AA11/(Q11) -> #DIV/0! | AD11: =IF(AND(R11>0,Z11>0),Z11/(R11),0) -> 0 | AE11: =IF(AND(S11>0,AA11>0),AA11/(S11),0) -> 0.1783591 | AF11: 0 | AG11: =+AF11+AG10 -> 0 | AH11: =AF11/(P11) -> #DIV/0! | AI11: =AG11/(Q11) -> #DIV/0! | AJ11: =IF(AND(R11>0,AF11>0),AF11/(R11),0) -> 0 | AK11: =IF(AND(S11>0,AG11>0),AG11/(S11),0) -> 0 | AL11: ='3'!I46 -> 1722.22 | AM11: =AL11+AM10 -> 11163.7 | AN11: =IF(AND(L11>0,AL11>0),(AL11/(P11*1000)*1000),0) -> #DIV/0! | AO11: =IF(AND(M11>0,AM11>0),(AM11/(Q11*1000)*1000),0) -> #DIV/0! | AP11: =IF(AND(R11>0,AL11>0),(AL11/(R11*1000)*1000),0) -> 0 | AQ11: =IF(AND(S11>0,AM11>0),(AM11/(S11*1000)*1000),0) -> 3318.5791 | AR11: =+Listrik!AA10 -> 0 | AS11: =AR11+AS10 -> 0 | AT11: =IF(AND(L11>0,AR11>0),(AR11/(P11*1000)*1000),0) -> 0 | AU11: =IF(AND(M11>0,AS11>0),(AS11/(Q11*1000)*1000),0) -> 0 | AV11: =IF(AND(R11>0,AR11>0),(AR11/(R11*1000)*1000),0) -> 0 | AW11: =IF(AND(S11>0,AS11>0),(AS11/(S11*1000)*1000),0) -> 0 | AY11: =+Efficiency2!K16 -> 0 | AZ11: =AZ10+AY11 -> 0 | BA11: =+R11/AY11 -> #DIV/0! | BB11: =+S11/AZ11 -> #DIV/0!
A12: =A11+1 -> 45934 | B12: STOP | C12: 17 | D12: =+'4'!F42 -> 0 | E12: =+'4'!G42 -> 0 | F12: =1-(E12/D12) -> #DIV/0! | G12: =+P12/N12 -> 0 | H12: =+P12/L12 -> 0 | I12: =+R12/P12 -> #DIV/0! | J12: =+R12/L12 -> 0 | K12: =+S12/M12 -> 0.015944758 | L12: =+Efficiency1!K21 -> 52.744608 | M12: =M11+L12 -> 210.97843 | N12: =+Efficiency1!C21 -> 52.744608 | O12: =O11+N12 -> 210.97843 | P12: ='4'!I38 -> 0 | Q12: =Q11+P12 -> 0 | R12: ='4'!I40 -> 0 | S12: =S11+R12 -> 3.364 | T12: =+[1]Report1!AZ12 -> 0 | U12: =T12+U11 -> 0 | V12: =T12/P12 -> #DIV/0! | W12: =U12/Q12 -> #DIV/0! | X12: =IF(AND(R12>0,T12>0),(T12/(R12*1000))*1000,0) -> 0 | Y12: =IF(AND(S12>0,U12>0),U12/S12,0) -> 0 | Z12: 0.1 | AA12: =Z12+AA11 -> 0.7 | AB12: =Z12/(P12) -> #DIV/0! | AC12: =AA12/(Q12) -> #DIV/0! | AD12: =IF(AND(R12>0,Z12>0),Z12/(R12),0) -> 0 | AE12: =IF(AND(S12>0,AA12>0),AA12/(S12),0) -> 0.20808561 | AF12: 0 | AG12: =+AF12+AG11 -> 0 | AH12: =AF12/(P12) -> #DIV/0! | AI12: =AG12/(Q12) -> #DIV/0! | AJ12: =IF(AND(R12>0,AF12>0),AF12/(R12),0) -> 0 | AK12: =IF(AND(S12>0,AG12>0),AG12/(S12),0) -> 0 | AL12: ='4'!I46 -> 3976.44 | AM12: =AL12+AM11 -> 15140.14 | AN12: =IF(AND(L12>0,AL12>0),(AL12/(P12*1000)*1000),0) -> #DIV/0! | AO12: =IF(AND(M12>0,AM12>0),(AM12/(Q12*1000)*1000),0) -> #DIV/0! | AP12: =IF(AND(R12>0,AL12>0),(AL12/(R12*1000)*1000),0) -> 0 | AQ12: =IF(AND(S12>0,AM12>0),(AM12/(S12*1000)*1000),0) -> 4500.6361 | AR12: =+Listrik!AA11 -> 0 | AS12: =AR12+AS11 -> 0 | AT12: =IF(AND(L12>0,AR12>0),(AR12/(P12*1000)*1000),0) -> 0 | AU12: =IF(AND(M12>0,AS12>0),(AS12/(Q12*1000)*1000),0) -> 0 | AV12: =IF(AND(R12>0,AR12>0),(AR12/(R12*1000)*1000),0) -> 0 | AW12: =IF(AND(S12>0,AS12>0),(AS12/(S12*1000)*1000),0) -> 0 | AY12: =+Efficiency2!K21 -> 0 | AZ12: =AZ11+AY12 -> 0 | BA12: =+R12/AY12 -> #DIV/0! | BB12: =+S12/AZ12 -> #DIV/0!
A13: =A12+1 -> 45935 | B13: STOP | C13: 17 | D13: =+'5'!F42 -> 0 | E13: =+'5'!G42 -> 0 | F13: =1-(E13/D13) -> #DIV/0! | G13: =+P13/N13 -> 0 | H13: =+P13/L13 -> 0 | I13: =+R13/P13 -> #DIV/0! | J13: =+R13/L13 -> 0 | K13: =+S13/M13 -> 0.012755806 | L13: =+Efficiency1!K26 -> 52.744608 | M13: =M12+L13 -> 263.72304 | N13: =+Efficiency1!C26 -> 52.744608 | O13: =O12+N13 -> 263.72304 | P13: ='5'!I38 -> 0 | Q13: =Q12+P13 -> 0 | R13: ='5'!I40 -> 0 | S13: =S12+R13 -> 3.364 | T13: =+[1]Report1!AZ13 -> 0 | U13: =T13+U12 -> 0 | V13: =T13/P13 -> #DIV/0! | W13: =U13/Q13 -> #DIV/0! | X13: =IF(AND(R13>0,T13>0),(T13/(R13*1000))*1000,0) -> 0 | Y13: =IF(AND(S13>0,U13>0),U13/S13,0) -> 0 | Z13: 0.1 | AA13: =Z13+AA12 -> 0.8 | AB13: =Z13/(P13) -> #DIV/0! | AC13: =AA13/(Q13) -> #DIV/0! | AD13: =IF(AND(R13>0,Z13>0),Z13/(R13),0) -> 0 | AE13: =IF(AND(S13>0,AA13>0),AA13/(S13),0) -> 0.23781213 | AF13: 0 | AG13: =+AF13+AG12 -> 0 | AH13: =AF13/(P13) -> #DIV/0! | AI13: =AG13/(Q13) -> #DIV/0! | AJ13: =IF(AND(R13>0,AF13>0),AF13/(R13),0) -> 0 | AK13: =IF(AND(S13>0,AG13>0),AG13/(S13),0) -> 0 | AL13: ='5'!I46 -> 3020.48 | AM13: =AL13+AM12 -> 18160.62 | AN13: =IF(AND(L13>0,AL13>0),(AL13/(P13*1000)*1000),0) -> #DIV/0! | AO13: =IF(AND(M13>0,AM13>0),(AM13/(Q13*1000)*1000),0) -> #DIV/0! | AP13: =IF(AND(R13>0,AL13>0),(AL13/(R13*1000)*1000),0) -> 0 | AQ13: =IF(AND(S13>0,AM13>0),(AM13/(S13*1000)*1000),0) -> 5398.5196 | AR13: =+Listrik!AA12 -> 0 | AS13: =AR13+AS12 -> 0 | AT13: =IF(AND(L13>0,AR13>0),(AR13/(P13*1000)*1000),0) -> 0 | AU13: =IF(AND(M13>0,AS13>0),(AS13/(Q13*1000)*1000),0) -> 0 | AV13: =IF(AND(R13>0,AR13>0),(AR13/(R13*1000)*1000),0) -> 0 | AW13: =IF(AND(S13>0,AS13>0),(AS13/(S13*1000)*1000),0) -> 0 | AY13: =+Efficiency2!K26 -> 0 | AZ13: =AZ12+AY13 -> 0 | BA13: =+R13/AY13 -> #DIV/0! | BB13: =+S13/AZ13 -> #DIV/0!
A14: =A13+1 -> 45936 | B14: STOP | C14: 17 | D14: =+'6'!F42 -> 0 | E14: =+'6'!G42 -> 0 | F14: =1-(E14/D14) -> #DIV/0! | G14: =+P14/N14 -> 0 | H14: =+P14/L14 -> 0 | I14: =+R14/P14 -> #DIV/0! | J14: =+R14/L14 -> 0 | K14: =+S14/M14 -> 0.010629839 | L14: =+Efficiency1!K31 -> 52.744608 | M14: =M13+L14 -> 316.46765 | N14: =+Efficiency1!C31 -> 52.744608 | O14: =O13+N14 -> 316.46765 | P14: ='6'!I38 -> 0 | Q14: =Q13+P14 -> 0 | R14: ='6'!I40 -> 0 | S14: =S13+R14 -> 3.364 | T14: =+[1]Report1!AZ14 -> 0 | U14: =T14+U13 -> 0 | V14: =T14/P14 -> #DIV/0! | W14: =U14/Q14 -> #DIV/0! | X14: =IF(AND(R14>0,T14>0),(T14/(R14*1000))*1000,0) -> 0 | Y14: =IF(AND(S14>0,U14>0),U14/S14,0) -> 0 | Z14: 0.1 | AA14: =Z14+AA13 -> 0.9 | AB14: =Z14/(P14) -> #DIV/0! | AC14: =AA14/(Q14) -> #DIV/0! | AD14: =IF(AND(R14>0,Z14>0),Z14/(R14),0) -> 0 | AE14: =IF(AND(S14>0,AA14>0),AA14/(S14),0) -> 0.26753864 | AF14: 0 | AG14: =+AF14+AG13 -> 0 | AH14: =AF14/(P14) -> #DIV/0! | AI14: =AG14/(Q14) -> #DIV/0! | AJ14: =IF(AND(R14>0,AF14>0),AF14/(R14),0) -> 0 | AK14: =IF(AND(S14>0,AG14>0),AG14/(S14),0) -> 0 | AL14: ='6'!I46 -> 2234.74 | AM14: =AL14+AM13 -> 20395.36 | AN14: =IF(AND(L14>0,AL14>0),(AL14/(P14*1000)*1000),0) -> #DIV/0! | AO14: =IF(AND(M14>0,AM14>0),(AM14/(Q14*1000)*1000),0) -> #DIV/0! | AP14: =IF(AND(R14>0,AL14>0),(AL14/(R14*1000)*1000),0) -> 0 | AQ14: =IF(AND(S14>0,AM14>0),(AM14/(S14*1000)*1000),0) -> 6062.83 | AR14: =+Listrik!AA13 -> 0 | AS14: =AR14+AS13 -> 0 | AT14: =IF(AND(L14>0,AR14>0),(AR14/(P14*1000)*1000),0) -> 0 | AU14: =IF(AND(M14>0,AS14>0),(AS14/(Q14*1000)*1000),0) -> 0 | AV14: =IF(AND(R14>0,AR14>0),(AR14/(R14*1000)*1000),0) -> 0 | AW14: =IF(AND(S14>0,AS14>0),(AS14/(S14*1000)*1000),0) -> 0 | AY14: =+Efficiency2!K31 -> 0 | AZ14: =AZ13+AY14 -> 0 | BA14: =+R14/AY14 -> #DIV/0! | BB14: =+S14/AZ14 -> #DIV/0!
A15: =A14+1 -> 45937 | B15: STOP | C15: 17 | D15: =+'7'!F42 -> 0 | E15: =+'7'!G42 -> 0 | F15: =1-(E15/D15) -> #DIV/0! | G15: =+P15/N15 -> 0 | H15: =+P15/L15 -> 0 | I15: =+R15/P15 -> #DIV/0! | J15: =+R15/L15 -> 0 | K15: =+S15/M15 -> 0.0091112902 | L15: =+Efficiency1!K36 -> 52.744608 | M15: =M14+L15 -> 369.21226 | N15: =+Efficiency1!C36 -> 52.744608 | O15: =O14+N15 -> 369.21226 | P15: ='7'!I38 -> 0 | Q15: =Q14+P15 -> 0 | R15: ='7'!I40 -> 0 | S15: =S14+R15 -> 3.364 | T15: =+[1]Report1!AZ15 -> 0 | U15: =T15+U14 -> 0 | V15: =T15/P15 -> #DIV/0! | W15: =U15/Q15 -> #DIV/0! | X15: =IF(AND(R15>0,T15>0),(T15/(R15*1000))*1000,0) -> 0 | Y15: =IF(AND(S15>0,U15>0),U15/S15,0) -> 0 | Z15: 0.1 | AA15: =Z15+AA14 -> 1 | AB15: =Z15/(P15) -> #DIV/0! | AC15: =AA15/(Q15) -> #DIV/0! | AD15: =IF(AND(R15>0,Z15>0),Z15/(R15),0) -> 0 | AE15: =IF(AND(S15>0,AA15>0),AA15/(S15),0) -> 0.29726516 | AF15: 0 | AG15: =+AF15+AG14 -> 0 | AH15: =AF15/(P15) -> #DIV/0! | AI15: =AG15/(Q15) -> #DIV/0! | AJ15: =IF(AND(R15>0,AF15>0),AF15/(R15),0) -> 0 | AK15: =IF(AND(S15>0,AG15>0),AG15/(S15),0) -> 0 | AL15: ='7'!I46 -> 2928.3 | AM15: =AL15+AM14 -> 23323.66 | AN15: =IF(AND(L15>0,AL15>0),(AL15/(P15*1000)*1000),0) -> #DIV/0! | AO15: =IF(AND(M15>0,AM15>0),(AM15/(Q15*1000)*1000),0) -> #DIV/0! | AP15: =IF(AND(R15>0,AL15>0),(AL15/(R15*1000)*1000),0) -> 0 | AQ15: =IF(AND(S15>0,AM15>0),(AM15/(S15*1000)*1000),0) -> 6933.3115 | AR15: =+Listrik!AA14 -> 0 | AS15: =AR15+AS14 -> 0 | AT15: =IF(AND(L15>0,AR15>0),(AR15/(P15*1000)*1000),0) -> 0 | AU15: =IF(AND(M15>0,AS15>0),(AS15/(Q15*1000)*1000),0) -> 0 | AV15: =IF(AND(R15>0,AR15>0),(AR15/(R15*1000)*1000),0) -> 0 | AW15: =IF(AND(S15>0,AS15>0),(AS15/(S15*1000)*1000),0) -> 0 | AY15: =+Efficiency2!K36 -> 0 | AZ15: =AZ14+AY15 -> 0 | BA15: =+R15/AY15 -> #DIV/0! | BB15: =+S15/AZ15 -> #DIV/0!
A16: =A15+1 -> 45938 | B16: STOP | C16: 17 | D16: =+'8'!F42 -> 0 | E16: =+'8'!G42 -> 0 | F16: =1-(E16/D16) -> #DIV/0! | G16: =+P16/N16 -> 0 | H16: =+P16/L16 -> 0 | I16: =+R16/P16 -> #DIV/0! | J16: =+R16/L16 -> 0 | K16: =+S16/M16 -> 0.0079723789 | L16: =+Efficiency1!K41 -> 52.744608 | M16: =M15+L16 -> 421.95686 | N16: =+Efficiency1!C41 -> 52.744608 | O16: =O15+N16 -> 421.95686 | P16: ='8'!I38 -> 0 | Q16: =Q15+P16 -> 0 | R16: ='8'!I40 -> 0 | S16: =S15+R16 -> 3.364 | T16: =+[1]Report1!AZ16 -> 0 | U16: =T16+U15 -> 0 | V16: =T16/P16 -> #DIV/0! | W16: =U16/Q16 -> #DIV/0! | X16: =IF(AND(R16>0,T16>0),(T16/(R16*1000))*1000,0) -> 0 | Y16: =IF(AND(S16>0,U16>0),U16/S16,0) -> 0 | Z16: 1.6 | AA16: =Z16+AA15 -> 2.6 | AB16: =Z16/(P16) -> #DIV/0! | AC16: =AA16/(Q16) -> #DIV/0! | AD16: =IF(AND(R16>0,Z16>0),Z16/(R16),0) -> 0 | AE16: =IF(AND(S16>0,AA16>0),AA16/(S16),0) -> 0.77288942 | AF16: 0 | AG16: =+AF16+AG15 -> 0 | AH16: =AF16/(P16) -> #DIV/0! | AI16: =AG16/(Q16) -> #DIV/0! | AJ16: =IF(AND(R16>0,AF16>0),AF16/(R16),0) -> 0 | AK16: =IF(AND(S16>0,AG16>0),AG16/(S16),0) -> 0 | AL16: ='8'!I46 -> 2439.26 | AM16: =AL16+AM15 -> 25762.92 | AN16: =IF(AND(L16>0,AL16>0),(AL16/(P16*1000)*1000),0) -> #DIV/0! | AO16: =IF(AND(M16>0,AM16>0),(AM16/(Q16*1000)*1000),0) -> #DIV/0! | AP16: =IF(AND(R16>0,AL16>0),(AL16/(R16*1000)*1000),0) -> 0 | AQ16: =IF(AND(S16>0,AM16>0),(AM16/(S16*1000)*1000),0) -> 7658.4185 | AR16: =+Listrik!AA15 -> 0 | AS16: =AR16+AS15 -> 0 | AT16: =IF(AND(L16>0,AR16>0),(AR16/(P16*1000)*1000),0) -> 0 | AU16: =IF(AND(M16>0,AS16>0),(AS16/(Q16*1000)*1000),0) -> 0 | AV16: =IF(AND(R16>0,AR16>0),(AR16/(R16*1000)*1000),0) -> 0 | AW16: =IF(AND(S16>0,AS16>0),(AS16/(S16*1000)*1000),0) -> 0 | AY16: =+Efficiency2!K41 -> 0 | AZ16: =AZ15+AY16 -> 0 | BA16: =+R16/AY16 -> #DIV/0! | BB16: =+S16/AZ16 -> #DIV/0!
A17: =A16+1 -> 45939 | B17: Toilet | C17: 14/14,5 | D17: =+'9'!F42 -> 951.44865 | E17: =+'9'!G42 -> 729.57978 | F17: =1-(E17/D17) -> 0.23319058 | G17: =+P17/N17 -> 0.57939612 | H17: =+P17/L17 -> 0.42345123 | I17: =+R17/P17 -> 0.79638957 | J17: =+R17/L17 -> 0.33723214 | K17: =+S17/M17 -> 0.044702661 | L17: =+SUM(Efficiency1!K46:K47) -> 52.981308 | M17: =M16+L17 -> 474.93817 | N17: =+SUM(Efficiency1!C46:C47) -> 38.72135 | O17: =O16+N17 -> 460.67821 | P17: ='9'!I38 -> 22.435 | Q17: =Q16+P17 -> 22.435 | R17: ='9'!I40 -> 17.867 | S17: =S16+R17 -> 21.231 | T17: =+[1]Report1!AZ17 -> 2768.5009 | U17: =T17+U16 -> 2768.5009 | V17: =T17/P17 -> 123.40098 | W17: =U17/Q17 -> 123.40098 | X17: =IF(AND(R17>0,T17>0),(T17/(R17*1000))*1000,0) -> 154.95052 | Y17: =IF(AND(S17>0,U17>0),U17/S17,0) -> 130.39899 | Z17: 63.9 | AA17: =Z17+AA16 -> 66.5 | AB17: =Z17/(P17) -> 2.8482282 | AC17: =AA17/(Q17) -> 2.9641186 | AD17: =IF(AND(R17>0,Z17>0),Z17/(R17),0) -> 3.5764258 | AE17: =IF(AND(S17>0,AA17>0),AA17/(S17),0) -> 3.1322123 | AF17: 0 | AG17: =+AF17+AG16 -> 0 | AH17: =AF17/(P17) -> 0 | AI17: =AG17/(Q17) -> 0 | AJ17: =IF(AND(R17>0,AF17>0),AF17/(R17),0) -> 0 | AK17: =IF(AND(S17>0,AG17>0),AG17/(S17),0) -> 0 | AL17: ='9'!I46 -> 16669.86 | AM17: =AL17+AM16 -> 42432.78 | AN17: =IF(AND(L17>0,AL17>0),(AL17/(P17*1000)*1000),0) -> 743.0292 | AO17: =IF(AND(M17>0,AM17>0),(AM17/(Q17*1000)*1000),0) -> 1891.3653 | AP17: =IF(AND(R17>0,AL17>0),(AL17/(R17*1000)*1000),0) -> 932.99715 | AQ17: =IF(AND(S17>0,AM17>0),(AM17/(S17*1000)*1000),0) -> 1998.6237 | AR17: =+Listrik!AA16 -> 0 | AS17: =AR17+AS16 -> 0 | AT17: =IF(AND(L17>0,AR17>0),(AR17/(P17*1000)*1000),0) -> 0 | AU17: =IF(AND(M17>0,AS17>0),(AS17/(Q17*1000)*1000),0) -> 0 | AV17: =IF(AND(R17>0,AR17>0),(AR17/(R17*1000)*1000),0) -> 0 | AW17: =IF(AND(S17>0,AS17>0),(AS17/(S17*1000)*1000),0) -> 0 | AY17: =+SUM(Efficiency2!K46:K47) -> 41.010396 | AZ17: =AZ16+AY17 -> 41.010396 | BA17: =+R17/AY17 -> 0.43567002 | BB17: =+S17/AZ17 -> 0.517698
A18: =A17+1 -> 45940 | B18: Toilet | C18: 14,5 | D18: =+'10'!F42 -> 1163.1159 | E18: =+'10'!G42 -> 911.01594 | F18: =1-(E18/D18) -> 0.21674537 | G18: =+P18/N18 -> 0.87433328 | H18: =+P18/L18 -> 0.82678941 | I18: =+R18/P18 -> 0.89416315 | J18: =+R18/L18 -> 0.73928463 | K18: =+S18/M18 -> 0.11276736 | L18: =+Efficiency1!K52 -> 51.597177 | M18: =M17+L18 -> 526.53535 | N18: =+Efficiency1!C52 -> 48.791463 | O18: =O17+N18 -> 509.46968 | P18: ='10'!I38 -> 42.66 | Q18: =Q17+P18 -> 65.095 | R18: ='10'!I40 -> 38.145 | S18: =S17+R18 -> 59.376 | T18: =+[1]Report1!AZ18 -> 3799.3281 | U18: =T18+U17 -> 6567.8291 | V18: =T18/P18 -> 89.060669 | W18: =U18/Q18 -> 100.89606 | X18: =IF(AND(R18>0,T18>0),(T18/(R18*1000))*1000,0) -> 99.602258 | Y18: =IF(AND(S18>0,U18>0),U18/S18,0) -> 110.61421 | Z18: 95.2 | AA18: =Z18+AA17 -> 161.7 | AB18: =Z18/(P18) -> 2.2315987 | AC18: =AA18/(Q18) -> 2.4840618 | AD18: =IF(AND(R18>0,Z18>0),Z18/(R18),0) -> 2.4957399 | AE18: =IF(AND(S18>0,AA18>0),AA18/(S18),0) -> 2.7233226 | AF18: 0 | AG18: =+AF18+AG17 -> 0 | AH18: =AF18/(P18) -> 0 | AI18: =AG18/(Q18) -> 0 | AJ18: =IF(AND(R18>0,AF18>0),AF18/(R18),0) -> 0 | AK18: =IF(AND(S18>0,AG18>0),AG18/(S18),0) -> 0 | AL18: ='10'!I46 -> 35815.582 | AM18: =AL18+AM17 -> 78248.362 | AN18: =IF(AND(L18>0,AL18>0),(AL18/(P18*1000)*1000),0) -> 839.55889 | AO18: =IF(AND(M18>0,AM18>0),(AM18/(Q18*1000)*1000),0) -> 1202.0641 | AP18: =IF(AND(R18>0,AL18>0),(AL18/(R18*1000)*1000),0) -> 938.93256 | AQ18: =IF(AND(S18>0,AM18>0),(AM18/(S18*1000)*1000),0) -> 1317.845 | AR18: =+Listrik!AA17 -> 0 | AS18: =AR18+AS17 -> 0 | AT18: =IF(AND(L18>0,AR18>0),(AR18/(P18*1000)*1000),0) -> 0 | AU18: =IF(AND(M18>0,AS18>0),(AS18/(Q18*1000)*1000),0) -> 0 | AV18: =IF(AND(R18>0,AR18>0),(AR18/(R18*1000)*1000),0) -> 0 | AW18: =IF(AND(S18>0,AS18>0),(AS18/(S18*1000)*1000),0) -> 0 | AY18: =+SUM(Efficiency2!K52) -> 51.597177 | AZ18: =AZ17+AY18 -> 92.607573 | BA18: =+R18/AY18 -> 0.73928463 | BB18: =+S18/AZ18 -> 0.64115707
A19: =A18+1 -> 45941 | B19: Toilet | C19: 14,5 | D19: =+'11'!F42 -> 1215.5903 | E19: =+'11'!G42 -> 944.13785 | F19: =1-(E19/D19) -> 0.22330915 | G19: =+P19/N19 -> 0.89183549 | H19: =+P19/L19 -> 0.87427948 | I19: =+R19/P19 -> 0.78641121 | J19: =+R19/L19 -> 0.68754318 | K19: =+S19/M19 -> 0.16405009 | L19: =+Efficiency1!K57 -> 51.58076 | M19: =M18+L19 -> 578.11611 | N19: =+Efficiency1!C57 -> 50.56538 | O19: =O18+N19 -> 560.03506 | P19: ='11'!I38 -> 45.096 | Q19: =Q18+P19 -> 110.191 | R19: ='11'!I40 -> 35.464 | S19: =S18+R19 -> 94.84 | T19: =+[1]Report1!AZ19 -> 4117.2852 | U19: =T19+U18 -> 10685.114 | V19: =T19/P19 -> 91.300452 | W19: =U19/Q19 -> 96.969029 | X19: =IF(AND(R19>0,T19>0),(T19/(R19*1000))*1000,0) -> 116.0976 | Y19: =IF(AND(S19>0,U19>0),U19/S19,0) -> 112.66464 | Z19: 98.4 | AA19: =Z19+AA18 -> 260.1 | AB19: =Z19/(P19) -> 2.1820117 | AC19: =AA19/(Q19) -> 2.3604469 | AD19: =IF(AND(R19>0,Z19>0),Z19/(R19),0) -> 2.7746447 | AE19: =IF(AND(S19>0,AA19>0),AA19/(S19),0) -> 2.7425137 | AF19: 0 | AG19: =+AF19+AG18 -> 0 | AH19: =AF19/(P19) -> 0 | AI19: =AG19/(Q19) -> 0 | AJ19: =IF(AND(R19>0,AF19>0),AF19/(R19),0) -> 0 | AK19: =IF(AND(S19>0,AG19>0),AG19/(S19),0) -> 0 | AL19: ='11'!I46 -> 40069.17 | AM19: =AL19+AM18 -> 118317.53 | AN19: =IF(AND(L19>0,AL19>0),(AL19/(P19*1000)*1000),0) -> 888.53047 | AO19: =IF(AND(M19>0,AM19>0),(AM19/(Q19*1000)*1000),0) -> 1073.7495 | AP19: =IF(AND(R19>0,AL19>0),(AL19/(R19*1000)*1000),0) -> 1129.8548 | AQ19: =IF(AND(S19>0,AM19>0),(AM19/(S19*1000)*1000),0) -> 1247.5488 | AR19: =+Listrik!AA18 -> 0 | AS19: =AR19+AS18 -> 0 | AT19: =IF(AND(L19>0,AR19>0),(AR19/(P19*1000)*1000),0) -> 0 | AU19: =IF(AND(M19>0,AS19>0),(AS19/(Q19*1000)*1000),0) -> 0 | AV19: =IF(AND(R19>0,AR19>0),(AR19/(R19*1000)*1000),0) -> 0 | AW19: =IF(AND(S19>0,AS19>0),(AS19/(S19*1000)*1000),0) -> 0 | AY19: =+Efficiency2!K57 -> 51.58076 | AZ19: =AZ18+AY19 -> 144.18833 | BA19: =+R19/AY19 -> 0.68754318 | BB19: =+S19/AZ19 -> 0.65775086
A20: =A19+1 -> 45942 | B20: Toilet | C20: 14,5 | D20: =+'12'!F42 -> 1219.2936 | E20: =+'12'!G42 -> 946.41212 | F20: =1-(E20/D20) -> 0.22380294 | G20: =+P20/N20 -> 0.8418499 | H20: =+P20/L20 -> 0.8277921 | I20: =+R20/P20 -> 1.0490731 | J20: =+R20/L20 -> 0.86841446 | K20: =+S20/M20 -> 0.22171346 | L20: =+Efficiency1!K61 -> 51.547967 | M20: =M19+L20 -> 629.66408 | N20: =+Efficiency1!C61 -> 50.687183 | O20: =O19+N20 -> 610.72224 | P20: ='12'!I38 -> 42.671 | Q20: =Q19+P20 -> 152.862 | R20: ='12'!I40 -> 44.765 | S20: =S19+R20 -> 139.605 | T20: =+[1]Report1!AZ20 -> 3583.8023 | U20: =T20+U19 -> 14268.917 | V20: =T20/P20 -> 83.986838 | W20: =U20/Q20 -> 93.345087 | X20: =IF(AND(R20>0,T20>0),(T20/(R20*1000))*1000,0) -> 80.058134 | Y20: =IF(AND(S20>0,U20>0),U20/S20,0) -> 102.20921 | Z20: 90.4 | AA20: =Z20+AA19 -> 350.5 | AB20: =Z20/(P20) -> 2.1185348 | AC20: =AA20/(Q20) -> 2.2929178 | AD20: =IF(AND(R20>0,Z20>0),Z20/(R20),0) -> 2.0194348 | AE20: =IF(AND(S20>0,AA20>0),AA20/(S20),0) -> 2.5106551 | AF20: 0 | AG20: =+AF20+AG19 -> 0 | AH20: =AF20/(P20) -> 0 | AI20: =AG20/(Q20) -> 0 | AJ20: =IF(AND(R20>0,AF20>0),AF20/(R20),0) -> 0 | AK20: =IF(AND(S20>0,AG20>0),AG20/(S20),0) -> 0 | AL20: ='12'!I46 -> 37186.62 | AM20: =AL20+AM19 -> 155504.15 | AN20: =IF(AND(L20>0,AL20>0),(AL20/(P20*1000)*1000),0) -> 871.4729 | AO20: =IF(AND(M20>0,AM20>0),(AM20/(Q20*1000)*1000),0) -> 1017.2846 | AP20: =IF(AND(R20>0,AL20>0),(AL20/(R20*1000)*1000),0) -> 830.70747 | AQ20: =IF(AND(S20>0,AM20>0),(AM20/(S20*1000)*1000),0) -> 1113.8867 | AR20: =+Listrik!AA19 -> 0 | AS20: =AR20+AS19 -> 0 | AT20: =IF(AND(L20>0,AR20>0),(AR20/(P20*1000)*1000),0) -> 0 | AU20: =IF(AND(M20>0,AS20>0),(AS20/(Q20*1000)*1000),0) -> 0 | AV20: =IF(AND(R20>0,AR20>0),(AR20/(R20*1000)*1000),0) -> 0 | AW20: =IF(AND(S20>0,AS20>0),(AS20/(S20*1000)*1000),0) -> 0 | AY20: =+Efficiency2!K61 -> 51.547967 | AZ20: =AZ19+AY20 -> 195.7363 | BA20: =+R20/AY20 -> 0.86841446 | BB20: =+S20/AZ20 -> 0.71322999
A21: =A20+1 -> 45943 | B21: Toilet | C21: 14,5 | D21: =+'13'!F42 -> 1193.4896 | E21: =+'13'!G42 -> 929.93847 | F21: =1-(E21/D21) -> 0.22082397 | G21: =+P21/N21 -> 0.87619892 | H21: =+P21/L21 -> 0.8467484 | I21: =+R21/P21 -> 0.96778111 | J21: =+R21/L21 -> 0.81946711 | K21: =+S21/M21 -> 0.26693728 | L21: =+Efficiency1!K66 -> 51.537151 | M21: =M20+L21 -> 681.20123 | N21: =+Efficiency1!C66 -> 49.804901 | O21: =O20+N21 -> 660.52714 | P21: ='13'!I38 -> 43.639 | Q21: =Q20+P21 -> 196.501 | R21: ='13'!I40 -> 42.233 | S21: =S20+R21 -> 181.838 | T21: =+[1]Report1!AZ21 -> 3966.529 | U21: =T21+U20 -> 18235.446 | V21: =T21/P21 -> 90.894131 | W21: =U21/Q21 -> 92.800778 | X21: =IF(AND(R21>0,T21>0),(T21/(R21*1000))*1000,0) -> 93.920133 | Y21: =IF(AND(S21>0,U21>0),U21/S21,0) -> 100.28402 | Z21: 94.3 | AA21: =Z21+AA20 -> 444.8 | AB21: =Z21/(P21) -> 2.1609111 | AC21: =AA21/(Q21) -> 2.2636017 | AD21: =IF(AND(R21>0,Z21>0),Z21/(R21),0) -> 2.2328511 | AE21: =IF(AND(S21>0,AA21>0),AA21/(S21),0) -> 2.4461334 | AF21: 0 | AG21: =+AF21+AG20 -> 0 | AH21: =AF21/(P21) -> 0 | AI21: =AG21/(Q21) -> 0 | AJ21: =IF(AND(R21>0,AF21>0),AF21/(R21),0) -> 0 | AK21: =IF(AND(S21>0,AG21>0),AG21/(S21),0) -> 0 | AL21: ='13'!I46 -> 40184.41 | AM21: =AL21+AM20 -> 195688.56 | AN21: =IF(AND(L21>0,AL21>0),(AL21/(P21*1000)*1000),0) -> 920.8371 | AO21: =IF(AND(M21>0,AM21>0),(AM21/(Q21*1000)*1000),0) -> 995.86548 | AP21: =IF(AND(R21>0,AL21>0),(AL21/(R21*1000)*1000),0) -> 951.49315 | AQ21: =IF(AND(S21>0,AM21>0),(AM21/(S21*1000)*1000),0) -> 1076.1698 | AR21: =+Listrik!AA20 -> 0 | AS21: =AR21+AS20 -> 0 | AT21: =IF(AND(L21>0,AR21>0),(AR21/(P21*1000)*1000),0) -> 0 | AU21: =IF(AND(M21>0,AS21>0),(AS21/(Q21*1000)*1000),0) -> 0 | AV21: =IF(AND(R21>0,AR21>0),(AR21/(R21*1000)*1000),0) -> 0 | AW21: =IF(AND(S21>0,AS21>0),(AS21/(S21*1000)*1000),0) -> 0 | AY21: =+Efficiency2!K66 -> 51.537151 | AZ21: =AZ20+AY21 -> 247.27345 | BA21: =+R21/AY21 -> 0.81946711 | BB21: =+S21/AZ21 -> 0.73537211
A22: =A21+1 -> 45944 | B22: Toilet | C22: 14,5/13,5 | D22: =+'14'!F42 -> 1233.4722 | E22: =+'14'!G42 -> 970.61736 | F22: =1-(E22/D22) -> 0.21310157 | G22: =+P22/N22 -> 0.89169958 | H22: =+P22/L22 -> 0.87477633 | I22: =+R22/P22 -> 0.86588979 | J22: =+R22/L22 -> 0.75745989 | K22: =+S22/M22 -> 0.30178192 | L22: =+SUM(Efficiency1!K70:K71) -> 52.089887 | M22: =M21+L22 -> 733.29111 | N22: =+SUM(Efficiency1!C70:C71) -> 51.101291 | O22: =O21+N22 -> 711.62843 | P22: ='14'!I38 -> 45.567 | Q22: =Q21+P22 -> 242.068 | R22: ='14'!I40 -> 39.456 | S22: =S21+R22 -> 221.294 | T22: =+[1]Report1!AZ22 -> 4108.524 | U22: =T22+U21 -> 22343.97 | V22: =T22/P22 -> 90.164461 | W22: =U22/Q22 -> 92.304516 | X22: =IF(AND(R22>0,T22>0),(T22/(R22*1000))*1000,0) -> 104.12926 | Y22: =IF(AND(S22>0,U22>0),U22/S22,0) -> 100.96961 | Z22: 95.4 | AA22: =Z22+AA21 -> 540.2 | AB22: =Z22/(P22) -> 2.0936204 | AC22: =AA22/(Q22) -> 2.2316043 | AD22: =IF(AND(R22>0,Z22>0),Z22/(R22),0) -> 2.4178832 | AE22: =IF(AND(S22>0,AA22>0),AA22/(S22),0) -> 2.4410965 | AF22: 0 | AG22: =+AF22+AG21 -> 0 | AH22: =AF22/(P22) -> 0 | AI22: =AG22/(Q22) -> 0 | AJ22: =IF(AND(R22>0,AF22>0),AF22/(R22),0) -> 0 | AK22: =IF(AND(S22>0,AG22>0),AG22/(S22),0) -> 0 | AL22: ='14'!I46 -> 42128.6 | AM22: =AL22+AM21 -> 237817.16 | AN22: =IF(AND(L22>0,AL22>0),(AL22/(P22*1000)*1000),0) -> 924.54188 | AO22: =IF(AND(M22>0,AM22>0),(AM22/(Q22*1000)*1000),0) -> 982.43949 | AP22: =IF(AND(R22>0,AL22>0),(AL22/(R22*1000)*1000),0) -> 1067.7362 | AQ22: =IF(AND(S22>0,AM22>0),(AM22/(S22*1000)*1000),0) -> 1074.6661 | AR22: =+Listrik!AA21 -> 0 | AS22: =AR22+AS21 -> 0 | AT22: =IF(AND(L22>0,AR22>0),(AR22/(P22*1000)*1000),0) -> 0 | AU22: =IF(AND(M22>0,AS22>0),(AS22/(Q22*1000)*1000),0) -> 0 | AV22: =IF(AND(R22>0,AR22>0),(AR22/(R22*1000)*1000),0) -> 0 | AW22: =IF(AND(S22>0,AS22>0),(AS22/(S22*1000)*1000),0) -> 0 | AY22: =+SUM(Efficiency2!K70:K71) -> 52.089887 | AZ22: =AZ21+AY22 -> 299.36334 | BA22: =+R22/AY22 -> 0.75745989 | BB22: =+S22/AZ22 -> 0.73921543
A23: =A22+1 -> 45945 | B23: Toilet | C23: 13,5/16,5/12,5 | D23: =+'15'!F42 -> 1251.0825 | E23: =+'15'!G42 -> 983.96389 | F23: =1-(E23/D23) -> 0.21350997 | G23: =+P23/N23 -> 0.91002021 | H23: =+P23/L23 -> 0.88709355 | I23: =+R23/P23 -> 0.86179056 | J23: =+R23/L23 -> 0.76448885 | K23: =+S23/M23 -> 0.3323878 | L23: =+SUM(Efficiency1!K74:K76) -> 51.939279 | M23: =M22+L23 -> 785.23039 | N23: =+SUM(Efficiency1!C74:C76) -> 50.630744 | O23: =O22+N23 -> 762.25918 | P23: ='15'!I38 -> 46.075 | Q23: =Q22+P23 -> 288.143 | R23: ='15'!I40 -> 39.707 | S23: =S22+R23 -> 261.001 | T23: =+[1]Report1!AZ23 -> 3919.3263 | U23: =T23+U22 -> 26263.296 | V23: =T23/P23 -> 85.064055 | W23: =U23/Q23 -> 91.146743 | X23: =IF(AND(R23>0,T23>0),(T23/(R23*1000))*1000,0) -> 98.706181 | Y23: =IF(AND(S23>0,U23>0),U23/S23,0) -> 100.62527 | Z23: 94.8 | AA23: =Z23+AA22 -> 635 | AB23: =Z23/(P23) -> 2.0575149 | AC23: =AA23/(Q23) -> 2.2037669 | AD23: =IF(AND(R23>0,Z23>0),Z23/(R23),0) -> 2.3874884 | AE23: =IF(AND(S23>0,AA23>0),AA23/(S23),0) -> 2.4329409 | AF23: 0 | AG23: =+AF23+AG22 -> 0 | AH23: =AF23/(P23) -> 0 | AI23: =AG23/(Q23) -> 0 | AJ23: =IF(AND(R23>0,AF23>0),AF23/(R23),0) -> 0 | AK23: =IF(AND(S23>0,AG23>0),AG23/(S23),0) -> 0 | AL23: ='15'!I46 -> 41750.8 | AM23: =AL23+AM22 -> 279567.96 | AN23: =IF(AND(L23>0,AL23>0),(AL23/(P23*1000)*1000),0) -> 906.14867 | AO23: =IF(AND(M23>0,AM23>0),(AM23/(Q23*1000)*1000),0) -> 970.24034 | AP23: =IF(AND(R23>0,AL23>0),(AL23/(R23*1000)*1000),0) -> 1051.472 | AQ23: =IF(AND(S23>0,AM23>0),(AM23/(S23*1000)*1000),0) -> 1071.1375 | AR23: =+Listrik!AA22 -> 0 | AS23: =AR23+AS22 -> 0 | AT23: =IF(AND(L23>0,AR23>0),(AR23/(P23*1000)*1000),0) -> 0 | AU23: =IF(AND(M23>0,AS23>0),(AS23/(Q23*1000)*1000),0) -> 0 | AV23: =IF(AND(R23>0,AR23>0),(AR23/(R23*1000)*1000),0) -> 0 | AW23: =IF(AND(S23>0,AS23>0),(AS23/(S23*1000)*1000),0) -> 0 | AY23: =+SUM(Efficiency2!K74:K76) -> 51.939279 | AZ23: =AZ22+AY23 -> 351.30262 | BA23: =+R23/AY23 -> 0.76448885 | BB23: =+S23/AZ23 -> 0.74295205
A24: =A23+1 -> 45946 | B24: Toilet/Towel | C24: 12,5/16,5/18 | D24: =+'16'!F42 -> 1090.4518 | E24: =+'16'!G42 -> 846.1718 | F24: =1-(E24/D24) -> 0.22401724 | G24: =+P24/N24 -> 0.9157624 | H24: =+P24/L24 -> 0.9157624 | I24: =+R24/P24 -> 0.91224431 | J24: =+R24/L24 -> 0.83539903 | K24: =+S24/M24 -> 0.36398766 | L24: =+SUM(Efficiency1!K78:K81) -> 52.635924 | M24: =M23+L24 -> 837.86632 | N24: =+SUM(Efficiency1!C78:C81) -> 52.635924 | O24: =O23+N24 -> 814.8951 | P24: ='16'!I38 -> 48.202 | Q24: =Q23+P24 -> 336.345 | R24: ='16'!I40 -> 43.972 | S24: =S23+R24 -> 304.973 | T24: =+[1]Report1!AZ24 -> 3927.6601 | U24: =T24+U23 -> 30190.956 | V24: =T24/P24 -> 81.483343 | W24: =U24/Q24 -> 89.76187 | X24: =IF(AND(R24>0,T24>0),(T24/(R24*1000))*1000,0) -> 89.321844 | Y24: =IF(AND(S24>0,U24>0),U24/S24,0) -> 98.995505 | Z24: 101.8 | AA24: =Z24+AA23 -> 736.8 | AB24: =Z24/(P24) -> 2.1119456 | AC24: =AA24/(Q24) -> 2.1906079 | AD24: =IF(AND(R24>0,Z24>0),Z24/(R24),0) -> 2.3151096 | AE24: =IF(AND(S24>0,AA24>0),AA24/(S24),0) -> 2.4159516 | AF24: 0 | AG24: =+AF24+AG23 -> 0 | AH24: =AF24/(P24) -> 0 | AI24: =AG24/(Q24) -> 0 | AJ24: =IF(AND(R24>0,AF24>0),AF24/(R24),0) -> 0 | AK24: =IF(AND(S24>0,AG24>0),AG24/(S24),0) -> 0 | AL24: ='16'!I46 -> 42060.6 | AM24: =AL24+AM23 -> 321628.56 | AN24: =IF(AND(L24>0,AL24>0),(AL24/(P24*1000)*1000),0) -> 872.59035 | AO24: =IF(AND(M24>0,AM24>0),(AM24/(Q24*1000)*1000),0) -> 956.246 | AP24: =IF(AND(R24>0,AL24>0),(AL24/(R24*1000)*1000),0) -> 956.53143 | AQ24: =IF(AND(S24>0,AM24>0),(AM24/(S24*1000)*1000),0) -> 1054.6132 | AR24: =+Listrik!AA23 -> 0 | AS24: =AR24+AS23 -> 0 | AT24: =IF(AND(L24>0,AR24>0),(AR24/(P24*1000)*1000),0) -> 0 | AU24: =IF(AND(M24>0,AS24>0),(AS24/(Q24*1000)*1000),0) -> 0 | AV24: =IF(AND(R24>0,AR24>0),(AR24/(R24*1000)*1000),0) -> 0 | AW24: =IF(AND(S24>0,AS24>0),(AS24/(S24*1000)*1000),0) -> 0 | AY24: =+SUM(Efficiency2!K78:K80) -> 52.635924 | AZ24: =AZ23+AY24 -> 403.93854 | BA24: =+R24/AY24 -> 0.83539903 | BB24: =+S24/AZ24 -> 0.75499852
A25: =A24+1 -> 45947 | B25: Towel | C25: 18 | D25: =+'17'!F42 -> 1026.6667 | E25: =+'17'!G42 -> 776.93333 | F25: =1-(E25/D25) -> 0.24324675 | G25: =+P25/N25 -> 0.98365474 | H25: =+P25/L25 -> 0.97573482 | I25: =+R25/P25 -> 1.0814001 | J25: =+R25/L25 -> 1.0551598 | K25: =+S25/M25 -> 0.4045048 | L25: =+Efficiency1!K83 -> 52.175037 | M25: =M24+L25 -> 890.04135 | N25: =+Efficiency1!C83 -> 51.754948 | O25: =O24+N25 -> 866.65005 | P25: ='17'!I38 -> 50.909 | Q25: =Q24+P25 -> 387.254 | R25: ='17'!I40 -> 55.053 | S25: =S24+R25 -> 360.026 | T25: =+[1]Report1!AZ25 -> 4142.5594 | U25: =T25+U24 -> 34333.515 | V25: =T25/P25 -> 81.371847 | W25: =U25/Q25 -> 88.658904 | X25: =IF(AND(R25>0,T25>0),(T25/(R25*1000))*1000,0) -> 75.246751 | Y25: =IF(AND(S25>0,U25>0),U25/S25,0) -> 95.363989 | Z25: 104.6 | AA25: =Z25+AA24 -> 841.4 | AB25: =Z25/(P25) -> 2.0546465 | AC25: =AA25/(Q25) -> 2.1727342 | AD25: =IF(AND(R25>0,Z25>0),Z25/(R25),0) -> 1.8999873 | AE25: =IF(AND(S25>0,AA25>0),AA25/(S25),0) -> 2.3370534 | AF25: 0 | AG25: =+AF25+AG24 -> 0 | AH25: =AF25/(P25) -> 0 | AI25: =AG25/(Q25) -> 0 | AJ25: =IF(AND(R25>0,AF25>0),AF25/(R25),0) -> 0 | AK25: =IF(AND(S25>0,AG25>0),AG25/(S25),0) -> 0 | AL25: ='17'!I46 -> 44528.14 | AM25: =AL25+AM24 -> 366156.7 | AN25: =IF(AND(L25>0,AL25>0),(AL25/(P25*1000)*1000),0) -> 874.66145 | AO25: =IF(AND(M25>0,AM25>0),(AM25/(Q25*1000)*1000),0) -> 945.52078 | AP25: =IF(AND(R25>0,AL25>0),(AL25/(R25*1000)*1000),0) -> 808.82313 | AQ25: =IF(AND(S25>0,AM25>0),(AM25/(S25*1000)*1000),0) -> 1017.0285 | AR25: =+Listrik!AA24 -> 0 | AS25: =AR25+AS24 -> 0 | AT25: =IF(AND(L25>0,AR25>0),(AR25/(P25*1000)*1000),0) -> 0 | AU25: =IF(AND(M25>0,AS25>0),(AS25/(Q25*1000)*1000),0) -> 0 | AV25: =IF(AND(R25>0,AR25>0),(AR25/(R25*1000)*1000),0) -> 0 | AW25: =IF(AND(S25>0,AS25>0),(AS25/(S25*1000)*1000),0) -> 0 | AY25: =+Efficiency2!K83 -> 52.175037 | AZ25: =AZ24+AY25 -> 456.11358 | BA25: =+R25/AY25 -> 1.0551598 | BB25: =+S25/AZ25 -> 0.7893341
A26: =A25+1 -> 45948 | B26: Towel | C26: 18 | D26: =+'18'!F42 -> 1020.7083 | E26: =+'18'!G42 -> 765.52417 | F26: =1-(E26/D26) -> 0.25000694 | G26: =+P26/N26 -> 0.91014925 | H26: =+P26/L26 -> 0.89757326 | I26: =+R26/P26 -> 1.0348394 | J26: =+R26/L26 -> 0.92884416 | K26: =+S26/M26 -> 0.4332951 | L26: =+Efficiency1!K87 -> 51.709428 | M26: =M25+L26 -> 941.75078 | N26: =+Efficiency1!C87 -> 50.994933 | O26: =O25+N26 -> 917.64498 | P26: ='18'!I38 -> 46.413 | Q26: =Q25+P26 -> 433.667 | R26: ='18'!I40 -> 48.03 | S26: =S25+R26 -> 408.056 | T26: =+[1]Report1!AZ26 -> 3881.8829 | U26: =T26+U25 -> 38215.398 | V26: =T26/P26 -> 83.637837 | W26: =U26/Q26 -> 88.121527 | X26: =IF(AND(R26>0,T26>0),(T26/(R26*1000))*1000,0) -> 80.822047 | Y26: =IF(AND(S26>0,U26>0),U26/S26,0) -> 93.652338 | Z26: 102.8 | AA26: =Z26+AA25 -> 944.2 | AB26: =Z26/(P26) -> 2.2148967 | AC26: =AA26/(Q26) -> 2.1772466 | AD26: =IF(AND(R26>0,Z26>0),Z26/(R26),0) -> 2.140329 | AE26: =IF(AND(S26>0,AA26>0),AA26/(S26),0) -> 2.3138981 | AF26: 0 | AG26: =+AF26+AG25 -> 0 | AH26: =AF26/(P26) -> 0 | AI26: =AG26/(Q26) -> 0 | AJ26: =IF(AND(R26>0,AF26>0),AF26/(R26),0) -> 0 | AK26: =IF(AND(S26>0,AG26>0),AG26/(S26),0) -> 0 | AL26: ='18'!I46 -> 46691.97 | AM26: =AL26+AM25 -> 412848.67 | AN26: =IF(AND(L26>0,AL26>0),(AL26/(P26*1000)*1000),0) -> 1006.0106 | AO26: =IF(AND(M26>0,AM26>0),(AM26/(Q26*1000)*1000),0) -> 951.99467 | AP26: =IF(AND(R26>0,AL26>0),(AL26/(R26*1000)*1000),0) -> 972.14179 | AQ26: =IF(AND(S26>0,AM26>0),(AM26/(S26*1000)*1000),0) -> 1011.7451 | AR26: =+Listrik!AA25 -> 0 | AS26: =AR26+AS25 -> 0 | AT26: =IF(AND(L26>0,AR26>0),(AR26/(P26*1000)*1000),0) -> 0 | AU26: =IF(AND(M26>0,AS26>0),(AS26/(Q26*1000)*1000),0) -> 0 | AV26: =IF(AND(R26>0,AR26>0),(AR26/(R26*1000)*1000),0) -> 0 | AW26: =IF(AND(S26>0,AS26>0),(AS26/(S26*1000)*1000),0) -> 0 | AY26: =+Efficiency2!K87 -> 51.709428 | AZ26: =AZ25+AY26 -> 507.82301 | BA26: =+R26/AY26 -> 0.92884416 | BB26: =+S26/AZ26 -> 0.80353981
A27: =A26+1 -> 45949 | B27: Towel | C27: 18 | D27: =+'19'!F42 -> 1017.6681 | E27: =+'19'!G42 -> 775.69032 | F27: =1-(E27/D27) -> 0.23777675 | G27: =+P27/N27 -> 0.943429 | H27: =+P27/L27 -> 0.92763056 | I27: =+R27/P27 -> 0.93659357 | J27: =+R27/L27 -> 0.86881282 | K27: =+S27/M27 -> 0.45631364 | L27: =+Efficiency1!K91 -> 52.552171 | M27: =M26+L27 -> 994.30295 | N27: =+Efficiency1!C91 -> 51.672145 | O27: =O26+N27 -> 969.31713 | P27: ='19'!I38 -> 48.749 | Q27: =Q26+P27 -> 482.416 | R27: ='19'!I40 -> 45.658 | S27: =S26+R27 -> 453.714 | T27: =+[1]Report1!AZ27 -> 4757.3024 | U27: =T27+U26 -> 42972.701 | V27: =T27/P27 -> 97.587693 | W27: =U27/Q27 -> 89.0781 | X27: =IF(AND(R27>0,T27>0),(T27/(R27*1000))*1000,0) -> 104.19428 | Y27: =IF(AND(S27>0,U27>0),U27/S27,0) -> 94.713191 | Z27: 102.9 | AA27: =Z27+AA26 -> 1047.1 | AB27: =Z27/(P27) -> 2.1108125 | AC27: =AA27/(Q27) -> 2.1705333 | AD27: =IF(AND(R27>0,Z27>0),Z27/(R27),0) -> 2.2537124 | AE27: =IF(AND(S27>0,AA27>0),AA27/(S27),0) -> 2.3078415 | AF27: 0 | AG27: =+AF27+AG26 -> 0 | AH27: =AF27/(P27) -> 0 | AI27: =AG27/(Q27) -> 0 | AJ27: =IF(AND(R27>0,AF27>0),AF27/(R27),0) -> 0 | AK27: =IF(AND(S27>0,AG27>0),AG27/(S27),0) -> 0 | AL27: ='19'!I46 -> 39424.87 | AM27: =AL27+AM26 -> 452273.54 | AN27: =IF(AND(L27>0,AL27>0),(AL27/(P27*1000)*1000),0) -> 808.73187 | AO27: =IF(AND(M27>0,AM27>0),(AM27/(Q27*1000)*1000),0) -> 937.51771 | AP27: =IF(AND(R27>0,AL27>0),(AL27/(R27*1000)*1000),0) -> 863.48219 | AQ27: =IF(AND(S27>0,AM27>0),(AM27/(S27*1000)*1000),0) -> 996.82519 | AR27: =+Listrik!AA26 -> 0 | AS27: =AR27+AS26 -> 0 | AT27: =IF(AND(L27>0,AR27>0),(AR27/(P27*1000)*1000),0) -> 0 | AU27: =IF(AND(M27>0,AS27>0),(AS27/(Q27*1000)*1000),0) -> 0 | AV27: =IF(AND(R27>0,AR27>0),(AR27/(R27*1000)*1000),0) -> 0 | AW27: =IF(AND(S27>0,AS27>0),(AS27/(S27*1000)*1000),0) -> 0 | AY27: =+Efficiency2!K91 -> 52.552171 | AZ27: =AZ26+AY27 -> 560.37518 | BA27: =+R27/AY27 -> 0.86881282 | BB27: =+S27/AZ27 -> 0.80966113
A28: =A27+1 -> 45950 | B28: Towel | C28: 18 | D28: =+'20'!F42 -> 1013.3333 | E28: =+'20'!G42 -> 770.13333 | F28: =1-(E28/D28) -> 0.24 | G28: =+P28/N28 -> 0.9639201 | H28: =+P28/L28 -> 0.94374142 | I28: =+R28/P28 -> 0.98964632 | J28: =+R28/L28 -> 0.93397022 | K28: =+S28/M28 -> 0.48022558 | L28: =+Efficiency1!K95 -> 52.398887 | M28: =M27+L28 -> 1046.7018 | N28: =+Efficiency1!C95 -> 51.30197 | O28: =O27+N28 -> 1020.6191 | P28: ='20'!I38 -> 49.451 | Q28: =Q27+P28 -> 531.867 | R28: ='20'!I40 -> 48.939 | S28: =S27+R28 -> 502.653 | T28: =+[1]Report1!AZ28 -> 4568.7659 | U28: =T28+U27 -> 47541.467 | V28: =T28/P28 -> 92.389758 | W28: =U28/Q28 -> 89.386006 | X28: =IF(AND(R28>0,T28>0),(T28/(R28*1000))*1000,0) -> 93.35634 | Y28: =IF(AND(S28>0,U28>0),U28/S28,0) -> 94.581086 | Z28: 102.9 | AA28: =Z28+AA27 -> 1150 | AB28: =Z28/(P28) -> 2.0808477 | AC28: =AA28/(Q28) -> 2.1621947 | AD28: =IF(AND(R28>0,Z28>0),Z28/(R28),0) -> 2.1026175 | AE28: =IF(AND(S28>0,AA28>0),AA28/(S28),0) -> 2.2878606 | AF28: 0 | AG28: =+AF28+AG27 -> 0 | AH28: =AF28/(P28) -> 0 | AI28: =AG28/(Q28) -> 0 | AJ28: =IF(AND(R28>0,AF28>0),AF28/(R28),0) -> 0 | AK28: =IF(AND(S28>0,AG28>0),AG28/(S28),0) -> 0 | AL28: ='20'!I46 -> 40537.83 | AM28: =AL28+AM27 -> 492811.37 | AN28: =IF(AND(L28>0,AL28>0),(AL28/(P28*1000)*1000),0) -> 819.75754 | AO28: =IF(AND(M28>0,AM28>0),(AM28/(Q28*1000)*1000),0) -> 926.56881 | AP28: =IF(AND(R28>0,AL28>0),(AL28/(R28*1000)*1000),0) -> 828.33384 | AQ28: =IF(AND(S28>0,AM28>0),(AM28/(S28*1000)*1000),0) -> 980.42063 | AR28: =+Listrik!AA27 -> 0 | AS28: =AR28+AS27 -> 0 | AT28: =IF(AND(L28>0,AR28>0),(AR28/(P28*1000)*1000),0) -> 0 | AU28: =IF(AND(M28>0,AS28>0),(AS28/(Q28*1000)*1000),0) -> 0 | AV28: =IF(AND(R28>0,AR28>0),(AR28/(R28*1000)*1000),0) -> 0 | AW28: =IF(AND(S28>0,AS28>0),(AS28/(S28*1000)*1000),0) -> 0 | AY28: =+Efficiency2!K95 -> 52.398887 | AZ28: =AZ27+AY28 -> 612.77406 | BA28: =+R28/AY28 -> 0.93397022 | BB28: =+S28/AZ28 -> 0.82029092
A29: =A28+1 -> 45951 | B29: Towel/Facial/Toilet | C29: 18/15/12 | D29: =+'21'!F42 -> 1258.9259 | E29: =+'21'!G42 -> 925.19089 | F29: =1-(E29/D29) -> 0.26509505 | G29: =+P29/N29 -> 0.87947368 | H29: =+P29/L29 -> 0.86180515 | I29: =+R29/P29 -> 0.94613866 | J29: =+R29/L29 -> 0.81538717 | K29: =+S29/M29 -> 0.49463715 | L29: =+SUM(Efficiency1!K99:K102) -> 47.029192 | M29: =M28+L29 -> 1093.731 | N29: =+SUM(Efficiency1!C99:C102) -> 46.084381 | O29: =O28+N29 -> 1066.7035 | P29: ='21'!I38 -> 40.53 | Q29: =Q28+P29 -> 572.397 | R29: ='21'!I40 -> 38.347 | S29: =S28+R29 -> 541 | T29: =+[1]Report1!AZ29 -> 4524.8061 | U29: =T29+U28 -> 52066.273 | V29: =T29/P29 -> 111.64091 | W29: =U29/Q29 -> 90.96182 | X29: =IF(AND(R29>0,T29>0),(T29/(R29*1000))*1000,0) -> 117.99635 | Y29: =IF(AND(S29>0,U29>0),U29/S29,0) -> 96.2408 | Z29: 91.8 | AA29: =Z29+AA28 -> 1241.8 | AB29: =Z29/(P29) -> 2.2649889 | AC29: =AA29/(Q29) -> 2.1694733 | AD29: =IF(AND(R29>0,Z29>0),Z29/(R29),0) -> 2.3939291 | AE29: =IF(AND(S29>0,AA29>0),AA29/(S29),0) -> 2.2953789 | AF29: 0 | AG29: =+AF29+AG28 -> 0 | AH29: =AF29/(P29) -> 0 | AI29: =AG29/(Q29) -> 0 | AJ29: =IF(AND(R29>0,AF29>0),AF29/(R29),0) -> 0 | AK29: =IF(AND(S29>0,AG29>0),AG29/(S29),0) -> 0 | AL29: ='21'!I46 -> 41992.29 | AM29: =AL29+AM28 -> 534803.66 | AN29: =IF(AND(L29>0,AL29>0),(AL29/(P29*1000)*1000),0) -> 1036.0792 | AO29: =IF(AND(M29>0,AM29>0),(AM29/(Q29*1000)*1000),0) -> 934.32297 | AP29: =IF(AND(R29>0,AL29>0),(AL29/(R29*1000)*1000),0) -> 1095.0606 | AQ29: =IF(AND(S29>0,AM29>0),(AM29/(S29*1000)*1000),0) -> 988.54651 | AR29: =+Listrik!AA28 -> 0 | AS29: =AR29+AS28 -> 0 | AT29: =IF(AND(L29>0,AR29>0),(AR29/(P29*1000)*1000),0) -> 0 | AU29: =IF(AND(M29>0,AS29>0),(AS29/(Q29*1000)*1000),0) -> 0 | AV29: =IF(AND(R29>0,AR29>0),(AR29/(R29*1000)*1000),0) -> 0 | AW29: =IF(AND(S29>0,AS29>0),(AS29/(S29*1000)*1000),0) -> 0 | AY29: =+SUM(Efficiency2!K99:K101) -> 47.029192 | AZ29: =AZ28+AY29 -> 659.80326 | BA29: =+R29/AY29 -> 0.81538717 | BB29: =+S29/AZ29 -> 0.81994139
A30: =A29+1 -> 45952 | B30: Toilet/Facial | C30: 12/12/12,5 | D30: =+'22'!F42 -> 1341.6667 | E30: =+'22'!G42 -> 997.16667 | F30: =1-(E30/D30) -> 0.25677019 | G30: =+P30/N30 -> 0.90230942 | H30: =+P30/L30 -> 0.89684375 | I30: =+R30/P30 -> 0.92599917 | J30: =+R30/L30 -> 0.83047657 | K30: =+S30/M30 -> 0.50809847 | L30: =+SUM(Efficiency1!K104:K106) -> 45.670163 | M30: =M29+L30 -> 1139.4012 | N30: =+SUM(Efficiency1!C104:C106) -> 45.393519 | O30: =O29+N30 -> 1112.097 | P30: ='22'!I38 -> 40.959 | Q30: =Q29+P30 -> 613.356 | R30: ='22'!I40 -> 37.928 | S30: =S29+R30 -> 578.928 | T30: =+[1]Report1!AZ30 -> 4602.2886 | U30: =T30+U29 -> 56668.561 | V30: =T30/P30 -> 112.3633 | W30: =U30/Q30 -> 92.390979 | X30: =IF(AND(R30>0,T30>0),(T30/(R30*1000))*1000,0) -> 121.34277 | Y30: =IF(AND(S30>0,U30>0),U30/S30,0) -> 97.885335 | Z30: 91.4 | AA30: =Z30+AA29 -> 1333.2 | AB30: =Z30/(P30) -> 2.2314998 | AC30: =AA30/(Q30) -> 2.1736153 | AD30: =IF(AND(R30>0,Z30>0),Z30/(R30),0) -> 2.4098291 | AE30: =IF(AND(S30>0,AA30>0),AA30/(S30),0) -> 2.302877 | AF30: 0 | AG30: =+AF30+AG29 -> 0 | AH30: =AF30/(P30) -> 0 | AI30: =AG30/(Q30) -> 0 | AJ30: =IF(AND(R30>0,AF30>0),AF30/(R30),0) -> 0 | AK30: =IF(AND(S30>0,AG30>0),AG30/(S30),0) -> 0 | AL30: ='22'!I46 -> 42396.22 | AM30: =AL30+AM29 -> 577199.88 | AN30: =IF(AND(L30>0,AL30>0),(AL30/(P30*1000)*1000),0) -> 1035.0892 | AO30: =IF(AND(M30>0,AM30>0),(AM30/(Q30*1000)*1000),0) -> 941.05199 | AP30: =IF(AND(R30>0,AL30>0),(AL30/(R30*1000)*1000),0) -> 1117.808 | AQ30: =IF(AND(S30>0,AM30>0),(AM30/(S30*1000)*1000),0) -> 997.01497 | AR30: =+Listrik!AA29 -> 0 | AS30: =AR30+AS29 -> 0 | AT30: =IF(AND(L30>0,AR30>0),(AR30/(P30*1000)*1000),0) -> 0 | AU30: =IF(AND(M30>0,AS30>0),(AS30/(Q30*1000)*1000),0) -> 0 | AV30: =IF(AND(R30>0,AR30>0),(AR30/(R30*1000)*1000),0) -> 0 | AW30: =IF(AND(S30>0,AS30>0),(AS30/(S30*1000)*1000),0) -> 0 | AY30: =+SUM(Efficiency2!K104:K106) -> 45.670163 | AZ30: =AZ29+AY30 -> 705.47342 | BA30: =+R30/AY30 -> 0.83047657 | BB30: =+S30/AZ30 -> 0.82062341
A31: =A30+1 -> 45953 | B31: Toilet | C31: 12,5/13/14,5 | D31: =+'23'!F42 -> 1287.7431 | E31: =+'23'!G42 -> 974.14062 | F31: =1-(E31/D31) -> 0.24352873 | G31: =+P31/N31 -> 0.95729036 | H31: =+P31/L31 -> 0.95254788 | I31: =+R31/P31 -> 0.87211536 | J31: =+R31/L31 -> 0.83073164 | K31: =+S31/M31 -> 0.52187275 | L31: =+SUM(Efficiency1!K108:K110) -> 50.814243 | M31: =M30+L31 -> 1190.2154 | N31: =+SUM(Efficiency1!C108:C110) -> 50.562506 | O31: =O30+N31 -> 1162.6595 | P31: ='23'!I38 -> 48.403 | Q31: =Q30+P31 -> 661.759 | R31: ='23'!I40 -> 42.213 | S31: =S30+R31 -> 621.141 | T31: =+[1]Report1!AZ31 -> 4680.104 | U31: =T31+U30 -> 61348.665 | V31: =T31/P31 -> 96.690371 | W31: =U31/Q31 -> 92.705449 | X31: =IF(AND(R31>0,T31>0),(T31/(R31*1000))*1000,0) -> 110.86879 | Y31: =IF(AND(S31>0,U31>0),U31/S31,0) -> 98.767696 | Z31: 96.3 | AA31: =Z31+AA30 -> 1429.5 | AB31: =Z31/(P31) -> 1.9895461 | AC31: =AA31/(Q31) -> 2.160152 | AD31: =IF(AND(R31>0,Z31>0),Z31/(R31),0) -> 2.2812878 | AE31: =IF(AND(S31>0,AA31>0),AA31/(S31),0) -> 2.3014098 | AF31: 0 | AG31: =+AF31+AG30 -> 0 | AH31: =AF31/(P31) -> 0 | AI31: =AG31/(Q31) -> 0 | AJ31: =IF(AND(R31>0,AF31>0),AF31/(R31),0) -> 0 | AK31: =IF(AND(S31>0,AG31>0),AG31/(S31),0) -> 0 | AL31: ='23'!I46 -> 44425.91 | AM31: =AL31+AM30 -> 621625.79 | AN31: =IF(AND(L31>0,AL31>0),(AL31/(P31*1000)*1000),0) -> 917.83381 | AO31: =IF(AND(M31>0,AM31>0),(AM31/(Q31*1000)*1000),0) -> 939.35374 | AP31: =IF(AND(R31>0,AL31>0),(AL31/(R31*1000)*1000),0) -> 1052.4225 | AQ31: =IF(AND(S31>0,AM31>0),(AM31/(S31*1000)*1000),0) -> 1000.7805 | AR31: =+Listrik!AA30 -> 0 | AS31: =AR31+AS30 -> 0 | AT31: =IF(AND(L31>0,AR31>0),(AR31/(P31*1000)*1000),0) -> 0 | AU31: =IF(AND(M31>0,AS31>0),(AS31/(Q31*1000)*1000),0) -> 0 | AV31: =IF(AND(R31>0,AR31>0),(AR31/(R31*1000)*1000),0) -> 0 | AW31: =IF(AND(S31>0,AS31>0),(AS31/(S31*1000)*1000),0) -> 0 | AY31: =+SUM(Efficiency2!K108:K110) -> 50.814243 | AZ31: =AZ30+AY31 -> 756.28766 | BA31: =+R31/AY31 -> 0.83073164 | BB31: =+S31/AZ31 -> 0.82130257
A32: =A31+1 -> 45954 | B32: Toilet/Facial | C32: 14,5/12/16 | D32: =+'24'!F42 -> 1280.5556 | E32: =+'24'!G42 -> 958.20833 | F32: =1-(E32/D32) -> 0.25172451 | G32: =+P32/N32 -> 0.85931236 | H32: =+P32/L32 -> 0.83552534 | I32: =+R32/P32 -> 0.96578671 | J32: =+R32/L32 -> 0.80693927 | K32: =+S32/M32 -> 0.53287601 | L32: =+SUM(Efficiency1!K112:K114) -> 47.785504 | M32: =M31+L32 -> 1238.0009 | N32: =+SUM(Efficiency1!C112:C114) -> 46.462732 | O32: =O31+N32 -> 1209.1222 | P32: ='24'!I38 -> 39.926 | Q32: =Q31+P32 -> 701.685 | R32: ='24'!I40 -> 38.56 | S32: =S31+R32 -> 659.701 | T32: =+[1]Report1!AZ32 -> 4262.64 | U32: =T32+U31 -> 65611.305 | V32: =T32/P32 -> 106.76351 | W32: =U32/Q32 -> 93.505355 | X32: =IF(AND(R32>0,T32>0),(T32/(R32*1000))*1000,0) -> 110.54564 | Y32: =IF(AND(S32>0,U32>0),U32/S32,0) -> 99.456125 | Z32: 89.9 | AA32: =Z32+AA31 -> 1519.4 | AB32: =Z32/(P32) -> 2.2516656 | AC32: =AA32/(Q32) -> 2.1653591 | AD32: =IF(AND(R32>0,Z32>0),Z32/(R32),0) -> 2.3314315 | AE32: =IF(AND(S32>0,AA32>0),AA32/(S32),0) -> 2.3031646 | AF32: 0 | AG32: =+AF32+AG31 -> 0 | AH32: =AF32/(P32) -> 0 | AI32: =AG32/(Q32) -> 0 | AJ32: =IF(AND(R32>0,AF32>0),AF32/(R32),0) -> 0 | AK32: =IF(AND(S32>0,AG32>0),AG32/(S32),0) -> 0 | AL32: =+'24'!I46 -> 44988.19 | AM32: =AL32+AM31 -> 666613.98 | AN32: =IF(AND(L32>0,AL32>0),(AL32/(P32*1000)*1000),0) -> 1126.7893 | AO32: =IF(AND(M32>0,AM32>0),(AM32/(Q32*1000)*1000),0) -> 950.01886 | AP32: =IF(AND(R32>0,AL32>0),(AL32/(R32*1000)*1000),0) -> 1166.7062 | AQ32: =IF(AND(S32>0,AM32>0),(AM32/(S32*1000)*1000),0) -> 1010.479 | AR32: =+Listrik!AA31 -> 0 | AS32: =AR32+AS31 -> 0 | AT32: =IF(AND(L32>0,AR32>0),(AR32/(P32*1000)*1000),0) -> 0 | AU32: =IF(AND(M32>0,AS32>0),(AS32/(Q32*1000)*1000),0) -> 0 | AV32: =IF(AND(R32>0,AR32>0),(AR32/(R32*1000)*1000),0) -> 0 | AW32: =IF(AND(S32>0,AS32>0),(AS32/(S32*1000)*1000),0) -> 0 | AY32: =+SUM(Efficiency2!K112:K114) -> 46.280138 | AZ32: =AZ31+AY32 -> 802.5678 | BA32: =+R32/AY32 -> 0.8331868 | BB32: =+S32/AZ32 -> 0.82198787
A33: =A32+1 -> 45955 | B33: Facial/Toilet | C33: 12/13 | D33: =+'25'!F42 -> 1214.2662 | E33: =+'25'!G42 -> 939.57873 | F33: =1-(E33/D33) -> 0.22621685 | G33: =+P33/N33 -> 0.67063396 | H33: =+P33/L33 -> 0.60240319 | I33: =+R33/P33 -> 0.77070424 | J33: =+R33/L33 -> 0.4642747 | K33: =+S33/M33 -> 0.5302216 | L33: =+SUM(Efficiency1!K117:K118) -> 49.830413 | M33: =M32+L33 -> 1287.8314 | N33: =+SUM(Efficiency1!C117:C118) -> 44.760632 | O33: =O32+N33 -> 1253.8829 | P33: ='25'!I38 -> 30.018 | Q33: =Q32+P33 -> 731.703 | R33: ='25'!I40 -> 23.135 | S33: =S32+R33 -> 682.836 | T33: =+[1]Report1!AZ33 -> 3112.4447 | U33: =T33+U32 -> 68723.75 | V33: =T33/P33 -> 103.68595 | W33: =U33/Q33 -> 93.923013 | X33: =IF(AND(R33>0,T33>0),(T33/(R33*1000))*1000,0) -> 134.53403 | Y33: =IF(AND(S33>0,U33>0),U33/S33,0) -> 100.64459 | Z33: 87.7 | AA33: =Z33+AA32 -> 1607.1 | AB33: =Z33/(P33) -> 2.9215804 | AC33: =AA33/(Q33) -> 2.196383 | AD33: =IF(AND(R33>0,Z33>0),Z33/(R33),0) -> 3.7907932 | AE33: =IF(AND(S33>0,AA33>0),AA33/(S33),0) -> 2.3535666 | AF33: 0 | AG33: =+AF33+AG32 -> 0 | AH33: =AF33/(P33) -> 0 | AI33: =AG33/(Q33) -> 0 | AJ33: =IF(AND(R33>0,AF33>0),AF33/(R33),0) -> 0 | AK33: =IF(AND(S33>0,AG33>0),AG33/(S33),0) -> 0 | AL33: =+'25'!I46 -> 42685.96 | AM33: =AL33+AM32 -> 709299.94 | AN33: =IF(AND(L33>0,AL33>0),(AL33/(P33*1000)*1000),0) -> 1422.0121 | AO33: =IF(AND(M33>0,AM33>0),(AM33/(Q33*1000)*1000),0) -> 969.38231 | AP33: =IF(AND(R33>0,AL33>0),(AL33/(R33*1000)*1000),0) -> 1845.0815 | AQ33: =IF(AND(S33>0,AM33>0),(AM33/(S33*1000)*1000),0) -> 1038.7559 | AR33: =+Listrik!AA32 -> 0 | AS33: =AR33+AS32 -> 0 | AT33: =IF(AND(L33>0,AR33>0),(AR33/(P33*1000)*1000),0) -> 0 | AU33: =IF(AND(M33>0,AS33>0),(AS33/(Q33*1000)*1000),0) -> 0 | AV33: =IF(AND(R33>0,AR33>0),(AR33/(R33*1000)*1000),0) -> 0 | AW33: =IF(AND(S33>0,AS33>0),(AS33/(S33*1000)*1000),0) -> 0 | AY33: =+SUM(Efficiency2!K117:K118) -> 49.830413 | AZ33: =AZ32+AY33 -> 852.39821 | BA33: =+R33/AY33 -> 0.4642747 | BB33: =+S33/AZ33 -> 0.80107629
A34: =A33+1 -> 45956 | B34: Toilet | C34: 13 | D34: =+'26'!F42 -> 799.0625 | E34: =+'26'!G42 -> 600.65573 | F34: =1-(E34/D34) -> 0.24829944 | G34: =+P34/N34 -> 1.2361673 | H34: =+P34/L34 -> 0.73168512 | I34: =+R34/P34 -> 0.67604409 | J34: =+R34/L34 -> 0.4946514 | K34: =+S34/M34 -> 0.52892481 | L34: =+Efficiency1!K122 -> 48.727245 | M34: =M33+L34 -> 1336.5586 | N34: =+Efficiency1!C122 -> 28.841566 | O34: =O33+N34 -> 1282.7244 | P34: ='26'!I38 -> 35.653 | Q34: =Q33+P34 -> 767.356 | R34: ='26'!I40 -> 24.103 | S34: =S33+R34 -> 706.939 | T34: =+[1]Report1!AZ34 -> 1235.1013 | U34: =T34+U33 -> 69958.851 | V34: =T34/P34 -> 34.642283 | W34: =U34/Q34 -> 91.168703 | X34: =IF(AND(R34>0,T34>0),(T34/(R34*1000))*1000,0) -> 51.242639 | Y34: =IF(AND(S34>0,U34>0),U34/S34,0) -> 98.960238 | Z34: 79.2 | AA34: =Z34+AA33 -> 1686.3 | AB34: =Z34/(P34) -> 2.2214119 | AC34: =AA34/(Q34) -> 2.1975459 | AD34: =IF(AND(R34>0,Z34>0),Z34/(R34),0) -> 3.285898 | AE34: =IF(AND(S34>0,AA34>0),AA34/(S34),0) -> 2.3853543 | AF34: 0 | AG34: =+AF34+AG33 -> 0 | AH34: =AF34/(P34) -> 0 | AI34: =AG34/(Q34) -> 0 | AJ34: =IF(AND(R34>0,AF34>0),AF34/(R34),0) -> 0 | AK34: =IF(AND(S34>0,AG34>0),AG34/(S34),0) -> 0 | AL34: ='26'!I46 -> 32910.33 | AM34: =AL34+AM33 -> 742210.27 | AN34: =IF(AND(L34>0,AL34>0),(AL34/(P34*1000)*1000),0) -> 923.07323 | AO34: =IF(AND(M34>0,AM34>0),(AM34/(Q34*1000)*1000),0) -> 967.23069 | AP34: =IF(AND(R34>0,AL34>0),(AL34/(R34*1000)*1000),0) -> 1365.4039 | AQ34: =IF(AND(S34>0,AM34>0),(AM34/(S34*1000)*1000),0) -> 1049.893 | AR34: =+Listrik!AA33 -> 0 | AS34: =AR34+AS33 -> 0 | AT34: =IF(AND(L34>0,AR34>0),(AR34/(P34*1000)*1000),0) -> 0 | AU34: =IF(AND(M34>0,AS34>0),(AS34/(Q34*1000)*1000),0) -> 0 | AV34: =IF(AND(R34>0,AR34>0),(AR34/(R34*1000)*1000),0) -> 0 | AW34: =IF(AND(S34>0,AS34>0),(AS34/(S34*1000)*1000),0) -> 0 | AY34: =+Efficiency2!K122 -> 28.841566 | AZ34: =AZ33+AY34 -> 881.23978 | BA34: =+R34/AY34 -> 0.83570358 | BB34: =+S34/AZ34 -> 0.80220959
A35: =A34+1 -> 45957 | B35: Toilet | C35: 13 | D35: =+'27'!F42 -> 1310.9076 | E35: =+'27'!G42 -> 1009.3988 | F35: =1-(E35/D35) -> 0.23 | G35: =+P35/N35 -> 0.7117192 | H35: =+P35/L35 -> 0.6911097 | I35: =+R35/P35 -> 0.81145704 | J35: =+R35/L35 -> 0.56080583 | K35: =+S35/M35 -> 0.530054 | L35: =+Efficiency1!K126 -> 49.077592 | M35: =M34+L35 -> 1385.6362 | N35: =+Efficiency1!C126 -> 47.656435 | O35: =O34+N35 -> 1330.3809 | P35: ='27'!I38 -> 33.918 | Q35: =Q34+P35 -> 801.274 | R35: ='27'!I40 -> 27.523 | S35: =S34+R35 -> 734.462 | T35: =+[1]Report1!AZ35 -> 3279.5542 | U35: =T35+U34 -> 73238.406 | V35: =T35/P35 -> 96.690673 | W35: =U35/Q35 -> 91.402449 | X35: =IF(AND(R35>0,T35>0),(T35/(R35*1000))*1000,0) -> 119.15686 | Y35: =IF(AND(S35>0,U35>0),U35/S35,0) -> 99.71708 | Z35: 78.7 | AA35: =Z35+AA34 -> 1765 | AB35: =Z35/(P35) -> 2.3203019 | AC35: =AA35/(Q35) -> 2.2027421 | AD35: =IF(AND(R35>0,Z35>0),Z35/(R35),0) -> 2.8594267 | AE35: =IF(AND(S35>0,AA35>0),AA35/(S35),0) -> 2.4031196 | AF35: 0 | AG35: =+AF35+AG34 -> 0 | AH35: =AF35/(P35) -> 0 | AI35: =AG35/(Q35) -> 0 | AJ35: =IF(AND(R35>0,AF35>0),AF35/(R35),0) -> 0 | AK35: =IF(AND(S35>0,AG35>0),AG35/(S35),0) -> 0 | AL35: ='27'!I46 -> 36787.73 | AM35: =AL35+AM34 -> 778998 | AN35: =IF(AND(L35>0,AL35>0),(AL35/(P35*1000)*1000),0) -> 1084.6079 | AO35: =IF(AND(M35>0,AM35>0),(AM35/(Q35*1000)*1000),0) -> 972.19928 | AP35: =IF(AND(R35>0,AL35>0),(AL35/(R35*1000)*1000),0) -> 1336.6177 | AQ35: =IF(AND(S35>0,AM35>0),(AM35/(S35*1000)*1000),0) -> 1060.6376 | AR35: =+Listrik!AA34 -> 0 | AS35: =AR35+AS34 -> 0 | AT35: =IF(AND(L35>0,AR35>0),(AR35/(P35*1000)*1000),0) -> 0 | AU35: =IF(AND(M35>0,AS35>0),(AS35/(Q35*1000)*1000),0) -> 0 | AV35: =IF(AND(R35>0,AR35>0),(AR35/(R35*1000)*1000),0) -> 0 | AW35: =IF(AND(S35>0,AS35>0),(AS35/(S35*1000)*1000),0) -> 0 | AY35: =+Efficiency2!K126 -> 49.077592 | AZ35: =AZ34+AY35 -> 930.31737 | BA35: =+R35/AY35 -> 0.56080583 | BB35: =+S35/AZ35 -> 0.78947467
A36: =A35+1 -> 45958 | B36: Toilet | C36: 13 | D36: =+'28'!F42 -> 1306.6667 | E36: =+'28'!G42 -> 1006.1333 | F36: =1-(E36/D36) -> 0.23 | G36: =+P36/N36 -> 0.93828257 | H36: =+P36/L36 -> 0.90816486 | I36: =+R36/P36 -> 1.1401101 | J36: =+R36/L36 -> 1.0354079 | K36: =+S36/M36 -> 0.54731995 | L36: =+Efficiency1!K132 -> 49.016431 | M36: =M35+L36 -> 1434.6526 | N36: =+Efficiency1!C132 -> 47.443064 | O36: =O35+N36 -> 1377.8239 | P36: ='28'!I38 -> 44.515 | Q36: =Q35+P36 -> 845.789 | R36: ='28'!I40 -> 50.752 | S36: =S35+R36 -> 785.214 | T36: =+[1]Report1!AZ36 -> 3987.5155 | U36: =T36+U35 -> 77225.921 | V36: =T36/P36 -> 89.576895 | W36: =U36/Q36 -> 91.306367 | X36: =IF(AND(R36>0,T36>0),(T36/(R36*1000))*1000,0) -> 78.568637 | Y36: =IF(AND(S36>0,U36>0),U36/S36,0) -> 98.350158 | Z36: 91.8 | AA36: =Z36+AA35 -> 1856.8 | AB36: =Z36/(P36) -> 2.0622262 | AC36: =AA36/(Q36) -> 2.1953466 | AD36: =IF(AND(R36>0,Z36>0),Z36/(R36),0) -> 1.8087957 | AE36: =IF(AND(S36>0,AA36>0),AA36/(S36),0) -> 2.3647057 | AF36: 0 | AG36: =+AF36+AG35 -> 0 | AH36: =AF36/(P36) -> 0 | AI36: =AG36/(Q36) -> 0 | AJ36: =IF(AND(R36>0,AF36>0),AF36/(R36),0) -> 0 | AK36: =IF(AND(S36>0,AG36>0),AG36/(S36),0) -> 0 | AL36: ='28'!I46 -> 41213.17 | AM36: =AL36+AM35 -> 820211.17 | AN36: =IF(AND(L36>0,AL36>0),(AL36/(P36*1000)*1000),0) -> 925.82658 | AO36: =IF(AND(M36>0,AM36>0),(AM36/(Q36*1000)*1000),0) -> 969.75862 | AP36: =IF(AND(R36>0,AL36>0),(AL36/(R36*1000)*1000),0) -> 812.05017 | AQ36: =IF(AND(S36>0,AM36>0),(AM36/(S36*1000)*1000),0) -> 1044.5702 | AR36: =+Listrik!AA35 -> 0 | AS36: =AR36+AS35 -> 0 | AT36: =IF(AND(L36>0,AR36>0),(AR36/(P36*1000)*1000),0) -> 0 | AU36: =IF(AND(M36>0,AS36>0),(AS36/(Q36*1000)*1000),0) -> 0 | AV36: =IF(AND(R36>0,AR36>0),(AR36/(R36*1000)*1000),0) -> 0 | AW36: =IF(AND(S36>0,AS36>0),(AS36/(S36*1000)*1000),0) -> 0 | AY36: =+Efficiency2!K132 -> 49.016431 | AZ36: =AZ35+AY36 -> 979.3338 | BA36: =+R36/AY36 -> 1.0354079 | BB36: =+S36/AZ36 -> 0.80178382
A37: =A36+1 -> 45959 | B37: Toilet/Facial | C37: 13/13 | D37: =+'29'!F42 -> 1320.2431 | E37: =+'29'!G42 -> 1016.5872 | F37: =1-(E37/D37) -> 0.23 | G37: =+P37/N37 -> 0.95223449 | H37: =+P37/L37 -> 0.93125883 | I37: =+R37/P37 -> 0.89078026 | J37: =+R37/L37 -> 0.82954699 | K37: =+S37/M37 -> 0.55677131 | L37: =+SUM(Efficiency1!K136:K137) -> 49.709059 | M37: =M36+L37 -> 1484.3617 | N37: =+SUM(Efficiency1!C136:C137) -> 48.614076 | O37: =O36+N37 -> 1426.438 | P37: ='29'!I38 -> 46.292 | Q37: =Q36+P37 -> 892.081 | R37: ='29'!I40 -> 41.236 | S37: =S36+R37 -> 826.45 | T37: =+[1]Report1!AZ37 -> 4136.4004 | U37: =T37+U36 -> 81362.322 | V37: =T37/P37 -> 89.35454 | W37: =U37/Q37 -> 91.205083 | X37: =IF(AND(R37>0,T37>0),(T37/(R37*1000))*1000,0) -> 100.31042 | Y37: =IF(AND(S37>0,U37>0),U37/S37,0) -> 98.447966 | Z37: 93 | AA37: =Z37+AA36 -> 1949.8 | AB37: =Z37/(P37) -> 2.0089864 | AC37: =AA37/(Q37) -> 2.185676 | AD37: =IF(AND(R37>0,Z37>0),Z37/(R37),0) -> 2.2553109 | AE37: =IF(AND(S37>0,AA37>0),AA37/(S37),0) -> 2.3592474 | AF37: 0 | AG37: =+AF37+AG36 -> 0 | AH37: =AF37/(P37) -> 0 | AI37: =AG37/(Q37) -> 0 | AJ37: =IF(AND(R37>0,AF37>0),AF37/(R37),0) -> 0 | AK37: =IF(AND(S37>0,AG37>0),AG37/(S37),0) -> 0 | AL37: ='29'!I46 -> 44163.74 | AM37: =AL37+AM36 -> 864374.91 | AN37: =IF(AND(L37>0,AL37>0),(AL37/(P37*1000)*1000),0) -> 954.02532 | AO37: =IF(AND(M37>0,AM37>0),(AM37/(Q37*1000)*1000),0) -> 968.94218 | AP37: =IF(AND(R37>0,AL37>0),(AL37/(R37*1000)*1000),0) -> 1070.9996 | AQ37: =IF(AND(S37>0,AM37>0),(AM37/(S37*1000)*1000),0) -> 1045.8889 | AR37: =+Listrik!AA36 -> 0 | AS37: =AR37+AS36 -> 0 | AT37: =IF(AND(L37>0,AR37>0),(AR37/(P37*1000)*1000),0) -> 0 | AU37: =IF(AND(M37>0,AS37>0),(AS37/(Q37*1000)*1000),0) -> 0 | AV37: =IF(AND(R37>0,AR37>0),(AR37/(R37*1000)*1000),0) -> 0 | AW37: =IF(AND(S37>0,AS37>0),(AS37/(S37*1000)*1000),0) -> 0 | AY37: =+SUM(Efficiency2!K136:K137) -> 49.709059 | AZ37: =AZ36+AY37 -> 1029.0429 | BA37: =+R37/AY37 -> 0.82954699 | BB37: =+S37/AZ37 -> 0.80312495
A38: =A37+1 -> 45960 | B38: Toilet/Facial | C38: 13/12/16/14/13,5 | D38: =+'30'!F42 -> 1332.9861 | E38: =+'30'!G42 -> 1041.1826 | F38: =1-(E38/D38) -> 0.21890961 | G38: =+P38/N38 -> 0.90364721 | H38: =+P38/L38 -> 0.90131916 | I38: =+R38/P38 -> 0.81646035 | J38: =+R38/L38 -> 0.73589136 | K38: =+S38/M38 -> 0.56292283 | L38: =+SUM(Efficiency1!K141:K145) -> 52.790401 | M38: =M37+L38 -> 1537.1521 | N38: =+SUM(Efficiency1!C141:C145) -> 52.654398 | O38: =O37+N38 -> 1479.0924 | P38: ='30'!I38 -> 47.581 | Q38: =Q37+P38 -> 939.662 | R38: ='30'!I40 -> 38.848 | S38: =S37+R38 -> 865.298 | T38: =+[1]Report1!AZ38 -> 4105.0039 | U38: =T38+U37 -> 85467.325 | V38: =T38/P38 -> 86.274014 | W38: =U38/Q38 -> 90.955392 | X38: =IF(AND(R38>0,T38>0),(T38/(R38*1000))*1000,0) -> 105.66835 | Y38: =IF(AND(S38>0,U38>0),U38/S38,0) -> 98.772129 | Z38: 93.2 | AA38: =Z38+AA37 -> 2043 | AB38: =Z38/(P38) -> 1.9587651 | AC38: =AA38/(Q38) -> 2.174186 | AD38: =IF(AND(R38>0,Z38>0),Z38/(R38),0) -> 2.3990939 | AE38: =IF(AND(S38>0,AA38>0),AA38/(S38),0) -> 2.3610363 | AF38: 4.3 | AG38: =+AF38+AG37 -> 4.3 | AH38: =AF38/(P38) -> 0.090372207 | AI38: =AG38/(Q38) -> 0.0045761135 | AJ38: =IF(AND(R38>0,AF38>0),AF38/(R38),0) -> 0.11068781 | AK38: =IF(AND(S38>0,AG38>0),AG38/(S38),0) -> 0.0049693863 | AL38: ='30'!I46 -> 37793.78 | AM38: =AL38+AM37 -> 902168.69 | AN38: =IF(AND(L38>0,AL38>0),(AL38/(P38*1000)*1000),0) -> 794.30403 | AO38: =IF(AND(M38>0,AM38>0),(AM38/(Q38*1000)*1000),0) -> 960.09916 | AP38: =IF(AND(R38>0,AL38>0),(AL38/(R38*1000)*1000),0) -> 972.86295 | AQ38: =IF(AND(S38>0,AM38>0),(AM38/(S38*1000)*1000),0) -> 1042.6104 | AR38: =+Listrik!AA37 -> 9973.8 | AS38: =AR38+AS37 -> 9973.8 | AT38: =IF(AND(L38>0,AR38>0),(AR38/(P38*1000)*1000),0) -> 209.61728 | AU38: =IF(AND(M38>0,AS38>0),(AS38/(Q38*1000)*1000),0) -> 10.614242 | AV38: =IF(AND(R38>0,AR38>0),(AR38/(R38*1000)*1000),0) -> 256.73909 | AW38: =IF(AND(S38>0,AS38>0),(AS38/(S38*1000)*1000),0) -> 11.526434 | AY38: =+SUM(Efficiency2!K141:K145) -> 52.113849 | AZ38: =AZ37+AY38 -> 1081.1567 | BA38: =+R38/AY38 -> 0.74544485 | BB38: =+S38/AZ38 -> 0.80034466
